2023-11-02 14:54:13,270 DEBUG ++Rcv raw: b'\x81~\x01\x9a{"topic":"orderbook.50.BTCUSDC","ts":1698936853184,"type":"delta","data":{"s":"BTCUSDC","b":[["34953.56","0.114437"],["34944.42","0.286168"],["34942","0.0341"],["34941.52","0.206875"],["34952.55","0"],["34950.01","0"],["34943.41","0"],["34959.2","0"]],"a":[["34967.85","0.03432"],["34972.75","0.00057"],["34972.85","0.028599"],["34968.45","0"],["34971.4","0"],["34967.86","0"]],"u":20009868,"seq":14108034006}}'
2023-11-02 14:54:13,270 DEBUG ++Rcv decoded: fin=1 opcode=1 data=b'{"topic":"orderbook.50.BTCUSDC","ts":1698936853184,"type":"delta","data":{"s":"BTCUSDC","b":[["34953.56","0.114437"],["34944.42","0.286168"],["34942","0.0341"],["34941.52","0.206875"],["34952.55","0"],["34950.01","0"],["34943.41","0"],["34959.2","0"]],"a":[["34967.85","0.03432"],["34972.75","0.00057"],["34972.85","0.028599"],["34968.45","0"],["34971.4","0"],["34967.86","0"]],"u":20009868,"seq":14108034006}}'
2023-11-02 14:54:13,289 DEBUG ++Rcv raw: b'\x81~\x01]{"topic":"orderbook.50.BTCUSDC","ts":1698936853204,"type":"delta","data":{"s":"BTCUSDC","b":[["34960.01","0.037815"],["34951.27","0.370888"],["34950.02","0"]],"a":[["34969.99","0.095861"],["34970","0.0324"],["34970.76","0.03"],["34985.87","0.116723"],["34970.07","0"],["34991.01","0"],["34991","0"],["34967.85","0"]],"u":20009869,"seq":14108034030}}'
2023-11-02 14:54:13,289 DEBUG ++Rcv decoded: fin=1 opcode=1 data=b'{"topic":"orderbook.50.BTCUSDC","ts":1698936853204,"type":"delta","data":{"s":"BTCUSDC","b":[["34960.01","0.037815"],["34951.27","0.370888"],["34950.02","0"]],"a":[["34969.99","0.095861"],["34970","0.0324"],["34970.76","0.03"],["34985.87","0.116723"],["34970.07","0"],["34991.01","0"],["34991","0"],["34967.85","0"]],"u":20009869,"seq":14108034030}}'
2023-11-02 14:54:13,309 DEBUG ++Rcv raw: b'\x81~\x00\xee{"topic":"orderbook.50.BTCUSDC","ts":1698936853224,"type":"delta","data":{"s":"BTCUSDC","b":[],"a":[["34969.99","0.121881"],["34970.07","0.01439"],["34971.89","0.051545"],["34972.75","0"],["34990.96","0"]],"u":20009870,"seq":14108034044}}'
2023-11-02 14:54:13,309 DEBUG ++Rcv decoded: fin=1 opcode=1 data=b'{"topic":"orderbook.50.BTCUSDC","ts":1698936853224,"type":"delta","data":{"s":"BTCUSDC","b":[],"a":[["34969.99","0.121881"],["34970.07","0.01439"],["34971.89","0.051545"],["34972.75","0"],["34990.96","0"]],"u":20009870,"seq":14108034044}}'
2023-11-02 14:54:13,329 DEBUG ++Rcv raw: b'\x81~\x00\xed{"topic":"orderbook.50.BTCUSDC","ts":1698936853244,"type":"delta","data":{"s":"BTCUSDC","b":[["34960.01","0.067464"],["34954.72","0.003157"],["34941.52","0"]],"a":[["34974.88","0.00057"],["34989.37","0"]],"u":20009871,"seq":14108034054}}'
2023-11-02 14:54:13,329 DEBUG ++Rcv decoded: fin=1 opcode=1 data=b'{"topic":"orderbook.50.BTCUSDC","ts":1698936853244,"type":"delta","data":{"s":"BTCUSDC","b":[["34960.01","0.067464"],["34954.72","0.003157"],["34941.52","0"]],"a":[["34974.88","0.00057"],["34989.37","0"]],"u":20009871,"seq":14108034054}}'
2023-11-02 14:54:13,349 DEBUG ++Rcv raw: b'\x81~\x00\xae{"topic":"orderbook.50.BTCUSDC","ts":1698936853263,"type":"delta","data":{"s":"BTCUSDC","b":[["34941.52","0.206875"],["34944.38","0"]],"a":[],"u":20009872,"seq":14108034062}}'
2023-11-02 14:54:13,349 DEBUG ++Rcv decoded: fin=1 opcode=1 data=b'{"topic":"orderbook.50.BTCUSDC","ts":1698936853263,"type":"delta","data":{"s":"BTCUSDC","b":[["34941.52","0.206875"],["34944.38","0"]],"a":[],"u":20009872,"seq":14108034062}}'
2023-11-02 14:54:13,368 DEBUG ++Rcv raw: b'\x81~\x01\x17{"topic":"orderbook.50.BTCUSDC","ts":1698936853283,"type":"delta","data":{"s":"BTCUSDC","b":[["34961.59","0.051547"],["34958.15","0.051548"],["34941.48","0.082683"],["34954.97","0"],["34960.01","0"],["34957.23","0"]],"a":[["34973.61","0.474211"]],"u":20009873,"seq":14108034092}}'
2023-11-02 14:54:13,369 DEBUG ++Rcv decoded: fin=1 opcode=1 data=b'{"topic":"orderbook.50.BTCUSDC","ts":1698936853283,"type":"delta","data":{"s":"BTCUSDC","b":[["34961.59","0.051547"],["34958.15","0.051548"],["34941.48","0.082683"],["34954.97","0"],["34960.01","0"],["34957.23","0"]],"a":[["34973.61","0.474211"]],"u":20009873,"seq":14108034092}}'
2023-11-02 14:54:13,388 DEBUG ++Rcv raw: b'\x81~\x00\xae{"topic":"orderbook.50.BTCUSDC","ts":1698936853303,"type":"delta","data":{"s":"BTCUSDC","b":[],"a":[["34983.04","0.075313"],["34988.12","0"]],"u":20009874,"seq":14108034106}}'
2023-11-02 14:54:13,388 DEBUG ++Rcv decoded: fin=1 opcode=1 data=b'{"topic":"orderbook.50.BTCUSDC","ts":1698936853303,"type":"delta","data":{"s":"BTCUSDC","b":[],"a":[["34983.04","0.075313"],["34988.12","0"]],"u":20009874,"seq":14108034106}}'
2023-11-02 14:54:13,409 DEBUG ++Rcv raw: b'\x81~\x00\xff{"topic":"orderbook.50.BTCUSDC","ts":1698936853323,"type":"delta","data":{"s":"BTCUSDC","b":[["34957.14","0.028601"],["34950.03","0.077866"],["34960.13","0"],["34941.48","0"]],"a":[["34969.98","0.028601"],["34977.72","0"]],"u":20009875,"seq":14108034125}}'
2023-11-02 14:54:13,409 DEBUG ++Rcv decoded: fin=1 opcode=1 data=b'{"topic":"orderbook.50.BTCUSDC","ts":1698936853323,"type":"delta","data":{"s":"BTCUSDC","b":[["34957.14","0.028601"],["34950.03","0.077866"],["34960.13","0"],["34941.48","0"]],"a":[["34969.98","0.028601"],["34977.72","0"]],"u":20009875,"seq":14108034125}}'
2023-11-02 14:54:13,429 DEBUG ++Rcv raw: b'\x81~\x01u{"topic":"orderbook.50.BTCUSDC","ts":1698936853343,"type":"delta","data":{"s":"BTCUSDC","b":[["34963.79","0.10537"],["34959.73","0.057208"],["34951.28","0.222532"],["34941.52","0"],["34942","0"],["34942.2","0"]],"a":[["34967.21","0.057196"],["34979.81","0.049142"],["34985.86","0.243302"],["34987.53","0"],["34972.85","0"],["34988.11","0"]],"u":20009876,"seq":14108034147}}'
2023-11-02 14:54:13,429 DEBUG ++Rcv decoded: fin=1 opcode=1 data=b'{"topic":"orderbook.50.BTCUSDC","ts":1698936853343,"type":"delta","data":{"s":"BTCUSDC","b":[["34963.79","0.10537"],["34959.73","0.057208"],["34951.28","0.222532"],["34941.52","0"],["34942","0"],["34942.2","0"]],"a":[["34967.21","0.057196"],["34979.81","0.049142"],["34985.86","0.243302"],["34987.53","0"],["34972.85","0"],["34988.11","0"]],"u":20009876,"seq":14108034147}}'
2023-11-02 14:54:13,449 DEBUG ++Rcv raw: b'\x81~\x00\xf9{"topic":"orderbook.50.BTCUSDC","ts":1698936853364,"type":"delta","data":{"s":"BTCUSDC","b":[["34953.29","0.1875"],["34943.35","0"]],"a":[["34967.18","0.000239"],["34975.33","0.021"],["34974.88","0"],["34980.9","0"]],"u":20009877,"seq":14108034168}}'
2023-11-02 14:54:13,449 DEBUG ++Rcv decoded: fin=1 opcode=1 data=b'{"topic":"orderbook.50.BTCUSDC","ts":1698936853364,"type":"delta","data":{"s":"BTCUSDC","b":[["34953.29","0.1875"],["34943.35","0"]],"a":[["34967.18","0.000239"],["34975.33","0.021"],["34974.88","0"],["34980.9","0"]],"u":20009877,"seq":14108034168}}'
2023-11-02 14:54:13,469 DEBUG ++Rcv raw: b'\x81~\x01<{"topic":"orderbook.50.BTCUSDC","ts":1698936853384,"type":"delta","data":{"s":"BTCUSDC","b":[["34963.79","0.10837"],["34962.51","0.028602"],["34953.8","0.112503"],["34943.75","0"],["34954.71","0"]],"a":[["34972.07","0.00057"],["34986.8","0.528984"],["34980.89","0"],["34967.21","0"]],"u":20009878,"seq":14108034183}}'
2023-11-02 14:54:13,470 DEBUG ++Rcv decoded: fin=1 opcode=1 data=b'{"topic":"orderbook.50.BTCUSDC","ts":1698936853384,"type":"delta","data":{"s":"BTCUSDC","b":[["34963.79","0.10837"],["34962.51","0.028602"],["34953.8","0.112503"],["34943.75","0"],["34954.71","0"]],"a":[["34972.07","0.00057"],["34986.8","0.528984"],["34980.89","0"],["34967.21","0"]],"u":20009878,"seq":14108034183}}'
2023-11-02 14:54:13,489 DEBUG ++Rcv raw: b'\x81~\x00\xc2{"topic":"orderbook.50.BTCUSDC","ts":1698936853404,"type":"delta","data":{"s":"BTCUSDC","b":[["34963.8","0.008956"],["34963.79","0.003"],["34962.52","0"]],"a":[],"u":20009879,"seq":14108034191}}'
2023-11-02 14:54:13,489 DEBUG ++Rcv decoded: fin=1 opcode=1 data=b'{"topic":"orderbook.50.BTCUSDC","ts":1698936853404,"type":"delta","data":{"s":"BTCUSDC","b":[["34963.8","0.008956"],["34963.79","0.003"],["34962.52","0"]],"a":[],"u":20009879,"seq":14108034191}}'
2023-11-02 14:54:13,509 DEBUG ++Rcv raw: b'\x81~\x00\xfe{"topic":"orderbook.50.BTCUSDC","ts":1698936853424,"type":"delta","data":{"s":"BTCUSDC","b":[["34960.01","0.106514"],["34957.23","0.021606"],["34943.75","0.1875"],["34958.15","0"],["34963.79","0"],["34961.59","0"]],"a":[],"u":20009880,"seq":14108034201}}'
2023-11-02 14:54:13,509 DEBUG ++Rcv decoded: fin=1 opcode=1 data=b'{"topic":"orderbook.50.BTCUSDC","ts":1698936853424,"type":"delta","data":{"s":"BTCUSDC","b":[["34960.01","0.106514"],["34957.23","0.021606"],["34943.75","0.1875"],["34958.15","0"],["34963.79","0"],["34961.59","0"]],"a":[],"u":20009880,"seq":14108034201}}'
2023-11-02 14:54:13,529 DEBUG ++Rcv raw: b'\x81~\x00\xac{"topic":"orderbook.50.BTCUSDC","ts":1698936853444,"type":"delta","data":{"s":"BTCUSDC","b":[],"a":[["34987.53","0.1875"],["34985.87","0"]],"u":20009881,"seq":14108034204}}'
2023-11-02 14:54:13,530 DEBUG ++Rcv decoded: fin=1 opcode=1 data=b'{"topic":"orderbook.50.BTCUSDC","ts":1698936853444,"type":"delta","data":{"s":"BTCUSDC","b":[],"a":[["34987.53","0.1875"],["34985.87","0"]],"u":20009881,"seq":14108034204}}'
2023-11-02 14:54:13,550 DEBUG ++Rcv raw: b'\x81~\x00\x9d{"topic":"orderbook.50.BTCUSDC","ts":1698936853464,"type":"delta","data":{"s":"BTCUSDC","b":[],"a":[["34970.07","0.037072"]],"u":20009882,"seq":14108034211}}'
2023-11-02 14:54:13,550 DEBUG ++Rcv decoded: fin=1 opcode=1 data=b'{"topic":"orderbook.50.BTCUSDC","ts":1698936853464,"type":"delta","data":{"s":"BTCUSDC","b":[],"a":[["34970.07","0.037072"]],"u":20009882,"seq":14108034211}}'
2023-11-02 14:54:13,568 DEBUG ++Rcv raw: b'\x81~\x01\x16{"topic":"orderbook.50.BTCUSDC","ts":1698936853483,"type":"delta","data":{"s":"BTCUSDC","b":[["34961.59","0.027476"],["34958.15","0.051548"],["34957.23","0"],["34960.01","0"]],"a":[["34969.97","0.150882"],["34969.99","0.02602"],["34987.53","0"]],"u":20009883,"seq":14108034218}}'
2023-11-02 14:54:13,569 DEBUG ++Rcv decoded: fin=1 opcode=1 data=b'{"topic":"orderbook.50.BTCUSDC","ts":1698936853483,"type":"delta","data":{"s":"BTCUSDC","b":[["34961.59","0.027476"],["34958.15","0.051548"],["34957.23","0"],["34960.01","0"]],"a":[["34969.97","0.150882"],["34969.99","0.02602"],["34987.53","0"]],"u":20009883,"seq":14108034218}}'
2023-11-02 14:54:13,610 DEBUG ++Rcv raw: b'\x81~\x00\xab{"topic":"orderbook.50.BTCUSDC","ts":1698936853524,"type":"delta","data":{"s":"BTCUSDC","b":[],"a":[["34982.22","0.0859"],["34986.8","0"]],"u":20009884,"seq":14108034231}}'
2023-11-02 14:54:13,610 DEBUG ++Rcv decoded: fin=1 opcode=1 data=b'{"topic":"orderbook.50.BTCUSDC","ts":1698936853524,"type":"delta","data":{"s":"BTCUSDC","b":[],"a":[["34982.22","0.0859"],["34986.8","0"]],"u":20009884,"seq":14108034231}}'
2023-11-02 14:54:13,649 DEBUG ++Rcv raw: b'\x81~\x00\xd7{"topic":"orderbook.50.BTCUSDC","ts":1698936853563,"type":"delta","data":{"s":"BTCUSDC","b":[],"a":[["34967.68","0.000239"],["34971.74","0.042576"],["34986.02","0"],["34985.86","0"]],"u":20009885,"seq":14108034263}}'
2023-11-02 14:54:13,649 DEBUG ++Rcv decoded: fin=1 opcode=1 data=b'{"topic":"orderbook.50.BTCUSDC","ts":1698936853563,"type":"delta","data":{"s":"BTCUSDC","b":[],"a":[["34967.68","0.000239"],["34971.74","0.042576"],["34986.02","0"],["34985.86","0"]],"u":20009885,"seq":14108034263}}'
2023-11-02 14:54:13,690 DEBUG ++Rcv raw: b'\x81~\x00\xae{"topic":"orderbook.50.BTCUSDC","ts":1698936853604,"type":"delta","data":{"s":"BTCUSDC","b":[],"a":[["34985.86","0.243302"],["34983.04","0"]],"u":20009886,"seq":14108034287}}'
2023-11-02 14:54:13,690 DEBUG ++Rcv decoded: fin=1 opcode=1 data=b'{"topic":"orderbook.50.BTCUSDC","ts":1698936853604,"type":"delta","data":{"s":"BTCUSDC","b":[],"a":[["34985.86","0.243302"],["34983.04","0"]],"u":20009886,"seq":14108034287}}'
2023-11-02 14:54:13,709 DEBUG ++Rcv raw: b'\x81~\x00\xff{"topic":"orderbook.50.BTCUSDC","ts":1698936853623,"type":"delta","data":{"s":"BTCUSDC","b":[["34960.01","0.106509"],["34957.23","0.021601"],["34943.35","0.02598"],["34961.59","0"],["34958.15","0"],["34962.51","0"]],"a":[],"u":20009887,"seq":14108034300}}'
2023-11-02 14:54:13,709 DEBUG ++Rcv decoded: fin=1 opcode=1 data=b'{"topic":"orderbook.50.BTCUSDC","ts":1698936853623,"type":"delta","data":{"s":"BTCUSDC","b":[["34960.01","0.106509"],["34957.23","0.021601"],["34943.35","0.02598"],["34961.59","0"],["34958.15","0"],["34962.51","0"]],"a":[],"u":20009887,"seq":14108034300}}'
2023-11-02 14:54:13,728 DEBUG ++Rcv raw: b'\x81~\x00\xae{"topic":"orderbook.50.BTCUSDC","ts":1698936853643,"type":"delta","data":{"s":"BTCUSDC","b":[["34954.97","0.002268"],["34943.35","0"]],"a":[],"u":20009888,"seq":14108034328}}'
2023-11-02 14:54:13,729 DEBUG ++Rcv decoded: fin=1 opcode=1 data=b'{"topic":"orderbook.50.BTCUSDC","ts":1698936853643,"type":"delta","data":{"s":"BTCUSDC","b":[["34954.97","0.002268"],["34943.35","0"]],"a":[],"u":20009888,"seq":14108034328}}'
2023-11-02 14:54:13,749 DEBUG ++Rcv raw: b'\x81~\x00\xfc{"topic":"orderbook.50.BTCUSDC","ts":1698936853664,"type":"delta","data":{"s":"BTCUSDC","b":[["34943.35","0.02598"],["34943.12","0.20625"],["34963.8","0"],["34954.72","0"]],"a":[["34966.13","0.099552"],["34985.86","0"]],"u":20009889,"seq":14108034341}}'
2023-11-02 14:54:13,749 DEBUG ++Rcv decoded: fin=1 opcode=1 data=b'{"topic":"orderbook.50.BTCUSDC","ts":1698936853664,"type":"delta","data":{"s":"BTCUSDC","b":[["34943.35","0.02598"],["34943.12","0.20625"],["34963.8","0"],["34954.72","0"]],"a":[["34966.13","0.099552"],["34985.86","0"]],"u":20009889,"seq":14108034341}}'
2023-11-02 14:54:13,769 DEBUG ++Rcv raw: b'\x81~\x00\xd7{"topic":"orderbook.50.BTCUSDC","ts":1698936853684,"type":"delta","data":{"s":"BTCUSDC","b":[["34963.17","0.008956"],["34963.16","0.094355"],["34953.29","0"],["34943.12","0"]],"a":[],"u":20009890,"seq":14108034355}}'
2023-11-02 14:54:13,769 DEBUG ++Rcv decoded: fin=1 opcode=1 data=b'{"topic":"orderbook.50.BTCUSDC","ts":1698936853684,"type":"delta","data":{"s":"BTCUSDC","b":[["34963.17","0.008956"],["34963.16","0.094355"],["34953.29","0"],["34943.12","0"]],"a":[],"u":20009890,"seq":14108034355}}'
2023-11-02 14:54:13,789 DEBUG ++Rcv raw: b'\x81~\x01%{"topic":"orderbook.50.BTCUSDC","ts":1698936853704,"type":"delta","data":{"s":"BTCUSDC","b":[["34961.59","0.0236"],["34958.15","0.051543"],["34954.01","0.068666"],["34943.12","0.20625"],["34960.01","0"],["34963.16","0"],["34957.23","0"],["34953.8","0"]],"a":[],"u":20009891,"seq":14108034369}}'
2023-11-02 14:54:13,790 DEBUG ++Rcv decoded: fin=1 opcode=1 data=b'{"topic":"orderbook.50.BTCUSDC","ts":1698936853704,"type":"delta","data":{"s":"BTCUSDC","b":[["34961.59","0.0236"],["34958.15","0.051543"],["34954.01","0.068666"],["34943.12","0.20625"],["34960.01","0"],["34963.16","0"],["34957.23","0"],["34953.8","0"]],"a":[],"u":20009891,"seq":14108034369}}'
2023-11-02 14:54:13,809 DEBUG ++Rcv raw: b'\x81~\x00\xae{"topic":"orderbook.50.BTCUSDC","ts":1698936853724,"type":"delta","data":{"s":"BTCUSDC","b":[["34963.81","0.028601"],["34943.12","0"]],"a":[],"u":20009892,"seq":14108034387}}'
2023-11-02 14:54:13,809 DEBUG ++Rcv decoded: fin=1 opcode=1 data=b'{"topic":"orderbook.50.BTCUSDC","ts":1698936853724,"type":"delta","data":{"s":"BTCUSDC","b":[["34963.81","0.028601"],["34943.12","0"]],"a":[],"u":20009892,"seq":14108034387}}'
2023-11-02 14:54:13,829 DEBUG ++Rcv raw: b'\x81~\x01s{"topic":"orderbook.50.BTCUSDC","ts":1698936853743,"type":"delta","data":{"s":"BTCUSDC","b":[["34963.82","0.008956"],["34953.31","0.1875"],["34963.17","0"],["34957.11","0"]],"a":[["34985.86","0.243302"],["34986.02","0.4055"],["34986.8","0.528984"],["34987.53","0.1875"],["34981.67","0"],["34966.13","0"],["34972.07","0"],["34972.52","0"]],"u":20009893,"seq":14108034407}}'
2023-11-02 14:54:13,829 DEBUG ++Rcv decoded: fin=1 opcode=1 data=b'{"topic":"orderbook.50.BTCUSDC","ts":1698936853743,"type":"delta","data":{"s":"BTCUSDC","b":[["34963.82","0.008956"],["34953.31","0.1875"],["34963.17","0"],["34957.11","0"]],"a":[["34985.86","0.243302"],["34986.02","0.4055"],["34986.8","0.528984"],["34987.53","0.1875"],["34981.67","0"],["34966.13","0"],["34972.07","0"],["34972.52","0"]],"u":20009893,"seq":14108034407}}'
2023-11-02 14:54:13,849 DEBUG ++Rcv raw: b'\x81~\x01\x15{"topic":"orderbook.50.BTCUSDC","ts":1698936853763,"type":"delta","data":{"s":"BTCUSDC","b":[["34954.01","0.103922"]],"a":[["34972.07","0.00057"],["34973.49","0.114372"],["34982.64","0.285856"],["34986.02","0"],["34987.53","0"],["34986.8","0"]],"u":20009894,"seq":14108034424}}'
2023-11-02 14:54:13,849 DEBUG ++Rcv decoded: fin=1 opcode=1 data=b'{"topic":"orderbook.50.BTCUSDC","ts":1698936853763,"type":"delta","data":{"s":"BTCUSDC","b":[["34954.01","0.103922"]],"a":[["34972.07","0.00057"],["34973.49","0.114372"],["34982.64","0.285856"],["34986.02","0"],["34987.53","0"],["34986.8","0"]],"u":20009894,"seq":14108034424}}'
2023-11-02 14:54:13,870 DEBUG ++Rcv raw: b'\x81~\x00\xac{"topic":"orderbook.50.BTCUSDC","ts":1698936853784,"type":"delta","data":{"s":"BTCUSDC","b":[],"a":[["34986.02","0.4055"],["34967.68","0"]],"u":20009895,"seq":14108034428}}'
2023-11-02 14:54:13,870 DEBUG ++Rcv decoded: fin=1 opcode=1 data=b'{"topic":"orderbook.50.BTCUSDC","ts":1698936853784,"type":"delta","data":{"s":"BTCUSDC","b":[],"a":[["34986.02","0.4055"],["34967.68","0"]],"u":20009895,"seq":14108034428}}'
2023-11-02 14:54:13,910 DEBUG ++Rcv raw: b'\x81~\x00\xad{"topic":"orderbook.50.BTCUSDC","ts":1698936853824,"type":"delta","data":{"s":"BTCUSDC","b":[["34943.12","0.20625"],["34963.81","0"]],"a":[],"u":20009896,"seq":14108034437}}'
2023-11-02 14:54:13,910 DEBUG ++Rcv decoded: fin=1 opcode=1 data=b'{"topic":"orderbook.50.BTCUSDC","ts":1698936853824,"type":"delta","data":{"s":"BTCUSDC","b":[["34943.12","0.20625"],["34963.81","0"]],"a":[],"u":20009896,"seq":14108034437}}'
2023-11-02 14:54:13,929 DEBUG ++Rcv raw: b'\x81~\x00\xd5{"topic":"orderbook.50.BTCUSDC","ts":1698936853844,"type":"delta","data":{"s":"BTCUSDC","b":[["34954.71","0.003013"],["34943.12","0"]],"a":[["34986.8","0.528984"],["34971.74","0"]],"u":20009897,"seq":14108034450}}'
2023-11-02 14:54:13,930 DEBUG ++Rcv decoded: fin=1 opcode=1 data=b'{"topic":"orderbook.50.BTCUSDC","ts":1698936853844,"type":"delta","data":{"s":"BTCUSDC","b":[["34954.71","0.003013"],["34943.12","0"]],"a":[["34986.8","0.528984"],["34971.74","0"]],"u":20009897,"seq":14108034450}}'
2023-11-02 14:54:13,949 DEBUG ++Rcv raw: b'\x81~\x00\xad{"topic":"orderbook.50.BTCUSDC","ts":1698936853864,"type":"delta","data":{"s":"BTCUSDC","b":[["34943.12","0.20625"],["34954.97","0"]],"a":[],"u":20009898,"seq":14108034456}}'
2023-11-02 14:54:13,950 DEBUG ++Rcv decoded: fin=1 opcode=1 data=b'{"topic":"orderbook.50.BTCUSDC","ts":1698936853864,"type":"delta","data":{"s":"BTCUSDC","b":[["34943.12","0.20625"],["34954.97","0"]],"a":[],"u":20009898,"seq":14108034456}}'
2023-11-02 14:54:14,029 DEBUG ++Rcv raw: b'\x81~\x00\xad{"topic":"orderbook.50.BTCUSDC","ts":1698936853944,"type":"delta","data":{"s":"BTCUSDC","b":[],"a":[["34972.81","0.358547"],["34986.8","0"]],"u":20009899,"seq":14108034479}}'
2023-11-02 14:54:14,030 DEBUG ++Rcv decoded: fin=1 opcode=1 data=b'{"topic":"orderbook.50.BTCUSDC","ts":1698936853944,"type":"delta","data":{"s":"BTCUSDC","b":[],"a":[["34972.81","0.358547"],["34986.8","0"]],"u":20009899,"seq":14108034479}}'
2023-11-02 14:54:14,089 DEBUG ++Rcv raw: b'\x81~\x00\xfd{"topic":"orderbook.50.BTCUSDC","ts":1698936854003,"type":"delta","data":{"s":"BTCUSDC","b":[["34963.9","0.109066"],["34962.01","0.008956"],["34943.12","0"],["34963.82","0"]],"a":[["34986.8","0.528984"],["34969.99","0"]],"u":20009900,"seq":14108034505}}'
2023-11-02 14:54:14,089 DEBUG ++Rcv decoded: fin=1 opcode=1 data=b'{"topic":"orderbook.50.BTCUSDC","ts":1698936854003,"type":"delta","data":{"s":"BTCUSDC","b":[["34963.9","0.109066"],["34962.01","0.008956"],["34943.12","0"],["34963.82","0"]],"a":[["34986.8","0.528984"],["34969.99","0"]],"u":20009900,"seq":14108034505}}'
2023-11-02 14:54:14,109 DEBUG ++Rcv raw: b'\x81~\x01\x00{"topic":"orderbook.50.BTCUSDC","ts":1698936854024,"type":"delta","data":{"s":"BTCUSDC","b":[["34963.91","0.008956"],["34962","0.0354"],["34961.59","0.048596"],["34943.12","0.20625"],["34963.9","0"],["34962.01","0"]],"a":[],"u":20009901,"seq":14108034518}}'
2023-11-02 14:54:14,109 DEBUG ++Rcv decoded: fin=1 opcode=1 data=b'{"topic":"orderbook.50.BTCUSDC","ts":1698936854024,"type":"delta","data":{"s":"BTCUSDC","b":[["34963.91","0.008956"],["34962","0.0354"],["34961.59","0.048596"],["34943.12","0.20625"],["34963.9","0"],["34962.01","0"]],"a":[],"u":20009901,"seq":14108034518}}'
2023-11-02 14:54:14,129 DEBUG ++Rcv raw: b'\x81~\x00\x98{"topic":"orderbook.50.BTCUSDC","ts":1698936854044,"type":"delta","data":{"s":"BTCUSDC","b":[["34962","0.0324"]],"a":[],"u":20009902,"seq":14108034520}}'
2023-11-02 14:54:14,130 DEBUG ++Rcv decoded: fin=1 opcode=1 data=b'{"topic":"orderbook.50.BTCUSDC","ts":1698936854044,"type":"delta","data":{"s":"BTCUSDC","b":[["34962","0.0324"]],"a":[],"u":20009902,"seq":14108034520}}'
2023-11-02 14:54:14,149 DEBUG ++Rcv raw: b'\x81~\x00\xac{"topic":"orderbook.50.BTCUSDC","ts":1698936854063,"type":"delta","data":{"s":"BTCUSDC","b":[["34963.83","0.0286"],["34943.12","0"]],"a":[],"u":20009903,"seq":14108034536}}'
2023-11-02 14:54:14,149 DEBUG ++Rcv decoded: fin=1 opcode=1 data=b'{"topic":"orderbook.50.BTCUSDC","ts":1698936854063,"type":"delta","data":{"s":"BTCUSDC","b":[["34963.83","0.0286"],["34943.12","0"]],"a":[],"u":20009903,"seq":14108034536}}'
2023-11-02 14:54:14,188 DEBUG ++Rcv raw: b'\x81~\x00\xd4{"topic":"orderbook.50.BTCUSDC","ts":1698936854103,"type":"delta","data":{"s":"BTCUSDC","b":[["34942.2","0.043599"],["34954.96","0"]],"a":[["34967.07","0.057196"],["34986.8","0"]],"u":20009904,"seq":14108034581}}'
2023-11-02 14:54:14,189 DEBUG ++Rcv decoded: fin=1 opcode=1 data=b'{"topic":"orderbook.50.BTCUSDC","ts":1698936854103,"type":"delta","data":{"s":"BTCUSDC","b":[["34942.2","0.043599"],["34954.96","0"]],"a":[["34967.07","0.057196"],["34986.8","0"]],"u":20009904,"seq":14108034581}}'
2023-11-02 14:54:14,209 DEBUG ++Rcv raw: b'\x81~\x01\xbd{"topic":"orderbook.50.BTCUSDC","ts":1698936854123,"type":"delta","data":{"s":"BTCUSDC","b":[["34942","0.0341"],["34941.44","0.025298"],["34940.99","0.126463"],["34940.87","0.00154"],["34940.24","0.05724"],["34963.83","0"],["34958.46","0"],["34953.31","0"],["34962","0"],["34963.91","0"]],"a":[["34967.06","0.046193"],["34968","0.0324"],["34972.04","0.042233"],["34986.02","0"],["34985.86","0"],["34985.12","0"]],"u":20009905,"seq":14108034603}}'
2023-11-02 14:54:14,210 DEBUG ++Rcv decoded: fin=1 opcode=1 data=b'{"topic":"orderbook.50.BTCUSDC","ts":1698936854123,"type":"delta","data":{"s":"BTCUSDC","b":[["34942","0.0341"],["34941.44","0.025298"],["34940.99","0.126463"],["34940.87","0.00154"],["34940.24","0.05724"],["34963.83","0"],["34958.46","0"],["34953.31","0"],["34962","0"],["34963.91","0"]],"a":[["34967.06","0.046193"],["34968","0.0324"],["34972.04","0.042233"],["34986.02","0"],["34985.86","0"],["34985.12","0"]],"u":20009905,"seq":14108034603}}'
2023-11-02 14:54:14,229 DEBUG ++Rcv raw: b'\x81~\x01R{"topic":"orderbook.50.BTCUSDC","ts":1698936854143,"type":"delta","data":{"s":"BTCUSDC","b":[["34961.59","0.0236"],["34956.7","0.00057"],["34954.01","0.068666"],["34959.78","0"]],"a":[["34985.12","0.000491"],["34985.86","0.243302"],["34986.02","0.4055"],["34967.07","0"],["34967.18","0"],["34967.06","0"]],"u":20009906,"seq":14108034626}}'
2023-11-02 14:54:14,229 DEBUG ++Rcv decoded: fin=1 opcode=1 data=b'{"topic":"orderbook.50.BTCUSDC","ts":1698936854143,"type":"delta","data":{"s":"BTCUSDC","b":[["34961.59","0.0236"],["34956.7","0.00057"],["34954.01","0.068666"],["34959.78","0"]],"a":[["34985.12","0.000491"],["34985.86","0.243302"],["34986.02","0.4055"],["34967.07","0"],["34967.18","0"],["34967.06","0"]],"u":20009906,"seq":14108034626}}'
2023-11-02 14:54:14,249 DEBUG ++Rcv raw: b'\x81~\x00\xd4{"topic":"orderbook.50.BTCUSDC","ts":1698936854163,"type":"delta","data":{"s":"BTCUSDC","b":[["34939.85","0.1875"],["34959.73","0"]],"a":[["34986.52","0.060806"],["34982.64","0"]],"u":20009907,"seq":14108034644}}'
2023-11-02 14:54:14,249 DEBUG ++Rcv decoded: fin=1 opcode=1 data=b'{"topic":"orderbook.50.BTCUSDC","ts":1698936854163,"type":"delta","data":{"s":"BTCUSDC","b":[["34939.85","0.1875"],["34959.73","0"]],"a":[["34986.52","0.060806"],["34982.64","0"]],"u":20009907,"seq":14108034644}}'
2023-11-02 14:54:14,269 DEBUG ++Rcv raw: b'\x81~\x00\xd6{"topic":"orderbook.50.BTCUSDC","ts":1698936854183,"type":"delta","data":{"s":"BTCUSDC","b":[["34959.08","0.057209"],["34939.85","0"]],"a":[["34981.67","0.285864"],["34986.52","0"]],"u":20009908,"seq":14108034661}}'
2023-11-02 14:54:14,269 DEBUG ++Rcv decoded: fin=1 opcode=1 data=b'{"topic":"orderbook.50.BTCUSDC","ts":1698936854183,"type":"delta","data":{"s":"BTCUSDC","b":[["34959.08","0.057209"],["34939.85","0"]],"a":[["34981.67","0.285864"],["34986.52","0"]],"u":20009908,"seq":14108034661}}'
2023-11-02 14:54:14,289 DEBUG ++Rcv raw: b'\x81~\x01P{"topic":"orderbook.50.BTCUSDC","ts":1698936854203,"type":"delta","data":{"s":"BTCUSDC","b":[["34959.09","0.034332"],["34943.15","0.20658"],["34940.87","0"],["34940.24","0"]],"a":[["34966.48","0.057197"],["34967.99","0.008756"],["34972.44","0.114375"],["34973.49","0"],["34986.02","0"],["34985.86","0"]],"u":20009909,"seq":14108034685}}'
2023-11-02 14:54:14,289 DEBUG ++Rcv decoded: fin=1 opcode=1 data=b'{"topic":"orderbook.50.BTCUSDC","ts":1698936854203,"type":"delta","data":{"s":"BTCUSDC","b":[["34959.09","0.034332"],["34943.15","0.20658"],["34940.87","0"],["34940.24","0"]],"a":[["34966.48","0.057197"],["34967.99","0.008756"],["34972.44","0.114375"],["34973.49","0"],["34986.02","0"],["34985.86","0"]],"u":20009909,"seq":14108034685}}'
2023-11-02 14:54:14,309 DEBUG ++Rcv raw: b'\x81~\x00\xd2{"topic":"orderbook.50.BTCUSDC","ts":1698936854224,"type":"delta","data":{"s":"BTCUSDC","b":[["34961.6","0.00572"],["34940.99","0"]],"a":[["34973.48","0.1875"],["34985.12","0"]],"u":20009910,"seq":14108034693}}'
2023-11-02 14:54:14,309 DEBUG ++Rcv decoded: fin=1 opcode=1 data=b'{"topic":"orderbook.50.BTCUSDC","ts":1698936854224,"type":"delta","data":{"s":"BTCUSDC","b":[["34961.6","0.00572"],["34940.99","0"]],"a":[["34973.48","0.1875"],["34985.12","0"]],"u":20009910,"seq":14108034693}}'
2023-11-02 14:54:14,329 DEBUG ++Rcv raw: b'\x81~\x01\x1f{"topic":"orderbook.50.BTCUSDC","ts":1698936854244,"type":"delta","data":{"s":"BTCUSDC","b":[["34961.85","0.101201"],["34943.36","0.028"],["34942","0"],["34941.44","0"]],"a":[["34965.36","0.102388"],["34966.47","0.008756"],["34985","0"],["34967.99","0"]],"u":20009911,"seq":14108034701}}'
2023-11-02 14:54:14,329 DEBUG ++Rcv decoded: fin=1 opcode=1 data=b'{"topic":"orderbook.50.BTCUSDC","ts":1698936854244,"type":"delta","data":{"s":"BTCUSDC","b":[["34961.85","0.101201"],["34943.36","0.028"],["34942","0"],["34941.44","0"]],"a":[["34965.36","0.102388"],["34966.47","0.008756"],["34985","0"],["34967.99","0"]],"u":20009911,"seq":14108034701}}'
2023-11-02 14:54:14,349 DEBUG ++Rcv raw: b'\x81~\x00\xae{"topic":"orderbook.50.BTCUSDC","ts":1698936854264,"type":"delta","data":{"s":"BTCUSDC","b":[["34954.02","0.001092"],["34954.71","0"]],"a":[],"u":20009912,"seq":14108034716}}'
2023-11-02 14:54:14,349 DEBUG ++Rcv decoded: fin=1 opcode=1 data=b'{"topic":"orderbook.50.BTCUSDC","ts":1698936854264,"type":"delta","data":{"s":"BTCUSDC","b":[["34954.02","0.001092"],["34954.71","0"]],"a":[],"u":20009912,"seq":14108034716}}'
2023-11-02 14:54:14,389 DEBUG ++Rcv raw: b'\x81~\x00\xad{"topic":"orderbook.50.BTCUSDC","ts":1698936854304,"type":"delta","data":{"s":"BTCUSDC","b":[["34958.17","0.022609"],["34942.2","0"]],"a":[],"u":20009913,"seq":14108034724}}'
2023-11-02 14:54:14,389 DEBUG ++Rcv decoded: fin=1 opcode=1 data=b'{"topic":"orderbook.50.BTCUSDC","ts":1698936854304,"type":"delta","data":{"s":"BTCUSDC","b":[["34958.17","0.022609"],["34942.2","0"]],"a":[],"u":20009913,"seq":14108034724}}'
2023-11-02 14:54:14,429 DEBUG ++Rcv raw: b'\x81~\x00\xd6{"topic":"orderbook.50.BTCUSDC","ts":1698936854344,"type":"delta","data":{"s":"BTCUSDC","b":[["34944.43","0.171708"],["34943.15","0"]],"a":[["34981.66","0.171527"],["34984.95","0"]],"u":20009914,"seq":14108034731}}'
2023-11-02 14:54:14,429 DEBUG ++Rcv decoded: fin=1 opcode=1 data=b'{"topic":"orderbook.50.BTCUSDC","ts":1698936854344,"type":"delta","data":{"s":"BTCUSDC","b":[["34944.43","0.171708"],["34943.15","0"]],"a":[["34981.66","0.171527"],["34984.95","0"]],"u":20009914,"seq":14108034731}}'
2023-11-02 14:54:14,449 DEBUG ++Rcv raw: b'\x81~\x00\xac{"topic":"orderbook.50.BTCUSDC","ts":1698936854364,"type":"delta","data":{"s":"BTCUSDC","b":[["34943.15","0.20658"],["34961.6","0"]],"a":[],"u":20009915,"seq":14108034744}}'
2023-11-02 14:54:14,449 DEBUG ++Rcv decoded: fin=1 opcode=1 data=b'{"topic":"orderbook.50.BTCUSDC","ts":1698936854364,"type":"delta","data":{"s":"BTCUSDC","b":[["34943.15","0.20658"],["34961.6","0"]],"a":[],"u":20009915,"seq":14108034744}}'
2023-11-02 14:54:14,489 DEBUG ++Rcv raw: b'\x81~\x00\xae{"topic":"orderbook.50.BTCUSDC","ts":1698936854404,"type":"delta","data":{"s":"BTCUSDC","b":[],"a":[["34965.35","0.008756"],["34966.47","0"]],"u":20009916,"seq":14108034761}}'
2023-11-02 14:54:14,489 DEBUG ++Rcv decoded: fin=1 opcode=1 data=b'{"topic":"orderbook.50.BTCUSDC","ts":1698936854404,"type":"delta","data":{"s":"BTCUSDC","b":[],"a":[["34965.35","0.008756"],["34966.47","0"]],"u":20009916,"seq":14108034761}}'
2023-11-02 14:54:14,509 DEBUG ++Rcv raw: b'\x81~\x00\xac{"topic":"orderbook.50.BTCUSDC","ts":1698936854423,"type":"delta","data":{"s":"BTCUSDC","b":[],"a":[["34984.95","0.0002"],["34965.36","0"]],"u":20009917,"seq":14108034772}}'
2023-11-02 14:54:14,509 DEBUG ++Rcv decoded: fin=1 opcode=1 data=b'{"topic":"orderbook.50.BTCUSDC","ts":1698936854423,"type":"delta","data":{"s":"BTCUSDC","b":[],"a":[["34984.95","0.0002"],["34965.36","0"]],"u":20009917,"seq":14108034772}}'
2023-11-02 14:54:14,549 DEBUG ++Rcv raw: b'\x81~\x00\xad{"topic":"orderbook.50.BTCUSDC","ts":1698936854463,"type":"delta","data":{"s":"BTCUSDC","b":[["34961.86","0.00572"],["34961.85","0"]],"a":[],"u":20009918,"seq":14108034789}}'
2023-11-02 14:54:14,549 DEBUG ++Rcv decoded: fin=1 opcode=1 data=b'{"topic":"orderbook.50.BTCUSDC","ts":1698936854463,"type":"delta","data":{"s":"BTCUSDC","b":[["34961.86","0.00572"],["34961.85","0"]],"a":[],"u":20009918,"seq":14108034789}}'
2023-11-02 14:54:14,569 DEBUG ++Rcv raw: b'\x81~\x00\xff{"topic":"orderbook.50.BTCUSDC","ts":1698936854483,"type":"delta","data":{"s":"BTCUSDC","b":[["34960.01","0.070984"],["34957.23","0.021601"],["34942.2","0.043599"],["34959.09","0"],["34958.15","0"],["34961.59","0"]],"a":[],"u":20009919,"seq":14108034795}}'
2023-11-02 14:54:14,569 DEBUG ++Rcv decoded: fin=1 opcode=1 data=b'{"topic":"orderbook.50.BTCUSDC","ts":1698936854483,"type":"delta","data":{"s":"BTCUSDC","b":[["34960.01","0.070984"],["34957.23","0.021601"],["34942.2","0.043599"],["34959.09","0"],["34958.15","0"],["34961.59","0"]],"a":[],"u":20009919,"seq":14108034795}}'
2023-11-02 14:54:14,609 DEBUG ++Rcv raw: b'\x81~\x00\xd5{"topic":"orderbook.50.BTCUSDC","ts":1698936854524,"type":"delta","data":{"s":"BTCUSDC","b":[],"a":[["34967.25","0.000239"],["34968.46","0.0859"],["34984.95","0"],["34984.83","0"]],"u":20009920,"seq":14108034813}}'
2023-11-02 14:54:14,609 DEBUG ++Rcv decoded: fin=1 opcode=1 data=b'{"topic":"orderbook.50.BTCUSDC","ts":1698936854524,"type":"delta","data":{"s":"BTCUSDC","b":[],"a":[["34967.25","0.000239"],["34968.46","0.0859"],["34984.95","0"],["34984.83","0"]],"u":20009920,"seq":14108034813}}'
2023-11-02 14:54:14,629 DEBUG ++Rcv raw: b'\x81~\x00\xae{"topic":"orderbook.50.BTCUSDC","ts":1698936854544,"type":"delta","data":{"s":"BTCUSDC","b":[],"a":[["34967.99","0.070982"],["34969.97","0"]],"u":20009921,"seq":14108034816}}'
2023-11-02 14:54:14,629 DEBUG ++Rcv decoded: fin=1 opcode=1 data=b'{"topic":"orderbook.50.BTCUSDC","ts":1698936854544,"type":"delta","data":{"s":"BTCUSDC","b":[],"a":[["34967.99","0.070982"],["34969.97","0"]],"u":20009921,"seq":14108034816}}'
2023-11-02 14:54:14,650 DEBUG ++Rcv raw: b'\x81~\x00\xd2{"topic":"orderbook.50.BTCUSDC","ts":1698936854564,"type":"delta","data":{"s":"BTCUSDC","b":[["34954.09","0.014061"],["34942","0.0341"],["34961.86","0"],["34958.17","0"]],"a":[],"u":20009922,"seq":14108034831}}'
2023-11-02 14:54:14,650 DEBUG ++Rcv decoded: fin=1 opcode=1 data=b'{"topic":"orderbook.50.BTCUSDC","ts":1698936854564,"type":"delta","data":{"s":"BTCUSDC","b":[["34954.09","0.014061"],["34942","0.0341"],["34961.86","0"],["34958.17","0"]],"a":[],"u":20009922,"seq":14108034831}}'
2023-11-02 14:54:14,669 DEBUG ++Rcv raw: b'\x81~\x00\x9b{"topic":"orderbook.50.BTCUSDC","ts":1698936854583,"type":"delta","data":{"s":"BTCUSDC","b":[["34961.58","0.0889"]],"a":[],"u":20009923,"seq":14108034839}}'
2023-11-02 14:54:14,669 DEBUG ++Rcv decoded: fin=1 opcode=1 data=b'{"topic":"orderbook.50.BTCUSDC","ts":1698936854583,"type":"delta","data":{"s":"BTCUSDC","b":[["34961.58","0.0889"]],"a":[],"u":20009923,"seq":14108034839}}'
2023-11-02 14:54:14,749 DEBUG ++Rcv raw: b'\x81~\x00\xac{"topic":"orderbook.50.BTCUSDC","ts":1698936854664,"type":"delta","data":{"s":"BTCUSDC","b":[],"a":[["34984.83","0.0002"],["34965.35","0"]],"u":20009924,"seq":14108034871}}'
2023-11-02 14:54:14,749 DEBUG ++Rcv decoded: fin=1 opcode=1 data=b'{"topic":"orderbook.50.BTCUSDC","ts":1698936854664,"type":"delta","data":{"s":"BTCUSDC","b":[],"a":[["34984.83","0.0002"],["34965.35","0"]],"u":20009924,"seq":14108034871}}'
2023-11-02 14:54:14,769 DEBUG ++Rcv raw: b'\x81~\x00\xeb{"topic":"orderbook.50.BTCUSDC","ts":1698936854684,"type":"delta","data":{"s":"BTCUSDC","b":[["34961.58","0.003"]],"a":[["34963.89","0.099178"],["34966.47","0.008756"],["34984.83","0"],["34983.74","0"]],"u":20009925,"seq":14108034892}}'
2023-11-02 14:54:14,769 DEBUG ++Rcv decoded: fin=1 opcode=1 data=b'{"topic":"orderbook.50.BTCUSDC","ts":1698936854684,"type":"delta","data":{"s":"BTCUSDC","b":[["34961.58","0.003"]],"a":[["34963.89","0.099178"],["34966.47","0.008756"],["34984.83","0"],["34983.74","0"]],"u":20009925,"seq":14108034892}}'
2023-11-02 14:54:14,789 DEBUG ++Rcv raw: b'\x81~\x01p{"topic":"orderbook.50.BTCUSDC","ts":1698936854704,"type":"delta","data":{"s":"BTCUSDC","b":[["34941.44","0.025298"],["34940.99","0.126463"],["34940.87","0.00154"],["34940.24","0.05724"],["34939.85","0.1875"],["34961.58","0"],["34956.7","0"],["34956.43","0"],["34960","0"],["34960.01","0"]],"a":[["34983.74","0.1875"],["34972.07","0"]],"u":20009926,"seq":14108034936}}'
2023-11-02 14:54:14,789 DEBUG ++Rcv decoded: fin=1 opcode=1 data=b'{"topic":"orderbook.50.BTCUSDC","ts":1698936854704,"type":"delta","data":{"s":"BTCUSDC","b":[["34941.44","0.025298"],["34940.99","0.126463"],["34940.87","0.00154"],["34940.24","0.05724"],["34939.85","0.1875"],["34961.58","0"],["34956.7","0"],["34956.43","0"],["34960","0"],["34960.01","0"]],"a":[["34983.74","0.1875"],["34972.07","0"]],"u":20009926,"seq":14108034936}}'
2023-11-02 14:54:14,809 DEBUG ++Rcv raw: b'\x81~\x01\x91{"topic":"orderbook.50.BTCUSDC","ts":1698936854723,"type":"delta","data":{"s":"BTCUSDC","b":[["34959.09","0.034328"],["34956.43","0.051544"],["34954.97","0.00057"],["34940.24","0"],["34939.85","0"],["34940.87","0"]],"a":[["34963.88","0.008756"],["34966.47","0.034323"],["34967.15","0.000239"],["34969.97","0.051546"],["34967.99","0"],["34963.89","0"],["34983.74","0"]],"u":20009927,"seq":14108034975}}'
2023-11-02 14:54:14,809 DEBUG ++Rcv decoded: fin=1 opcode=1 data=b'{"topic":"orderbook.50.BTCUSDC","ts":1698936854723,"type":"delta","data":{"s":"BTCUSDC","b":[["34959.09","0.034328"],["34956.43","0.051544"],["34954.97","0.00057"],["34940.24","0"],["34939.85","0"],["34940.87","0"]],"a":[["34963.88","0.008756"],["34966.47","0.034323"],["34967.15","0.000239"],["34969.97","0.051546"],["34967.99","0"],["34963.89","0"],["34983.74","0"]],"u":20009927,"seq":14108034975}}'
2023-11-02 14:54:14,829 DEBUG ++Rcv raw: b'\x81~\x01\xfb{"topic":"orderbook.50.BTCUSDC","ts":1698936854743,"type":"delta","data":{"s":"BTCUSDC","b":[["34959.09","0.02235"],["34940.87","0.00154"],["34940.24","0.05724"],["34949.26","0"],["34959.86","0"]],"a":[["34961.93","0.003"],["34965.34","0.01147"],["34966","0.0324"],["34966.46","0.054919"],["34966.74","0.0859"],["34967.99","0.051548"],["34970.26","0.001"],["34981.9","0"],["34982.22","0"],["34982.24","0"],["34981.67","0"],["34981.66","0"],["34969.97","0"],["34966.47","0"]],"u":20009928,"seq":14108035029}}'
2023-11-02 14:54:14,829 DEBUG ++Rcv decoded: fin=1 opcode=1 data=b'{"topic":"orderbook.50.BTCUSDC","ts":1698936854743,"type":"delta","data":{"s":"BTCUSDC","b":[["34959.09","0.02235"],["34940.87","0.00154"],["34940.24","0.05724"],["34949.26","0"],["34959.86","0"]],"a":[["34961.93","0.003"],["34965.34","0.01147"],["34966","0.0324"],["34966.46","0.054919"],["34966.74","0.0859"],["34967.99","0.051548"],["34970.26","0.001"],["34981.9","0"],["34982.22","0"],["34982.24","0"],["34981.67","0"],["34981.66","0"],["34969.97","0"],["34966.47","0"]],"u":20009928,"seq":14108035029}}'
2023-11-02 14:54:14,849 DEBUG ++Rcv raw: b'\x81~\x01f{"topic":"orderbook.50.BTCUSDC","ts":1698936854763,"type":"delta","data":{"s":"BTCUSDC","b":[["34958.15","0.05154"],["34957.85","0.02246"],["34954.1","0.001463"],["34940.24","0"],["34957.23","0"],["34940.87","0"]],"a":[["34966.47","0.085859"],["34966.48","0.080394"],["34969.97","0.051542"],["34966.46","0"],["34967.99","0"]],"u":20009929,"seq":14108035062}}'
2023-11-02 14:54:14,849 DEBUG ++Rcv decoded: fin=1 opcode=1 data=b'{"topic":"orderbook.50.BTCUSDC","ts":1698936854763,"type":"delta","data":{"s":"BTCUSDC","b":[["34958.15","0.05154"],["34957.85","0.02246"],["34954.1","0.001463"],["34940.24","0"],["34957.23","0"],["34940.87","0"]],"a":[["34966.47","0.085859"],["34966.48","0.080394"],["34969.97","0.051542"],["34966.46","0"],["34967.99","0"]],"u":20009929,"seq":14108035062}}'
2023-11-02 14:54:14,869 DEBUG ++Rcv raw: b'\x81~\x00\xac{"topic":"orderbook.50.BTCUSDC","ts":1698936854783,"type":"delta","data":{"s":"BTCUSDC","b":[["34949.26","0.1875"],["34954.02","0"]],"a":[],"u":20009930,"seq":14108035099}}'
2023-11-02 14:54:14,869 DEBUG ++Rcv decoded: fin=1 opcode=1 data=b'{"topic":"orderbook.50.BTCUSDC","ts":1698936854783,"type":"delta","data":{"s":"BTCUSDC","b":[["34949.26","0.1875"],["34954.02","0"]],"a":[],"u":20009930,"seq":14108035099}}'
2023-11-02 14:54:14,889 DEBUG ++Rcv raw: b'\x81~\x00\xc6{"topic":"orderbook.50.BTCUSDC","ts":1698936854803,"type":"delta","data":{"s":"BTCUSDC","b":[],"a":[["34966.06","0.057198"],["34966.48","0.023197"],["34981.28","0"]],"u":20009931,"seq":14108035136}}'
2023-11-02 14:54:14,889 DEBUG ++Rcv decoded: fin=1 opcode=1 data=b'{"topic":"orderbook.50.BTCUSDC","ts":1698936854803,"type":"delta","data":{"s":"BTCUSDC","b":[],"a":[["34966.06","0.057198"],["34966.48","0.023197"],["34981.28","0"]],"u":20009931,"seq":14108035136}}'
2023-11-02 14:54:14,909 DEBUG ++Rcv raw: b'\x81~\x00\xfd{"topic":"orderbook.50.BTCUSDC","ts":1698936854823,"type":"delta","data":{"s":"BTCUSDC","b":[["34959.86","0.0859"],["34940.99","0"]],"a":[["34981.28","0.000562"],["34981.66","0.171527"],["34966.74","0"],["34965.34","0"]],"u":20009932,"seq":14108035161}}'
2023-11-02 14:54:14,909 DEBUG ++Rcv decoded: fin=1 opcode=1 data=b'{"topic":"orderbook.50.BTCUSDC","ts":1698936854823,"type":"delta","data":{"s":"BTCUSDC","b":[["34959.86","0.0859"],["34940.99","0"]],"a":[["34981.28","0.000562"],["34981.66","0.171527"],["34966.74","0"],["34965.34","0"]],"u":20009932,"seq":14108035161}}'
2023-11-02 14:54:14,929 DEBUG ++Rcv raw: b'\x81~\x01P{"topic":"orderbook.50.BTCUSDC","ts":1698936854844,"type":"delta","data":{"s":"BTCUSDC","b":[["34957.23","0.021603"],["34940.99","0.126463"],["34940.87","0.00154"],["34954.97","0"],["34949.26","0"],["34958.15","0"]],"a":[["34965.99","0.067681"],["34967.99","0.051545"],["34966.47","0"],["34969.97","0"]],"u":20009933,"seq":14108035178}}'
2023-11-02 14:54:14,930 DEBUG ++Rcv decoded: fin=1 opcode=1 data=b'{"topic":"orderbook.50.BTCUSDC","ts":1698936854844,"type":"delta","data":{"s":"BTCUSDC","b":[["34957.23","0.021603"],["34940.99","0.126463"],["34940.87","0.00154"],["34954.97","0"],["34949.26","0"],["34958.15","0"]],"a":[["34965.99","0.067681"],["34967.99","0.051545"],["34966.47","0"],["34969.97","0"]],"u":20009933,"seq":14108035178}}'
2023-11-02 14:54:14,948 DEBUG ++Rcv raw: b'\x81~\x01#{"topic":"orderbook.50.BTCUSDC","ts":1698936854863,"type":"delta","data":{"s":"BTCUSDC","b":[["34940.24","0.05724"],["34939.85","0.1875"],["34939.34","0.000261"],["34944.42","0"],["34959.08","0"],["34953.56","0"]],"a":[["34966.74","0.0859"],["34981.66","0"]],"u":20009934,"seq":14108035215}}'
2023-11-02 14:54:14,949 DEBUG ++Rcv decoded: fin=1 opcode=1 data=b'{"topic":"orderbook.50.BTCUSDC","ts":1698936854863,"type":"delta","data":{"s":"BTCUSDC","b":[["34940.24","0.05724"],["34939.85","0.1875"],["34939.34","0.000261"],["34944.42","0"],["34959.08","0"],["34953.56","0"]],"a":[["34966.74","0.0859"],["34981.66","0"]],"u":20009934,"seq":14108035215}}'
2023-11-02 14:54:14,969 DEBUG ++Rcv raw: b'\x81~\x01\x8f{"topic":"orderbook.50.BTCUSDC","ts":1698936854884,"type":"delta","data":{"s":"BTCUSDC","b":[["34959.87","0.038227"],["34958.54","0.05721"],["34954.71","0.051547"],["34952.44","0.114441"],["34949.36","0.1875"],["34943.36","0.314177"],["34939.34","0"],["34959.86","0"],["34944.43","0"],["34954.01","0"],["34959.09","0"]],"a":[["34969.97","0.051548"],["34967.99","0"]],"u":20009935,"seq":14108035245}}'
2023-11-02 14:54:14,969 DEBUG ++Rcv decoded: fin=1 opcode=1 data=b'{"topic":"orderbook.50.BTCUSDC","ts":1698936854884,"type":"delta","data":{"s":"BTCUSDC","b":[["34959.87","0.038227"],["34958.54","0.05721"],["34954.71","0.051547"],["34952.44","0.114441"],["34949.36","0.1875"],["34943.36","0.314177"],["34939.34","0"],["34959.86","0"],["34944.43","0"],["34954.01","0"],["34959.09","0"]],"a":[["34969.97","0.051548"],["34967.99","0"]],"u":20009935,"seq":14108035245}}'
2023-11-02 14:54:14,989 DEBUG ++Rcv raw: b'\x81~\x00\xd6{"topic":"orderbook.50.BTCUSDC","ts":1698936854904,"type":"delta","data":{"s":"BTCUSDC","b":[["34958.55","0.034335"],["34958.15","0.05154"],["34959.87","0"],["34957.23","0"]],"a":[],"u":20009936,"seq":14108035253}}'
2023-11-02 14:54:14,991 DEBUG ++Rcv decoded: fin=1 opcode=1 data=b'{"topic":"orderbook.50.BTCUSDC","ts":1698936854904,"type":"delta","data":{"s":"BTCUSDC","b":[["34958.55","0.034335"],["34958.15","0.05154"],["34959.87","0"],["34957.23","0"]],"a":[],"u":20009936,"seq":14108035253}}'
2023-11-02 14:54:15,016 DEBUG ++Rcv raw: b'\x81~\x00\xf9{"topic":"orderbook.50.BTCUSDC","ts":1698936854930,"type":"delta","data":{"s":"BTCUSDC","b":[["34953.66","0.00057"],["34939.85","0"]],"a":[["34961.92","0.01147"],["34967.78","0.03"],["34970.76","0"],["34981.28","0"]],"u":20009937,"seq":14108035273}}'
2023-11-02 14:54:15,016 DEBUG ++Rcv decoded: fin=1 opcode=1 data=b'{"topic":"orderbook.50.BTCUSDC","ts":1698936854930,"type":"delta","data":{"s":"BTCUSDC","b":[["34953.66","0.00057"],["34939.85","0"]],"a":[["34961.92","0.01147"],["34967.78","0.03"],["34970.76","0"],["34981.28","0"]],"u":20009937,"seq":14108035273}}'
2023-11-02 14:54:15,029 DEBUG ++Rcv raw: b'\x81~\x00\xd7{"topic":"orderbook.50.BTCUSDC","ts":1698936854944,"type":"delta","data":{"s":"BTCUSDC","b":[],"a":[["34981.28","0.000562"],["34981.66","0.171527"],["34966.06","0"],["34971.89","0"]],"u":20009938,"seq":14108035290}}'
2023-11-02 14:54:15,030 DEBUG ++Rcv decoded: fin=1 opcode=1 data=b'{"topic":"orderbook.50.BTCUSDC","ts":1698936854944,"type":"delta","data":{"s":"BTCUSDC","b":[],"a":[["34981.28","0.000562"],["34981.66","0.171527"],["34966.06","0"],["34971.89","0"]],"u":20009938,"seq":14108035290}}'
2023-11-02 14:54:15,050 DEBUG ++Rcv raw: b'\x81~\x00\xee{"topic":"orderbook.50.BTCUSDC","ts":1698936854965,"type":"delta","data":{"s":"BTCUSDC","b":[["34943.36","0.286177"]],"a":[["34965.63","0.057199"],["34966.47","0.065459"],["34965.99","0"],["34967.25","0"]],"u":20009939,"seq":14108035303}}'
2023-11-02 14:54:15,050 DEBUG ++Rcv decoded: fin=1 opcode=1 data=b'{"topic":"orderbook.50.BTCUSDC","ts":1698936854965,"type":"delta","data":{"s":"BTCUSDC","b":[["34943.36","0.286177"]],"a":[["34965.63","0.057199"],["34966.47","0.065459"],["34965.99","0"],["34967.25","0"]],"u":20009939,"seq":14108035303}}'
2023-11-02 14:54:15,069 DEBUG ++Rcv raw: b'\x81~\x00\xac{"topic":"orderbook.50.BTCUSDC","ts":1698936854983,"type":"delta","data":{"s":"BTCUSDC","b":[],"a":[["34968.92","0.1875"],["34981.66","0"]],"u":20009940,"seq":14108035323}}'
2023-11-02 14:54:15,069 DEBUG ++Rcv decoded: fin=1 opcode=1 data=b'{"topic":"orderbook.50.BTCUSDC","ts":1698936854983,"type":"delta","data":{"s":"BTCUSDC","b":[],"a":[["34968.92","0.1875"],["34981.66","0"]],"u":20009940,"seq":14108035323}}'
2023-11-02 14:54:15,089 DEBUG ++Rcv raw: b'\x81~\x00\xee{"topic":"orderbook.50.BTCUSDC","ts":1698936855003,"type":"delta","data":{"s":"BTCUSDC","b":[["34959.76","0.091148"]],"a":[["34968.91","0.112502"],["34971.89","0.051543"],["34981.28","0"],["34969.97","0"]],"u":20009941,"seq":14108035336}}'
2023-11-02 14:54:15,089 DEBUG ++Rcv decoded: fin=1 opcode=1 data=b'{"topic":"orderbook.50.BTCUSDC","ts":1698936855003,"type":"delta","data":{"s":"BTCUSDC","b":[["34959.76","0.091148"]],"a":[["34968.91","0.112502"],["34971.89","0.051543"],["34981.28","0"],["34969.97","0"]],"u":20009941,"seq":14108035336}}'
2023-11-02 14:54:15,109 DEBUG ++Rcv raw: b'\x81~\x01O{"topic":"orderbook.50.BTCUSDC","ts":1698936855023,"type":"delta","data":{"s":"BTCUSDC","b":[["34957.23","0.021604"],["34939.85","0.1875"],["34958.15","0"],["34949.36","0"]],"a":[["34981.28","0.000562"],["34981.66","0.171527"],["34981.67","0.285864"],["34961.92","0"],["34968.92","0"],["34963.88","0"]],"u":20009942,"seq":14108035353}}'
2023-11-02 14:54:15,109 DEBUG ++Rcv decoded: fin=1 opcode=1 data=b'{"topic":"orderbook.50.BTCUSDC","ts":1698936855023,"type":"delta","data":{"s":"BTCUSDC","b":[["34957.23","0.021604"],["34939.85","0.1875"],["34958.15","0"],["34949.36","0"]],"a":[["34981.28","0.000562"],["34981.66","0.171527"],["34981.67","0.285864"],["34961.92","0"],["34968.92","0"],["34963.88","0"]],"u":20009942,"seq":14108035353}}'
2023-11-02 14:54:15,129 DEBUG ++Rcv raw: b'\x81~\x00\xfb{"topic":"orderbook.50.BTCUSDC","ts":1698936855043,"type":"delta","data":{"s":"BTCUSDC","b":[["34953","0.001573"],["34953.66","0"]],"a":[["34969.97","0.051545"],["34981.9","0.114401"],["34968.91","0"],["34971.89","0"]],"u":20009943,"seq":14108035369}}'
2023-11-02 14:54:15,129 DEBUG ++Rcv decoded: fin=1 opcode=1 data=b'{"topic":"orderbook.50.BTCUSDC","ts":1698936855043,"type":"delta","data":{"s":"BTCUSDC","b":[["34953","0.001573"],["34953.66","0"]],"a":[["34969.97","0.051545"],["34981.9","0.114401"],["34968.91","0"],["34971.89","0"]],"u":20009943,"seq":14108035369}}'
2023-11-02 14:54:15,149 DEBUG ++Rcv raw: b'\x81~\x00\xfc{"topic":"orderbook.50.BTCUSDC","ts":1698936855063,"type":"delta","data":{"s":"BTCUSDC","b":[["34939.34","0.000261"],["34937.76","0.029857"],["34954.1","0"],["34958.54","0"]],"a":[["34982.22","0.0859"],["34965.63","0"]],"u":20009944,"seq":14108035379}}'
2023-11-02 14:54:15,149 DEBUG ++Rcv decoded: fin=1 opcode=1 data=b'{"topic":"orderbook.50.BTCUSDC","ts":1698936855063,"type":"delta","data":{"s":"BTCUSDC","b":[["34939.34","0.000261"],["34937.76","0.029857"],["34954.1","0"],["34958.54","0"]],"a":[["34982.22","0.0859"],["34965.63","0"]],"u":20009944,"seq":14108035379}}'
2023-11-02 14:54:15,168 DEBUG ++Rcv raw: b'\x81~\x01({"topic":"orderbook.50.BTCUSDC","ts":1698936855083,"type":"delta","data":{"s":"BTCUSDC","b":[["34959.06","0.057209"],["34958.15","0.084462"],["34937.39","0.278379"],["34958.55","0"],["34957.23","0"],["34956.43","0"]],"a":[["34966.17","0.057198"],["34973.97","0"]],"u":20009945,"seq":14108035393}}'
2023-11-02 14:54:15,168 DEBUG ++Rcv decoded: fin=1 opcode=1 data=b'{"topic":"orderbook.50.BTCUSDC","ts":1698936855083,"type":"delta","data":{"s":"BTCUSDC","b":[["34959.06","0.057209"],["34958.15","0.084462"],["34937.39","0.278379"],["34958.55","0"],["34957.23","0"],["34956.43","0"]],"a":[["34966.17","0.057198"],["34973.97","0"]],"u":20009945,"seq":14108035393}}'
2023-11-02 14:54:15,188 DEBUG ++Rcv raw: b'\x81~\x00\xd6{"topic":"orderbook.50.BTCUSDC","ts":1698936855103,"type":"delta","data":{"s":"BTCUSDC","b":[],"a":[["34961.91","0.01147"],["34966.16","0.099784"],["34966.47","0"],["34973.61","0"]],"u":20009946,"seq":14108035405}}'
2023-11-02 14:54:15,189 DEBUG ++Rcv decoded: fin=1 opcode=1 data=b'{"topic":"orderbook.50.BTCUSDC","ts":1698936855103,"type":"delta","data":{"s":"BTCUSDC","b":[],"a":[["34961.91","0.01147"],["34966.16","0.099784"],["34966.47","0"],["34973.61","0"]],"u":20009946,"seq":14108035405}}'
2023-11-02 14:54:15,209 DEBUG ++Rcv raw: b'\x81~\x00\xd3{"topic":"orderbook.50.BTCUSDC","ts":1698936855123,"type":"delta","data":{"s":"BTCUSDC","b":[["34949.26","0.1875"],["34957.85","0"]],"a":[["34968.52","0.04407"],["34982.22","0"]],"u":20009947,"seq":14108035416}}'
2023-11-02 14:54:15,209 DEBUG ++Rcv decoded: fin=1 opcode=1 data=b'{"topic":"orderbook.50.BTCUSDC","ts":1698936855123,"type":"delta","data":{"s":"BTCUSDC","b":[["34949.26","0.1875"],["34957.85","0"]],"a":[["34968.52","0.04407"],["34982.22","0"]],"u":20009947,"seq":14108035416}}'
2023-11-02 14:54:15,228 DEBUG ++Rcv raw: b'\x81~\x00\xac{"topic":"orderbook.50.BTCUSDC","ts":1698936855143,"type":"delta","data":{"s":"BTCUSDC","b":[],"a":[["34967.99","0.02645"],["34981.9","0"]],"u":20009948,"seq":14108035419}}'
2023-11-02 14:54:15,228 DEBUG ++Rcv decoded: fin=1 opcode=1 data=b'{"topic":"orderbook.50.BTCUSDC","ts":1698936855143,"type":"delta","data":{"s":"BTCUSDC","b":[],"a":[["34967.99","0.02645"],["34981.9","0"]],"u":20009948,"seq":14108035419}}'
2023-11-02 14:54:15,249 DEBUG ++Rcv raw: b'\x81~\x01r{"topic":"orderbook.50.BTCUSDC","ts":1698936855164,"type":"delta","data":{"s":"BTCUSDC","b":[["34959.07","0.034334"],["34957.23","0.0216"],["34956.43","0.051541"],["34944.19","0.028"],["34959.06","0"],["34937.39","0"],["34958.15","0"],["34937.76","0"]],"a":[["34981.9","0.114401"],["34982.22","0.0859"],["34981.67","0"],["34966.17","0"]],"u":20009949,"seq":14108035452}}'
2023-11-02 14:54:15,249 DEBUG ++Rcv decoded: fin=1 opcode=1 data=b'{"topic":"orderbook.50.BTCUSDC","ts":1698936855164,"type":"delta","data":{"s":"BTCUSDC","b":[["34959.07","0.034334"],["34957.23","0.0216"],["34956.43","0.051541"],["34944.19","0.028"],["34959.06","0"],["34937.39","0"],["34958.15","0"],["34937.76","0"]],"a":[["34981.9","0.114401"],["34982.22","0.0859"],["34981.67","0"],["34966.17","0"]],"u":20009949,"seq":14108035452}}'
2023-11-02 14:54:15,268 DEBUG ++Rcv raw: b'\x81~\x01\xb4{"topic":"orderbook.50.BTCUSDC","ts":1698936855183,"type":"delta","data":{"s":"BTCUSDC","b":[["34958.33","0.05721"],["34958.15","0.070982"],["34937.76","0.029857"],["34957.23","0"],["34956.43","0"],["34959.07","0"]],"a":[["34964","0.0324"],["34965.43","0.057199"],["34966.16","0.065461"],["34978.24","1.372943"],["34980.62","0.285872"],["34981.28","0"],["34982.22","0"],["34981.66","0"],["34981.9","0"]],"u":20009950,"seq":14108035476}}'
2023-11-02 14:54:15,268 DEBUG ++Rcv decoded: fin=1 opcode=1 data=b'{"topic":"orderbook.50.BTCUSDC","ts":1698936855183,"type":"delta","data":{"s":"BTCUSDC","b":[["34958.33","0.05721"],["34958.15","0.070982"],["34937.76","0.029857"],["34957.23","0"],["34956.43","0"],["34959.07","0"]],"a":[["34964","0.0324"],["34965.43","0.057199"],["34966.16","0.065461"],["34978.24","1.372943"],["34980.62","0.285872"],["34981.28","0"],["34982.22","0"],["34981.66","0"],["34981.9","0"]],"u":20009950,"seq":14108035476}}'
2023-11-02 14:54:15,288 DEBUG ++Rcv raw: b'\x81~\x01%{"topic":"orderbook.50.BTCUSDC","ts":1698936855203,"type":"delta","data":{"s":"BTCUSDC","b":[["34937.39","0.278379"],["34949.26","0"]],"a":[["34981.28","0.000562"],["34981.9","0.114401"],["34982.22","0.0859"],["34978.77","0"],["34961.91","0"],["34967.15","0"]],"u":20009951,"seq":14108035499}}'
2023-11-02 14:54:15,288 DEBUG ++Rcv decoded: fin=1 opcode=1 data=b'{"topic":"orderbook.50.BTCUSDC","ts":1698936855203,"type":"delta","data":{"s":"BTCUSDC","b":[["34937.39","0.278379"],["34949.26","0"]],"a":[["34981.28","0.000562"],["34981.9","0.114401"],["34982.22","0.0859"],["34978.77","0"],["34961.91","0"],["34967.15","0"]],"u":20009951,"seq":14108035499}}'
2023-11-02 14:54:15,308 DEBUG ++Rcv raw: b'\x81~\x00\xae{"topic":"orderbook.50.BTCUSDC","ts":1698936855223,"type":"delta","data":{"s":"BTCUSDC","b":[],"a":[["34977.69","0.029857"],["34982.22","0"]],"u":20009952,"seq":14108035507}}'
2023-11-02 14:54:15,309 DEBUG ++Rcv decoded: fin=1 opcode=1 data=b'{"topic":"orderbook.50.BTCUSDC","ts":1698936855223,"type":"delta","data":{"s":"BTCUSDC","b":[],"a":[["34977.69","0.029857"],["34982.22","0"]],"u":20009952,"seq":14108035507}}'
2023-11-02 14:54:15,329 DEBUG ++Rcv raw: b'\x81~\x00\xae{"topic":"orderbook.50.BTCUSDC","ts":1698936855244,"type":"delta","data":{"s":"BTCUSDC","b":[["34952.45","0.001775"],["34937.39","0"]],"a":[],"u":20009953,"seq":14108035519}}'
2023-11-02 14:54:15,329 DEBUG ++Rcv decoded: fin=1 opcode=1 data=b'{"topic":"orderbook.50.BTCUSDC","ts":1698936855244,"type":"delta","data":{"s":"BTCUSDC","b":[["34952.45","0.001775"],["34937.39","0"]],"a":[],"u":20009953,"seq":14108035519}}'
2023-11-02 14:54:15,349 DEBUG ++Rcv raw: b'\x81~\x019{"topic":"orderbook.50.BTCUSDC","ts":1698936855264,"type":"delta","data":{"s":"BTCUSDC","b":[["34959.76","0.000008"],["34937.39","0.278379"],["34936.51","0.823863"],["34953","0"],["34958.33","0"]],"a":[["34968.93","0.1875"],["34982.22","0.0859"],["34972.44","0"],["34965.43","0"]],"u":20009954,"seq":14108035534}}'
2023-11-02 14:54:15,349 DEBUG ++Rcv decoded: fin=1 opcode=1 data=b'{"topic":"orderbook.50.BTCUSDC","ts":1698936855264,"type":"delta","data":{"s":"BTCUSDC","b":[["34959.76","0.000008"],["34937.39","0.278379"],["34936.51","0.823863"],["34953","0"],["34958.33","0"]],"a":[["34968.93","0.1875"],["34982.22","0.0859"],["34972.44","0"],["34965.43","0"]],"u":20009954,"seq":14108035534}}'
2023-11-02 14:54:15,369 DEBUG ++Rcv raw: b'\x81~\x01u{"topic":"orderbook.50.BTCUSDC","ts":1698936855283,"type":"delta","data":{"s":"BTCUSDC","b":[["34957.8","0.057211"],["34953.26","0.00057"],["34937.39","0"],["34936.51","0"]],"a":[["34964.95","0.0572"],["34968.92","0.112504"],["34971.48","0.114378"],["34971.89","0.051545"],["34981.28","0"],["34969.97","0"],["34982.22","0"],["34981.9","0"]],"u":20009955,"seq":14108035552}}'
2023-11-02 14:54:15,369 DEBUG ++Rcv decoded: fin=1 opcode=1 data=b'{"topic":"orderbook.50.BTCUSDC","ts":1698936855283,"type":"delta","data":{"s":"BTCUSDC","b":[["34957.8","0.057211"],["34953.26","0.00057"],["34937.39","0"],["34936.51","0"]],"a":[["34964.95","0.0572"],["34968.92","0.112504"],["34971.48","0.114378"],["34971.89","0.051545"],["34981.28","0"],["34969.97","0"],["34982.22","0"],["34981.9","0"]],"u":20009955,"seq":14108035552}}'
2023-11-02 14:54:15,389 DEBUG ++Rcv raw: b'\x81~\x00\xae{"topic":"orderbook.50.BTCUSDC","ts":1698936855304,"type":"delta","data":{"s":"BTCUSDC","b":[],"a":[["34971.47","0.068632"],["34971.89","0"]],"u":20009956,"seq":14108035562}}'
2023-11-02 14:54:15,389 DEBUG ++Rcv decoded: fin=1 opcode=1 data=b'{"topic":"orderbook.50.BTCUSDC","ts":1698936855304,"type":"delta","data":{"s":"BTCUSDC","b":[],"a":[["34971.47","0.068632"],["34971.89","0"]],"u":20009956,"seq":14108035562}}'
2023-11-02 14:54:15,430 DEBUG ++Rcv raw: b'\x81~\x00\xae{"topic":"orderbook.50.BTCUSDC","ts":1698936855344,"type":"delta","data":{"s":"BTCUSDC","b":[["34937.39","0.278379"],["34939.34","0"]],"a":[],"u":20009957,"seq":14108035581}}'
2023-11-02 14:54:15,430 DEBUG ++Rcv decoded: fin=1 opcode=1 data=b'{"topic":"orderbook.50.BTCUSDC","ts":1698936855344,"type":"delta","data":{"s":"BTCUSDC","b":[["34937.39","0.278379"],["34939.34","0"]],"a":[],"u":20009957,"seq":14108035581}}'
2023-11-02 14:54:15,449 DEBUG ++Rcv raw: b'\x81~\x00\xd6{"topic":"orderbook.50.BTCUSDC","ts":1698936855363,"type":"delta","data":{"s":"BTCUSDC","b":[["34943.76","0.171713"],["34937.39","0"]],"a":[["34978.23","0.823773"],["34980.62","0"]],"u":20009958,"seq":14108035593}}'
2023-11-02 14:54:15,449 DEBUG ++Rcv decoded: fin=1 opcode=1 data=b'{"topic":"orderbook.50.BTCUSDC","ts":1698936855363,"type":"delta","data":{"s":"BTCUSDC","b":[["34943.76","0.171713"],["34937.39","0"]],"a":[["34978.23","0.823773"],["34980.62","0"]],"u":20009958,"seq":14108035593}}'
2023-11-02 14:54:15,469 DEBUG ++Rcv raw: b'\x81~\x00\xac{"topic":"orderbook.50.BTCUSDC","ts":1698936855383,"type":"delta","data":{"s":"BTCUSDC","b":[],"a":[["34964.94","0.03432"],["34980.5","0"]],"u":20009959,"seq":14108035608}}'
2023-11-02 14:54:15,470 DEBUG ++Rcv decoded: fin=1 opcode=1 data=b'{"topic":"orderbook.50.BTCUSDC","ts":1698936855383,"type":"delta","data":{"s":"BTCUSDC","b":[],"a":[["34964.94","0.03432"],["34980.5","0"]],"u":20009959,"seq":14108035608}}'
2023-11-02 14:54:15,509 DEBUG ++Rcv raw: b'\x81~\x00\xac{"topic":"orderbook.50.BTCUSDC","ts":1698936855423,"type":"delta","data":{"s":"BTCUSDC","b":[],"a":[["34961.9","0.01147"],["34980.48","0"]],"u":20009960,"seq":14108035629}}'
2023-11-02 14:54:15,509 DEBUG ++Rcv decoded: fin=1 opcode=1 data=b'{"topic":"orderbook.50.BTCUSDC","ts":1698936855423,"type":"delta","data":{"s":"BTCUSDC","b":[],"a":[["34961.9","0.01147"],["34980.48","0"]],"u":20009960,"seq":14108035629}}'
2023-11-02 14:54:15,549 DEBUG ++Rcv raw: b'\x81~\x00\xfe{"topic":"orderbook.50.BTCUSDC","ts":1698936855463,"type":"delta","data":{"s":"BTCUSDC","b":[["34951.29","0.001971"],["34937.39","0.278379"],["34952.45","0"],["34957.8","0"]],"a":[["34980.48","0.023472"],["34964.95","0"]],"u":20009961,"seq":14108035642}}'
2023-11-02 14:54:15,549 DEBUG ++Rcv decoded: fin=1 opcode=1 data=b'{"topic":"orderbook.50.BTCUSDC","ts":1698936855463,"type":"delta","data":{"s":"BTCUSDC","b":[["34951.29","0.001971"],["34937.39","0.278379"],["34952.45","0"],["34957.8","0"]],"a":[["34980.48","0.023472"],["34964.95","0"]],"u":20009961,"seq":14108035642}}'
2023-11-02 14:54:15,569 DEBUG ++Rcv raw: b'\x81~\x00\xd5{"topic":"orderbook.50.BTCUSDC","ts":1698936855483,"type":"delta","data":{"s":"BTCUSDC","b":[["34958.39","0.05721"],["34937.39","0"]],"a":[["34965.53","0.057199"],["34964.94","0"]],"u":20009962,"seq":14108035648}}'
2023-11-02 14:54:15,569 DEBUG ++Rcv decoded: fin=1 opcode=1 data=b'{"topic":"orderbook.50.BTCUSDC","ts":1698936855483,"type":"delta","data":{"s":"BTCUSDC","b":[["34958.39","0.05721"],["34937.39","0"]],"a":[["34965.53","0.057199"],["34964.94","0"]],"u":20009962,"seq":14108035648}}'
2023-11-02 14:54:15,589 DEBUG ++Rcv raw: b'\x81~\x01\x16{"topic":"orderbook.50.BTCUSDC","ts":1698936855504,"type":"delta","data":{"s":"BTCUSDC","b":[["34958.4","0.034327"],["34958.15","0.051542"],["34956.43","0.051543"],["34939.85","0"],["34937.76","0"]],"a":[["34961.78","0.105729"],["34980.48","0"]],"u":20009963,"seq":14108035657}}'
2023-11-02 14:54:15,589 DEBUG ++Rcv decoded: fin=1 opcode=1 data=b'{"topic":"orderbook.50.BTCUSDC","ts":1698936855504,"type":"delta","data":{"s":"BTCUSDC","b":[["34958.4","0.034327"],["34958.15","0.051542"],["34956.43","0.051543"],["34939.85","0"],["34937.76","0"]],"a":[["34961.78","0.105729"],["34980.48","0"]],"u":20009963,"seq":14108035657}}'
2023-11-02 14:54:15,609 DEBUG ++Rcv raw: b'\x81~\x00\xad{"topic":"orderbook.50.BTCUSDC","ts":1698936855524,"type":"delta","data":{"s":"BTCUSDC","b":[],"a":[["34980.48","0.023472"],["34961.9","0"]],"u":20009964,"seq":14108035660}}'
2023-11-02 14:54:15,609 DEBUG ++Rcv decoded: fin=1 opcode=1 data=b'{"topic":"orderbook.50.BTCUSDC","ts":1698936855524,"type":"delta","data":{"s":"BTCUSDC","b":[],"a":[["34980.48","0.023472"],["34961.9","0"]],"u":20009964,"seq":14108035660}}'
2023-11-02 14:54:15,709 DEBUG ++Rcv raw: b'\x81~\x00\xad{"topic":"orderbook.50.BTCUSDC","ts":1698936855624,"type":"delta","data":{"s":"BTCUSDC","b":[],"a":[["34961.77","0.01147"],["34961.78","0"]],"u":20009965,"seq":14108035696}}'
2023-11-02 14:54:15,709 DEBUG ++Rcv decoded: fin=1 opcode=1 data=b'{"topic":"orderbook.50.BTCUSDC","ts":1698936855624,"type":"delta","data":{"s":"BTCUSDC","b":[],"a":[["34961.77","0.01147"],["34961.78","0"]],"u":20009965,"seq":14108035696}}'
2023-11-02 14:54:15,748 DEBUG ++Rcv raw: b'\x81~\x00\xad{"topic":"orderbook.50.BTCUSDC","ts":1698936855663,"type":"delta","data":{"s":"BTCUSDC","b":[["34957.03","0.02313"],["34940.24","0"]],"a":[],"u":20009966,"seq":14108035706}}'
2023-11-02 14:54:15,749 DEBUG ++Rcv decoded: fin=1 opcode=1 data=b'{"topic":"orderbook.50.BTCUSDC","ts":1698936855663,"type":"delta","data":{"s":"BTCUSDC","b":[["34957.03","0.02313"],["34940.24","0"]],"a":[],"u":20009966,"seq":14108035706}}'
2023-11-02 14:54:15,789 DEBUG ++Rcv raw: b'\x81~\x00\xab{"topic":"orderbook.50.BTCUSDC","ts":1698936855704,"type":"delta","data":{"s":"BTCUSDC","b":[],"a":[["34980.5","0.0859"],["34961.77","0"]],"u":20009967,"seq":14108035722}}'
2023-11-02 14:54:15,789 DEBUG ++Rcv decoded: fin=1 opcode=1 data=b'{"topic":"orderbook.50.BTCUSDC","ts":1698936855704,"type":"delta","data":{"s":"BTCUSDC","b":[],"a":[["34980.5","0.0859"],["34961.77","0"]],"u":20009967,"seq":14108035722}}'
2023-11-02 14:54:15,809 DEBUG ++Rcv raw: b'\x81~\x00\xad{"topic":"orderbook.50.BTCUSDC","ts":1698936855724,"type":"delta","data":{"s":"BTCUSDC","b":[["34941.1","0.000261"],["34940.87","0"]],"a":[],"u":20009968,"seq":14108035730}}'
2023-11-02 14:54:15,809 DEBUG ++Rcv decoded: fin=1 opcode=1 data=b'{"topic":"orderbook.50.BTCUSDC","ts":1698936855724,"type":"delta","data":{"s":"BTCUSDC","b":[["34941.1","0.000261"],["34940.87","0"]],"a":[],"u":20009968,"seq":14108035730}}'
2023-11-02 14:54:15,850 DEBUG ++Rcv raw: b'\x81~\x00\xad{"topic":"orderbook.50.BTCUSDC","ts":1698936855764,"type":"delta","data":{"s":"BTCUSDC","b":[],"a":[["34965.49","0.000239"],["34980.5","0"]],"u":20009969,"seq":14108035733}}'
2023-11-02 14:54:15,850 DEBUG ++Rcv decoded: fin=1 opcode=1 data=b'{"topic":"orderbook.50.BTCUSDC","ts":1698936855764,"type":"delta","data":{"s":"BTCUSDC","b":[],"a":[["34965.49","0.000239"],["34980.5","0"]],"u":20009969,"seq":14108035733}}'
2023-11-02 14:54:15,889 DEBUG ++Rcv raw: b'\x81~\x00\xad{"topic":"orderbook.50.BTCUSDC","ts":1698936855804,"type":"delta","data":{"s":"BTCUSDC","b":[],"a":[["34961.92","0.01147"],["34968.93","0"]],"u":20009970,"seq":14108035756}}'
2023-11-02 14:54:15,890 DEBUG ++Rcv decoded: fin=1 opcode=1 data=b'{"topic":"orderbook.50.BTCUSDC","ts":1698936855804,"type":"delta","data":{"s":"BTCUSDC","b":[],"a":[["34961.92","0.01147"],["34968.93","0"]],"u":20009970,"seq":14108035756}}'
2023-11-02 14:54:15,909 DEBUG ++Rcv raw: b'\x81~\x00\xd1{"topic":"orderbook.50.BTCUSDC","ts":1698936855824,"type":"delta","data":{"s":"BTCUSDC","b":[],"a":[["34969.97","0.051544"],["34980.5","0.0859"],["34964","0"],["34968.92","0"]],"u":20009971,"seq":14108035774}}'
2023-11-02 14:54:15,910 DEBUG ++Rcv decoded: fin=1 opcode=1 data=b'{"topic":"orderbook.50.BTCUSDC","ts":1698936855824,"type":"delta","data":{"s":"BTCUSDC","b":[],"a":[["34969.97","0.051544"],["34980.5","0.0859"],["34964","0"],["34968.92","0"]],"u":20009971,"seq":14108035774}}'
2023-11-02 14:54:15,930 DEBUG ++Rcv raw: b'\x81~\x00\xac{"topic":"orderbook.50.BTCUSDC","ts":1698936855843,"type":"delta","data":{"s":"BTCUSDC","b":[["34949.26","0.1875"],["34940.99","0"]],"a":[],"u":20009972,"seq":14108035779}}'
2023-11-02 14:54:15,930 DEBUG ++Rcv decoded: fin=1 opcode=1 data=b'{"topic":"orderbook.50.BTCUSDC","ts":1698936855843,"type":"delta","data":{"s":"BTCUSDC","b":[["34949.26","0.1875"],["34940.99","0"]],"a":[],"u":20009972,"seq":14108035779}}'
2023-11-02 14:54:15,949 DEBUG ++Rcv raw: b'\x81~\x00\xae{"topic":"orderbook.50.BTCUSDC","ts":1698936855863,"type":"delta","data":{"s":"BTCUSDC","b":[["34940.99","0.126463"],["34944.19","0"]],"a":[],"u":20009973,"seq":14108035805}}'
2023-11-02 14:54:15,949 DEBUG ++Rcv decoded: fin=1 opcode=1 data=b'{"topic":"orderbook.50.BTCUSDC","ts":1698936855863,"type":"delta","data":{"s":"BTCUSDC","b":[["34940.99","0.126463"],["34944.19","0"]],"a":[],"u":20009973,"seq":14108035805}}'
2023-11-02 14:54:15,969 DEBUG ++Rcv raw: b'\x81~\x00\xd4{"topic":"orderbook.50.BTCUSDC","ts":1698936855883,"type":"delta","data":{"s":"BTCUSDC","b":[["34941.2","0.000261"],["34940.99","0"]],"a":[["34965.42","0.000239"],["34980.5","0"]],"u":20009974,"seq":14108035824}}'
2023-11-02 14:54:15,969 DEBUG ++Rcv decoded: fin=1 opcode=1 data=b'{"topic":"orderbook.50.BTCUSDC","ts":1698936855883,"type":"delta","data":{"s":"BTCUSDC","b":[["34941.2","0.000261"],["34940.99","0"]],"a":[["34965.42","0.000239"],["34980.5","0"]],"u":20009974,"seq":14108035824}}'
2023-11-02 14:54:15,988 DEBUG ++Rcv raw: b'\x81~\x00\xd3{"topic":"orderbook.50.BTCUSDC","ts":1698936855903,"type":"delta","data":{"s":"BTCUSDC","b":[["34953","0.001038"],["34949.26","0"]],"a":[["34961.54","0.103291"],["34961.92","0"]],"u":20009975,"seq":14108035835}}'
2023-11-02 14:54:15,989 DEBUG ++Rcv decoded: fin=1 opcode=1 data=b'{"topic":"orderbook.50.BTCUSDC","ts":1698936855903,"type":"delta","data":{"s":"BTCUSDC","b":[["34953","0.001038"],["34949.26","0"]],"a":[["34961.54","0.103291"],["34961.92","0"]],"u":20009975,"seq":14108035835}}'
2023-11-02 14:54:16,009 DEBUG ++Rcv raw: b'\x81~\x00\xae{"topic":"orderbook.50.BTCUSDC","ts":1698936855923,"type":"delta","data":{"s":"BTCUSDC","b":[["34940.99","0.126463"],["34951.29","0"]],"a":[],"u":20009976,"seq":14108035838}}'
2023-11-02 14:54:16,010 DEBUG ++Rcv decoded: fin=1 opcode=1 data=b'{"topic":"orderbook.50.BTCUSDC","ts":1698936855923,"type":"delta","data":{"s":"BTCUSDC","b":[["34940.99","0.126463"],["34951.29","0"]],"a":[],"u":20009976,"seq":14108035838}}'
2023-11-02 14:54:16,089 DEBUG ++Rcv raw: b'\x81~\x00\xad{"topic":"orderbook.50.BTCUSDC","ts":1698936856003,"type":"delta","data":{"s":"BTCUSDC","b":[],"a":[["34961.53","0.01147"],["34961.54","0"]],"u":20009977,"seq":14108035869}}'
2023-11-02 14:54:16,090 DEBUG ++Rcv decoded: fin=1 opcode=1 data=b'{"topic":"orderbook.50.BTCUSDC","ts":1698936856003,"type":"delta","data":{"s":"BTCUSDC","b":[],"a":[["34961.53","0.01147"],["34961.54","0"]],"u":20009977,"seq":14108035869}}'
2023-11-02 14:54:16,149 DEBUG ++Rcv raw: b'\x81~\x00\xcf{"topic":"orderbook.50.BTCUSDC","ts":1698936856064,"type":"delta","data":{"s":"BTCUSDC","b":[["34941.45","0.028"],["34941.1","0"]],"a":[["34980.5","0.0859"],["34965.49","0"]],"u":20009978,"seq":14108035883}}'
2023-11-02 14:54:16,149 DEBUG ++Rcv decoded: fin=1 opcode=1 data=b'{"topic":"orderbook.50.BTCUSDC","ts":1698936856064,"type":"delta","data":{"s":"BTCUSDC","b":[["34941.45","0.028"],["34941.1","0"]],"a":[["34980.5","0.0859"],["34965.49","0"]],"u":20009978,"seq":14108035883}}'
2023-11-02 14:54:16,189 DEBUG ++Rcv raw: b'\x81~\x00\xae{"topic":"orderbook.50.BTCUSDC","ts":1698936856103,"type":"delta","data":{"s":"BTCUSDC","b":[],"a":[["34980.62","0.285872"],["34961.53","0"]],"u":20009979,"seq":14108035888}}'
2023-11-02 14:54:16,189 DEBUG ++Rcv decoded: fin=1 opcode=1 data=b'{"topic":"orderbook.50.BTCUSDC","ts":1698936856103,"type":"delta","data":{"s":"BTCUSDC","b":[],"a":[["34980.62","0.285872"],["34961.53","0"]],"u":20009979,"seq":14108035888}}'
2023-11-02 14:54:16,209 DEBUG ++Rcv raw: b'\x81~\x00\xac{"topic":"orderbook.50.BTCUSDC","ts":1698936856124,"type":"delta","data":{"s":"BTCUSDC","b":[],"a":[["34968.93","0.1875"],["34980.62","0"]],"u":20009980,"seq":14108035897}}'
2023-11-02 14:54:16,209 DEBUG ++Rcv decoded: fin=1 opcode=1 data=b'{"topic":"orderbook.50.BTCUSDC","ts":1698936856124,"type":"delta","data":{"s":"BTCUSDC","b":[],"a":[["34968.93","0.1875"],["34980.62","0"]],"u":20009980,"seq":14108035897}}'
2023-11-02 14:54:16,229 DEBUG ++Rcv raw: b'\x81~\x00\xae{"topic":"orderbook.50.BTCUSDC","ts":1698936856144,"type":"delta","data":{"s":"BTCUSDC","b":[],"a":[["34968.92","0.112505"],["34969.97","0"]],"u":20009981,"seq":14108035900}}'
2023-11-02 14:54:16,230 DEBUG ++Rcv decoded: fin=1 opcode=1 data=b'{"topic":"orderbook.50.BTCUSDC","ts":1698936856144,"type":"delta","data":{"s":"BTCUSDC","b":[],"a":[["34968.92","0.112505"],["34969.97","0"]],"u":20009981,"seq":14108035900}}'
2023-11-02 14:54:16,309 DEBUG ++Rcv raw: b'\x81~\x00\xad{"topic":"orderbook.50.BTCUSDC","ts":1698936856223,"type":"delta","data":{"s":"BTCUSDC","b":[],"a":[["34961.63","0.094718"],["34980.5","0"]],"u":20009982,"seq":14108035927}}'
2023-11-02 14:54:16,309 DEBUG ++Rcv decoded: fin=1 opcode=1 data=b'{"topic":"orderbook.50.BTCUSDC","ts":1698936856223,"type":"delta","data":{"s":"BTCUSDC","b":[],"a":[["34961.63","0.094718"],["34980.5","0"]],"u":20009982,"seq":14108035927}}'
2023-11-02 14:54:16,349 DEBUG ++Rcv raw: b'\x81~\x00\xab{"topic":"orderbook.50.BTCUSDC","ts":1698936856264,"type":"delta","data":{"s":"BTCUSDC","b":[],"a":[["34980.5","0.0859"],["34965.42","0"]],"u":20009983,"seq":14108035945}}'
2023-11-02 14:54:16,350 DEBUG ++Rcv decoded: fin=1 opcode=1 data=b'{"topic":"orderbook.50.BTCUSDC","ts":1698936856264,"type":"delta","data":{"s":"BTCUSDC","b":[],"a":[["34980.5","0.0859"],["34965.42","0"]],"u":20009983,"seq":14108035945}}'
2023-11-02 14:54:16,409 DEBUG ++Rcv raw: b'\x81~\x00\xad{"topic":"orderbook.50.BTCUSDC","ts":1698936856324,"type":"delta","data":{"s":"BTCUSDC","b":[],"a":[["34961.52","0.01147"],["34961.63","0"]],"u":20009984,"seq":14108035981}}'
2023-11-02 14:54:16,409 DEBUG ++Rcv decoded: fin=1 opcode=1 data=b'{"topic":"orderbook.50.BTCUSDC","ts":1698936856324,"type":"delta","data":{"s":"BTCUSDC","b":[],"a":[["34961.52","0.01147"],["34961.63","0"]],"u":20009984,"seq":14108035981}}'
2023-11-02 14:54:16,448 DEBUG ++Rcv raw: b'\x81~\x00\xa8{"topic":"orderbook.50.BTCUSDC","ts":1698936856363,"type":"delta","data":{"s":"BTCUSDC","b":[],"a":[["34964","0.0324"],["34980.5","0"]],"u":20009985,"seq":14108035993}}'
2023-11-02 14:54:16,449 DEBUG ++Rcv decoded: fin=1 opcode=1 data=b'{"topic":"orderbook.50.BTCUSDC","ts":1698936856363,"type":"delta","data":{"s":"BTCUSDC","b":[],"a":[["34964","0.0324"],["34980.5","0"]],"u":20009985,"seq":14108035993}}'
2023-11-02 14:54:16,469 DEBUG ++Rcv raw: b'\x81~\x00\xfd{"topic":"orderbook.50.BTCUSDC","ts":1698936856383,"type":"delta","data":{"s":"BTCUSDC","b":[["34948.1","0.068646"],["34940.99","0"]],"a":[["34961.51","0.008756"],["34972.8","0.215135"],["34979.81","0"],["34980.48","0"]],"u":20009986,"seq":14108035998}}'
2023-11-02 14:54:16,469 DEBUG ++Rcv decoded: fin=1 opcode=1 data=b'{"topic":"orderbook.50.BTCUSDC","ts":1698936856383,"type":"delta","data":{"s":"BTCUSDC","b":[["34948.1","0.068646"],["34940.99","0"]],"a":[["34961.51","0.008756"],["34972.8","0.215135"],["34979.81","0"],["34980.48","0"]],"u":20009986,"seq":14108035998}}'
2023-11-02 14:54:16,509 DEBUG ++Rcv raw: b'\x81~\x01\x99{"topic":"orderbook.50.BTCUSDC","ts":1698936856424,"type":"delta","data":{"s":"BTCUSDC","b":[["34940.99","0.126463"],["34940.87","0.00154"],["34940.24","0.05724"],["34939.85","0.1875"],["34937.76","0.029857"],["34937.39","0.278379"],["34959.76","0"],["34958","0"],["34958.4","0"],["34958.15","0"],["34958.39","0"],["34958.14","0"]],"a":[["34965.02","0.0859"],["34961.52","0"]],"u":20009987,"seq":14108036018}}'
2023-11-02 14:54:16,509 DEBUG ++Rcv decoded: fin=1 opcode=1 data=b'{"topic":"orderbook.50.BTCUSDC","ts":1698936856424,"type":"delta","data":{"s":"BTCUSDC","b":[["34940.99","0.126463"],["34940.87","0.00154"],["34940.24","0.05724"],["34939.85","0.1875"],["34937.76","0.029857"],["34937.39","0.278379"],["34959.76","0"],["34958","0"],["34958.4","0"],["34958.15","0"],["34958.39","0"],["34958.14","0"]],"a":[["34965.02","0.0859"],["34961.52","0"]],"u":20009987,"seq":14108036018}}'
2023-11-02 14:54:16,531 DEBUG ++Rcv raw: b'\x81~\x01v{"topic":"orderbook.50.BTCUSDC","ts":1698936856443,"type":"delta","data":{"s":"BTCUSDC","b":[["34957.64","0.057212"],["34957.23","0.052647"],["34951.29","0.001254"],["34957.22","0"],["34941.2","0"],["34937.39","0"]],"a":[["34961.5","0.046193"],["34965.01","0.05154"],["34965.13","0.057199"],["34978.87","0"],["34965.53","0"],["34978.9","0"]],"u":20009988,"seq":14108036037}}'
2023-11-02 14:54:16,531 DEBUG ++Rcv decoded: fin=1 opcode=1 data=b'{"topic":"orderbook.50.BTCUSDC","ts":1698936856443,"type":"delta","data":{"s":"BTCUSDC","b":[["34957.64","0.057212"],["34957.23","0.052647"],["34951.29","0.001254"],["34957.22","0"],["34941.2","0"],["34937.39","0"]],"a":[["34961.5","0.046193"],["34965.01","0.05154"],["34965.13","0.057199"],["34978.87","0"],["34965.53","0"],["34978.9","0"]],"u":20009988,"seq":14108036037}}'
2023-11-02 14:54:16,549 DEBUG ++Rcv raw: b'\x81~\x01\x8a{"topic":"orderbook.50.BTCUSDC","ts":1698936856464,"type":"delta","data":{"s":"BTCUSDC","b":[["34957.65","0.086966"],["34937.39","0.278379"],["34936.51","0.823863"],["34957.23","0"],["34953","0"],["34957.64","0"]],"a":[["34965.01","0.079419"],["34978.87","0.07078"],["34978.9","0.002162"],["34979.7","0.28588"],["34961.5","0"],["34971.48","0"],["34965.13","0"]],"u":20009989,"seq":14108036054}}'
2023-11-02 14:54:16,549 DEBUG ++Rcv decoded: fin=1 opcode=1 data=b'{"topic":"orderbook.50.BTCUSDC","ts":1698936856464,"type":"delta","data":{"s":"BTCUSDC","b":[["34957.65","0.086966"],["34937.39","0.278379"],["34936.51","0.823863"],["34957.23","0"],["34953","0"],["34957.64","0"]],"a":[["34965.01","0.079419"],["34978.87","0.07078"],["34978.9","0.002162"],["34979.7","0.28588"],["34961.5","0"],["34971.48","0"],["34965.13","0"]],"u":20009989,"seq":14108036054}}'
2023-11-02 14:54:16,569 DEBUG ++Rcv raw: b'\x81~\x00\xdb{"topic":"orderbook.50.BTCUSDC","ts":1698936856483,"type":"delta","data":{"s":"BTCUSDC","b":[["34957.65","0.031041"]],"a":[["34965.01","0.05154"],["34970.58","0.114381"],["34979.7","0"]],"u":20009990,"seq":14108036060}}'
2023-11-02 14:54:16,569 DEBUG ++Rcv decoded: fin=1 opcode=1 data=b'{"topic":"orderbook.50.BTCUSDC","ts":1698936856483,"type":"delta","data":{"s":"BTCUSDC","b":[["34957.65","0.031041"]],"a":[["34965.01","0.05154"],["34970.58","0.114381"],["34979.7","0"]],"u":20009990,"seq":14108036060}}'
2023-11-02 14:54:16,591 DEBUG ++Rcv raw: b'\x81~\x01\'{"topic":"orderbook.50.BTCUSDC","ts":1698936856503,"type":"delta","data":{"s":"BTCUSDC","b":[["34955.76","0.028602"],["34944.93","0.114411"],["34948.09","0"],["34957.14","0"]],"a":[["34961.5","0.028602"],["34978.32","0.114411"],["34969.98","0"],["34971.47","0"]],"u":20009991,"seq":14108036076}}'
2023-11-02 14:54:16,591 DEBUG ++Rcv decoded: fin=1 opcode=1 data=b'{"topic":"orderbook.50.BTCUSDC","ts":1698936856503,"type":"delta","data":{"s":"BTCUSDC","b":[["34955.76","0.028602"],["34944.93","0.114411"],["34948.09","0"],["34957.14","0"]],"a":[["34961.5","0.028602"],["34978.32","0.114411"],["34969.98","0"],["34971.47","0"]],"u":20009991,"seq":14108036076}}'
2023-11-02 14:54:16,609 DEBUG ++Rcv raw: b'\x81~\x01<{"topic":"orderbook.50.BTCUSDC","ts":1698936856523,"type":"delta","data":{"s":"BTCUSDC","b":[["34956.43","0.081703"],["34954.01","0.029532"],["34936.5","1.373091"],["34936.35","0.1875"],["34948.1","0"],["34954.71","0"],["34957.65","0"]],"a":[["34961.49","0.008756"],["34961.51","0"]],"u":20009992,"seq":14108036088}}'
2023-11-02 14:54:16,610 DEBUG ++Rcv decoded: fin=1 opcode=1 data=b'{"topic":"orderbook.50.BTCUSDC","ts":1698936856523,"type":"delta","data":{"s":"BTCUSDC","b":[["34956.43","0.081703"],["34954.01","0.029532"],["34936.5","1.373091"],["34936.35","0.1875"],["34948.1","0"],["34954.71","0"],["34957.65","0"]],"a":[["34961.49","0.008756"],["34961.51","0"]],"u":20009992,"seq":14108036088}}'
2023-11-02 14:54:16,629 DEBUG ++Rcv raw: b'\x81~\x01w{"topic":"orderbook.50.BTCUSDC","ts":1698936856544,"type":"delta","data":{"s":"BTCUSDC","b":[["34957.59","0.057212"],["34951.47","0.114444"],["34949.55","0.051546"],["34936.5","0"],["34936.35","0"],["34952.44","0"]],"a":[["34960.1","0.008756"],["34960.11","0.072318"],["34964.25","0.057201"],["34961.49","0"],["34978.9","0"],["34978.87","0"]],"u":20009993,"seq":14108036099}}'
2023-11-02 14:54:16,630 DEBUG ++Rcv decoded: fin=1 opcode=1 data=b'{"topic":"orderbook.50.BTCUSDC","ts":1698936856544,"type":"delta","data":{"s":"BTCUSDC","b":[["34957.59","0.057212"],["34951.47","0.114444"],["34949.55","0.051546"],["34936.5","0"],["34936.35","0"],["34952.44","0"]],"a":[["34960.1","0.008756"],["34960.11","0.072318"],["34964.25","0.057201"],["34961.49","0"],["34978.9","0"],["34978.87","0"]],"u":20009993,"seq":14108036099}}'
2023-11-02 14:54:16,649 DEBUG ++Rcv raw: b'\x81~\x01\xde{"topic":"orderbook.50.BTCUSDC","ts":1698936856564,"type":"delta","data":{"s":"BTCUSDC","b":[["34957.6","0.048212"],["34956.43","0.051543"],["34954.71","0.051548"],["34936.5","1.373091"],["34936.35","0.1875"],["34933.72","0.274807"],["34953.26","0"],["34957.03","0"],["34954.01","0"],["34943.36","0"],["34957.59","0"]],"a":[["34978.87","0.07078"],["34978.9","0.002162"],["34979.81","0.049142"],["34960.11","0"],["34964.25","0"],["34970.58","0"]],"u":20009994,"seq":14108036121}}'
2023-11-02 14:54:16,650 DEBUG ++Rcv decoded: fin=1 opcode=1 data=b'{"topic":"orderbook.50.BTCUSDC","ts":1698936856564,"type":"delta","data":{"s":"BTCUSDC","b":[["34957.6","0.048212"],["34956.43","0.051543"],["34954.71","0.051548"],["34936.5","1.373091"],["34936.35","0.1875"],["34933.72","0.274807"],["34953.26","0"],["34957.03","0"],["34954.01","0"],["34943.36","0"],["34957.59","0"]],"a":[["34978.87","0.07078"],["34978.9","0.002162"],["34979.81","0.049142"],["34960.11","0"],["34964.25","0"],["34970.58","0"]],"u":20009994,"seq":14108036121}}'
2023-11-02 14:54:16,669 DEBUG ++Rcv raw: b'\x81~\x01>{"topic":"orderbook.50.BTCUSDC","ts":1698936856584,"type":"delta","data":{"s":"BTCUSDC","b":[["34956.43","0.081708"],["34954.01","0.029527"],["34942.31","0.286185"],["34933.71","0.45801"],["34957.6","0"],["34954.71","0"],["34943.76","0"]],"a":[["34978.73","0.285888"],["34979.81","0"]],"u":20009995,"seq":14108036138}}'
2023-11-02 14:54:16,670 DEBUG ++Rcv decoded: fin=1 opcode=1 data=b'{"topic":"orderbook.50.BTCUSDC","ts":1698936856584,"type":"delta","data":{"s":"BTCUSDC","b":[["34956.43","0.081708"],["34954.01","0.029527"],["34942.31","0.286185"],["34933.71","0.45801"],["34957.6","0"],["34954.71","0"],["34943.76","0"]],"a":[["34978.73","0.285888"],["34979.81","0"]],"u":20009995,"seq":14108036138}}'
2023-11-02 14:54:16,689 DEBUG ++Rcv raw: b'\x81~\x01={"topic":"orderbook.50.BTCUSDC","ts":1698936856604,"type":"delta","data":{"s":"BTCUSDC","b":[["34956.43","0.027408"],["34951.54","0.00057"],["34932.01","0.112502"],["34931.31","0.1875"],["34951.27","0"],["34940.99","0"],["34953.79","0"]],"a":[["34976.88","0.031073"],["34978.87","0"]],"u":20009996,"seq":14108036154}}'
2023-11-02 14:54:16,690 DEBUG ++Rcv decoded: fin=1 opcode=1 data=b'{"topic":"orderbook.50.BTCUSDC","ts":1698936856604,"type":"delta","data":{"s":"BTCUSDC","b":[["34956.43","0.027408"],["34951.54","0.00057"],["34932.01","0.112502"],["34931.31","0.1875"],["34951.27","0"],["34940.99","0"],["34953.79","0"]],"a":[["34976.88","0.031073"],["34978.87","0"]],"u":20009996,"seq":14108036154}}'
2023-11-02 14:54:16,709 DEBUG ++Rcv raw: b'\x81~\x02*{"topic":"orderbook.50.BTCUSDC","ts":1698936856623,"type":"delta","data":{"s":"BTCUSDC","b":[["34954.71","0.059977"],["34953.78","0.036"],["34951.48","0.068668"],["34951.47","0.168644"],["34950.04","0.046722"],["34948.02","0.353576"],["34956.43","0"],["34955.76","0"],["34954.01","0"],["34951.28","0"],["34952.99","0"]],"a":[["34960.08","0.008756"],["34960.09","0.03895"],["34962","0.0324"],["34966.83","0.028603"],["34971.89","0.369737"],["34961.5","0"],["34978.9","0"],["34972.81","0"],["34960.1","0"],["34967.78","0"]],"u":20009997,"seq":14108036189}}'
2023-11-02 14:54:16,709 DEBUG ++Rcv decoded: fin=1 opcode=1 data=b'{"topic":"orderbook.50.BTCUSDC","ts":1698936856623,"type":"delta","data":{"s":"BTCUSDC","b":[["34954.71","0.059977"],["34953.78","0.036"],["34951.48","0.068668"],["34951.47","0.168644"],["34950.04","0.046722"],["34948.02","0.353576"],["34956.43","0"],["34955.76","0"],["34954.01","0"],["34951.28","0"],["34952.99","0"]],"a":[["34960.08","0.008756"],["34960.09","0.03895"],["34962","0.0324"],["34966.83","0.028603"],["34971.89","0.369737"],["34961.5","0"],["34978.9","0"],["34972.81","0"],["34960.1","0"],["34967.78","0"]],"u":20009997,"seq":14108036189}}'
2023-11-02 14:54:16,729 DEBUG ++Rcv raw: b'\x81~\x01\x89{"topic":"orderbook.50.BTCUSDC","ts":1698936856644,"type":"delta","data":{"s":"BTCUSDC","b":[["34952.92","0.028604"],["34948.03","0.213694"],["34948.02","0"],["34949.55","0"]],"a":[["34963.3","0.0859"],["34964.25","0.03"],["34967.99","0.048239"],["34978.9","0.002162"],["34979.81","0.049142"],["34960.09","0"],["34970.26","0"],["34966.83","0"],["34972.8","0"]],"u":20009998,"seq":14108036212}}'
2023-11-02 14:54:16,730 DEBUG ++Rcv decoded: fin=1 opcode=1 data=b'{"topic":"orderbook.50.BTCUSDC","ts":1698936856644,"type":"delta","data":{"s":"BTCUSDC","b":[["34952.92","0.028604"],["34948.03","0.213694"],["34948.02","0"],["34949.55","0"]],"a":[["34963.3","0.0859"],["34964.25","0.03"],["34967.99","0.048239"],["34978.9","0.002162"],["34979.81","0.049142"],["34960.09","0"],["34970.26","0"],["34966.83","0"],["34972.8","0"]],"u":20009998,"seq":14108036212}}'
2023-11-02 14:54:16,749 DEBUG ++Rcv raw: b'\x81~\x01\x16{"topic":"orderbook.50.BTCUSDC","ts":1698936856664,"type":"delta","data":{"s":"BTCUSDC","b":[["34948.04","0.128222"],["34948.03","0.001545"],["34951.29","0"]],"a":[["34963.29","0.051547"],["34965.32","0.028604"],["34967.99","0"],["34963.3","0"]],"u":20009999,"seq":14108036227}}'
2023-11-02 14:54:16,749 DEBUG ++Rcv decoded: fin=1 opcode=1 data=b'{"topic":"orderbook.50.BTCUSDC","ts":1698936856664,"type":"delta","data":{"s":"BTCUSDC","b":[["34948.04","0.128222"],["34948.03","0.001545"],["34951.29","0"]],"a":[["34963.29","0.051547"],["34965.32","0.028604"],["34967.99","0"],["34963.3","0"]],"u":20009999,"seq":14108036227}}'
2023-11-02 14:54:16,770 DEBUG ++Rcv raw: b'\x81~\x00\xd6{"topic":"orderbook.50.BTCUSDC","ts":1698936856684,"type":"delta","data":{"s":"BTCUSDC","b":[["34949.55","0.051548"],["34948.04","0"]],"a":[["34980.48","0.023472"],["34963.29","0"]],"u":20010000,"seq":14108036235}}'
2023-11-02 14:54:16,770 DEBUG ++Rcv decoded: fin=1 opcode=1 data=b'{"topic":"orderbook.50.BTCUSDC","ts":1698936856684,"type":"delta","data":{"s":"BTCUSDC","b":[["34949.55","0.051548"],["34948.04","0"]],"a":[["34980.48","0.023472"],["34963.29","0"]],"u":20010000,"seq":14108036235}}'
2023-11-02 14:54:16,809 DEBUG ++Rcv raw: b'\x81~\x00\xab{"topic":"orderbook.50.BTCUSDC","ts":1698936856724,"type":"delta","data":{"s":"BTCUSDC","b":[],"a":[["34980.5","0.0859"],["34971.89","0"]],"u":20010001,"seq":14108036255}}'
2023-11-02 14:54:16,809 DEBUG ++Rcv decoded: fin=1 opcode=1 data=b'{"topic":"orderbook.50.BTCUSDC","ts":1698936856724,"type":"delta","data":{"s":"BTCUSDC","b":[],"a":[["34980.5","0.0859"],["34971.89","0"]],"u":20010001,"seq":14108036255}}'
2023-11-02 14:54:16,888 DEBUG ++Rcv raw: b'\x81~\x00\xea{"topic":"orderbook.50.BTCUSDC","ts":1698936856803,"type":"delta","data":{"s":"BTCUSDC","b":[["34956.78","0.102946"],["34956.42","0.11188"],["34931.31","0"]],"a":[["34981.28","0.000562"],["34962","0"]],"u":20010002,"seq":14108036279}}'
2023-11-02 14:54:16,889 DEBUG ++Rcv decoded: fin=1 opcode=1 data=b'{"topic":"orderbook.50.BTCUSDC","ts":1698936856803,"type":"delta","data":{"s":"BTCUSDC","b":[["34956.78","0.102946"],["34956.42","0.11188"],["34931.31","0"]],"a":[["34981.28","0.000562"],["34962","0"]],"u":20010002,"seq":14108036279}}'
2023-11-02 14:54:16,908 DEBUG ++Rcv raw: b'\x81~\x00\xac{"topic":"orderbook.50.BTCUSDC","ts":1698936856823,"type":"delta","data":{"s":"BTCUSDC","b":[["34931.31","0.1875"],["34941.45","0"]],"a":[],"u":20010003,"seq":14108036280}}'
2023-11-02 14:54:16,909 DEBUG ++Rcv decoded: fin=1 opcode=1 data=b'{"topic":"orderbook.50.BTCUSDC","ts":1698936856823,"type":"delta","data":{"s":"BTCUSDC","b":[["34931.31","0.1875"],["34941.45","0"]],"a":[],"u":20010003,"seq":14108036280}}'
2023-11-02 14:54:16,929 DEBUG ++Rcv raw: b'\x81~\x00\xff{"topic":"orderbook.50.BTCUSDC","ts":1698936856844,"type":"delta","data":{"s":"BTCUSDC","b":[["34950.05","0.001784"],["34942.33","0.000261"],["34931.31","0"],["34932.01","0"]],"a":[["34964.38","0.000239"],["34981.28","0"]],"u":20010004,"seq":14108036293}}'
2023-11-02 14:54:16,929 DEBUG ++Rcv decoded: fin=1 opcode=1 data=b'{"topic":"orderbook.50.BTCUSDC","ts":1698936856844,"type":"delta","data":{"s":"BTCUSDC","b":[["34950.05","0.001784"],["34942.33","0.000261"],["34931.31","0"],["34932.01","0"]],"a":[["34964.38","0.000239"],["34981.28","0"]],"u":20010004,"seq":14108036293}}'
2023-11-02 14:54:16,949 DEBUG ++Rcv raw: b'\x81~\x00\xad{"topic":"orderbook.50.BTCUSDC","ts":1698936856864,"type":"delta","data":{"s":"BTCUSDC","b":[],"a":[["34960.07","0.028604"],["34980.5","0"]],"u":20010005,"seq":14108036297}}'
2023-11-02 14:54:16,949 DEBUG ++Rcv decoded: fin=1 opcode=1 data=b'{"topic":"orderbook.50.BTCUSDC","ts":1698936856864,"type":"delta","data":{"s":"BTCUSDC","b":[],"a":[["34960.07","0.028604"],["34980.5","0"]],"u":20010005,"seq":14108036297}}'
2023-11-02 14:54:16,969 DEBUG ++Rcv raw: b'\x81~\x00\xae{"topic":"orderbook.50.BTCUSDC","ts":1698936856884,"type":"delta","data":{"s":"BTCUSDC","b":[["34932.01","0.112502"],["34948.03","0"]],"a":[],"u":20010006,"seq":14108036309}}'
2023-11-02 14:54:16,969 DEBUG ++Rcv decoded: fin=1 opcode=1 data=b'{"topic":"orderbook.50.BTCUSDC","ts":1698936856884,"type":"delta","data":{"s":"BTCUSDC","b":[["34932.01","0.112502"],["34948.03","0"]],"a":[],"u":20010006,"seq":14108036309}}'
2023-11-02 14:54:16,989 DEBUG ++Rcv raw: b'\x81~\x00\xab{"topic":"orderbook.50.BTCUSDC","ts":1698936856904,"type":"delta","data":{"s":"BTCUSDC","b":[],"a":[["34980.5","0.0859"],["34960.08","0"]],"u":20010007,"seq":14108036316}}'
2023-11-02 14:54:16,990 DEBUG ++Rcv decoded: fin=1 opcode=1 data=b'{"topic":"orderbook.50.BTCUSDC","ts":1698936856904,"type":"delta","data":{"s":"BTCUSDC","b":[],"a":[["34980.5","0.0859"],["34960.08","0"]],"u":20010007,"seq":14108036316}}'
2023-11-02 14:54:17,010 DEBUG ++Rcv raw: b'\x81~\x00\xfb{"topic":"orderbook.50.BTCUSDC","ts":1698936856924,"type":"delta","data":{"s":"BTCUSDC","b":[["34948.02","0.36978"],["34944.38","0.0859"],["34933.71","0"],["34932.01","0"]],"a":[["34971.89","0.362443"],["34980.5","0"]],"u":20010008,"seq":14108036321}}'
2023-11-02 14:54:17,010 DEBUG ++Rcv decoded: fin=1 opcode=1 data=b'{"topic":"orderbook.50.BTCUSDC","ts":1698936856924,"type":"delta","data":{"s":"BTCUSDC","b":[["34948.02","0.36978"],["34944.38","0.0859"],["34933.71","0"],["34932.01","0"]],"a":[["34971.89","0.362443"],["34980.5","0"]],"u":20010008,"seq":14108036321}}'
2023-11-02 14:54:17,029 DEBUG ++Rcv raw: b'\x81~\x00\xd3{"topic":"orderbook.50.BTCUSDC","ts":1698936856944,"type":"delta","data":{"s":"BTCUSDC","b":[["34948.03","0.221877"],["34949.55","0"]],"a":[["34980.5","0.0859"],["34960.07","0"]],"u":20010009,"seq":14108036327}}'
2023-11-02 14:54:17,029 DEBUG ++Rcv decoded: fin=1 opcode=1 data=b'{"topic":"orderbook.50.BTCUSDC","ts":1698936856944,"type":"delta","data":{"s":"BTCUSDC","b":[["34948.03","0.221877"],["34949.55","0"]],"a":[["34980.5","0.0859"],["34960.07","0"]],"u":20010009,"seq":14108036327}}'
2023-11-02 14:54:17,049 DEBUG ++Rcv raw: b'\x81~\x00\xfe{"topic":"orderbook.50.BTCUSDC","ts":1698936856964,"type":"delta","data":{"s":"BTCUSDC","b":[],"a":[["34960.59","0.042135"],["34960.6","0.070225"],["34961.92","0.008756"],["34980.48","0"],["34980.5","0"],["34979.81","0"]],"u":20010010,"seq":14108036334}}'
2023-11-02 14:54:17,049 DEBUG ++Rcv decoded: fin=1 opcode=1 data=b'{"topic":"orderbook.50.BTCUSDC","ts":1698936856964,"type":"delta","data":{"s":"BTCUSDC","b":[],"a":[["34960.59","0.042135"],["34960.6","0.070225"],["34961.92","0.008756"],["34980.48","0"],["34980.5","0"],["34979.81","0"]],"u":20010010,"seq":14108036334}}'
2023-11-02 14:54:17,069 DEBUG ++Rcv raw: b'\x81~\x00\xad{"topic":"orderbook.50.BTCUSDC","ts":1698936856984,"type":"delta","data":{"s":"BTCUSDC","b":[],"a":[["34979.81","0.049142"],["34960.6","0"]],"u":20010011,"seq":14108036347}}'
2023-11-02 14:54:17,069 DEBUG ++Rcv decoded: fin=1 opcode=1 data=b'{"topic":"orderbook.50.BTCUSDC","ts":1698936856984,"type":"delta","data":{"s":"BTCUSDC","b":[],"a":[["34979.81","0.049142"],["34960.6","0"]],"u":20010011,"seq":14108036347}}'
2023-11-02 14:54:17,089 DEBUG ++Rcv raw: b'\x81~\x00\xd3{"topic":"orderbook.50.BTCUSDC","ts":1698936857004,"type":"delta","data":{"s":"BTCUSDC","b":[["34943.76","0.028"],["34933.72","0"]],"a":[["34974.82","0.075313"],["34960.59","0"]],"u":20010012,"seq":14108036372}}'
2023-11-02 14:54:17,089 DEBUG ++Rcv decoded: fin=1 opcode=1 data=b'{"topic":"orderbook.50.BTCUSDC","ts":1698936857004,"type":"delta","data":{"s":"BTCUSDC","b":[["34943.76","0.028"],["34933.72","0"]],"a":[["34974.82","0.075313"],["34960.59","0"]],"u":20010012,"seq":14108036372}}'
2023-11-02 14:54:17,129 DEBUG ++Rcv raw: b'\x81~\x00\xc6{"topic":"orderbook.50.BTCUSDC","ts":1698936857043,"type":"delta","data":{"s":"BTCUSDC","b":[],"a":[["34961.91","0.024215"],["34961.92","0.037358"],["34979.81","0"]],"u":20010013,"seq":14108036382}}'
2023-11-02 14:54:17,129 DEBUG ++Rcv decoded: fin=1 opcode=1 data=b'{"topic":"orderbook.50.BTCUSDC","ts":1698936857043,"type":"delta","data":{"s":"BTCUSDC","b":[],"a":[["34961.91","0.024215"],["34961.92","0.037358"],["34979.81","0"]],"u":20010013,"seq":14108036382}}'
2023-11-02 14:54:17,169 DEBUG ++Rcv raw: b'\x81~\x00\xc4{"topic":"orderbook.50.BTCUSDC","ts":1698936857083,"type":"delta","data":{"s":"BTCUSDC","b":[],"a":[["34961.9","0.008756"],["34961.92","0.028602"],["34978.9","0"]],"u":20010014,"seq":14108036402}}'
2023-11-02 14:54:17,169 DEBUG ++Rcv decoded: fin=1 opcode=1 data=b'{"topic":"orderbook.50.BTCUSDC","ts":1698936857083,"type":"delta","data":{"s":"BTCUSDC","b":[],"a":[["34961.9","0.008756"],["34961.92","0.028602"],["34978.9","0"]],"u":20010014,"seq":14108036402}}'
2023-11-02 14:54:17,188 DEBUG ++Rcv raw: b'\x81~\x00\xff{"topic":"orderbook.50.BTCUSDC","ts":1698936857103,"type":"delta","data":{"s":"BTCUSDC","b":[["34957.18","0.057212"],["34936.35","0"]],"a":[["34963.98","0.057201"],["34969.67","0.114384"],["34978.73","0"],["34978.78","0"]],"u":20010015,"seq":14108036412}}'
2023-11-02 14:54:17,188 DEBUG ++Rcv decoded: fin=1 opcode=1 data=b'{"topic":"orderbook.50.BTCUSDC","ts":1698936857103,"type":"delta","data":{"s":"BTCUSDC","b":[["34957.18","0.057212"],["34936.35","0"]],"a":[["34963.98","0.057201"],["34969.67","0.114384"],["34978.73","0"],["34978.78","0"]],"u":20010015,"seq":14108036412}}'
2023-11-02 14:54:17,208 DEBUG ++Rcv raw: b'\x81~\x00\xfd{"topic":"orderbook.50.BTCUSDC","ts":1698936857123,"type":"delta","data":{"s":"BTCUSDC","b":[["34942.08","0.044206"],["34936.35","0.1875"],["34948.02","0"],["34956.78","0"]],"a":[["34977.49","0.071633"],["34978.32","0"]],"u":20010016,"seq":14108036437}}'
2023-11-02 14:54:17,209 DEBUG ++Rcv decoded: fin=1 opcode=1 data=b'{"topic":"orderbook.50.BTCUSDC","ts":1698936857123,"type":"delta","data":{"s":"BTCUSDC","b":[["34942.08","0.044206"],["34936.35","0.1875"],["34948.02","0"],["34956.78","0"]],"a":[["34977.49","0.071633"],["34978.32","0"]],"u":20010016,"seq":14108036437}}'
2023-11-02 14:54:17,229 DEBUG ++Rcv raw: b'\x81~\x00\xae{"topic":"orderbook.50.BTCUSDC","ts":1698936857143,"type":"delta","data":{"s":"BTCUSDC","b":[["34949.55","0.051542"],["34948.03","0"]],"a":[],"u":20010017,"seq":14108036451}}'
2023-11-02 14:54:17,229 DEBUG ++Rcv decoded: fin=1 opcode=1 data=b'{"topic":"orderbook.50.BTCUSDC","ts":1698936857143,"type":"delta","data":{"s":"BTCUSDC","b":[["34949.55","0.051542"],["34948.03","0"]],"a":[],"u":20010017,"seq":14108036451}}'
2023-11-02 14:54:17,269 DEBUG ++Rcv raw: b'\x81~\x00\xd6{"topic":"orderbook.50.BTCUSDC","ts":1698936857183,"type":"delta","data":{"s":"BTCUSDC","b":[["34944.07","0.000261"],["34936.35","0"]],"a":[["34962.67","0.000239"],["34978.28","0"]],"u":20010018,"seq":14108036470}}'
2023-11-02 14:54:17,269 DEBUG ++Rcv decoded: fin=1 opcode=1 data=b'{"topic":"orderbook.50.BTCUSDC","ts":1698936857183,"type":"delta","data":{"s":"BTCUSDC","b":[["34944.07","0.000261"],["34936.35","0"]],"a":[["34962.67","0.000239"],["34978.28","0"]],"u":20010018,"seq":14108036470}}'
2023-11-02 14:54:17,309 DEBUG ++Rcv raw: b'\x81~\x00\xc5{"topic":"orderbook.50.BTCUSDC","ts":1698936857223,"type":"delta","data":{"s":"BTCUSDC","b":[["34949.55","0.405629"]],"a":[["34978.28","0.001447"],["34978.24","0"]],"u":20010019,"seq":14108036486}}'
2023-11-02 14:54:17,310 DEBUG ++Rcv decoded: fin=1 opcode=1 data=b'{"topic":"orderbook.50.BTCUSDC","ts":1698936857223,"type":"delta","data":{"s":"BTCUSDC","b":[["34949.55","0.405629"]],"a":[["34978.28","0.001447"],["34978.24","0"]],"u":20010019,"seq":14108036486}}'
2023-11-02 14:54:17,329 DEBUG ++Rcv raw: b'\x81~\x00\xed{"topic":"orderbook.50.BTCUSDC","ts":1698936857243,"type":"delta","data":{"s":"BTCUSDC","b":[["34949.56","0.212455"],["34949.55","0.354087"],["34936.5","0"]],"a":[["34975.22","1.372918"],["34978.23","0"]],"u":20010020,"seq":14108036493}}'
2023-11-02 14:54:17,329 DEBUG ++Rcv decoded: fin=1 opcode=1 data=b'{"topic":"orderbook.50.BTCUSDC","ts":1698936857243,"type":"delta","data":{"s":"BTCUSDC","b":[["34949.56","0.212455"],["34949.55","0.354087"],["34936.5","0"]],"a":[["34975.22","1.372918"],["34978.23","0"]],"u":20010020,"seq":14108036493}}'
2023-11-02 14:54:17,369 DEBUG ++Rcv raw: b'\x81~\x00\xc5{"topic":"orderbook.50.BTCUSDC","ts":1698936857283,"type":"delta","data":{"s":"BTCUSDC","b":[["34957.18","0.083192"]],"a":[["34978.32","0.114411"],["34961.92","0"]],"u":20010021,"seq":14108036554}}'
2023-11-02 14:54:17,369 DEBUG ++Rcv decoded: fin=1 opcode=1 data=b'{"topic":"orderbook.50.BTCUSDC","ts":1698936857283,"type":"delta","data":{"s":"BTCUSDC","b":[["34957.18","0.083192"]],"a":[["34978.32","0.114411"],["34961.92","0"]],"u":20010021,"seq":14108036554}}'
2023-11-02 14:54:17,389 DEBUG ++Rcv raw: b'\x81~\x01%{"topic":"orderbook.50.BTCUSDC","ts":1698936857303,"type":"delta","data":{"s":"BTCUSDC","b":[["34943.19","0.286178"],["34936.5","1.373091"],["34942.31","0"],["34942.33","0"]],"a":[["34978.73","0.285888"],["34978.78","0.0859"],["34961.91","0"],["34964.38","0"]],"u":20010022,"seq":14108036576}}'
2023-11-02 14:54:17,389 DEBUG ++Rcv decoded: fin=1 opcode=1 data=b'{"topic":"orderbook.50.BTCUSDC","ts":1698936857303,"type":"delta","data":{"s":"BTCUSDC","b":[["34943.19","0.286178"],["34936.5","1.373091"],["34942.31","0"],["34942.33","0"]],"a":[["34978.73","0.285888"],["34978.78","0.0859"],["34961.91","0"],["34964.38","0"]],"u":20010022,"seq":14108036576}}'
2023-11-02 14:54:17,409 DEBUG ++Rcv raw: b'\x81~\x00\xd6{"topic":"orderbook.50.BTCUSDC","ts":1698936857324,"type":"delta","data":{"s":"BTCUSDC","b":[["34956.43","0.052692"],["34954.01","0.021606"],["34936.5","0"],["34954.71","0"]],"a":[],"u":20010023,"seq":14108036600}}'
2023-11-02 14:54:17,409 DEBUG ++Rcv decoded: fin=1 opcode=1 data=b'{"topic":"orderbook.50.BTCUSDC","ts":1698936857324,"type":"delta","data":{"s":"BTCUSDC","b":[["34956.43","0.052692"],["34954.01","0.021606"],["34936.5","0"],["34954.71","0"]],"a":[],"u":20010023,"seq":14108036600}}'
2023-11-02 14:54:17,429 DEBUG ++Rcv raw: b'\x81~\x00\xaa{"topic":"orderbook.50.BTCUSDC","ts":1698936857343,"type":"delta","data":{"s":"BTCUSDC","b":[],"a":[["34978.9","0.002162"],["34964","0"]],"u":20010024,"seq":14108036615}}'
2023-11-02 14:54:17,429 DEBUG ++Rcv decoded: fin=1 opcode=1 data=b'{"topic":"orderbook.50.BTCUSDC","ts":1698936857343,"type":"delta","data":{"s":"BTCUSDC","b":[],"a":[["34978.9","0.002162"],["34964","0"]],"u":20010024,"seq":14108036615}}'
2023-11-02 14:54:17,449 DEBUG ++Rcv raw: b'\x81~\x00\xc3{"topic":"orderbook.50.BTCUSDC","ts":1698936857363,"type":"delta","data":{"s":"BTCUSDC","b":[["34957.18","0.02598"]],"a":[["34961.89","0.028602"],["34978.9","0"]],"u":20010025,"seq":14108036650}}'
2023-11-02 14:54:17,449 DEBUG ++Rcv decoded: fin=1 opcode=1 data=b'{"topic":"orderbook.50.BTCUSDC","ts":1698936857363,"type":"delta","data":{"s":"BTCUSDC","b":[["34957.18","0.02598"]],"a":[["34961.89","0.028602"],["34978.9","0"]],"u":20010025,"seq":14108036650}}'
2023-11-02 14:54:17,469 DEBUG ++Rcv raw: b'\x81~\x01x{"topic":"orderbook.50.BTCUSDC","ts":1698936857384,"type":"delta","data":{"s":"BTCUSDC","b":[["34959.79","0.102685"],["34957.74","0.057211"],["34943.77","0.171714"],["34937.39","0"],["34957.18","0"],["34936.51","0"]],"a":[["34961.87","0.062117"],["34961.88","0.03895"],["34974.81","0.823759"],["34968.93","0"],["34978.78","0"],["34961.9","0"]],"u":20010026,"seq":14108036672}}'
2023-11-02 14:54:17,469 DEBUG ++Rcv decoded: fin=1 opcode=1 data=b'{"topic":"orderbook.50.BTCUSDC","ts":1698936857384,"type":"delta","data":{"s":"BTCUSDC","b":[["34959.79","0.102685"],["34957.74","0.057211"],["34943.77","0.171714"],["34937.39","0"],["34957.18","0"],["34936.51","0"]],"a":[["34961.87","0.062117"],["34961.88","0.03895"],["34974.81","0.823759"],["34968.93","0"],["34978.78","0"],["34961.9","0"]],"u":20010026,"seq":14108036672}}'
2023-11-02 14:54:17,489 DEBUG ++Rcv raw: b'\x81~\x01-{"topic":"orderbook.50.BTCUSDC","ts":1698936857403,"type":"delta","data":{"s":"BTCUSDC","b":[["34956.43","0.079982"],["34937.39","0.278379"],["34951.54","0"]],"a":[["34961.87","0.042333"],["34969.66","0.068633"],["34978.78","0.0859"],["34961.88","0"],["34968.92","0"]],"u":20010027,"seq":14108036688}}'
2023-11-02 14:54:17,489 DEBUG ++Rcv decoded: fin=1 opcode=1 data=b'{"topic":"orderbook.50.BTCUSDC","ts":1698936857403,"type":"delta","data":{"s":"BTCUSDC","b":[["34956.43","0.079982"],["34937.39","0.278379"],["34951.54","0"]],"a":[["34961.87","0.042333"],["34969.66","0.068633"],["34978.78","0.0859"],["34961.88","0"],["34968.92","0"]],"u":20010027,"seq":14108036688}}'
2023-11-02 14:54:17,509 DEBUG ++Rcv raw: b'\x81~\x00\xd3{"topic":"orderbook.50.BTCUSDC","ts":1698936857424,"type":"delta","data":{"s":"BTCUSDC","b":[["34958.14","0.0859"],["34937.39","0"]],"a":[["34978.9","0.002162"],["34961.87","0"]],"u":20010028,"seq":14108036702}}'
2023-11-02 14:54:17,509 DEBUG ++Rcv decoded: fin=1 opcode=1 data=b'{"topic":"orderbook.50.BTCUSDC","ts":1698936857424,"type":"delta","data":{"s":"BTCUSDC","b":[["34958.14","0.0859"],["34937.39","0"]],"a":[["34978.9","0.002162"],["34961.87","0"]],"u":20010028,"seq":14108036702}}'
2023-11-02 14:54:17,549 DEBUG ++Rcv raw: b'\x81~\x00\xae{"topic":"orderbook.50.BTCUSDC","ts":1698936857464,"type":"delta","data":{"s":"BTCUSDC","b":[["34951.49","0.002546"],["34950.05","0"]],"a":[],"u":20010029,"seq":14108036722}}'
2023-11-02 14:54:17,549 DEBUG ++Rcv decoded: fin=1 opcode=1 data=b'{"topic":"orderbook.50.BTCUSDC","ts":1698936857464,"type":"delta","data":{"s":"BTCUSDC","b":[["34951.49","0.002546"],["34950.05","0"]],"a":[],"u":20010029,"seq":14108036722}}'
2023-11-02 14:54:17,589 DEBUG ++Rcv raw: b'\x81~\x00\xac{"topic":"orderbook.50.BTCUSDC","ts":1698936857503,"type":"delta","data":{"s":"BTCUSDC","b":[["34949.29","0.1875"],["34937.76","0"]],"a":[],"u":20010030,"seq":14108036751}}'
2023-11-02 14:54:17,589 DEBUG ++Rcv decoded: fin=1 opcode=1 data=b'{"topic":"orderbook.50.BTCUSDC","ts":1698936857503,"type":"delta","data":{"s":"BTCUSDC","b":[["34949.29","0.1875"],["34937.76","0"]],"a":[],"u":20010030,"seq":14108036751}}'
2023-11-02 14:54:17,629 DEBUG ++Rcv raw: b'\x81~\x00\xfd{"topic":"orderbook.50.BTCUSDC","ts":1698936857543,"type":"delta","data":{"s":"BTCUSDC","b":[],"a":[["34979.81","0.049142"],["34980.48","0.023472"],["34980.5","0.0859"],["34961.93","0"],["34965.02","0"],["34961.89","0"]],"u":20010031,"seq":14108036782}}'
2023-11-02 14:54:17,629 DEBUG ++Rcv decoded: fin=1 opcode=1 data=b'{"topic":"orderbook.50.BTCUSDC","ts":1698936857543,"type":"delta","data":{"s":"BTCUSDC","b":[],"a":[["34979.81","0.049142"],["34980.48","0.023472"],["34980.5","0.0859"],["34961.93","0"],["34965.02","0"],["34961.89","0"]],"u":20010031,"seq":14108036782}}'
2023-11-02 14:54:17,649 DEBUG ++Rcv raw: b'\x81~\x01!{"topic":"orderbook.50.BTCUSDC","ts":1698936857564,"type":"delta","data":{"s":"BTCUSDC","b":[["34954.9","0.00057"],["34959.79","0"]],"a":[["34963.97","0.052324"],["34967.46","0.001"],["34971.88","0.21747"],["34980.5","0"],["34965.01","0"],["34980.48","0"]],"u":20010032,"seq":14108036805}}'
2023-11-02 14:54:17,650 DEBUG ++Rcv decoded: fin=1 opcode=1 data=b'{"topic":"orderbook.50.BTCUSDC","ts":1698936857564,"type":"delta","data":{"s":"BTCUSDC","b":[["34954.9","0.00057"],["34959.79","0"]],"a":[["34963.97","0.052324"],["34967.46","0.001"],["34971.88","0.21747"],["34980.5","0"],["34965.01","0"],["34980.48","0"]],"u":20010032,"seq":14108036805}}'
2023-11-02 14:54:17,670 DEBUG ++Rcv raw: b'\x81~\x00\xaa{"topic":"orderbook.50.BTCUSDC","ts":1698936857584,"type":"delta","data":{"s":"BTCUSDC","b":[["34959.8","0.003"],["34939.85","0"]],"a":[],"u":20010033,"seq":14108036829}}'
2023-11-02 14:54:17,670 DEBUG ++Rcv decoded: fin=1 opcode=1 data=b'{"topic":"orderbook.50.BTCUSDC","ts":1698936857584,"type":"delta","data":{"s":"BTCUSDC","b":[["34959.8","0.003"],["34939.85","0"]],"a":[],"u":20010033,"seq":14108036829}}'
2023-11-02 14:54:17,729 DEBUG ++Rcv raw: b'\x81~\x00\x9d{"topic":"orderbook.50.BTCUSDC","ts":1698936857643,"type":"delta","data":{"s":"BTCUSDC","b":[],"a":[["34969.67","0.301884"]],"u":20010034,"seq":14108036844}}'
2023-11-02 14:54:17,729 DEBUG ++Rcv decoded: fin=1 opcode=1 data=b'{"topic":"orderbook.50.BTCUSDC","ts":1698936857643,"type":"delta","data":{"s":"BTCUSDC","b":[],"a":[["34969.67","0.301884"]],"u":20010034,"seq":14108036844}}'
2023-11-02 14:54:17,749 DEBUG ++Rcv raw: b'\x81~\x00\xc6{"topic":"orderbook.50.BTCUSDC","ts":1698936857663,"type":"delta","data":{"s":"BTCUSDC","b":[],"a":[["34962.66","0.028601"],["34969.66","0.172557"],["34979.81","0"]],"u":20010035,"seq":14108036858}}'
2023-11-02 14:54:17,749 DEBUG ++Rcv decoded: fin=1 opcode=1 data=b'{"topic":"orderbook.50.BTCUSDC","ts":1698936857663,"type":"delta","data":{"s":"BTCUSDC","b":[],"a":[["34962.66","0.028601"],["34969.66","0.172557"],["34979.81","0"]],"u":20010035,"seq":14108036858}}'
2023-11-02 14:54:17,788 DEBUG ++Rcv raw: b'\x81~\x00\xac{"topic":"orderbook.50.BTCUSDC","ts":1698936857703,"type":"delta","data":{"s":"BTCUSDC","b":[["34939.85","0.1875"],["34943.76","0"]],"a":[],"u":20010036,"seq":14108036871}}'
2023-11-02 14:54:17,789 DEBUG ++Rcv decoded: fin=1 opcode=1 data=b'{"topic":"orderbook.50.BTCUSDC","ts":1698936857703,"type":"delta","data":{"s":"BTCUSDC","b":[["34939.85","0.1875"],["34943.76","0"]],"a":[],"u":20010036,"seq":14108036871}}'
2023-11-02 14:54:17,809 DEBUG ++Rcv raw: b'\x81~\x00\xd6{"topic":"orderbook.50.BTCUSDC","ts":1698936857724,"type":"delta","data":{"s":"BTCUSDC","b":[["34937.76","0.029857"],["34949.29","0"]],"a":[["34962.65","0.008756"],["34974.82","0"]],"u":20010037,"seq":14108036878}}'
2023-11-02 14:54:17,809 DEBUG ++Rcv decoded: fin=1 opcode=1 data=b'{"topic":"orderbook.50.BTCUSDC","ts":1698936857724,"type":"delta","data":{"s":"BTCUSDC","b":[["34937.76","0.029857"],["34949.29","0"]],"a":[["34962.65","0.008756"],["34974.82","0"]],"u":20010037,"seq":14108036878}}'
2023-11-02 14:54:17,849 DEBUG ++Rcv raw: b'\x81~\x00\xd6{"topic":"orderbook.50.BTCUSDC","ts":1698936857763,"type":"delta","data":{"s":"BTCUSDC","b":[["34937.39","0.278379"],["34944.07","0"]],"a":[["34979.81","0.049142"],["34962.67","0"]],"u":20010038,"seq":14108036898}}'
2023-11-02 14:54:17,849 DEBUG ++Rcv decoded: fin=1 opcode=1 data=b'{"topic":"orderbook.50.BTCUSDC","ts":1698936857763,"type":"delta","data":{"s":"BTCUSDC","b":[["34937.39","0.278379"],["34944.07","0"]],"a":[["34979.81","0.049142"],["34962.67","0"]],"u":20010038,"seq":14108036898}}'
2023-11-02 14:54:17,889 DEBUG ++Rcv raw: b'\x81~\x00\xfd{"topic":"orderbook.50.BTCUSDC","ts":1698936857803,"type":"delta","data":{"s":"BTCUSDC","b":[],"a":[["34962.18","0.036291"],["34962.19","0.064913"],["34965.02","0.0859"],["34978.78","0"],["34978.9","0"],["34979.81","0"]],"u":20010039,"seq":14108036923}}'
2023-11-02 14:54:17,889 DEBUG ++Rcv decoded: fin=1 opcode=1 data=b'{"topic":"orderbook.50.BTCUSDC","ts":1698936857803,"type":"delta","data":{"s":"BTCUSDC","b":[],"a":[["34962.18","0.036291"],["34962.19","0.064913"],["34965.02","0.0859"],["34978.78","0"],["34978.9","0"],["34979.81","0"]],"u":20010039,"seq":14108036923}}'
2023-11-02 14:54:17,909 DEBUG ++Rcv raw: b'\x81~\x01${"topic":"orderbook.50.BTCUSDC","ts":1698936857824,"type":"delta","data":{"s":"BTCUSDC","b":[["34936.51","0.823863"],["34954.9","0"]],"a":[["34965.01","0.051548"],["34978.78","0.0859"],["34978.9","0.002162"],["34965.02","0"],["34962.19","0"],["34963.97","0"]],"u":20010040,"seq":14108036933}}'
2023-11-02 14:54:17,909 DEBUG ++Rcv decoded: fin=1 opcode=1 data=b'{"topic":"orderbook.50.BTCUSDC","ts":1698936857824,"type":"delta","data":{"s":"BTCUSDC","b":[["34936.51","0.823863"],["34954.9","0"]],"a":[["34965.01","0.051548"],["34978.78","0.0859"],["34978.9","0.002162"],["34965.02","0"],["34962.19","0"],["34963.97","0"]],"u":20010040,"seq":14108036933}}'
2023-11-02 14:54:17,928 DEBUG ++Rcv raw: b'\x81~\x00\xc5{"topic":"orderbook.50.BTCUSDC","ts":1698936857843,"type":"delta","data":{"s":"BTCUSDC","b":[],"a":[["34962.18","0.022423"],["34963.97","0.03432"],["34965.01","0"]],"u":20010041,"seq":14108036939}}'
2023-11-02 14:54:17,929 DEBUG ++Rcv decoded: fin=1 opcode=1 data=b'{"topic":"orderbook.50.BTCUSDC","ts":1698936857843,"type":"delta","data":{"s":"BTCUSDC","b":[],"a":[["34962.18","0.022423"],["34963.97","0.03432"],["34965.01","0"]],"u":20010041,"seq":14108036939}}'
2023-11-02 14:54:17,969 DEBUG ++Rcv raw: b'\x81~\x00\xae{"topic":"orderbook.50.BTCUSDC","ts":1698936857884,"type":"delta","data":{"s":"BTCUSDC","b":[],"a":[["34979.81","0.049142"],["34962.66","0"]],"u":20010042,"seq":14108036964}}'
2023-11-02 14:54:17,969 DEBUG ++Rcv decoded: fin=1 opcode=1 data=b'{"topic":"orderbook.50.BTCUSDC","ts":1698936857884,"type":"delta","data":{"s":"BTCUSDC","b":[],"a":[["34979.81","0.049142"],["34962.66","0"]],"u":20010042,"seq":14108036964}}'
2023-11-02 14:54:17,989 DEBUG ++Rcv raw: b'\x81~\x00\xae{"topic":"orderbook.50.BTCUSDC","ts":1698936857904,"type":"delta","data":{"s":"BTCUSDC","b":[],"a":[["34980.48","0.023472"],["34962.18","0"]],"u":20010043,"seq":14108036968}}'
2023-11-02 14:54:17,990 DEBUG ++Rcv decoded: fin=1 opcode=1 data=b'{"topic":"orderbook.50.BTCUSDC","ts":1698936857904,"type":"delta","data":{"s":"BTCUSDC","b":[],"a":[["34980.48","0.023472"],["34962.18","0"]],"u":20010043,"seq":14108036968}}'
2023-11-02 14:54:18,009 DEBUG ++Rcv raw: b'\x81~\x00\xd3{"topic":"orderbook.50.BTCUSDC","ts":1698936857924,"type":"delta","data":{"s":"BTCUSDC","b":[["34954.91","0.00057"],["34941.45","0.028"],["34937.39","0"],["34936.51","0"]],"a":[],"u":20010044,"seq":14108036984}}'
2023-11-02 14:54:18,010 DEBUG ++Rcv decoded: fin=1 opcode=1 data=b'{"topic":"orderbook.50.BTCUSDC","ts":1698936857924,"type":"delta","data":{"s":"BTCUSDC","b":[["34954.91","0.00057"],["34941.45","0.028"],["34937.39","0"],["34936.51","0"]],"a":[],"u":20010044,"seq":14108036984}}'
2023-11-02 14:54:18,049 DEBUG ++Rcv raw: b'\x81~\x00\xab{"topic":"orderbook.50.BTCUSDC","ts":1698936857964,"type":"delta","data":{"s":"BTCUSDC","b":[],"a":[["34980.5","0.0859"],["34962.65","0"]],"u":20010045,"seq":14108037010}}'
2023-11-02 14:54:18,050 DEBUG ++Rcv decoded: fin=1 opcode=1 data=b'{"topic":"orderbook.50.BTCUSDC","ts":1698936857964,"type":"delta","data":{"s":"BTCUSDC","b":[],"a":[["34980.5","0.0859"],["34962.65","0"]],"u":20010045,"seq":14108037010}}'
2023-11-02 14:54:18,069 DEBUG ++Rcv raw: b'\x81~\x01\x13{"topic":"orderbook.50.BTCUSDC","ts":1698936857984,"type":"delta","data":{"s":"BTCUSDC","b":[["34952.33","0.114441"],["34951.47","0.0542"],["34937.76","0"]],"a":[["34962.17","0.028602"],["34968.86","0.00057"],["34980.5","0"],["34964.25","0"]],"u":20010046,"seq":14108037019}}'
2023-11-02 14:54:18,070 DEBUG ++Rcv decoded: fin=1 opcode=1 data=b'{"topic":"orderbook.50.BTCUSDC","ts":1698936857984,"type":"delta","data":{"s":"BTCUSDC","b":[["34952.33","0.114441"],["34951.47","0.0542"],["34937.76","0"]],"a":[["34962.17","0.028602"],["34968.86","0.00057"],["34980.5","0"],["34964.25","0"]],"u":20010046,"seq":14108037019}}'
2023-11-02 14:54:18,088 DEBUG ++Rcv raw: b'\x81~\x01({"topic":"orderbook.50.BTCUSDC","ts":1698936858003,"type":"delta","data":{"s":"BTCUSDC","b":[["34952.99","0.068665"],["34951.27","0.051542"],["34937.76","0.029857"],["34954.91","0"],["34950.04","0"],["34951.48","0"]],"a":[["34963.96","0.008756"],["34980.48","0"]],"u":20010047,"seq":14108037025}}'
2023-11-02 14:54:18,089 DEBUG ++Rcv decoded: fin=1 opcode=1 data=b'{"topic":"orderbook.50.BTCUSDC","ts":1698936858003,"type":"delta","data":{"s":"BTCUSDC","b":[["34952.99","0.068665"],["34951.27","0.051542"],["34937.76","0.029857"],["34954.91","0"],["34950.04","0"],["34951.48","0"]],"a":[["34963.96","0.008756"],["34980.48","0"]],"u":20010047,"seq":14108037025}}'
2023-11-02 14:54:18,109 DEBUG ++Rcv raw: b'\x81~\x00\xae{"topic":"orderbook.50.BTCUSDC","ts":1698936858024,"type":"delta","data":{"s":"BTCUSDC","b":[],"a":[["34980.48","0.023472"],["34968.86","0"]],"u":20010048,"seq":14108037031}}'
2023-11-02 14:54:18,110 DEBUG ++Rcv decoded: fin=1 opcode=1 data=b'{"topic":"orderbook.50.BTCUSDC","ts":1698936858024,"type":"delta","data":{"s":"BTCUSDC","b":[],"a":[["34980.48","0.023472"],["34968.86","0"]],"u":20010048,"seq":14108037031}}'
2023-11-02 14:54:18,130 DEBUG ++Rcv raw: b'\x81~\x00\xff{"topic":"orderbook.50.BTCUSDC","ts":1698936858044,"type":"delta","data":{"s":"BTCUSDC","b":[["34954.28","0.028603"],["34952.92","0"]],"a":[["34962.16","0.008756"],["34966.61","0.028603"],["34963.96","0"],["34965.32","0"]],"u":20010049,"seq":14108037041}}'
2023-11-02 14:54:18,130 DEBUG ++Rcv decoded: fin=1 opcode=1 data=b'{"topic":"orderbook.50.BTCUSDC","ts":1698936858044,"type":"delta","data":{"s":"BTCUSDC","b":[["34954.28","0.028603"],["34952.92","0"]],"a":[["34962.16","0.008756"],["34966.61","0.028603"],["34963.96","0"],["34965.32","0"]],"u":20010049,"seq":14108037041}}'
2023-11-02 14:54:18,149 DEBUG ++Rcv raw: b'\x81~\x00\xae{"topic":"orderbook.50.BTCUSDC","ts":1698936858064,"type":"delta","data":{"s":"BTCUSDC","b":[["34951.48","0.001516"],["34937.76","0"]],"a":[],"u":20010050,"seq":14108037049}}'
2023-11-02 14:54:18,149 DEBUG ++Rcv decoded: fin=1 opcode=1 data=b'{"topic":"orderbook.50.BTCUSDC","ts":1698936858064,"type":"delta","data":{"s":"BTCUSDC","b":[["34951.48","0.001516"],["34937.76","0"]],"a":[],"u":20010050,"seq":14108037049}}'
2023-11-02 14:54:18,170 DEBUG ++Rcv raw: b'\x81~\x00\xd3{"topic":"orderbook.50.BTCUSDC","ts":1698936858084,"type":"delta","data":{"s":"BTCUSDC","b":[["34937.76","0.029857"],["34951.49","0"]],"a":[["34980.5","0.0859"],["34962.17","0"]],"u":20010051,"seq":14108037055}}'
2023-11-02 14:54:18,170 DEBUG ++Rcv decoded: fin=1 opcode=1 data=b'{"topic":"orderbook.50.BTCUSDC","ts":1698936858084,"type":"delta","data":{"s":"BTCUSDC","b":[["34937.76","0.029857"],["34951.49","0"]],"a":[["34980.5","0.0859"],["34962.17","0"]],"u":20010051,"seq":14108037055}}'
2023-11-02 14:54:18,209 DEBUG ++Rcv raw: b'\x81~\x00\xab{"topic":"orderbook.50.BTCUSDC","ts":1698936858123,"type":"delta","data":{"s":"BTCUSDC","b":[["34949.3","0.1875"],["34942.08","0"]],"a":[],"u":20010052,"seq":14108037068}}'
2023-11-02 14:54:18,209 DEBUG ++Rcv decoded: fin=1 opcode=1 data=b'{"topic":"orderbook.50.BTCUSDC","ts":1698936858123,"type":"delta","data":{"s":"BTCUSDC","b":[["34949.3","0.1875"],["34942.08","0"]],"a":[],"u":20010052,"seq":14108037068}}'
2023-11-02 14:54:18,249 DEBUG ++Rcv raw: b'\x81~\x00\xae{"topic":"orderbook.50.BTCUSDC","ts":1698936858164,"type":"delta","data":{"s":"BTCUSDC","b":[],"a":[["34962.15","0.028602"],["34978.73","0"]],"u":20010053,"seq":14108037098}}'
2023-11-02 14:54:18,250 DEBUG ++Rcv decoded: fin=1 opcode=1 data=b'{"topic":"orderbook.50.BTCUSDC","ts":1698936858164,"type":"delta","data":{"s":"BTCUSDC","b":[],"a":[["34962.15","0.028602"],["34978.73","0"]],"u":20010053,"seq":14108037098}}'
2023-11-02 14:54:18,269 DEBUG ++Rcv raw: b'\x81~\x00\xfd{"topic":"orderbook.50.BTCUSDC","ts":1698936858184,"type":"delta","data":{"s":"BTCUSDC","b":[["34937.39","0.278379"],["34949.3","0"]],"a":[["34962.14","0.022417"],["34977.87","0.285895"],["34980.5","0"],["34980.48","0"]],"u":20010054,"seq":14108037107}}'
2023-11-02 14:54:18,270 DEBUG ++Rcv decoded: fin=1 opcode=1 data=b'{"topic":"orderbook.50.BTCUSDC","ts":1698936858184,"type":"delta","data":{"s":"BTCUSDC","b":[["34937.39","0.278379"],["34949.3","0"]],"a":[["34962.14","0.022417"],["34977.87","0.285895"],["34980.5","0"],["34980.48","0"]],"u":20010054,"seq":14108037107}}'
2023-11-02 14:54:18,309 DEBUG ++Rcv raw: b'\x81~\x00\xae{"topic":"orderbook.50.BTCUSDC","ts":1698936858224,"type":"delta","data":{"s":"BTCUSDC","b":[],"a":[["34962.06","0.075773"],["34979.81","0"]],"u":20010055,"seq":14108037117}}'
2023-11-02 14:54:18,309 DEBUG ++Rcv decoded: fin=1 opcode=1 data=b'{"topic":"orderbook.50.BTCUSDC","ts":1698936858224,"type":"delta","data":{"s":"BTCUSDC","b":[],"a":[["34962.06","0.075773"],["34979.81","0"]],"u":20010055,"seq":14108037117}}'
2023-11-02 14:54:18,329 DEBUG ++Rcv raw: b'\x81~\x01!{"topic":"orderbook.50.BTCUSDC","ts":1698936858244,"type":"delta","data":{"s":"BTCUSDC","b":[["34944.96","0.000261"],["34937.39","0"]],"a":[["34961.92","0.000239"],["34963.96","0.03"],["34965.02","0.0859"],["34963.97","0"],["34978.78","0"],["34978.9","0"]],"u":20010056,"seq":14108037125}}'
2023-11-02 14:54:18,329 DEBUG ++Rcv decoded: fin=1 opcode=1 data=b'{"topic":"orderbook.50.BTCUSDC","ts":1698936858244,"type":"delta","data":{"s":"BTCUSDC","b":[["34944.96","0.000261"],["34937.39","0"]],"a":[["34961.92","0.000239"],["34963.96","0.03"],["34965.02","0.0859"],["34963.97","0"],["34978.78","0"],["34978.9","0"]],"u":20010056,"seq":14108037125}}'
2023-11-02 14:54:18,349 DEBUG ++Rcv raw: b'\x81~\x00\xd7{"topic":"orderbook.50.BTCUSDC","ts":1698936858264,"type":"delta","data":{"s":"BTCUSDC","b":[],"a":[["34961.91","0.008756"],["34965.01","0.051544"],["34962.06","0"],["34962.16","0"]],"u":20010057,"seq":14108037135}}'
2023-11-02 14:54:18,349 DEBUG ++Rcv decoded: fin=1 opcode=1 data=b'{"topic":"orderbook.50.BTCUSDC","ts":1698936858264,"type":"delta","data":{"s":"BTCUSDC","b":[],"a":[["34961.91","0.008756"],["34965.01","0.051544"],["34962.06","0"],["34962.16","0"]],"u":20010057,"seq":14108037135}}'
2023-11-02 14:54:18,369 DEBUG ++Rcv raw: b'\x81~\x00\xac{"topic":"orderbook.50.BTCUSDC","ts":1698936858284,"type":"delta","data":{"s":"BTCUSDC","b":[],"a":[["34978.78","0.0859"],["34962.15","0"]],"u":20010058,"seq":14108037146}}'
2023-11-02 14:54:18,370 DEBUG ++Rcv decoded: fin=1 opcode=1 data=b'{"topic":"orderbook.50.BTCUSDC","ts":1698936858284,"type":"delta","data":{"s":"BTCUSDC","b":[],"a":[["34978.78","0.0859"],["34962.15","0"]],"u":20010058,"seq":14108037146}}'
2023-11-02 14:54:18,390 DEBUG ++Rcv raw: b'\x81~\x00\xad{"topic":"orderbook.50.BTCUSDC","ts":1698936858304,"type":"delta","data":{"s":"BTCUSDC","b":[],"a":[["34978.9","0.002162"],["34962.14","0"]],"u":20010059,"seq":14108037150}}'
2023-11-02 14:54:18,390 DEBUG ++Rcv decoded: fin=1 opcode=1 data=b'{"topic":"orderbook.50.BTCUSDC","ts":1698936858304,"type":"delta","data":{"s":"BTCUSDC","b":[],"a":[["34978.9","0.002162"],["34962.14","0"]],"u":20010059,"seq":14108037150}}'
2023-11-02 14:54:18,468 DEBUG ++Rcv raw: b'\x81~\x00\xac{"topic":"orderbook.50.BTCUSDC","ts":1698936858383,"type":"delta","data":{"s":"BTCUSDC","b":[],"a":[["34961.9","0.028602"],["34978.9","0"]],"u":20010060,"seq":14108037164}}'
2023-11-02 14:54:18,469 DEBUG ++Rcv decoded: fin=1 opcode=1 data=b'{"topic":"orderbook.50.BTCUSDC","ts":1698936858383,"type":"delta","data":{"s":"BTCUSDC","b":[],"a":[["34961.9","0.028602"],["34978.9","0"]],"u":20010060,"seq":14108037164}}'
2023-11-02 14:54:18,489 DEBUG ++Rcv raw: b'\x81~\x00\xd6{"topic":"orderbook.50.BTCUSDC","ts":1698936858403,"type":"delta","data":{"s":"BTCUSDC","b":[["34944.94","0.068652"],["34937.76","0"]],"a":[["34973.47","0.112507"],["34978.78","0"]],"u":20010061,"seq":14108037172}}'
2023-11-02 14:54:18,489 DEBUG ++Rcv decoded: fin=1 opcode=1 data=b'{"topic":"orderbook.50.BTCUSDC","ts":1698936858403,"type":"delta","data":{"s":"BTCUSDC","b":[["34944.94","0.068652"],["34937.76","0"]],"a":[["34973.47","0.112507"],["34978.78","0"]],"u":20010061,"seq":14108037172}}'
2023-11-02 14:54:18,549 DEBUG ++Rcv raw: b'\x81~\x00\xae{"topic":"orderbook.50.BTCUSDC","ts":1698936858463,"type":"delta","data":{"s":"BTCUSDC","b":[["34937.76","0.029857"],["34957.74","0"]],"a":[],"u":20010062,"seq":14108037191}}'
2023-11-02 14:54:18,549 DEBUG ++Rcv decoded: fin=1 opcode=1 data=b'{"topic":"orderbook.50.BTCUSDC","ts":1698936858463,"type":"delta","data":{"s":"BTCUSDC","b":[["34937.76","0.029857"],["34957.74","0"]],"a":[],"u":20010062,"seq":14108037191}}'
2023-11-02 14:54:18,569 DEBUG ++Rcv raw: b'\x81~\x00\xff{"topic":"orderbook.50.BTCUSDC","ts":1698936858483,"type":"delta","data":{"s":"BTCUSDC","b":[["34957.32","0.057212"],["34945.17","0.000261"],["34939.85","0"],["34937.76","0"]],"a":[["34961.76","0.000239"],["34978.32","0"]],"u":20010063,"seq":14108037197}}'
2023-11-02 14:54:18,569 DEBUG ++Rcv decoded: fin=1 opcode=1 data=b'{"topic":"orderbook.50.BTCUSDC","ts":1698936858483,"type":"delta","data":{"s":"BTCUSDC","b":[["34957.32","0.057212"],["34945.17","0.000261"],["34939.85","0"],["34937.76","0"]],"a":[["34961.76","0.000239"],["34978.32","0"]],"u":20010063,"seq":14108037197}}'
2023-11-02 14:54:18,590 DEBUG ++Rcv raw: b'\x81~\x00\xd6{"topic":"orderbook.50.BTCUSDC","ts":1698936858504,"type":"delta","data":{"s":"BTCUSDC","b":[["34957.33","0.034336"],["34954.71","0.05154"],["34940.24","0"],["34954.01","0"]],"a":[],"u":20010064,"seq":14108037204}}'
2023-11-02 14:54:18,590 DEBUG ++Rcv decoded: fin=1 opcode=1 data=b'{"topic":"orderbook.50.BTCUSDC","ts":1698936858504,"type":"delta","data":{"s":"BTCUSDC","b":[["34957.33","0.034336"],["34954.71","0.05154"],["34940.24","0"],["34954.01","0"]],"a":[],"u":20010064,"seq":14108037204}}'
2023-11-02 14:54:18,609 DEBUG ++Rcv raw: b'\x81~\x00\xae{"topic":"orderbook.50.BTCUSDC","ts":1698936858523,"type":"delta","data":{"s":"BTCUSDC","b":[],"a":[["34978.32","0.114411"],["34961.91","0"]],"u":20010065,"seq":14108037216}}'
2023-11-02 14:54:18,609 DEBUG ++Rcv decoded: fin=1 opcode=1 data=b'{"topic":"orderbook.50.BTCUSDC","ts":1698936858523,"type":"delta","data":{"s":"BTCUSDC","b":[],"a":[["34978.32","0.114411"],["34961.91","0"]],"u":20010065,"seq":14108037216}}'
2023-11-02 14:54:18,669 DEBUG ++Rcv raw: b'\x81~\x00\xd3{"topic":"orderbook.50.BTCUSDC","ts":1698936858584,"type":"delta","data":{"s":"BTCUSDC","b":[],"a":[["34963.6","0.057202"],["34978.78","0.0859"],["34963.98","0"],["34961.9","0"]],"u":20010066,"seq":14108037254}}'
2023-11-02 14:54:18,669 DEBUG ++Rcv decoded: fin=1 opcode=1 data=b'{"topic":"orderbook.50.BTCUSDC","ts":1698936858584,"type":"delta","data":{"s":"BTCUSDC","b":[],"a":[["34963.6","0.057202"],["34978.78","0.0859"],["34963.98","0"],["34961.9","0"]],"u":20010066,"seq":14108037254}}'
2023-11-02 14:54:18,709 DEBUG ++Rcv raw: b'\x81~\x00\xad{"topic":"orderbook.50.BTCUSDC","ts":1698936858623,"type":"delta","data":{"s":"BTCUSDC","b":[["34940.24","0.05724"],["34944.96","0"]],"a":[],"u":20010067,"seq":14108037330}}'
2023-11-02 14:54:18,709 DEBUG ++Rcv decoded: fin=1 opcode=1 data=b'{"topic":"orderbook.50.BTCUSDC","ts":1698936858623,"type":"delta","data":{"s":"BTCUSDC","b":[["34940.24","0.05724"],["34944.96","0"]],"a":[],"u":20010067,"seq":14108037330}}'
2023-11-02 14:54:18,729 DEBUG ++Rcv raw: b'\x81~\x00\xac{"topic":"orderbook.50.BTCUSDC","ts":1698936858643,"type":"delta","data":{"s":"BTCUSDC","b":[["34939.85","0.1875"],["34941.45","0"]],"a":[],"u":20010068,"seq":14108037369}}'
2023-11-02 14:54:18,729 DEBUG ++Rcv decoded: fin=1 opcode=1 data=b'{"topic":"orderbook.50.BTCUSDC","ts":1698936858643,"type":"delta","data":{"s":"BTCUSDC","b":[["34939.85","0.1875"],["34941.45","0"]],"a":[],"u":20010068,"seq":14108037369}}'
2023-11-02 14:54:18,770 DEBUG ++Rcv raw: b'\x81~\x00\xae{"topic":"orderbook.50.BTCUSDC","ts":1698936858684,"type":"delta","data":{"s":"BTCUSDC","b":[],"a":[["34961.75","0.028602"],["34978.78","0"]],"u":20010069,"seq":14108037401}}'
2023-11-02 14:54:18,770 DEBUG ++Rcv decoded: fin=1 opcode=1 data=b'{"topic":"orderbook.50.BTCUSDC","ts":1698936858684,"type":"delta","data":{"s":"BTCUSDC","b":[],"a":[["34961.75","0.028602"],["34978.78","0"]],"u":20010069,"seq":14108037401}}'
2023-11-02 14:54:18,823 DEBUG ++Rcv raw: b'\x81~\x00\xac{"topic":"orderbook.50.BTCUSDC","ts":1698936858723,"type":"delta","data":{"s":"BTCUSDC","b":[],"a":[["34978.78","0.0859"],["34961.92","0"]],"u":20010070,"seq":14108037415}}'
2023-11-02 14:54:18,824 DEBUG ++Rcv decoded: fin=1 opcode=1 data=b'{"topic":"orderbook.50.BTCUSDC","ts":1698936858723,"type":"delta","data":{"s":"BTCUSDC","b":[],"a":[["34978.78","0.0859"],["34961.92","0"]],"u":20010070,"seq":14108037415}}'
2023-11-02 14:54:18,849 DEBUG ++Rcv raw: b'\x81~\x00\xc1{"topic":"orderbook.50.BTCUSDC","ts":1698936858763,"type":"delta","data":{"s":"BTCUSDC","b":[],"a":[["34969.67","0.1875"],["34974.89","0.021"],["34975.33","0"]],"u":20010071,"seq":14108037445}}'
2023-11-02 14:54:18,849 DEBUG ++Rcv decoded: fin=1 opcode=1 data=b'{"topic":"orderbook.50.BTCUSDC","ts":1698936858763,"type":"delta","data":{"s":"BTCUSDC","b":[],"a":[["34969.67","0.1875"],["34974.89","0.021"],["34975.33","0"]],"u":20010071,"seq":14108037445}}'
2023-11-02 14:54:18,868 DEBUG ++Rcv raw: b'\x81~\x00\xc5{"topic":"orderbook.50.BTCUSDC","ts":1698936858783,"type":"delta","data":{"s":"BTCUSDC","b":[],"a":[["34968.8","0.114387"],["34969.66","0.103922"],["34978.78","0"]],"u":20010072,"seq":14108037451}}'
2023-11-02 14:54:18,869 DEBUG ++Rcv decoded: fin=1 opcode=1 data=b'{"topic":"orderbook.50.BTCUSDC","ts":1698936858783,"type":"delta","data":{"s":"BTCUSDC","b":[],"a":[["34968.8","0.114387"],["34969.66","0.103922"],["34978.78","0"]],"u":20010072,"seq":14108037451}}'
2023-11-02 14:54:18,929 DEBUG ++Rcv raw: b'\x81~\x00\xd2{"topic":"orderbook.50.BTCUSDC","ts":1698936858843,"type":"delta","data":{"s":"BTCUSDC","b":[["34942.01","0.028"],["34939.85","0"]],"a":[["34960.89","0.07525"],["34961.76","0"]],"u":20010073,"seq":14108037477}}'
2023-11-02 14:54:18,929 DEBUG ++Rcv decoded: fin=1 opcode=1 data=b'{"topic":"orderbook.50.BTCUSDC","ts":1698936858843,"type":"delta","data":{"s":"BTCUSDC","b":[["34942.01","0.028"],["34939.85","0"]],"a":[["34960.89","0.07525"],["34961.76","0"]],"u":20010073,"seq":14108037477}}'
2023-11-02 14:54:18,950 DEBUG ++Rcv raw: b'\x81~\x00\xfc{"topic":"orderbook.50.BTCUSDC","ts":1698936858864,"type":"delta","data":{"s":"BTCUSDC","b":[["34939.85","0.1875"],["34937.76","0.029857"],["34959.8","0"],["34958.14","0"]],"a":[["34961.74","0.008756"],["34978.32","0"]],"u":20010074,"seq":14108037487}}'
2023-11-02 14:54:18,950 DEBUG ++Rcv decoded: fin=1 opcode=1 data=b'{"topic":"orderbook.50.BTCUSDC","ts":1698936858864,"type":"delta","data":{"s":"BTCUSDC","b":[["34939.85","0.1875"],["34937.76","0.029857"],["34959.8","0"],["34958.14","0"]],"a":[["34961.74","0.008756"],["34978.32","0"]],"u":20010074,"seq":14108037487}}'
2023-11-02 14:54:18,969 DEBUG ++Rcv raw: b'\x81~\x01){"topic":"orderbook.50.BTCUSDC","ts":1698936858884,"type":"delta","data":{"s":"BTCUSDC","b":[["34957.33","0.036336"],["34956.42","0.0859"],["34952.44","0.00057"],["34937.76","0"]],"a":[["34960.15","0.003"],["34960.88","0.008756"],["34961.74","0"],["34967.46","0"]],"u":20010075,"seq":14108037510}}'
2023-11-02 14:54:18,970 DEBUG ++Rcv decoded: fin=1 opcode=1 data=b'{"topic":"orderbook.50.BTCUSDC","ts":1698936858884,"type":"delta","data":{"s":"BTCUSDC","b":[["34957.33","0.036336"],["34956.42","0.0859"],["34952.44","0.00057"],["34937.76","0"]],"a":[["34960.15","0.003"],["34960.88","0.008756"],["34961.74","0"],["34967.46","0"]],"u":20010075,"seq":14108037510}}'
2023-11-02 14:54:18,989 DEBUG ++Rcv raw: b'\x81~\x00\xee{"topic":"orderbook.50.BTCUSDC","ts":1698936858904,"type":"delta","data":{"s":"BTCUSDC","b":[["34957.54","0.057212"],["34956.43","0.052692"],["34957.32","0"]],"a":[["34978.32","0.114411"],["34960.89","0"]],"u":20010076,"seq":14108037518}}'
2023-11-02 14:54:18,989 DEBUG ++Rcv decoded: fin=1 opcode=1 data=b'{"topic":"orderbook.50.BTCUSDC","ts":1698936858904,"type":"delta","data":{"s":"BTCUSDC","b":[["34957.54","0.057212"],["34956.43","0.052692"],["34957.32","0"]],"a":[["34978.32","0.114411"],["34960.89","0"]],"u":20010076,"seq":14108037518}}'
2023-11-02 14:54:19,009 DEBUG ++Rcv raw: b'\x81~\x00\xec{"topic":"orderbook.50.BTCUSDC","ts":1698936858924,"type":"delta","data":{"s":"BTCUSDC","b":[["34957.33","0.002"],["34954.29","0.021602"],["34937.76","0.029857"],["34954.71","0"],["34952.44","0"]],"a":[],"u":20010077,"seq":14108037526}}'
2023-11-02 14:54:19,009 DEBUG ++Rcv decoded: fin=1 opcode=1 data=b'{"topic":"orderbook.50.BTCUSDC","ts":1698936858924,"type":"delta","data":{"s":"BTCUSDC","b":[["34957.33","0.002"],["34954.29","0.021602"],["34937.76","0.029857"],["34954.71","0"],["34952.44","0"]],"a":[],"u":20010077,"seq":14108037526}}'
2023-11-02 14:54:19,029 DEBUG ++Rcv raw: b'\x81~\x00\xd4{"topic":"orderbook.50.BTCUSDC","ts":1698936858943,"type":"delta","data":{"s":"BTCUSDC","b":[["34950.04","0.000932"],["34937.76","0"]],"a":[["34978.78","0.0859"],["34961.75","0"]],"u":20010078,"seq":14108037549}}'
2023-11-02 14:54:19,029 DEBUG ++Rcv decoded: fin=1 opcode=1 data=b'{"topic":"orderbook.50.BTCUSDC","ts":1698936858943,"type":"delta","data":{"s":"BTCUSDC","b":[["34950.04","0.000932"],["34937.76","0"]],"a":[["34978.78","0.0859"],["34961.75","0"]],"u":20010078,"seq":14108037549}}'
2023-11-02 14:54:19,048 DEBUG ++Rcv raw: b'\x81~\x00\xae{"topic":"orderbook.50.BTCUSDC","ts":1698936858963,"type":"delta","data":{"s":"BTCUSDC","b":[["34937.76","0.029857"],["34951.48","0"]],"a":[],"u":20010079,"seq":14108037562}}'
2023-11-02 14:54:19,049 DEBUG ++Rcv decoded: fin=1 opcode=1 data=b'{"topic":"orderbook.50.BTCUSDC","ts":1698936858963,"type":"delta","data":{"s":"BTCUSDC","b":[["34937.76","0.029857"],["34951.48","0"]],"a":[],"u":20010079,"seq":14108037562}}'
2023-11-02 14:54:19,089 DEBUG ++Rcv raw: b'\x81~\x00\xae{"topic":"orderbook.50.BTCUSDC","ts":1698936859003,"type":"delta","data":{"s":"BTCUSDC","b":[["34937.39","0.278379"],["34945.17","0"]],"a":[],"u":20010080,"seq":14108037601}}'
2023-11-02 14:54:19,089 DEBUG ++Rcv decoded: fin=1 opcode=1 data=b'{"topic":"orderbook.50.BTCUSDC","ts":1698936859003,"type":"delta","data":{"s":"BTCUSDC","b":[["34937.39","0.278379"],["34945.17","0"]],"a":[],"u":20010080,"seq":14108037601}}'
2023-11-02 14:54:19,129 DEBUG ++Rcv raw: b'\x81~\x00\xae{"topic":"orderbook.50.BTCUSDC","ts":1698936859044,"type":"delta","data":{"s":"BTCUSDC","b":[],"a":[["34960.14","0.028604"],["34978.78","0"]],"u":20010081,"seq":14108037612}}'
2023-11-02 14:54:19,129 DEBUG ++Rcv decoded: fin=1 opcode=1 data=b'{"topic":"orderbook.50.BTCUSDC","ts":1698936859044,"type":"delta","data":{"s":"BTCUSDC","b":[],"a":[["34960.14","0.028604"],["34978.78","0"]],"u":20010081,"seq":14108037612}}'
2023-11-02 14:54:19,189 DEBUG ++Rcv raw: b'\x81~\x00\xae{"topic":"orderbook.50.BTCUSDC","ts":1698936859104,"type":"delta","data":{"s":"BTCUSDC","b":[],"a":[["34960.13","0.008756"],["34960.88","0"]],"u":20010082,"seq":14108037654}}'
2023-11-02 14:54:19,190 DEBUG ++Rcv decoded: fin=1 opcode=1 data=b'{"topic":"orderbook.50.BTCUSDC","ts":1698936859104,"type":"delta","data":{"s":"BTCUSDC","b":[],"a":[["34960.13","0.008756"],["34960.88","0"]],"u":20010082,"seq":14108037654}}'
2023-11-02 14:54:19,213 DEBUG ++Rcv raw: b'\x81~\x00\xc5{"topic":"orderbook.50.BTCUSDC","ts":1698936859123,"type":"delta","data":{"s":"BTCUSDC","b":[["34956.43","0.029523"]],"a":[["34958.74","0.076595"],["34960.14","0"]],"u":20010083,"seq":14108037677}}'
2023-11-02 14:54:19,213 DEBUG ++Rcv decoded: fin=1 opcode=1 data=b'{"topic":"orderbook.50.BTCUSDC","ts":1698936859123,"type":"delta","data":{"s":"BTCUSDC","b":[["34956.43","0.029523"]],"a":[["34958.74","0.076595"],["34960.14","0"]],"u":20010083,"seq":14108037677}}'
2023-11-02 14:54:19,229 DEBUG ++Rcv raw: b'\x81~\x00\xff{"topic":"orderbook.50.BTCUSDC","ts":1698936859143,"type":"delta","data":{"s":"BTCUSDC","b":[["34957.54","0.006012"]],"a":[["34964","0.0324"],["34965.01","0.095574"],["34965.74","0.1875"],["34978.28","0"],["34978.32","0"]],"u":20010084,"seq":14108037697}}'
2023-11-02 14:54:19,229 DEBUG ++Rcv decoded: fin=1 opcode=1 data=b'{"topic":"orderbook.50.BTCUSDC","ts":1698936859143,"type":"delta","data":{"s":"BTCUSDC","b":[["34957.54","0.006012"]],"a":[["34964","0.0324"],["34965.01","0.095574"],["34965.74","0.1875"],["34978.28","0"],["34978.32","0"]],"u":20010084,"seq":14108037697}}'
2023-11-02 14:54:19,249 DEBUG ++Rcv raw: b'\x81~\x01\xd9{"topic":"orderbook.50.BTCUSDC","ts":1698936859163,"type":"delta","data":{"s":"BTCUSDC","b":[["34944.14","0.28617"],["34936.51","0.823863"],["34936.5","1.373091"],["34936.35","0.1875"],["34957.33","0"],["34957.54","0"],["34943.19","0"],["34956.42","0"]],"a":[["34961.27","0.000239"],["34963.3","0.0859"],["34965","0.077963"],["34965.01","0.04403"],["34965.73","0.112506"],["34977.69","0"],["34977.49","0"],["34966.16","0"],["34977.87","0"]],"u":20010085,"seq":14108037721}}'
2023-11-02 14:54:19,249 DEBUG ++Rcv decoded: fin=1 opcode=1 data=b'{"topic":"orderbook.50.BTCUSDC","ts":1698936859163,"type":"delta","data":{"s":"BTCUSDC","b":[["34944.14","0.28617"],["34936.51","0.823863"],["34936.5","1.373091"],["34936.35","0.1875"],["34957.33","0"],["34957.54","0"],["34943.19","0"],["34956.42","0"]],"a":[["34961.27","0.000239"],["34963.3","0.0859"],["34965","0.077963"],["34965.01","0.04403"],["34965.73","0.112506"],["34977.69","0"],["34977.49","0"],["34966.16","0"],["34977.87","0"]],"u":20010085,"seq":14108037721}}'
2023-11-02 14:54:19,269 DEBUG ++Rcv raw: b'\x81~\x01w{"topic":"orderbook.50.BTCUSDC","ts":1698936859183,"type":"delta","data":{"s":"BTCUSDC","b":[["34954.72","0.097501"],["34954.29","0.064965"],["34933.72","0.274807"],["34933.71","0.45801"],["34956.43","0"],["34943.77","0"],["34956","0"]],"a":[["34963.29","0.051548"],["34963.37","0.001"],["34965","0.051549"],["34977.23","0"],["34977.06","0"]],"u":20010086,"seq":14108037735}}'
2023-11-02 14:54:19,269 DEBUG ++Rcv decoded: fin=1 opcode=1 data=b'{"topic":"orderbook.50.BTCUSDC","ts":1698936859183,"type":"delta","data":{"s":"BTCUSDC","b":[["34954.72","0.097501"],["34954.29","0.064965"],["34933.72","0.274807"],["34933.71","0.45801"],["34956.43","0"],["34943.77","0"],["34956","0"]],"a":[["34963.29","0.051548"],["34963.37","0.001"],["34965","0.051549"],["34977.23","0"],["34977.06","0"]],"u":20010086,"seq":14108037735}}'
2023-11-02 14:54:19,289 DEBUG ++Rcv raw: b'\x81~\x00\xff{"topic":"orderbook.50.BTCUSDC","ts":1698936859203,"type":"delta","data":{"s":"BTCUSDC","b":[["34954.73","0.135639"],["34949.83","0.00057"],["34942.48","0.094326"],["34933.71","0"],["34954.72","0"],["34954.29","0"]],"a":[],"u":20010087,"seq":14108037765}}'
2023-11-02 14:54:19,289 DEBUG ++Rcv decoded: fin=1 opcode=1 data=b'{"topic":"orderbook.50.BTCUSDC","ts":1698936859203,"type":"delta","data":{"s":"BTCUSDC","b":[["34954.73","0.135639"],["34949.83","0.00057"],["34942.48","0.094326"],["34933.71","0"],["34954.72","0"],["34954.29","0"]],"a":[],"u":20010087,"seq":14108037765}}'
2023-11-02 14:54:19,309 DEBUG ++Rcv raw: b'\x81~\x00\xc5{"topic":"orderbook.50.BTCUSDC","ts":1698936859224,"type":"delta","data":{"s":"BTCUSDC","b":[["34954.73","0.077139"]],"a":[["34958.73","0.028605"],["34976.88","0"]],"u":20010088,"seq":14108037776}}'
2023-11-02 14:54:19,309 DEBUG ++Rcv decoded: fin=1 opcode=1 data=b'{"topic":"orderbook.50.BTCUSDC","ts":1698936859224,"type":"delta","data":{"s":"BTCUSDC","b":[["34954.73","0.077139"]],"a":[["34958.73","0.028605"],["34976.88","0"]],"u":20010088,"seq":14108037776}}'
2023-11-02 14:54:19,329 DEBUG ++Rcv raw: b'\x81~\x00\xd5{"topic":"orderbook.50.BTCUSDC","ts":1698936859244,"type":"delta","data":{"s":"BTCUSDC","b":[["34933.71","0.45801"],["34950.04","0"]],"a":[["34976.88","0.031073"],["34958.74","0"]],"u":20010089,"seq":14108037813}}'
2023-11-02 14:54:19,329 DEBUG ++Rcv decoded: fin=1 opcode=1 data=b'{"topic":"orderbook.50.BTCUSDC","ts":1698936859244,"type":"delta","data":{"s":"BTCUSDC","b":[["34933.71","0.45801"],["34950.04","0"]],"a":[["34976.88","0.031073"],["34958.74","0"]],"u":20010089,"seq":14108037813}}'
2023-11-02 14:54:19,430 DEBUG ++Rcv raw: b'\x81~\x00\xd4{"topic":"orderbook.50.BTCUSDC","ts":1698936859344,"type":"delta","data":{"s":"BTCUSDC","b":[["34955.13","0.057216"],["34933.71","0"]],"a":[["34977.06","0.0859"],["34958.73","0"]],"u":20010090,"seq":14108037870}}'
2023-11-02 14:54:19,430 DEBUG ++Rcv decoded: fin=1 opcode=1 data=b'{"topic":"orderbook.50.BTCUSDC","ts":1698936859344,"type":"delta","data":{"s":"BTCUSDC","b":[["34955.13","0.057216"],["34933.71","0"]],"a":[["34977.06","0.0859"],["34958.73","0"]],"u":20010090,"seq":14108037870}}'
2023-11-02 14:54:19,451 DEBUG ++Rcv raw: b'\x81~\x01\x10{"topic":"orderbook.50.BTCUSDC","ts":1698936859364,"type":"delta","data":{"s":"BTCUSDC","b":[["34955.14","0.034331"],["34954.73","0.051543"],["34955.13","0"]],"a":[["34962","0.0324"],["34977.23","0.1875"],["34960.13","0"],["34965.74","0"]],"u":20010091,"seq":14108037878}}'
2023-11-02 14:54:19,451 DEBUG ++Rcv decoded: fin=1 opcode=1 data=b'{"topic":"orderbook.50.BTCUSDC","ts":1698936859364,"type":"delta","data":{"s":"BTCUSDC","b":[["34955.14","0.034331"],["34954.73","0.051543"],["34955.13","0"]],"a":[["34962","0.0324"],["34977.23","0.1875"],["34960.13","0"],["34965.74","0"]],"u":20010091,"seq":14108037878}}'
2023-11-02 14:54:19,470 DEBUG ++Rcv raw: b'\x81~\x00\xfe{"topic":"orderbook.50.BTCUSDC","ts":1698936859384,"type":"delta","data":{"s":"BTCUSDC","b":[["34933.71","0.45801"],["34955.14","0"]],"a":[["34960.12","0.008756"],["34966.47","0.051544"],["34977.23","0"],["34965.73","0"]],"u":20010092,"seq":14108037886}}'
2023-11-02 14:54:19,470 DEBUG ++Rcv decoded: fin=1 opcode=1 data=b'{"topic":"orderbook.50.BTCUSDC","ts":1698936859384,"type":"delta","data":{"s":"BTCUSDC","b":[["34933.71","0.45801"],["34955.14","0"]],"a":[["34960.12","0.008756"],["34966.47","0.051544"],["34977.23","0"],["34965.73","0"]],"u":20010092,"seq":14108037886}}'
2023-11-02 14:54:19,496 DEBUG ++Rcv raw: b'\x81~\x00\xff{"topic":"orderbook.50.BTCUSDC","ts":1698936859404,"type":"delta","data":{"s":"BTCUSDC","b":[["34945.96","0.000261"],["34944.39","0.171707"],["34933.72","0"],["34933.71","0"]],"a":[["34961.09","0.000239"],["34977.06","0"]],"u":20010093,"seq":14108037892}}'
2023-11-02 14:54:19,496 DEBUG ++Rcv decoded: fin=1 opcode=1 data=b'{"topic":"orderbook.50.BTCUSDC","ts":1698936859404,"type":"delta","data":{"s":"BTCUSDC","b":[["34945.96","0.000261"],["34944.39","0.171707"],["34933.72","0"],["34933.71","0"]],"a":[["34961.09","0.000239"],["34977.06","0"]],"u":20010093,"seq":14108037892}}'
2023-11-02 14:54:19,609 DEBUG ++Rcv raw: b'\x81~\x00\xd4{"topic":"orderbook.50.BTCUSDC","ts":1698936859523,"type":"delta","data":{"s":"BTCUSDC","b":[["34946.09","0.000262"],["34942.66","0.0859"],["34936.5","0"],["34936.35","0"]],"a":[],"u":20010094,"seq":14108037935}}'
2023-11-02 14:54:19,609 DEBUG ++Rcv decoded: fin=1 opcode=1 data=b'{"topic":"orderbook.50.BTCUSDC","ts":1698936859523,"type":"delta","data":{"s":"BTCUSDC","b":[["34946.09","0.000262"],["34942.66","0.0859"],["34936.5","0"],["34936.35","0"]],"a":[],"u":20010094,"seq":14108037935}}'
2023-11-02 14:54:19,629 DEBUG ++Rcv raw: b'\x81~\x01u{"topic":"orderbook.50.BTCUSDC","ts":1698936859543,"type":"delta","data":{"s":"BTCUSDC","b":[["34936.5","1.373091"],["34936.35","0.1875"],["34933.72","0.274807"],["34933.71","0.45801"],["34932.01","0.325407"],["34952.99","0"],["34954.73","0"],["34947.83","0"],["34951.27","0"],["34954.7","0"]],"a":[["34957.29","0.076444"],["34961.27","0"]],"u":20010095,"seq":14108037955}}'
2023-11-02 14:54:19,629 DEBUG ++Rcv decoded: fin=1 opcode=1 data=b'{"topic":"orderbook.50.BTCUSDC","ts":1698936859543,"type":"delta","data":{"s":"BTCUSDC","b":[["34936.5","1.373091"],["34936.35","0.1875"],["34933.72","0.274807"],["34933.71","0.45801"],["34932.01","0.325407"],["34952.99","0"],["34954.73","0"],["34947.83","0"],["34951.27","0"],["34954.7","0"]],"a":[["34957.29","0.076444"],["34961.27","0"]],"u":20010095,"seq":14108037955}}'
2023-11-02 14:54:19,649 DEBUG ++Rcv raw: b'\x81~\x02\x00{"topic":"orderbook.50.BTCUSDC","ts":1698936859563,"type":"delta","data":{"s":"BTCUSDC","b":[["34954.59","0.026903"],["34954.45","0.093158"],["34954.29","0.053806"],["34950.04","0.067528"],["34947.83","0.051548"],["34954","0"],["34942.01","0"],["34950.03","0"],["34932.01","0"],["34944.18","0"]],"a":[["34957.28","0.008756"],["34957.29","0.03895"],["34960","0.0324"],["34961.58","0.0859"],["34963.62","0.1875"],["34976.85","0"],["34976.88","0"],["34976.24","0"],["34960.12","0"]],"u":20010096,"seq":14108037993}}'
2023-11-02 14:54:19,650 DEBUG ++Rcv decoded: fin=1 opcode=1 data=b'{"topic":"orderbook.50.BTCUSDC","ts":1698936859563,"type":"delta","data":{"s":"BTCUSDC","b":[["34954.59","0.026903"],["34954.45","0.093158"],["34954.29","0.053806"],["34950.04","0.067528"],["34947.83","0.051548"],["34954","0"],["34942.01","0"],["34950.03","0"],["34932.01","0"],["34944.18","0"]],"a":[["34957.28","0.008756"],["34957.29","0.03895"],["34960","0.0324"],["34961.58","0.0859"],["34963.62","0.1875"],["34976.85","0"],["34976.88","0"],["34976.24","0"],["34960.12","0"]],"u":20010096,"seq":14108037993}}'
2023-11-02 14:54:19,669 DEBUG ++Rcv raw: b'\x81~\x01\xc7{"topic":"orderbook.50.BTCUSDC","ts":1698936859584,"type":"delta","data":{"s":"BTCUSDC","b":[["34951.27","0.051549"],["34944.08","0.1875"],["34943.36","0.079497"],["34932.01","0.325407"],["34931.31","0.1875"],["34950.04","0"],["34953.78","0"],["34954.59","0"],["34954.45","0"],["34954.29","0"]],"a":[["34960.12","0.028604"],["34976.24","0.278379"],["34976.85","0.05718"],["34957.29","0"],["34963.62","0"],["34963.37","0"]],"u":20010097,"seq":14108038018}}'
2023-11-02 14:54:19,669 DEBUG ++Rcv decoded: fin=1 opcode=1 data=b'{"topic":"orderbook.50.BTCUSDC","ts":1698936859584,"type":"delta","data":{"s":"BTCUSDC","b":[["34951.27","0.051549"],["34944.08","0.1875"],["34943.36","0.079497"],["34932.01","0.325407"],["34931.31","0.1875"],["34950.04","0"],["34953.78","0"],["34954.59","0"],["34954.45","0"],["34954.29","0"]],"a":[["34960.12","0.028604"],["34976.24","0.278379"],["34976.85","0.05718"],["34957.29","0"],["34963.62","0"],["34963.37","0"]],"u":20010097,"seq":14108038018}}'
2023-11-02 14:54:19,689 DEBUG ++Rcv raw: b'\x81~\x01\xf9{"topic":"orderbook.50.BTCUSDC","ts":1698936859604,"type":"delta","data":{"s":"BTCUSDC","b":[["34932.01","0.112502"],["34927.27","0.1875"],["34925.01","1.32582"],["34925","2.2097"],["34924.42","0.4207"],["34923.58","0.1875"],["34922.1","0.91843"],["34944.14","0"],["34949.55","0"],["34954.28","0"],["34952.33","0"],["34949.83","0"],["34942.48","0"]],"a":[["34964.28","0.1875"],["34976.88","0.031073"],["34977.06","0.0859"],["34966.61","0"],["34968.8","0"],["34963.6","0"]],"u":20010098,"seq":14108038062}}'
2023-11-02 14:54:19,689 DEBUG ++Rcv decoded: fin=1 opcode=1 data=b'{"topic":"orderbook.50.BTCUSDC","ts":1698936859604,"type":"delta","data":{"s":"BTCUSDC","b":[["34932.01","0.112502"],["34927.27","0.1875"],["34925.01","1.32582"],["34925","2.2097"],["34924.42","0.4207"],["34923.58","0.1875"],["34922.1","0.91843"],["34944.14","0"],["34949.55","0"],["34954.28","0"],["34952.33","0"],["34949.83","0"],["34942.48","0"]],"a":[["34964.28","0.1875"],["34976.88","0.031073"],["34977.06","0.0859"],["34966.61","0"],["34968.8","0"],["34963.6","0"]],"u":20010098,"seq":14108038062}}'
2023-11-02 14:54:19,709 DEBUG ++Rcv raw: b'\x81~\x02\xc8{"topic":"orderbook.50.BTCUSDC","ts":1698936859623,"type":"delta","data":{"s":"BTCUSDC","b":[["34953.1","0.028605"],["34951.48","0.03252"],["34950.32","0.114448"],["34949.56","0.051541"],["34949.2","0.00057"],["34943.76","0.12395"],["34941.21","0.286194"],["34922.09","2.2053"],["34954.09","0"],["34944.39","0"],["34941.44","0"],["34936.5","0"],["34944.08","0"],["34933.71","0"],["34951.27","0"]],"a":[["34957.26","0.037382"],["34957.27","0.03895"],["34958","0.0324"],["34961.34","0.057206"],["34966.69","0.114394"],["34969.65","0.35422"],["34975.19","0.285916"],["34957.28","0"],["34971.89","0"],["34976.24","0"],["34976.85","0"],["34976.88","0"],["34965","0"],["34977.06","0"]],"u":20010099,"seq":14108038113}}'
2023-11-02 14:54:19,709 DEBUG ++Rcv decoded: fin=1 opcode=1 data=b'{"topic":"orderbook.50.BTCUSDC","ts":1698936859623,"type":"delta","data":{"s":"BTCUSDC","b":[["34953.1","0.028605"],["34951.48","0.03252"],["34950.32","0.114448"],["34949.56","0.051541"],["34949.2","0.00057"],["34943.76","0.12395"],["34941.21","0.286194"],["34922.09","2.2053"],["34954.09","0"],["34944.39","0"],["34941.44","0"],["34936.5","0"],["34944.08","0"],["34933.71","0"],["34951.27","0"]],"a":[["34957.26","0.037382"],["34957.27","0.03895"],["34958","0.0324"],["34961.34","0.057206"],["34966.69","0.114394"],["34969.65","0.35422"],["34975.19","0.285916"],["34957.28","0"],["34971.89","0"],["34976.24","0"],["34976.85","0"],["34976.88","0"],["34965","0"],["34977.06","0"]],"u":20010099,"seq":14108038113}}'
2023-11-02 14:54:19,729 DEBUG ++Rcv raw: b'\x81~\x01\x9f{"topic":"orderbook.50.BTCUSDC","ts":1698936859644,"type":"delta","data":{"s":"BTCUSDC","b":[["34950.33","0.068672"],["34949.48","0.047603"],["34918.51","0.1875"],["34916.9","0.035725"],["34936.51","0"],["34933.72","0"],["34951.47","0"],["34944.93","0"]],"a":[["34961.33","0.051546"],["34963.95","0.112507"],["34969.64","0.21254"],["34969.66","0"],["34957.27","0"],["34971.88","0"]],"u":20010100,"seq":14108038155}}'
2023-11-02 14:54:19,730 DEBUG ++Rcv decoded: fin=1 opcode=1 data=b'{"topic":"orderbook.50.BTCUSDC","ts":1698936859644,"type":"delta","data":{"s":"BTCUSDC","b":[["34950.33","0.068672"],["34949.48","0.047603"],["34918.51","0.1875"],["34916.9","0.035725"],["34936.51","0"],["34933.72","0"],["34951.47","0"],["34944.93","0"]],"a":[["34961.33","0.051546"],["34963.95","0.112507"],["34969.64","0.21254"],["34969.66","0"],["34957.27","0"],["34971.88","0"]],"u":20010100,"seq":14108038155}}'
2023-11-02 14:54:19,749 DEBUG ++Rcv raw: b'\x81~\x02\x1e{"topic":"orderbook.50.BTCUSDC","ts":1698936859663,"type":"delta","data":{"s":"BTCUSDC","b":[["34952.98","0.100225"],["34946.11","0.052642"],["34912.41","0.41246"],["34912.4","0.687434"],["34911.28","0.1875"],["34910.79","0.4192"],["34907.01","0.955091"],["34944.94","0"],["34940.24","0"],["34941.21","0"],["34951.48","0"],["34950.32","0"],["34949.56","0"]],"a":[["34957.25","0.022429"],["34957.26","0.008756"],["34976.24","0.278379"],["34976.85","0.05718"],["34966.69","0"],["34975.19","0"],["34961.34","0"]],"u":20010101,"seq":14108038189}}'
2023-11-02 14:54:19,749 DEBUG ++Rcv decoded: fin=1 opcode=1 data=b'{"topic":"orderbook.50.BTCUSDC","ts":1698936859663,"type":"delta","data":{"s":"BTCUSDC","b":[["34952.98","0.100225"],["34946.11","0.052642"],["34912.41","0.41246"],["34912.4","0.687434"],["34911.28","0.1875"],["34910.79","0.4192"],["34907.01","0.955091"],["34944.94","0"],["34940.24","0"],["34941.21","0"],["34951.48","0"],["34950.32","0"],["34949.56","0"]],"a":[["34957.25","0.022429"],["34957.26","0.008756"],["34976.24","0.278379"],["34976.85","0.05718"],["34966.69","0"],["34975.19","0"],["34961.34","0"]],"u":20010101,"seq":14108038189}}'
2023-11-02 14:54:19,769 DEBUG ++Rcv raw: b'\x81~\x01\xc7{"topic":"orderbook.50.BTCUSDC","ts":1698936859683,"type":"delta","data":{"s":"BTCUSDC","b":[["34952.05","0.057221"],["34951.27","0.051541"],["34940.3","0.025298"],["34938.55","0.089926"],["34928.02","0.05726"],["34927.86","0.458086"],["34950.33","0"],["34912.4","0"],["34910.79","0"],["34911.28","0"],["34945.96","0"],["34907.01","0"]],"a":[["34976.88","0.031073"],["34977.06","0.0859"],["34961.09","0"],["34957.25","0"]],"u":20010102,"seq":14108038231}}'
2023-11-02 14:54:19,769 DEBUG ++Rcv decoded: fin=1 opcode=1 data=b'{"topic":"orderbook.50.BTCUSDC","ts":1698936859683,"type":"delta","data":{"s":"BTCUSDC","b":[["34952.05","0.057221"],["34951.27","0.051541"],["34940.3","0.025298"],["34938.55","0.089926"],["34928.02","0.05726"],["34927.86","0.458086"],["34950.33","0"],["34912.4","0"],["34910.79","0"],["34911.28","0"],["34945.96","0"],["34907.01","0"]],"a":[["34976.88","0.031073"],["34977.06","0.0859"],["34961.09","0"],["34957.25","0"]],"u":20010102,"seq":14108038231}}'
2023-11-02 14:54:19,789 DEBUG ++Rcv raw: b'\x81~\x01M{"topic":"orderbook.50.BTCUSDC","ts":1698936859704,"type":"delta","data":{"s":"BTCUSDC","b":[["34952.06","0.034335"],["34949.55","0.051544"],["34927.87","0.274856"],["34951.27","0"],["34953.24","0"],["34947.7","0"]],"a":[["34957.24","0.008756"],["34957.25","0.002"],["34957.26","0"],["34977.06","0"]],"u":20010103,"seq":14108038263}}'
2023-11-02 14:54:19,790 DEBUG ++Rcv decoded: fin=1 opcode=1 data=b'{"topic":"orderbook.50.BTCUSDC","ts":1698936859704,"type":"delta","data":{"s":"BTCUSDC","b":[["34952.06","0.034335"],["34949.55","0.051544"],["34927.87","0.274856"],["34951.27","0"],["34953.24","0"],["34947.7","0"]],"a":[["34957.24","0.008756"],["34957.25","0.002"],["34957.26","0"],["34977.06","0"]],"u":20010103,"seq":14108038263}}'
2023-11-02 14:54:19,810 DEBUG ++Rcv raw: b'\x81~\x01\xe1{"topic":"orderbook.50.BTCUSDC","ts":1698936859725,"type":"delta","data":{"s":"BTCUSDC","b":[["34946.11","0.001093"],["34945.8","0.114462"],["34936.59","0.286232"],["34935.28","1.372992"],["34918.51","0"],["34916.9","0"],["34912.41","0"]],"a":[["34957.22","0.038585"],["34957.23","0.03895"],["34959.32","0.057209"],["34965.57","0.114398"],["34975.73","0.285912"],["34976.85","0"],["34976.24","0"],["34976.88","0"],["34976.23","0"],["34957.24","0"]],"u":20010104,"seq":14108038290}}'
2023-11-02 14:54:19,810 DEBUG ++Rcv decoded: fin=1 opcode=1 data=b'{"topic":"orderbook.50.BTCUSDC","ts":1698936859725,"type":"delta","data":{"s":"BTCUSDC","b":[["34946.11","0.001093"],["34945.8","0.114462"],["34936.59","0.286232"],["34935.28","1.372992"],["34918.51","0"],["34916.9","0"],["34912.41","0"]],"a":[["34957.22","0.038585"],["34957.23","0.03895"],["34959.32","0.057209"],["34965.57","0.114398"],["34975.73","0.285912"],["34976.85","0"],["34976.24","0"],["34976.88","0"],["34976.23","0"],["34957.24","0"]],"u":20010104,"seq":14108038290}}'
2023-11-02 14:54:19,829 DEBUG ++Rcv raw: b'\x81~\x01\x06{"topic":"orderbook.50.BTCUSDC","ts":1698936859743,"type":"delta","data":{"s":"BTCUSDC","b":[["34946.11","0.069777"]],"a":[["34957.21","0.047729"],["34957.22","0.008756"],["34959.31","0.034334"],["34957.23","0"],["34959.32","0"]],"u":20010105,"seq":14108038314}}'
2023-11-02 14:54:19,829 DEBUG ++Rcv decoded: fin=1 opcode=1 data=b'{"topic":"orderbook.50.BTCUSDC","ts":1698936859743,"type":"delta","data":{"s":"BTCUSDC","b":[["34946.11","0.069777"]],"a":[["34957.21","0.047729"],["34957.22","0.008756"],["34959.31","0.034334"],["34957.23","0"],["34959.32","0"]],"u":20010105,"seq":14108038314}}'
2023-11-02 14:54:19,850 DEBUG ++Rcv raw: b'\x81~\x01\x9a{"topic":"orderbook.50.BTCUSDC","ts":1698936859764,"type":"delta","data":{"s":"BTCUSDC","b":[["34950.22","0.036"],["34944.01","0.001408"],["34943.2","0.028"],["34922.09","0"],["34952.05","0"],["34922.1","0"]],"a":[["34976.23","0.080337"],["34976.24","0.278379"],["34976.85","0.05718"],["34976.88","0.031073"],["34957.21","0"],["34965.57","0"],["34959.31","0"],["34963.96","0"]],"u":20010106,"seq":14108038360}}'
2023-11-02 14:54:19,850 DEBUG ++Rcv decoded: fin=1 opcode=1 data=b'{"topic":"orderbook.50.BTCUSDC","ts":1698936859764,"type":"delta","data":{"s":"BTCUSDC","b":[["34950.22","0.036"],["34944.01","0.001408"],["34943.2","0.028"],["34922.09","0"],["34952.05","0"],["34922.1","0"]],"a":[["34976.23","0.080337"],["34976.24","0.278379"],["34976.85","0.05718"],["34976.88","0.031073"],["34957.21","0"],["34965.57","0"],["34959.31","0"],["34963.96","0"]],"u":20010106,"seq":14108038360}}'
2023-11-02 14:54:19,869 DEBUG ++Rcv raw: b'\x81~\x01a{"topic":"orderbook.50.BTCUSDC","ts":1698936859784,"type":"delta","data":{"s":"BTCUSDC","b":[["34954.09","0.101259"],["34953.63","0.057218"],["34951.27","0.051542"],["34946.11","0.068684"],["34922.1","0.91843"],["34936.59","0"],["34945.8","0"],["34952.06","0"],["34949.55","0"]],"a":[["34961.4","0.03"],["34975.73","0"]],"u":20010107,"seq":14108038378}}'
2023-11-02 14:54:19,869 DEBUG ++Rcv decoded: fin=1 opcode=1 data=b'{"topic":"orderbook.50.BTCUSDC","ts":1698936859784,"type":"delta","data":{"s":"BTCUSDC","b":[["34954.09","0.101259"],["34953.63","0.057218"],["34951.27","0.051542"],["34946.11","0.068684"],["34922.1","0.91843"],["34936.59","0"],["34945.8","0"],["34952.06","0"],["34949.55","0"]],"a":[["34961.4","0.03"],["34975.73","0"]],"u":20010107,"seq":14108038378}}'
2023-11-02 14:54:19,889 DEBUG ++Rcv raw: b'\x81~\x01!{"topic":"orderbook.50.BTCUSDC","ts":1698936859803,"type":"delta","data":{"s":"BTCUSDC","b":[["34922.09","2.2053"],["34918.51","0.1875"],["34916.9","0.035725"],["34946.11","0"],["34937.76","0"],["34950.22","0"]],"a":[["34977.06","0.0859"],["34960.12","0"]],"u":20010108,"seq":14108038393}}'
2023-11-02 14:54:19,889 DEBUG ++Rcv decoded: fin=1 opcode=1 data=b'{"topic":"orderbook.50.BTCUSDC","ts":1698936859803,"type":"delta","data":{"s":"BTCUSDC","b":[["34922.09","2.2053"],["34918.51","0.1875"],["34916.9","0.035725"],["34946.11","0"],["34937.76","0"],["34950.22","0"]],"a":[["34977.06","0.0859"],["34960.12","0"]],"u":20010108,"seq":14108038393}}'
2023-11-02 14:54:19,909 DEBUG ++Rcv raw: b'\x81~\x00\xad{"topic":"orderbook.50.BTCUSDC","ts":1698936859824,"type":"delta","data":{"s":"BTCUSDC","b":[],"a":[["34972.6","0.024311"],["34977.06","0"]],"u":20010109,"seq":14108038395}}'
2023-11-02 14:54:19,909 DEBUG ++Rcv decoded: fin=1 opcode=1 data=b'{"topic":"orderbook.50.BTCUSDC","ts":1698936859824,"type":"delta","data":{"s":"BTCUSDC","b":[],"a":[["34972.6","0.024311"],["34977.06","0"]],"u":20010109,"seq":14108038395}}'
2023-11-02 14:54:19,929 DEBUG ++Rcv raw: b'\x81~\x00\xd4{"topic":"orderbook.50.BTCUSDC","ts":1698936859844,"type":"delta","data":{"s":"BTCUSDC","b":[["34944.39","0.002947"],["34943.59","0.1875"],["34938.55","0"],["34916.9","0"]],"a":[],"u":20010110,"seq":14108038425}}'
2023-11-02 14:54:19,929 DEBUG ++Rcv decoded: fin=1 opcode=1 data=b'{"topic":"orderbook.50.BTCUSDC","ts":1698936859844,"type":"delta","data":{"s":"BTCUSDC","b":[["34944.39","0.002947"],["34943.59","0.1875"],["34938.55","0"],["34916.9","0"]],"a":[],"u":20010110,"seq":14108038425}}'
2023-11-02 14:54:19,949 DEBUG ++Rcv raw: b'\x81~\x00\xd4{"topic":"orderbook.50.BTCUSDC","ts":1698936859864,"type":"delta","data":{"s":"BTCUSDC","b":[["34916.9","0.035725"],["34911.28","0.1875"],["34953.63","0"],["34944.01","0"]],"a":[],"u":20010111,"seq":14108038432}}'
2023-11-02 14:54:19,949 DEBUG ++Rcv decoded: fin=1 opcode=1 data=b'{"topic":"orderbook.50.BTCUSDC","ts":1698936859864,"type":"delta","data":{"s":"BTCUSDC","b":[["34916.9","0.035725"],["34911.28","0.1875"],["34953.63","0"],["34944.01","0"]],"a":[],"u":20010111,"seq":14108038432}}'
2023-11-02 14:54:19,969 DEBUG ++Rcv raw: b'\x81~\x01;{"topic":"orderbook.50.BTCUSDC","ts":1698936859883,"type":"delta","data":{"s":"BTCUSDC","b":[["34955.04","0.057216"],["34948","0.148555"],["34937.6","0.286224"],["34916.9","0"],["34911.28","0"]],"a":[["34962.58","0.057204"],["34969.46","0.114385"],["34976.88","0"],["34976.85","0"]],"u":20010112,"seq":14108038452}}'
2023-11-02 14:54:19,969 DEBUG ++Rcv decoded: fin=1 opcode=1 data=b'{"topic":"orderbook.50.BTCUSDC","ts":1698936859883,"type":"delta","data":{"s":"BTCUSDC","b":[["34955.04","0.057216"],["34948","0.148555"],["34937.6","0.286224"],["34916.9","0"],["34911.28","0"]],"a":[["34962.58","0.057204"],["34969.46","0.114385"],["34976.88","0"],["34976.85","0"]],"u":20010112,"seq":14108038452}}'
2023-11-02 14:54:19,989 DEBUG ++Rcv raw: b'\x81~\x01M{"topic":"orderbook.50.BTCUSDC","ts":1698936859903,"type":"delta","data":{"s":"BTCUSDC","b":[["34948.02","0.089136"],["34946.11","0.051544"],["34940.94","0.0859"],["34947.83","0"],["34954.09","0"],["34949.2","0"]],"a":[["34957.2","0.023622"],["34957.21","0.028606"],["34976.24","0"],["34976.23","0"]],"u":20010113,"seq":14108038473}}'
2023-11-02 14:54:19,989 DEBUG ++Rcv decoded: fin=1 opcode=1 data=b'{"topic":"orderbook.50.BTCUSDC","ts":1698936859903,"type":"delta","data":{"s":"BTCUSDC","b":[["34948.02","0.089136"],["34946.11","0.051544"],["34940.94","0.0859"],["34947.83","0"],["34954.09","0"],["34949.2","0"]],"a":[["34957.2","0.023622"],["34957.21","0.028606"],["34976.24","0"],["34976.23","0"]],"u":20010113,"seq":14108038473}}'
2023-11-02 14:54:20,009 DEBUG ++Rcv raw: b'\x81~\x00\xc6{"topic":"orderbook.50.BTCUSDC","ts":1698936859923,"type":"delta","data":{"s":"BTCUSDC","b":[["34948.55","0.035728"],["34948.02","0.455455"],["34918.51","0"]],"a":[],"u":20010114,"seq":14108038477}}'
2023-11-02 14:54:20,009 DEBUG ++Rcv decoded: fin=1 opcode=1 data=b'{"topic":"orderbook.50.BTCUSDC","ts":1698936859923,"type":"delta","data":{"s":"BTCUSDC","b":[["34948.55","0.035728"],["34948.02","0.455455"],["34918.51","0"]],"a":[],"u":20010114,"seq":14108038477}}'
2023-11-02 14:54:20,029 DEBUG ++Rcv raw: b'\x81~\x00\xef{"topic":"orderbook.50.BTCUSDC","ts":1698936859943,"type":"delta","data":{"s":"BTCUSDC","b":[["34948.56","0.219797"],["34948.02","0.366319"],["34947.83","0.051547"],["34922.09","0"],["34946.11","0"]],"a":[],"u":20010115,"seq":14108038501}}'
2023-11-02 14:54:20,029 DEBUG ++Rcv decoded: fin=1 opcode=1 data=b'{"topic":"orderbook.50.BTCUSDC","ts":1698936859943,"type":"delta","data":{"s":"BTCUSDC","b":[["34948.56","0.219797"],["34948.02","0.366319"],["34947.83","0.051547"],["34922.09","0"],["34946.11","0"]],"a":[],"u":20010115,"seq":14108038501}}'
2023-11-02 14:54:20,089 DEBUG ++Rcv raw: b'\x81~\x00\xec{"topic":"orderbook.50.BTCUSDC","ts":1698936860003,"type":"delta","data":{"s":"BTCUSDC","b":[["34955.04","0.034216"],["34922.09","2.2053"],["34946.09","0"]],"a":[["34957.19","0.047706"],["34957.22","0"]],"u":20010116,"seq":14108038533}}'
2023-11-02 14:54:20,090 DEBUG ++Rcv decoded: fin=1 opcode=1 data=b'{"topic":"orderbook.50.BTCUSDC","ts":1698936860003,"type":"delta","data":{"s":"BTCUSDC","b":[["34955.04","0.034216"],["34922.09","2.2053"],["34946.09","0"]],"a":[["34957.19","0.047706"],["34957.22","0"]],"u":20010116,"seq":14108038533}}'
2023-11-02 14:54:20,109 DEBUG ++Rcv raw: b'\x81~\x00\xee{"topic":"orderbook.50.BTCUSDC","ts":1698936860024,"type":"delta","data":{"s":"BTCUSDC","b":[],"a":[["34957.18","0.091123"],["34957.19","0.008756"],["34976.23","0.080337"],["34964.28","0"],["34957.2","0"]],"u":20010117,"seq":14108038544}}'
2023-11-02 14:54:20,110 DEBUG ++Rcv decoded: fin=1 opcode=1 data=b'{"topic":"orderbook.50.BTCUSDC","ts":1698936860024,"type":"delta","data":{"s":"BTCUSDC","b":[],"a":[["34957.18","0.091123"],["34957.19","0.008756"],["34976.23","0.080337"],["34964.28","0"],["34957.2","0"]],"u":20010117,"seq":14108038544}}'
2023-11-02 14:54:20,129 DEBUG ++Rcv raw: b'\x81~\x00\xfb{"topic":"orderbook.50.BTCUSDC","ts":1698936860044,"type":"delta","data":{"s":"BTCUSDC","b":[],"a":[["34957.17","0.051055"],["34964.18","0.1875"],["34965","0.051541"],["34957.18","0"],["34963.95","0"],["34976.23","0"]],"u":20010118,"seq":14108038559}}'
2023-11-02 14:54:20,129 DEBUG ++Rcv decoded: fin=1 opcode=1 data=b'{"topic":"orderbook.50.BTCUSDC","ts":1698936860044,"type":"delta","data":{"s":"BTCUSDC","b":[],"a":[["34957.17","0.051055"],["34964.18","0.1875"],["34965","0.051541"],["34957.18","0"],["34963.95","0"],["34976.23","0"]],"u":20010118,"seq":14108038559}}'
2023-11-02 14:54:20,149 DEBUG ++Rcv raw: b'\x81~\x01\x0e{"topic":"orderbook.50.BTCUSDC","ts":1698936860064,"type":"delta","data":{"s":"BTCUSDC","b":[["34918.51","0.1875"],["34937.6","0"]],"a":[["34957.17","0.023619"],["34963.99","0.112503"],["34976.23","0.080337"],["34965","0"],["34958","0"]],"u":20010119,"seq":14108038572}}'
2023-11-02 14:54:20,150 DEBUG ++Rcv decoded: fin=1 opcode=1 data=b'{"topic":"orderbook.50.BTCUSDC","ts":1698936860064,"type":"delta","data":{"s":"BTCUSDC","b":[["34918.51","0.1875"],["34937.6","0"]],"a":[["34957.17","0.023619"],["34963.99","0.112503"],["34976.23","0.080337"],["34965","0"],["34958","0"]],"u":20010119,"seq":14108038572}}'
2023-11-02 14:54:20,169 DEBUG ++Rcv raw: b'\x81~\x00\xff{"topic":"orderbook.50.BTCUSDC","ts":1698936860083,"type":"delta","data":{"s":"BTCUSDC","b":[["34955.63","0.057215"],["34938.71","0.286215"],["34918.51","0"],["34955.04","0"]],"a":[["34963.12","0.057203"],["34962.58","0"]],"u":20010120,"seq":14108038600}}'
2023-11-02 14:54:20,169 DEBUG ++Rcv decoded: fin=1 opcode=1 data=b'{"topic":"orderbook.50.BTCUSDC","ts":1698936860083,"type":"delta","data":{"s":"BTCUSDC","b":[["34955.63","0.057215"],["34938.71","0.286215"],["34918.51","0"],["34955.04","0"]],"a":[["34963.12","0.057203"],["34962.58","0"]],"u":20010120,"seq":14108038600}}'
2023-11-02 14:54:20,188 DEBUG ++Rcv raw: b'\x81~\x00\xd7{"topic":"orderbook.50.BTCUSDC","ts":1698936860103,"type":"delta","data":{"s":"BTCUSDC","b":[],"a":[["34976.24","0.278379"],["34976.36","0.075072"],["34957.17","0"],["34964.18","0"]],"u":20010121,"seq":14108038606}}'
2023-11-02 14:54:20,189 DEBUG ++Rcv decoded: fin=1 opcode=1 data=b'{"topic":"orderbook.50.BTCUSDC","ts":1698936860103,"type":"delta","data":{"s":"BTCUSDC","b":[],"a":[["34976.24","0.278379"],["34976.36","0.075072"],["34957.17","0"],["34964.18","0"]],"u":20010121,"seq":14108038606}}'
2023-11-02 14:54:20,209 DEBUG ++Rcv raw: b'\x81~\x00\xab{"topic":"orderbook.50.BTCUSDC","ts":1698936860124,"type":"delta","data":{"s":"BTCUSDC","b":[],"a":[["34965","0.051544"],["34963.99","0"]],"u":20010122,"seq":14108038616}}'
2023-11-02 14:54:20,209 DEBUG ++Rcv decoded: fin=1 opcode=1 data=b'{"topic":"orderbook.50.BTCUSDC","ts":1698936860124,"type":"delta","data":{"s":"BTCUSDC","b":[],"a":[["34965","0.051544"],["34963.99","0"]],"u":20010122,"seq":14108038616}}'
2023-11-02 14:54:20,228 DEBUG ++Rcv raw: b'\x81~\x00\xf9{"topic":"orderbook.50.BTCUSDC","ts":1698936860143,"type":"delta","data":{"s":"BTCUSDC","b":[["34949.55","0.001366"],["34922.09","0"]],"a":[["34976.85","0.05718"],["34977.06","0.0859"],["34960","0"],["34957.21","0"]],"u":20010123,"seq":14108038640}}'
2023-11-02 14:54:20,229 DEBUG ++Rcv decoded: fin=1 opcode=1 data=b'{"topic":"orderbook.50.BTCUSDC","ts":1698936860143,"type":"delta","data":{"s":"BTCUSDC","b":[["34949.55","0.001366"],["34922.09","0"]],"a":[["34976.85","0.05718"],["34977.06","0.0859"],["34960","0"],["34957.21","0"]],"u":20010123,"seq":14108038640}}'
2023-11-02 14:54:20,248 DEBUG ++Rcv raw: b'\x81~\x00\xac{"topic":"orderbook.50.BTCUSDC","ts":1698936860163,"type":"delta","data":{"s":"BTCUSDC","b":[["34922.09","2.2053"],["34944.39","0"]],"a":[],"u":20010124,"seq":14108038655}}'
2023-11-02 14:54:20,249 DEBUG ++Rcv decoded: fin=1 opcode=1 data=b'{"topic":"orderbook.50.BTCUSDC","ts":1698936860163,"type":"delta","data":{"s":"BTCUSDC","b":[["34922.09","2.2053"],["34944.39","0"]],"a":[],"u":20010124,"seq":14108038655}}'
2023-11-02 14:54:20,269 DEBUG ++Rcv raw: b'\x81~\x00\xd6{"topic":"orderbook.50.BTCUSDC","ts":1698936860183,"type":"delta","data":{"s":"BTCUSDC","b":[["34955.87","0.098306"],["34922.09","0"]],"a":[["34961.86","0.000239"],["34977.06","0"]],"u":20010125,"seq":14108038669}}'
2023-11-02 14:54:20,269 DEBUG ++Rcv decoded: fin=1 opcode=1 data=b'{"topic":"orderbook.50.BTCUSDC","ts":1698936860183,"type":"delta","data":{"s":"BTCUSDC","b":[["34955.87","0.098306"],["34922.09","0"]],"a":[["34961.86","0.000239"],["34977.06","0"]],"u":20010125,"seq":14108038669}}'
2023-11-02 14:54:20,289 DEBUG ++Rcv raw: b'\x81~\x00\xad{"topic":"orderbook.50.BTCUSDC","ts":1698936860203,"type":"delta","data":{"s":"BTCUSDC","b":[["34934.62","0.060266"],["34922.1","0"]],"a":[],"u":20010126,"seq":14108038679}}'
2023-11-02 14:54:20,290 DEBUG ++Rcv decoded: fin=1 opcode=1 data=b'{"topic":"orderbook.50.BTCUSDC","ts":1698936860203,"type":"delta","data":{"s":"BTCUSDC","b":[["34934.62","0.060266"],["34922.1","0"]],"a":[],"u":20010126,"seq":14108038679}}'
2023-11-02 14:54:20,309 DEBUG ++Rcv raw: b'\x81~\x00\xae{"topic":"orderbook.50.BTCUSDC","ts":1698936860223,"type":"delta","data":{"s":"BTCUSDC","b":[["34953.11","0.030669"],["34951.27","0"]],"a":[],"u":20010127,"seq":14108038689}}'
2023-11-02 14:54:20,309 DEBUG ++Rcv decoded: fin=1 opcode=1 data=b'{"topic":"orderbook.50.BTCUSDC","ts":1698936860223,"type":"delta","data":{"s":"BTCUSDC","b":[["34953.11","0.030669"],["34951.27","0"]],"a":[],"u":20010127,"seq":14108038689}}'
2023-11-02 14:54:20,328 DEBUG ++Rcv raw: b'\x81~\x00\xae{"topic":"orderbook.50.BTCUSDC","ts":1698936860243,"type":"delta","data":{"s":"BTCUSDC","b":[],"a":[["34957.18","0.028606"],["34976.85","0"]],"u":20010128,"seq":14108038697}}'
2023-11-02 14:54:20,329 DEBUG ++Rcv decoded: fin=1 opcode=1 data=b'{"topic":"orderbook.50.BTCUSDC","ts":1698936860243,"type":"delta","data":{"s":"BTCUSDC","b":[],"a":[["34957.18","0.028606"],["34976.85","0"]],"u":20010128,"seq":14108038697}}'
2023-11-02 14:54:20,409 DEBUG ++Rcv raw: b'\x81~\x00\xfd{"topic":"orderbook.50.BTCUSDC","ts":1698936860323,"type":"delta","data":{"s":"BTCUSDC","b":[],"a":[["34960.14","0.008756"],["34976.85","0.05718"],["34977.06","0.0859"],["34957.25","0"],["34957.18","0"],["34957.19","0"]],"u":20010129,"seq":14108038740}}'
2023-11-02 14:54:20,410 DEBUG ++Rcv decoded: fin=1 opcode=1 data=b'{"topic":"orderbook.50.BTCUSDC","ts":1698936860323,"type":"delta","data":{"s":"BTCUSDC","b":[],"a":[["34960.14","0.008756"],["34976.85","0.05718"],["34977.06","0.0859"],["34957.25","0"],["34957.18","0"],["34957.19","0"]],"u":20010129,"seq":14108038740}}'
2023-11-02 14:54:20,429 DEBUG ++Rcv raw: b'\x81~\x00\xd6{"topic":"orderbook.50.BTCUSDC","ts":1698936860344,"type":"delta","data":{"s":"BTCUSDC","b":[["34952.99","0.060141"],["34950.98","0.00057"],["34953.11","0"],["34923.58","0"]],"a":[],"u":20010130,"seq":14108038755}}'
2023-11-02 14:54:20,429 DEBUG ++Rcv decoded: fin=1 opcode=1 data=b'{"topic":"orderbook.50.BTCUSDC","ts":1698936860344,"type":"delta","data":{"s":"BTCUSDC","b":[["34952.99","0.060141"],["34950.98","0.00057"],["34953.11","0"],["34923.58","0"]],"a":[],"u":20010130,"seq":14108038755}}'
2023-11-02 14:54:20,450 DEBUG ++Rcv raw: b'\x81~\x00\xdb{"topic":"orderbook.50.BTCUSDC","ts":1698936860364,"type":"delta","data":{"s":"BTCUSDC","b":[["34953.1","0.051039"]],"a":[["34970.07","0.01439"],["34972.23","0.075313"],["34977.06","0"]],"u":20010131,"seq":14108038773}}'
2023-11-02 14:54:20,451 DEBUG ++Rcv decoded: fin=1 opcode=1 data=b'{"topic":"orderbook.50.BTCUSDC","ts":1698936860364,"type":"delta","data":{"s":"BTCUSDC","b":[["34953.1","0.051039"]],"a":[["34970.07","0.01439"],["34972.23","0.075313"],["34977.06","0"]],"u":20010131,"seq":14108038773}}'
2023-11-02 14:54:20,491 DEBUG ++Rcv raw: b'\x81~\x00\xae{"topic":"orderbook.50.BTCUSDC","ts":1698936860404,"type":"delta","data":{"s":"BTCUSDC","b":[["34955.88","0.008756"],["34924.42","0"]],"a":[],"u":20010132,"seq":14108038791}}'
2023-11-02 14:54:20,491 DEBUG ++Rcv decoded: fin=1 opcode=1 data=b'{"topic":"orderbook.50.BTCUSDC","ts":1698936860404,"type":"delta","data":{"s":"BTCUSDC","b":[["34955.88","0.008756"],["34924.42","0"]],"a":[],"u":20010132,"seq":14108038791}}'
2023-11-02 14:54:20,508 DEBUG ++Rcv raw: b'\x81~\x00\xd6{"topic":"orderbook.50.BTCUSDC","ts":1698936860423,"type":"delta","data":{"s":"BTCUSDC","b":[["34938.72","0.171736"],["34955.87","0"]],"a":[["34976.22","0.167035"],["34976.85","0"]],"u":20010133,"seq":14108038802}}'
2023-11-02 14:54:20,509 DEBUG ++Rcv decoded: fin=1 opcode=1 data=b'{"topic":"orderbook.50.BTCUSDC","ts":1698936860423,"type":"delta","data":{"s":"BTCUSDC","b":[["34938.72","0.171736"],["34955.87","0"]],"a":[["34976.22","0.167035"],["34976.85","0"]],"u":20010133,"seq":14108038802}}'
2023-11-02 14:54:20,529 DEBUG ++Rcv raw: b'\x81~\x01#{"topic":"orderbook.50.BTCUSDC","ts":1698936860444,"type":"delta","data":{"s":"BTCUSDC","b":[["34945.57","0.000261"],["34925","0"]],"a":[["34960.13","0.028604"],["34961.64","0.000239"],["34975.33","0.0005"],["34976.24","0"],["34976.23","0"],["34976.36","0"]],"u":20010134,"seq":14108038813}}'
2023-11-02 14:54:20,529 DEBUG ++Rcv decoded: fin=1 opcode=1 data=b'{"topic":"orderbook.50.BTCUSDC","ts":1698936860444,"type":"delta","data":{"s":"BTCUSDC","b":[["34945.57","0.000261"],["34925","0"]],"a":[["34960.13","0.028604"],["34961.64","0.000239"],["34975.33","0.0005"],["34976.24","0"],["34976.23","0"],["34976.36","0"]],"u":20010134,"seq":14108038813}}'
2023-11-02 14:54:20,549 DEBUG ++Rcv raw: b'\x81~\x00\xae{"topic":"orderbook.50.BTCUSDC","ts":1698936860464,"type":"delta","data":{"s":"BTCUSDC","b":[],"a":[["34960.49","0.023157"],["34976.22","0"]],"u":20010135,"seq":14108038826}}'
2023-11-02 14:54:20,549 DEBUG ++Rcv decoded: fin=1 opcode=1 data=b'{"topic":"orderbook.50.BTCUSDC","ts":1698936860464,"type":"delta","data":{"s":"BTCUSDC","b":[],"a":[["34960.49","0.023157"],["34976.22","0"]],"u":20010135,"seq":14108038826}}'
2023-11-02 14:54:20,569 DEBUG ++Rcv raw: b'\x81~\x00\xa8{"topic":"orderbook.50.BTCUSDC","ts":1698936860484,"type":"delta","data":{"s":"BTCUSDC","b":[["34925","2.2097"],["34943.2","0"]],"a":[],"u":20010136,"seq":14108038841}}'
2023-11-02 14:54:20,569 DEBUG ++Rcv decoded: fin=1 opcode=1 data=b'{"topic":"orderbook.50.BTCUSDC","ts":1698936860484,"type":"delta","data":{"s":"BTCUSDC","b":[["34925","2.2097"],["34943.2","0"]],"a":[],"u":20010136,"seq":14108038841}}'
2023-11-02 14:54:20,629 DEBUG ++Rcv raw: b'\x81~\x00\xd6{"topic":"orderbook.50.BTCUSDC","ts":1698936860543,"type":"delta","data":{"s":"BTCUSDC","b":[["34953.11","0.090758"],["34952.99","0"]],"a":[["34976.22","0.167035"],["34960.13","0"]],"u":20010137,"seq":14108038862}}'
2023-11-02 14:54:20,630 DEBUG ++Rcv decoded: fin=1 opcode=1 data=b'{"topic":"orderbook.50.BTCUSDC","ts":1698936860543,"type":"delta","data":{"s":"BTCUSDC","b":[["34953.11","0.090758"],["34952.99","0"]],"a":[["34976.22","0.167035"],["34960.13","0"]],"u":20010137,"seq":14108038862}}'
2023-11-02 14:54:20,709 DEBUG ++Rcv raw: b'\x81~\x00\xa6{"topic":"orderbook.50.BTCUSDC","ts":1698936860624,"type":"delta","data":{"s":"BTCUSDC","b":[["34954","0.0324"],["34925","0"]],"a":[],"u":20010138,"seq":14108038935}}'
2023-11-02 14:54:20,709 DEBUG ++Rcv decoded: fin=1 opcode=1 data=b'{"topic":"orderbook.50.BTCUSDC","ts":1698936860624,"type":"delta","data":{"s":"BTCUSDC","b":[["34954","0.0324"],["34925","0"]],"a":[],"u":20010138,"seq":14108038935}}'
2023-11-02 14:54:20,729 DEBUG ++Rcv raw: b'\x81~\x00\xd6{"topic":"orderbook.50.BTCUSDC","ts":1698936860644,"type":"delta","data":{"s":"BTCUSDC","b":[["34957.15","0.107768"],["34945.57","0"]],"a":[["34960.12","0.028604"],["34961.64","0"]],"u":20010139,"seq":14108038968}}'
2023-11-02 14:54:20,729 DEBUG ++Rcv decoded: fin=1 opcode=1 data=b'{"topic":"orderbook.50.BTCUSDC","ts":1698936860644,"type":"delta","data":{"s":"BTCUSDC","b":[["34957.15","0.107768"],["34945.57","0"]],"a":[["34960.12","0.028604"],["34961.64","0"]],"u":20010139,"seq":14108038968}}'
2023-11-02 14:54:20,760 DEBUG ++Rcv raw: b'\x81~\x00\xd3{"topic":"orderbook.50.BTCUSDC","ts":1698936860664,"type":"delta","data":{"s":"BTCUSDC","b":[["34954.7","0.0859"],["34925.01","0"]],"a":[["34976.23","0.080337"],["34961.58","0"]],"u":20010140,"seq":14108038977}}'
2023-11-02 14:54:20,761 DEBUG ++Rcv decoded: fin=1 opcode=1 data=b'{"topic":"orderbook.50.BTCUSDC","ts":1698936860664,"type":"delta","data":{"s":"BTCUSDC","b":[["34954.7","0.0859"],["34925.01","0"]],"a":[["34976.23","0.080337"],["34961.58","0"]],"u":20010140,"seq":14108038977}}'
2023-11-02 14:54:20,768 DEBUG ++Rcv raw: b'\x81~\x00\xfb{"topic":"orderbook.50.BTCUSDC","ts":1698936860683,"type":"delta","data":{"s":"BTCUSDC","b":[["34955.89","0.01144"],["34935.29","0.028"],["34927.86","0"],["34927.27","0"]],"a":[["34960.11","0.038111"],["34961.33","0"]],"u":20010141,"seq":14108038994}}'
2023-11-02 14:54:20,769 DEBUG ++Rcv decoded: fin=1 opcode=1 data=b'{"topic":"orderbook.50.BTCUSDC","ts":1698936860683,"type":"delta","data":{"s":"BTCUSDC","b":[["34955.89","0.01144"],["34935.29","0.028"],["34927.86","0"],["34927.27","0"]],"a":[["34960.11","0.038111"],["34961.33","0"]],"u":20010141,"seq":14108038994}}'
2023-11-02 14:54:20,789 DEBUG ++Rcv raw: b'\x81~\x00\x9b{"topic":"orderbook.50.BTCUSDC","ts":1698936860703,"type":"delta","data":{"s":"BTCUSDC","b":[],"a":[["34965.01","0.0446"]],"u":20010142,"seq":14108039007}}'
2023-11-02 14:54:20,789 DEBUG ++Rcv decoded: fin=1 opcode=1 data=b'{"topic":"orderbook.50.BTCUSDC","ts":1698936860703,"type":"delta","data":{"s":"BTCUSDC","b":[],"a":[["34965.01","0.0446"]],"u":20010142,"seq":14108039007}}'
2023-11-02 14:54:20,814 DEBUG ++Rcv raw: b'\x81~\x00\xae{"topic":"orderbook.50.BTCUSDC","ts":1698936860723,"type":"delta","data":{"s":"BTCUSDC","b":[],"a":[["34976.24","0.278379"],["34960.12","0"]],"u":20010143,"seq":14108039017}}'
2023-11-02 14:54:20,814 DEBUG ++Rcv decoded: fin=1 opcode=1 data=b'{"topic":"orderbook.50.BTCUSDC","ts":1698936860723,"type":"delta","data":{"s":"BTCUSDC","b":[],"a":[["34976.24","0.278379"],["34960.12","0"]],"u":20010143,"seq":14108039017}}'
2023-11-02 14:54:20,828 DEBUG ++Rcv raw: b'\x81~\x01\'{"topic":"orderbook.50.BTCUSDC","ts":1698936860743,"type":"delta","data":{"s":"BTCUSDC","b":[["34948.57","0.002743"],["34955.88","0"]],"a":[["34963.11","0.085863"],["34976.36","0.075072"],["34976.85","0.05718"],["34960.14","0"],["34963.29","0"],["34960.11","0"]],"u":20010144,"seq":14108039032}}'
2023-11-02 14:54:20,829 DEBUG ++Rcv decoded: fin=1 opcode=1 data=b'{"topic":"orderbook.50.BTCUSDC","ts":1698936860743,"type":"delta","data":{"s":"BTCUSDC","b":[["34948.57","0.002743"],["34955.88","0"]],"a":[["34963.11","0.085863"],["34976.36","0.075072"],["34976.85","0.05718"],["34960.14","0"],["34963.29","0"],["34960.11","0"]],"u":20010144,"seq":14108039032}}'
2023-11-02 14:54:20,849 DEBUG ++Rcv raw: b'\x81~\x00\xae{"topic":"orderbook.50.BTCUSDC","ts":1698936860763,"type":"delta","data":{"s":"BTCUSDC","b":[["34927.86","0.458086"],["34949.55","0"]],"a":[],"u":20010145,"seq":14108039037}}'
2023-11-02 14:54:20,849 DEBUG ++Rcv decoded: fin=1 opcode=1 data=b'{"topic":"orderbook.50.BTCUSDC","ts":1698936860763,"type":"delta","data":{"s":"BTCUSDC","b":[["34927.86","0.458086"],["34949.55","0"]],"a":[],"u":20010145,"seq":14108039037}}'
2023-11-02 14:54:20,988 DEBUG ++Rcv raw: b'\x81~\x00\xd2{"topic":"orderbook.50.BTCUSDC","ts":1698936860903,"type":"delta","data":{"s":"BTCUSDC","b":[["34927.27","0.1875"],["34955.89","0"]],"a":[["34977.06","0.0859"],["34963.12","0"]],"u":20010146,"seq":14108039086}}'
2023-11-02 14:54:20,989 DEBUG ++Rcv decoded: fin=1 opcode=1 data=b'{"topic":"orderbook.50.BTCUSDC","ts":1698936860903,"type":"delta","data":{"s":"BTCUSDC","b":[["34927.27","0.1875"],["34955.89","0"]],"a":[["34977.06","0.0859"],["34963.12","0"]],"u":20010146,"seq":14108039086}}'
2023-11-02 14:54:21,009 DEBUG ++Rcv raw: b'\x81~\x00\xc6{"topic":"orderbook.50.BTCUSDC","ts":1698936860923,"type":"delta","data":{"s":"BTCUSDC","b":[],"a":[["34962.64","0.057203"],["34963.11","0.051543"],["34977.06","0"]],"u":20010147,"seq":14108039091}}'
2023-11-02 14:54:21,009 DEBUG ++Rcv decoded: fin=1 opcode=1 data=b'{"topic":"orderbook.50.BTCUSDC","ts":1698936860923,"type":"delta","data":{"s":"BTCUSDC","b":[],"a":[["34962.64","0.057203"],["34963.11","0.051543"],["34977.06","0"]],"u":20010147,"seq":14108039091}}'
2023-11-02 14:54:21,029 DEBUG ++Rcv raw: b'\x81~\x00\xae{"topic":"orderbook.50.BTCUSDC","ts":1698936860944,"type":"delta","data":{"s":"BTCUSDC","b":[],"a":[["34962.63","0.085865"],["34963.11","0"]],"u":20010148,"seq":14108039095}}'
2023-11-02 14:54:21,029 DEBUG ++Rcv decoded: fin=1 opcode=1 data=b'{"topic":"orderbook.50.BTCUSDC","ts":1698936860944,"type":"delta","data":{"s":"BTCUSDC","b":[],"a":[["34962.63","0.085865"],["34963.11","0"]],"u":20010148,"seq":14108039095}}'
2023-11-02 14:54:21,049 DEBUG ++Rcv raw: b'\x81~\x00\xd6{"topic":"orderbook.50.BTCUSDC","ts":1698936860963,"type":"delta","data":{"s":"BTCUSDC","b":[],"a":[["34960.09","0.032861"],["34960.1","0.028604"],["34976.85","0"],["34976.36","0"]],"u":20010149,"seq":14108039126}}'
2023-11-02 14:54:21,049 DEBUG ++Rcv decoded: fin=1 opcode=1 data=b'{"topic":"orderbook.50.BTCUSDC","ts":1698936860963,"type":"delta","data":{"s":"BTCUSDC","b":[],"a":[["34960.09","0.032861"],["34960.1","0.028604"],["34976.85","0"],["34976.36","0"]],"u":20010149,"seq":14108039126}}'
2023-11-02 14:54:21,068 DEBUG ++Rcv raw: b'\x81~\x00\xc6{"topic":"orderbook.50.BTCUSDC","ts":1698936860983,"type":"delta","data":{"s":"BTCUSDC","b":[],"a":[["34962.63","0.051546"],["34976.36","0.075072"],["34961.86","0"]],"u":20010150,"seq":14108039160}}'
2023-11-02 14:54:21,068 DEBUG ++Rcv decoded: fin=1 opcode=1 data=b'{"topic":"orderbook.50.BTCUSDC","ts":1698936860983,"type":"delta","data":{"s":"BTCUSDC","b":[],"a":[["34962.63","0.051546"],["34976.36","0.075072"],["34961.86","0"]],"u":20010150,"seq":14108039160}}'
2023-11-02 14:54:21,088 DEBUG ++Rcv raw: b'\x81~\x00\xad{"topic":"orderbook.50.BTCUSDC","ts":1698936861003,"type":"delta","data":{"s":"BTCUSDC","b":[["34957.16","0.01144"],["34927.27","0"]],"a":[],"u":20010151,"seq":14108039173}}'
2023-11-02 14:54:21,089 DEBUG ++Rcv decoded: fin=1 opcode=1 data=b'{"topic":"orderbook.50.BTCUSDC","ts":1698936861003,"type":"delta","data":{"s":"BTCUSDC","b":[["34957.16","0.01144"],["34927.27","0"]],"a":[],"u":20010151,"seq":14108039173}}'
2023-11-02 14:54:21,110 DEBUG ++Rcv raw: b'\x81~\x00\xac{"topic":"orderbook.50.BTCUSDC","ts":1698936861024,"type":"delta","data":{"s":"BTCUSDC","b":[["34927.27","0.1875"],["34957.15","0"]],"a":[],"u":20010152,"seq":14108039178}}'
2023-11-02 14:54:21,111 DEBUG ++Rcv decoded: fin=1 opcode=1 data=b'{"topic":"orderbook.50.BTCUSDC","ts":1698936861024,"type":"delta","data":{"s":"BTCUSDC","b":[["34927.27","0.1875"],["34957.15","0"]],"a":[],"u":20010152,"seq":14108039178}}'
2023-11-02 14:54:21,149 DEBUG ++Rcv raw: b'\x81~\x00\xac{"topic":"orderbook.50.BTCUSDC","ts":1698936861064,"type":"delta","data":{"s":"BTCUSDC","b":[],"a":[["34976.85","0.05718"],["34960.1","0"]],"u":20010153,"seq":14108039191}}'
2023-11-02 14:54:21,150 DEBUG ++Rcv decoded: fin=1 opcode=1 data=b'{"topic":"orderbook.50.BTCUSDC","ts":1698936861064,"type":"delta","data":{"s":"BTCUSDC","b":[],"a":[["34976.85","0.05718"],["34960.1","0"]],"u":20010153,"seq":14108039191}}'
2023-11-02 14:54:21,170 DEBUG ++Rcv raw: b'\x81~\x01\x15{"topic":"orderbook.50.BTCUSDC","ts":1698936861084,"type":"delta","data":{"s":"BTCUSDC","b":[["34957.17","0.008756"],["34946.15","0.000262"],["34927.27","0"],["34927.86","0"]],"a":[["34962.63","0.079426"],["34977.06","0.0859"],["34960.09","0"]],"u":20010154,"seq":14108039211}}'
2023-11-02 14:54:21,170 DEBUG ++Rcv decoded: fin=1 opcode=1 data=b'{"topic":"orderbook.50.BTCUSDC","ts":1698936861084,"type":"delta","data":{"s":"BTCUSDC","b":[["34957.17","0.008756"],["34946.15","0.000262"],["34927.27","0"],["34927.86","0"]],"a":[["34962.63","0.079426"],["34977.06","0.0859"],["34960.09","0"]],"u":20010154,"seq":14108039211}}'
2023-11-02 14:54:21,189 DEBUG ++Rcv raw: b'\x81~\x00\xcc{"topic":"orderbook.50.BTCUSDC","ts":1698936861103,"type":"delta","data":{"s":"BTCUSDC","b":[["34956","0.0324"],["34957.16","0"]],"a":[["34977.23","0.1875"],["34962","0"]],"u":20010155,"seq":14108039217}}'
2023-11-02 14:54:21,189 DEBUG ++Rcv decoded: fin=1 opcode=1 data=b'{"topic":"orderbook.50.BTCUSDC","ts":1698936861103,"type":"delta","data":{"s":"BTCUSDC","b":[["34956","0.0324"],["34957.16","0"]],"a":[["34977.23","0.1875"],["34962","0"]],"u":20010155,"seq":14108039217}}'
2023-11-02 14:54:21,209 DEBUG ++Rcv raw: b'\x81~\x00\xd7{"topic":"orderbook.50.BTCUSDC","ts":1698936861123,"type":"delta","data":{"s":"BTCUSDC","b":[],"a":[["34977.74","0.045909"],["34978.28","0.001447"],["34960.49","0"],["34960.15","0"]],"u":20010156,"seq":14108039232}}'
2023-11-02 14:54:21,209 DEBUG ++Rcv decoded: fin=1 opcode=1 data=b'{"topic":"orderbook.50.BTCUSDC","ts":1698936861123,"type":"delta","data":{"s":"BTCUSDC","b":[],"a":[["34977.74","0.045909"],["34978.28","0.001447"],["34960.49","0"],["34960.15","0"]],"u":20010156,"seq":14108039232}}'
2023-11-02 14:54:21,229 DEBUG ++Rcv raw: b'\x81~\x00\xc4{"topic":"orderbook.50.BTCUSDC","ts":1698936861144,"type":"delta","data":{"s":"BTCUSDC","b":[["34957.17","0.010756"]],"a":[["34978.9","0.002162"],["34975.33","0"]],"u":20010157,"seq":14108039251}}'
2023-11-02 14:54:21,229 DEBUG ++Rcv decoded: fin=1 opcode=1 data=b'{"topic":"orderbook.50.BTCUSDC","ts":1698936861144,"type":"delta","data":{"s":"BTCUSDC","b":[["34957.17","0.010756"]],"a":[["34978.9","0.002162"],["34975.33","0"]],"u":20010157,"seq":14108039251}}'
2023-11-02 14:54:21,251 DEBUG ++Rcv raw: b'\x81~\x00\xed{"topic":"orderbook.50.BTCUSDC","ts":1698936861165,"type":"delta","data":{"s":"BTCUSDC","b":[["34957.17","0.013756"],["34954.71","0.051548"],["34953.11","0"]],"a":[["34960.08","0.028604"],["34978.9","0"]],"u":20010158,"seq":14108039271}}'
2023-11-02 14:54:21,251 DEBUG ++Rcv decoded: fin=1 opcode=1 data=b'{"topic":"orderbook.50.BTCUSDC","ts":1698936861165,"type":"delta","data":{"s":"BTCUSDC","b":[["34957.17","0.013756"],["34954.71","0.051548"],["34953.11","0"]],"a":[["34960.08","0.028604"],["34978.9","0"]],"u":20010158,"seq":14108039271}}'
2023-11-02 14:54:21,273 DEBUG ++Rcv raw: b'\x81~\x02\x15{"topic":"orderbook.50.BTCUSDC","ts":1698936861183,"type":"delta","data":{"s":"BTCUSDC","b":[["34957.19","0.008756"],["34957.18","0.01144"],["34957.17","0.005"],["34956.42","0.0859"],["34953.11","0.060144"],["34948","0.0341"],["34938.34","0.061143"],["34955.63","0"],["34928.02","0"],["34927.87","0"],["34931.31","0"],["34938.71","0"]],"a":[["34978.9","0.002162"],["34979.17","0.001"],["34980.48","0.023472"],["34981.28","0.000562"],["34963.3","0"],["34962.64","0"],["34960.08","0"],["34969.46","0"]],"u":20010159,"seq":14108039314}}'
2023-11-02 14:54:21,273 DEBUG ++Rcv decoded: fin=1 opcode=1 data=b'{"topic":"orderbook.50.BTCUSDC","ts":1698936861183,"type":"delta","data":{"s":"BTCUSDC","b":[["34957.19","0.008756"],["34957.18","0.01144"],["34957.17","0.005"],["34956.42","0.0859"],["34953.11","0.060144"],["34948","0.0341"],["34938.34","0.061143"],["34955.63","0"],["34928.02","0"],["34927.87","0"],["34931.31","0"],["34938.71","0"]],"a":[["34978.9","0.002162"],["34979.17","0.001"],["34980.48","0.023472"],["34981.28","0.000562"],["34963.3","0"],["34962.64","0"],["34960.08","0"],["34969.46","0"]],"u":20010159,"seq":14108039314}}'
2023-11-02 14:54:21,292 DEBUG ++Rcv raw: b'\x81~\x01\xdd{"topic":"orderbook.50.BTCUSDC","ts":1698936861203,"type":"delta","data":{"s":"BTCUSDC","b":[["34957.91","0.057211"],["34957.18","0.03742"],["34957.17","0.002"],["34950.78","0.114446"],["34941.24","0.286194"],["34932.01","0"],["34934.62","0"],["34938.72","0"]],"a":[["34964.62","0.0572"],["34965.01","0.00057"],["34971.3","0.114379"],["34980.84","0.28587"],["34982.24","0.02859"],["34969.67","0"],["34961.4","0"],["34962.63","0"],["34964","0"]],"u":20010160,"seq":14108039371}}'
2023-11-02 14:54:21,292 DEBUG ++Rcv decoded: fin=1 opcode=1 data=b'{"topic":"orderbook.50.BTCUSDC","ts":1698936861203,"type":"delta","data":{"s":"BTCUSDC","b":[["34957.91","0.057211"],["34957.18","0.03742"],["34957.17","0.002"],["34950.78","0.114446"],["34941.24","0.286194"],["34932.01","0"],["34934.62","0"],["34938.72","0"]],"a":[["34964.62","0.0572"],["34965.01","0.00057"],["34971.3","0.114379"],["34980.84","0.28587"],["34982.24","0.02859"],["34969.67","0"],["34961.4","0"],["34962.63","0"],["34964","0"]],"u":20010160,"seq":14108039371}}'
2023-11-02 14:54:21,309 DEBUG ++Rcv raw: b'\x81~\x024{"topic":"orderbook.50.BTCUSDC","ts":1698936861224,"type":"delta","data":{"s":"BTCUSDC","b":[["34959.77","0.008756"],["34959.76","0.098139"],["34957.91","0.02598"],["34957.2","0.053806"],["34954.71","0.080151"],["34953.1","0.022434"],["34951.27","0.068668"],["34947.41","0.1875"],["34946.38","0.000262"],["34936.35","0"],["34938.34","0"],["34935.28","0"],["34957.19","0"],["34937.39","0"],["34935.29","0"]],"a":[["34964.61","0.11262"],["34966.75","0.028603"],["34971.29","0.068629"],["34965.01","0"],["34965","0"],["34982.24","0"]],"u":20010161,"seq":14108039416}}'
2023-11-02 14:54:21,309 DEBUG ++Rcv decoded: fin=1 opcode=1 data=b'{"topic":"orderbook.50.BTCUSDC","ts":1698936861224,"type":"delta","data":{"s":"BTCUSDC","b":[["34959.77","0.008756"],["34959.76","0.098139"],["34957.91","0.02598"],["34957.2","0.053806"],["34954.71","0.080151"],["34953.1","0.022434"],["34951.27","0.068668"],["34947.41","0.1875"],["34946.38","0.000262"],["34936.35","0"],["34938.34","0"],["34935.28","0"],["34957.19","0"],["34937.39","0"],["34935.29","0"]],"a":[["34964.61","0.11262"],["34966.75","0.028603"],["34971.29","0.068629"],["34965.01","0"],["34965","0"],["34982.24","0"]],"u":20010161,"seq":14108039416}}'
2023-11-02 14:54:21,331 DEBUG ++Rcv raw: b'\x81~\x01\xb7{"topic":"orderbook.50.BTCUSDC","ts":1698936861244,"type":"delta","data":{"s":"BTCUSDC","b":[["34958.14","0.0859"],["34956.43","0.027568"],["34954.71","0.028603"],["34951.28","0.003448"],["34948.02","0"],["34959.76","0"],["34950.98","0"]],"a":[["34963.17","0.022853"],["34963.18","0.038081"],["34967.99","0.051544"],["34969.5","0.00057"],["34979.17","0"],["34980.84","0"],["34964.62","0"],["34981.28","0"]],"u":20010162,"seq":14108039454}}'
2023-11-02 14:54:21,331 DEBUG ++Rcv decoded: fin=1 opcode=1 data=b'{"topic":"orderbook.50.BTCUSDC","ts":1698936861244,"type":"delta","data":{"s":"BTCUSDC","b":[["34958.14","0.0859"],["34956.43","0.027568"],["34954.71","0.028603"],["34951.28","0.003448"],["34948.02","0"],["34959.76","0"],["34950.98","0"]],"a":[["34963.17","0.022853"],["34963.18","0.038081"],["34967.99","0.051544"],["34969.5","0.00057"],["34979.17","0"],["34980.84","0"],["34964.62","0"],["34981.28","0"]],"u":20010162,"seq":14108039454}}'
2023-11-02 14:54:21,352 DEBUG ++Rcv raw: b'\x81~\x01f{"topic":"orderbook.50.BTCUSDC","ts":1698936861263,"type":"delta","data":{"s":"BTCUSDC","b":[["34954.88","0.00057"],["34954.72","0.06871"],["34949.55","0.051547"],["34948.58","0.366339"],["34958.14","0"],["34948.57","0"],["34956.43","0"],["34948.56","0"]],"a":[["34964.61","0.051548"],["34980.84","0.28587"],["34963.18","0"]],"u":20010163,"seq":14108039480}}'
2023-11-02 14:54:21,352 DEBUG ++Rcv decoded: fin=1 opcode=1 data=b'{"topic":"orderbook.50.BTCUSDC","ts":1698936861263,"type":"delta","data":{"s":"BTCUSDC","b":[["34954.88","0.00057"],["34954.72","0.06871"],["34949.55","0.051547"],["34948.58","0.366339"],["34958.14","0"],["34948.57","0"],["34956.43","0"],["34948.56","0"]],"a":[["34964.61","0.051548"],["34980.84","0.28587"],["34963.18","0"]],"u":20010163,"seq":14108039480}}'
2023-11-02 14:54:21,370 DEBUG ++Rcv raw: b'\x81~\x01:{"topic":"orderbook.50.BTCUSDC","ts":1698936861284,"type":"delta","data":{"s":"BTCUSDC","b":[["34958","0.0324"],["34957.18","0.02598"],["34948.59","0.219803"],["34945.01","0.114412"],["34948.58","0"],["34949.55","0"],["34939.85","0"]],"a":[["34978.02","0.114412"],["34963.17","0"]],"u":20010164,"seq":14108039507}}'
2023-11-02 14:54:21,370 DEBUG ++Rcv decoded: fin=1 opcode=1 data=b'{"topic":"orderbook.50.BTCUSDC","ts":1698936861284,"type":"delta","data":{"s":"BTCUSDC","b":[["34958","0.0324"],["34957.18","0.02598"],["34948.59","0.219803"],["34945.01","0.114412"],["34948.58","0"],["34949.55","0"],["34939.85","0"]],"a":[["34978.02","0.114412"],["34963.17","0"]],"u":20010164,"seq":14108039507}}'
2023-11-02 14:54:21,390 DEBUG ++Rcv raw: b'\x81~\x01${"topic":"orderbook.50.BTCUSDC","ts":1698936861304,"type":"delta","data":{"s":"BTCUSDC","b":[["34956.43","0.0301"],["34949.55","0.051542"],["34954.72","0"],["34948.59","0"]],"a":[["34981.28","0.000562"],["34982.24","0.02859"],["34971.3","0"],["34980.84","0"]],"u":20010165,"seq":14108039534}}'
2023-11-02 14:54:21,390 DEBUG ++Rcv decoded: fin=1 opcode=1 data=b'{"topic":"orderbook.50.BTCUSDC","ts":1698936861304,"type":"delta","data":{"s":"BTCUSDC","b":[["34956.43","0.0301"],["34949.55","0.051542"],["34954.72","0"],["34948.59","0"]],"a":[["34981.28","0.000562"],["34982.24","0.02859"],["34971.3","0"],["34980.84","0"]],"u":20010165,"seq":14108039534}}'
2023-11-02 14:54:21,410 DEBUG ++Rcv raw: b'\x81~\x01\x00{"topic":"orderbook.50.BTCUSDC","ts":1698936861323,"type":"delta","data":{"s":"BTCUSDC","b":[],"a":[["34963.82","0.057201"],["34970.27","0.114382"],["34979.86","0.285878"],["34980.48","0"],["34981.28","0"],["34982.24","0"]],"u":20010166,"seq":14108039543}}'
2023-11-02 14:54:21,411 DEBUG ++Rcv decoded: fin=1 opcode=1 data=b'{"topic":"orderbook.50.BTCUSDC","ts":1698936861323,"type":"delta","data":{"s":"BTCUSDC","b":[],"a":[["34963.82","0.057201"],["34970.27","0.114382"],["34979.86","0.285878"],["34980.48","0"],["34981.28","0"],["34982.24","0"]],"u":20010166,"seq":14108039543}}'
2023-11-02 14:54:21,429 DEBUG ++Rcv raw: b'\x81~\x00\xe9{"topic":"orderbook.50.BTCUSDC","ts":1698936861344,"type":"delta","data":{"s":"BTCUSDC","b":[["34956.43","0.06722"],["34939.85","0.1875"],["34948.55","0"]],"a":[["34977.05","0.0005"],["34979.86","0"]],"u":20010167,"seq":14108039556}}'
2023-11-02 14:54:21,429 DEBUG ++Rcv decoded: fin=1 opcode=1 data=b'{"topic":"orderbook.50.BTCUSDC","ts":1698936861344,"type":"delta","data":{"s":"BTCUSDC","b":[["34956.43","0.06722"],["34939.85","0.1875"],["34948.55","0"]],"a":[["34977.05","0.0005"],["34979.86","0"]],"u":20010167,"seq":14108039556}}'
2023-11-02 14:54:21,450 DEBUG ++Rcv raw: b'\x81~\x00\xed{"topic":"orderbook.50.BTCUSDC","ts":1698936861364,"type":"delta","data":{"s":"BTCUSDC","b":[["34959.78","0.028604"],["34956.43","0.0301"],["34938.34","0.061143"],["34943.15","0"],["34950.78","0"]],"a":[],"u":20010168,"seq":14108039570}}'
2023-11-02 14:54:21,450 DEBUG ++Rcv decoded: fin=1 opcode=1 data=b'{"topic":"orderbook.50.BTCUSDC","ts":1698936861364,"type":"delta","data":{"s":"BTCUSDC","b":[["34959.78","0.028604"],["34956.43","0.0301"],["34938.34","0.061143"],["34943.15","0"],["34950.78","0"]],"a":[],"u":20010168,"seq":14108039570}}'
2023-11-02 14:54:21,469 DEBUG ++Rcv raw: b'\x81~\x00\xc5{"topic":"orderbook.50.BTCUSDC","ts":1698936861384,"type":"delta","data":{"s":"BTCUSDC","b":[["34956.43","0.067221"],["34949.75","0.11445"],["34951.27","0"]],"a":[],"u":20010169,"seq":14108039573}}'
2023-11-02 14:54:21,470 DEBUG ++Rcv decoded: fin=1 opcode=1 data=b'{"topic":"orderbook.50.BTCUSDC","ts":1698936861384,"type":"delta","data":{"s":"BTCUSDC","b":[["34956.43","0.067221"],["34949.75","0.11445"],["34951.27","0"]],"a":[],"u":20010169,"seq":14108039573}}'
2023-11-02 14:54:21,489 DEBUG ++Rcv raw: b'\x81~\x01\x00{"topic":"orderbook.50.BTCUSDC","ts":1698936861403,"type":"delta","data":{"s":"BTCUSDC","b":[["34959.79","0.008756"],["34950.01","0.068675"],["34940.14","0.286203"],["34949.55","0"],["34959.77","0"],["34941.24","0"]],"a":[],"u":20010170,"seq":14108039589}}'
2023-11-02 14:54:21,489 DEBUG ++Rcv decoded: fin=1 opcode=1 data=b'{"topic":"orderbook.50.BTCUSDC","ts":1698936861403,"type":"delta","data":{"s":"BTCUSDC","b":[["34959.79","0.008756"],["34950.01","0.068675"],["34940.14","0.286203"],["34949.55","0"],["34959.77","0"],["34941.24","0"]],"a":[],"u":20010170,"seq":14108039589}}'
2023-11-02 14:54:21,510 DEBUG ++Rcv raw: b'\x81~\x00\xfe{"topic":"orderbook.50.BTCUSDC","ts":1698936861424,"type":"delta","data":{"s":"BTCUSDC","b":[["34957.21","0.030388"],["34954.72","0.051547"],["34938.34","0"],["34939.85","0"]],"a":[["34961.39","0.016702"],["34978.9","0"]],"u":20010171,"seq":14108039605}}'
2023-11-02 14:54:21,510 DEBUG ++Rcv decoded: fin=1 opcode=1 data=b'{"topic":"orderbook.50.BTCUSDC","ts":1698936861424,"type":"delta","data":{"s":"BTCUSDC","b":[["34957.21","0.030388"],["34954.72","0.051547"],["34938.34","0"],["34939.85","0"]],"a":[["34961.39","0.016702"],["34978.9","0"]],"u":20010171,"seq":14108039605}}'
2023-11-02 14:54:21,529 DEBUG ++Rcv raw: b'\x81~\x00\xd4{"topic":"orderbook.50.BTCUSDC","ts":1698936861444,"type":"delta","data":{"s":"BTCUSDC","b":[["34945.02","0.068655"],["34939.85","0.1875"],["34957.2","0"],["34954.88","0"]],"a":[],"u":20010172,"seq":14108039620}}'
2023-11-02 14:54:21,530 DEBUG ++Rcv decoded: fin=1 opcode=1 data=b'{"topic":"orderbook.50.BTCUSDC","ts":1698936861444,"type":"delta","data":{"s":"BTCUSDC","b":[["34945.02","0.068655"],["34939.85","0.1875"],["34957.2","0"],["34954.88","0"]],"a":[],"u":20010172,"seq":14108039620}}'
2023-11-02 14:54:21,548 DEBUG ++Rcv raw: b'\x81~\x01 {"topic":"orderbook.50.BTCUSDC","ts":1698936861463,"type":"delta","data":{"s":"BTCUSDC","b":[["34951.85","0.036"],["34938.34","0.061143"],["34937.39","0.278379"],["34959.78","0"],["34954.72","0"],["34957.21","0"]],"a":[["34967.23","0.03"],["34969.5","0"]],"u":20010173,"seq":14108039648}}'
2023-11-02 14:54:21,549 DEBUG ++Rcv decoded: fin=1 opcode=1 data=b'{"topic":"orderbook.50.BTCUSDC","ts":1698936861463,"type":"delta","data":{"s":"BTCUSDC","b":[["34951.85","0.036"],["34938.34","0.061143"],["34937.39","0.278379"],["34959.78","0"],["34954.72","0"],["34957.21","0"]],"a":[["34967.23","0.03"],["34969.5","0"]],"u":20010173,"seq":14108039648}}'
2023-11-02 14:54:21,629 DEBUG ++Rcv raw: b'\x81~\x00\xff{"topic":"orderbook.50.BTCUSDC","ts":1698936861544,"type":"delta","data":{"s":"BTCUSDC","b":[["34960.02","0.107383"],["34950.02","0.003492"],["34937.39","0"],["34938.34","0"]],"a":[["34963.53","0.036252"],["34961.39","0"]],"u":20010174,"seq":14108039695}}'
2023-11-02 14:54:21,630 DEBUG ++Rcv decoded: fin=1 opcode=1 data=b'{"topic":"orderbook.50.BTCUSDC","ts":1698936861544,"type":"delta","data":{"s":"BTCUSDC","b":[["34960.02","0.107383"],["34950.02","0.003492"],["34937.39","0"],["34938.34","0"]],"a":[["34963.53","0.036252"],["34961.39","0"]],"u":20010174,"seq":14108039695}}'
2023-11-02 14:54:21,649 DEBUG ++Rcv raw: b'\x81~\x01\xa0{"topic":"orderbook.50.BTCUSDC","ts":1698936861564,"type":"delta","data":{"s":"BTCUSDC","b":[["34960.03","0.008756"],["34958.14","0.0859"],["34956.48","0.057213"],["34955.13","0.00057"],["34948.02","0.356271"],["34951.28","0"],["34960.02","0"],["34959.79","0"],["34940.94","0"],["34939.85","0"]],"a":[["34963.46","0.057202"],["34963.52","0.021752"],["34963.82","0"],["34963.53","0"]],"u":20010175,"seq":14108039714}}'
2023-11-02 14:54:21,650 DEBUG ++Rcv decoded: fin=1 opcode=1 data=b'{"topic":"orderbook.50.BTCUSDC","ts":1698936861564,"type":"delta","data":{"s":"BTCUSDC","b":[["34960.03","0.008756"],["34958.14","0.0859"],["34956.48","0.057213"],["34955.13","0.00057"],["34948.02","0.356271"],["34951.28","0"],["34960.02","0"],["34959.79","0"],["34940.94","0"],["34939.85","0"]],"a":[["34963.46","0.057202"],["34963.52","0.021752"],["34963.82","0"],["34963.53","0"]],"u":20010175,"seq":14108039714}}'
2023-11-02 14:54:21,669 DEBUG ++Rcv raw: b'\x81~\x01${"topic":"orderbook.50.BTCUSDC","ts":1698936861584,"type":"delta","data":{"s":"BTCUSDC","b":[["34956.49","0.10531"],["34939.85","0.1875"],["34958.14","0"],["34956.43","0"]],"a":[["34963.45","0.034325"],["34968.42","0.00057"],["34978.28","0"],["34963.52","0"]],"u":20010176,"seq":14108039731}}'
2023-11-02 14:54:21,669 DEBUG ++Rcv decoded: fin=1 opcode=1 data=b'{"topic":"orderbook.50.BTCUSDC","ts":1698936861584,"type":"delta","data":{"s":"BTCUSDC","b":[["34956.49","0.10531"],["34939.85","0.1875"],["34958.14","0"],["34956.43","0"]],"a":[["34963.45","0.034325"],["34968.42","0.00057"],["34978.28","0"],["34963.52","0"]],"u":20010176,"seq":14108039731}}'
2023-11-02 14:54:21,688 DEBUG ++Rcv raw: b'\x81~\x00\xae{"topic":"orderbook.50.BTCUSDC","ts":1698936861603,"type":"delta","data":{"s":"BTCUSDC","b":[],"a":[["34978.28","0.001447"],["34963.46","0"]],"u":20010177,"seq":14108039735}}'
2023-11-02 14:54:21,688 DEBUG ++Rcv decoded: fin=1 opcode=1 data=b'{"topic":"orderbook.50.BTCUSDC","ts":1698936861603,"type":"delta","data":{"s":"BTCUSDC","b":[],"a":[["34978.28","0.001447"],["34963.46","0"]],"u":20010177,"seq":14108039735}}'
2023-11-02 14:54:21,709 DEBUG ++Rcv raw: b'\x81~\x00\xad{"topic":"orderbook.50.BTCUSDC","ts":1698936861623,"type":"delta","data":{"s":"BTCUSDC","b":[],"a":[["34978.9","0.002162"],["34963.45","0"]],"u":20010178,"seq":14108039739}}'
2023-11-02 14:54:21,709 DEBUG ++Rcv decoded: fin=1 opcode=1 data=b'{"topic":"orderbook.50.BTCUSDC","ts":1698936861623,"type":"delta","data":{"s":"BTCUSDC","b":[],"a":[["34978.9","0.002162"],["34963.45","0"]],"u":20010178,"seq":14108039739}}'
2023-11-02 14:54:21,729 DEBUG ++Rcv raw: b'\x81~\x00\xd3{"topic":"orderbook.50.BTCUSDC","ts":1698936861643,"type":"delta","data":{"s":"BTCUSDC","b":[["34958.14","0.0859"],["34939.85","0"]],"a":[["34963.52","0.028601"],["34978.9","0"]],"u":20010179,"seq":14108039748}}'
2023-11-02 14:54:21,729 DEBUG ++Rcv decoded: fin=1 opcode=1 data=b'{"topic":"orderbook.50.BTCUSDC","ts":1698936861643,"type":"delta","data":{"s":"BTCUSDC","b":[["34958.14","0.0859"],["34939.85","0"]],"a":[["34963.52","0.028601"],["34978.9","0"]],"u":20010179,"seq":14108039748}}'
2023-11-02 14:54:21,789 DEBUG ++Rcv raw: b'\x81~\x00\xad{"topic":"orderbook.50.BTCUSDC","ts":1698936861704,"type":"delta","data":{"s":"BTCUSDC","b":[["34959.8","0.028604"],["34940.14","0"]],"a":[],"u":20010180,"seq":14108039771}}'
2023-11-02 14:54:21,789 DEBUG ++Rcv decoded: fin=1 opcode=1 data=b'{"topic":"orderbook.50.BTCUSDC","ts":1698936861704,"type":"delta","data":{"s":"BTCUSDC","b":[["34959.8","0.028604"],["34940.14","0"]],"a":[],"u":20010180,"seq":14108039771}}'
2023-11-02 14:54:21,809 DEBUG ++Rcv raw: b'\x81~\x00\xd6{"topic":"orderbook.50.BTCUSDC","ts":1698936861723,"type":"delta","data":{"s":"BTCUSDC","b":[["34958.15","0.069412"],["34954.72","0.051546"],["34956.49","0"],["34940.3","0"]],"a":[],"u":20010181,"seq":14108039776}}'
2023-11-02 14:54:21,809 DEBUG ++Rcv decoded: fin=1 opcode=1 data=b'{"topic":"orderbook.50.BTCUSDC","ts":1698936861723,"type":"delta","data":{"s":"BTCUSDC","b":[["34958.15","0.069412"],["34954.72","0.051546"],["34956.49","0"],["34940.3","0"]],"a":[],"u":20010181,"seq":14108039776}}'
2023-11-02 14:54:21,829 DEBUG ++Rcv raw: b'\x81~\x01\x00{"topic":"orderbook.50.BTCUSDC","ts":1698936861743,"type":"delta","data":{"s":"BTCUSDC","b":[],"a":[["34963.47","0.051488"],["34963.48","0.057202"],["34976.72","0.075313"],["34963.52","0"],["34978.28","0"],["34972.23","0"]],"u":20010182,"seq":14108039791}}'
2023-11-02 14:54:21,830 DEBUG ++Rcv decoded: fin=1 opcode=1 data=b'{"topic":"orderbook.50.BTCUSDC","ts":1698936861743,"type":"delta","data":{"s":"BTCUSDC","b":[],"a":[["34963.47","0.051488"],["34963.48","0.057202"],["34976.72","0.075313"],["34963.52","0"],["34978.28","0"],["34972.23","0"]],"u":20010182,"seq":14108039791}}'
2023-11-02 14:54:21,849 DEBUG ++Rcv raw: b'\x81~\x01\x05{"topic":"orderbook.50.BTCUSDC","ts":1698936861764,"type":"delta","data":{"s":"BTCUSDC","b":[["34960.03","0.011756"],["34940.3","0.025298"],["34956.48","0"]],"a":[["34963.47","0.034329"],["34978.28","0.001447"],["34963.48","0"]],"u":20010183,"seq":14108039809}}'
2023-11-02 14:54:21,849 DEBUG ++Rcv decoded: fin=1 opcode=1 data=b'{"topic":"orderbook.50.BTCUSDC","ts":1698936861764,"type":"delta","data":{"s":"BTCUSDC","b":[["34960.03","0.011756"],["34940.3","0.025298"],["34956.48","0"]],"a":[["34963.47","0.034329"],["34978.28","0.001447"],["34963.48","0"]],"u":20010183,"seq":14108039809}}'
2023-11-02 14:54:21,870 DEBUG ++Rcv raw: b'\x81~\x00\xfc{"topic":"orderbook.50.BTCUSDC","ts":1698936861784,"type":"delta","data":{"s":"BTCUSDC","b":[["34960.39","0.10355"],["34955.77","0.057215"],["34940.87","0"],["34940.3","0"]],"a":[["34963.9","0.039078"],["34963.47","0"]],"u":20010184,"seq":14108039820}}'
2023-11-02 14:54:21,870 DEBUG ++Rcv decoded: fin=1 opcode=1 data=b'{"topic":"orderbook.50.BTCUSDC","ts":1698936861784,"type":"delta","data":{"s":"BTCUSDC","b":[["34960.39","0.10355"],["34955.77","0.057215"],["34940.87","0"],["34940.3","0"]],"a":[["34963.9","0.039078"],["34963.47","0"]],"u":20010184,"seq":14108039820}}'
2023-11-02 14:54:21,889 DEBUG ++Rcv raw: b'\x81~\x01\'{"topic":"orderbook.50.BTCUSDC","ts":1698936861804,"type":"delta","data":{"s":"BTCUSDC","b":[["34960.4","0.008756"],["34960.03","0.003"],["34958.15","0.038957"],["34942","0"]],"a":[["34978.76","0.285887"],["34978.9","0.002162"],["34970.27","0"],["34965.02","0"]],"u":20010185,"seq":14108039832}}'
2023-11-02 14:54:21,889 DEBUG ++Rcv decoded: fin=1 opcode=1 data=b'{"topic":"orderbook.50.BTCUSDC","ts":1698936861804,"type":"delta","data":{"s":"BTCUSDC","b":[["34960.4","0.008756"],["34960.03","0.003"],["34958.15","0.038957"],["34942","0"]],"a":[["34978.76","0.285887"],["34978.9","0.002162"],["34970.27","0"],["34965.02","0"]],"u":20010185,"seq":14108039832}}'
2023-11-02 14:54:21,909 DEBUG ++Rcv raw: b'\x81~\x01J{"topic":"orderbook.50.BTCUSDC","ts":1698936861824,"type":"delta","data":{"s":"BTCUSDC","b":[["34942","0.0341"],["34940.87","0.00154"],["34960.03","0"],["34960.39","0"]],"a":[["34963.51","0.028601"],["34963.89","0.023446"],["34969.24","0.114386"],["34978.76","0"],["34978.9","0"],["34964.61","0"]],"u":20010186,"seq":14108039843}}'
2023-11-02 14:54:21,909 DEBUG ++Rcv decoded: fin=1 opcode=1 data=b'{"topic":"orderbook.50.BTCUSDC","ts":1698936861824,"type":"delta","data":{"s":"BTCUSDC","b":[["34942","0.0341"],["34940.87","0.00154"],["34960.03","0"],["34960.39","0"]],"a":[["34963.51","0.028601"],["34963.89","0.023446"],["34969.24","0.114386"],["34978.76","0"],["34978.9","0"],["34964.61","0"]],"u":20010186,"seq":14108039843}}'
2023-11-02 14:54:21,929 DEBUG ++Rcv raw: b'\x81~\x00\xad{"topic":"orderbook.50.BTCUSDC","ts":1698936861843,"type":"delta","data":{"s":"BTCUSDC","b":[],"a":[["34978.76","0.285887"],["34963.9","0"]],"u":20010187,"seq":14108039846}}'
2023-11-02 14:54:21,929 DEBUG ++Rcv decoded: fin=1 opcode=1 data=b'{"topic":"orderbook.50.BTCUSDC","ts":1698936861843,"type":"delta","data":{"s":"BTCUSDC","b":[],"a":[["34978.76","0.285887"],["34963.9","0"]],"u":20010187,"seq":14108039846}}'
2023-11-02 14:54:21,949 DEBUG ++Rcv raw: b'\x81~\x00\xec{"topic":"orderbook.50.BTCUSDC","ts":1698936861864,"type":"delta","data":{"s":"BTCUSDC","b":[["34940.3","0.025298"],["34955.77","0"]],"a":[["34966.47","0.076178"],["34978.9","0.002162"],["34963.89","0"]],"u":20010188,"seq":14108039874}}'
2023-11-02 14:54:21,949 DEBUG ++Rcv decoded: fin=1 opcode=1 data=b'{"topic":"orderbook.50.BTCUSDC","ts":1698936861864,"type":"delta","data":{"s":"BTCUSDC","b":[["34940.3","0.025298"],["34955.77","0"]],"a":[["34966.47","0.076178"],["34978.9","0.002162"],["34963.89","0"]],"u":20010188,"seq":14108039874}}'
2023-11-02 14:54:21,969 DEBUG ++Rcv raw: b'\x81~\x00\xfd{"topic":"orderbook.50.BTCUSDC","ts":1698936861884,"type":"delta","data":{"s":"BTCUSDC","b":[["34956.24","0.057214"],["34940.3","0"]],"a":[["34963.12","0.051484"],["34963.13","0.057203"],["34978.9","0"],["34978.76","0"]],"u":20010189,"seq":14108039907}}'
2023-11-02 14:54:21,969 DEBUG ++Rcv decoded: fin=1 opcode=1 data=b'{"topic":"orderbook.50.BTCUSDC","ts":1698936861884,"type":"delta","data":{"s":"BTCUSDC","b":[["34956.24","0.057214"],["34940.3","0"]],"a":[["34963.12","0.051484"],["34963.13","0.057203"],["34978.9","0"],["34978.76","0"]],"u":20010189,"seq":14108039907}}'
2023-11-02 14:54:21,989 DEBUG ++Rcv raw: b'\x81~\x00\xed{"topic":"orderbook.50.BTCUSDC","ts":1698936861904,"type":"delta","data":{"s":"BTCUSDC","b":[["34940.3","0.025298"],["34955.13","0"]],"a":[["34966.47","0.051544"],["34978.76","0.285887"],["34968.42","0"]],"u":20010190,"seq":14108039929}}'
2023-11-02 14:54:21,989 DEBUG ++Rcv decoded: fin=1 opcode=1 data=b'{"topic":"orderbook.50.BTCUSDC","ts":1698936861904,"type":"delta","data":{"s":"BTCUSDC","b":[["34940.3","0.025298"],["34955.13","0"]],"a":[["34966.47","0.051544"],["34978.76","0.285887"],["34968.42","0"]],"u":20010190,"seq":14108039929}}'
2023-11-02 14:54:22,009 DEBUG ++Rcv raw: b'\x81~\x00\xc5{"topic":"orderbook.50.BTCUSDC","ts":1698936861924,"type":"delta","data":{"s":"BTCUSDC","b":[["34958.15","0.024558"],["34940.14","0.286203"],["34959.8","0"]],"a":[],"u":20010191,"seq":14108039940}}'
2023-11-02 14:54:22,010 DEBUG ++Rcv decoded: fin=1 opcode=1 data=b'{"topic":"orderbook.50.BTCUSDC","ts":1698936861924,"type":"delta","data":{"s":"BTCUSDC","b":[["34958.15","0.024558"],["34940.14","0.286203"],["34959.8","0"]],"a":[],"u":20010191,"seq":14108039940}}'
2023-11-02 14:54:22,030 DEBUG ++Rcv raw: b'\x81~\x00\xac{"topic":"orderbook.50.BTCUSDC","ts":1698936861944,"type":"delta","data":{"s":"BTCUSDC","b":[],"a":[["34965.02","0.0859"],["34963.51","0"]],"u":20010192,"seq":14108039944}}'
2023-11-02 14:54:22,030 DEBUG ++Rcv decoded: fin=1 opcode=1 data=b'{"topic":"orderbook.50.BTCUSDC","ts":1698936861944,"type":"delta","data":{"s":"BTCUSDC","b":[],"a":[["34965.02","0.0859"],["34963.51","0"]],"u":20010192,"seq":14108039944}}'
2023-11-02 14:54:22,048 DEBUG ++Rcv raw: b'\x81~\x00\xc6{"topic":"orderbook.50.BTCUSDC","ts":1698936861963,"type":"delta","data":{"s":"BTCUSDC","b":[],"a":[["34963.12","0.034325"],["34965.01","0.051545"],["34978.76","0"]],"u":20010193,"seq":14108039950}}'
