2023-11-02 14:54:41,189 DEBUG ++Rcv raw: b'\x81~\x00\xd5{"topic":"orderbook.50.BTCUSDC","ts":1698936881103,"type":"delta","data":{"s":"BTCUSDC","b":[["34946.11","0.051542"],["34936.35","0"]],"a":[["34980.19","0.171527"],["34980.2","0"]],"u":20010837,"seq":14108050635}}'
2023-11-02 14:54:41,189 DEBUG ++Rcv decoded: fin=1 opcode=1 data=b'{"topic":"orderbook.50.BTCUSDC","ts":1698936881103,"type":"delta","data":{"s":"BTCUSDC","b":[["34946.11","0.051542"],["34936.35","0"]],"a":[["34980.19","0.171527"],["34980.2","0"]],"u":20010837,"seq":14108050635}}'
2023-11-02 14:54:41,209 DEBUG ++Rcv raw: b'\x81~\x00\xac{"topic":"orderbook.50.BTCUSDC","ts":1698936881124,"type":"delta","data":{"s":"BTCUSDC","b":[["34936.35","0.1875"],["34939.34","0"]],"a":[],"u":20010838,"seq":14108050647}}'
2023-11-02 14:54:41,210 DEBUG ++Rcv decoded: fin=1 opcode=1 data=b'{"topic":"orderbook.50.BTCUSDC","ts":1698936881124,"type":"delta","data":{"s":"BTCUSDC","b":[["34936.35","0.1875"],["34939.34","0"]],"a":[],"u":20010838,"seq":14108050647}}'
2023-11-02 14:54:41,290 DEBUG ++Rcv raw: b'\x81~\x00\xae{"topic":"orderbook.50.BTCUSDC","ts":1698936881204,"type":"delta","data":{"s":"BTCUSDC","b":[],"a":[["34973.99","0.043411"],["34980.19","0"]],"u":20010839,"seq":14108050682}}'
2023-11-02 14:54:41,290 DEBUG ++Rcv decoded: fin=1 opcode=1 data=b'{"topic":"orderbook.50.BTCUSDC","ts":1698936881204,"type":"delta","data":{"s":"BTCUSDC","b":[],"a":[["34973.99","0.043411"],["34980.19","0"]],"u":20010839,"seq":14108050682}}'
2023-11-02 14:54:41,329 DEBUG ++Rcv raw: b'\x81~\x00\xd6{"topic":"orderbook.50.BTCUSDC","ts":1698936881244,"type":"delta","data":{"s":"BTCUSDC","b":[],"a":[["34963.67","0.095021"],["34963.68","0.028601"],["34978.9","0"],["34965.01","0"]],"u":20010840,"seq":14108050719}}'
2023-11-02 14:54:41,329 DEBUG ++Rcv decoded: fin=1 opcode=1 data=b'{"topic":"orderbook.50.BTCUSDC","ts":1698936881244,"type":"delta","data":{"s":"BTCUSDC","b":[],"a":[["34963.67","0.095021"],["34963.68","0.028601"],["34978.9","0"],["34965.01","0"]],"u":20010840,"seq":14108050719}}'
2023-11-02 14:54:41,349 DEBUG ++Rcv raw: b'\x81~\x01({"topic":"orderbook.50.BTCUSDC","ts":1698936881264,"type":"delta","data":{"s":"BTCUSDC","b":[],"a":[["34960.53","0.048747"],["34960.54","0.081237"],["34963.66","0.008756"],["34968.56","0.00057"],["34978.28","0"],["34963.77","0"],["34977.05","0"],["34977.06","0"]],"u":20010841,"seq":14108050737}}'
2023-11-02 14:54:41,350 DEBUG ++Rcv decoded: fin=1 opcode=1 data=b'{"topic":"orderbook.50.BTCUSDC","ts":1698936881264,"type":"delta","data":{"s":"BTCUSDC","b":[],"a":[["34960.53","0.048747"],["34960.54","0.081237"],["34963.66","0.008756"],["34968.56","0.00057"],["34978.28","0"],["34963.77","0"],["34977.05","0"],["34977.06","0"]],"u":20010841,"seq":14108050737}}'
2023-11-02 14:54:41,369 DEBUG ++Rcv raw: b'\x81~\x01?{"topic":"orderbook.50.BTCUSDC","ts":1698936881284,"type":"delta","data":{"s":"BTCUSDC","b":[],"a":[["34963.66","0.038756"],["34965.01","0.051546"],["34977.05","0.051548"],["34977.06","0.0859"],["34978.28","0.279826"],["34963.94","0"],["34963.67","0"],["34968.56","0"],["34960.54","0"]],"u":20010842,"seq":14108050752}}'
2023-11-02 14:54:41,369 DEBUG ++Rcv decoded: fin=1 opcode=1 data=b'{"topic":"orderbook.50.BTCUSDC","ts":1698936881284,"type":"delta","data":{"s":"BTCUSDC","b":[],"a":[["34963.66","0.038756"],["34965.01","0.051546"],["34977.05","0.051548"],["34977.06","0.0859"],["34978.28","0.279826"],["34963.94","0"],["34963.67","0"],["34968.56","0"],["34960.54","0"]],"u":20010842,"seq":14108050752}}'
2023-11-02 14:54:41,388 DEBUG ++Rcv raw: b'\x81~\x00\xd6{"topic":"orderbook.50.BTCUSDC","ts":1698936881303,"type":"delta","data":{"s":"BTCUSDC","b":[],"a":[["34963.65","0.095024"],["34978.9","0.002162"],["34960.53","0"],["34965.01","0"]],"u":20010843,"seq":14108050757}}'
2023-11-02 14:54:41,389 DEBUG ++Rcv decoded: fin=1 opcode=1 data=b'{"topic":"orderbook.50.BTCUSDC","ts":1698936881303,"type":"delta","data":{"s":"BTCUSDC","b":[],"a":[["34963.65","0.095024"],["34978.9","0.002162"],["34960.53","0"],["34965.01","0"]],"u":20010843,"seq":14108050757}}'
2023-11-02 14:54:41,409 DEBUG ++Rcv raw: b'\x81~\x01\x11{"topic":"orderbook.50.BTCUSDC","ts":1698936881324,"type":"delta","data":{"s":"BTCUSDC","b":[["34949.58","0.014223"],["34936.35","0"]],"a":[["34963.64","0.038756"],["34963.66","0.03"],["34968.54","0.00057"],["34978.28","0"],["34978.9","0"]],"u":20010844,"seq":14108050770}}'
2023-11-02 14:54:41,409 DEBUG ++Rcv decoded: fin=1 opcode=1 data=b'{"topic":"orderbook.50.BTCUSDC","ts":1698936881324,"type":"delta","data":{"s":"BTCUSDC","b":[["34949.58","0.014223"],["34936.35","0"]],"a":[["34963.64","0.038756"],["34963.66","0.03"],["34968.54","0.00057"],["34978.28","0"],["34978.9","0"]],"u":20010844,"seq":14108050770}}'
2023-11-02 14:54:41,428 DEBUG ++Rcv raw: b'\x81~\x00\xee{"topic":"orderbook.50.BTCUSDC","ts":1698936881343,"type":"delta","data":{"s":"BTCUSDC","b":[["34948.17","0.000261"],["34936.36","0"]],"a":[["34963.64","0.008756"],["34970.33","0.000239"],["34977.06","0"]],"u":20010845,"seq":14108050780}}'
2023-11-02 14:54:41,429 DEBUG ++Rcv decoded: fin=1 opcode=1 data=b'{"topic":"orderbook.50.BTCUSDC","ts":1698936881343,"type":"delta","data":{"s":"BTCUSDC","b":[["34948.17","0.000261"],["34936.36","0"]],"a":[["34963.64","0.008756"],["34970.33","0.000239"],["34977.06","0"]],"u":20010845,"seq":14108050780}}'
2023-11-02 14:54:41,529 DEBUG ++Rcv raw: b'\x81~\x00\xab{"topic":"orderbook.50.BTCUSDC","ts":1698936881443,"type":"delta","data":{"s":"BTCUSDC","b":[],"a":[["34977.06","0.0859"],["34963.8","0"]],"u":20010846,"seq":14108050824}}'
2023-11-02 14:54:41,529 DEBUG ++Rcv decoded: fin=1 opcode=1 data=b'{"topic":"orderbook.50.BTCUSDC","ts":1698936881443,"type":"delta","data":{"s":"BTCUSDC","b":[],"a":[["34977.06","0.0859"],["34963.8","0"]],"u":20010846,"seq":14108050824}}'
2023-11-02 14:54:41,588 DEBUG ++Rcv raw: b'\x81~\x016{"topic":"orderbook.50.BTCUSDC","ts":1698936881503,"type":"delta","data":{"s":"BTCUSDC","b":[["34936.36","0.823804"],["34936.35","0.1875"],["34957.13","0"],["34956","0"]],"a":[["34961.99","0.008756"],["34962","0.0324"],["34963.64","0.026078"],["34977.06","0"],["34963.68","0"]],"u":20010847,"seq":14108050850}}'
2023-11-02 14:54:41,589 DEBUG ++Rcv decoded: fin=1 opcode=1 data=b'{"topic":"orderbook.50.BTCUSDC","ts":1698936881503,"type":"delta","data":{"s":"BTCUSDC","b":[["34936.36","0.823804"],["34936.35","0.1875"],["34957.13","0"],["34956","0"]],"a":[["34961.99","0.008756"],["34962","0.0324"],["34963.64","0.026078"],["34977.06","0"],["34963.68","0"]],"u":20010847,"seq":14108050850}}'
2023-11-02 14:54:41,609 DEBUG ++Rcv raw: b'\x81~\x01P{"topic":"orderbook.50.BTCUSDC","ts":1698936881524,"type":"delta","data":{"s":"BTCUSDC","b":[["34948.21","0.000261"],["34936.35","0"]],"a":[["34961.97","0.048072"],["34961.98","0.03895"],["34963.63","0.070257"],["34970.24","0.000239"],["34975.67","0"],["34963.65","0"],["34976.12","0"],["34977.05","0"]],"u":20010848,"seq":14108050862}}'
2023-11-02 14:54:41,609 DEBUG ++Rcv decoded: fin=1 opcode=1 data=b'{"topic":"orderbook.50.BTCUSDC","ts":1698936881524,"type":"delta","data":{"s":"BTCUSDC","b":[["34948.21","0.000261"],["34936.35","0"]],"a":[["34961.97","0.048072"],["34961.98","0.03895"],["34963.63","0.070257"],["34970.24","0.000239"],["34975.67","0"],["34963.65","0"],["34976.12","0"],["34977.05","0"]],"u":20010848,"seq":14108050862}}'
2023-11-02 14:54:41,629 DEBUG ++Rcv raw: b'\x81~\x01\x12{"topic":"orderbook.50.BTCUSDC","ts":1698936881543,"type":"delta","data":{"s":"BTCUSDC","b":[["34956.42","0.0889"]],"a":[["34961.96","0.008756"],["34965.01","0.05154"],["34975.67","0.1875"],["34961.99","0"],["34963.63","0"],["34961.98","0"]],"u":20010849,"seq":14108050869}}'
2023-11-02 14:54:41,629 DEBUG ++Rcv decoded: fin=1 opcode=1 data=b'{"topic":"orderbook.50.BTCUSDC","ts":1698936881543,"type":"delta","data":{"s":"BTCUSDC","b":[["34956.42","0.0889"]],"a":[["34961.96","0.008756"],["34965.01","0.05154"],["34975.67","0.1875"],["34961.99","0"],["34963.63","0"],["34961.98","0"]],"u":20010849,"seq":14108050869}}'
2023-11-02 14:54:41,649 DEBUG ++Rcv raw: b'\x81~\x00\xae{"topic":"orderbook.50.BTCUSDC","ts":1698936881563,"type":"delta","data":{"s":"BTCUSDC","b":[],"a":[["34976.12","0.043812"],["34961.97","0"]],"u":20010850,"seq":14108050876}}'
2023-11-02 14:54:41,649 DEBUG ++Rcv decoded: fin=1 opcode=1 data=b'{"topic":"orderbook.50.BTCUSDC","ts":1698936881563,"type":"delta","data":{"s":"BTCUSDC","b":[],"a":[["34976.12","0.043812"],["34961.97","0"]],"u":20010850,"seq":14108050876}}'
2023-11-02 14:54:41,688 DEBUG ++Rcv raw: b'\x81~\x00\xae{"topic":"orderbook.50.BTCUSDC","ts":1698936881603,"type":"delta","data":{"s":"BTCUSDC","b":[],"a":[["34961.98","0.028602"],["34976.12","0"]],"u":20010851,"seq":14108050902}}'
2023-11-02 14:54:41,689 DEBUG ++Rcv decoded: fin=1 opcode=1 data=b'{"topic":"orderbook.50.BTCUSDC","ts":1698936881603,"type":"delta","data":{"s":"BTCUSDC","b":[],"a":[["34961.98","0.028602"],["34976.12","0"]],"u":20010851,"seq":14108050902}}'
2023-11-02 14:54:41,709 DEBUG ++Rcv raw: b'\x81~\x00\xae{"topic":"orderbook.50.BTCUSDC","ts":1698936881624,"type":"delta","data":{"s":"BTCUSDC","b":[],"a":[["34961.97","0.036602"],["34975.67","0"]],"u":20010852,"seq":14108050906}}'
2023-11-02 14:54:41,710 DEBUG ++Rcv decoded: fin=1 opcode=1 data=b'{"topic":"orderbook.50.BTCUSDC","ts":1698936881624,"type":"delta","data":{"s":"BTCUSDC","b":[],"a":[["34961.97","0.036602"],["34975.67","0"]],"u":20010852,"seq":14108050906}}'
2023-11-02 14:54:41,748 DEBUG ++Rcv raw: b'\x81~\x00\xd2{"topic":"orderbook.50.BTCUSDC","ts":1698936881663,"type":"delta","data":{"s":"BTCUSDC","b":[["34936.35","0.1875"],["34948.17","0"]],"a":[["34975.67","0.1875"],["34970.33","0"]],"u":20010853,"seq":14108050941}}'
2023-11-02 14:54:41,749 DEBUG ++Rcv decoded: fin=1 opcode=1 data=b'{"topic":"orderbook.50.BTCUSDC","ts":1698936881663,"type":"delta","data":{"s":"BTCUSDC","b":[["34936.35","0.1875"],["34948.17","0"]],"a":[["34975.67","0.1875"],["34970.33","0"]],"u":20010853,"seq":14108050941}}'
2023-11-02 14:54:41,770 DEBUG ++Rcv raw: b'\x81~\x00\x9d{"topic":"orderbook.50.BTCUSDC","ts":1698936881684,"type":"delta","data":{"s":"BTCUSDC","b":[["34954.71","0.036696"]],"a":[],"u":20010854,"seq":14108050950}}'
2023-11-02 14:54:41,770 DEBUG ++Rcv decoded: fin=1 opcode=1 data=b'{"topic":"orderbook.50.BTCUSDC","ts":1698936881684,"type":"delta","data":{"s":"BTCUSDC","b":[["34954.71","0.036696"]],"a":[],"u":20010854,"seq":14108050950}}'
2023-11-02 14:54:41,789 DEBUG ++Rcv raw: b'\x81~\x00\xae{"topic":"orderbook.50.BTCUSDC","ts":1698936881704,"type":"delta","data":{"s":"BTCUSDC","b":[],"a":[["34976.12","0.043812"],["34961.98","0"]],"u":20010855,"seq":14108050953}}'
2023-11-02 14:54:41,789 DEBUG ++Rcv decoded: fin=1 opcode=1 data=b'{"topic":"orderbook.50.BTCUSDC","ts":1698936881704,"type":"delta","data":{"s":"BTCUSDC","b":[],"a":[["34976.12","0.043812"],["34961.98","0"]],"u":20010855,"seq":14108050953}}'
2023-11-02 14:54:41,809 DEBUG ++Rcv raw: b'\x81~\x00\xae{"topic":"orderbook.50.BTCUSDC","ts":1698936881723,"type":"delta","data":{"s":"BTCUSDC","b":[],"a":[["34977.05","0.051548"],["34961.97","0"]],"u":20010856,"seq":14108050955}}'
2023-11-02 14:54:41,809 DEBUG ++Rcv decoded: fin=1 opcode=1 data=b'{"topic":"orderbook.50.BTCUSDC","ts":1698936881723,"type":"delta","data":{"s":"BTCUSDC","b":[],"a":[["34977.05","0.051548"],["34961.97","0"]],"u":20010856,"seq":14108050955}}'
2023-11-02 14:54:41,849 DEBUG ++Rcv raw: b'\x81~\x00\xae{"topic":"orderbook.50.BTCUSDC","ts":1698936881764,"type":"delta","data":{"s":"BTCUSDC","b":[],"a":[["34963.67","0.057202"],["34977.05","0"]],"u":20010857,"seq":14108050962}}'
2023-11-02 14:54:41,849 DEBUG ++Rcv decoded: fin=1 opcode=1 data=b'{"topic":"orderbook.50.BTCUSDC","ts":1698936881764,"type":"delta","data":{"s":"BTCUSDC","b":[],"a":[["34963.67","0.057202"],["34977.05","0"]],"u":20010857,"seq":14108050962}}'
2023-11-02 14:54:41,869 DEBUG ++Rcv raw: b'\x81~\x00\xae{"topic":"orderbook.50.BTCUSDC","ts":1698936881784,"type":"delta","data":{"s":"BTCUSDC","b":[],"a":[["34963.63","0.104574"],["34965.01","0"]],"u":20010858,"seq":14108050968}}'
2023-11-02 14:54:41,869 DEBUG ++Rcv decoded: fin=1 opcode=1 data=b'{"topic":"orderbook.50.BTCUSDC","ts":1698936881784,"type":"delta","data":{"s":"BTCUSDC","b":[],"a":[["34963.63","0.104574"],["34965.01","0"]],"u":20010858,"seq":14108050968}}'
2023-11-02 14:54:41,889 DEBUG ++Rcv raw: b'\x81~\x00\xd7{"topic":"orderbook.50.BTCUSDC","ts":1698936881804,"type":"delta","data":{"s":"BTCUSDC","b":[],"a":[["34961.94","0.041858"],["34961.95","0.028602"],["34975.67","0"],["34976.12","0"]],"u":20010859,"seq":14108050977}}'
2023-11-02 14:54:41,889 DEBUG ++Rcv decoded: fin=1 opcode=1 data=b'{"topic":"orderbook.50.BTCUSDC","ts":1698936881804,"type":"delta","data":{"s":"BTCUSDC","b":[],"a":[["34961.94","0.041858"],["34961.95","0.028602"],["34975.67","0"],["34976.12","0"]],"u":20010859,"seq":14108050977}}'
2023-11-02 14:54:41,909 DEBUG ++Rcv raw: b'\x81~\x00\xef{"topic":"orderbook.50.BTCUSDC","ts":1698936881824,"type":"delta","data":{"s":"BTCUSDC","b":[],"a":[["34958.51","0.076158"],["34961.94","0.050614"],["34965.01","0.051545"],["34961.96","0"],["34963.63","0"]],"u":20010860,"seq":14108050986}}'
2023-11-02 14:54:41,910 DEBUG ++Rcv decoded: fin=1 opcode=1 data=b'{"topic":"orderbook.50.BTCUSDC","ts":1698936881824,"type":"delta","data":{"s":"BTCUSDC","b":[],"a":[["34958.51","0.076158"],["34961.94","0.050614"],["34965.01","0.051545"],["34961.96","0"],["34963.63","0"]],"u":20010860,"seq":14108050986}}'
2023-11-02 14:54:41,929 DEBUG ++Rcv raw: b'\x81~\x00\xfd{"topic":"orderbook.50.BTCUSDC","ts":1698936881844,"type":"delta","data":{"s":"BTCUSDC","b":[["34935.91","1.373003"],["34951.53","0"]],"a":[["34975.67","0.1875"],["34976.12","0.043812"],["34970.24","0"],["34968.54","0"]],"u":20010861,"seq":14108050991}}'
2023-11-02 14:54:41,929 DEBUG ++Rcv decoded: fin=1 opcode=1 data=b'{"topic":"orderbook.50.BTCUSDC","ts":1698936881844,"type":"delta","data":{"s":"BTCUSDC","b":[["34935.91","1.373003"],["34951.53","0"]],"a":[["34975.67","0.1875"],["34976.12","0.043812"],["34970.24","0"],["34968.54","0"]],"u":20010861,"seq":14108050991}}'
2023-11-02 14:54:41,989 DEBUG ++Rcv raw: b'\x81~\x00\xae{"topic":"orderbook.50.BTCUSDC","ts":1698936881904,"type":"delta","data":{"s":"BTCUSDC","b":[],"a":[["34977.05","0.051548"],["34961.95","0"]],"u":20010862,"seq":14108051013}}'
2023-11-02 14:54:41,990 DEBUG ++Rcv decoded: fin=1 opcode=1 data=b'{"topic":"orderbook.50.BTCUSDC","ts":1698936881904,"type":"delta","data":{"s":"BTCUSDC","b":[],"a":[["34977.05","0.051548"],["34961.95","0"]],"u":20010862,"seq":14108051013}}'
2023-11-02 14:54:42,009 DEBUG ++Rcv raw: b'\x81~\x00\xc6{"topic":"orderbook.50.BTCUSDC","ts":1698936881924,"type":"delta","data":{"s":"BTCUSDC","b":[],"a":[["34961.94","0.008756"],["34963.63","0.104577"],["34965.01","0"]],"u":20010863,"seq":14108051021}}'
2023-11-02 14:54:42,010 DEBUG ++Rcv decoded: fin=1 opcode=1 data=b'{"topic":"orderbook.50.BTCUSDC","ts":1698936881924,"type":"delta","data":{"s":"BTCUSDC","b":[],"a":[["34961.94","0.008756"],["34963.63","0.104577"],["34965.01","0"]],"u":20010863,"seq":14108051021}}'
2023-11-02 14:54:42,109 DEBUG ++Rcv raw: b'\x81~\x00\xeb{"topic":"orderbook.50.BTCUSDC","ts":1698936882024,"type":"delta","data":{"s":"BTCUSDC","b":[["34956.42","0.045329"],["34931.31","0.1875"],["34948.21","0"]],"a":[["34958.5","0.028605"],["34977.05","0"]],"u":20010864,"seq":14108051040}}'
2023-11-02 14:54:42,109 DEBUG ++Rcv decoded: fin=1 opcode=1 data=b'{"topic":"orderbook.50.BTCUSDC","ts":1698936882024,"type":"delta","data":{"s":"BTCUSDC","b":[["34956.42","0.045329"],["34931.31","0.1875"],["34948.21","0"]],"a":[["34958.5","0.028605"],["34977.05","0"]],"u":20010864,"seq":14108051040}}'
2023-11-02 14:54:42,128 DEBUG ++Rcv raw: b'\x81~\x01]{"topic":"orderbook.50.BTCUSDC","ts":1698936882043,"type":"delta","data":{"s":"BTCUSDC","b":[["34956.42","0.003"],["34953.06","0.087082"],["34950.01","0.028671"],["34927.87","0.274859"],["34954","0"],["34954.71","0"],["34951.27","0"]],"a":[["34963.3","0.0859"],["34966.22","0.001"],["34958.51","0"],["34974.59","0"]],"u":20010865,"seq":14108051053}}'
2023-11-02 14:54:42,129 DEBUG ++Rcv decoded: fin=1 opcode=1 data=b'{"topic":"orderbook.50.BTCUSDC","ts":1698936882043,"type":"delta","data":{"s":"BTCUSDC","b":[["34956.42","0.003"],["34953.06","0.087082"],["34950.01","0.028671"],["34927.87","0.274859"],["34954","0"],["34954.71","0"],["34951.27","0"]],"a":[["34963.3","0.0859"],["34966.22","0.001"],["34958.51","0"],["34974.59","0"]],"u":20010865,"seq":14108051053}}'
2023-11-02 14:54:42,148 DEBUG ++Rcv raw: b'\x81~\x01\x16{"topic":"orderbook.50.BTCUSDC","ts":1698936882063,"type":"delta","data":{"s":"BTCUSDC","b":[],"a":[["34963.29","0.051549"],["34965.01","0.05154"],["34973.8","1.373004"],["34974.49","0.029858"],["34963.63","0"],["34975.67","0"],["34976.12","0"]],"u":20010866,"seq":14108051077}}'
2023-11-02 14:54:42,149 DEBUG ++Rcv decoded: fin=1 opcode=1 data=b'{"topic":"orderbook.50.BTCUSDC","ts":1698936882063,"type":"delta","data":{"s":"BTCUSDC","b":[],"a":[["34963.29","0.051549"],["34965.01","0.05154"],["34973.8","1.373004"],["34974.49","0.029858"],["34963.63","0"],["34975.67","0"],["34976.12","0"]],"u":20010866,"seq":14108051077}}'
2023-11-02 14:54:42,209 DEBUG ++Rcv raw: b'\x81~\x00\xae{"topic":"orderbook.50.BTCUSDC","ts":1698936882123,"type":"delta","data":{"s":"BTCUSDC","b":[["34935.93","0.070565"],["34927.87","0"]],"a":[],"u":20010867,"seq":14108051113}}'
2023-11-02 14:54:42,209 DEBUG ++Rcv decoded: fin=1 opcode=1 data=b'{"topic":"orderbook.50.BTCUSDC","ts":1698936882123,"type":"delta","data":{"s":"BTCUSDC","b":[["34935.93","0.070565"],["34927.87","0"]],"a":[],"u":20010867,"seq":14108051113}}'
2023-11-02 14:54:42,230 DEBUG ++Rcv raw: b'\x81~\x01*{"topic":"orderbook.50.BTCUSDC","ts":1698936882144,"type":"delta","data":{"s":"BTCUSDC","b":[["34956.42","0.0889"],["34950.02","0.000799"],["34938.01","0.093893"],["34935.91","0"],["34931.31","0"]],"a":[["34973.61","0.817362"],["34975.67","0.1875"],["34958.5","0"]],"u":20010868,"seq":14108051126}}'
2023-11-02 14:54:42,231 DEBUG ++Rcv decoded: fin=1 opcode=1 data=b'{"topic":"orderbook.50.BTCUSDC","ts":1698936882144,"type":"delta","data":{"s":"BTCUSDC","b":[["34956.42","0.0889"],["34950.02","0.000799"],["34938.01","0.093893"],["34935.91","0"],["34931.31","0"]],"a":[["34973.61","0.817362"],["34975.67","0.1875"],["34958.5","0"]],"u":20010868,"seq":14108051126}}'
2023-11-02 14:54:42,249 DEBUG ++Rcv raw: b'\x81~\x00\xfc{"topic":"orderbook.50.BTCUSDC","ts":1698936882164,"type":"delta","data":{"s":"BTCUSDC","b":[["34951.53","0.00057"],["34935.93","0"]],"a":[["34966.83","0.00057"],["34976.12","0.043812"],["34963.3","0"],["34961.94","0"]],"u":20010869,"seq":14108051137}}'
2023-11-02 14:54:42,249 DEBUG ++Rcv decoded: fin=1 opcode=1 data=b'{"topic":"orderbook.50.BTCUSDC","ts":1698936882164,"type":"delta","data":{"s":"BTCUSDC","b":[["34951.53","0.00057"],["34935.93","0"]],"a":[["34966.83","0.00057"],["34976.12","0.043812"],["34963.3","0"],["34961.94","0"]],"u":20010869,"seq":14108051137}}'
2023-11-02 14:54:42,270 DEBUG ++Rcv raw: b'\x81~\x01\'{"topic":"orderbook.50.BTCUSDC","ts":1698936882183,"type":"delta","data":{"s":"BTCUSDC","b":[["34935.93","0.070565"],["34935.91","1.373003"],["34949.6","0"],["34939.87","0"]],"a":[["34963.63","0.104576"],["34977.05","0.051548"],["34965.01","0"],["34963.29","0"]],"u":20010870,"seq":14108051148}}'
2023-11-02 14:54:42,270 DEBUG ++Rcv decoded: fin=1 opcode=1 data=b'{"topic":"orderbook.50.BTCUSDC","ts":1698936882183,"type":"delta","data":{"s":"BTCUSDC","b":[["34935.93","0.070565"],["34935.91","1.373003"],["34949.6","0"],["34939.87","0"]],"a":[["34963.63","0.104576"],["34977.05","0.051548"],["34965.01","0"],["34963.29","0"]],"u":20010870,"seq":14108051148}}'
2023-11-02 14:54:42,330 DEBUG ++Rcv raw: b'\x81~\x00\xff{"topic":"orderbook.50.BTCUSDC","ts":1698936882244,"type":"delta","data":{"s":"BTCUSDC","b":[["34948.43","0.000261"],["34935.91","0"]],"a":[["34961.92","0.036607"],["34961.93","0.028602"],["34976.12","0"],["34977.05","0"]],"u":20010871,"seq":14108051163}}'
2023-11-02 14:54:42,330 DEBUG ++Rcv decoded: fin=1 opcode=1 data=b'{"topic":"orderbook.50.BTCUSDC","ts":1698936882244,"type":"delta","data":{"s":"BTCUSDC","b":[["34948.43","0.000261"],["34935.91","0"]],"a":[["34961.92","0.036607"],["34961.93","0.028602"],["34976.12","0"],["34977.05","0"]],"u":20010871,"seq":14108051163}}'
2023-11-02 14:54:42,349 DEBUG ++Rcv raw: b'\x81~\x01\x11{"topic":"orderbook.50.BTCUSDC","ts":1698936882264,"type":"delta","data":{"s":"BTCUSDC","b":[["34956.42","0.003"]],"a":[["34958.07","0.076588"],["34963.3","0.0859"],["34965.01","0.051547"],["34975.67","0"],["34975.34","0"],["34963.63","0"]],"u":20010872,"seq":14108051174}}'
2023-11-02 14:54:42,350 DEBUG ++Rcv decoded: fin=1 opcode=1 data=b'{"topic":"orderbook.50.BTCUSDC","ts":1698936882264,"type":"delta","data":{"s":"BTCUSDC","b":[["34956.42","0.003"]],"a":[["34958.07","0.076588"],["34963.3","0.0859"],["34965.01","0.051547"],["34975.67","0"],["34975.34","0"],["34963.63","0"]],"u":20010872,"seq":14108051174}}'
2023-11-02 14:54:42,370 DEBUG ++Rcv raw: b'\x81~\x00\xfb{"topic":"orderbook.50.BTCUSDC","ts":1698936882284,"type":"delta","data":{"s":"BTCUSDC","b":[["34935.91","1.373003"],["34951.53","0"]],"a":[["34975.34","0.0859"],["34975.67","0.1875"],["34966.83","0"],["34963.66","0"]],"u":20010873,"seq":14108051183}}'
2023-11-02 14:54:42,371 DEBUG ++Rcv decoded: fin=1 opcode=1 data=b'{"topic":"orderbook.50.BTCUSDC","ts":1698936882284,"type":"delta","data":{"s":"BTCUSDC","b":[["34935.91","1.373003"],["34951.53","0"]],"a":[["34975.34","0.0859"],["34975.67","0.1875"],["34966.83","0"],["34963.66","0"]],"u":20010873,"seq":14108051183}}'
2023-11-02 14:54:42,428 DEBUG ++Rcv raw: b'\x81~\x00\xae{"topic":"orderbook.50.BTCUSDC","ts":1698936882343,"type":"delta","data":{"s":"BTCUSDC","b":[],"a":[["34976.12","0.043812"],["34961.93","0"]],"u":20010874,"seq":14108051214}}'
2023-11-02 14:54:42,429 DEBUG ++Rcv decoded: fin=1 opcode=1 data=b'{"topic":"orderbook.50.BTCUSDC","ts":1698936882343,"type":"delta","data":{"s":"BTCUSDC","b":[],"a":[["34976.12","0.043812"],["34961.93","0"]],"u":20010874,"seq":14108051214}}'
2023-11-02 14:54:42,449 DEBUG ++Rcv raw: b'\x81~\x00\xae{"topic":"orderbook.50.BTCUSDC","ts":1698936882364,"type":"delta","data":{"s":"BTCUSDC","b":[],"a":[["34963.29","0.051548"],["34961.92","0"]],"u":20010875,"seq":14108051220}}'
2023-11-02 14:54:42,449 DEBUG ++Rcv decoded: fin=1 opcode=1 data=b'{"topic":"orderbook.50.BTCUSDC","ts":1698936882364,"type":"delta","data":{"s":"BTCUSDC","b":[],"a":[["34963.29","0.051548"],["34961.92","0"]],"u":20010875,"seq":14108051220}}'
2023-11-02 14:54:42,469 DEBUG ++Rcv raw: b'\x81~\x00\x9d{"topic":"orderbook.50.BTCUSDC","ts":1698936882384,"type":"delta","data":{"s":"BTCUSDC","b":[["34942.67","0.079544"]],"a":[],"u":20010876,"seq":14108051237}}'
2023-11-02 14:54:42,469 DEBUG ++Rcv decoded: fin=1 opcode=1 data=b'{"topic":"orderbook.50.BTCUSDC","ts":1698936882384,"type":"delta","data":{"s":"BTCUSDC","b":[["34942.67","0.079544"]],"a":[],"u":20010876,"seq":14108051237}}'
2023-11-02 14:54:42,489 DEBUG ++Rcv raw: b'\x81~\x00\xd6{"topic":"orderbook.50.BTCUSDC","ts":1698936882404,"type":"delta","data":{"s":"BTCUSDC","b":[["34948.49","0.000261"],["34935.91","0"]],"a":[["34969.76","0.000239"],["34976.12","0"]],"u":20010877,"seq":14108051243}}'
2023-11-02 14:54:42,489 DEBUG ++Rcv decoded: fin=1 opcode=1 data=b'{"topic":"orderbook.50.BTCUSDC","ts":1698936882404,"type":"delta","data":{"s":"BTCUSDC","b":[["34948.49","0.000261"],["34935.91","0"]],"a":[["34969.76","0.000239"],["34976.12","0"]],"u":20010877,"seq":14108051243}}'
2023-11-02 14:54:42,529 DEBUG ++Rcv raw: b'\x81~\x00\xae{"topic":"orderbook.50.BTCUSDC","ts":1698936882444,"type":"delta","data":{"s":"BTCUSDC","b":[],"a":[["34958.06","0.028605"],["34958.07","0"]],"u":20010878,"seq":14108051253}}'
2023-11-02 14:54:42,529 DEBUG ++Rcv decoded: fin=1 opcode=1 data=b'{"topic":"orderbook.50.BTCUSDC","ts":1698936882444,"type":"delta","data":{"s":"BTCUSDC","b":[],"a":[["34958.06","0.028605"],["34958.07","0"]],"u":20010878,"seq":14108051253}}'
2023-11-02 14:54:42,609 DEBUG ++Rcv raw: b'\x81~\x00\xa9{"topic":"orderbook.50.BTCUSDC","ts":1698936882524,"type":"delta","data":{"s":"BTCUSDC","b":[],"a":[["34960","0.0324"],["34975.67","0"]],"u":20010879,"seq":14108051277}}'
2023-11-02 14:54:42,610 DEBUG ++Rcv decoded: fin=1 opcode=1 data=b'{"topic":"orderbook.50.BTCUSDC","ts":1698936882524,"type":"delta","data":{"s":"BTCUSDC","b":[],"a":[["34960","0.0324"],["34975.67","0"]],"u":20010879,"seq":14108051277}}'
2023-11-02 14:54:42,628 DEBUG ++Rcv raw: b'\x81~\x00\xfd{"topic":"orderbook.50.BTCUSDC","ts":1698936882543,"type":"delta","data":{"s":"BTCUSDC","b":[["34935.91","1.373003"],["34931.31","0.1875"],["34956.42","0"],["34955.77","0"]],"a":[["34958.05","0.008756"],["34975.34","0"]],"u":20010880,"seq":14108051305}}'
2023-11-02 14:54:42,629 DEBUG ++Rcv decoded: fin=1 opcode=1 data=b'{"topic":"orderbook.50.BTCUSDC","ts":1698936882543,"type":"delta","data":{"s":"BTCUSDC","b":[["34935.91","1.373003"],["34931.31","0.1875"],["34956.42","0"],["34955.77","0"]],"a":[["34958.05","0.008756"],["34975.34","0"]],"u":20010880,"seq":14108051305}}'
2023-11-02 14:54:42,650 DEBUG ++Rcv raw: b'\x81~\x01\x1f{"topic":"orderbook.50.BTCUSDC","ts":1698936882564,"type":"delta","data":{"s":"BTCUSDC","b":[["34955.03","0.057216"],["34949.81","0.00057"],["34931.31","0"],["34935.91","0"]],"a":[["34956.77","0.003"],["34961.58","0.0859"],["34974.99","0"],["34975","0"]],"u":20010881,"seq":14108051341}}'
2023-11-02 14:54:42,650 DEBUG ++Rcv decoded: fin=1 opcode=1 data=b'{"topic":"orderbook.50.BTCUSDC","ts":1698936882564,"type":"delta","data":{"s":"BTCUSDC","b":[["34955.03","0.057216"],["34949.81","0.00057"],["34931.31","0"],["34935.91","0"]],"a":[["34956.77","0.003"],["34961.58","0.0859"],["34974.99","0"],["34975","0"]],"u":20010881,"seq":14108051341}}'
2023-11-02 14:54:42,669 DEBUG ++Rcv raw: b'\x81~\x01\x9d{"topic":"orderbook.50.BTCUSDC","ts":1698936882583,"type":"delta","data":{"s":"BTCUSDC","b":[["34935.91","1.373003"],["34931.31","0.1875"],["34927.87","0.274859"],["34927.86","0.458086"],["34955.03","0"],["34948.43","0"],["34949.81","0"],["34954.7","0"]],"a":[["34961.57","0.051549"],["34967.27","0.1875"],["34969.65","0.000239"],["34974.49","0"],["34974.93","0"],["34974.5","0"]],"u":20010882,"seq":14108051368}}'
2023-11-02 14:54:42,669 DEBUG ++Rcv decoded: fin=1 opcode=1 data=b'{"topic":"orderbook.50.BTCUSDC","ts":1698936882583,"type":"delta","data":{"s":"BTCUSDC","b":[["34935.91","1.373003"],["34931.31","0.1875"],["34927.87","0.274859"],["34927.86","0.458086"],["34955.03","0"],["34948.43","0"],["34949.81","0"],["34954.7","0"]],"a":[["34961.57","0.051549"],["34967.27","0.1875"],["34969.65","0.000239"],["34974.49","0"],["34974.93","0"],["34974.5","0"]],"u":20010882,"seq":14108051368}}'
2023-11-02 14:54:42,690 DEBUG ++Rcv raw: b'\x81~\x00\xd5{"topic":"orderbook.50.BTCUSDC","ts":1698936882604,"type":"delta","data":{"s":"BTCUSDC","b":[["34948.17","0.00057"],["34927.86","0"]],"a":[["34974.49","0.029858"],["34967.99","0"]],"u":20010883,"seq":14108051380}}'
2023-11-02 14:54:42,690 DEBUG ++Rcv decoded: fin=1 opcode=1 data=b'{"topic":"orderbook.50.BTCUSDC","ts":1698936882604,"type":"delta","data":{"s":"BTCUSDC","b":[["34948.17","0.00057"],["34927.86","0"]],"a":[["34974.49","0.029858"],["34967.99","0"]],"u":20010883,"seq":14108051380}}'
2023-11-02 14:54:42,709 DEBUG ++Rcv raw: b'\x81~\x00\xae{"topic":"orderbook.50.BTCUSDC","ts":1698936882624,"type":"delta","data":{"s":"BTCUSDC","b":[["34927.86","0.458086"],["34952.43","0"]],"a":[],"u":20010884,"seq":14108051385}}'
2023-11-02 14:54:42,709 DEBUG ++Rcv decoded: fin=1 opcode=1 data=b'{"topic":"orderbook.50.BTCUSDC","ts":1698936882624,"type":"delta","data":{"s":"BTCUSDC","b":[["34927.86","0.458086"],["34952.43","0"]],"a":[],"u":20010884,"seq":14108051385}}'
2023-11-02 14:54:42,749 DEBUG ++Rcv raw: b'\x81~\x00\xae{"topic":"orderbook.50.BTCUSDC","ts":1698936882664,"type":"delta","data":{"s":"BTCUSDC","b":[["34954.07","0.108706"],["34950.02","0"]],"a":[],"u":20010885,"seq":14108051417}}'
2023-11-02 14:54:42,749 DEBUG ++Rcv decoded: fin=1 opcode=1 data=b'{"topic":"orderbook.50.BTCUSDC","ts":1698936882664,"type":"delta","data":{"s":"BTCUSDC","b":[["34954.07","0.108706"],["34950.02","0"]],"a":[],"u":20010885,"seq":14108051417}}'
2023-11-02 14:54:42,770 DEBUG ++Rcv raw: b'\x81~\x00\xd2{"topic":"orderbook.50.BTCUSDC","ts":1698936882684,"type":"delta","data":{"s":"BTCUSDC","b":[["34927.27","0.1875"],["34948.17","0"]],"a":[["34963.02","0.0441"],["34958.06","0"]],"u":20010886,"seq":14108051464}}'
2023-11-02 14:54:42,770 DEBUG ++Rcv decoded: fin=1 opcode=1 data=b'{"topic":"orderbook.50.BTCUSDC","ts":1698936882684,"type":"delta","data":{"s":"BTCUSDC","b":[["34927.27","0.1875"],["34948.17","0"]],"a":[["34963.02","0.0441"],["34958.06","0"]],"u":20010886,"seq":14108051464}}'
2023-11-02 14:54:42,790 DEBUG ++Rcv raw: b'\x81~\x00\xad{"topic":"orderbook.50.BTCUSDC","ts":1698936882704,"type":"delta","data":{"s":"BTCUSDC","b":[["34925.01","1.32582"],["34945.86","0"]],"a":[],"u":20010887,"seq":14108051472}}'
2023-11-02 14:54:42,790 DEBUG ++Rcv decoded: fin=1 opcode=1 data=b'{"topic":"orderbook.50.BTCUSDC","ts":1698936882704,"type":"delta","data":{"s":"BTCUSDC","b":[["34925.01","1.32582"],["34945.86","0"]],"a":[],"u":20010887,"seq":14108051472}}'
2023-11-02 14:54:42,830 DEBUG ++Rcv raw: b'\x81~\x00\xae{"topic":"orderbook.50.BTCUSDC","ts":1698936882744,"type":"delta","data":{"s":"BTCUSDC","b":[["34950.02","0.001391"],["34925.01","0"]],"a":[],"u":20010888,"seq":14108051485}}'
2023-11-02 14:54:42,830 DEBUG ++Rcv decoded: fin=1 opcode=1 data=b'{"topic":"orderbook.50.BTCUSDC","ts":1698936882744,"type":"delta","data":{"s":"BTCUSDC","b":[["34950.02","0.001391"],["34925.01","0"]],"a":[],"u":20010888,"seq":14108051485}}'
2023-11-02 14:54:42,849 DEBUG ++Rcv raw: b'\x81~\x01\x00{"topic":"orderbook.50.BTCUSDC","ts":1698936882763,"type":"delta","data":{"s":"BTCUSDC","b":[["34955.51","0.057215"],["34954.08","0.055291"],["34951.27","0.051541"],["34953.06","0"],["34950.01","0"],["34954.07","0"]],"a":[],"u":20010889,"seq":14108051494}}'
2023-11-02 14:54:42,849 DEBUG ++Rcv decoded: fin=1 opcode=1 data=b'{"topic":"orderbook.50.BTCUSDC","ts":1698936882763,"type":"delta","data":{"s":"BTCUSDC","b":[["34955.51","0.057215"],["34954.08","0.055291"],["34951.27","0.051541"],["34953.06","0"],["34950.01","0"],["34954.07","0"]],"a":[],"u":20010889,"seq":14108051494}}'
2023-11-02 14:54:42,870 DEBUG ++Rcv raw: b'\x81~\x01\'{"topic":"orderbook.50.BTCUSDC","ts":1698936882783,"type":"delta","data":{"s":"BTCUSDC","b":[["34953.06","0.065477"],["34950.01","0.028666"],["34925.01","1.32582"],["34955.51","0"],["34954.08","0"],["34951.27","0"]],"a":[["34956.76","0.074799"],["34974.49","0"]],"u":20010890,"seq":14108051508}}'
2023-11-02 14:54:42,870 DEBUG ++Rcv decoded: fin=1 opcode=1 data=b'{"topic":"orderbook.50.BTCUSDC","ts":1698936882783,"type":"delta","data":{"s":"BTCUSDC","b":[["34953.06","0.065477"],["34950.01","0.028666"],["34925.01","1.32582"],["34955.51","0"],["34954.08","0"],["34951.27","0"]],"a":[["34956.76","0.074799"],["34974.49","0"]],"u":20010890,"seq":14108051508}}'
2023-11-02 14:54:42,889 DEBUG ++Rcv raw: b'\x81~\x00\xed{"topic":"orderbook.50.BTCUSDC","ts":1698936882804,"type":"delta","data":{"s":"BTCUSDC","b":[["34948.17","0.00057"],["34925.01","0"]],"a":[["34956.76","0.028606"],["34974.49","0.029858"],["34969.76","0"]],"u":20010891,"seq":14108051520}}'
2023-11-02 14:54:42,889 DEBUG ++Rcv decoded: fin=1 opcode=1 data=b'{"topic":"orderbook.50.BTCUSDC","ts":1698936882804,"type":"delta","data":{"s":"BTCUSDC","b":[["34948.17","0.00057"],["34925.01","0"]],"a":[["34956.76","0.028606"],["34974.49","0.029858"],["34969.76","0"]],"u":20010891,"seq":14108051520}}'
2023-11-02 14:54:42,929 DEBUG ++Rcv raw: b'\x81~\x00\xac{"topic":"orderbook.50.BTCUSDC","ts":1698936882844,"type":"delta","data":{"s":"BTCUSDC","b":[["34940.94","0.0859"],["34950.02","0"]],"a":[],"u":20010892,"seq":14108051554}}'
2023-11-02 14:54:42,929 DEBUG ++Rcv decoded: fin=1 opcode=1 data=b'{"topic":"orderbook.50.BTCUSDC","ts":1698936882844,"type":"delta","data":{"s":"BTCUSDC","b":[["34940.94","0.0859"],["34950.02","0"]],"a":[],"u":20010892,"seq":14108051554}}'
2023-11-02 14:54:42,950 DEBUG ++Rcv raw: b'\x81~\x00\xad{"topic":"orderbook.50.BTCUSDC","ts":1698936882864,"type":"delta","data":{"s":"BTCUSDC","b":[],"a":[["34974.5","0.057184"],["34958.05","0"]],"u":20010893,"seq":14108051558}}'
2023-11-02 14:54:42,950 DEBUG ++Rcv decoded: fin=1 opcode=1 data=b'{"topic":"orderbook.50.BTCUSDC","ts":1698936882864,"type":"delta","data":{"s":"BTCUSDC","b":[],"a":[["34974.5","0.057184"],["34958.05","0"]],"u":20010893,"seq":14108051558}}'
2023-11-02 14:54:42,969 DEBUG ++Rcv raw: b'\x81~\x00\xad{"topic":"orderbook.50.BTCUSDC","ts":1698936882884,"type":"delta","data":{"s":"BTCUSDC","b":[["34925.01","1.32582"],["34953.05","0"]],"a":[],"u":20010894,"seq":14108051567}}'
2023-11-02 14:54:42,969 DEBUG ++Rcv decoded: fin=1 opcode=1 data=b'{"topic":"orderbook.50.BTCUSDC","ts":1698936882884,"type":"delta","data":{"s":"BTCUSDC","b":[["34925.01","1.32582"],["34953.05","0"]],"a":[],"u":20010894,"seq":14108051567}}'
2023-11-02 14:54:43,089 DEBUG ++Rcv raw: b'\x81~\x00\xd3{"topic":"orderbook.50.BTCUSDC","ts":1698936883003,"type":"delta","data":{"s":"BTCUSDC","b":[["34953.5","0.094112"],["34948.49","0"]],"a":[["34974.93","0.0441"],["34969.65","0"]],"u":20010895,"seq":14108051617}}'
2023-11-02 14:54:43,089 DEBUG ++Rcv decoded: fin=1 opcode=1 data=b'{"topic":"orderbook.50.BTCUSDC","ts":1698936883003,"type":"delta","data":{"s":"BTCUSDC","b":[["34953.5","0.094112"],["34948.49","0"]],"a":[["34974.93","0.0441"],["34969.65","0"]],"u":20010895,"seq":14108051617}}'
2023-11-02 14:54:43,109 DEBUG ++Rcv raw: b'\x81~\x00\xfa{"topic":"orderbook.50.BTCUSDC","ts":1698936883023,"type":"delta","data":{"s":"BTCUSDC","b":[["34953.51","0.056471"],["34951.27","0.051545"],["34925","2.2097"],["34953.5","0"],["34953.06","0"],["34950.01","0"]],"a":[],"u":20010896,"seq":14108051624}}'
2023-11-02 14:54:43,109 DEBUG ++Rcv decoded: fin=1 opcode=1 data=b'{"topic":"orderbook.50.BTCUSDC","ts":1698936883023,"type":"delta","data":{"s":"BTCUSDC","b":[["34953.51","0.056471"],["34951.27","0.051545"],["34925","2.2097"],["34953.5","0"],["34953.06","0"],["34950.01","0"]],"a":[],"u":20010896,"seq":14108051624}}'
2023-11-02 14:54:43,129 DEBUG ++Rcv raw: b'\x81~\x01F{"topic":"orderbook.50.BTCUSDC","ts":1698936883043,"type":"delta","data":{"s":"BTCUSDC","b":[["34953.32","0.021608"],["34953.31","0.036"],["34952.99","0.051546"],["34950.01","0.02867"],["34951.27","0"],["34925.01","0"],["34925","0"],["34953.51","0"]],"a":[["34963.15","0.03"],["34974.93","0"]],"u":20010897,"seq":14108051638}}'
2023-11-02 14:54:43,129 DEBUG ++Rcv decoded: fin=1 opcode=1 data=b'{"topic":"orderbook.50.BTCUSDC","ts":1698936883043,"type":"delta","data":{"s":"BTCUSDC","b":[["34953.32","0.021608"],["34953.31","0.036"],["34952.99","0.051546"],["34950.01","0.02867"],["34951.27","0"],["34925.01","0"],["34925","0"],["34953.51","0"]],"a":[["34963.15","0.03"],["34974.93","0"]],"u":20010897,"seq":14108051638}}'
2023-11-02 14:54:43,149 DEBUG ++Rcv raw: b'\x81~\x00\xae{"topic":"orderbook.50.BTCUSDC","ts":1698936883063,"type":"delta","data":{"s":"BTCUSDC","b":[["34951.27","0.051549"],["34950.01","0"]],"a":[],"u":20010898,"seq":14108051647}}'
2023-11-02 14:54:43,149 DEBUG ++Rcv decoded: fin=1 opcode=1 data=b'{"topic":"orderbook.50.BTCUSDC","ts":1698936883063,"type":"delta","data":{"s":"BTCUSDC","b":[["34951.27","0.051549"],["34950.01","0"]],"a":[],"u":20010898,"seq":14108051647}}'
2023-11-02 14:54:43,189 DEBUG ++Rcv raw: b'\x81~\x00\x9d{"topic":"orderbook.50.BTCUSDC","ts":1698936883103,"type":"delta","data":{"s":"BTCUSDC","b":[["34942.67","0.051544"]],"a":[],"u":20010899,"seq":14108051698}}'
2023-11-02 14:54:43,189 DEBUG ++Rcv decoded: fin=1 opcode=1 data=b'{"topic":"orderbook.50.BTCUSDC","ts":1698936883103,"type":"delta","data":{"s":"BTCUSDC","b":[["34942.67","0.051544"]],"a":[],"u":20010899,"seq":14108051698}}'
2023-11-02 14:54:43,228 DEBUG ++Rcv raw: b'\x81~\x00\xfe{"topic":"orderbook.50.BTCUSDC","ts":1698936883143,"type":"delta","data":{"s":"BTCUSDC","b":[["34952.98","0.108989"],["34949.6","0.00121"],["34927.27","0"]],"a":[["34962","0.055271"],["34967.26","0.1125"],["34974.5","0"]],"u":20010900,"seq":14108051736}}'
2023-11-02 14:54:43,229 DEBUG ++Rcv decoded: fin=1 opcode=1 data=b'{"topic":"orderbook.50.BTCUSDC","ts":1698936883143,"type":"delta","data":{"s":"BTCUSDC","b":[["34952.98","0.108989"],["34949.6","0.00121"],["34927.27","0"]],"a":[["34962","0.055271"],["34967.26","0.1125"],["34974.5","0"]],"u":20010900,"seq":14108051736}}'
2023-11-02 14:54:43,329 DEBUG ++Rcv raw: b'\x81~\x00\xc2{"topic":"orderbook.50.BTCUSDC","ts":1698936883244,"type":"delta","data":{"s":"BTCUSDC","b":[["34927.27","0.1875"],["34949.6","0"]],"a":[["34956.76","0.000006"]],"u":20010901,"seq":14108051768}}'
2023-11-02 14:54:43,329 DEBUG ++Rcv decoded: fin=1 opcode=1 data=b'{"topic":"orderbook.50.BTCUSDC","ts":1698936883244,"type":"delta","data":{"s":"BTCUSDC","b":[["34927.27","0.1875"],["34949.6","0"]],"a":[["34956.76","0.000006"]],"u":20010901,"seq":14108051768}}'
2023-11-02 14:54:43,349 DEBUG ++Rcv raw: b'\x81~\x00\xed{"topic":"orderbook.50.BTCUSDC","ts":1698936883264,"type":"delta","data":{"s":"BTCUSDC","b":[["34954.05","0.099108"],["34927.27","0"]],"a":[["34956.77","0.000006"],["34974.5","0.057184"],["34956.76","0"]],"u":20010902,"seq":14108051778}}'
2023-11-02 14:54:43,350 DEBUG ++Rcv decoded: fin=1 opcode=1 data=b'{"topic":"orderbook.50.BTCUSDC","ts":1698936883264,"type":"delta","data":{"s":"BTCUSDC","b":[["34954.05","0.099108"],["34927.27","0"]],"a":[["34956.77","0.000006"],["34974.5","0.057184"],["34956.76","0"]],"u":20010902,"seq":14108051778}}'
2023-11-02 14:54:43,370 DEBUG ++Rcv raw: b'\x81~\x00\xac{"topic":"orderbook.50.BTCUSDC","ts":1698936883284,"type":"delta","data":{"s":"BTCUSDC","b":[],"a":[["34974.93","0.0441"],["34966.22","0"]],"u":20010903,"seq":14108051780}}'
2023-11-02 14:54:43,370 DEBUG ++Rcv decoded: fin=1 opcode=1 data=b'{"topic":"orderbook.50.BTCUSDC","ts":1698936883284,"type":"delta","data":{"s":"BTCUSDC","b":[],"a":[["34974.93","0.0441"],["34966.22","0"]],"u":20010903,"seq":14108051780}}'
2023-11-02 14:54:43,390 DEBUG ++Rcv raw: b'\x81~\x00\xdd{"topic":"orderbook.50.BTCUSDC","ts":1698936883304,"type":"delta","data":{"s":"BTCUSDC","b":[["34954.05","0.101108"],["34939.86","0.199724"]],"a":[["34963.19","0.057203"],["34963.67","0"]],"u":20010904,"seq":14108051790}}'
2023-11-02 14:54:43,391 DEBUG ++Rcv decoded: fin=1 opcode=1 data=b'{"topic":"orderbook.50.BTCUSDC","ts":1698936883304,"type":"delta","data":{"s":"BTCUSDC","b":[["34954.05","0.101108"],["34939.86","0.199724"]],"a":[["34963.19","0.057203"],["34963.67","0"]],"u":20010904,"seq":14108051790}}'
2023-11-02 14:54:43,409 DEBUG ++Rcv raw: b'\x81~\x00\xc6{"topic":"orderbook.50.BTCUSDC","ts":1698936883323,"type":"delta","data":{"s":"BTCUSDC","b":[["34954.05","0.104108"],["34948.79","0.000261"],["34927.86","0"]],"a":[],"u":20010905,"seq":14108051796}}'
2023-11-02 14:54:43,409 DEBUG ++Rcv decoded: fin=1 opcode=1 data=b'{"topic":"orderbook.50.BTCUSDC","ts":1698936883323,"type":"delta","data":{"s":"BTCUSDC","b":[["34954.05","0.104108"],["34948.79","0.000261"],["34927.86","0"]],"a":[],"u":20010905,"seq":14108051796}}'
2023-11-02 14:54:43,429 DEBUG ++Rcv raw: b'\x81~\x00\xfd{"topic":"orderbook.50.BTCUSDC","ts":1698936883344,"type":"delta","data":{"s":"BTCUSDC","b":[["34949.6","0.001435"],["34945.83","0.04325"],["34927.87","0"],["34931.31","0"]],"a":[["34963.41","0.028605"],["34974.93","0"]],"u":20010906,"seq":14108051816}}'
2023-11-02 14:54:43,429 DEBUG ++Rcv decoded: fin=1 opcode=1 data=b'{"topic":"orderbook.50.BTCUSDC","ts":1698936883344,"type":"delta","data":{"s":"BTCUSDC","b":[["34949.6","0.001435"],["34945.83","0.04325"],["34927.87","0"],["34931.31","0"]],"a":[["34963.41","0.028605"],["34974.93","0"]],"u":20010906,"seq":14108051816}}'
2023-11-02 14:54:43,449 DEBUG ++Rcv raw: b'\x81~\x00\xd4{"topic":"orderbook.50.BTCUSDC","ts":1698936883363,"type":"delta","data":{"s":"BTCUSDC","b":[["34951.95","0.028605"],["34935.91","0"]],"a":[["34974.93","0.0441"],["34963.79","0"]],"u":20010907,"seq":14108051827}}'
2023-11-02 14:54:43,449 DEBUG ++Rcv decoded: fin=1 opcode=1 data=b'{"topic":"orderbook.50.BTCUSDC","ts":1698936883363,"type":"delta","data":{"s":"BTCUSDC","b":[["34951.95","0.028605"],["34935.91","0"]],"a":[["34974.93","0.0441"],["34963.79","0"]],"u":20010907,"seq":14108051827}}'
2023-11-02 14:54:43,469 DEBUG ++Rcv raw: b'\x81~\x00\xae{"topic":"orderbook.50.BTCUSDC","ts":1698936883384,"type":"delta","data":{"s":"BTCUSDC","b":[],"a":[["34956.76","0.028606"],["34974.93","0"]],"u":20010908,"seq":14108051830}}'
2023-11-02 14:54:43,469 DEBUG ++Rcv decoded: fin=1 opcode=1 data=b'{"topic":"orderbook.50.BTCUSDC","ts":1698936883384,"type":"delta","data":{"s":"BTCUSDC","b":[],"a":[["34956.76","0.028606"],["34974.93","0"]],"u":20010908,"seq":14108051830}}'
2023-11-02 14:54:43,488 DEBUG ++Rcv raw: b'\x81~\x00\xae{"topic":"orderbook.50.BTCUSDC","ts":1698936883403,"type":"delta","data":{"s":"BTCUSDC","b":[["34935.91","1.373003"],["34948.17","0"]],"a":[],"u":20010909,"seq":14108051845}}'
2023-11-02 14:54:43,489 DEBUG ++Rcv decoded: fin=1 opcode=1 data=b'{"topic":"orderbook.50.BTCUSDC","ts":1698936883403,"type":"delta","data":{"s":"BTCUSDC","b":[["34935.91","1.373003"],["34948.17","0"]],"a":[],"u":20010909,"seq":14108051845}}'
2023-11-02 14:54:43,529 DEBUG ++Rcv raw: b'\x81~\x00\xae{"topic":"orderbook.50.BTCUSDC","ts":1698936883444,"type":"delta","data":{"s":"BTCUSDC","b":[],"a":[["34969.66","0.114384"],["34970.72","0"]],"u":20010910,"seq":14108051854}}'
2023-11-02 14:54:43,529 DEBUG ++Rcv decoded: fin=1 opcode=1 data=b'{"topic":"orderbook.50.BTCUSDC","ts":1698936883444,"type":"delta","data":{"s":"BTCUSDC","b":[],"a":[["34969.66","0.114384"],["34970.72","0"]],"u":20010910,"seq":14108051854}}'
2023-11-02 14:54:43,589 DEBUG ++Rcv raw: b'\x81~\x00\xae{"topic":"orderbook.50.BTCUSDC","ts":1698936883504,"type":"delta","data":{"s":"BTCUSDC","b":[["34948.85","0.000261"],["34935.91","0"]],"a":[],"u":20010911,"seq":14108051878}}'
2023-11-02 14:54:43,590 DEBUG ++Rcv decoded: fin=1 opcode=1 data=b'{"topic":"orderbook.50.BTCUSDC","ts":1698936883504,"type":"delta","data":{"s":"BTCUSDC","b":[["34948.85","0.000261"],["34935.91","0"]],"a":[],"u":20010911,"seq":14108051878}}'
2023-11-02 14:54:43,610 DEBUG ++Rcv raw: b'\x81~\x00\xac{"topic":"orderbook.50.BTCUSDC","ts":1698936883524,"type":"delta","data":{"s":"BTCUSDC","b":[],"a":[["34969.1","0.000239"],["34974.5","0"]],"u":20010912,"seq":14108051879}}'
2023-11-02 14:54:43,611 DEBUG ++Rcv decoded: fin=1 opcode=1 data=b'{"topic":"orderbook.50.BTCUSDC","ts":1698936883524,"type":"delta","data":{"s":"BTCUSDC","b":[],"a":[["34969.1","0.000239"],["34974.5","0"]],"u":20010912,"seq":14108051879}}'
2023-11-02 14:54:43,629 DEBUG ++Rcv raw: b'\x81~\x00\xad{"topic":"orderbook.50.BTCUSDC","ts":1698936883544,"type":"delta","data":{"s":"BTCUSDC","b":[["34935.91","1.373003"],["34949.6","0"]],"a":[],"u":20010913,"seq":14108051883}}'
2023-11-02 14:54:43,629 DEBUG ++Rcv decoded: fin=1 opcode=1 data=b'{"topic":"orderbook.50.BTCUSDC","ts":1698936883544,"type":"delta","data":{"s":"BTCUSDC","b":[["34935.91","1.373003"],["34949.6","0"]],"a":[],"u":20010913,"seq":14108051883}}'
2023-11-02 14:54:43,650 DEBUG ++Rcv raw: b'\x81~\x00\xac{"topic":"orderbook.50.BTCUSDC","ts":1698936883564,"type":"delta","data":{"s":"BTCUSDC","b":[],"a":[["34973.79","0.0005"],["34974.49","0"]],"u":20010914,"seq":14108051895}}'
2023-11-02 14:54:43,650 DEBUG ++Rcv decoded: fin=1 opcode=1 data=b'{"topic":"orderbook.50.BTCUSDC","ts":1698936883564,"type":"delta","data":{"s":"BTCUSDC","b":[],"a":[["34973.79","0.0005"],["34974.49","0"]],"u":20010914,"seq":14108051895}}'
2023-11-02 14:54:43,729 DEBUG ++Rcv raw: b'\x81~\x03\x0c{"topic":"orderbook.50.BTCUSDC","ts":1698936883643,"type":"delta","data":{"s":"BTCUSDC","b":[["34951.27","0.028605"],["34931.31","0.1875"],["34927.87","0.274859"],["34927.86","0.458086"],["34927.27","0.1875"],["34925.01","1.32582"],["34925","2.2097"],["34924.42","0.4207"],["34923.58","0.1875"],["34922.09","2.2053"],["34918.51","0.1875"],["34916.9","0.035725"],["34912.05","0.98593"],["34951.95","0"],["34951.26","0"],["34943.59","0"],["34953.32","0"],["34952.99","0"],["34953.31","0"],["34949.58","0"],["34949.54","0"],["34952.98","0"],["34951.62","0"],["34947.82","0"],["34954.05","0"]],"a":[["34956.75","0.008756"],["34958","0.0324"],["34959.86","0.0859"],["34963.76","0.1875"],["34956.76","0"],["34963.19","0"],["34973.99","0"],["34974","0"]],"u":20010915,"seq":14108051964}}'
2023-11-02 14:54:43,729 DEBUG ++Rcv decoded: fin=1 opcode=1 data=b'{"topic":"orderbook.50.BTCUSDC","ts":1698936883643,"type":"delta","data":{"s":"BTCUSDC","b":[["34951.27","0.028605"],["34931.31","0.1875"],["34927.87","0.274859"],["34927.86","0.458086"],["34927.27","0.1875"],["34925.01","1.32582"],["34925","2.2097"],["34924.42","0.4207"],["34923.58","0.1875"],["34922.09","2.2053"],["34918.51","0.1875"],["34916.9","0.035725"],["34912.05","0.98593"],["34951.95","0"],["34951.26","0"],["34943.59","0"],["34953.32","0"],["34952.99","0"],["34953.31","0"],["34949.58","0"],["34949.54","0"],["34952.98","0"],["34951.62","0"],["34947.82","0"],["34954.05","0"]],"a":[["34956.75","0.008756"],["34958","0.0324"],["34959.86","0.0859"],["34963.76","0.1875"],["34956.76","0"],["34963.19","0"],["34973.99","0"],["34974","0"]],"u":20010915,"seq":14108051964}}'
2023-11-02 14:54:43,751 DEBUG ++Rcv raw: b'\x81~\x02\xaf{"topic":"orderbook.50.BTCUSDC","ts":1698936883664,"type":"delta","data":{"s":"BTCUSDC","b":[["34950.01","0.049127"],["34946.38","0.00057"],["34946.2","0.046418"],["34912.04","2.2146"],["34911.28","0.1875"],["34910.79","0.4192"],["34905.97","0.1875"],["34901.18","0.1875"],["34948.93","0"],["34935.93","0"],["34945.83","0"],["34935.91","0"],["34951.27","0"],["34947.83","0"],["34948.79","0"],["34939.57","0"]],"a":[["34956.73","0.008756"],["34956.74","0.03895"],["34958.14","0.0859"],["34959.85","0.070986"],["34963.63","0.112507"],["34969","0.000239"],["34956.75","0"],["34961.57","0"],["34965.01","0"],["34969.66","0"],["34973.8","0"],["34963.41","0"]],"u":20010916,"seq":14108052043}}'
2023-11-02 14:54:43,751 DEBUG ++Rcv decoded: fin=1 opcode=1 data=b'{"topic":"orderbook.50.BTCUSDC","ts":1698936883664,"type":"delta","data":{"s":"BTCUSDC","b":[["34950.01","0.049127"],["34946.38","0.00057"],["34946.2","0.046418"],["34912.04","2.2146"],["34911.28","0.1875"],["34910.79","0.4192"],["34905.97","0.1875"],["34901.18","0.1875"],["34948.93","0"],["34935.93","0"],["34945.83","0"],["34935.91","0"],["34951.27","0"],["34947.83","0"],["34948.79","0"],["34939.57","0"]],"a":[["34956.73","0.008756"],["34956.74","0.03895"],["34958.14","0.0859"],["34959.85","0.070986"],["34963.63","0.112507"],["34969","0.000239"],["34956.75","0"],["34961.57","0"],["34965.01","0"],["34969.66","0"],["34973.8","0"],["34963.41","0"]],"u":20010916,"seq":14108052043}}'
2023-11-02 14:54:43,770 DEBUG ++Rcv raw: b'\x81~\x02&{"topic":"orderbook.50.BTCUSDC","ts":1698936883683,"type":"delta","data":{"s":"BTCUSDC","b":[["34946.36","0.114461"],["34945.3","0.001"],["34939.86","0.028"],["34937.4","0.167036"],["34937.02","0.286229"],["34915.01","0.1875"],["34948.94","0"],["34936.36","0"],["34905.97","0"],["34901.18","0"],["34950","0"]],"a":[["34956.71","0.008756"],["34956.75","0.002"],["34957.99","0.070981"],["34961.57","0.051542"],["34966.46","0.114395"],["34973.79","0"],["34956.74","0"],["34959.85","0"],["34970.31","0"],["34956.73","0"]],"u":20010917,"seq":14108052111}}'
2023-11-02 14:54:43,770 DEBUG ++Rcv decoded: fin=1 opcode=1 data=b'{"topic":"orderbook.50.BTCUSDC","ts":1698936883683,"type":"delta","data":{"s":"BTCUSDC","b":[["34946.36","0.114461"],["34945.3","0.001"],["34939.86","0.028"],["34937.4","0.167036"],["34937.02","0.286229"],["34915.01","0.1875"],["34948.94","0"],["34936.36","0"],["34905.97","0"],["34901.18","0"],["34950","0"]],"a":[["34956.71","0.008756"],["34956.75","0.002"],["34957.99","0.070981"],["34961.57","0.051542"],["34966.46","0.114395"],["34973.79","0"],["34956.74","0"],["34959.85","0"],["34970.31","0"],["34956.73","0"]],"u":20010917,"seq":14108052111}}'
2023-11-02 14:54:43,789 DEBUG ++Rcv raw: b'\x81~\x01\x8d{"topic":"orderbook.50.BTCUSDC","ts":1698936883703,"type":"delta","data":{"s":"BTCUSDC","b":[["34950.01","0.028666"],["34948.01","0.35829"],["34946.37","0.06868"],["34931.99","0.278379"],["34915.02","0.112505"],["34937.39","0"],["34910.79","0"],["34946.2","0"],["34949.59","0"]],"a":[["34956.7","0.03895"],["34969.68","0.363415"],["34973.64","0"],["34969.69","0"]],"u":20010918,"seq":14108052138}}'
2023-11-02 14:54:43,789 DEBUG ++Rcv decoded: fin=1 opcode=1 data=b'{"topic":"orderbook.50.BTCUSDC","ts":1698936883703,"type":"delta","data":{"s":"BTCUSDC","b":[["34950.01","0.028666"],["34948.01","0.35829"],["34946.37","0.06868"],["34931.99","0.278379"],["34915.02","0.112505"],["34937.39","0"],["34910.79","0"],["34946.2","0"],["34949.59","0"]],"a":[["34956.7","0.03895"],["34969.68","0.363415"],["34973.64","0"],["34969.69","0"]],"u":20010918,"seq":14108052138}}'
2023-11-02 14:54:43,809 DEBUG ++Rcv raw: b'\x81~\x01e{"topic":"orderbook.50.BTCUSDC","ts":1698936883724,"type":"delta","data":{"s":"BTCUSDC","b":[["34948.02","0.118749"],["34910.79","0.4192"],["34946.37","0"],["34950.01","0"]],"a":[["34956.68","0.03895"],["34956.69","0.008756"],["34956.75","0.030606"],["34972.87","0.033854"],["34973.62","0"],["34956.7","0"],["34956.71","0"]],"u":20010919,"seq":14108052171}}'
2023-11-02 14:54:43,809 DEBUG ++Rcv decoded: fin=1 opcode=1 data=b'{"topic":"orderbook.50.BTCUSDC","ts":1698936883724,"type":"delta","data":{"s":"BTCUSDC","b":[["34948.02","0.118749"],["34910.79","0.4192"],["34946.37","0"],["34950.01","0"]],"a":[["34956.68","0.03895"],["34956.69","0.008756"],["34956.75","0.030606"],["34972.87","0.033854"],["34973.62","0"],["34956.7","0"],["34956.71","0"]],"u":20010919,"seq":14108052171}}'
2023-11-02 14:54:43,829 DEBUG ++Rcv raw: b'\x81~\x01\x13{"topic":"orderbook.50.BTCUSDC","ts":1698936883743,"type":"delta","data":{"s":"BTCUSDC","b":[["34905.97","0.1875"],["34944.27","0"]],"a":[["34956.42","0.0859"],["34956.67","0.008756"],["34956.68","0.026078"],["34973.61","0"],["34956.69","0"]],"u":20010920,"seq":14108052225}}'
2023-11-02 14:54:43,829 DEBUG ++Rcv decoded: fin=1 opcode=1 data=b'{"topic":"orderbook.50.BTCUSDC","ts":1698936883743,"type":"delta","data":{"s":"BTCUSDC","b":[["34905.97","0.1875"],["34944.27","0"]],"a":[["34956.42","0.0859"],["34956.67","0.008756"],["34956.68","0.026078"],["34973.61","0"],["34956.69","0"]],"u":20010920,"seq":14108052225}}'
2023-11-02 14:54:43,849 DEBUG ++Rcv raw: b'\x81~\x03\xdd{"topic":"orderbook.50.BTCUSDC","ts":1698936883763,"type":"delta","data":{"s":"BTCUSDC","b":[["34939.87","0.112508"],["34935.31","1.373004"],["34901.18","0.1875"],["34900","0.0002"],["34899.54","0.412612"],["34899.53","0.687688"],["34899","0.000286"],["34896.94","0.425906"],["34896.88","0.1875"],["34895.71","0.034325"],["34893.07","0.028602"],["34891.58","0.1875"],["34890.19","1.866636"],["34887.17","0.1875"],["34942.66","0"],["34949.97","0"],["34946.19","0"],["34946.1","0"],["34948.02","0"],["34946.36","0"],["34944.38","0"],["34939.85","0"],["34948.85","0"],["34943.75","0"],["34944.01","0"],["34940.94","0"],["34937.02","0"],["34927.86","0"]],"a":[["34954.69","0.060297"],["34954.7","0.0859"],["34956","0.0324"],["34956.41","0.090497"],["34957.99","0.051549"],["34959.92","0.1875"],["34960.04","0.057208"],["34962.87","0.028606"],["34971.9","0"],["34972.95","0"],["34972.55","0"],["34956.67","0"],["34973.09","0"],["34972.87","0"],["34973.24","0"]],"u":20010921,"seq":14108052337}}'
2023-11-02 14:54:43,849 DEBUG ++Rcv decoded: fin=1 opcode=1 data=b'{"topic":"orderbook.50.BTCUSDC","ts":1698936883763,"type":"delta","data":{"s":"BTCUSDC","b":[["34939.87","0.112508"],["34935.31","1.373004"],["34901.18","0.1875"],["34900","0.0002"],["34899.54","0.412612"],["34899.53","0.687688"],["34899","0.000286"],["34896.94","0.425906"],["34896.88","0.1875"],["34895.71","0.034325"],["34893.07","0.028602"],["34891.58","0.1875"],["34890.19","1.866636"],["34887.17","0.1875"],["34942.66","0"],["34949.97","0"],["34946.19","0"],["34946.1","0"],["34948.02","0"],["34946.36","0"],["34944.38","0"],["34939.85","0"],["34948.85","0"],["34943.75","0"],["34944.01","0"],["34940.94","0"],["34937.02","0"],["34927.86","0"]],"a":[["34954.69","0.060297"],["34954.7","0.0859"],["34956","0.0324"],["34956.41","0.090497"],["34957.99","0.051549"],["34959.92","0.1875"],["34960.04","0.057208"],["34962.87","0.028606"],["34971.9","0"],["34972.95","0"],["34972.55","0"],["34956.67","0"],["34973.09","0"],["34972.87","0"],["34973.24","0"]],"u":20010921,"seq":14108052337}}'
2023-11-02 14:54:43,871 DEBUG ++Rcv raw: b'\x81~\x03\xa2{"topic":"orderbook.50.BTCUSDC","ts":1698936883783,"type":"delta","data":{"s":"BTCUSDC","b":[["34947.11","0.014492"],["34944.01","0.036051"],["34937.92","0.026205"],["34935.32","0.823806"],["34890.2","0.151609"],["34883.98","1.5"],["34883.97","0.4159"],["34882.9","0.1875"],["34882.67","0.4237"],["34948","0"],["34943.35","0"],["34927.87","0"],["34946.11","0"],["34939.87","0"],["34946.38","0"],["34937.4","0"],["34939.11","0"],["34948.01","0"]],"a":[["34948.01","0.00002"],["34948.02","0.05842"],["34948.03","0.05842"],["34948.86","0.05842"],["34952.98","0.0859"],["34954","0.0324"],["34954.68","0.122365"],["34954.69","0.008756"],["34954.7","0.111978"],["34955.99","0.054304"],["34959.85","0.112507"],["34969.67","0.218057"],["34960.04","0"],["34970.18","0"],["34971.37","0"],["34966.46","0"],["34970.32","0"],["34970.83","0"],["34970.66","0"],["34956.41","0"],["34971.39","0"],["34971.41","0"]],"u":20010922,"seq":14108052453}}'
2023-11-02 14:54:43,871 DEBUG ++Rcv decoded: fin=1 opcode=1 data=b'{"topic":"orderbook.50.BTCUSDC","ts":1698936883783,"type":"delta","data":{"s":"BTCUSDC","b":[["34947.11","0.014492"],["34944.01","0.036051"],["34937.92","0.026205"],["34935.32","0.823806"],["34890.2","0.151609"],["34883.98","1.5"],["34883.97","0.4159"],["34882.9","0.1875"],["34882.67","0.4237"],["34948","0"],["34943.35","0"],["34927.87","0"],["34946.11","0"],["34939.87","0"],["34946.38","0"],["34937.4","0"],["34939.11","0"],["34948.01","0"]],"a":[["34948.01","0.00002"],["34948.02","0.05842"],["34948.03","0.05842"],["34948.86","0.05842"],["34952.98","0.0859"],["34954","0.0324"],["34954.68","0.122365"],["34954.69","0.008756"],["34954.7","0.111978"],["34955.99","0.054304"],["34959.85","0.112507"],["34969.67","0.218057"],["34960.04","0"],["34970.18","0"],["34971.37","0"],["34966.46","0"],["34970.32","0"],["34970.83","0"],["34970.66","0"],["34956.41","0"],["34971.39","0"],["34971.41","0"]],"u":20010922,"seq":14108052453}}'
2023-11-02 14:54:43,889 DEBUG ++Rcv raw: b'\x81~\x03\x0e{"topic":"orderbook.50.BTCUSDC","ts":1698936883804,"type":"delta","data":{"s":"BTCUSDC","b":[["34944.01","0.053806"],["34942","0.0324"],["34939.87","0.078699"],["34936.36","0.112501"],["34881.86","0.038473"],["34935.31","0"],["34945.3","0"],["34947.11","0"],["34946","0"]],"a":[["34946.01","0.05842"],["34951.99","0.008756"],["34952","0.0324"],["34952.98","0.111978"],["34954.68","0.08772"],["34956.75","0.028606"],["34961.56","0.001456"],["34970.18","0.0859"],["34970.32","0.000863"],["34970.83","0.043104"],["34971.37","0.112506"],["34971.39","0.076322"],["34971.41","0.1875"],["34969.68","0"],["34962.87","0"],["34948.86","0"],["34948.02","0"],["34966.79","0"],["34948.03","0"],["34948.01","0"],["34955.99","0"],["34954.69","0"],["34963.02","0"]],"u":20010923,"seq":14108052556}}'
2023-11-02 14:54:43,889 DEBUG ++Rcv decoded: fin=1 opcode=1 data=b'{"topic":"orderbook.50.BTCUSDC","ts":1698936883804,"type":"delta","data":{"s":"BTCUSDC","b":[["34944.01","0.053806"],["34942","0.0324"],["34939.87","0.078699"],["34936.36","0.112501"],["34881.86","0.038473"],["34935.31","0"],["34945.3","0"],["34947.11","0"],["34946","0"]],"a":[["34946.01","0.05842"],["34951.99","0.008756"],["34952","0.0324"],["34952.98","0.111978"],["34954.68","0.08772"],["34956.75","0.028606"],["34961.56","0.001456"],["34970.18","0.0859"],["34970.32","0.000863"],["34970.83","0.043104"],["34971.37","0.112506"],["34971.39","0.076322"],["34971.41","0.1875"],["34969.68","0"],["34962.87","0"],["34948.86","0"],["34948.02","0"],["34966.79","0"],["34948.03","0"],["34948.01","0"],["34955.99","0"],["34954.69","0"],["34963.02","0"]],"u":20010923,"seq":14108052556}}'
2023-11-02 14:54:43,909 DEBUG ++Rcv raw: b'\x81~\x02\x99{"topic":"orderbook.50.BTCUSDC","ts":1698936883824,"type":"delta","data":{"s":"BTCUSDC","b":[["34942.67","0.081653"],["34932","0.167031"],["34922.63","0.278379"],["34912.31","0.048901"],["34891.59","0.112505"],["34879","0.1875"],["34876.57","0.000563"],["34875.02","0.1875"],["34899.53","0"],["34931.99","0"],["34936.35","0"],["34935.32","0"],["34944","0"],["34944.01","0"],["34939.87","0"]],"a":[["34950","0.0324"],["34951.25","0.060304"],["34951.26","0.0859"],["34952.97","0.051542"],["34962.86","0.077408"],["34971.09","0.02825"],["34971.39","0"],["34969.67","0"],["34956.75","0"],["34951.99","0"],["34970","0"],["34946.01","0"]],"u":20010924,"seq":14108052626}}'
2023-11-02 14:54:43,909 DEBUG ++Rcv decoded: fin=1 opcode=1 data=b'{"topic":"orderbook.50.BTCUSDC","ts":1698936883824,"type":"delta","data":{"s":"BTCUSDC","b":[["34942.67","0.081653"],["34932","0.167031"],["34922.63","0.278379"],["34912.31","0.048901"],["34891.59","0.112505"],["34879","0.1875"],["34876.57","0.000563"],["34875.02","0.1875"],["34899.53","0"],["34931.99","0"],["34936.35","0"],["34935.32","0"],["34944","0"],["34944.01","0"],["34939.87","0"]],"a":[["34950","0.0324"],["34951.25","0.060304"],["34951.26","0.0859"],["34952.97","0.051542"],["34962.86","0.077408"],["34971.09","0.02825"],["34971.39","0"],["34969.67","0"],["34956.75","0"],["34951.99","0"],["34970","0"],["34946.01","0"]],"u":20010924,"seq":14108052626}}'
2023-11-02 14:54:43,929 DEBUG ++Rcv raw: b'\x81~\x03g{"topic":"orderbook.50.BTCUSDC","ts":1698936883843,"type":"delta","data":{"s":"BTCUSDC","b":[["34946.34","0.032373"],["34946.15","0.106622"],["34943.53","0.032373"],["34937.78","0.00057"],["34937","0.114491"],["34936.36","0.078699"],["34935.67","0.1875"],["34925.87","0.28632"],["34925.02","0.003561"],["34922.64","0.840026"],["34915.9","0.458243"],["34886.82","0.687938"],["34883.99","0.290417"],["34881.86","0"],["34941.97","0"],["34924.42","0"],["34882.9","0"],["34875.02","0"],["34883.97","0"],["34932","0"],["34883.98","0"],["34882.67","0"],["34899.54","0"],["34879","0"],["34876.57","0"]],"a":[["34949.59","0.08315"],["34949.99","0.008756"],["34951.24","0.087723"],["34958.27","0.03"],["34964.12","0.114403"],["34970.07","0.051542"],["34951.25","0"],["34950","0"],["34951.26","0"],["34971.41","0"],["34971.37","0"],["34971.09","0"]],"u":20010925,"seq":14108052707}}'
2023-11-02 14:54:43,929 DEBUG ++Rcv decoded: fin=1 opcode=1 data=b'{"topic":"orderbook.50.BTCUSDC","ts":1698936883843,"type":"delta","data":{"s":"BTCUSDC","b":[["34946.34","0.032373"],["34946.15","0.106622"],["34943.53","0.032373"],["34937.78","0.00057"],["34937","0.114491"],["34936.36","0.078699"],["34935.67","0.1875"],["34925.87","0.28632"],["34925.02","0.003561"],["34922.64","0.840026"],["34915.9","0.458243"],["34886.82","0.687938"],["34883.99","0.290417"],["34881.86","0"],["34941.97","0"],["34924.42","0"],["34882.9","0"],["34875.02","0"],["34883.97","0"],["34932","0"],["34883.98","0"],["34882.67","0"],["34899.54","0"],["34879","0"],["34876.57","0"]],"a":[["34949.59","0.08315"],["34949.99","0.008756"],["34951.24","0.087723"],["34958.27","0.03"],["34964.12","0.114403"],["34970.07","0.051542"],["34951.25","0"],["34950","0"],["34951.26","0"],["34971.41","0"],["34971.37","0"],["34971.09","0"]],"u":20010925,"seq":14108052707}}'
2023-11-02 14:54:43,949 DEBUG ++Rcv raw: b'\x81~\x02\x15{"topic":"orderbook.50.BTCUSDC","ts":1698936883864,"type":"delta","data":{"s":"BTCUSDC","b":[["34939.87","0.034718"],["34937.01","0.068699"],["34933.27","0.071356"],["34925.88","0.171798"],["34886.83","0.209174"],["34883.98","1.5"],["34883.97","0.4159"],["34915.02","0"],["34912.31","0"],["34942.67","0"],["34946.15","0"],["34943.53","0"],["34895.71","0"],["34937.78","0"]],"a":[["34949.57","0.085087"],["34949.58","0.008756"],["34951.26","0.0859"],["34949.59","0"],["34951.24","0"],["34949.99","0"]],"u":20010926,"seq":14108052766}}'
2023-11-02 14:54:43,949 DEBUG ++Rcv decoded: fin=1 opcode=1 data=b'{"topic":"orderbook.50.BTCUSDC","ts":1698936883864,"type":"delta","data":{"s":"BTCUSDC","b":[["34939.87","0.034718"],["34937.01","0.068699"],["34933.27","0.071356"],["34925.88","0.171798"],["34886.83","0.209174"],["34883.98","1.5"],["34883.97","0.4159"],["34915.02","0"],["34912.31","0"],["34942.67","0"],["34946.15","0"],["34943.53","0"],["34895.71","0"],["34937.78","0"]],"a":[["34949.57","0.085087"],["34949.58","0.008756"],["34951.26","0.0859"],["34949.59","0"],["34951.24","0"],["34949.99","0"]],"u":20010926,"seq":14108052766}}'
2023-11-02 14:54:43,970 DEBUG ++Rcv raw: b'\x81~\x01\x98{"topic":"orderbook.50.BTCUSDC","ts":1698936883883,"type":"delta","data":{"s":"BTCUSDC","b":[["34935.68","0.112509"],["34882.9","0.1875"],["34882.67","0.4237"],["34881.86","0.038473"],["34915.9","0"],["34937","0"],["34925.87","0"],["34946.34","0"]],"a":[["34949.56","0.008756"],["34951.25","0.05154"],["34971.09","0.02825"],["34949.58","0"],["34949.57","0"],["34964.12","0"]],"u":20010927,"seq":14108052818}}'
2023-11-02 14:54:43,970 DEBUG ++Rcv decoded: fin=1 opcode=1 data=b'{"topic":"orderbook.50.BTCUSDC","ts":1698936883883,"type":"delta","data":{"s":"BTCUSDC","b":[["34935.68","0.112509"],["34882.9","0.1875"],["34882.67","0.4237"],["34881.86","0.038473"],["34915.9","0"],["34937","0"],["34925.87","0"],["34946.34","0"]],"a":[["34949.56","0.008756"],["34951.25","0.05154"],["34971.09","0.02825"],["34949.58","0"],["34949.57","0"],["34964.12","0"]],"u":20010927,"seq":14108052818}}'
2023-11-02 14:54:43,989 DEBUG ++Rcv raw: b'\x81~\x01\x1f{"topic":"orderbook.50.BTCUSDC","ts":1698936883903,"type":"delta","data":{"s":"BTCUSDC","b":[["34942.94","0.034343"],["34931.32","0.112501"],["34919","1.373004"],["34925.88","0"],["34937.01","0"],["34881.86","0"]],"a":[["34950","0.0324"],["34969.1","0"]],"u":20010928,"seq":14108052887}}'
2023-11-02 14:54:43,989 DEBUG ++Rcv decoded: fin=1 opcode=1 data=b'{"topic":"orderbook.50.BTCUSDC","ts":1698936883903,"type":"delta","data":{"s":"BTCUSDC","b":[["34942.94","0.034343"],["34931.32","0.112501"],["34919","1.373004"],["34925.88","0"],["34937.01","0"],["34881.86","0"]],"a":[["34950","0.0324"],["34969.1","0"]],"u":20010928,"seq":14108052887}}'
2023-11-02 14:54:44,009 DEBUG ++Rcv raw: b'\x81~\x01^{"topic":"orderbook.50.BTCUSDC","ts":1698936883923,"type":"delta","data":{"s":"BTCUSDC","b":[["34942.01","0.034996"],["34942","0.058322"],["34938.05","0.00057"],["34938.02","0.031373"],["34882.67","0"],["34942.94","0"],["34937.92","0"]],"a":[["34955.44","0.03"],["34971.15","0.278379"],["34958.27","0"],["34968","0"]],"u":20010929,"seq":14108052937}}'
2023-11-02 14:54:44,009 DEBUG ++Rcv decoded: fin=1 opcode=1 data=b'{"topic":"orderbook.50.BTCUSDC","ts":1698936883923,"type":"delta","data":{"s":"BTCUSDC","b":[["34942.01","0.034996"],["34942","0.058322"],["34938.05","0.00057"],["34938.02","0.031373"],["34882.67","0"],["34942.94","0"],["34937.92","0"]],"a":[["34955.44","0.03"],["34971.15","0.278379"],["34958.27","0"],["34968","0"]],"u":20010929,"seq":14108052937}}'
2023-11-02 14:54:44,029 DEBUG ++Rcv raw: b'\x81~\x02\x1b{"topic":"orderbook.50.BTCUSDC","ts":1698936883943,"type":"delta","data":{"s":"BTCUSDC","b":[["34942.03","0.053733"],["34942.02","0.031234"],["34932.23","0.114507"],["34921.1","0.286359"],["34910.03","0.45832"],["34882.9","0"],["34939.87","0"],["34942.01","0"],["34883.97","0"],["34883.98","0"]],"a":[["34949.54","0.008756"],["34949.55","0.048275"],["34952.96","0.001456"],["34955.99","0.051544"],["34959.36","0.114418"],["34971.09","0"],["34949.56","0"],["34970.83","0"],["34955.44","0"],["34971.15","0"]],"u":20010930,"seq":14108053007}}'
2023-11-02 14:54:44,029 DEBUG ++Rcv decoded: fin=1 opcode=1 data=b'{"topic":"orderbook.50.BTCUSDC","ts":1698936883943,"type":"delta","data":{"s":"BTCUSDC","b":[["34942.03","0.053733"],["34942.02","0.031234"],["34932.23","0.114507"],["34921.1","0.286359"],["34910.03","0.45832"],["34882.9","0"],["34939.87","0"],["34942.01","0"],["34883.97","0"],["34883.98","0"]],"a":[["34949.54","0.008756"],["34949.55","0.048275"],["34952.96","0.001456"],["34955.99","0.051544"],["34959.36","0.114418"],["34971.09","0"],["34949.56","0"],["34970.83","0"],["34955.44","0"],["34971.15","0"]],"u":20010930,"seq":14108053007}}'
2023-11-02 14:54:44,049 DEBUG ++Rcv raw: b'\x81~\x01\x92{"topic":"orderbook.50.BTCUSDC","ts":1698936883964,"type":"delta","data":{"s":"BTCUSDC","b":[["34883.98","1.5"],["34883.97","0.4159"],["34882.9","0.1875"],["34882.67","0.4237"],["34932.23","0"],["34942.02","0"],["34921.1","0"],["34939.76","0"]],"a":[["34952.13","0.03"],["34970.82","0.167032"],["34970.83","0.043104"],["34959.36","0"],["34961.56","0"],["34955.99","0"]],"u":20010931,"seq":14108053041}}'
2023-11-02 14:54:44,049 DEBUG ++Rcv decoded: fin=1 opcode=1 data=b'{"topic":"orderbook.50.BTCUSDC","ts":1698936883964,"type":"delta","data":{"s":"BTCUSDC","b":[["34883.98","1.5"],["34883.97","0.4159"],["34882.9","0.1875"],["34882.67","0.4237"],["34932.23","0"],["34942.02","0"],["34921.1","0"],["34939.76","0"]],"a":[["34952.13","0.03"],["34970.82","0.167032"],["34970.83","0.043104"],["34959.36","0"],["34961.56","0"],["34955.99","0"]],"u":20010931,"seq":14108053041}}'
2023-11-02 14:54:44,069 DEBUG ++Rcv raw: b'\x81~\x00\xc6{"topic":"orderbook.50.BTCUSDC","ts":1698936883984,"type":"delta","data":{"s":"BTCUSDC","b":[["34942.03","0.034995"],["34931.51","0.026205"],["34933.27","0"]],"a":[],"u":20010932,"seq":14108053075}}'
2023-11-02 14:54:44,070 DEBUG ++Rcv decoded: fin=1 opcode=1 data=b'{"topic":"orderbook.50.BTCUSDC","ts":1698936883984,"type":"delta","data":{"s":"BTCUSDC","b":[["34942.03","0.034995"],["34931.51","0.026205"],["34933.27","0"]],"a":[],"u":20010932,"seq":14108053075}}'
2023-11-02 14:54:44,089 DEBUG ++Rcv raw: b'\x81~\x00\xee{"topic":"orderbook.50.BTCUSDC","ts":1698936884004,"type":"delta","data":{"s":"BTCUSDC","b":[["34927.28","0.112504"],["34931.32","0"]],"a":[["34949.54","0.038756"],["34955.99","0.362003"],["34952.13","0"]],"u":20010933,"seq":14108053097}}'
2023-11-02 14:54:44,089 DEBUG ++Rcv decoded: fin=1 opcode=1 data=b'{"topic":"orderbook.50.BTCUSDC","ts":1698936884004,"type":"delta","data":{"s":"BTCUSDC","b":[["34927.28","0.112504"],["34931.32","0"]],"a":[["34949.54","0.038756"],["34955.99","0.362003"],["34952.13","0"]],"u":20010933,"seq":14108053097}}'
2023-11-02 14:54:44,109 DEBUG ++Rcv raw: b'\x81~\x01({"topic":"orderbook.50.BTCUSDC","ts":1698936884024,"type":"delta","data":{"s":"BTCUSDC","b":[["34938.29","0.057243"],["34881.86","0.038473"],["34935.67","0"],["34910.03","0"]],"a":[["34949.53","0.052223"],["34955.98","0.217207"],["34970.83","0"],["34970.82","0"]],"u":20010934,"seq":14108053117}}'
2023-11-02 14:54:44,110 DEBUG ++Rcv decoded: fin=1 opcode=1 data=b'{"topic":"orderbook.50.BTCUSDC","ts":1698936884024,"type":"delta","data":{"s":"BTCUSDC","b":[["34938.29","0.057243"],["34881.86","0.038473"],["34935.67","0"],["34910.03","0"]],"a":[["34949.53","0.052223"],["34955.98","0.217207"],["34970.83","0"],["34970.82","0"]],"u":20010934,"seq":14108053117}}'
2023-11-02 14:54:44,130 DEBUG ++Rcv raw: b'\x81~\x01\xcd{"topic":"orderbook.50.BTCUSDC","ts":1698936884044,"type":"delta","data":{"s":"BTCUSDC","b":[["34942.05","0.072482"],["34935.03","0.1875"],["34931.52","0.112507"],["34927.29","0.003561"],["34896.95","0.255551"],["34927.28","0"],["34882.67","0"],["34942.03","0"],["34935.68","0"],["34881.86","0"]],"a":[["34948.48","0.008756"],["34949.54","0.03"],["34949.55","0.076887"],["34970.82","0.167032"],["34963.15","0"],["34970.18","0"]],"u":20010935,"seq":14108053161}}'
2023-11-02 14:54:44,130 DEBUG ++Rcv decoded: fin=1 opcode=1 data=b'{"topic":"orderbook.50.BTCUSDC","ts":1698936884044,"type":"delta","data":{"s":"BTCUSDC","b":[["34942.05","0.072482"],["34935.03","0.1875"],["34931.52","0.112507"],["34927.29","0.003561"],["34896.95","0.255551"],["34927.28","0"],["34882.67","0"],["34942.03","0"],["34935.68","0"],["34881.86","0"]],"a":[["34948.48","0.008756"],["34949.54","0.03"],["34949.55","0.076887"],["34970.82","0.167032"],["34963.15","0"],["34970.18","0"]],"u":20010935,"seq":14108053161}}'
2023-11-02 14:54:44,149 DEBUG ++Rcv raw: b'\x81~\x01\xb9{"topic":"orderbook.50.BTCUSDC","ts":1698936884063,"type":"delta","data":{"s":"BTCUSDC","b":[["34942.05","0.034993"],["34935.04","0.112501"],["34927.28","0.112502"],["34882.67","0.4237"],["34938.29","0"],["34931.52","0"],["34925.02","0"]],"a":[["34949.52","0.03"],["34949.53","0.054223"],["34955.48","0.1875"],["34964.14","0.02859"],["34970.07","0.024363"],["34970.82","0"],["34970.32","0"],["34970.08","0"]],"u":20010936,"seq":14108053205}}'
2023-11-02 14:54:44,149 DEBUG ++Rcv decoded: fin=1 opcode=1 data=b'{"topic":"orderbook.50.BTCUSDC","ts":1698936884063,"type":"delta","data":{"s":"BTCUSDC","b":[["34942.05","0.034993"],["34935.04","0.112501"],["34927.28","0.112502"],["34882.67","0.4237"],["34938.29","0"],["34931.52","0"],["34925.02","0"]],"a":[["34949.52","0.03"],["34949.53","0.054223"],["34955.48","0.1875"],["34964.14","0.02859"],["34970.07","0.024363"],["34970.82","0"],["34970.32","0"],["34970.08","0"]],"u":20010936,"seq":14108053205}}'
2023-11-02 14:54:44,171 DEBUG ++Rcv raw: b'\x81~\x01\xb3{"topic":"orderbook.50.BTCUSDC","ts":1698936884083,"type":"delta","data":{"s":"BTCUSDC","b":[["34930.59","0.114512"],["34928.32","0.029863"],["34918.47","0.286381"],["34907.31","0.458356"],["34882.67","0"],["34883.97","0"],["34939.86","0"],["34882.9","0"]],"a":[["34949.51","0.083336"],["34949.53","0.002"],["34957.93","0.114423"],["34968.1","0.285974"],["34968.46","0"],["34969","0"],["34970.07","0"]],"u":20010937,"seq":14108053237}}'
2023-11-02 14:54:44,171 DEBUG ++Rcv decoded: fin=1 opcode=1 data=b'{"topic":"orderbook.50.BTCUSDC","ts":1698936884083,"type":"delta","data":{"s":"BTCUSDC","b":[["34930.59","0.114512"],["34928.32","0.029863"],["34918.47","0.286381"],["34907.31","0.458356"],["34882.67","0"],["34883.97","0"],["34939.86","0"],["34882.9","0"]],"a":[["34949.51","0.083336"],["34949.53","0.002"],["34957.93","0.114423"],["34968.1","0.285974"],["34968.46","0"],["34969","0"],["34970.07","0"]],"u":20010937,"seq":14108053237}}'
2023-11-02 14:54:44,190 DEBUG ++Rcv raw: b'\x81~\x01${"topic":"orderbook.50.BTCUSDC","ts":1698936884103,"type":"delta","data":{"s":"BTCUSDC","b":[["34946.72","0.000052"],["34930.6","0.068712"],["34918.47","0"],["34935.03","0"]],"a":[["34957.92","0.068659"],["34968.46","0.0859"],["34957.99","0"],["34968.1","0"]],"u":20010938,"seq":14108053260}}'
2023-11-02 14:54:44,190 DEBUG ++Rcv decoded: fin=1 opcode=1 data=b'{"topic":"orderbook.50.BTCUSDC","ts":1698936884103,"type":"delta","data":{"s":"BTCUSDC","b":[["34946.72","0.000052"],["34930.6","0.068712"],["34918.47","0"],["34935.03","0"]],"a":[["34957.92","0.068659"],["34968.46","0.0859"],["34957.99","0"],["34968.1","0"]],"u":20010938,"seq":14108053260}}'
2023-11-02 14:54:44,209 DEBUG ++Rcv raw: b'\x81~\x01\xa4{"topic":"orderbook.50.BTCUSDC","ts":1698936884123,"type":"delta","data":{"s":"BTCUSDC","b":[["34939.2","0.057242"],["34931.52","0.112507"],["34883.97","0.4159"],["34930.6","0"],["34935.04","0"],["34946.72","0"]],"a":[["34948.46","0.008756"],["34949.17","0.057225"],["34949.55","0.048275"],["34952.98","0.0859"],["34956.57","1.373004"],["34968.46","0"],["34949.53","0"],["34948.48","0"]],"u":20010939,"seq":14108053303}}'
2023-11-02 14:54:44,209 DEBUG ++Rcv decoded: fin=1 opcode=1 data=b'{"topic":"orderbook.50.BTCUSDC","ts":1698936884123,"type":"delta","data":{"s":"BTCUSDC","b":[["34939.2","0.057242"],["34931.52","0.112507"],["34883.97","0.4159"],["34930.6","0"],["34935.04","0"],["34946.72","0"]],"a":[["34948.46","0.008756"],["34949.17","0.057225"],["34949.55","0.048275"],["34952.98","0.0859"],["34956.57","1.373004"],["34968.46","0"],["34949.53","0"],["34948.48","0"]],"u":20010939,"seq":14108053303}}'
2023-11-02 14:54:44,229 DEBUG ++Rcv raw: b'\x81~\x00\xee{"topic":"orderbook.50.BTCUSDC","ts":1698936884143,"type":"delta","data":{"s":"BTCUSDC","b":[["34939.21","0.034353"],["34883.97","0"]],"a":[["34955.98","0.542365"],["34970.07","0.024363"],["34949.52","0"]],"u":20010940,"seq":14108053330}}'
2023-11-02 14:54:44,230 DEBUG ++Rcv decoded: fin=1 opcode=1 data=b'{"topic":"orderbook.50.BTCUSDC","ts":1698936884143,"type":"delta","data":{"s":"BTCUSDC","b":[["34939.21","0.034353"],["34883.97","0"]],"a":[["34955.98","0.542365"],["34970.07","0.024363"],["34949.52","0"]],"u":20010940,"seq":14108053330}}'
2023-11-02 14:54:44,249 DEBUG ++Rcv raw: b'\x81~\x01r{"topic":"orderbook.50.BTCUSDC","ts":1698936884164,"type":"delta","data":{"s":"BTCUSDC","b":[["34945.92","0.100665"],["34940","0.0324"],["34883.98","0"],["34939.2","0"]],"a":[["34949.16","0.069412"],["34970.08","0.0406"],["34970.32","0.000863"],["34970.82","0.167032"],["34955.48","0"],["34970.07","0"],["34949.51","0"],["34949.17","0"]],"u":20010941,"seq":14108053375}}'
2023-11-02 14:54:44,249 DEBUG ++Rcv decoded: fin=1 opcode=1 data=b'{"topic":"orderbook.50.BTCUSDC","ts":1698936884164,"type":"delta","data":{"s":"BTCUSDC","b":[["34945.92","0.100665"],["34940","0.0324"],["34883.98","0"],["34939.2","0"]],"a":[["34949.16","0.069412"],["34970.08","0.0406"],["34970.32","0.000863"],["34970.82","0.167032"],["34955.48","0"],["34970.07","0"],["34949.51","0"],["34949.17","0"]],"u":20010941,"seq":14108053375}}'
2023-11-02 14:54:44,269 DEBUG ++Rcv raw: b'\x81~\x01f{"topic":"orderbook.50.BTCUSDC","ts":1698936884183,"type":"delta","data":{"s":"BTCUSDC","b":[["34939.66","0.04425"],["34919.68","0.286371"],["34915.44","0.061201"],["34939.21","0"],["34883.99","0"],["34938.05","0"]],"a":[["34949.16","0.046968"],["34955.46","0.1875"],["34969.46","0.285963"],["34970.82","0"],["34970.32","0"]],"u":20010942,"seq":14108053412}}'
2023-11-02 14:54:44,269 DEBUG ++Rcv decoded: fin=1 opcode=1 data=b'{"topic":"orderbook.50.BTCUSDC","ts":1698936884183,"type":"delta","data":{"s":"BTCUSDC","b":[["34939.66","0.04425"],["34919.68","0.286371"],["34915.44","0.061201"],["34939.21","0"],["34883.99","0"],["34938.05","0"]],"a":[["34949.16","0.046968"],["34955.46","0.1875"],["34969.46","0.285963"],["34970.82","0"],["34970.32","0"]],"u":20010942,"seq":14108053412}}'
2023-11-02 14:54:44,289 DEBUG ++Rcv raw: b'\x81~\x01\x17{"topic":"orderbook.50.BTCUSDC","ts":1698936884204,"type":"delta","data":{"s":"BTCUSDC","b":[["34945.92","0.015065"],["34904.94","0.155893"],["34886.82","0"]],"a":[["34948.45","0.037532"],["34969.45","0.171581"],["34969.46","0"],["34970.08","0"]],"u":20010943,"seq":14108053429}}'
2023-11-02 14:54:44,290 DEBUG ++Rcv decoded: fin=1 opcode=1 data=b'{"topic":"orderbook.50.BTCUSDC","ts":1698936884204,"type":"delta","data":{"s":"BTCUSDC","b":[["34945.92","0.015065"],["34904.94","0.155893"],["34886.82","0"]],"a":[["34948.45","0.037532"],["34969.45","0.171581"],["34969.46","0"],["34970.08","0"]],"u":20010943,"seq":14108053429}}'
2023-11-02 14:54:44,309 DEBUG ++Rcv raw: b'\x81~\x01\x02{"topic":"orderbook.50.BTCUSDC","ts":1698936884223,"type":"delta","data":{"s":"BTCUSDC","b":[["34945.92","0.000005"]],"a":[["34948.37","0.089715"],["34948.44","0.03"],["34948.45","0.030613"],["34948.46","0"],["34969.45","0"]],"u":20010944,"seq":14108053450}}'
2023-11-02 14:54:44,309 DEBUG ++Rcv decoded: fin=1 opcode=1 data=b'{"topic":"orderbook.50.BTCUSDC","ts":1698936884223,"type":"delta","data":{"s":"BTCUSDC","b":[["34945.92","0.000005"]],"a":[["34948.37","0.089715"],["34948.44","0.03"],["34948.45","0.030613"],["34948.46","0"],["34969.45","0"]],"u":20010944,"seq":14108053450}}'
2023-11-02 14:54:44,329 DEBUG ++Rcv raw: b'\x81~\x01<{"topic":"orderbook.50.BTCUSDC","ts":1698936884244,"type":"delta","data":{"s":"BTCUSDC","b":[["34937.16","0.00057"],["34935.79","0.04425"],["34939.66","0"],["34886.83","0"]],"a":[["34948.36","0.008756"],["34949.54","0.1159"],["34969.46","0.285963"],["34966.74","0"],["34948.37","0"]],"u":20010945,"seq":14108053470}}'
2023-11-02 14:54:44,330 DEBUG ++Rcv decoded: fin=1 opcode=1 data=b'{"topic":"orderbook.50.BTCUSDC","ts":1698936884244,"type":"delta","data":{"s":"BTCUSDC","b":[["34937.16","0.00057"],["34935.79","0.04425"],["34939.66","0"],["34886.83","0"]],"a":[["34948.36","0.008756"],["34949.54","0.1159"],["34969.46","0.285963"],["34966.74","0"],["34948.37","0"]],"u":20010945,"seq":14108053470}}'
2023-11-02 14:54:44,349 DEBUG ++Rcv raw: b'\x81~\x00\xef{"topic":"orderbook.50.BTCUSDC","ts":1698936884263,"type":"delta","data":{"s":"BTCUSDC","b":[],"a":[["34949.16","0.085303"],["34964.61","0.055868"],["34969.45","0.171584"],["34948.44","0"],["34966.12","0"]],"u":20010946,"seq":14108053488}}'
2023-11-02 14:54:44,349 DEBUG ++Rcv decoded: fin=1 opcode=1 data=b'{"topic":"orderbook.50.BTCUSDC","ts":1698936884263,"type":"delta","data":{"s":"BTCUSDC","b":[],"a":[["34949.16","0.085303"],["34964.61","0.055868"],["34969.45","0.171584"],["34948.44","0"],["34966.12","0"]],"u":20010946,"seq":14108053488}}'
2023-11-02 14:54:44,369 DEBUG ++Rcv raw: b'\x81~\x01\x00{"topic":"orderbook.50.BTCUSDC","ts":1698936884284,"type":"delta","data":{"s":"BTCUSDC","b":[["34886.83","0.209174"],["34945.92","0"]],"a":[["34948.36","0.040212"],["34949.54","0.03"],["34970.08","0.0406"],["34952.96","0"]],"u":20010947,"seq":14108053507}}'
2023-11-02 14:54:44,369 DEBUG ++Rcv decoded: fin=1 opcode=1 data=b'{"topic":"orderbook.50.BTCUSDC","ts":1698936884284,"type":"delta","data":{"s":"BTCUSDC","b":[["34886.83","0.209174"],["34945.92","0"]],"a":[["34948.36","0.040212"],["34949.54","0.03"],["34970.08","0.0406"],["34952.96","0"]],"u":20010947,"seq":14108053507}}'
2023-11-02 14:54:44,389 DEBUG ++Rcv raw: b'\x81~\x01\xbb{"topic":"orderbook.50.BTCUSDC","ts":1698936884303,"type":"delta","data":{"s":"BTCUSDC","b":[["34931.97","0.114508"],["34931.53","0.003561"],["34886.82","0.687938"],["34919.68","0"],["34927.29","0"],["34930.59","0"]],"a":[["34948.35","0.03"],["34948.36","0.010212"],["34949.16","0.046968"],["34949.54","0.1159"],["34950.3","0.057224"],["34959.28","0.114418"],["34957.93","0"],["34969.46","0"],["34970.08","0"]],"u":20010948,"seq":14108053536}}'
2023-11-02 14:54:44,389 DEBUG ++Rcv decoded: fin=1 opcode=1 data=b'{"topic":"orderbook.50.BTCUSDC","ts":1698936884303,"type":"delta","data":{"s":"BTCUSDC","b":[["34931.97","0.114508"],["34931.53","0.003561"],["34886.82","0.687938"],["34919.68","0"],["34927.29","0"],["34930.59","0"]],"a":[["34948.35","0.03"],["34948.36","0.010212"],["34949.16","0.046968"],["34949.54","0.1159"],["34950.3","0.057224"],["34959.28","0.114418"],["34957.93","0"],["34969.46","0"],["34970.08","0"]],"u":20010948,"seq":14108053536}}'
2023-11-02 14:54:44,409 DEBUG ++Rcv raw: b'\x81~\x01R{"topic":"orderbook.50.BTCUSDC","ts":1698936884324,"type":"delta","data":{"s":"BTCUSDC","b":[["34940.35","0.05724"],["34920.91","0.286361"],["34886.82","0"],["34907.31","0"]],"a":[["34948.45","0.002"],["34949.16","0.092642"],["34969.46","0.285963"],["34970.08","0.0406"],["34948.35","0"],["34969.45","0"]],"u":20010949,"seq":14108053549}}'
2023-11-02 14:54:44,409 DEBUG ++Rcv decoded: fin=1 opcode=1 data=b'{"topic":"orderbook.50.BTCUSDC","ts":1698936884324,"type":"delta","data":{"s":"BTCUSDC","b":[["34940.35","0.05724"],["34920.91","0.286361"],["34886.82","0"],["34907.31","0"]],"a":[["34948.45","0.002"],["34949.16","0.092642"],["34969.46","0.285963"],["34970.08","0.0406"],["34948.35","0"],["34969.45","0"]],"u":20010949,"seq":14108053549}}'
2023-11-02 14:54:44,429 DEBUG ++Rcv raw: b'\x81~\x00\xd5{"topic":"orderbook.50.BTCUSDC","ts":1698936884343,"type":"delta","data":{"s":"BTCUSDC","b":[["34910.05","0.45832"],["34886.83","0"]],"a":[["34969.45","0.171577"],["34970.08","0"]],"u":20010950,"seq":14108053551}}'
2023-11-02 14:54:44,429 DEBUG ++Rcv decoded: fin=1 opcode=1 data=b'{"topic":"orderbook.50.BTCUSDC","ts":1698936884343,"type":"delta","data":{"s":"BTCUSDC","b":[["34910.05","0.45832"],["34886.83","0"]],"a":[["34969.45","0.171577"],["34970.08","0"]],"u":20010950,"seq":14108053551}}'
2023-11-02 14:54:44,449 DEBUG ++Rcv raw: b'\x81~\x00\xfd{"topic":"orderbook.50.BTCUSDC","ts":1698936884363,"type":"delta","data":{"s":"BTCUSDC","b":[["34941.55","0.014049"],["34940.35","0"]],"a":[["34970.08","0.0406"],["34970.32","0.000863"],["34955.99","0"],["34969.46","0"]],"u":20010951,"seq":14108053571}}'
2023-11-02 14:54:44,449 DEBUG ++Rcv decoded: fin=1 opcode=1 data=b'{"topic":"orderbook.50.BTCUSDC","ts":1698936884363,"type":"delta","data":{"s":"BTCUSDC","b":[["34941.55","0.014049"],["34940.35","0"]],"a":[["34970.08","0.0406"],["34970.32","0.000863"],["34955.99","0"],["34969.46","0"]],"u":20010951,"seq":14108053571}}'
2023-11-02 14:54:44,469 DEBUG ++Rcv raw: b'\x81~\x00\xfd{"topic":"orderbook.50.BTCUSDC","ts":1698936884384,"type":"delta","data":{"s":"BTCUSDC","b":[["34886.83","0.209174"],["34941.55","0"]],"a":[["34955.97","0.35425"],["34970.82","0.167032"],["34969.45","0"],["34950.3","0"]],"u":20010952,"seq":14108053585}}'
2023-11-02 14:54:44,469 DEBUG ++Rcv decoded: fin=1 opcode=1 data=b'{"topic":"orderbook.50.BTCUSDC","ts":1698936884384,"type":"delta","data":{"s":"BTCUSDC","b":[["34886.83","0.209174"],["34941.55","0"]],"a":[["34955.97","0.35425"],["34970.82","0.167032"],["34969.45","0"],["34950.3","0"]],"u":20010952,"seq":14108053585}}'
2023-11-02 14:54:44,489 DEBUG ++Rcv raw: b'\x81~\x00\xec{"topic":"orderbook.50.BTCUSDC","ts":1698936884404,"type":"delta","data":{"s":"BTCUSDC","b":[["34938.57","0.014193"],["34886.83","0"]],"a":[["34953.25","0.00057"],["34957.92","0.08316"],["34970.82","0"]],"u":20010953,"seq":14108053598}}'
2023-11-02 14:54:44,489 DEBUG ++Rcv decoded: fin=1 opcode=1 data=b'{"topic":"orderbook.50.BTCUSDC","ts":1698936884404,"type":"delta","data":{"s":"BTCUSDC","b":[["34938.57","0.014193"],["34886.83","0"]],"a":[["34953.25","0.00057"],["34957.92","0.08316"],["34970.82","0"]],"u":20010953,"seq":14108053598}}'
2023-11-02 14:54:44,512 DEBUG ++Rcv raw: b'\x81~\x00\xd6{"topic":"orderbook.50.BTCUSDC","ts":1698936884424,"type":"delta","data":{"s":"BTCUSDC","b":[["34905.37","0.050823"],["34887.17","0"]],"a":[["34970.82","0.167032"],["34964.61","0"]],"u":20010954,"seq":14108053606}}'
2023-11-02 14:54:44,512 DEBUG ++Rcv decoded: fin=1 opcode=1 data=b'{"topic":"orderbook.50.BTCUSDC","ts":1698936884424,"type":"delta","data":{"s":"BTCUSDC","b":[["34905.37","0.050823"],["34887.17","0"]],"a":[["34970.82","0.167032"],["34964.61","0"]],"u":20010954,"seq":14108053606}}'
2023-11-02 14:54:44,549 DEBUG ++Rcv raw: b'\x81~\x00\xd5{"topic":"orderbook.50.BTCUSDC","ts":1698936884464,"type":"delta","data":{"s":"BTCUSDC","b":[["34887.17","0.1875"],["34886.83","0.209174"],["34920.91","0"],["34931.97","0"]],"a":[],"u":20010955,"seq":14108053652}}'
2023-11-02 14:54:44,549 DEBUG ++Rcv decoded: fin=1 opcode=1 data=b'{"topic":"orderbook.50.BTCUSDC","ts":1698936884464,"type":"delta","data":{"s":"BTCUSDC","b":[["34887.17","0.1875"],["34886.83","0.209174"],["34920.91","0"],["34931.97","0"]],"a":[],"u":20010955,"seq":14108053652}}'
2023-11-02 14:54:44,569 DEBUG ++Rcv raw: b'\x81~\x01L{"topic":"orderbook.50.BTCUSDC","ts":1698936884484,"type":"delta","data":{"s":"BTCUSDC","b":[["34941.53","0.057238"],["34933.3","0.114503"],["34922.18","0.28635"],["34890.19","0"],["34887.17","0"],["34886.83","0"]],"a":[["34951.4","0.057222"],["34967.99","0.0005"],["34970.82","0"],["34970.32","0"]],"u":20010956,"seq":14108053670}}'
2023-11-02 14:54:44,569 DEBUG ++Rcv decoded: fin=1 opcode=1 data=b'{"topic":"orderbook.50.BTCUSDC","ts":1698936884484,"type":"delta","data":{"s":"BTCUSDC","b":[["34941.53","0.057238"],["34933.3","0.114503"],["34922.18","0.28635"],["34890.19","0"],["34887.17","0"],["34886.83","0"]],"a":[["34951.4","0.057222"],["34967.99","0.0005"],["34970.82","0"],["34970.32","0"]],"u":20010956,"seq":14108053670}}'
2023-11-02 14:54:44,589 DEBUG ++Rcv raw: b'\x81~\x00\xee{"topic":"orderbook.50.BTCUSDC","ts":1698936884504,"type":"delta","data":{"s":"BTCUSDC","b":[["34946.29","0.099505"],["34942.05","0.064963"],["34933.31","0.068703"],["34891.58","0"],["34890.2","0"]],"a":[],"u":20010957,"seq":14108053684}}'
2023-11-02 14:54:44,589 DEBUG ++Rcv decoded: fin=1 opcode=1 data=b'{"topic":"orderbook.50.BTCUSDC","ts":1698936884504,"type":"delta","data":{"s":"BTCUSDC","b":[["34946.29","0.099505"],["34942.05","0.064963"],["34933.31","0.068703"],["34891.58","0"],["34890.2","0"]],"a":[],"u":20010957,"seq":14108053684}}'
2023-11-02 14:54:44,609 DEBUG ++Rcv raw: b'\x81~\x01\x00{"topic":"orderbook.50.BTCUSDC","ts":1698936884523,"type":"delta","data":{"s":"BTCUSDC","b":[["34891.58","0.1875"],["34937.16","0"]],"a":[["34948.36","0.001456"],["34949.54","0.03"],["34970.32","0.000863"],["34953.25","0"]],"u":20010958,"seq":14108053695}}'
2023-11-02 14:54:44,609 DEBUG ++Rcv decoded: fin=1 opcode=1 data=b'{"topic":"orderbook.50.BTCUSDC","ts":1698936884523,"type":"delta","data":{"s":"BTCUSDC","b":[["34891.58","0.1875"],["34937.16","0"]],"a":[["34948.36","0.001456"],["34949.54","0.03"],["34970.32","0.000863"],["34953.25","0"]],"u":20010958,"seq":14108053695}}'
2023-11-02 14:54:44,629 DEBUG ++Rcv raw: b'\x81~\x00\xc1{"topic":"orderbook.50.BTCUSDC","ts":1698936884544,"type":"delta","data":{"s":"BTCUSDC","b":[["34890.2","0.151609"],["34938","0"]],"a":[["34949.16","0.046968"]],"u":20010959,"seq":14108053725}}'
2023-11-02 14:54:44,629 DEBUG ++Rcv decoded: fin=1 opcode=1 data=b'{"topic":"orderbook.50.BTCUSDC","ts":1698936884544,"type":"delta","data":{"s":"BTCUSDC","b":[["34890.2","0.151609"],["34938","0"]],"a":[["34949.16","0.046968"]],"u":20010959,"seq":14108053725}}'
2023-11-02 14:54:44,649 DEBUG ++Rcv raw: b'\x81~\x00\xff{"topic":"orderbook.50.BTCUSDC","ts":1698936884564,"type":"delta","data":{"s":"BTCUSDC","b":[["34936.66","0.028616"],["34936.37","0.047224"],["34938.57","0"],["34938.01","0"]],"a":[["34951.49","0.028616"],["34970.32","0"]],"u":20010960,"seq":14108053739}}'
2023-11-02 14:54:44,649 DEBUG ++Rcv decoded: fin=1 opcode=1 data=b'{"topic":"orderbook.50.BTCUSDC","ts":1698936884564,"type":"delta","data":{"s":"BTCUSDC","b":[["34936.66","0.028616"],["34936.37","0.047224"],["34938.57","0"],["34938.01","0"]],"a":[["34951.49","0.028616"],["34970.32","0"]],"u":20010960,"seq":14108053739}}'
2023-11-02 14:54:44,669 DEBUG ++Rcv raw: b'\x81~\x00\xd6{"topic":"orderbook.50.BTCUSDC","ts":1698936884583,"type":"delta","data":{"s":"BTCUSDC","b":[["34890.19","1.866636"],["34928.32","0"]],"a":[["34948.35","0.028613"],["34970.08","0"]],"u":20010961,"seq":14108053750}}'
2023-11-02 14:54:44,669 DEBUG ++Rcv decoded: fin=1 opcode=1 data=b'{"topic":"orderbook.50.BTCUSDC","ts":1698936884583,"type":"delta","data":{"s":"BTCUSDC","b":[["34890.19","1.866636"],["34928.32","0"]],"a":[["34948.35","0.028613"],["34970.08","0"]],"u":20010961,"seq":14108053750}}'
2023-11-02 14:54:44,694 DEBUG ++Rcv raw: b'\x81~\x00\xac{"topic":"orderbook.50.BTCUSDC","ts":1698936884604,"type":"delta","data":{"s":"BTCUSDC","b":[["34887.17","0.1875"],["34927.28","0"]],"a":[],"u":20010962,"seq":14108053758}}'
2023-11-02 14:54:44,695 DEBUG ++Rcv decoded: fin=1 opcode=1 data=b'{"topic":"orderbook.50.BTCUSDC","ts":1698936884604,"type":"delta","data":{"s":"BTCUSDC","b":[["34887.17","0.1875"],["34927.28","0"]],"a":[],"u":20010962,"seq":14108053758}}'
2023-11-02 14:54:44,709 DEBUG ++Rcv raw: b'\x81~\x00\xc5{"topic":"orderbook.50.BTCUSDC","ts":1698936884624,"type":"delta","data":{"s":"BTCUSDC","b":[["34946.29","0.076505"]],"a":[["34948.34","0.046288"],["34967.99","0"]],"u":20010963,"seq":14108053779}}'
2023-11-02 14:54:44,710 DEBUG ++Rcv decoded: fin=1 opcode=1 data=b'{"topic":"orderbook.50.BTCUSDC","ts":1698936884624,"type":"delta","data":{"s":"BTCUSDC","b":[["34946.29","0.076505"]],"a":[["34948.34","0.046288"],["34967.99","0"]],"u":20010963,"seq":14108053779}}'
2023-11-02 14:54:44,730 DEBUG ++Rcv raw: b'\x81~\x00\xec{"topic":"orderbook.50.BTCUSDC","ts":1698936884644,"type":"delta","data":{"s":"BTCUSDC","b":[["34940.94","0.0859"],["34887.17","0"]],"a":[["34948.34","0.008756"],["34954.67","0.001456"],["34948.45","0"]],"u":20010964,"seq":14108053790}}'
2023-11-02 14:54:44,731 DEBUG ++Rcv decoded: fin=1 opcode=1 data=b'{"topic":"orderbook.50.BTCUSDC","ts":1698936884644,"type":"delta","data":{"s":"BTCUSDC","b":[["34940.94","0.0859"],["34887.17","0"]],"a":[["34948.34","0.008756"],["34954.67","0.001456"],["34948.45","0"]],"u":20010964,"seq":14108053790}}'
2023-11-02 14:54:44,749 DEBUG ++Rcv raw: b'\x81~\x00\xea{"topic":"orderbook.50.BTCUSDC","ts":1698936884664,"type":"delta","data":{"s":"BTCUSDC","b":[["34946.29","0.053505"]],"a":[["34967.99","0.0005"],["34970.08","0.0406"],["34948.35","0"],["34948.36","0"]],"u":20010965,"seq":14108053812}}'
2023-11-02 14:54:44,750 DEBUG ++Rcv decoded: fin=1 opcode=1 data=b'{"topic":"orderbook.50.BTCUSDC","ts":1698936884664,"type":"delta","data":{"s":"BTCUSDC","b":[["34946.29","0.053505"]],"a":[["34967.99","0.0005"],["34970.08","0.0406"],["34948.35","0"],["34948.36","0"]],"u":20010965,"seq":14108053812}}'
2023-11-02 14:54:44,792 DEBUG ++Rcv raw: b'\x81~\x00\xae{"topic":"orderbook.50.BTCUSDC","ts":1698936884703,"type":"delta","data":{"s":"BTCUSDC","b":[["34927.54","0.156626"],["34890.19","0"]],"a":[],"u":20010966,"seq":14108053832}}'
2023-11-02 14:54:44,793 DEBUG ++Rcv decoded: fin=1 opcode=1 data=b'{"topic":"orderbook.50.BTCUSDC","ts":1698936884703,"type":"delta","data":{"s":"BTCUSDC","b":[["34927.54","0.156626"],["34890.19","0"]],"a":[],"u":20010966,"seq":14108053832}}'
2023-11-02 14:54:44,849 DEBUG ++Rcv raw: b'\x81~\x00\xec{"topic":"orderbook.50.BTCUSDC","ts":1698936884764,"type":"delta","data":{"s":"BTCUSDC","b":[["34890.19","1.866636"],["34946.29","0"]],"a":[["34948.33","0.028613"],["34949.54","0.1159"],["34970.08","0"]],"u":20010967,"seq":14108053886}}'
2023-11-02 14:54:44,850 DEBUG ++Rcv decoded: fin=1 opcode=1 data=b'{"topic":"orderbook.50.BTCUSDC","ts":1698936884764,"type":"delta","data":{"s":"BTCUSDC","b":[["34890.19","1.866636"],["34946.29","0"]],"a":[["34948.33","0.028613"],["34949.54","0.1159"],["34970.08","0"]],"u":20010967,"seq":14108053886}}'
2023-11-02 14:54:44,869 DEBUG ++Rcv raw: b'\x81~\x01P{"topic":"orderbook.50.BTCUSDC","ts":1698936884784,"type":"delta","data":{"s":"BTCUSDC","b":[["34945.69","0.095506"],["34937.16","0.00057"],["34890.2","0"],["34890.19","0"]],"a":[["34948.32","0.008756"],["34949.16","0.09264"],["34949.54","0.03"],["34953.22","0.00057"],["34948.34","0"],["34967.99","0"]],"u":20010968,"seq":14108053905}}'
2023-11-02 14:54:44,870 DEBUG ++Rcv decoded: fin=1 opcode=1 data=b'{"topic":"orderbook.50.BTCUSDC","ts":1698936884784,"type":"delta","data":{"s":"BTCUSDC","b":[["34945.69","0.095506"],["34937.16","0.00057"],["34890.2","0"],["34890.19","0"]],"a":[["34948.32","0.008756"],["34949.16","0.09264"],["34949.54","0.03"],["34953.22","0.00057"],["34948.34","0"],["34967.99","0"]],"u":20010968,"seq":14108053905}}'
2023-11-02 14:54:44,889 DEBUG ++Rcv raw: b'\x81~\x00\xeb{"topic":"orderbook.50.BTCUSDC","ts":1698936884804,"type":"delta","data":{"s":"BTCUSDC","b":[["34890.2","0.151609"],["34937.16","0"]],"a":[["34949.16","0.046968"],["34967.99","0.0005"],["34953.22","0"]],"u":20010969,"seq":14108053930}}'
2023-11-02 14:54:44,889 DEBUG ++Rcv decoded: fin=1 opcode=1 data=b'{"topic":"orderbook.50.BTCUSDC","ts":1698936884804,"type":"delta","data":{"s":"BTCUSDC","b":[["34890.2","0.151609"],["34937.16","0"]],"a":[["34949.16","0.046968"],["34967.99","0.0005"],["34953.22","0"]],"u":20010969,"seq":14108053930}}'
2023-11-02 14:54:44,911 DEBUG ++Rcv raw: b'\x81~\x00\xac{"topic":"orderbook.50.BTCUSDC","ts":1698936884824,"type":"delta","data":{"s":"BTCUSDC","b":[["34939.43","0.04425"],["34890.2","0"]],"a":[],"u":20010970,"seq":14108053937}}'
2023-11-02 14:54:44,911 DEBUG ++Rcv decoded: fin=1 opcode=1 data=b'{"topic":"orderbook.50.BTCUSDC","ts":1698936884824,"type":"delta","data":{"s":"BTCUSDC","b":[["34939.43","0.04425"],["34890.2","0"]],"a":[],"u":20010970,"seq":14108053937}}'
2023-11-02 14:54:44,969 DEBUG ++Rcv raw: b'\x81~\x00\xac{"topic":"orderbook.50.BTCUSDC","ts":1698936884884,"type":"delta","data":{"s":"BTCUSDC","b":[],"a":[["34970.08","0.0406"],["34948.33","0"]],"u":20010971,"seq":14108053978}}'
2023-11-02 14:54:44,969 DEBUG ++Rcv decoded: fin=1 opcode=1 data=b'{"topic":"orderbook.50.BTCUSDC","ts":1698936884884,"type":"delta","data":{"s":"BTCUSDC","b":[],"a":[["34970.08","0.0406"],["34948.33","0"]],"u":20010971,"seq":14108053978}}'
2023-11-02 14:54:45,069 DEBUG ++Rcv raw: b'\x81~\x00\xae{"topic":"orderbook.50.BTCUSDC","ts":1698936884984,"type":"delta","data":{"s":"BTCUSDC","b":[],"a":[["34948.31","0.028613"],["34970.08","0"]],"u":20010972,"seq":14108054035}}'
2023-11-02 14:54:45,070 DEBUG ++Rcv decoded: fin=1 opcode=1 data=b'{"topic":"orderbook.50.BTCUSDC","ts":1698936884984,"type":"delta","data":{"s":"BTCUSDC","b":[],"a":[["34948.31","0.028613"],["34970.08","0"]],"u":20010972,"seq":14108054035}}'
2023-11-02 14:54:45,109 DEBUG ++Rcv raw: b'\x81~\x00\xc4{"topic":"orderbook.50.BTCUSDC","ts":1698936885024,"type":"delta","data":{"s":"BTCUSDC","b":[["34945.69","0.063506"]],"a":[["34948.3","0.046288"],["34948.32","0"]],"u":20010973,"seq":14108054067}}'
2023-11-02 14:54:45,109 DEBUG ++Rcv decoded: fin=1 opcode=1 data=b'{"topic":"orderbook.50.BTCUSDC","ts":1698936885024,"type":"delta","data":{"s":"BTCUSDC","b":[["34945.69","0.063506"]],"a":[["34948.3","0.046288"],["34948.32","0"]],"u":20010973,"seq":14108054067}}'
2023-11-02 14:54:45,129 DEBUG ++Rcv raw: b'\x81~\x01\x1b{"topic":"orderbook.50.BTCUSDC","ts":1698936885044,"type":"delta","data":{"s":"BTCUSDC","b":[["34945.69","0.040506"]],"a":[["34948.29","0.037532"],["34948.3","0.008756"],["34949.54","0.1159"],["34955.45","0.000829"],["34967.27","0"],["34967.99","0"]],"u":20010974,"seq":14108054077}}'
2023-11-02 14:54:45,129 DEBUG ++Rcv decoded: fin=1 opcode=1 data=b'{"topic":"orderbook.50.BTCUSDC","ts":1698936885044,"type":"delta","data":{"s":"BTCUSDC","b":[["34945.69","0.040506"]],"a":[["34948.29","0.037532"],["34948.3","0.008756"],["34949.54","0.1159"],["34955.45","0.000829"],["34967.27","0"],["34967.99","0"]],"u":20010974,"seq":14108054077}}'
2023-11-02 14:54:45,149 DEBUG ++Rcv raw: b'\x81~\x00\xeb{"topic":"orderbook.50.BTCUSDC","ts":1698936885064,"type":"delta","data":{"s":"BTCUSDC","b":[],"a":[["34949.16","0.083727"],["34967.27","0.1875"],["34967.99","0.0005"],["34954.67","0"],["34948.29","0"]],"u":20010975,"seq":14108054087}}'
2023-11-02 14:54:45,149 DEBUG ++Rcv decoded: fin=1 opcode=1 data=b'{"topic":"orderbook.50.BTCUSDC","ts":1698936885064,"type":"delta","data":{"s":"BTCUSDC","b":[],"a":[["34949.16","0.083727"],["34967.27","0.1875"],["34967.99","0.0005"],["34954.67","0"],["34948.29","0"]],"u":20010975,"seq":14108054087}}'
2023-11-02 14:54:45,170 DEBUG ++Rcv raw: b'\x81~\x01\xb0{"topic":"orderbook.50.BTCUSDC","ts":1698936885084,"type":"delta","data":{"s":"BTCUSDC","b":[["34942","0.0324"],["34935.19","0.1875"],["34890.2","0.151609"],["34890.19","1.866636"],["34887.17","0.1875"],["34886.83","0.209174"],["34933.3","0"],["34945.69","0"],["34941.53","0"],["34910.05","0"],["34922.18","0"]],"a":[["34948.26","0.097706"],["34949.53","0.091779"],["34949.16","0"],["34959.28","0"]],"u":20010976,"seq":14108054129}}'
2023-11-02 14:54:45,171 DEBUG ++Rcv decoded: fin=1 opcode=1 data=b'{"topic":"orderbook.50.BTCUSDC","ts":1698936885084,"type":"delta","data":{"s":"BTCUSDC","b":[["34942","0.0324"],["34935.19","0.1875"],["34890.2","0.151609"],["34890.19","1.866636"],["34887.17","0.1875"],["34886.83","0.209174"],["34933.3","0"],["34945.69","0"],["34941.53","0"],["34910.05","0"],["34922.18","0"]],"a":[["34948.26","0.097706"],["34949.53","0.091779"],["34949.16","0"],["34959.28","0"]],"u":20010976,"seq":14108054129}}'
2023-11-02 14:54:45,188 DEBUG ++Rcv raw: b'\x81~\x02u{"topic":"orderbook.50.BTCUSDC","ts":1698936885103,"type":"delta","data":{"s":"BTCUSDC","b":[["34940.95","0.051549"],["34940.77","0.057239"],["34938","0.0324"],["34937.16","0.00057"],["34935.2","0.1125"],["34930.8","0.114512"],["34918.65","0.286379"],["34906.88","0.458362"],["34933.31","0"],["34939.43","0"],["34890.19","0"],["34887.17","0"],["34886.83","0"],["34942.05","0"],["34935.19","0"],["34890.2","0"]],"a":[["34948.25","0.008756"],["34949.54","0.0859"],["34953.15","0.00057"],["34961.74","0.11441"],["34962.85","0.001"],["34967.27","0"],["34948.3","0"],["34967.99","0"],["34948.26","0"]],"u":20010977,"seq":14108054161}}'
2023-11-02 14:54:45,189 DEBUG ++Rcv decoded: fin=1 opcode=1 data=b'{"topic":"orderbook.50.BTCUSDC","ts":1698936885103,"type":"delta","data":{"s":"BTCUSDC","b":[["34940.95","0.051549"],["34940.77","0.057239"],["34938","0.0324"],["34937.16","0.00057"],["34935.2","0.1125"],["34930.8","0.114512"],["34918.65","0.286379"],["34906.88","0.458362"],["34933.31","0"],["34939.43","0"],["34890.19","0"],["34887.17","0"],["34886.83","0"],["34942.05","0"],["34935.19","0"],["34890.2","0"]],"a":[["34948.25","0.008756"],["34949.54","0.0859"],["34953.15","0.00057"],["34961.74","0.11441"],["34962.85","0.001"],["34967.27","0"],["34948.3","0"],["34967.99","0"],["34948.26","0"]],"u":20010977,"seq":14108054161}}'
2023-11-02 14:54:45,209 DEBUG ++Rcv raw: b'\x81~\x00\xfc{"topic":"orderbook.50.BTCUSDC","ts":1698936885124,"type":"delta","data":{"s":"BTCUSDC","b":[["34927.55","0.112501"],["34916.85","0.062573"],["34935.2","0"],["34891.58","0"]],"a":[["34967.27","0.1875"],["34948.31","0"]],"u":20010978,"seq":14108054174}}'
2023-11-02 14:54:45,210 DEBUG ++Rcv decoded: fin=1 opcode=1 data=b'{"topic":"orderbook.50.BTCUSDC","ts":1698936885124,"type":"delta","data":{"s":"BTCUSDC","b":[["34927.55","0.112501"],["34916.85","0.062573"],["34935.2","0"],["34891.58","0"]],"a":[["34967.27","0.1875"],["34948.31","0"]],"u":20010978,"seq":14108054174}}'
2023-11-02 14:54:45,249 DEBUG ++Rcv raw: b'\x81~\x00\xae{"topic":"orderbook.50.BTCUSDC","ts":1698936885163,"type":"delta","data":{"s":"BTCUSDC","b":[["34938.47","0.014032"],["34891.59","0"]],"a":[],"u":20010979,"seq":14108054205}}'
2023-11-02 14:54:45,249 DEBUG ++Rcv decoded: fin=1 opcode=1 data=b'{"topic":"orderbook.50.BTCUSDC","ts":1698936885163,"type":"delta","data":{"s":"BTCUSDC","b":[["34938.47","0.014032"],["34891.59","0"]],"a":[],"u":20010979,"seq":14108054205}}'
2023-11-02 14:54:45,309 DEBUG ++Rcv raw: b'\x81~\x00\xd3{"topic":"orderbook.50.BTCUSDC","ts":1698936885224,"type":"delta","data":{"s":"BTCUSDC","b":[["34891.59","0.112505"],["34942","0"]],"a":[["34948.24","0.028613"],["34967.27","0"]],"u":20010980,"seq":14108054243}}'
2023-11-02 14:54:45,309 DEBUG ++Rcv decoded: fin=1 opcode=1 data=b'{"topic":"orderbook.50.BTCUSDC","ts":1698936885224,"type":"delta","data":{"s":"BTCUSDC","b":[["34891.59","0.112505"],["34942","0"]],"a":[["34948.24","0.028613"],["34967.27","0"]],"u":20010980,"seq":14108054243}}'
2023-11-02 14:54:45,329 DEBUG ++Rcv raw: b'\x81~\x00\x9d{"topic":"orderbook.50.BTCUSDC","ts":1698936885244,"type":"delta","data":{"s":"BTCUSDC","b":[],"a":[["34948.24","0.058613"]],"u":20010981,"seq":14108054268}}'
2023-11-02 14:54:45,329 DEBUG ++Rcv decoded: fin=1 opcode=1 data=b'{"topic":"orderbook.50.BTCUSDC","ts":1698936885244,"type":"delta","data":{"s":"BTCUSDC","b":[],"a":[["34948.24","0.058613"]],"u":20010981,"seq":14108054268}}'
2023-11-02 14:54:45,349 DEBUG ++Rcv raw: b'\x81~\x00\xff{"topic":"orderbook.50.BTCUSDC","ts":1698936885263,"type":"delta","data":{"s":"BTCUSDC","b":[["34927.56","0.003561"],["34931.53","0"]],"a":[["34948.23","0.008756"],["34954.67","0.001456"],["34955.45","0"],["34948.25","0"]],"u":20010982,"seq":14108054287}}'
2023-11-02 14:54:45,349 DEBUG ++Rcv decoded: fin=1 opcode=1 data=b'{"topic":"orderbook.50.BTCUSDC","ts":1698936885263,"type":"delta","data":{"s":"BTCUSDC","b":[["34927.56","0.003561"],["34931.53","0"]],"a":[["34948.23","0.008756"],["34954.67","0.001456"],["34955.45","0"],["34948.25","0"]],"u":20010982,"seq":14108054287}}'
2023-11-02 14:54:45,369 DEBUG ++Rcv raw: b'\x81~\x00\xd1{"topic":"orderbook.50.BTCUSDC","ts":1698936885283,"type":"delta","data":{"s":"BTCUSDC","b":[["34891.58","0.1875"],["34940.77","0"]],"a":[["34951.11","0.028"],["34967.26","0"]],"u":20010983,"seq":14108054299}}'
2023-11-02 14:54:45,369 DEBUG ++Rcv decoded: fin=1 opcode=1 data=b'{"topic":"orderbook.50.BTCUSDC","ts":1698936885283,"type":"delta","data":{"s":"BTCUSDC","b":[["34891.58","0.1875"],["34940.77","0"]],"a":[["34951.11","0.028"],["34967.26","0"]],"u":20010983,"seq":14108054299}}'
2023-11-02 14:54:45,389 DEBUG ++Rcv raw: b'\x81~\x00\xd3{"topic":"orderbook.50.BTCUSDC","ts":1698936885303,"type":"delta","data":{"s":"BTCUSDC","b":[["34940.01","0.05724"],["34937.5","0.0859"],["34891.59","0"],["34891.58","0"]],"a":[],"u":20010984,"seq":14108054308}}'
2023-11-02 14:54:45,389 DEBUG ++Rcv decoded: fin=1 opcode=1 data=b'{"topic":"orderbook.50.BTCUSDC","ts":1698936885303,"type":"delta","data":{"s":"BTCUSDC","b":[["34940.01","0.05724"],["34937.5","0.0859"],["34891.59","0"],["34891.58","0"]],"a":[],"u":20010984,"seq":14108054308}}'
2023-11-02 14:54:45,409 DEBUG ++Rcv raw: b'\x81~\x01T{"topic":"orderbook.50.BTCUSDC","ts":1698936885324,"type":"delta","data":{"s":"BTCUSDC","b":[["34943.87","0.098524"],["34938.03","0.051544"],["34936.37","0.026555"],["34893.07","0"],["34896.88","0"]],"a":[["34947.37","0.008756"],["34947.38","0.109008"],["34948.24","0.03"],["34948.23","0"],["34966.13","0"]],"u":20010985,"seq":14108054323}}'
2023-11-02 14:54:45,409 DEBUG ++Rcv decoded: fin=1 opcode=1 data=b'{"topic":"orderbook.50.BTCUSDC","ts":1698936885324,"type":"delta","data":{"s":"BTCUSDC","b":[["34943.87","0.098524"],["34938.03","0.051544"],["34936.37","0.026555"],["34893.07","0"],["34896.88","0"]],"a":[["34947.37","0.008756"],["34947.38","0.109008"],["34948.24","0.03"],["34948.23","0"],["34966.13","0"]],"u":20010985,"seq":14108054323}}'
2023-11-02 14:54:45,430 DEBUG ++Rcv raw: b'\x81~\x00\xde{"topic":"orderbook.50.BTCUSDC","ts":1698936885344,"type":"delta","data":{"s":"BTCUSDC","b":[],"a":[["34947.37","0.038756"],["34947.38","0.048413"],["34966.13","0.022371"],["34949.55","0"]],"u":20010986,"seq":14108054333}}'
2023-11-02 14:54:45,431 DEBUG ++Rcv decoded: fin=1 opcode=1 data=b'{"topic":"orderbook.50.BTCUSDC","ts":1698936885344,"type":"delta","data":{"s":"BTCUSDC","b":[],"a":[["34947.37","0.038756"],["34947.38","0.048413"],["34966.13","0.022371"],["34949.55","0"]],"u":20010986,"seq":14108054333}}'
2023-11-02 14:54:45,448 DEBUG ++Rcv raw: b'\x81~\x00\xec{"topic":"orderbook.50.BTCUSDC","ts":1698936885363,"type":"delta","data":{"s":"BTCUSDC","b":[["34896.88","0.1875"],["34893.07","0.028602"],["34938.47","0"],["34940.01","0"]],"a":[["34949.53","0.051546"]],"u":20010987,"seq":14108054355}}'
2023-11-02 14:54:45,449 DEBUG ++Rcv decoded: fin=1 opcode=1 data=b'{"topic":"orderbook.50.BTCUSDC","ts":1698936885363,"type":"delta","data":{"s":"BTCUSDC","b":[["34896.88","0.1875"],["34893.07","0.028602"],["34938.47","0"],["34940.01","0"]],"a":[["34949.53","0.051546"]],"u":20010987,"seq":14108054355}}'
2023-11-02 14:54:45,489 DEBUG ++Rcv raw: b'\x81~\x00\xac{"topic":"orderbook.50.BTCUSDC","ts":1698936885403,"type":"delta","data":{"s":"BTCUSDC","b":[],"a":[["34959.99","0.0005"],["34966.13","0"]],"u":20010988,"seq":14108054391}}'
2023-11-02 14:54:45,489 DEBUG ++Rcv decoded: fin=1 opcode=1 data=b'{"topic":"orderbook.50.BTCUSDC","ts":1698936885403,"type":"delta","data":{"s":"BTCUSDC","b":[],"a":[["34959.99","0.0005"],["34966.13","0"]],"u":20010988,"seq":14108054391}}'
2023-11-02 14:54:45,529 DEBUG ++Rcv raw: b'\x81~\x00\xae{"topic":"orderbook.50.BTCUSDC","ts":1698936885443,"type":"delta","data":{"s":"BTCUSDC","b":[["34934.62","0.041899"],["34893.07","0"]],"a":[],"u":20010989,"seq":14108054426}}'
2023-11-02 14:54:45,529 DEBUG ++Rcv decoded: fin=1 opcode=1 data=b'{"topic":"orderbook.50.BTCUSDC","ts":1698936885443,"type":"delta","data":{"s":"BTCUSDC","b":[["34934.62","0.041899"],["34893.07","0"]],"a":[],"u":20010989,"seq":14108054426}}'
2023-11-02 14:54:45,629 DEBUG ++Rcv raw: b'\x81~\x00\xd7{"topic":"orderbook.50.BTCUSDC","ts":1698936885544,"type":"delta","data":{"s":"BTCUSDC","b":[["34931.53","0.003561"],["34927.08","0.000261"],["34896.94","0"],["34896.88","0"]],"a":[],"u":20010990,"seq":14108054520}}'
2023-11-02 14:54:45,629 DEBUG ++Rcv decoded: fin=1 opcode=1 data=b'{"topic":"orderbook.50.BTCUSDC","ts":1698936885544,"type":"delta","data":{"s":"BTCUSDC","b":[["34931.53","0.003561"],["34927.08","0.000261"],["34896.94","0"],["34896.88","0"]],"a":[],"u":20010990,"seq":14108054520}}'
2023-11-02 14:54:45,650 DEBUG ++Rcv raw: b'\x81~\x00\xfa{"topic":"orderbook.50.BTCUSDC","ts":1698936885564,"type":"delta","data":{"s":"BTCUSDC","b":[["34934.06","0.0859"],["34927.56","0"]],"a":[["34948.22","0.028613"],["34955.45","0.000798"],["34965.02","0"],["34966","0"]],"u":20010991,"seq":14108054532}}'
2023-11-02 14:54:45,650 DEBUG ++Rcv decoded: fin=1 opcode=1 data=b'{"topic":"orderbook.50.BTCUSDC","ts":1698936885564,"type":"delta","data":{"s":"BTCUSDC","b":[["34934.06","0.0859"],["34927.56","0"]],"a":[["34948.22","0.028613"],["34955.45","0.000798"],["34965.02","0"],["34966","0"]],"u":20010991,"seq":14108054532}}'
2023-11-02 14:54:45,670 DEBUG ++Rcv raw: b'\x81~\x00\xd4{"topic":"orderbook.50.BTCUSDC","ts":1698936885584,"type":"delta","data":{"s":"BTCUSDC","b":[["34934.63","0.051547"],["34896.95","0"]],"a":[["34965.02","0.0859"],["34954.67","0"]],"u":20010992,"seq":14108054544}}'
2023-11-02 14:54:45,671 DEBUG ++Rcv decoded: fin=1 opcode=1 data=b'{"topic":"orderbook.50.BTCUSDC","ts":1698936885584,"type":"delta","data":{"s":"BTCUSDC","b":[["34934.63","0.051547"],["34896.95","0"]],"a":[["34965.02","0.0859"],["34954.67","0"]],"u":20010992,"seq":14108054544}}'
2023-11-02 14:54:45,690 DEBUG ++Rcv raw: b'\x81~\x01\x18{"topic":"orderbook.50.BTCUSDC","ts":1698936885604,"type":"delta","data":{"s":"BTCUSDC","b":[["34945.6","0.107126"],["34939.34","0.04425"],["34935.1","0.1875"],["34900","0"],["34899","0"],["34943.87","0"]],"a":[["34966","0.0324"],["34955.46","0"]],"u":20010993,"seq":14108054563}}'
2023-11-02 14:54:45,690 DEBUG ++Rcv decoded: fin=1 opcode=1 data=b'{"topic":"orderbook.50.BTCUSDC","ts":1698936885604,"type":"delta","data":{"s":"BTCUSDC","b":[["34945.6","0.107126"],["34939.34","0.04425"],["34935.1","0.1875"],["34900","0"],["34899","0"],["34943.87","0"]],"a":[["34966","0.0324"],["34955.46","0"]],"u":20010993,"seq":14108054563}}'
2023-11-02 14:54:45,709 DEBUG ++Rcv raw: b'\x81~\x01\x12{"topic":"orderbook.50.BTCUSDC","ts":1698936885624,"type":"delta","data":{"s":"BTCUSDC","b":[["34935.11","0.112508"],["34900","0.0002"],["34937.16","0"],["34934.63","0"]],"a":[["34947.37","0.008756"],["34966.13","0.022371"],["34953.15","0"]],"u":20010994,"seq":14108054573}}'
2023-11-02 14:54:45,709 DEBUG ++Rcv decoded: fin=1 opcode=1 data=b'{"topic":"orderbook.50.BTCUSDC","ts":1698936885624,"type":"delta","data":{"s":"BTCUSDC","b":[["34935.11","0.112508"],["34900","0.0002"],["34937.16","0"],["34934.63","0"]],"a":[["34947.37","0.008756"],["34966.13","0.022371"],["34953.15","0"]],"u":20010994,"seq":14108054573}}'
2023-11-02 14:54:45,789 DEBUG ++Rcv raw: b'\x81~\x00\xd0{"topic":"orderbook.50.BTCUSDC","ts":1698936885704,"type":"delta","data":{"s":"BTCUSDC","b":[["34932.88","0.00026"],["34900","0"]],"a":[["34967.26","0.1125"],["34947.37","0"]],"u":20010995,"seq":14108054606}}'
2023-11-02 14:54:45,789 DEBUG ++Rcv decoded: fin=1 opcode=1 data=b'{"topic":"orderbook.50.BTCUSDC","ts":1698936885704,"type":"delta","data":{"s":"BTCUSDC","b":[["34932.88","0.00026"],["34900","0"]],"a":[["34967.26","0.1125"],["34947.37","0"]],"u":20010995,"seq":14108054606}}'
2023-11-02 14:54:45,909 DEBUG ++Rcv raw: b'\x81~\x00\xf8{"topic":"orderbook.50.BTCUSDC","ts":1698936885824,"type":"delta","data":{"s":"BTCUSDC","b":[["34928.9","0.0859"],["34901.18","0"]],"a":[["34967.27","0.1875"],["34970.08","0.0406"],["34948.22","0"],["34962.85","0"]],"u":20010996,"seq":14108054643}}'
2023-11-02 14:54:45,909 DEBUG ++Rcv decoded: fin=1 opcode=1 data=b'{"topic":"orderbook.50.BTCUSDC","ts":1698936885824,"type":"delta","data":{"s":"BTCUSDC","b":[["34928.9","0.0859"],["34901.18","0"]],"a":[["34967.27","0.1875"],["34970.08","0.0406"],["34948.22","0"],["34962.85","0"]],"u":20010996,"seq":14108054643}}'
2023-11-02 14:54:45,929 DEBUG ++Rcv raw: b'\x81~\x00\xae{"topic":"orderbook.50.BTCUSDC","ts":1698936885844,"type":"delta","data":{"s":"BTCUSDC","b":[["34928.91","0.051549"],["34904.94","0"]],"a":[],"u":20010997,"seq":14108054646}}'
2023-11-02 14:54:45,929 DEBUG ++Rcv decoded: fin=1 opcode=1 data=b'{"topic":"orderbook.50.BTCUSDC","ts":1698936885844,"type":"delta","data":{"s":"BTCUSDC","b":[["34928.91","0.051549"],["34904.94","0"]],"a":[],"u":20010997,"seq":14108054646}}'
2023-11-02 14:54:45,949 DEBUG ++Rcv raw: b'\x81~\x01\x00{"topic":"orderbook.50.BTCUSDC","ts":1698936885864,"type":"delta","data":{"s":"BTCUSDC","b":[["34940.95","0.073963"],["34904.94","0.155893"],["34945.6","0"]],"a":[["34962","0.0324"],["34970.32","0.000863"],["34966.13","0"]],"u":20010998,"seq":14108054660}}'
2023-11-02 14:54:45,950 DEBUG ++Rcv decoded: fin=1 opcode=1 data=b'{"topic":"orderbook.50.BTCUSDC","ts":1698936885864,"type":"delta","data":{"s":"BTCUSDC","b":[["34940.95","0.073963"],["34904.94","0.155893"],["34945.6","0"]],"a":[["34962","0.0324"],["34970.32","0.000863"],["34966.13","0"]],"u":20010998,"seq":14108054660}}'
2023-11-02 14:54:45,969 DEBUG ++Rcv raw: b'\x81~\x01\x15{"topic":"orderbook.50.BTCUSDC","ts":1698936885883,"type":"delta","data":{"s":"BTCUSDC","b":[["34940.96","0.080541"],["34940.95","0.048336"],["34936.06","0.00057"],["34939.34","0"],["34935.1","0"]],"a":[["34947.37","0.008756"],["34970.32","0"]],"u":20010999,"seq":14108054672}}'
2023-11-02 14:54:45,969 DEBUG ++Rcv decoded: fin=1 opcode=1 data=b'{"topic":"orderbook.50.BTCUSDC","ts":1698936885883,"type":"delta","data":{"s":"BTCUSDC","b":[["34940.96","0.080541"],["34940.95","0.048336"],["34936.06","0.00057"],["34939.34","0"],["34935.1","0"]],"a":[["34947.37","0.008756"],["34970.32","0"]],"u":20010999,"seq":14108054672}}'
2023-11-02 14:54:45,990 DEBUG ++Rcv raw: b'\x81~\x00\xd5{"topic":"orderbook.50.BTCUSDC","ts":1698936885903,"type":"delta","data":{"s":"BTCUSDC","b":[["34934.63","0.051541"],["34935.11","0"]],"a":[["34952.27","0.00057"],["34970.08","0"]],"u":20011000,"seq":14108054676}}'
2023-11-02 14:54:45,990 DEBUG ++Rcv decoded: fin=1 opcode=1 data=b'{"topic":"orderbook.50.BTCUSDC","ts":1698936885903,"type":"delta","data":{"s":"BTCUSDC","b":[["34934.63","0.051541"],["34935.11","0"]],"a":[["34952.27","0.00057"],["34970.08","0"]],"u":20011000,"seq":14108054676}}'
2023-11-02 14:54:46,009 DEBUG ++Rcv raw: b'\x81~\x00\xc4{"topic":"orderbook.50.BTCUSDC","ts":1698936885924,"type":"delta","data":{"s":"BTCUSDC","b":[["34938.46","0.014556"],["34904.94","0"]],"a":[["34947.37","0.03737"]],"u":20011001,"seq":14108054685}}'
2023-11-02 14:54:46,009 DEBUG ++Rcv decoded: fin=1 opcode=1 data=b'{"topic":"orderbook.50.BTCUSDC","ts":1698936885924,"type":"delta","data":{"s":"BTCUSDC","b":[["34938.46","0.014556"],["34904.94","0"]],"a":[["34947.37","0.03737"]],"u":20011001,"seq":14108054685}}'
2023-11-02 14:54:46,029 DEBUG ++Rcv raw: b'\x81~\x00\xd7{"topic":"orderbook.50.BTCUSDC","ts":1698936885943,"type":"delta","data":{"s":"BTCUSDC","b":[],"a":[["34955.96","0.001293"],["34957.93","0.043087"],["34967.27","0"],["34967.26","0"]],"u":20011002,"seq":14108054693}}'
2023-11-02 14:54:46,029 DEBUG ++Rcv decoded: fin=1 opcode=1 data=b'{"topic":"orderbook.50.BTCUSDC","ts":1698936885943,"type":"delta","data":{"s":"BTCUSDC","b":[],"a":[["34955.96","0.001293"],["34957.93","0.043087"],["34967.27","0"],["34967.26","0"]],"u":20011002,"seq":14108054693}}'
2023-11-02 14:54:46,049 DEBUG ++Rcv raw: b'\x81~\x00\xae{"topic":"orderbook.50.BTCUSDC","ts":1698936885963,"type":"delta","data":{"s":"BTCUSDC","b":[],"a":[["34950.82","0.022773"],["34955.45","0"]],"u":20011003,"seq":14108054702}}'
2023-11-02 14:54:46,049 DEBUG ++Rcv decoded: fin=1 opcode=1 data=b'{"topic":"orderbook.50.BTCUSDC","ts":1698936885963,"type":"delta","data":{"s":"BTCUSDC","b":[],"a":[["34950.82","0.022773"],["34955.45","0"]],"u":20011003,"seq":14108054702}}'
2023-11-02 14:54:46,069 DEBUG ++Rcv raw: b'\x81~\x00\xae{"topic":"orderbook.50.BTCUSDC","ts":1698936885984,"type":"delta","data":{"s":"BTCUSDC","b":[["34904.94","0.155893"],["34927.08","0"]],"a":[],"u":20011004,"seq":14108054705}}'
2023-11-02 14:54:46,069 DEBUG ++Rcv decoded: fin=1 opcode=1 data=b'{"topic":"orderbook.50.BTCUSDC","ts":1698936885984,"type":"delta","data":{"s":"BTCUSDC","b":[["34904.94","0.155893"],["34927.08","0"]],"a":[],"u":20011004,"seq":14108054705}}'
2023-11-02 14:54:46,112 DEBUG ++Rcv raw: b'\x81~\x00\x9d{"topic":"orderbook.50.BTCUSDC","ts":1698936886024,"type":"delta","data":{"s":"BTCUSDC","b":[],"a":[["34959.85","0.113507"]],"u":20011005,"seq":14108054711}}'
2023-11-02 14:54:46,112 DEBUG ++Rcv decoded: fin=1 opcode=1 data=b'{"topic":"orderbook.50.BTCUSDC","ts":1698936886024,"type":"delta","data":{"s":"BTCUSDC","b":[],"a":[["34959.85","0.113507"]],"u":20011005,"seq":14108054711}}'
2023-11-02 14:54:46,169 DEBUG ++Rcv raw: b'\x81~\x00\xd4{"topic":"orderbook.50.BTCUSDC","ts":1698936886084,"type":"delta","data":{"s":"BTCUSDC","b":[["34945.4","0.089194"],["34930.62","0.0859"],["34904.94","0"],["34905.37","0"]],"a":[],"u":20011006,"seq":14108054728}}'
2023-11-02 14:54:46,169 DEBUG ++Rcv decoded: fin=1 opcode=1 data=b'{"topic":"orderbook.50.BTCUSDC","ts":1698936886084,"type":"delta","data":{"s":"BTCUSDC","b":[["34945.4","0.089194"],["34930.62","0.0859"],["34904.94","0"],["34905.37","0"]],"a":[],"u":20011006,"seq":14108054728}}'
2023-11-02 14:54:46,189 DEBUG ++Rcv raw: b'\x81~\x00\xd3{"topic":"orderbook.50.BTCUSDC","ts":1698936886104,"type":"delta","data":{"s":"BTCUSDC","b":[["34934.9","0.1875"],["34936.06","0"]],"a":[["34966.94","0.025967"],["34952.27","0"]],"u":20011007,"seq":14108054740}}'
2023-11-02 14:54:46,189 DEBUG ++Rcv decoded: fin=1 opcode=1 data=b'{"topic":"orderbook.50.BTCUSDC","ts":1698936886104,"type":"delta","data":{"s":"BTCUSDC","b":[["34934.9","0.1875"],["34936.06","0"]],"a":[["34966.94","0.025967"],["34952.27","0"]],"u":20011007,"seq":14108054740}}'
2023-11-02 14:54:46,211 DEBUG ++Rcv raw: b'\x81~\x00\xf9{"topic":"orderbook.50.BTCUSDC","ts":1698936886123,"type":"delta","data":{"s":"BTCUSDC","b":[["34934.91","0.112502"],["34901.18","0.1875"],["34900","0.0002"],["34916.85","0"],["34915.44","0"],["34934.63","0"]],"a":[],"u":20011008,"seq":14108054748}}'
2023-11-02 14:54:46,211 DEBUG ++Rcv decoded: fin=1 opcode=1 data=b'{"topic":"orderbook.50.BTCUSDC","ts":1698936886123,"type":"delta","data":{"s":"BTCUSDC","b":[["34934.91","0.112502"],["34901.18","0.1875"],["34900","0.0002"],["34916.85","0"],["34915.44","0"],["34934.63","0"]],"a":[],"u":20011008,"seq":14108054748}}'
2023-11-02 14:54:46,228 DEBUG ++Rcv raw: b'\x81~\x00\xd0{"topic":"orderbook.50.BTCUSDC","ts":1698936886143,"type":"delta","data":{"s":"BTCUSDC","b":[["34934.92","0.00162"],["34931.11","0.028"],["34901.18","0"],["34900","0"]],"a":[],"u":20011009,"seq":14108054760}}'
2023-11-02 14:54:46,229 DEBUG ++Rcv decoded: fin=1 opcode=1 data=b'{"topic":"orderbook.50.BTCUSDC","ts":1698936886143,"type":"delta","data":{"s":"BTCUSDC","b":[["34934.92","0.00162"],["34931.11","0.028"],["34901.18","0"],["34900","0"]],"a":[],"u":20011009,"seq":14108054760}}'
2023-11-02 14:54:46,249 DEBUG ++Rcv raw: b'\x81~\x00\xac{"topic":"orderbook.50.BTCUSDC","ts":1698936886163,"type":"delta","data":{"s":"BTCUSDC","b":[["34901.18","0.1875"],["34931.53","0"]],"a":[],"u":20011010,"seq":14108054769}}'
2023-11-02 14:54:46,249 DEBUG ++Rcv decoded: fin=1 opcode=1 data=b'{"topic":"orderbook.50.BTCUSDC","ts":1698936886163,"type":"delta","data":{"s":"BTCUSDC","b":[["34901.18","0.1875"],["34931.53","0"]],"a":[],"u":20011010,"seq":14108054769}}'
2023-11-02 14:54:46,309 DEBUG ++Rcv raw: b'\x81~\x00\xd6{"topic":"orderbook.50.BTCUSDC","ts":1698936886223,"type":"delta","data":{"s":"BTCUSDC","b":[["34914.71","0.119966"],["34901.18","0"]],"a":[["34961.11","0.074198"],["34966.94","0"]],"u":20011011,"seq":14108054817}}'
2023-11-02 14:54:46,309 DEBUG ++Rcv decoded: fin=1 opcode=1 data=b'{"topic":"orderbook.50.BTCUSDC","ts":1698936886223,"type":"delta","data":{"s":"BTCUSDC","b":[["34914.71","0.119966"],["34901.18","0"]],"a":[["34961.11","0.074198"],["34966.94","0"]],"u":20011011,"seq":14108054817}}'
2023-11-02 14:54:46,329 DEBUG ++Rcv raw: b'\x81~\x00\xae{"topic":"orderbook.50.BTCUSDC","ts":1698936886244,"type":"delta","data":{"s":"BTCUSDC","b":[],"a":[["34966.94","0.025967"],["34955.96","0"]],"u":20011012,"seq":14108054819}}'
2023-11-02 14:54:46,329 DEBUG ++Rcv decoded: fin=1 opcode=1 data=b'{"topic":"orderbook.50.BTCUSDC","ts":1698936886244,"type":"delta","data":{"s":"BTCUSDC","b":[],"a":[["34966.94","0.025967"],["34955.96","0"]],"u":20011012,"seq":14108054819}}'
2023-11-02 14:54:46,369 DEBUG ++Rcv raw: b'\x81~\x00\xae{"topic":"orderbook.50.BTCUSDC","ts":1698936886284,"type":"delta","data":{"s":"BTCUSDC","b":[["34904.21","0.204079"],["34932.88","0"]],"a":[],"u":20011013,"seq":14108054838}}'
2023-11-02 14:54:46,369 DEBUG ++Rcv decoded: fin=1 opcode=1 data=b'{"topic":"orderbook.50.BTCUSDC","ts":1698936886284,"type":"delta","data":{"s":"BTCUSDC","b":[["34904.21","0.204079"],["34932.88","0"]],"a":[],"u":20011013,"seq":14108054838}}'
2023-11-02 14:54:46,430 DEBUG ++Rcv raw: b'\x81~\x00\xac{"topic":"orderbook.50.BTCUSDC","ts":1698936886344,"type":"delta","data":{"s":"BTCUSDC","b":[["34932.34","0.0859"],["34904.21","0"]],"a":[],"u":20011014,"seq":14108054841}}'
2023-11-02 14:54:46,430 DEBUG ++Rcv decoded: fin=1 opcode=1 data=b'{"topic":"orderbook.50.BTCUSDC","ts":1698936886344,"type":"delta","data":{"s":"BTCUSDC","b":[["34932.34","0.0859"],["34904.21","0"]],"a":[],"u":20011014,"seq":14108054841}}'
2023-11-02 14:54:46,449 DEBUG ++Rcv raw: b'\x81~\x00\xae{"topic":"orderbook.50.BTCUSDC","ts":1698936886364,"type":"delta","data":{"s":"BTCUSDC","b":[["34932.35","0.051543"],["34905.97","0"]],"a":[],"u":20011015,"seq":14108054846}}'
2023-11-02 14:54:46,450 DEBUG ++Rcv decoded: fin=1 opcode=1 data=b'{"topic":"orderbook.50.BTCUSDC","ts":1698936886364,"type":"delta","data":{"s":"BTCUSDC","b":[["34932.35","0.051543"],["34905.97","0"]],"a":[],"u":20011015,"seq":14108054846}}'
2023-11-02 14:54:46,469 DEBUG ++Rcv raw: b'\x81~\x00\xab{"topic":"orderbook.50.BTCUSDC","ts":1698936886383,"type":"delta","data":{"s":"BTCUSDC","b":[["34905.97","0.1875"],["34945.4","0"]],"a":[],"u":20011016,"seq":14108054854}}'
2023-11-02 14:54:46,469 DEBUG ++Rcv decoded: fin=1 opcode=1 data=b'{"topic":"orderbook.50.BTCUSDC","ts":1698936886383,"type":"delta","data":{"s":"BTCUSDC","b":[["34905.97","0.1875"],["34945.4","0"]],"a":[],"u":20011016,"seq":14108054854}}'
2023-11-02 14:54:46,491 DEBUG ++Rcv raw: b'\x81~\x00\xf7{"topic":"orderbook.50.BTCUSDC","ts":1698936886403,"type":"delta","data":{"s":"BTCUSDC","b":[["34936.07","0.00057"],["34934.9","0"]],"a":[["34952.26","0.00057"],["34954.37","0.1875"],["34966","0"],["34966.94","0"]],"u":20011017,"seq":14108054861}}'
2023-11-02 14:54:46,491 DEBUG ++Rcv decoded: fin=1 opcode=1 data=b'{"topic":"orderbook.50.BTCUSDC","ts":1698936886403,"type":"delta","data":{"s":"BTCUSDC","b":[["34936.07","0.00057"],["34934.9","0"]],"a":[["34952.26","0.00057"],["34954.37","0.1875"],["34966","0"],["34966.94","0"]],"u":20011017,"seq":14108054861}}'
2023-11-02 14:54:46,510 DEBUG ++Rcv raw: b'\x81~\x00\xff{"topic":"orderbook.50.BTCUSDC","ts":1698936886425,"type":"delta","data":{"s":"BTCUSDC","b":[["34934.63","0.051544"],["34904.21","0.204079"],["34932.35","0"],["34934.91","0"]],"a":[["34954.36","0.112505"],["34954.68","0"]],"u":20011018,"seq":14108054868}}'
2023-11-02 14:54:46,511 DEBUG ++Rcv decoded: fin=1 opcode=1 data=b'{"topic":"orderbook.50.BTCUSDC","ts":1698936886425,"type":"delta","data":{"s":"BTCUSDC","b":[["34934.63","0.051544"],["34904.21","0.204079"],["34932.35","0"],["34934.91","0"]],"a":[["34954.36","0.112505"],["34954.68","0"]],"u":20011018,"seq":14108054868}}'
2023-11-02 14:54:46,529 DEBUG ++Rcv raw: b'\x81~\x00\xae{"topic":"orderbook.50.BTCUSDC","ts":1698936886443,"type":"delta","data":{"s":"BTCUSDC","b":[["34931.53","0.002675"],["34904.21","0"]],"a":[],"u":20011019,"seq":14108054891}}'
2023-11-02 14:54:46,530 DEBUG ++Rcv decoded: fin=1 opcode=1 data=b'{"topic":"orderbook.50.BTCUSDC","ts":1698936886443,"type":"delta","data":{"s":"BTCUSDC","b":[["34931.53","0.002675"],["34904.21","0"]],"a":[],"u":20011019,"seq":14108054891}}'
2023-11-02 14:54:46,550 DEBUG ++Rcv raw: b'\x81~\x00\xd5{"topic":"orderbook.50.BTCUSDC","ts":1698936886464,"type":"delta","data":{"s":"BTCUSDC","b":[["34904.21","0.204079"],["34934.92","0"]],"a":[["34963.9","0.057201"],["34965.02","0"]],"u":20011020,"seq":14108054901}}'
2023-11-02 14:54:46,550 DEBUG ++Rcv decoded: fin=1 opcode=1 data=b'{"topic":"orderbook.50.BTCUSDC","ts":1698936886464,"type":"delta","data":{"s":"BTCUSDC","b":[["34904.21","0.204079"],["34934.92","0"]],"a":[["34963.9","0.057201"],["34965.02","0"]],"u":20011020,"seq":14108054901}}'
2023-11-02 14:54:46,669 DEBUG ++Rcv raw: b'\x81~\x00\xee{"topic":"orderbook.50.BTCUSDC","ts":1698936886583,"type":"delta","data":{"s":"BTCUSDC","b":[["34942.96","0.091818"],["34940.95","0.022414"],["34904.21","0"]],"a":[["34946.47","0.105295"],["34964.14","0"]],"u":20011021,"seq":14108054941}}'
2023-11-02 14:54:46,669 DEBUG ++Rcv decoded: fin=1 opcode=1 data=b'{"topic":"orderbook.50.BTCUSDC","ts":1698936886583,"type":"delta","data":{"s":"BTCUSDC","b":[["34942.96","0.091818"],["34940.95","0.022414"],["34904.21","0"]],"a":[["34946.47","0.105295"],["34964.14","0"]],"u":20011021,"seq":14108054941}}'
2023-11-02 14:54:46,689 DEBUG ++Rcv raw: b'\x81~\x00\xec{"topic":"orderbook.50.BTCUSDC","ts":1698936886604,"type":"delta","data":{"s":"BTCUSDC","b":[["34935.78","0.0859"],["34905.97","0"]],"a":[["34946.46","0.008756"],["34947.37","0.028614"],["34946.47","0"]],"u":20011022,"seq":14108054951}}'
2023-11-02 14:54:46,690 DEBUG ++Rcv decoded: fin=1 opcode=1 data=b'{"topic":"orderbook.50.BTCUSDC","ts":1698936886604,"type":"delta","data":{"s":"BTCUSDC","b":[["34935.78","0.0859"],["34905.97","0"]],"a":[["34946.46","0.008756"],["34947.37","0.028614"],["34946.47","0"]],"u":20011022,"seq":14108054951}}'
2023-11-02 14:54:46,709 DEBUG ++Rcv raw: b'\x81~\x00\xc6{"topic":"orderbook.50.BTCUSDC","ts":1698936886623,"type":"delta","data":{"s":"BTCUSDC","b":[["34936.37","0.048227"],["34932.35","0.051547"],["34934.63","0"]],"a":[],"u":20011023,"seq":14108054957}}'
2023-11-02 14:54:46,709 DEBUG ++Rcv decoded: fin=1 opcode=1 data=b'{"topic":"orderbook.50.BTCUSDC","ts":1698936886623,"type":"delta","data":{"s":"BTCUSDC","b":[["34936.37","0.048227"],["34932.35","0.051547"],["34934.63","0"]],"a":[],"u":20011023,"seq":14108054957}}'
2023-11-02 14:54:46,749 DEBUG ++Rcv raw: b'\x81~\x00\xd6{"topic":"orderbook.50.BTCUSDC","ts":1698936886664,"type":"delta","data":{"s":"BTCUSDC","b":[["34932.97","0.00026"],["34932.36","0.002913"],["34931.53","0"],["34906.88","0"]],"a":[],"u":20011024,"seq":14108054978}}'
2023-11-02 14:54:46,750 DEBUG ++Rcv decoded: fin=1 opcode=1 data=b'{"topic":"orderbook.50.BTCUSDC","ts":1698936886664,"type":"delta","data":{"s":"BTCUSDC","b":[["34932.97","0.00026"],["34932.36","0.002913"],["34931.53","0"],["34906.88","0"]],"a":[],"u":20011024,"seq":14108054978}}'
2023-11-02 14:54:46,769 DEBUG ++Rcv raw: b'\x81~\x00\xad{"topic":"orderbook.50.BTCUSDC","ts":1698936886684,"type":"delta","data":{"s":"BTCUSDC","b":[],"a":[["34964.14","0.02859"],["34947.37","0"]],"u":20011025,"seq":14108054986}}'
2023-11-02 14:54:46,770 DEBUG ++Rcv decoded: fin=1 opcode=1 data=b'{"topic":"orderbook.50.BTCUSDC","ts":1698936886684,"type":"delta","data":{"s":"BTCUSDC","b":[],"a":[["34964.14","0.02859"],["34947.37","0"]],"u":20011025,"seq":14108054986}}'
2023-11-02 14:54:46,829 DEBUG ++Rcv raw: b'\x81~\x00\x9d{"topic":"orderbook.50.BTCUSDC","ts":1698936886743,"type":"delta","data":{"s":"BTCUSDC","b":[],"a":[["34959.85","0.112507"]],"u":20011026,"seq":14108054995}}'
2023-11-02 14:54:46,829 DEBUG ++Rcv decoded: fin=1 opcode=1 data=b'{"topic":"orderbook.50.BTCUSDC","ts":1698936886743,"type":"delta","data":{"s":"BTCUSDC","b":[],"a":[["34959.85","0.112507"]],"u":20011026,"seq":14108054995}}'
2023-11-02 14:54:46,849 DEBUG ++Rcv raw: b'\x81~\x00\xae{"topic":"orderbook.50.BTCUSDC","ts":1698936886763,"type":"delta","data":{"s":"BTCUSDC","b":[["34940.73","0.057239"],["34910.79","0"]],"a":[],"u":20011027,"seq":14108054999}}'
2023-11-02 14:54:46,849 DEBUG ++Rcv decoded: fin=1 opcode=1 data=b'{"topic":"orderbook.50.BTCUSDC","ts":1698936886763,"type":"delta","data":{"s":"BTCUSDC","b":[["34940.73","0.057239"],["34910.79","0"]],"a":[],"u":20011027,"seq":14108054999}}'
2023-11-02 14:54:46,889 DEBUG ++Rcv raw: b'\x81~\x00\xae{"topic":"orderbook.50.BTCUSDC","ts":1698936886803,"type":"delta","data":{"s":"BTCUSDC","b":[],"a":[["34946.45","0.028615"],["34964.14","0"]],"u":20011028,"seq":14108055012}}'
2023-11-02 14:54:46,889 DEBUG ++Rcv decoded: fin=1 opcode=1 data=b'{"topic":"orderbook.50.BTCUSDC","ts":1698936886803,"type":"delta","data":{"s":"BTCUSDC","b":[],"a":[["34946.45","0.028615"],["34964.14","0"]],"u":20011028,"seq":14108055012}}'
2023-11-02 14:54:46,929 DEBUG ++Rcv raw: b'\x81~\x00\xac{"topic":"orderbook.50.BTCUSDC","ts":1698936886844,"type":"delta","data":{"s":"BTCUSDC","b":[["34939.22","0.0859"],["34911.28","0"]],"a":[],"u":20011029,"seq":14108055043}}'
2023-11-02 14:54:46,930 DEBUG ++Rcv decoded: fin=1 opcode=1 data=b'{"topic":"orderbook.50.BTCUSDC","ts":1698936886844,"type":"delta","data":{"s":"BTCUSDC","b":[["34939.22","0.0859"],["34911.28","0"]],"a":[],"u":20011029,"seq":14108055043}}'
2023-11-02 14:54:46,948 DEBUG ++Rcv raw: b'\x81~\x00\xae{"topic":"orderbook.50.BTCUSDC","ts":1698936886863,"type":"delta","data":{"s":"BTCUSDC","b":[["34939.23","0.051548"],["34938.03","0"]],"a":[],"u":20011030,"seq":14108055046}}'
2023-11-02 14:54:46,949 DEBUG ++Rcv decoded: fin=1 opcode=1 data=b'{"topic":"orderbook.50.BTCUSDC","ts":1698936886863,"type":"delta","data":{"s":"BTCUSDC","b":[["34939.23","0.051548"],["34938.03","0"]],"a":[],"u":20011030,"seq":14108055046}}'
2023-11-02 14:54:46,988 DEBUG ++Rcv raw: b'\x81~\x00\xd4{"topic":"orderbook.50.BTCUSDC","ts":1698936886903,"type":"delta","data":{"s":"BTCUSDC","b":[["34911.28","0.1875"],["34931.11","0"]],"a":[["34946.18","0.093243"],["34946.45","0"]],"u":20011031,"seq":14108055074}}'
2023-11-02 14:54:46,989 DEBUG ++Rcv decoded: fin=1 opcode=1 data=b'{"topic":"orderbook.50.BTCUSDC","ts":1698936886903,"type":"delta","data":{"s":"BTCUSDC","b":[["34911.28","0.1875"],["34931.11","0"]],"a":[["34946.18","0.093243"],["34946.45","0"]],"u":20011031,"seq":14108055074}}'
2023-11-02 14:54:47,009 DEBUG ++Rcv raw: b'\x81~\x00\xad{"topic":"orderbook.50.BTCUSDC","ts":1698936886923,"type":"delta","data":{"s":"BTCUSDC","b":[],"a":[["34964.14","0.02859"],["34946.46","0"]],"u":20011032,"seq":14108055081}}'
2023-11-02 14:54:47,009 DEBUG ++Rcv decoded: fin=1 opcode=1 data=b'{"topic":"orderbook.50.BTCUSDC","ts":1698936886923,"type":"delta","data":{"s":"BTCUSDC","b":[],"a":[["34964.14","0.02859"],["34946.46","0"]],"u":20011032,"seq":14108055081}}'
2023-11-02 14:54:47,029 DEBUG ++Rcv raw: b'\x81~\x00\xfa{"topic":"orderbook.50.BTCUSDC","ts":1698936886943,"type":"delta","data":{"s":"BTCUSDC","b":[["34910.79","0.4192"],["34906.88","0.458362"],["34932.36","0"],["34931.51","0"]],"a":[["34961.56","0.001"],["34964.14","0"]],"u":20011033,"seq":14108055099}}'
2023-11-02 14:54:47,029 DEBUG ++Rcv decoded: fin=1 opcode=1 data=b'{"topic":"orderbook.50.BTCUSDC","ts":1698936886943,"type":"delta","data":{"s":"BTCUSDC","b":[["34910.79","0.4192"],["34906.88","0.458362"],["34932.36","0"],["34931.51","0"]],"a":[["34961.56","0.001"],["34964.14","0"]],"u":20011033,"seq":14108055099}}'
2023-11-02 14:54:47,069 DEBUG ++Rcv raw: b'\x81~\x00\xd2{"topic":"orderbook.50.BTCUSDC","ts":1698936886983,"type":"delta","data":{"s":"BTCUSDC","b":[["34933.01","0.00026"],["34906.88","0"]],"a":[["34946.44","0.028615"],["34964","0"]],"u":20011034,"seq":14108055115}}'
2023-11-02 14:54:47,070 DEBUG ++Rcv decoded: fin=1 opcode=1 data=b'{"topic":"orderbook.50.BTCUSDC","ts":1698936886983,"type":"delta","data":{"s":"BTCUSDC","b":[["34933.01","0.00026"],["34906.88","0"]],"a":[["34946.44","0.028615"],["34964","0"]],"u":20011034,"seq":14108055115}}'
2023-11-02 14:54:47,149 DEBUG ++Rcv raw: b'\x81~\x00\xae{"topic":"orderbook.50.BTCUSDC","ts":1698936887063,"type":"delta","data":{"s":"BTCUSDC","b":[["34928.78","0.025625"],["34910.79","0"]],"a":[],"u":20011035,"seq":14108055161}}'
2023-11-02 14:54:47,149 DEBUG ++Rcv decoded: fin=1 opcode=1 data=b'{"topic":"orderbook.50.BTCUSDC","ts":1698936887063,"type":"delta","data":{"s":"BTCUSDC","b":[["34928.78","0.025625"],["34910.79","0"]],"a":[],"u":20011035,"seq":14108055161}}'
2023-11-02 14:54:47,169 DEBUG ++Rcv raw: b'\x81~\x00\xa9{"topic":"orderbook.50.BTCUSDC","ts":1698936887083,"type":"delta","data":{"s":"BTCUSDC","b":[],"a":[["34964","0.0324"],["34946.44","0"]],"u":20011036,"seq":14108055174}}'
2023-11-02 14:54:47,169 DEBUG ++Rcv decoded: fin=1 opcode=1 data=b'{"topic":"orderbook.50.BTCUSDC","ts":1698936887083,"type":"delta","data":{"s":"BTCUSDC","b":[],"a":[["34964","0.0324"],["34946.44","0"]],"u":20011036,"seq":14108055174}}'
2023-11-02 14:54:47,190 DEBUG ++Rcv raw: b'\x81~\x00\xab{"topic":"orderbook.50.BTCUSDC","ts":1698936887104,"type":"delta","data":{"s":"BTCUSDC","b":[["34925.02","0.028"],["34911.28","0"]],"a":[],"u":20011037,"seq":14108055183}}'
2023-11-02 14:54:47,190 DEBUG ++Rcv decoded: fin=1 opcode=1 data=b'{"topic":"orderbook.50.BTCUSDC","ts":1698936887104,"type":"delta","data":{"s":"BTCUSDC","b":[["34925.02","0.028"],["34911.28","0"]],"a":[],"u":20011037,"seq":14108055183}}'
2023-11-02 14:54:47,269 DEBUG ++Rcv raw: b'\x81~\x00\xab{"topic":"orderbook.50.BTCUSDC","ts":1698936887184,"type":"delta","data":{"s":"BTCUSDC","b":[],"a":[["34946.17","0.028615"],["34964","0"]],"u":20011038,"seq":14108055208}}'
2023-11-02 14:54:47,270 DEBUG ++Rcv decoded: fin=1 opcode=1 data=b'{"topic":"orderbook.50.BTCUSDC","ts":1698936887184,"type":"delta","data":{"s":"BTCUSDC","b":[],"a":[["34946.17","0.028615"],["34964","0"]],"u":20011038,"seq":14108055208}}'
2023-11-02 14:54:47,290 DEBUG ++Rcv raw: b'\x81~\x00\xa9{"topic":"orderbook.50.BTCUSDC","ts":1698936887204,"type":"delta","data":{"s":"BTCUSDC","b":[],"a":[["34964","0.0324"],["34946.18","0"]],"u":20011039,"seq":14108055212}}'
2023-11-02 14:54:47,290 DEBUG ++Rcv decoded: fin=1 opcode=1 data=b'{"topic":"orderbook.50.BTCUSDC","ts":1698936887204,"type":"delta","data":{"s":"BTCUSDC","b":[],"a":[["34964","0.0324"],["34946.18","0"]],"u":20011039,"seq":14108055212}}'
2023-11-02 14:54:47,329 DEBUG ++Rcv raw: b'\x81~\x00\xac{"topic":"orderbook.50.BTCUSDC","ts":1698936887243,"type":"delta","data":{"s":"BTCUSDC","b":[["34911.28","0.1875"],["34932.97","0"]],"a":[],"u":20011040,"seq":14108055222}}'
2023-11-02 14:54:47,329 DEBUG ++Rcv decoded: fin=1 opcode=1 data=b'{"topic":"orderbook.50.BTCUSDC","ts":1698936887243,"type":"delta","data":{"s":"BTCUSDC","b":[["34911.28","0.1875"],["34932.97","0"]],"a":[],"u":20011040,"seq":14108055222}}'
2023-11-02 14:54:47,369 DEBUG ++Rcv raw: b'\x81~\x00\xab{"topic":"orderbook.50.BTCUSDC","ts":1698936887284,"type":"delta","data":{"s":"BTCUSDC","b":[],"a":[["34946.16","0.008756"],["34964","0"]],"u":20011041,"seq":14108055232}}'
2023-11-02 14:54:47,370 DEBUG ++Rcv decoded: fin=1 opcode=1 data=b'{"topic":"orderbook.50.BTCUSDC","ts":1698936887284,"type":"delta","data":{"s":"BTCUSDC","b":[],"a":[["34946.16","0.008756"],["34964","0"]],"u":20011041,"seq":14108055232}}'
2023-11-02 14:54:47,389 DEBUG ++Rcv raw: b'\x81~\x00\xa9{"topic":"orderbook.50.BTCUSDC","ts":1698936887304,"type":"delta","data":{"s":"BTCUSDC","b":[],"a":[["34964","0.0324"],["34946.17","0"]],"u":20011042,"seq":14108055236}}'
2023-11-02 14:54:47,389 DEBUG ++Rcv decoded: fin=1 opcode=1 data=b'{"topic":"orderbook.50.BTCUSDC","ts":1698936887304,"type":"delta","data":{"s":"BTCUSDC","b":[],"a":[["34964","0.0324"],["34946.17","0"]],"u":20011042,"seq":14108055236}}'
2023-11-02 14:54:47,429 DEBUG ++Rcv raw: b'\x81~\x00\xac{"topic":"orderbook.50.BTCUSDC","ts":1698936887344,"type":"delta","data":{"s":"BTCUSDC","b":[["34910.79","0.4192"],["34938.46","0"]],"a":[],"u":20011043,"seq":14108055255}}'
2023-11-02 14:54:47,430 DEBUG ++Rcv decoded: fin=1 opcode=1 data=b'{"topic":"orderbook.50.BTCUSDC","ts":1698936887344,"type":"delta","data":{"s":"BTCUSDC","b":[["34910.79","0.4192"],["34938.46","0"]],"a":[],"u":20011043,"seq":14108055255}}'
2023-11-02 14:54:47,469 DEBUG ++Rcv raw: b'\x81~\x00\xae{"topic":"orderbook.50.BTCUSDC","ts":1698936887384,"type":"delta","data":{"s":"BTCUSDC","b":[["34938.45","0.014139"],["34910.79","0"]],"a":[],"u":20011044,"seq":14108055278}}'
2023-11-02 14:54:47,469 DEBUG ++Rcv decoded: fin=1 opcode=1 data=b'{"topic":"orderbook.50.BTCUSDC","ts":1698936887384,"type":"delta","data":{"s":"BTCUSDC","b":[["34938.45","0.014139"],["34910.79","0"]],"a":[],"u":20011044,"seq":14108055278}}'
2023-11-02 14:54:47,589 DEBUG ++Rcv raw: b'\x81~\x00\xae{"topic":"orderbook.50.BTCUSDC","ts":1698936887503,"type":"delta","data":{"s":"BTCUSDC","b":[["34928.48","0.029866"],["34911.28","0"]],"a":[],"u":20011045,"seq":14108055363}}'
2023-11-02 14:54:47,589 DEBUG ++Rcv decoded: fin=1 opcode=1 data=b'{"topic":"orderbook.50.BTCUSDC","ts":1698936887503,"type":"delta","data":{"s":"BTCUSDC","b":[["34928.48","0.029866"],["34911.28","0"]],"a":[],"u":20011045,"seq":14108055363}}'
2023-11-02 14:54:47,609 DEBUG ++Rcv raw: b'\x81~\x00\xd3{"topic":"orderbook.50.BTCUSDC","ts":1698936887524,"type":"delta","data":{"s":"BTCUSDC","b":[["34911.28","0.1875"],["34934.62","0"]],"a":[["34964.14","0.02859"],["34959.99","0"]],"u":20011046,"seq":14108055367}}'
2023-11-02 14:54:47,609 DEBUG ++Rcv decoded: fin=1 opcode=1 data=b'{"topic":"orderbook.50.BTCUSDC","ts":1698936887524,"type":"delta","data":{"s":"BTCUSDC","b":[["34911.28","0.1875"],["34934.62","0"]],"a":[["34964.14","0.02859"],["34959.99","0"]],"u":20011046,"seq":14108055367}}'
2023-11-02 14:54:47,629 DEBUG ++Rcv raw: b'\x81~\x00\xd6{"topic":"orderbook.50.BTCUSDC","ts":1698936887543,"type":"delta","data":{"s":"BTCUSDC","b":[["34934.07","0.001152"],["34911.28","0"]],"a":[["34946.15","0.028615"],["34964.14","0"]],"u":20011047,"seq":14108055373}}'
2023-11-02 14:54:47,629 DEBUG ++Rcv decoded: fin=1 opcode=1 data=b'{"topic":"orderbook.50.BTCUSDC","ts":1698936887543,"type":"delta","data":{"s":"BTCUSDC","b":[["34934.07","0.001152"],["34911.28","0"]],"a":[["34946.15","0.028615"],["34964.14","0"]],"u":20011047,"seq":14108055373}}'
2023-11-02 14:54:47,669 DEBUG ++Rcv raw: b'\x81~\x00\xae{"topic":"orderbook.50.BTCUSDC","ts":1698936887584,"type":"delta","data":{"s":"BTCUSDC","b":[],"a":[["34962.19","0.027901"],["34946.16","0"]],"u":20011048,"seq":14108055387}}'
2023-11-02 14:54:47,670 DEBUG ++Rcv decoded: fin=1 opcode=1 data=b'{"topic":"orderbook.50.BTCUSDC","ts":1698936887584,"type":"delta","data":{"s":"BTCUSDC","b":[],"a":[["34962.19","0.027901"],["34946.16","0"]],"u":20011048,"seq":14108055387}}'
2023-11-02 14:54:47,729 DEBUG ++Rcv raw: b'\x81~\x00\xad{"topic":"orderbook.50.BTCUSDC","ts":1698936887644,"type":"delta","data":{"s":"BTCUSDC","b":[],"a":[["34964.14","0.02859"],["34961.56","0"]],"u":20011049,"seq":14108055394}}'
2023-11-02 14:54:47,729 DEBUG ++Rcv decoded: fin=1 opcode=1 data=b'{"topic":"orderbook.50.BTCUSDC","ts":1698936887644,"type":"delta","data":{"s":"BTCUSDC","b":[],"a":[["34964.14","0.02859"],["34961.56","0"]],"u":20011049,"seq":14108055394}}'
2023-11-02 14:54:47,769 DEBUG ++Rcv raw: b'\x81~\x00\xd2{"topic":"orderbook.50.BTCUSDC","ts":1698936887683,"type":"delta","data":{"s":"BTCUSDC","b":[["34911.28","0.1875"],["34933.01","0"]],"a":[["34965.02","0.0859"],["34946.15","0"]],"u":20011050,"seq":14108055413}}'
2023-11-02 14:54:47,769 DEBUG ++Rcv decoded: fin=1 opcode=1 data=b'{"topic":"orderbook.50.BTCUSDC","ts":1698936887683,"type":"delta","data":{"s":"BTCUSDC","b":[["34911.28","0.1875"],["34933.01","0"]],"a":[["34965.02","0.0859"],["34946.15","0"]],"u":20011050,"seq":14108055413}}'
2023-11-02 14:54:47,789 DEBUG ++Rcv raw: b'\x81~\x00\xae{"topic":"orderbook.50.BTCUSDC","ts":1698936887703,"type":"delta","data":{"s":"BTCUSDC","b":[],"a":[["34946.39","0.108478"],["34965.02","0"]],"u":20011051,"seq":14108055435}}'
2023-11-02 14:54:47,789 DEBUG ++Rcv decoded: fin=1 opcode=1 data=b'{"topic":"orderbook.50.BTCUSDC","ts":1698936887703,"type":"delta","data":{"s":"BTCUSDC","b":[],"a":[["34946.39","0.108478"],["34965.02","0"]],"u":20011051,"seq":14108055435}}'
2023-11-02 14:54:47,810 DEBUG ++Rcv raw: b'\x81~\x00\xd2{"topic":"orderbook.50.BTCUSDC","ts":1698936887724,"type":"delta","data":{"s":"BTCUSDC","b":[],"a":[["34946.38","0.008756"],["34958.13","0.0005"],["34964","0"],["34964.14","0"]],"u":20011052,"seq":14108055453}}'
2023-11-02 14:54:47,810 DEBUG ++Rcv decoded: fin=1 opcode=1 data=b'{"topic":"orderbook.50.BTCUSDC","ts":1698936887724,"type":"delta","data":{"s":"BTCUSDC","b":[],"a":[["34946.38","0.008756"],["34958.13","0.0005"],["34964","0"],["34964.14","0"]],"u":20011052,"seq":14108055453}}'
2023-11-02 14:54:47,830 DEBUG ++Rcv raw: b'\x81~\x00\xcf{"topic":"orderbook.50.BTCUSDC","ts":1698936887744,"type":"delta","data":{"s":"BTCUSDC","b":[["34910.79","0.4192"],["34934.07","0"]],"a":[["34964","0.0324"],["34946.39","0"]],"u":20011053,"seq":14108055466}}'
2023-11-02 14:54:47,830 DEBUG ++Rcv decoded: fin=1 opcode=1 data=b'{"topic":"orderbook.50.BTCUSDC","ts":1698936887744,"type":"delta","data":{"s":"BTCUSDC","b":[["34910.79","0.4192"],["34934.07","0"]],"a":[["34964","0.0324"],["34946.39","0"]],"u":20011053,"seq":14108055466}}'
2023-11-02 14:54:47,869 DEBUG ++Rcv raw: b'\x81~\x00\xab{"topic":"orderbook.50.BTCUSDC","ts":1698936887783,"type":"delta","data":{"s":"BTCUSDC","b":[],"a":[["34947.37","0.028614"],["34964","0"]],"u":20011054,"seq":14108055484}}'
2023-11-02 14:54:47,869 DEBUG ++Rcv decoded: fin=1 opcode=1 data=b'{"topic":"orderbook.50.BTCUSDC","ts":1698936887783,"type":"delta","data":{"s":"BTCUSDC","b":[],"a":[["34947.37","0.028614"],["34964","0"]],"u":20011054,"seq":14108055484}}'
2023-11-02 14:54:47,929 DEBUG ++Rcv raw: b'\x81~\x00\xd2{"topic":"orderbook.50.BTCUSDC","ts":1698936887843,"type":"delta","data":{"s":"BTCUSDC","b":[["34934.07","0.001379"],["34925.02","0"]],"a":[["34959.91","0.001"],["34963.9","0"]],"u":20011055,"seq":14108055506}}'
2023-11-02 14:54:47,929 DEBUG ++Rcv decoded: fin=1 opcode=1 data=b'{"topic":"orderbook.50.BTCUSDC","ts":1698936887843,"type":"delta","data":{"s":"BTCUSDC","b":[["34934.07","0.001379"],["34925.02","0"]],"a":[["34959.91","0.001"],["34963.9","0"]],"u":20011055,"seq":14108055506}}'
2023-11-02 14:54:47,969 DEBUG ++Rcv raw: b'\x81~\x00\xad{"topic":"orderbook.50.BTCUSDC","ts":1698936887884,"type":"delta","data":{"s":"BTCUSDC","b":[],"a":[["34963.9","0.057201"],["34947.37","0"]],"u":20011056,"seq":14108055517}}'
2023-11-02 14:54:47,969 DEBUG ++Rcv decoded: fin=1 opcode=1 data=b'{"topic":"orderbook.50.BTCUSDC","ts":1698936887884,"type":"delta","data":{"s":"BTCUSDC","b":[],"a":[["34963.9","0.057201"],["34947.37","0"]],"u":20011056,"seq":14108055517}}'
2023-11-02 14:54:48,049 DEBUG ++Rcv raw: b'\x81~\x00\xd1{"topic":"orderbook.50.BTCUSDC","ts":1698936887963,"type":"delta","data":{"s":"BTCUSDC","b":[["34906.88","0.458362"],["34918.65","0"]],"a":[["34964","0.0324"],["34961.74","0"]],"u":20011057,"seq":14108055558}}'
2023-11-02 14:54:48,050 DEBUG ++Rcv decoded: fin=1 opcode=1 data=b'{"topic":"orderbook.50.BTCUSDC","ts":1698936887963,"type":"delta","data":{"s":"BTCUSDC","b":[["34906.88","0.458362"],["34918.65","0"]],"a":[["34964","0.0324"],["34961.74","0"]],"u":20011057,"seq":14108055558}}'
2023-11-02 14:54:48,069 DEBUG ++Rcv raw: b'\x81~\x00\xd3{"topic":"orderbook.50.BTCUSDC","ts":1698936887984,"type":"delta","data":{"s":"BTCUSDC","b":[["34920.45","0.286365"],["34906.88","0"]],"a":[["34960.06","0.114416"],["34964","0"]],"u":20011058,"seq":14108055572}}'
2023-11-02 14:54:48,069 DEBUG ++Rcv decoded: fin=1 opcode=1 data=b'{"topic":"orderbook.50.BTCUSDC","ts":1698936887984,"type":"delta","data":{"s":"BTCUSDC","b":[["34920.45","0.286365"],["34906.88","0"]],"a":[["34960.06","0.114416"],["34964","0"]],"u":20011058,"seq":14108055572}}'
2023-11-02 14:54:48,129 DEBUG ++Rcv raw: b'\x81~\x00\xab{"topic":"orderbook.50.BTCUSDC","ts":1698936888043,"type":"delta","data":{"s":"BTCUSDC","b":[["34927.56","0.028"],["34910.79","0"]],"a":[],"u":20011059,"seq":14108055594}}'
2023-11-02 14:54:48,129 DEBUG ++Rcv decoded: fin=1 opcode=1 data=b'{"topic":"orderbook.50.BTCUSDC","ts":1698936888043,"type":"delta","data":{"s":"BTCUSDC","b":[["34927.56","0.028"],["34910.79","0"]],"a":[],"u":20011059,"seq":14108055594}}'
2023-11-02 14:54:48,169 DEBUG ++Rcv raw: b'\x81~\x00\xad{"topic":"orderbook.50.BTCUSDC","ts":1698936888083,"type":"delta","data":{"s":"BTCUSDC","b":[["34932.27","0.114507"],["34930.8","0"]],"a":[],"u":20011060,"seq":14108055620}}'
2023-11-02 14:54:48,169 DEBUG ++Rcv decoded: fin=1 opcode=1 data=b'{"topic":"orderbook.50.BTCUSDC","ts":1698936888083,"type":"delta","data":{"s":"BTCUSDC","b":[["34932.27","0.114507"],["34930.8","0"]],"a":[],"u":20011060,"seq":14108055620}}'
2023-11-02 14:54:48,189 DEBUG ++Rcv raw: b'\x81~\x00\xae{"topic":"orderbook.50.BTCUSDC","ts":1698936888103,"type":"delta","data":{"s":"BTCUSDC","b":[],"a":[["34946.26","0.108015"],["34946.38","0"]],"u":20011061,"seq":14108055631}}'
2023-11-02 14:54:48,189 DEBUG ++Rcv decoded: fin=1 opcode=1 data=b'{"topic":"orderbook.50.BTCUSDC","ts":1698936888103,"type":"delta","data":{"s":"BTCUSDC","b":[],"a":[["34946.26","0.108015"],["34946.38","0"]],"u":20011061,"seq":14108055631}}'
2023-11-02 14:54:48,209 DEBUG ++Rcv raw: b'\x81~\x00\xd4{"topic":"orderbook.50.BTCUSDC","ts":1698936888123,"type":"delta","data":{"s":"BTCUSDC","b":[["34933.15","0.00026"],["34911.28","0"]],"a":[["34946.37","0.028615"],["34963.9","0"]],"u":20011062,"seq":14108055642}}'
2023-11-02 14:54:48,209 DEBUG ++Rcv decoded: fin=1 opcode=1 data=b'{"topic":"orderbook.50.BTCUSDC","ts":1698936888123,"type":"delta","data":{"s":"BTCUSDC","b":[["34933.15","0.00026"],["34911.28","0"]],"a":[["34946.37","0.028615"],["34963.9","0"]],"u":20011062,"seq":14108055642}}'
2023-11-02 14:54:48,229 DEBUG ++Rcv raw: b'\x81~\x00\xae{"topic":"orderbook.50.BTCUSDC","ts":1698936888143,"type":"delta","data":{"s":"BTCUSDC","b":[],"a":[["34954.35","0.000475"],["34963.76","0"]],"u":20011063,"seq":14108055656}}'
2023-11-02 14:54:48,229 DEBUG ++Rcv decoded: fin=1 opcode=1 data=b'{"topic":"orderbook.50.BTCUSDC","ts":1698936888143,"type":"delta","data":{"s":"BTCUSDC","b":[],"a":[["34954.35","0.000475"],["34963.76","0"]],"u":20011063,"seq":14108055656}}'
2023-11-02 14:54:48,329 DEBUG ++Rcv raw: b'\x81~\x00\xd2{"topic":"orderbook.50.BTCUSDC","ts":1698936888243,"type":"delta","data":{"s":"BTCUSDC","b":[["34911.28","0.1875"],["34934.07","0"]],"a":[["34963.76","0.1875"],["34954.35","0"]],"u":20011064,"seq":14108055683}}'
2023-11-02 14:54:48,329 DEBUG ++Rcv decoded: fin=1 opcode=1 data=b'{"topic":"orderbook.50.BTCUSDC","ts":1698936888243,"type":"delta","data":{"s":"BTCUSDC","b":[["34911.28","0.1875"],["34934.07","0"]],"a":[["34963.76","0.1875"],["34954.35","0"]],"u":20011064,"seq":14108055683}}'
2023-11-02 14:54:48,369 DEBUG ++Rcv raw: b'\x81~\x00\xad{"topic":"orderbook.50.BTCUSDC","ts":1698936888284,"type":"delta","data":{"s":"BTCUSDC","b":[["34933.17","0.00026"],["34911.28","0"]],"a":[],"u":20011065,"seq":14108055696}}'
2023-11-02 14:54:48,369 DEBUG ++Rcv decoded: fin=1 opcode=1 data=b'{"topic":"orderbook.50.BTCUSDC","ts":1698936888284,"type":"delta","data":{"s":"BTCUSDC","b":[["34933.17","0.00026"],["34911.28","0"]],"a":[],"u":20011065,"seq":14108055696}}'
2023-11-02 14:54:48,409 DEBUG ++Rcv raw: b'\x81~\x00\x9d{"topic":"orderbook.50.BTCUSDC","ts":1698936888323,"type":"delta","data":{"s":"BTCUSDC","b":[["34934.06","0.128905"]],"a":[],"u":20011066,"seq":14108055704}}'
2023-11-02 14:54:48,409 DEBUG ++Rcv decoded: fin=1 opcode=1 data=b'{"topic":"orderbook.50.BTCUSDC","ts":1698936888323,"type":"delta","data":{"s":"BTCUSDC","b":[["34934.06","0.128905"]],"a":[],"u":20011066,"seq":14108055704}}'
2023-11-02 14:54:48,434 DEBUG ++Rcv raw: b'\x81~\x00\xfe{"topic":"orderbook.50.BTCUSDC","ts":1698936888344,"type":"delta","data":{"s":"BTCUSDC","b":[["34934.07","0.077343"],["34932.35","0"]],"a":[["34945.3","0.096125"],["34946.25","0.008756"],["34946.26","0"],["34963.76","0"]],"u":20011067,"seq":14108055713}}'
2023-11-02 14:54:48,435 DEBUG ++Rcv decoded: fin=1 opcode=1 data=b'{"topic":"orderbook.50.BTCUSDC","ts":1698936888344,"type":"delta","data":{"s":"BTCUSDC","b":[["34934.07","0.077343"],["34932.35","0"]],"a":[["34945.3","0.096125"],["34946.25","0.008756"],["34946.26","0"],["34963.76","0"]],"u":20011067,"seq":14108055713}}'
2023-11-02 14:54:48,449 DEBUG ++Rcv raw: b'\x81~\x00\xac{"topic":"orderbook.50.BTCUSDC","ts":1698936888363,"type":"delta","data":{"s":"BTCUSDC","b":[["34911.28","0.1875"],["34936.07","0"]],"a":[],"u":20011068,"seq":14108055718}}'
2023-11-02 14:54:48,449 DEBUG ++Rcv decoded: fin=1 opcode=1 data=b'{"topic":"orderbook.50.BTCUSDC","ts":1698936888363,"type":"delta","data":{"s":"BTCUSDC","b":[["34911.28","0.1875"],["34936.07","0"]],"a":[],"u":20011068,"seq":14108055718}}'
2023-11-02 14:54:48,468 DEBUG ++Rcv raw: b'\x81~\x01#{"topic":"orderbook.50.BTCUSDC","ts":1698936888383,"type":"delta","data":{"s":"BTCUSDC","b":[["34910.79","0.4192"],["34909.72","0.458324"],["34920.45","0"],["34940.73","0"]],"a":[["34963.76","0.1875"],["34963.9","0.057201"],["34952.26","0"],["34946.37","0"]],"u":20011069,"seq":14108055728}}'
2023-11-02 14:54:48,469 DEBUG ++Rcv decoded: fin=1 opcode=1 data=b'{"topic":"orderbook.50.BTCUSDC","ts":1698936888383,"type":"delta","data":{"s":"BTCUSDC","b":[["34910.79","0.4192"],["34909.72","0.458324"],["34920.45","0"],["34940.73","0"]],"a":[["34963.76","0.1875"],["34963.9","0.057201"],["34952.26","0"],["34946.37","0"]],"u":20011069,"seq":14108055728}}'
2023-11-02 14:54:48,489 DEBUG ++Rcv raw: b'\x81~\x00\xf9{"topic":"orderbook.50.BTCUSDC","ts":1698936888403,"type":"delta","data":{"s":"BTCUSDC","b":[["34941.46","0.057238"],["34921.88","0.286353"],["34909.72","0"],["34910.79","0"]],"a":[["34964","0.0324"],["34951.4","0"]],"u":20011070,"seq":14108055740}}'
2023-11-02 14:54:48,489 DEBUG ++Rcv decoded: fin=1 opcode=1 data=b'{"topic":"orderbook.50.BTCUSDC","ts":1698936888403,"type":"delta","data":{"s":"BTCUSDC","b":[["34941.46","0.057238"],["34921.88","0.286353"],["34909.72","0"],["34910.79","0"]],"a":[["34964","0.0324"],["34951.4","0"]],"u":20011070,"seq":14108055740}}'
2023-11-02 14:54:48,509 DEBUG ++Rcv raw: b'\x81~\x00\xab{"topic":"orderbook.50.BTCUSDC","ts":1698936888424,"type":"delta","data":{"s":"BTCUSDC","b":[],"a":[["34950.79","0.057223"],["34964","0"]],"u":20011071,"seq":14108055742}}'
2023-11-02 14:54:48,509 DEBUG ++Rcv decoded: fin=1 opcode=1 data=b'{"topic":"orderbook.50.BTCUSDC","ts":1698936888424,"type":"delta","data":{"s":"BTCUSDC","b":[],"a":[["34950.79","0.057223"],["34964","0"]],"u":20011071,"seq":14108055742}}'
2023-11-02 14:54:48,529 DEBUG ++Rcv raw: b'\x81~\x00\xd5{"topic":"orderbook.50.BTCUSDC","ts":1698936888444,"type":"delta","data":{"s":"BTCUSDC","b":[["34934.08","0.001303"],["34911.28","0"]],"a":[["34954.35","0.000432"],["34963.9","0"]],"u":20011072,"seq":14108055756}}'
2023-11-02 14:54:48,529 DEBUG ++Rcv decoded: fin=1 opcode=1 data=b'{"topic":"orderbook.50.BTCUSDC","ts":1698936888444,"type":"delta","data":{"s":"BTCUSDC","b":[["34934.08","0.001303"],["34911.28","0"]],"a":[["34954.35","0.000432"],["34963.9","0"]],"u":20011072,"seq":14108055756}}'
2023-11-02 14:54:48,569 DEBUG ++Rcv raw: b'\x81~\x00\xae{"topic":"orderbook.50.BTCUSDC","ts":1698936888483,"type":"delta","data":{"s":"BTCUSDC","b":[],"a":[["34945.29","0.028616"],["34963.76","0"]],"u":20011073,"seq":14108055777}}'
2023-11-02 14:54:48,569 DEBUG ++Rcv decoded: fin=1 opcode=1 data=b'{"topic":"orderbook.50.BTCUSDC","ts":1698936888483,"type":"delta","data":{"s":"BTCUSDC","b":[],"a":[["34945.29","0.028616"],["34963.76","0"]],"u":20011073,"seq":14108055777}}'
2023-11-02 14:54:48,589 DEBUG ++Rcv raw: b'\x81~\x00\xd1{"topic":"orderbook.50.BTCUSDC","ts":1698936888504,"type":"delta","data":{"s":"BTCUSDC","b":[["34911.28","0.1875"],["34933.15","0"]],"a":[["34947.82","0.0859"],["34945.3","0"]],"u":20011074,"seq":14108055787}}'
2023-11-02 14:54:48,589 DEBUG ++Rcv decoded: fin=1 opcode=1 data=b'{"topic":"orderbook.50.BTCUSDC","ts":1698936888504,"type":"delta","data":{"s":"BTCUSDC","b":[["34911.28","0.1875"],["34933.15","0"]],"a":[["34947.82","0.0859"],["34945.3","0"]],"u":20011074,"seq":14108055787}}'
2023-11-02 14:54:48,629 DEBUG ++Rcv raw: b'\x81~\x00\xac{"topic":"orderbook.50.BTCUSDC","ts":1698936888544,"type":"delta","data":{"s":"BTCUSDC","b":[["34910.79","0.4192"],["34942.96","0"]],"a":[],"u":20011075,"seq":14108055797}}'
2023-11-02 14:54:48,629 DEBUG ++Rcv decoded: fin=1 opcode=1 data=b'{"topic":"orderbook.50.BTCUSDC","ts":1698936888544,"type":"delta","data":{"s":"BTCUSDC","b":[["34910.79","0.4192"],["34942.96","0"]],"a":[],"u":20011075,"seq":14108055797}}'
2023-11-02 14:54:48,649 DEBUG ++Rcv raw: b'\x81~\x01${"topic":"orderbook.50.BTCUSDC","ts":1698936888563,"type":"delta","data":{"s":"BTCUSDC","b":[["34936.57","0.00057"],["34941.46","0"]],"a":[["34945.28","0.008756"],["34963.76","0.1875"],["34963.9","0.057201"],["34960.06","0"],["34946.25","0"],["34950.79","0"]],"u":20011076,"seq":14108055811}}'
2023-11-02 14:54:48,649 DEBUG ++Rcv decoded: fin=1 opcode=1 data=b'{"topic":"orderbook.50.BTCUSDC","ts":1698936888563,"type":"delta","data":{"s":"BTCUSDC","b":[["34936.57","0.00057"],["34941.46","0"]],"a":[["34945.28","0.008756"],["34963.76","0.1875"],["34963.9","0.057201"],["34960.06","0"],["34946.25","0"],["34950.79","0"]],"u":20011076,"seq":14108055811}}'
2023-11-02 14:54:48,669 DEBUG ++Rcv raw: b'\x81~\x00\xfd{"topic":"orderbook.50.BTCUSDC","ts":1698936888583,"type":"delta","data":{"s":"BTCUSDC","b":[["34940.68","0.057239"],["34910.79","0"]],"a":[["34950.12","0.057224"],["34958.68","0.11442"],["34963.76","0"],["34963.9","0"]],"u":20011077,"seq":14108055821}}'
2023-11-02 14:54:48,669 DEBUG ++Rcv decoded: fin=1 opcode=1 data=b'{"topic":"orderbook.50.BTCUSDC","ts":1698936888583,"type":"delta","data":{"s":"BTCUSDC","b":[["34940.68","0.057239"],["34910.79","0"]],"a":[["34950.12","0.057224"],["34958.68","0.11442"],["34963.76","0"],["34963.9","0"]],"u":20011077,"seq":14108055821}}'
2023-11-02 14:54:48,689 DEBUG ++Rcv raw: b'\x81~\x00\xac{"topic":"orderbook.50.BTCUSDC","ts":1698936888604,"type":"delta","data":{"s":"BTCUSDC","b":[],"a":[["34963.76","0.1875"],["34945.29","0"]],"u":20011078,"seq":14108055824}}'
2023-11-02 14:54:48,689 DEBUG ++Rcv decoded: fin=1 opcode=1 data=b'{"topic":"orderbook.50.BTCUSDC","ts":1698936888604,"type":"delta","data":{"s":"BTCUSDC","b":[],"a":[["34963.76","0.1875"],["34945.29","0"]],"u":20011078,"seq":14108055824}}'
2023-11-02 14:54:48,748 DEBUG ++Rcv raw: b'\x81~\x00\xac{"topic":"orderbook.50.BTCUSDC","ts":1698936888663,"type":"delta","data":{"s":"BTCUSDC","b":[["34910.79","0.4192"],["34933.17","0"]],"a":[],"u":20011079,"seq":14108055856}}'
2023-11-02 14:54:48,749 DEBUG ++Rcv decoded: fin=1 opcode=1 data=b'{"topic":"orderbook.50.BTCUSDC","ts":1698936888663,"type":"delta","data":{"s":"BTCUSDC","b":[["34910.79","0.4192"],["34933.17","0"]],"a":[],"u":20011079,"seq":14108055856}}'
2023-11-02 14:54:48,789 DEBUG ++Rcv raw: b'\x81~\x00\xae{"topic":"orderbook.50.BTCUSDC","ts":1698936888703,"type":"delta","data":{"s":"BTCUSDC","b":[],"a":[["34945.27","0.028616"],["34963.76","0"]],"u":20011080,"seq":14108055883}}'
2023-11-02 14:54:48,789 DEBUG ++Rcv decoded: fin=1 opcode=1 data=b'{"topic":"orderbook.50.BTCUSDC","ts":1698936888703,"type":"delta","data":{"s":"BTCUSDC","b":[],"a":[["34945.27","0.028616"],["34963.76","0"]],"u":20011080,"seq":14108055883}}'
2023-11-02 14:54:48,829 DEBUG ++Rcv raw: b'\x81~\x00\xae{"topic":"orderbook.50.BTCUSDC","ts":1698936888744,"type":"delta","data":{"s":"BTCUSDC","b":[],"a":[["34945.26","0.008756"],["34945.28","0"]],"u":20011081,"seq":14108055913}}'
2023-11-02 14:54:48,829 DEBUG ++Rcv decoded: fin=1 opcode=1 data=b'{"topic":"orderbook.50.BTCUSDC","ts":1698936888744,"type":"delta","data":{"s":"BTCUSDC","b":[],"a":[["34945.26","0.008756"],["34945.28","0"]],"u":20011081,"seq":14108055913}}'
2023-11-02 14:54:48,848 DEBUG ++Rcv raw: b'\x81~\x00\xd6{"topic":"orderbook.50.BTCUSDC","ts":1698936888763,"type":"delta","data":{"s":"BTCUSDC","b":[["34941.71","0.098403"],["34940.94","0"]],"a":[["34945.22","0.100345"],["34963.64","0"]],"u":20011082,"seq":14108055924}}'
2023-11-02 14:54:48,849 DEBUG ++Rcv decoded: fin=1 opcode=1 data=b'{"topic":"orderbook.50.BTCUSDC","ts":1698936888763,"type":"delta","data":{"s":"BTCUSDC","b":[["34941.71","0.098403"],["34940.94","0"]],"a":[["34945.22","0.100345"],["34963.64","0"]],"u":20011082,"seq":14108055924}}'
2023-11-02 14:54:48,869 DEBUG ++Rcv raw: b'\x81~\x00\xd7{"topic":"orderbook.50.BTCUSDC","ts":1698936888783,"type":"delta","data":{"s":"BTCUSDC","b":[["34941.72","0.059043"],["34909.72","0.458324"],["34940.96","0"],["34941.71","0"]],"a":[],"u":20011083,"seq":14108055929}}'
2023-11-02 14:54:48,869 DEBUG ++Rcv decoded: fin=1 opcode=1 data=b'{"topic":"orderbook.50.BTCUSDC","ts":1698936888783,"type":"delta","data":{"s":"BTCUSDC","b":[["34941.72","0.059043"],["34909.72","0.458324"],["34940.96","0"],["34941.71","0"]],"a":[],"u":20011083,"seq":14108055929}}'
2023-11-02 14:54:48,889 DEBUG ++Rcv raw: b'\x81~\x00\xd4{"topic":"orderbook.50.BTCUSDC","ts":1698936888803,"type":"delta","data":{"s":"BTCUSDC","b":[["34905.97","0.1875"],["34941.72","0"]],"a":[["34945.21","0.008756"],["34945.26","0"]],"u":20011084,"seq":14108055937}}'
2023-11-02 14:54:48,889 DEBUG ++Rcv decoded: fin=1 opcode=1 data=b'{"topic":"orderbook.50.BTCUSDC","ts":1698936888803,"type":"delta","data":{"s":"BTCUSDC","b":[["34905.97","0.1875"],["34941.72","0"]],"a":[["34945.21","0.008756"],["34945.26","0"]],"u":20011084,"seq":14108055937}}'
2023-11-02 14:54:48,909 DEBUG ++Rcv raw: b'\x81~\x00\xd6{"topic":"orderbook.50.BTCUSDC","ts":1698936888824,"type":"delta","data":{"s":"BTCUSDC","b":[["34940.98","0.057239"],["34940.68","0"]],"a":[["34963.64","0.026078"],["34945.22","0"]],"u":20011085,"seq":14108055943}}'
2023-11-02 14:54:48,910 DEBUG ++Rcv decoded: fin=1 opcode=1 data=b'{"topic":"orderbook.50.BTCUSDC","ts":1698936888824,"type":"delta","data":{"s":"BTCUSDC","b":[["34940.98","0.057239"],["34940.68","0"]],"a":[["34963.64","0.026078"],["34945.22","0"]],"u":20011085,"seq":14108055943}}'
2023-11-02 14:54:48,929 DEBUG ++Rcv raw: b'\x81~\x00\xd4{"topic":"orderbook.50.BTCUSDC","ts":1698936888844,"type":"delta","data":{"s":"BTCUSDC","b":[["34940.99","0.047794"],["34905.97","0"]],"a":[["34963.76","0.1875"],["34945.27","0"]],"u":20011086,"seq":14108055948}}'
2023-11-02 14:54:48,929 DEBUG ++Rcv decoded: fin=1 opcode=1 data=b'{"topic":"orderbook.50.BTCUSDC","ts":1698936888844,"type":"delta","data":{"s":"BTCUSDC","b":[["34940.99","0.047794"],["34905.97","0"]],"a":[["34963.76","0.1875"],["34945.27","0"]],"u":20011086,"seq":14108055948}}'
2023-11-02 14:54:48,949 DEBUG ++Rcv raw: b'\x81~\x00\xae{"topic":"orderbook.50.BTCUSDC","ts":1698936888863,"type":"delta","data":{"s":"BTCUSDC","b":[["34932.35","0.002203"],["34909.72","0"]],"a":[],"u":20011087,"seq":14108055964}}'
2023-11-02 14:54:48,949 DEBUG ++Rcv decoded: fin=1 opcode=1 data=b'{"topic":"orderbook.50.BTCUSDC","ts":1698936888863,"type":"delta","data":{"s":"BTCUSDC","b":[["34932.35","0.002203"],["34909.72","0"]],"a":[],"u":20011087,"seq":14108055964}}'
2023-11-02 14:54:48,969 DEBUG ++Rcv raw: b'\x81~\x00\xae{"topic":"orderbook.50.BTCUSDC","ts":1698936888883,"type":"delta","data":{"s":"BTCUSDC","b":[["34909.72","0.458324"],["34934.08","0"]],"a":[],"u":20011088,"seq":14108055973}}'
2023-11-02 14:54:48,970 DEBUG ++Rcv decoded: fin=1 opcode=1 data=b'{"topic":"orderbook.50.BTCUSDC","ts":1698936888883,"type":"delta","data":{"s":"BTCUSDC","b":[["34909.72","0.458324"],["34934.08","0"]],"a":[],"u":20011088,"seq":14108055973}}'
2023-11-02 14:54:48,989 DEBUG ++Rcv raw: b'\x81~\x00\xac{"topic":"orderbook.50.BTCUSDC","ts":1698936888904,"type":"delta","data":{"s":"BTCUSDC","b":[["34905.97","0.1875"],["34940.95","0"]],"a":[],"u":20011089,"seq":14108055977}}'
2023-11-02 14:54:48,989 DEBUG ++Rcv decoded: fin=1 opcode=1 data=b'{"topic":"orderbook.50.BTCUSDC","ts":1698936888904,"type":"delta","data":{"s":"BTCUSDC","b":[["34905.97","0.1875"],["34940.95","0"]],"a":[],"u":20011089,"seq":14108055977}}'
2023-11-02 14:54:49,009 DEBUG ++Rcv raw: b'\x81~\x00\x9d{"topic":"orderbook.50.BTCUSDC","ts":1698936888924,"type":"delta","data":{"s":"BTCUSDC","b":[["34940.99","0.034347"]],"a":[],"u":20011090,"seq":14108055987}}'
2023-11-02 14:54:49,010 DEBUG ++Rcv decoded: fin=1 opcode=1 data=b'{"topic":"orderbook.50.BTCUSDC","ts":1698936888924,"type":"delta","data":{"s":"BTCUSDC","b":[["34940.99","0.034347"]],"a":[],"u":20011090,"seq":14108055987}}'
2023-11-02 14:54:49,029 DEBUG ++Rcv raw: b'\x81~\x00\xd6{"topic":"orderbook.50.BTCUSDC","ts":1698936888943,"type":"delta","data":{"s":"BTCUSDC","b":[],"a":[["34945.2","0.028616"],["34947.81","0.038425"],["34963.76","0"],["34963.64","0"]],"u":20011091,"seq":14108056001}}'
2023-11-02 14:54:49,029 DEBUG ++Rcv decoded: fin=1 opcode=1 data=b'{"topic":"orderbook.50.BTCUSDC","ts":1698936888943,"type":"delta","data":{"s":"BTCUSDC","b":[],"a":[["34945.2","0.028616"],["34947.81","0.038425"],["34963.76","0"],["34963.64","0"]],"u":20011091,"seq":14108056001}}'
2023-11-02 14:54:49,050 DEBUG ++Rcv raw: b'\x81~\x00\xae{"topic":"orderbook.50.BTCUSDC","ts":1698936888964,"type":"delta","data":{"s":"BTCUSDC","b":[["34925.34","0.114467"],["34938.45","0"]],"a":[],"u":20011092,"seq":14108056016}}'
2023-11-02 14:54:49,050 DEBUG ++Rcv decoded: fin=1 opcode=1 data=b'{"topic":"orderbook.50.BTCUSDC","ts":1698936888964,"type":"delta","data":{"s":"BTCUSDC","b":[["34925.34","0.114467"],["34938.45","0"]],"a":[],"u":20011092,"seq":14108056016}}'
2023-11-02 14:54:49,070 DEBUG ++Rcv raw: b'\x81~\x00\xae{"topic":"orderbook.50.BTCUSDC","ts":1698936888984,"type":"delta","data":{"s":"BTCUSDC","b":[],"a":[["34960.64","0.114467"],["34963.63","0"]],"u":20011093,"seq":14108056026}}'
2023-11-02 14:54:49,070 DEBUG ++Rcv decoded: fin=1 opcode=1 data=b'{"topic":"orderbook.50.BTCUSDC","ts":1698936888984,"type":"delta","data":{"s":"BTCUSDC","b":[],"a":[["34960.64","0.114467"],["34963.63","0"]],"u":20011093,"seq":14108056026}}'
2023-11-02 14:54:49,090 DEBUG ++Rcv raw: b'\x81~\x00\xd7{"topic":"orderbook.50.BTCUSDC","ts":1698936889004,"type":"delta","data":{"s":"BTCUSDC","b":[],"a":[["34945.19","0.008756"],["34963.63","0.112507"],["34961.57","0"],["34945.21","0"]],"u":20011094,"seq":14108056040}}'
2023-11-02 14:54:49,090 DEBUG ++Rcv decoded: fin=1 opcode=1 data=b'{"topic":"orderbook.50.BTCUSDC","ts":1698936889004,"type":"delta","data":{"s":"BTCUSDC","b":[],"a":[["34945.19","0.008756"],["34963.63","0.112507"],["34961.57","0"],["34945.21","0"]],"u":20011094,"seq":14108056040}}'
2023-11-02 14:54:49,109 DEBUG ++Rcv raw: b'\x81~\x00\xfd{"topic":"orderbook.50.BTCUSDC","ts":1698936889024,"type":"delta","data":{"s":"BTCUSDC","b":[["34941.32","0.096575"],["34927.18","0.0859"],["34905.97","0"],["34940.99","0"]],"a":[["34944.82","0.108789"],["34963.63","0"]],"u":20011095,"seq":14108056056}}'
2023-11-02 14:54:49,109 DEBUG ++Rcv decoded: fin=1 opcode=1 data=b'{"topic":"orderbook.50.BTCUSDC","ts":1698936889024,"type":"delta","data":{"s":"BTCUSDC","b":[["34941.32","0.096575"],["34927.18","0.0859"],["34905.97","0"],["34940.99","0"]],"a":[["34944.82","0.108789"],["34963.63","0"]],"u":20011095,"seq":14108056056}}'
2023-11-02 14:54:49,129 DEBUG ++Rcv raw: b'\x81~\x00\xfe{"topic":"orderbook.50.BTCUSDC","ts":1698936889044,"type":"delta","data":{"s":"BTCUSDC","b":[["34941.33","0.092294"],["34925.35","0.068687"],["34909.72","0"],["34941.32","0"]],"a":[["34952.96","0.000476"],["34963.3","0"]],"u":20011096,"seq":14108056072}}'
2023-11-02 14:54:49,129 DEBUG ++Rcv decoded: fin=1 opcode=1 data=b'{"topic":"orderbook.50.BTCUSDC","ts":1698936889044,"type":"delta","data":{"s":"BTCUSDC","b":[["34941.33","0.092294"],["34925.35","0.068687"],["34909.72","0"],["34941.32","0"]],"a":[["34952.96","0.000476"],["34963.3","0"]],"u":20011096,"seq":14108056072}}'
2023-11-02 14:54:49,150 DEBUG ++Rcv raw: b'\x81~\x00\xc2{"topic":"orderbook.50.BTCUSDC","ts":1698936889064,"type":"delta","data":{"s":"BTCUSDC","b":[["34941.33","0.034351"]],"a":[["34963.3","0.0859"],["34954.35","0"]],"u":20011097,"seq":14108056081}}'
2023-11-02 14:54:49,150 DEBUG ++Rcv decoded: fin=1 opcode=1 data=b'{"topic":"orderbook.50.BTCUSDC","ts":1698936889064,"type":"delta","data":{"s":"BTCUSDC","b":[["34941.33","0.034351"]],"a":[["34963.3","0.0859"],["34954.35","0"]],"u":20011097,"seq":14108056081}}'
2023-11-02 14:54:49,169 DEBUG ++Rcv raw: b'\x81~\x00\xae{"topic":"orderbook.50.BTCUSDC","ts":1698936889083,"type":"delta","data":{"s":"BTCUSDC","b":[["34933.18","0.078163"],["34936.36","0"]],"a":[],"u":20011098,"seq":14108056107}}'
2023-11-02 14:54:49,169 DEBUG ++Rcv decoded: fin=1 opcode=1 data=b'{"topic":"orderbook.50.BTCUSDC","ts":1698936889083,"type":"delta","data":{"s":"BTCUSDC","b":[["34933.18","0.078163"],["34936.36","0"]],"a":[],"u":20011098,"seq":14108056107}}'
2023-11-02 14:54:49,189 DEBUG ++Rcv raw: b'\x81~\x00\xdc{"topic":"orderbook.50.BTCUSDC","ts":1698936889103,"type":"delta","data":{"s":"BTCUSDC","b":[["34934.06","0.0859"],["34933.29","0.000261"],["34932.35","0.070916"],["34910.79","0"]],"a":[],"u":20011099,"seq":14108056123}}'
2023-11-02 14:54:49,189 DEBUG ++Rcv decoded: fin=1 opcode=1 data=b'{"topic":"orderbook.50.BTCUSDC","ts":1698936889103,"type":"delta","data":{"s":"BTCUSDC","b":[["34934.06","0.0859"],["34933.29","0.000261"],["34932.35","0.070916"],["34910.79","0"]],"a":[],"u":20011099,"seq":14108056123}}'
2023-11-02 14:54:49,212 DEBUG ++Rcv raw: b'\x81~\x00\xfc{"topic":"orderbook.50.BTCUSDC","ts":1698936889125,"type":"delta","data":{"s":"BTCUSDC","b":[["34910.79","0.4192"],["34905.97","0.1875"],["34905.94","0.189196"],["34932.27","0"],["34921.88","0"],["34934.07","0"]],"a":[],"u":20011100,"seq":14108056145}}'
2023-11-02 14:54:49,212 DEBUG ++Rcv decoded: fin=1 opcode=1 data=b'{"topic":"orderbook.50.BTCUSDC","ts":1698936889125,"type":"delta","data":{"s":"BTCUSDC","b":[["34910.79","0.4192"],["34905.97","0.1875"],["34905.94","0.189196"],["34932.27","0"],["34921.88","0"],["34934.07","0"]],"a":[],"u":20011100,"seq":14108056145}}'
2023-11-02 14:54:49,229 DEBUG ++Rcv raw: b'\x81~\x01){"topic":"orderbook.50.BTCUSDC","ts":1698936889143,"type":"delta","data":{"s":"BTCUSDC","b":[["34933.61","0.114502"],["34931.53","0.002676"],["34923.26","0.286342"],["34912.72","0.458285"],["34905.94","0"],["34911.28","0"],["34910.79","0"],["34905.97","0"]],"a":[],"u":20011101,"seq":14108056172}}'
2023-11-02 14:54:49,229 DEBUG ++Rcv decoded: fin=1 opcode=1 data=b'{"topic":"orderbook.50.BTCUSDC","ts":1698936889143,"type":"delta","data":{"s":"BTCUSDC","b":[["34933.61","0.114502"],["34931.53","0.002676"],["34923.26","0.286342"],["34912.72","0.458285"],["34905.94","0"],["34911.28","0"],["34910.79","0"],["34905.97","0"]],"a":[],"u":20011101,"seq":14108056172}}'
2023-11-02 14:54:49,249 DEBUG ++Rcv raw: b'\x81~\x00\xc5{"topic":"orderbook.50.BTCUSDC","ts":1698936889163,"type":"delta","data":{"s":"BTCUSDC","b":[["34932.35","0.068713"]],"a":[["34963.63","0.112507"],["34958.68","0"]],"u":20011102,"seq":14108056186}}'
2023-11-02 14:54:49,250 DEBUG ++Rcv decoded: fin=1 opcode=1 data=b'{"topic":"orderbook.50.BTCUSDC","ts":1698936889163,"type":"delta","data":{"s":"BTCUSDC","b":[["34932.35","0.068713"]],"a":[["34963.63","0.112507"],["34958.68","0"]],"u":20011102,"seq":14108056186}}'
2023-11-02 14:54:49,268 DEBUG ++Rcv raw: b'\x81~\x00\xae{"topic":"orderbook.50.BTCUSDC","ts":1698936889183,"type":"delta","data":{"s":"BTCUSDC","b":[],"a":[["34957.51","0.114424"],["34963.63","0"]],"u":20011103,"seq":14108056191}}'
2023-11-02 14:54:49,269 DEBUG ++Rcv decoded: fin=1 opcode=1 data=b'{"topic":"orderbook.50.BTCUSDC","ts":1698936889183,"type":"delta","data":{"s":"BTCUSDC","b":[],"a":[["34957.51","0.114424"],["34963.63","0"]],"u":20011103,"seq":14108056191}}'
2023-11-02 14:54:49,289 DEBUG ++Rcv raw: b'\x81~\x00\x9d{"topic":"orderbook.50.BTCUSDC","ts":1698936889203,"type":"delta","data":{"s":"BTCUSDC","b":[],"a":[["34957.92","0.014501"]],"u":20011104,"seq":14108056204}}'
2023-11-02 14:54:49,289 DEBUG ++Rcv decoded: fin=1 opcode=1 data=b'{"topic":"orderbook.50.BTCUSDC","ts":1698936889203,"type":"delta","data":{"s":"BTCUSDC","b":[],"a":[["34957.92","0.014501"]],"u":20011104,"seq":14108056204}}'
2023-11-02 14:54:49,349 DEBUG ++Rcv raw: b'\x81~\x00\xd5{"topic":"orderbook.50.BTCUSDC","ts":1698936889263,"type":"delta","data":{"s":"BTCUSDC","b":[["34937.81","0.014352"],["34912.04","0"]],"a":[["34963.63","0.112507"],["34945.2","0"]],"u":20011105,"seq":14108056240}}'
2023-11-02 14:54:49,349 DEBUG ++Rcv decoded: fin=1 opcode=1 data=b'{"topic":"orderbook.50.BTCUSDC","ts":1698936889263,"type":"delta","data":{"s":"BTCUSDC","b":[["34937.81","0.014352"],["34912.04","0"]],"a":[["34963.63","0.112507"],["34945.2","0"]],"u":20011105,"seq":14108056240}}'
2023-11-02 14:54:49,389 DEBUG ++Rcv raw: b'\x81~\x00\xae{"topic":"orderbook.50.BTCUSDC","ts":1698936889303,"type":"delta","data":{"s":"BTCUSDC","b":[],"a":[["34963.64","0.026078"],["34945.19","0"]],"u":20011106,"seq":14108056259}}'
2023-11-02 14:54:49,389 DEBUG ++Rcv decoded: fin=1 opcode=1 data=b'{"topic":"orderbook.50.BTCUSDC","ts":1698936889303,"type":"delta","data":{"s":"BTCUSDC","b":[],"a":[["34963.64","0.026078"],["34945.19","0"]],"u":20011106,"seq":14108056259}}'
2023-11-02 14:54:49,429 DEBUG ++Rcv raw: b'\x81~\x00\xd0{"topic":"orderbook.50.BTCUSDC","ts":1698936889343,"type":"delta","data":{"s":"BTCUSDC","b":[["34912.04","2.2146"],["34919","0"]],"a":[["34953.99","0.00069"],["34963.64","0"]],"u":20011107,"seq":14108056281}}'
2023-11-02 14:54:49,429 DEBUG ++Rcv decoded: fin=1 opcode=1 data=b'{"topic":"orderbook.50.BTCUSDC","ts":1698936889343,"type":"delta","data":{"s":"BTCUSDC","b":[["34912.04","2.2146"],["34919","0"]],"a":[["34953.99","0.00069"],["34963.64","0"]],"u":20011107,"seq":14108056281}}'
2023-11-02 14:54:49,448 DEBUG ++Rcv raw: b'\x81~\x01g{"topic":"orderbook.50.BTCUSDC","ts":1698936889363,"type":"delta","data":{"s":"BTCUSDC","b":[["34940.87","0.024254"],["34919.42","0.057274"],["34916.71","1.373499"],["34912.05","0"],["34912.04","0"]],"a":[["34944.81","0.028616"],["34963.64","0.026078"],["34963.76","0.1875"],["34944.82","0"],["34952.96","0"],["34950.12","0"]],"u":20011108,"seq":14108056291}}'
2023-11-02 14:54:49,449 DEBUG ++Rcv decoded: fin=1 opcode=1 data=b'{"topic":"orderbook.50.BTCUSDC","ts":1698936889363,"type":"delta","data":{"s":"BTCUSDC","b":[["34940.87","0.024254"],["34919.42","0.057274"],["34916.71","1.373499"],["34912.05","0"],["34912.04","0"]],"a":[["34944.81","0.028616"],["34963.64","0.026078"],["34963.76","0.1875"],["34944.82","0"],["34952.96","0"],["34950.12","0"]],"u":20011108,"seq":14108056291}}'
2023-11-02 14:54:49,469 DEBUG ++Rcv raw: b'\x81~\x00\xd5{"topic":"orderbook.50.BTCUSDC","ts":1698936889383,"type":"delta","data":{"s":"BTCUSDC","b":[["34934.01","0.04312"],["34912.72","0"]],"a":[["34949.51","0.057225"],["34963.76","0"]],"u":20011109,"seq":14108056299}}'
2023-11-02 14:54:49,470 DEBUG ++Rcv decoded: fin=1 opcode=1 data=b'{"topic":"orderbook.50.BTCUSDC","ts":1698936889383,"type":"delta","data":{"s":"BTCUSDC","b":[["34934.01","0.04312"],["34912.72","0"]],"a":[["34949.51","0.057225"],["34963.76","0"]],"u":20011109,"seq":14108056299}}'
2023-11-02 14:54:49,509 DEBUG ++Rcv raw: b'\x81~\x00\xae{"topic":"orderbook.50.BTCUSDC","ts":1698936889424,"type":"delta","data":{"s":"BTCUSDC","b":[["34912.72","0.458285"],["34933.29","0"]],"a":[],"u":20011110,"seq":14108056315}}'
2023-11-02 14:54:49,510 DEBUG ++Rcv decoded: fin=1 opcode=1 data=b'{"topic":"orderbook.50.BTCUSDC","ts":1698936889424,"type":"delta","data":{"s":"BTCUSDC","b":[["34912.72","0.458285"],["34933.29","0"]],"a":[],"u":20011110,"seq":14108056315}}'
2023-11-02 14:54:49,528 DEBUG ++Rcv raw: b'\x81~\x00\xfb{"topic":"orderbook.50.BTCUSDC","ts":1698936889443,"type":"delta","data":{"s":"BTCUSDC","b":[["34912.05","0.98593"],["34912.04","2.2146"],["34941.33","0"],["34927.56","0"]],"a":[["34944.8","0.008756"],["34944.81","0"]],"u":20011111,"seq":14108056330}}'
2023-11-02 14:54:49,529 DEBUG ++Rcv decoded: fin=1 opcode=1 data=b'{"topic":"orderbook.50.BTCUSDC","ts":1698936889443,"type":"delta","data":{"s":"BTCUSDC","b":[["34912.05","0.98593"],["34912.04","2.2146"],["34941.33","0"],["34927.56","0"]],"a":[["34944.8","0.008756"],["34944.81","0"]],"u":20011111,"seq":14108056330}}'
2023-11-02 14:54:49,549 DEBUG ++Rcv raw: b'\x81~\x01\xe5{"topic":"orderbook.50.BTCUSDC","ts":1698936889463,"type":"delta","data":{"s":"BTCUSDC","b":[["34935.59","0.031523"],["34934.07","0.001519"],["34911.28","0.1875"],["34910.79","0.4192"],["34905.97","0.1875"],["34905.94","0.189196"],["34923.26","0"],["34940.98","0"],["34933.61","0"],["34931.31","0"],["34940","0"],["34938.02","0"]],"a":[["34946","0.0324"],["34947.37","0.080588"],["34963.76","0.1875"],["34957.51","0"],["34947.81","0"],["34949.51","0"]],"u":20011112,"seq":14108056374}}'
2023-11-02 14:54:49,549 DEBUG ++Rcv decoded: fin=1 opcode=1 data=b'{"topic":"orderbook.50.BTCUSDC","ts":1698936889463,"type":"delta","data":{"s":"BTCUSDC","b":[["34935.59","0.031523"],["34934.07","0.001519"],["34911.28","0.1875"],["34910.79","0.4192"],["34905.97","0.1875"],["34905.94","0.189196"],["34923.26","0"],["34940.98","0"],["34933.61","0"],["34931.31","0"],["34940","0"],["34938.02","0"]],"a":[["34946","0.0324"],["34947.37","0.080588"],["34963.76","0.1875"],["34957.51","0"],["34947.81","0"],["34949.51","0"]],"u":20011112,"seq":14108056374}}'
2023-11-02 14:54:49,569 DEBUG ++Rcv raw: b'\x81~\x01\xa5{"topic":"orderbook.50.BTCUSDC","ts":1698936889484,"type":"delta","data":{"s":"BTCUSDC","b":[["34938.89","0.057242"],["34934.88","0.001"],["34934.07","0.053061"],["34932.3","0.114507"],["34921.9","0.286353"],["34928.91","0"],["34905.94","0"],["34931.52","0"],["34931.53","0"]],"a":[["34947.05","0.057229"],["34954.42","0.114434"],["34957.92","0.066044"],["34955.97","0"],["34963.76","0"]],"u":20011113,"seq":14108056441}}'
2023-11-02 14:54:49,569 DEBUG ++Rcv decoded: fin=1 opcode=1 data=b'{"topic":"orderbook.50.BTCUSDC","ts":1698936889484,"type":"delta","data":{"s":"BTCUSDC","b":[["34938.89","0.057242"],["34934.88","0.001"],["34934.07","0.053061"],["34932.3","0.114507"],["34921.9","0.286353"],["34928.91","0"],["34905.94","0"],["34931.52","0"],["34931.53","0"]],"a":[["34947.05","0.057229"],["34954.42","0.114434"],["34957.92","0.066044"],["34955.97","0"],["34963.76","0"]],"u":20011113,"seq":14108056441}}'
2023-11-02 14:54:49,589 DEBUG ++Rcv raw: b'\x81~\x01N{"topic":"orderbook.50.BTCUSDC","ts":1698936889504,"type":"delta","data":{"s":"BTCUSDC","b":[["34938.01","0.051544"],["34905.94","0.189196"],["34901.18","0.1875"],["34932.3","0"],["34936.66","0"],["34937.81","0"]],"a":[["34954.35","0.000827"],["34954.69","0.369916"],["34951.49","0"],["34963.64","0"]],"u":20011114,"seq":14108056481}}'
2023-11-02 14:54:49,590 DEBUG ++Rcv decoded: fin=1 opcode=1 data=b'{"topic":"orderbook.50.BTCUSDC","ts":1698936889504,"type":"delta","data":{"s":"BTCUSDC","b":[["34938.01","0.051544"],["34905.94","0.189196"],["34901.18","0.1875"],["34932.3","0"],["34936.66","0"],["34937.81","0"]],"a":[["34954.35","0.000827"],["34954.69","0.369916"],["34951.49","0"],["34963.64","0"]],"u":20011114,"seq":14108056481}}'
2023-11-02 14:54:49,609 DEBUG ++Rcv raw: b'\x81~\x00\xe9{"topic":"orderbook.50.BTCUSDC","ts":1698936889523,"type":"delta","data":{"s":"BTCUSDC","b":[["34900","0.0002"],["34936.37","0"]],"a":[["34954.36","0.207892"],["34963.64","0.026078"],["34953.99","0"]],"u":20011115,"seq":14108056497}}'
2023-11-02 14:54:49,609 DEBUG ++Rcv decoded: fin=1 opcode=1 data=b'{"topic":"orderbook.50.BTCUSDC","ts":1698936889523,"type":"delta","data":{"s":"BTCUSDC","b":[["34900","0.0002"],["34936.37","0"]],"a":[["34954.36","0.207892"],["34963.64","0.026078"],["34953.99","0"]],"u":20011115,"seq":14108056497}}'
2023-11-02 14:54:49,629 DEBUG ++Rcv raw: b'\x81~\x00\xae{"topic":"orderbook.50.BTCUSDC","ts":1698936889543,"type":"delta","data":{"s":"BTCUSDC","b":[],"a":[["34944.79","0.028616"],["34963.64","0"]],"u":20011116,"seq":14108056532}}'
2023-11-02 14:54:49,629 DEBUG ++Rcv decoded: fin=1 opcode=1 data=b'{"topic":"orderbook.50.BTCUSDC","ts":1698936889543,"type":"delta","data":{"s":"BTCUSDC","b":[],"a":[["34944.79","0.028616"],["34963.64","0"]],"u":20011116,"seq":14108056532}}'
2023-11-02 14:54:49,649 DEBUG ++Rcv raw: b'\x81~\x00\xd6{"topic":"orderbook.50.BTCUSDC","ts":1698936889563,"type":"delta","data":{"s":"BTCUSDC","b":[],"a":[["34944.78","0.008756"],["34963.64","0.026078"],["34944.8","0"],["34947.05","0"]],"u":20011117,"seq":14108056547}}'
2023-11-02 14:54:49,650 DEBUG ++Rcv decoded: fin=1 opcode=1 data=b'{"topic":"orderbook.50.BTCUSDC","ts":1698936889563,"type":"delta","data":{"s":"BTCUSDC","b":[],"a":[["34944.78","0.008756"],["34963.64","0.026078"],["34944.8","0"],["34947.05","0"]],"u":20011117,"seq":14108056547}}'
2023-11-02 14:54:49,670 DEBUG ++Rcv raw: b'\x81~\x00\xf7{"topic":"orderbook.50.BTCUSDC","ts":1698936889583,"type":"delta","data":{"s":"BTCUSDC","b":[["34941.16","0.106589"],["34936","0.0324"],["34900","0"],["34901.18","0"]],"a":[["34944.67","0.091344"],["34954.69","0"]],"u":20011118,"seq":14108056567}}'
2023-11-02 14:54:49,670 DEBUG ++Rcv decoded: fin=1 opcode=1 data=b'{"topic":"orderbook.50.BTCUSDC","ts":1698936889583,"type":"delta","data":{"s":"BTCUSDC","b":[["34941.16","0.106589"],["34936","0.0324"],["34900","0"],["34901.18","0"]],"a":[["34944.67","0.091344"],["34954.69","0"]],"u":20011118,"seq":14108056567}}'
2023-11-02 14:54:49,689 DEBUG ++Rcv raw: b'\x81~\x00\xda{"topic":"orderbook.50.BTCUSDC","ts":1698936889603,"type":"delta","data":{"s":"BTCUSDC","b":[["34940.87","0.00154"],["34901.18","0.1875"],["34934.01","0"]],"a":[["34954.36","0.112505"]],"u":20011119,"seq":14108056577}}'
2023-11-02 14:54:49,689 DEBUG ++Rcv decoded: fin=1 opcode=1 data=b'{"topic":"orderbook.50.BTCUSDC","ts":1698936889603,"type":"delta","data":{"s":"BTCUSDC","b":[["34940.87","0.00154"],["34901.18","0.1875"],["34934.01","0"]],"a":[["34954.36","0.112505"]],"u":20011119,"seq":14108056577}}'
2023-11-02 14:54:49,709 DEBUG ++Rcv raw: b'\x81~\x00\xfd{"topic":"orderbook.50.BTCUSDC","ts":1698936889623,"type":"delta","data":{"s":"BTCUSDC","b":[],"a":[["34944.66","0.008756"],["34963.76","0.1875"],["34963.9","0.057201"],["34944.78","0"],["34944.67","0"],["34948.24","0"]],"u":20011120,"seq":14108056596}}'
2023-11-02 14:54:49,709 DEBUG ++Rcv decoded: fin=1 opcode=1 data=b'{"topic":"orderbook.50.BTCUSDC","ts":1698936889623,"type":"delta","data":{"s":"BTCUSDC","b":[],"a":[["34944.66","0.008756"],["34963.76","0.1875"],["34963.9","0.057201"],["34944.78","0"],["34944.67","0"],["34948.24","0"]],"u":20011120,"seq":14108056596}}'
2023-11-02 14:54:49,729 DEBUG ++Rcv raw: b'\x81~\x01\x1f{"topic":"orderbook.50.BTCUSDC","ts":1698936889643,"type":"delta","data":{"s":"BTCUSDC","b":[["34932.36","0.002369"],["34923.59","0.028"],["34905.94","0"],["34901.18","0"]],"a":[["34964","0.0324"],["34964.14","0.02859"],["34944.79","0"],["34949.53","0"]],"u":20011121,"seq":14108056607}}'
2023-11-02 14:54:49,729 DEBUG ++Rcv decoded: fin=1 opcode=1 data=b'{"topic":"orderbook.50.BTCUSDC","ts":1698936889643,"type":"delta","data":{"s":"BTCUSDC","b":[["34932.36","0.002369"],["34923.59","0.028"],["34905.94","0"],["34901.18","0"]],"a":[["34964","0.0324"],["34964.14","0.02859"],["34944.79","0"],["34949.53","0"]],"u":20011121,"seq":14108056607}}'
2023-11-02 14:54:49,750 DEBUG ++Rcv raw: b'\x81~\x00\x9d{"topic":"orderbook.50.BTCUSDC","ts":1698936889664,"type":"delta","data":{"s":"BTCUSDC","b":[["34934.07","0.051542"]],"a":[],"u":20011122,"seq":14108056626}}'
2023-11-02 14:54:49,750 DEBUG ++Rcv decoded: fin=1 opcode=1 data=b'{"topic":"orderbook.50.BTCUSDC","ts":1698936889664,"type":"delta","data":{"s":"BTCUSDC","b":[["34934.07","0.051542"]],"a":[],"u":20011122,"seq":14108056626}}'
2023-11-02 14:54:49,789 DEBUG ++Rcv raw: b'\x81~\x00\xd7{"topic":"orderbook.50.BTCUSDC","ts":1698936889704,"type":"delta","data":{"s":"BTCUSDC","b":[["34940.73","0.022965"],["34933.39","0.042751"],["34905.97","0"],["34910.79","0"]],"a":[],"u":20011123,"seq":14108056658}}'
2023-11-02 14:54:49,790 DEBUG ++Rcv decoded: fin=1 opcode=1 data=b'{"topic":"orderbook.50.BTCUSDC","ts":1698936889704,"type":"delta","data":{"s":"BTCUSDC","b":[["34940.73","0.022965"],["34933.39","0.042751"],["34905.97","0"],["34910.79","0"]],"a":[],"u":20011123,"seq":14108056658}}'
2023-11-02 14:54:49,809 DEBUG ++Rcv raw: b'\x81~\x00\xd4{"topic":"orderbook.50.BTCUSDC","ts":1698936889723,"type":"delta","data":{"s":"BTCUSDC","b":[["34931.15","0.11451"],["34933.39","0"]],"a":[["34947.2","0.057229"],["34964.14","0"]],"u":20011124,"seq":14108056667}}'
2023-11-02 14:54:49,809 DEBUG ++Rcv decoded: fin=1 opcode=1 data=b'{"topic":"orderbook.50.BTCUSDC","ts":1698936889723,"type":"delta","data":{"s":"BTCUSDC","b":[["34931.15","0.11451"],["34933.39","0"]],"a":[["34947.2","0.057229"],["34964.14","0"]],"u":20011124,"seq":14108056667}}'
2023-11-02 14:54:49,828 DEBUG ++Rcv raw: b'\x81~\x00\xae{"topic":"orderbook.50.BTCUSDC","ts":1698936889743,"type":"delta","data":{"s":"BTCUSDC","b":[["34937.24","0.014356"],["34911.28","0"]],"a":[],"u":20011125,"seq":14108056679}}'
2023-11-02 14:54:49,829 DEBUG ++Rcv decoded: fin=1 opcode=1 data=b'{"topic":"orderbook.50.BTCUSDC","ts":1698936889743,"type":"delta","data":{"s":"BTCUSDC","b":[["34937.24","0.014356"],["34911.28","0"]],"a":[],"u":20011125,"seq":14108056679}}'
2023-11-02 14:54:49,849 DEBUG ++Rcv raw: b'\x81~\x00\xac{"topic":"orderbook.50.BTCUSDC","ts":1698936889763,"type":"delta","data":{"s":"BTCUSDC","b":[["34911.28","0.1875"],["34937.24","0"]],"a":[],"u":20011126,"seq":14108056688}}'
2023-11-02 14:54:49,849 DEBUG ++Rcv decoded: fin=1 opcode=1 data=b'{"topic":"orderbook.50.BTCUSDC","ts":1698936889763,"type":"delta","data":{"s":"BTCUSDC","b":[["34911.28","0.1875"],["34937.24","0"]],"a":[],"u":20011126,"seq":14108056688}}'
2023-11-02 14:54:49,869 DEBUG ++Rcv raw: b'\x81~\x00\xae{"topic":"orderbook.50.BTCUSDC","ts":1698936889783,"type":"delta","data":{"s":"BTCUSDC","b":[["34929.03","0.000261"],["34911.28","0"]],"a":[],"u":20011127,"seq":14108056703}}'
2023-11-02 14:54:49,869 DEBUG ++Rcv decoded: fin=1 opcode=1 data=b'{"topic":"orderbook.50.BTCUSDC","ts":1698936889783,"type":"delta","data":{"s":"BTCUSDC","b":[["34929.03","0.000261"],["34911.28","0"]],"a":[],"u":20011127,"seq":14108056703}}'
2023-11-02 14:54:49,889 DEBUG ++Rcv raw: b'\x81~\x00\xab{"topic":"orderbook.50.BTCUSDC","ts":1698936889803,"type":"delta","data":{"s":"BTCUSDC","b":[],"a":[["34954.34","0.368317"],["34964","0"]],"u":20011128,"seq":14108056719}}'
2023-11-02 14:54:49,890 DEBUG ++Rcv decoded: fin=1 opcode=1 data=b'{"topic":"orderbook.50.BTCUSDC","ts":1698936889803,"type":"delta","data":{"s":"BTCUSDC","b":[],"a":[["34954.34","0.368317"],["34964","0"]],"u":20011128,"seq":14108056719}}'
2023-11-02 14:54:49,909 DEBUG ++Rcv raw: b'\x81~\x00\xae{"topic":"orderbook.50.BTCUSDC","ts":1698936889824,"type":"delta","data":{"s":"BTCUSDC","b":[],"a":[["34954.33","0.220997"],["34954.36","0"]],"u":20011129,"seq":14108056724}}'
2023-11-02 14:54:49,909 DEBUG ++Rcv decoded: fin=1 opcode=1 data=b'{"topic":"orderbook.50.BTCUSDC","ts":1698936889824,"type":"delta","data":{"s":"BTCUSDC","b":[],"a":[["34954.33","0.220997"],["34954.36","0"]],"u":20011129,"seq":14108056724}}'
2023-11-02 14:54:49,929 DEBUG ++Rcv raw: b'\x81~\x00\xad{"topic":"orderbook.50.BTCUSDC","ts":1698936889843,"type":"delta","data":{"s":"BTCUSDC","b":[],"a":[["34954.32","0.001237"],["34963.9","0"]],"u":20011130,"seq":14108056734}}'
2023-11-02 14:54:49,929 DEBUG ++Rcv decoded: fin=1 opcode=1 data=b'{"topic":"orderbook.50.BTCUSDC","ts":1698936889843,"type":"delta","data":{"s":"BTCUSDC","b":[],"a":[["34954.32","0.001237"],["34963.9","0"]],"u":20011130,"seq":14108056734}}'
2023-11-02 14:54:49,949 DEBUG ++Rcv raw: b'\x81~\x00\xd1{"topic":"orderbook.50.BTCUSDC","ts":1698936889863,"type":"delta","data":{"s":"BTCUSDC","b":[],"a":[["34963.9","0.057201"],["34964","0.0324"],["34944.66","0"],["34954.35","0"]],"u":20011131,"seq":14108056754}}'
2023-11-02 14:54:49,949 DEBUG ++Rcv decoded: fin=1 opcode=1 data=b'{"topic":"orderbook.50.BTCUSDC","ts":1698936889863,"type":"delta","data":{"s":"BTCUSDC","b":[],"a":[["34963.9","0.057201"],["34964","0.0324"],["34944.66","0"],["34954.35","0"]],"u":20011131,"seq":14108056754}}'
2023-11-02 14:54:49,969 DEBUG ++Rcv raw: b'\x81~\x01F{"topic":"orderbook.50.BTCUSDC","ts":1698936889884,"type":"delta","data":{"s":"BTCUSDC","b":[["34911.28","0.1875"],["34910.79","0.4192"],["34905.97","0.1875"],["34938.89","0"],["34931.15","0"],["34921.9","0"]],"a":[["34944.65","0.028616"],["34945.29","0.097823"],["34964","0"],["34947.2","0"]],"u":20011132,"seq":14108056770}}'
2023-11-02 14:54:49,969 DEBUG ++Rcv decoded: fin=1 opcode=1 data=b'{"topic":"orderbook.50.BTCUSDC","ts":1698936889884,"type":"delta","data":{"s":"BTCUSDC","b":[["34911.28","0.1875"],["34910.79","0.4192"],["34905.97","0.1875"],["34938.89","0"],["34931.15","0"],["34921.9","0"]],"a":[["34944.65","0.028616"],["34945.29","0.097823"],["34964","0"],["34947.2","0"]],"u":20011132,"seq":14108056770}}'
2023-11-02 14:54:49,989 DEBUG ++Rcv raw: b'\x81~\x01P{"topic":"orderbook.50.BTCUSDC","ts":1698936889904,"type":"delta","data":{"s":"BTCUSDC","b":[["34940.18","0.05724"],["34936.01","0.051548"],["34932.98","0.114504"],["34923.02","0.286344"],["34911.28","0"],["34905.97","0"],["34910.79","0"],["34938.01","0"]],"a":[["34948.14","0.057227"],["34945.29","0"]],"u":20011133,"seq":14108056785}}'
2023-11-02 14:54:49,990 DEBUG ++Rcv decoded: fin=1 opcode=1 data=b'{"topic":"orderbook.50.BTCUSDC","ts":1698936889904,"type":"delta","data":{"s":"BTCUSDC","b":[["34940.18","0.05724"],["34936.01","0.051548"],["34932.98","0.114504"],["34923.02","0.286344"],["34911.28","0"],["34905.97","0"],["34910.79","0"],["34938.01","0"]],"a":[["34948.14","0.057227"],["34945.29","0"]],"u":20011133,"seq":14108056785}}'
2023-11-02 14:54:50,009 DEBUG ++Rcv raw: b'\x81~\x00\xd4{"topic":"orderbook.50.BTCUSDC","ts":1698936889924,"type":"delta","data":{"s":"BTCUSDC","b":[["34932.99","0.068711"],["34932.35","0"]],"a":[["34949.53","0.05154"],["34963.9","0"]],"u":20011134,"seq":14108056797}}'
2023-11-02 14:54:50,009 DEBUG ++Rcv decoded: fin=1 opcode=1 data=b'{"topic":"orderbook.50.BTCUSDC","ts":1698936889924,"type":"delta","data":{"s":"BTCUSDC","b":[["34932.99","0.068711"],["34932.35","0"]],"a":[["34949.53","0.05154"],["34963.9","0"]],"u":20011134,"seq":14108056797}}'
2023-11-02 14:54:50,050 DEBUG ++Rcv raw: b'\x81~\x00\xd5{"topic":"orderbook.50.BTCUSDC","ts":1698936889964,"type":"delta","data":{"s":"BTCUSDC","b":[["34929.06","0.000261"],["34912.04","0"]],"a":[["34963.9","0.057201"],["34954.42","0"]],"u":20011135,"seq":14108056826}}'
2023-11-02 14:54:50,050 DEBUG ++Rcv decoded: fin=1 opcode=1 data=b'{"topic":"orderbook.50.BTCUSDC","ts":1698936889964,"type":"delta","data":{"s":"BTCUSDC","b":[["34929.06","0.000261"],["34912.04","0"]],"a":[["34963.9","0.057201"],["34954.42","0"]],"u":20011135,"seq":14108056826}}'
2023-11-02 14:54:50,069 DEBUG ++Rcv raw: b'\x81~\x00\xd4{"topic":"orderbook.50.BTCUSDC","ts":1698936889983,"type":"delta","data":{"s":"BTCUSDC","b":[],"a":[["34945.99","0.008756"],["34955.8","0.11443"],["34963.9","0"],["34944.65","0"]],"u":20011136,"seq":14108056847}}'
2023-11-02 14:54:50,069 DEBUG ++Rcv decoded: fin=1 opcode=1 data=b'{"topic":"orderbook.50.BTCUSDC","ts":1698936889983,"type":"delta","data":{"s":"BTCUSDC","b":[],"a":[["34945.99","0.008756"],["34955.8","0.11443"],["34963.9","0"],["34944.65","0"]],"u":20011136,"seq":14108056847}}'
2023-11-02 14:54:50,128 DEBUG ++Rcv raw: b'\x81~\x00\xae{"topic":"orderbook.50.BTCUSDC","ts":1698936890043,"type":"delta","data":{"s":"BTCUSDC","b":[["34933.19","0.001559"],["34912.05","0"]],"a":[],"u":20011137,"seq":14108056869}}'
2023-11-02 14:54:50,129 DEBUG ++Rcv decoded: fin=1 opcode=1 data=b'{"topic":"orderbook.50.BTCUSDC","ts":1698936890043,"type":"delta","data":{"s":"BTCUSDC","b":[["34933.19","0.001559"],["34912.05","0"]],"a":[],"u":20011137,"seq":14108056869}}'
2023-11-02 14:54:50,149 DEBUG ++Rcv raw: b'\x81~\x01#{"topic":"orderbook.50.BTCUSDC","ts":1698936890063,"type":"delta","data":{"s":"BTCUSDC","b":[["34940.99","0.057239"],["34912.05","0.98593"],["34940.18","0"],["34932.36","0"]],"a":[["34948.94","0.057226"],["34963.9","0.057201"],["34946","0"],["34948.14","0"]],"u":20011138,"seq":14108056890}}'
2023-11-02 14:54:50,149 DEBUG ++Rcv decoded: fin=1 opcode=1 data=b'{"topic":"orderbook.50.BTCUSDC","ts":1698936890063,"type":"delta","data":{"s":"BTCUSDC","b":[["34940.99","0.057239"],["34912.05","0.98593"],["34940.18","0"],["34932.36","0"]],"a":[["34948.94","0.057226"],["34963.9","0.057201"],["34946","0"],["34948.14","0"]],"u":20011138,"seq":14108056890}}'
2023-11-02 14:54:50,169 DEBUG ++Rcv raw: b'\x81~\x00\xfa{"topic":"orderbook.50.BTCUSDC","ts":1698936890084,"type":"delta","data":{"s":"BTCUSDC","b":[["34933.38","0.042412"],["34912.05","0"]],"a":[["34945.98","0.028615"],["34964","0.0324"],["34954.34","0"],["34949.53","0"]],"u":20011139,"seq":14108056902}}'
2023-11-02 14:54:50,170 DEBUG ++Rcv decoded: fin=1 opcode=1 data=b'{"topic":"orderbook.50.BTCUSDC","ts":1698936890084,"type":"delta","data":{"s":"BTCUSDC","b":[["34933.38","0.042412"],["34912.05","0"]],"a":[["34945.98","0.028615"],["34964","0.0324"],["34954.34","0"],["34949.53","0"]],"u":20011139,"seq":14108056902}}'
2023-11-02 14:54:50,189 DEBUG ++Rcv raw: b'\x81~\x01,{"topic":"orderbook.50.BTCUSDC","ts":1698936890104,"type":"delta","data":{"s":"BTCUSDC","b":[],"a":[["34945.17","0.008756"],["34945.18","0.104615"],["34945.98","0.058615"],["34954.33","0.112501"],["34954.69","0.368473"],["34963.9","0"],["34964","0"],["34945.99","0"]],"u":20011140,"seq":14108056920}}'
2023-11-02 14:54:50,189 DEBUG ++Rcv decoded: fin=1 opcode=1 data=b'{"topic":"orderbook.50.BTCUSDC","ts":1698936890104,"type":"delta","data":{"s":"BTCUSDC","b":[],"a":[["34945.17","0.008756"],["34945.18","0.104615"],["34945.98","0.058615"],["34954.33","0.112501"],["34954.69","0.368473"],["34963.9","0"],["34964","0"],["34945.99","0"]],"u":20011140,"seq":14108056920}}'
2023-11-02 14:54:50,209 DEBUG ++Rcv raw: b'\x81~\x00\xe9{"topic":"orderbook.50.BTCUSDC","ts":1698936890123,"type":"delta","data":{"s":"BTCUSDC","b":[],"a":[["34954.33","0.207023"],["34963.9","0.057201"],["34964","0.0324"],["34945.18","0"],["34961.11","0"]],"u":20011141,"seq":14108056933}}'
2023-11-02 14:54:50,209 DEBUG ++Rcv decoded: fin=1 opcode=1 data=b'{"topic":"orderbook.50.BTCUSDC","ts":1698936890123,"type":"delta","data":{"s":"BTCUSDC","b":[],"a":[["34954.33","0.207023"],["34963.9","0.057201"],["34964","0.0324"],["34945.18","0"],["34961.11","0"]],"u":20011141,"seq":14108056933}}'
2023-11-02 14:54:50,270 DEBUG ++Rcv raw: b'\x81~\x00\xad{"topic":"orderbook.50.BTCUSDC","ts":1698936890184,"type":"delta","data":{"s":"BTCUSDC","b":[["34912.05","0.98593"],["34929.03","0"]],"a":[],"u":20011142,"seq":14108056990}}'
2023-11-02 14:54:50,270 DEBUG ++Rcv decoded: fin=1 opcode=1 data=b'{"topic":"orderbook.50.BTCUSDC","ts":1698936890184,"type":"delta","data":{"s":"BTCUSDC","b":[["34912.05","0.98593"],["34929.03","0"]],"a":[],"u":20011142,"seq":14108056990}}'
2023-11-02 14:54:50,289 DEBUG ++Rcv raw: b'\x81~\x01\x0f{"topic":"orderbook.50.BTCUSDC","ts":1698936890203,"type":"delta","data":{"s":"BTCUSDC","b":[["34930.63","0.051543"],["34912.04","2.2146"],["34911.28","0.1875"],["34932.98","0"],["34914.71","0"],["34940.99","0"]],"a":[["34945.98","0.03"]],"u":20011143,"seq":14108057017}}'
2023-11-02 14:54:50,289 DEBUG ++Rcv decoded: fin=1 opcode=1 data=b'{"topic":"orderbook.50.BTCUSDC","ts":1698936890203,"type":"delta","data":{"s":"BTCUSDC","b":[["34930.63","0.051543"],["34912.04","2.2146"],["34911.28","0.1875"],["34932.98","0"],["34914.71","0"],["34940.99","0"]],"a":[["34945.98","0.03"]],"u":20011143,"seq":14108057017}}'
2023-11-02 14:54:50,309 DEBUG ++Rcv raw: b'\x81~\x01&{"topic":"orderbook.50.BTCUSDC","ts":1698936890223,"type":"delta","data":{"s":"BTCUSDC","b":[["34941.24","0.057238"],["34934.37","0.1145"],["34924.68","0.28633"],["34920.32","0.049064"],["34923.02","0"],["34930.63","0"],["34911.28","0"],["34941.16","0"]],"a":[],"u":20011144,"seq":14108057051}}'
2023-11-02 14:54:50,309 DEBUG ++Rcv decoded: fin=1 opcode=1 data=b'{"topic":"orderbook.50.BTCUSDC","ts":1698936890223,"type":"delta","data":{"s":"BTCUSDC","b":[["34941.24","0.057238"],["34934.37","0.1145"],["34924.68","0.28633"],["34920.32","0.049064"],["34923.02","0"],["34930.63","0"],["34911.28","0"],["34941.16","0"]],"a":[],"u":20011144,"seq":14108057051}}'
2023-11-02 14:54:50,330 DEBUG ++Rcv raw: b'\x81~\x00\xd7{"topic":"orderbook.50.BTCUSDC","ts":1698936890244,"type":"delta","data":{"s":"BTCUSDC","b":[["34936.02","0.001808"],["34934.38","0.068706"],["34934.07","0"],["34912.04","0"]],"a":[],"u":20011145,"seq":14108057072}}'
2023-11-02 14:54:50,330 DEBUG ++Rcv decoded: fin=1 opcode=1 data=b'{"topic":"orderbook.50.BTCUSDC","ts":1698936890244,"type":"delta","data":{"s":"BTCUSDC","b":[["34936.02","0.001808"],["34934.38","0.068706"],["34934.07","0"],["34912.04","0"]],"a":[],"u":20011145,"seq":14108057072}}'
2023-11-02 14:54:50,349 DEBUG ++Rcv raw: b'\x81~\x00\xac{"topic":"orderbook.50.BTCUSDC","ts":1698936890263,"type":"delta","data":{"s":"BTCUSDC","b":[["34912.04","2.2146"],["34933.19","0"]],"a":[],"u":20011146,"seq":14108057088}}'
2023-11-02 14:54:50,349 DEBUG ++Rcv decoded: fin=1 opcode=1 data=b'{"topic":"orderbook.50.BTCUSDC","ts":1698936890263,"type":"delta","data":{"s":"BTCUSDC","b":[["34912.04","2.2146"],["34933.19","0"]],"a":[],"u":20011146,"seq":14108057088}}'
2023-11-02 14:54:50,369 DEBUG ++Rcv raw: b'\x81~\x00\xab{"topic":"orderbook.50.BTCUSDC","ts":1698936890283,"type":"delta","data":{"s":"BTCUSDC","b":[],"a":[["34945.16","0.028616"],["34964","0"]],"u":20011147,"seq":14108057107}}'
2023-11-02 14:54:50,369 DEBUG ++Rcv decoded: fin=1 opcode=1 data=b'{"topic":"orderbook.50.BTCUSDC","ts":1698936890283,"type":"delta","data":{"s":"BTCUSDC","b":[],"a":[["34945.16","0.028616"],["34964","0"]],"u":20011147,"seq":14108057107}}'
2023-11-02 14:54:50,469 DEBUG ++Rcv raw: b'\x81~\x00\xd2{"topic":"orderbook.50.BTCUSDC","ts":1698936890383,"type":"delta","data":{"s":"BTCUSDC","b":[],"a":[["34945.15","0.008756"],["34964","0.0324"],["34945.17","0"],["34954.69","0"]],"u":20011148,"seq":14108057167}}'
2023-11-02 14:54:50,469 DEBUG ++Rcv decoded: fin=1 opcode=1 data=b'{"topic":"orderbook.50.BTCUSDC","ts":1698936890383,"type":"delta","data":{"s":"BTCUSDC","b":[],"a":[["34945.15","0.008756"],["34964","0.0324"],["34945.17","0"],["34954.69","0"]],"u":20011148,"seq":14108057167}}'
2023-11-02 14:54:50,488 DEBUG ++Rcv raw: b'\x81~\x00\x9d{"topic":"orderbook.50.BTCUSDC","ts":1698936890403,"type":"delta","data":{"s":"BTCUSDC","b":[],"a":[["34954.33","0.112501"]],"u":20011149,"seq":14108057177}}'
2023-11-02 14:54:50,489 DEBUG ++Rcv decoded: fin=1 opcode=1 data=b'{"topic":"orderbook.50.BTCUSDC","ts":1698936890403,"type":"delta","data":{"s":"BTCUSDC","b":[],"a":[["34954.33","0.112501"]],"u":20011149,"seq":14108057177}}'
2023-11-02 14:54:50,509 DEBUG ++Rcv raw: b'\x81~\x00\xab{"topic":"orderbook.50.BTCUSDC","ts":1698936890424,"type":"delta","data":{"s":"BTCUSDC","b":[],"a":[["34954.36","0.356176"],["34964","0"]],"u":20011150,"seq":14108057191}}'
2023-11-02 14:54:50,510 DEBUG ++Rcv decoded: fin=1 opcode=1 data=b'{"topic":"orderbook.50.BTCUSDC","ts":1698936890424,"type":"delta","data":{"s":"BTCUSDC","b":[],"a":[["34954.36","0.356176"],["34964","0"]],"u":20011150,"seq":14108057191}}'
2023-11-02 14:54:50,530 DEBUG ++Rcv raw: b'\x81~\x00\x9c{"topic":"orderbook.50.BTCUSDC","ts":1698936890444,"type":"delta","data":{"s":"BTCUSDC","b":[],"a":[["34954.33","0.19965"]],"u":20011151,"seq":14108057200}}'
2023-11-02 14:54:50,530 DEBUG ++Rcv decoded: fin=1 opcode=1 data=b'{"topic":"orderbook.50.BTCUSDC","ts":1698936890444,"type":"delta","data":{"s":"BTCUSDC","b":[],"a":[["34954.33","0.19965"]],"u":20011151,"seq":14108057200}}'
2023-11-02 14:54:50,549 DEBUG ++Rcv raw: b'\x81~\x01\x87{"topic":"orderbook.50.BTCUSDC","ts":1698936890463,"type":"delta","data":{"s":"BTCUSDC","b":[["34940.73","0.017819"],["34911.28","0.1875"],["34910.79","0.4192"],["34909.83","0.149811"],["34940.87","0"],["34939.22","0"],["34941.24","0"]],"a":[["34943.58","0.09563"],["34946.1","0.0859"],["34950.58","0.1875"],["34963.9","0"],["34963.64","0"],["34963.76","0"]],"u":20011152,"seq":14108057240}}'
2023-11-02 14:54:50,550 DEBUG ++Rcv decoded: fin=1 opcode=1 data=b'{"topic":"orderbook.50.BTCUSDC","ts":1698936890463,"type":"delta","data":{"s":"BTCUSDC","b":[["34940.73","0.017819"],["34911.28","0.1875"],["34910.79","0.4192"],["34909.83","0.149811"],["34940.87","0"],["34939.22","0"],["34941.24","0"]],"a":[["34943.58","0.09563"],["34946.1","0.0859"],["34950.58","0.1875"],["34963.9","0"],["34963.64","0"],["34963.76","0"]],"u":20011152,"seq":14108057240}}'
2023-11-02 14:54:50,568 DEBUG ++Rcv raw: b'\x81~\x01\x8b{"topic":"orderbook.50.BTCUSDC","ts":1698936890483,"type":"delta","data":{"s":"BTCUSDC","b":[["34938.01","0.070988"],["34905.97","0.1875"],["34901.18","0.1875"],["34939.23","0"],["34923.59","0"],["34936.01","0"]],"a":[["34943.57","0.008756"],["34943.58","0.002"],["34950.57","0.112509"],["34963.64","0.026078"],["34951.25","0"],["34945.15","0"],["34945.16","0"]],"u":20011153,"seq":14108057270}}'
2023-11-02 14:54:50,569 DEBUG ++Rcv decoded: fin=1 opcode=1 data=b'{"topic":"orderbook.50.BTCUSDC","ts":1698936890483,"type":"delta","data":{"s":"BTCUSDC","b":[["34938.01","0.070988"],["34905.97","0.1875"],["34901.18","0.1875"],["34939.23","0"],["34923.59","0"],["34936.01","0"]],"a":[["34943.57","0.008756"],["34943.58","0.002"],["34950.57","0.112509"],["34963.64","0.026078"],["34951.25","0"],["34945.15","0"],["34945.16","0"]],"u":20011153,"seq":14108057270}}'
2023-11-02 14:54:50,591 DEBUG ++Rcv raw: b'\x81~\x01D{"topic":"orderbook.50.BTCUSDC","ts":1698936890504,"type":"delta","data":{"s":"BTCUSDC","b":[["34900","0.0002"],["34899","0.000286"],["34896.95","0.255551"],["34934.88","0"],["34940.73","0"],["34935.79","0"]],"a":[["34943.56","0.037532"],["34946","0.0324"],["34948.94","0"],["34963.64","0"]],"u":20011154,"seq":14108057304}}'
2023-11-02 14:54:50,591 DEBUG ++Rcv decoded: fin=1 opcode=1 data=b'{"topic":"orderbook.50.BTCUSDC","ts":1698936890504,"type":"delta","data":{"s":"BTCUSDC","b":[["34900","0.0002"],["34899","0.000286"],["34896.95","0.255551"],["34934.88","0"],["34940.73","0"],["34935.79","0"]],"a":[["34943.56","0.037532"],["34946","0.0324"],["34948.94","0"],["34963.64","0"]],"u":20011154,"seq":14108057304}}'
2023-11-02 14:54:50,609 DEBUG ++Rcv raw: b'\x81~\x01\xbf{"topic":"orderbook.50.BTCUSDC","ts":1698936890524,"type":"delta","data":{"s":"BTCUSDC","b":[["34928.91","0.05154"],["34898.62","2.2123"],["34896.94","0.425906"],["34922.09","0"],["34936.57","0"],["34938","0"]],"a":[["34943.55","0.008756"],["34944","0.0324"],["34945.97","0.06674"],["34948.37","0.057227"],["34949.53","0.051542"],["34963.63","0"],["34943.57","0"],["34955.8","0"],["34943.56","0"],["34947.37","0"]],"u":20011155,"seq":14108057364}}'
2023-11-02 14:54:50,609 DEBUG ++Rcv decoded: fin=1 opcode=1 data=b'{"topic":"orderbook.50.BTCUSDC","ts":1698936890524,"type":"delta","data":{"s":"BTCUSDC","b":[["34928.91","0.05154"],["34898.62","2.2123"],["34896.94","0.425906"],["34922.09","0"],["34936.57","0"],["34938","0"]],"a":[["34943.55","0.008756"],["34944","0.0324"],["34945.97","0.06674"],["34948.37","0.057227"],["34949.53","0.051542"],["34963.63","0"],["34943.57","0"],["34955.8","0"],["34943.56","0"],["34947.37","0"]],"u":20011155,"seq":14108057364}}'
2023-11-02 14:54:50,630 DEBUG ++Rcv raw: b'\x81~\x01f{"topic":"orderbook.50.BTCUSDC","ts":1698936890543,"type":"delta","data":{"s":"BTCUSDC","b":[["34938.01","0.051543"],["34933.12","0.00057"],["34898.63","1.246124"],["34896.88","0.1875"],["34893.07","0.028602"],["34934.37","0"],["34896.95","0"],["34924.68","0"],["34922.64","0"]],"a":[["34963.63","0.112507"],["34948.37","0"]],"u":20011156,"seq":14108057435}}'
2023-11-02 14:54:50,631 DEBUG ++Rcv decoded: fin=1 opcode=1 data=b'{"topic":"orderbook.50.BTCUSDC","ts":1698936890543,"type":"delta","data":{"s":"BTCUSDC","b":[["34938.01","0.051543"],["34933.12","0.00057"],["34898.63","1.246124"],["34896.88","0.1875"],["34893.07","0.028602"],["34934.37","0"],["34896.95","0"],["34924.68","0"],["34922.64","0"]],"a":[["34963.63","0.112507"],["34948.37","0"]],"u":20011156,"seq":14108057435}}'
2023-11-02 14:54:50,649 DEBUG ++Rcv raw: b'\x81~\x01\'{"topic":"orderbook.50.BTCUSDC","ts":1698936890564,"type":"delta","data":{"s":"BTCUSDC","b":[["34937.04","0.01423"],["34932.72","0.114505"],["34923.15","0.286342"],["34896.88","0"],["34893.07","0"],["34896.94","0"]],"a":[["34949.52","0.001114"],["34954.32","0"]],"u":20011157,"seq":14108057474}}'
2023-11-02 14:54:50,649 DEBUG ++Rcv decoded: fin=1 opcode=1 data=b'{"topic":"orderbook.50.BTCUSDC","ts":1698936890564,"type":"delta","data":{"s":"BTCUSDC","b":[["34937.04","0.01423"],["34932.72","0.114505"],["34923.15","0.286342"],["34896.88","0"],["34893.07","0"],["34896.94","0"]],"a":[["34949.52","0.001114"],["34954.32","0"]],"u":20011157,"seq":14108057474}}'
2023-11-02 14:54:50,669 DEBUG ++Rcv raw: b'\x81~\x01\x9d{"topic":"orderbook.50.BTCUSDC","ts":1698936890583,"type":"delta","data":{"s":"BTCUSDC","b":[["34930.63","0.051545"],["34896.94","0.425906"],["34896.88","0.1875"],["34893.07","0.028602"],["34891.59","0.112505"],["34937.04","0"],["34928.91","0"],["34937.5","0"],["34932.72","0"],["34923.15","0"]],"a":[["34943.56","0.028617"],["34944.38","0.0859"],["34963.3","0"],["34954.36","0"]],"u":20011158,"seq":14108057506}}'
2023-11-02 14:54:50,669 DEBUG ++Rcv decoded: fin=1 opcode=1 data=b'{"topic":"orderbook.50.BTCUSDC","ts":1698936890583,"type":"delta","data":{"s":"BTCUSDC","b":[["34930.63","0.051545"],["34896.94","0.425906"],["34896.88","0.1875"],["34893.07","0.028602"],["34891.59","0.112505"],["34937.04","0"],["34928.91","0"],["34937.5","0"],["34932.72","0"],["34923.15","0"]],"a":[["34943.56","0.028617"],["34944.38","0.0859"],["34963.3","0"],["34954.36","0"]],"u":20011158,"seq":14108057506}}'
2023-11-02 14:54:50,689 DEBUG ++Rcv raw: b'\x81~\x01\x8e{"topic":"orderbook.50.BTCUSDC","ts":1698936890603,"type":"delta","data":{"s":"BTCUSDC","b":[["34936.01","0.070986"],["34933.22","0.028619"],["34929.77","0.04432"],["34928.91","0.051547"],["34929.06","0"],["34938.01","0"],["34891.59","0"],["34930.63","0"]],"a":[["34944.37","0.025664"],["34954.33","0.112501"],["34963.64","0.026078"],["34944","0"],["34963.29","0"]],"u":20011159,"seq":14108057537}}'
2023-11-02 14:54:50,689 DEBUG ++Rcv decoded: fin=1 opcode=1 data=b'{"topic":"orderbook.50.BTCUSDC","ts":1698936890603,"type":"delta","data":{"s":"BTCUSDC","b":[["34936.01","0.070986"],["34933.22","0.028619"],["34929.77","0.04432"],["34928.91","0.051547"],["34929.06","0"],["34938.01","0"],["34891.59","0"],["34930.63","0"]],"a":[["34944.37","0.025664"],["34954.33","0.112501"],["34963.64","0.026078"],["34944","0"],["34963.29","0"]],"u":20011159,"seq":14108057537}}'
2023-11-02 14:54:50,709 DEBUG ++Rcv raw: b'\x81~\x01<{"topic":"orderbook.50.BTCUSDC","ts":1698936890624,"type":"delta","data":{"s":"BTCUSDC","b":[["34891.59","0.112505"],["34891.58","0.1875"],["34933.18","0"],["34933.12","0"]],"a":[["34944.37","0.048341"],["34947.37","0.080159"],["34963.76","0.1875"],["34949.53","0"],["34945.97","0"]],"u":20011160,"seq":14108057564}}'
