2023-11-02 14:54:33,489 DEBUG ++Rcv decoded: fin=1 opcode=1 data=b'{"topic":"orderbook.50.BTCUSDC","ts":1698936873404,"type":"delta","data":{"s":"BTCUSDC","b":[["34950.96","0.1875"],["34955.8","0"]],"a":[["34964.62","0.03"],["34968.91","0"]],"u":20010541,"seq":14108044625}}'
2023-11-02 14:54:33,509 DEBUG ++Rcv raw: b'\x81~\x00\xc4{"topic":"orderbook.50.BTCUSDC","ts":1698936873424,"type":"delta","data":{"s":"BTCUSDC","b":[["34951.27","0.106064"]],"a":[["34964.2","0.036008"],["34981.28","0"]],"u":20010542,"seq":14108044627}}'
2023-11-02 14:54:33,509 DEBUG ++Rcv decoded: fin=1 opcode=1 data=b'{"topic":"orderbook.50.BTCUSDC","ts":1698936873424,"type":"delta","data":{"s":"BTCUSDC","b":[["34951.27","0.106064"]],"a":[["34964.2","0.036008"],["34981.28","0"]],"u":20010542,"seq":14108044627}}'
2023-11-02 14:54:33,529 DEBUG ++Rcv raw: b'\x81~\x00\xae{"topic":"orderbook.50.BTCUSDC","ts":1698936873444,"type":"delta","data":{"s":"BTCUSDC","b":[],"a":[["34981.28","0.000562"],["34964.62","0"]],"u":20010543,"seq":14108044629}}'
2023-11-02 14:54:33,529 DEBUG ++Rcv decoded: fin=1 opcode=1 data=b'{"topic":"orderbook.50.BTCUSDC","ts":1698936873444,"type":"delta","data":{"s":"BTCUSDC","b":[],"a":[["34981.28","0.000562"],["34964.62","0"]],"u":20010543,"seq":14108044629}}'
2023-11-02 14:54:33,549 DEBUG ++Rcv raw: b'\x81~\x00\xac{"topic":"orderbook.50.BTCUSDC","ts":1698936873464,"type":"delta","data":{"s":"BTCUSDC","b":[],"a":[["34981.7","0.034346"],["34964.2","0"]],"u":20010544,"seq":14108044634}}'
2023-11-02 14:54:33,549 DEBUG ++Rcv decoded: fin=1 opcode=1 data=b'{"topic":"orderbook.50.BTCUSDC","ts":1698936873464,"type":"delta","data":{"s":"BTCUSDC","b":[],"a":[["34981.7","0.034346"],["34964.2","0"]],"u":20010544,"seq":14108044634}}'
2023-11-02 14:54:33,570 DEBUG ++Rcv raw: b'\x81~\x00\xad{"topic":"orderbook.50.BTCUSDC","ts":1698936873484,"type":"delta","data":{"s":"BTCUSDC","b":[["34960.7","0.028603"],["34939.27","0"]],"a":[],"u":20010545,"seq":14108044641}}'
2023-11-02 14:54:33,570 DEBUG ++Rcv decoded: fin=1 opcode=1 data=b'{"topic":"orderbook.50.BTCUSDC","ts":1698936873484,"type":"delta","data":{"s":"BTCUSDC","b":[["34960.7","0.028603"],["34939.27","0"]],"a":[],"u":20010545,"seq":14108044641}}'
2023-11-02 14:54:33,589 DEBUG ++Rcv raw: b'\x81~\x00\x9c{"topic":"orderbook.50.BTCUSDC","ts":1698936873504,"type":"delta","data":{"s":"BTCUSDC","b":[],"a":[["34981.7","0.033846"]],"u":20010546,"seq":14108044644}}'
2023-11-02 14:54:33,589 DEBUG ++Rcv decoded: fin=1 opcode=1 data=b'{"topic":"orderbook.50.BTCUSDC","ts":1698936873504,"type":"delta","data":{"s":"BTCUSDC","b":[],"a":[["34981.7","0.033846"]],"u":20010546,"seq":14108044644}}'
2023-11-02 14:54:33,628 DEBUG ++Rcv raw: b'\x81~\x00\xfa{"topic":"orderbook.50.BTCUSDC","ts":1698936873543,"type":"delta","data":{"s":"BTCUSDC","b":[["34961.47","0.008756"],["34951.28","0.003188"],["34939.85","0"],["34939.86","0"]],"a":[["34971.21","0.1875"],["34966","0"]],"u":20010547,"seq":14108044656}}'
2023-11-02 14:54:33,629 DEBUG ++Rcv decoded: fin=1 opcode=1 data=b'{"topic":"orderbook.50.BTCUSDC","ts":1698936873543,"type":"delta","data":{"s":"BTCUSDC","b":[["34961.47","0.008756"],["34951.28","0.003188"],["34939.85","0"],["34939.86","0"]],"a":[["34971.21","0.1875"],["34966","0"]],"u":20010547,"seq":14108044656}}'
2023-11-02 14:54:33,649 DEBUG ++Rcv raw: b'\x81~\x01;{"topic":"orderbook.50.BTCUSDC","ts":1698936873563,"type":"delta","data":{"s":"BTCUSDC","b":[["34961.47","0.011756"],["34939.86","0.028"],["34939.85","0.1875"],["34939.27","0.029858"],["34956.54","0"],["34961.46","0"],["34953.53","0"]],"a":[["34981.71","0.056401"],["34971.21","0"]],"u":20010548,"seq":14108044676}}'
2023-11-02 14:54:33,649 DEBUG ++Rcv decoded: fin=1 opcode=1 data=b'{"topic":"orderbook.50.BTCUSDC","ts":1698936873563,"type":"delta","data":{"s":"BTCUSDC","b":[["34961.47","0.011756"],["34939.86","0.028"],["34939.85","0.1875"],["34939.27","0.029858"],["34956.54","0"],["34961.46","0"],["34953.53","0"]],"a":[["34981.71","0.056401"],["34971.21","0"]],"u":20010548,"seq":14108044676}}'
2023-11-02 14:54:33,669 DEBUG ++Rcv raw: b'\x81~\x01N{"topic":"orderbook.50.BTCUSDC","ts":1698936873584,"type":"delta","data":{"s":"BTCUSDC","b":[["34957.87","0.057211"],["34953.11","0.051549"],["34952.68","0.11444"],["34953.54","0"],["34939.27","0"],["34960.7","0"]],"a":[["34963.44","0.034321"],["34963.45","0.057202"],["34981.7","0"],["34981.71","0"]],"u":20010549,"seq":14108044694}}'
2023-11-02 14:54:33,670 DEBUG ++Rcv decoded: fin=1 opcode=1 data=b'{"topic":"orderbook.50.BTCUSDC","ts":1698936873584,"type":"delta","data":{"s":"BTCUSDC","b":[["34957.87","0.057211"],["34953.11","0.051549"],["34952.68","0.11444"],["34953.54","0"],["34939.27","0"],["34960.7","0"]],"a":[["34963.44","0.034321"],["34963.45","0.057202"],["34981.7","0"],["34981.71","0"]],"u":20010549,"seq":14108044694}}'
2023-11-02 14:54:33,689 DEBUG ++Rcv raw: b'\x81~\x00\xd5{"topic":"orderbook.50.BTCUSDC","ts":1698936873604,"type":"delta","data":{"s":"BTCUSDC","b":[["34939.27","0.029858"],["34950.96","0"]],"a":[["34981.7","0.033846"],["34963.45","0"]],"u":20010550,"seq":14108044702}}'
2023-11-02 14:54:33,690 DEBUG ++Rcv decoded: fin=1 opcode=1 data=b'{"topic":"orderbook.50.BTCUSDC","ts":1698936873604,"type":"delta","data":{"s":"BTCUSDC","b":[["34939.27","0.029858"],["34950.96","0"]],"a":[["34981.7","0.033846"],["34963.45","0"]],"u":20010550,"seq":14108044702}}'
2023-11-02 14:54:33,709 DEBUG ++Rcv raw: b'\x81~\x00\xd6{"topic":"orderbook.50.BTCUSDC","ts":1698936873623,"type":"delta","data":{"s":"BTCUSDC","b":[["34939.11","0.057242"],["34951.27","0"]],"a":[["34981.71","0.056401"],["34963.44","0"]],"u":20010551,"seq":14108044709}}'
2023-11-02 14:54:33,709 DEBUG ++Rcv decoded: fin=1 opcode=1 data=b'{"topic":"orderbook.50.BTCUSDC","ts":1698936873623,"type":"delta","data":{"s":"BTCUSDC","b":[["34939.11","0.057242"],["34951.27","0"]],"a":[["34981.71","0.056401"],["34963.44","0"]],"u":20010551,"seq":14108044709}}'
2023-11-02 14:54:33,728 DEBUG ++Rcv raw: b'\x81~\x00\xd2{"topic":"orderbook.50.BTCUSDC","ts":1698936873643,"type":"delta","data":{"s":"BTCUSDC","b":[["34950.97","0.1875"],["34939.11","0"]],"a":[["34971.21","0.1875"],["34981.71","0"]],"u":20010552,"seq":14108044721}}'
2023-11-02 14:54:33,729 DEBUG ++Rcv decoded: fin=1 opcode=1 data=b'{"topic":"orderbook.50.BTCUSDC","ts":1698936873643,"type":"delta","data":{"s":"BTCUSDC","b":[["34950.97","0.1875"],["34939.11","0"]],"a":[["34971.21","0.1875"],["34981.71","0"]],"u":20010552,"seq":14108044721}}'
2023-11-02 14:54:33,749 DEBUG ++Rcv raw: b'\x81~\x00\xae{"topic":"orderbook.50.BTCUSDC","ts":1698936873663,"type":"delta","data":{"s":"BTCUSDC","b":[["34951.27","0.112501"],["34939.27","0"]],"a":[],"u":20010553,"seq":14108044730}}'
2023-11-02 14:54:33,749 DEBUG ++Rcv decoded: fin=1 opcode=1 data=b'{"topic":"orderbook.50.BTCUSDC","ts":1698936873663,"type":"delta","data":{"s":"BTCUSDC","b":[["34951.27","0.112501"],["34939.27","0"]],"a":[],"u":20010553,"seq":14108044730}}'
2023-11-02 14:54:33,835 DEBUG ++Rcv raw: b'\x81~\x00\x9d{"topic":"orderbook.50.BTCUSDC","ts":1698936873744,"type":"delta","data":{"s":"BTCUSDC","b":[["34961.47","0.000006"]],"a":[],"u":20010554,"seq":14108044769}}'
2023-11-02 14:54:33,835 DEBUG ++Rcv decoded: fin=1 opcode=1 data=b'{"topic":"orderbook.50.BTCUSDC","ts":1698936873744,"type":"delta","data":{"s":"BTCUSDC","b":[["34961.47","0.000006"]],"a":[],"u":20010554,"seq":14108044769}}'
2023-11-02 14:54:33,850 DEBUG ++Rcv raw: b'\x81~\x00\xa8{"topic":"orderbook.50.BTCUSDC","ts":1698936873764,"type":"delta","data":{"s":"BTCUSDC","b":[],"a":[["34966","0.0324"],["34981.7","0"]],"u":20010555,"seq":14108044775}}'
2023-11-02 14:54:33,850 DEBUG ++Rcv decoded: fin=1 opcode=1 data=b'{"topic":"orderbook.50.BTCUSDC","ts":1698936873764,"type":"delta","data":{"s":"BTCUSDC","b":[],"a":[["34966","0.0324"],["34981.7","0"]],"u":20010555,"seq":14108044775}}'
2023-11-02 14:54:33,869 DEBUG ++Rcv raw: b'\x81~\x00\xf9{"topic":"orderbook.50.BTCUSDC","ts":1698936873784,"type":"delta","data":{"s":"BTCUSDC","b":[["34955.79","0.00057"],["34939.85","0"]],"a":[["34961.82","0.003"],["34969.1","0.00057"],["34981.28","0"],["34980.48","0"]],"u":20010556,"seq":14108044787}}'
2023-11-02 14:54:33,869 DEBUG ++Rcv decoded: fin=1 opcode=1 data=b'{"topic":"orderbook.50.BTCUSDC","ts":1698936873784,"type":"delta","data":{"s":"BTCUSDC","b":[["34955.79","0.00057"],["34939.85","0"]],"a":[["34961.82","0.003"],["34969.1","0.00057"],["34981.28","0"],["34980.48","0"]],"u":20010556,"seq":14108044787}}'
2023-11-02 14:54:33,889 DEBUG ++Rcv raw: b'\x81~\x01 {"topic":"orderbook.50.BTCUSDC","ts":1698936873804,"type":"delta","data":{"s":"BTCUSDC","b":[["34939.85","0.1875"],["34939.27","0.029858"],["34955.79","0"],["34950.97","0"]],"a":[["34963.51","0.057202"],["34964.51","0.03"],["34978.9","0"],["34969.1","0"]],"u":20010557,"seq":14108044794}}'
2023-11-02 14:54:33,889 DEBUG ++Rcv decoded: fin=1 opcode=1 data=b'{"topic":"orderbook.50.BTCUSDC","ts":1698936873804,"type":"delta","data":{"s":"BTCUSDC","b":[["34939.85","0.1875"],["34939.27","0.029858"],["34955.79","0"],["34950.97","0"]],"a":[["34963.51","0.057202"],["34964.51","0.03"],["34978.9","0"],["34969.1","0"]],"u":20010557,"seq":14108044794}}'
2023-11-02 14:54:33,909 DEBUG ++Rcv raw: b'\x81~\x00\xd5{"topic":"orderbook.50.BTCUSDC","ts":1698936873824,"type":"delta","data":{"s":"BTCUSDC","b":[["34961.48","0.028602"],["34951.27","0"]],"a":[["34963.5","0.034323"],["34978.78","0"]],"u":20010558,"seq":14108044797}}'
2023-11-02 14:54:33,909 DEBUG ++Rcv decoded: fin=1 opcode=1 data=b'{"topic":"orderbook.50.BTCUSDC","ts":1698936873824,"type":"delta","data":{"s":"BTCUSDC","b":[["34961.48","0.028602"],["34951.27","0"]],"a":[["34963.5","0.034323"],["34978.78","0"]],"u":20010558,"seq":14108044797}}'
2023-11-02 14:54:33,928 DEBUG ++Rcv raw: b'\x81~\x00\xc3{"topic":"orderbook.50.BTCUSDC","ts":1698936873843,"type":"delta","data":{"s":"BTCUSDC","b":[["34961.48","0.000002"]],"a":[["34978.78","0.0859"],["34964.51","0"]],"u":20010559,"seq":14108044805}}'
2023-11-02 14:54:33,929 DEBUG ++Rcv decoded: fin=1 opcode=1 data=b'{"topic":"orderbook.50.BTCUSDC","ts":1698936873843,"type":"delta","data":{"s":"BTCUSDC","b":[["34961.48","0.000002"]],"a":[["34978.78","0.0859"],["34964.51","0"]],"u":20010559,"seq":14108044805}}'
2023-11-02 14:54:34,029 DEBUG ++Rcv raw: b'\x81~\x00\xef{"topic":"orderbook.50.BTCUSDC","ts":1698936873944,"type":"delta","data":{"s":"BTCUSDC","b":[["34960.68","0.000008"],["34951.27","0.001659"],["34945.02","0.171702"],["34961.47","0"],["34961.48","0"]],"a":[],"u":20010560,"seq":14108044863}}'
2023-11-02 14:54:34,030 DEBUG ++Rcv decoded: fin=1 opcode=1 data=b'{"topic":"orderbook.50.BTCUSDC","ts":1698936873944,"type":"delta","data":{"s":"BTCUSDC","b":[["34960.68","0.000008"],["34951.27","0.001659"],["34945.02","0.171702"],["34961.47","0"],["34961.48","0"]],"a":[],"u":20010560,"seq":14108044863}}'
2023-11-02 14:54:34,049 DEBUG ++Rcv raw: b'\x81~\x00\xfd{"topic":"orderbook.50.BTCUSDC","ts":1698936873964,"type":"delta","data":{"s":"BTCUSDC","b":[["34960.69","0.104963"],["34939.11","0.057242"],["34951.28","0"],["34959.41","0"]],"a":[["34965.02","0.0859"],["34978.78","0"]],"u":20010561,"seq":14108044881}}'
2023-11-02 14:54:34,049 DEBUG ++Rcv decoded: fin=1 opcode=1 data=b'{"topic":"orderbook.50.BTCUSDC","ts":1698936873964,"type":"delta","data":{"s":"BTCUSDC","b":[["34960.69","0.104963"],["34939.11","0.057242"],["34951.28","0"],["34959.41","0"]],"a":[["34965.02","0.0859"],["34978.78","0"]],"u":20010561,"seq":14108044881}}'
2023-11-02 14:54:34,069 DEBUG ++Rcv raw: b'\x81~\x01w{"topic":"orderbook.50.BTCUSDC","ts":1698936873983,"type":"delta","data":{"s":"BTCUSDC","b":[["34937.84","0.040649"],["34937.39","0.278379"],["34952.68","0"],["34957.87","0"]],"a":[["34965.01","0.051546"],["34976.65","0.285905"],["34978.78","0.0859"],["34978.9","0.002162"],["34961.82","0"],["34965.02","0"],["34963.51","0"],["34977.52","0"]],"u":20010562,"seq":14108044897}}'
2023-11-02 14:54:34,069 DEBUG ++Rcv decoded: fin=1 opcode=1 data=b'{"topic":"orderbook.50.BTCUSDC","ts":1698936873983,"type":"delta","data":{"s":"BTCUSDC","b":[["34937.84","0.040649"],["34937.39","0.278379"],["34952.68","0"],["34957.87","0"]],"a":[["34965.01","0.051546"],["34976.65","0.285905"],["34978.78","0.0859"],["34978.9","0.002162"],["34961.82","0"],["34965.02","0"],["34963.51","0"],["34977.52","0"]],"u":20010562,"seq":14108044897}}'
2023-11-02 14:54:34,089 DEBUG ++Rcv raw: b'\x81~\x02\x91{"topic":"orderbook.50.BTCUSDC","ts":1698936874004,"type":"delta","data":{"s":"BTCUSDC","b":[["34961.49","0.00572"],["34959.38","0.057209"],["34958.15","0.051547"],["34955.8","0.00057"],["34955.37","0.031235"],["34954.71","0.051549"],["34953.69","0.114437"],["34946.09","0.286155"],["34960.68","0"],["34951.19","0"],["34944.78","0"],["34939.11","0"],["34953.11","0"],["34937.84","0"],["34937.39","0"],["34956.53","0"]],"a":[["34964.77","0.0572"],["34968.39","0.00057"],["34980.48","0.023472"],["34981.28","0.000562"],["34981.7","0.033846"],["34963.5","0"],["34976.65","0"],["34971.21","0"],["34964.21","0"],["34965.01","0"]],"u":20010563,"seq":14108044921}}'
2023-11-02 14:54:34,089 DEBUG ++Rcv decoded: fin=1 opcode=1 data=b'{"topic":"orderbook.50.BTCUSDC","ts":1698936874004,"type":"delta","data":{"s":"BTCUSDC","b":[["34961.49","0.00572"],["34959.38","0.057209"],["34958.15","0.051547"],["34955.8","0.00057"],["34955.37","0.031235"],["34954.71","0.051549"],["34953.69","0.114437"],["34946.09","0.286155"],["34960.68","0"],["34951.19","0"],["34944.78","0"],["34939.11","0"],["34953.11","0"],["34937.84","0"],["34937.39","0"],["34956.53","0"]],"a":[["34964.77","0.0572"],["34968.39","0.00057"],["34980.48","0.023472"],["34981.28","0.000562"],["34981.7","0.033846"],["34963.5","0"],["34976.65","0"],["34971.21","0"],["34964.21","0"],["34965.01","0"]],"u":20010563,"seq":14108044921}}'
2023-11-02 14:54:34,109 DEBUG ++Rcv raw: b'\x81~\x01F{"topic":"orderbook.50.BTCUSDC","ts":1698936874023,"type":"delta","data":{"s":"BTCUSDC","b":[["34953.73","0.036"],["34950.99","0.1875"],["34939.11","0.057242"],["34960.69","0"],["34959.38","0"],["34945.02","0"]],"a":[["34964.76","0.03432"],["34969.71","0.03"],["34964.77","0"],["34981.7","0"]],"u":20010564,"seq":14108044934}}'
2023-11-02 14:54:34,109 DEBUG ++Rcv decoded: fin=1 opcode=1 data=b'{"topic":"orderbook.50.BTCUSDC","ts":1698936874023,"type":"delta","data":{"s":"BTCUSDC","b":[["34953.73","0.036"],["34950.99","0.1875"],["34939.11","0.057242"],["34960.69","0"],["34959.38","0"],["34945.02","0"]],"a":[["34964.76","0.03432"],["34969.71","0.03"],["34964.77","0"],["34981.7","0"]],"u":20010564,"seq":14108044934}}'
2023-11-02 14:54:34,129 DEBUG ++Rcv raw: b'\x81~\x00\xfd{"topic":"orderbook.50.BTCUSDC","ts":1698936874043,"type":"delta","data":{"s":"BTCUSDC","b":[["34937.84","0.040649"],["34946.09","0"]],"a":[["34964.25","0.022791"],["34971.76","0.1875"],["34967.97","0"],["34964.76","0"]],"u":20010565,"seq":14108044942}}'
2023-11-02 14:54:34,129 DEBUG ++Rcv decoded: fin=1 opcode=1 data=b'{"topic":"orderbook.50.BTCUSDC","ts":1698936874043,"type":"delta","data":{"s":"BTCUSDC","b":[["34937.84","0.040649"],["34946.09","0"]],"a":[["34964.25","0.022791"],["34971.76","0.1875"],["34967.97","0"],["34964.76","0"]],"u":20010565,"seq":14108044942}}'
2023-11-02 14:54:34,149 DEBUG ++Rcv raw: b'\x81~\x00\xfd{"topic":"orderbook.50.BTCUSDC","ts":1698936874064,"type":"delta","data":{"s":"BTCUSDC","b":[["34937.39","0.278379"],["34937.08","0.064686"],["34955.8","0"],["34950.99","0"]],"a":[["34981.7","0.033846"],["34968.39","0"]],"u":20010566,"seq":14108044947}}'
2023-11-02 14:54:34,149 DEBUG ++Rcv decoded: fin=1 opcode=1 data=b'{"topic":"orderbook.50.BTCUSDC","ts":1698936874064,"type":"delta","data":{"s":"BTCUSDC","b":[["34937.39","0.278379"],["34937.08","0.064686"],["34955.8","0"],["34950.99","0"]],"a":[["34981.7","0.033846"],["34968.39","0"]],"u":20010566,"seq":14108044947}}'
2023-11-02 14:54:34,169 DEBUG ++Rcv raw: b'\x81~\x00\xc3{"topic":"orderbook.50.BTCUSDC","ts":1698936874084,"type":"delta","data":{"s":"BTCUSDC","b":[["34961.49","0.00872"],["34950.99","0.1875"],["34937.08","0"]],"a":[],"u":20010567,"seq":14108044952}}'
2023-11-02 14:54:34,169 DEBUG ++Rcv decoded: fin=1 opcode=1 data=b'{"topic":"orderbook.50.BTCUSDC","ts":1698936874084,"type":"delta","data":{"s":"BTCUSDC","b":[["34961.49","0.00872"],["34950.99","0.1875"],["34937.08","0"]],"a":[],"u":20010567,"seq":14108044952}}'
2023-11-02 14:54:34,189 DEBUG ++Rcv raw: b'\x81~\x01:{"topic":"orderbook.50.BTCUSDC","ts":1698936874103,"type":"delta","data":{"s":"BTCUSDC","b":[["34961.49","0.003"],["34937.08","0.064686"],["34936.35","0.1875"],["34939.86","0"],["34953.69","0"]],"a":[["34981.71","0.056401"],["34982.24","0.02859"],["34964.25","0"],["34969.14","0"]],"u":20010568,"seq":14108044986}}'
2023-11-02 14:54:34,189 DEBUG ++Rcv decoded: fin=1 opcode=1 data=b'{"topic":"orderbook.50.BTCUSDC","ts":1698936874103,"type":"delta","data":{"s":"BTCUSDC","b":[["34961.49","0.003"],["34937.08","0.064686"],["34936.35","0.1875"],["34939.86","0"],["34953.69","0"]],"a":[["34981.71","0.056401"],["34982.24","0.02859"],["34964.25","0"],["34969.14","0"]],"u":20010568,"seq":14108044986}}'
2023-11-02 14:54:34,209 DEBUG ++Rcv raw: b'\x81~\x02@{"topic":"orderbook.50.BTCUSDC","ts":1698936874123,"type":"delta","data":{"s":"BTCUSDC","b":[["34958.12","0.057211"],["34956.6","0.00057"],["34953.11","0.051541"],["34952.85","0.114439"],["34945.28","0.286161"],["34937.84","0"],["34937.08","0"],["34937.39","0"],["34936.35","0"],["34950.99","0"]],"a":[["34963.51","0.057202"],["34965.99","0.008756"],["34968.32","0.114389"],["34969.7","0.051542"],["34970.89","0.00057"],["34977.25","0.2859"],["34981.71","0"],["34981.7","0"],["34981.28","0"],["34980.48","0"],["34969.13","0"],["34982.24","0"]],"u":20010569,"seq":14108045007}}'
2023-11-02 14:54:34,209 DEBUG ++Rcv decoded: fin=1 opcode=1 data=b'{"topic":"orderbook.50.BTCUSDC","ts":1698936874123,"type":"delta","data":{"s":"BTCUSDC","b":[["34958.12","0.057211"],["34956.6","0.00057"],["34953.11","0.051541"],["34952.85","0.114439"],["34945.28","0.286161"],["34937.84","0"],["34937.08","0"],["34937.39","0"],["34936.35","0"],["34950.99","0"]],"a":[["34963.51","0.057202"],["34965.99","0.008756"],["34968.32","0.114389"],["34969.7","0.051542"],["34970.89","0.00057"],["34977.25","0.2859"],["34981.71","0"],["34981.7","0"],["34981.28","0"],["34980.48","0"],["34969.13","0"],["34982.24","0"]],"u":20010569,"seq":14108045007}}'
2023-11-02 14:54:34,229 DEBUG ++Rcv raw: b'\x81~\x01\x16{"topic":"orderbook.50.BTCUSDC","ts":1698936874143,"type":"delta","data":{"s":"BTCUSDC","b":[["34958.15","0.079426"],["34937.84","0.040649"],["34956.6","0"]],"a":[["34967.98","0.068637"],["34980.48","0.023472"],["34976.56","0"],["34970.89","0"]],"u":20010570,"seq":14108045028}}'
2023-11-02 14:54:34,230 DEBUG ++Rcv decoded: fin=1 opcode=1 data=b'{"topic":"orderbook.50.BTCUSDC","ts":1698936874143,"type":"delta","data":{"s":"BTCUSDC","b":[["34958.15","0.079426"],["34937.84","0.040649"],["34956.6","0"]],"a":[["34967.98","0.068637"],["34980.48","0.023472"],["34976.56","0"],["34970.89","0"]],"u":20010570,"seq":14108045028}}'
2023-11-02 14:54:34,249 DEBUG ++Rcv raw: b'\x81~\x00\xac{"topic":"orderbook.50.BTCUSDC","ts":1698936874163,"type":"delta","data":{"s":"BTCUSDC","b":[["34950.99","0.1875"],["34937.84","0"]],"a":[],"u":20010571,"seq":14108045033}}'
2023-11-02 14:54:34,249 DEBUG ++Rcv decoded: fin=1 opcode=1 data=b'{"topic":"orderbook.50.BTCUSDC","ts":1698936874163,"type":"delta","data":{"s":"BTCUSDC","b":[["34950.99","0.1875"],["34937.84","0"]],"a":[],"u":20010571,"seq":14108045033}}'
2023-11-02 14:54:34,289 DEBUG ++Rcv raw: b'\x81~\x02\xa5{"topic":"orderbook.50.BTCUSDC","ts":1698936874203,"type":"delta","data":{"s":"BTCUSDC","b":[["34961.58","0.0859"],["34960","0.0324"],["34959.86","0.0859"],["34952.85","0"],["34958.12","0"],["34939.11","0"]],"a":[["34972.99","0.1875"],["34981.28","0.000562"],["34981.7","0.033846"],["34981.71","0.056401"],["34982.24","0.02859"],["34983.73","0.112508"],["34983.74","0.1875"],["34984.8","0.528984"],["34984.83","0.0002"],["34984.95","0.0002"],["34985","0.001"],["34969.06","0"],["34963.51","0"],["34966","0"],["34966.73","0"],["34968.46","0"],["34965.99","0"],["34968.32","0"],["34966.74","0"],["34970.18","0"],["34971.76","0"],["34966.48","0"]],"u":20010572,"seq":14108045112}}'
2023-11-02 14:54:34,289 DEBUG ++Rcv decoded: fin=1 opcode=1 data=b'{"topic":"orderbook.50.BTCUSDC","ts":1698936874203,"type":"delta","data":{"s":"BTCUSDC","b":[["34961.58","0.0859"],["34960","0.0324"],["34959.86","0.0859"],["34952.85","0"],["34958.12","0"],["34939.11","0"]],"a":[["34972.99","0.1875"],["34981.28","0.000562"],["34981.7","0.033846"],["34981.71","0.056401"],["34982.24","0.02859"],["34983.73","0.112508"],["34983.74","0.1875"],["34984.8","0.528984"],["34984.83","0.0002"],["34984.95","0.0002"],["34985","0.001"],["34969.06","0"],["34963.51","0"],["34966","0"],["34966.73","0"],["34968.46","0"],["34965.99","0"],["34968.32","0"],["34966.74","0"],["34970.18","0"],["34971.76","0"],["34966.48","0"]],"u":20010572,"seq":14108045112}}'
2023-11-02 14:54:34,310 DEBUG ++Rcv raw: b'\x81~\x03\xfd{"topic":"orderbook.50.BTCUSDC","ts":1698936874224,"type":"delta","data":{"s":"BTCUSDC","b":[["34964.38","0.013136"],["34964.37","0.104957"],["34963.3","0.0859"],["34962","0.0324"],["34961.59","0.095797"],["34961.49","0.028922"],["34961.34","0.052522"],["34958.3","0.028601"],["34958.15","0.051547"],["34956.69","0.00057"],["34954.49","0.1875"],["34942.66","0"],["34939.27","0"],["34945.28","0"],["34943.35","0"],["34942","0"],["34943.36","0"],["34940.87","0"],["34939.85","0"],["34940.31","0"]],"a":[["34969.39","0.028601"],["34969.7","0.024361"],["34972.87","0.00057"],["34972.98","0.112502"],["34974.81","0.493521"],["34977.42","0.04598"],["34985.12","0.000491"],["34986.01","0.0005"],["34986.02","0.4055"],["34986.98","0.274392"],["34986.99","0.457312"],["34987.53","0.1875"],["34988.08","0.274387"],["34969.71","0"],["34973.36","0"],["34973.47","0"],["34976.23","0"],["34967.98","0"],["34977.25","0"],["34972.99","0"],["34976.85","0"],["34968","0"],["34971.15","0"],["34977.49","0"]],"u":20010573,"seq":14108045200}}'
2023-11-02 14:54:34,311 DEBUG ++Rcv decoded: fin=1 opcode=1 data=b'{"topic":"orderbook.50.BTCUSDC","ts":1698936874224,"type":"delta","data":{"s":"BTCUSDC","b":[["34964.38","0.013136"],["34964.37","0.104957"],["34963.3","0.0859"],["34962","0.0324"],["34961.59","0.095797"],["34961.49","0.028922"],["34961.34","0.052522"],["34958.3","0.028601"],["34958.15","0.051547"],["34956.69","0.00057"],["34954.49","0.1875"],["34942.66","0"],["34939.27","0"],["34945.28","0"],["34943.35","0"],["34942","0"],["34943.36","0"],["34940.87","0"],["34939.85","0"],["34940.31","0"]],"a":[["34969.39","0.028601"],["34969.7","0.024361"],["34972.87","0.00057"],["34972.98","0.112502"],["34974.81","0.493521"],["34977.42","0.04598"],["34985.12","0.000491"],["34986.01","0.0005"],["34986.02","0.4055"],["34986.98","0.274392"],["34986.99","0.457312"],["34987.53","0.1875"],["34988.08","0.274387"],["34969.71","0"],["34973.36","0"],["34973.47","0"],["34976.23","0"],["34967.98","0"],["34977.25","0"],["34972.99","0"],["34976.85","0"],["34968","0"],["34971.15","0"],["34977.49","0"]],"u":20010573,"seq":14108045200}}'
2023-11-02 14:54:34,329 DEBUG ++Rcv raw: b'\x81~\x03\x9e{"topic":"orderbook.50.BTCUSDC","ts":1698936874243,"type":"delta","data":{"s":"BTCUSDC","b":[["34963.31","0.051544"],["34961.49","0.025922"],["34960.01","0.051545"],["34957.17","0.001"],["34956.53","0.051546"],["34943.36","0.079497"],["34943.35","0.02598"],["34942.66","0.0859"],["34940.87","0.00154"],["34940.31","0.112505"],["34939.85","0.1875"],["34956.69","0"],["34955.36","0"],["34949.55","0"],["34961.34","0"],["34958.15","0"],["34945.01","0"],["34961.59","0"],["34958.3","0"],["34955.37","0"],["34964.37","0"]],"a":[["34969.7","0.049914"],["34971.89","0.051548"],["34972.98","0.051549"],["34980.47","0.076322"],["34988.12","0.4084"],["34990.07","0.057159"],["34991.03","0.1875"],["34991.24","0.000308"],["34991.45","0.000286"],["34991.96","0.002812"],["34972.6","0"],["34972.82","0"],["34976.24","0"],["34978.02","0"],["34986.99","0"],["34969.39","0"],["34971.14","0"],["34977.42","0"]],"u":20010574,"seq":14108045260}}'
2023-11-02 14:54:34,329 DEBUG ++Rcv decoded: fin=1 opcode=1 data=b'{"topic":"orderbook.50.BTCUSDC","ts":1698936874243,"type":"delta","data":{"s":"BTCUSDC","b":[["34963.31","0.051544"],["34961.49","0.025922"],["34960.01","0.051545"],["34957.17","0.001"],["34956.53","0.051546"],["34943.36","0.079497"],["34943.35","0.02598"],["34942.66","0.0859"],["34940.87","0.00154"],["34940.31","0.112505"],["34939.85","0.1875"],["34956.69","0"],["34955.36","0"],["34949.55","0"],["34961.34","0"],["34958.15","0"],["34945.01","0"],["34961.59","0"],["34958.3","0"],["34955.37","0"],["34964.37","0"]],"a":[["34969.7","0.049914"],["34971.89","0.051548"],["34972.98","0.051549"],["34980.47","0.076322"],["34988.12","0.4084"],["34990.07","0.057159"],["34991.03","0.1875"],["34991.24","0.000308"],["34991.45","0.000286"],["34991.96","0.002812"],["34972.6","0"],["34972.82","0"],["34976.24","0"],["34978.02","0"],["34986.99","0"],["34969.39","0"],["34971.14","0"],["34977.42","0"]],"u":20010574,"seq":14108045260}}'
2023-11-02 14:54:34,349 DEBUG ++Rcv raw: b'\x81~\x02~{"topic":"orderbook.50.BTCUSDC","ts":1698936874263,"type":"delta","data":{"s":"BTCUSDC","b":[["34964.39","0.053806"],["34964","0.0324"],["34962.93","0.057203"],["34957.63","0.114424"],["34955.38","0.003561"],["34954.72","0.362891"],["34949.37","0.286128"],["34940.87","0"],["34949.56","0"],["34951.27","0"],["34956.52","0"],["34942.66","0"],["34940.31","0"],["34939.85","0"]],"a":[["34967.99","0.00007"],["34968.78","0.057193"],["34973.98","0.11437"],["34982.36","0.285858"],["34983.47","0.278379"],["34991.21","0.457257"],["34970","0"],["34982.24","0"],["34974.89","0"],["34986.98","0"],["34988.12","0"]],"u":20010575,"seq":14108045324}}'
2023-11-02 14:54:34,349 DEBUG ++Rcv decoded: fin=1 opcode=1 data=b'{"topic":"orderbook.50.BTCUSDC","ts":1698936874263,"type":"delta","data":{"s":"BTCUSDC","b":[["34964.39","0.053806"],["34964","0.0324"],["34962.93","0.057203"],["34957.63","0.114424"],["34955.38","0.003561"],["34954.72","0.362891"],["34949.37","0.286128"],["34940.87","0"],["34949.56","0"],["34951.27","0"],["34956.52","0"],["34942.66","0"],["34940.31","0"],["34939.85","0"]],"a":[["34967.99","0.00007"],["34968.78","0.057193"],["34973.98","0.11437"],["34982.36","0.285858"],["34983.47","0.278379"],["34991.21","0.457257"],["34970","0"],["34982.24","0"],["34974.89","0"],["34986.98","0"],["34988.12","0"]],"u":20010575,"seq":14108045324}}'
2023-11-02 14:54:34,369 DEBUG ++Rcv raw: b'\x81~\x02\xba{"topic":"orderbook.50.BTCUSDC","ts":1698936874284,"type":"delta","data":{"s":"BTCUSDC","b":[["34964.4","0.013136"],["34964.39","0.025922"],["34958.15","0.068656"],["34942.66","0.0859"],["34942.5","0.049354"],["34940.87","0.00154"],["34940.31","0.112505"],["34964.38","0"],["34954.71","0"],["34957.63","0"],["34949.37","0"],["34962.93","0"],["34956.53","0"]],"a":[["34969.7","0.024361"],["34977.24","0.075313"],["34990.49","0.12443"],["34992.54","0.001425"],["34994.86","0.002023"],["34995","0.001"],["34997.54","0.642755"],["34997.55","0.1875"],["34982.36","0"],["34968.78","0"],["34983.73","0"],["34988.08","0"],["34977.11","0"],["34991.21","0"],["34973.98","0"]],"u":20010576,"seq":14108045391}}'
2023-11-02 14:54:34,370 DEBUG ++Rcv decoded: fin=1 opcode=1 data=b'{"topic":"orderbook.50.BTCUSDC","ts":1698936874284,"type":"delta","data":{"s":"BTCUSDC","b":[["34964.4","0.013136"],["34964.39","0.025922"],["34958.15","0.068656"],["34942.66","0.0859"],["34942.5","0.049354"],["34940.87","0.00154"],["34940.31","0.112505"],["34964.38","0"],["34954.71","0"],["34957.63","0"],["34949.37","0"],["34962.93","0"],["34956.53","0"]],"a":[["34969.7","0.024361"],["34977.24","0.075313"],["34990.49","0.12443"],["34992.54","0.001425"],["34994.86","0.002023"],["34995","0.001"],["34997.54","0.642755"],["34997.55","0.1875"],["34982.36","0"],["34968.78","0"],["34983.73","0"],["34988.08","0"],["34977.11","0"],["34991.21","0"],["34973.98","0"]],"u":20010576,"seq":14108045391}}'
2023-11-02 14:54:34,389 DEBUG ++Rcv raw: b'\x81~\x01\x15{"topic":"orderbook.50.BTCUSDC","ts":1698936874304,"type":"delta","data":{"s":"BTCUSDC","b":[["34956.44","0.051544"],["34943.36","0.107497"],["34939.86","2.2125"],["34958.15","0"],["34942.66","0"]],"a":[["34977.05","0.112505"],["34972.04","0"]],"u":20010577,"seq":14108045409}}'
2023-11-02 14:54:34,389 DEBUG ++Rcv decoded: fin=1 opcode=1 data=b'{"topic":"orderbook.50.BTCUSDC","ts":1698936874304,"type":"delta","data":{"s":"BTCUSDC","b":[["34956.44","0.051544"],["34943.36","0.107497"],["34939.86","2.2125"],["34958.15","0"],["34942.66","0"]],"a":[["34977.05","0.112505"],["34972.04","0"]],"u":20010577,"seq":14108045409}}'
2023-11-02 14:54:34,409 DEBUG ++Rcv raw: b'\x81~\x01\x87{"topic":"orderbook.50.BTCUSDC","ts":1698936874324,"type":"delta","data":{"s":"BTCUSDC","b":[["34959.51","0.00057"],["34953.74","0.077355"],["34943.36","0.028"],["34940.31","0"],["34939.86","0"]],"a":[["34982.54","0.047176"],["34997.9","1.094688"],["34998","0.001249"],["34999","0.005725"],["34977.24","0"],["34967.99","0"],["34972.98","0"],["34972.87","0"]],"u":20010578,"seq":14108045436}}'
2023-11-02 14:54:34,409 DEBUG ++Rcv decoded: fin=1 opcode=1 data=b'{"topic":"orderbook.50.BTCUSDC","ts":1698936874324,"type":"delta","data":{"s":"BTCUSDC","b":[["34959.51","0.00057"],["34953.74","0.077355"],["34943.36","0.028"],["34940.31","0"],["34939.86","0"]],"a":[["34982.54","0.047176"],["34997.9","1.094688"],["34998","0.001249"],["34999","0.005725"],["34977.24","0"],["34967.99","0"],["34972.98","0"],["34972.87","0"]],"u":20010578,"seq":14108045436}}'
2023-11-02 14:54:34,431 DEBUG ++Rcv raw: b'\x81~\x01\xe7{"topic":"orderbook.50.BTCUSDC","ts":1698936874343,"type":"delta","data":{"s":"BTCUSDC","b":[["34964.41","0.045077"],["34961.5","0.00572"],["34954.73","0.21774"],["34951.27","0.112502"],["34946.11","0.051547"],["34950.76","0"],["34942.5","0"],["34943.36","0"],["34940.87","0"],["34943.35","0"]],"a":[["34974.59","0.00057"],["34983.46","0.167031"],["34984.79","0.317399"],["34990.48","0.1125"],["34999","0"],["34998","0"],["34981.71","0"],["34997.9","0"]],"u":20010579,"seq":14108045465}}'
2023-11-02 14:54:34,431 DEBUG ++Rcv decoded: fin=1 opcode=1 data=b'{"topic":"orderbook.50.BTCUSDC","ts":1698936874343,"type":"delta","data":{"s":"BTCUSDC","b":[["34964.41","0.045077"],["34961.5","0.00572"],["34954.73","0.21774"],["34951.27","0.112502"],["34946.11","0.051547"],["34950.76","0"],["34942.5","0"],["34943.36","0"],["34940.87","0"],["34943.35","0"]],"a":[["34974.59","0.00057"],["34983.46","0.167031"],["34984.79","0.317399"],["34990.48","0.1125"],["34999","0"],["34998","0"],["34981.71","0"],["34997.9","0"]],"u":20010579,"seq":14108045465}}'
2023-11-02 14:54:34,449 DEBUG ++Rcv raw: b'\x81~\x01K{"topic":"orderbook.50.BTCUSDC","ts":1698936874363,"type":"delta","data":{"s":"BTCUSDC","b":[["34964.42","0.013136"],["34949.55","0.051546"],["34964.4","0"],["34943.59","0"]],"a":[["34987.52","0.112508"],["34997.9","1.094688"],["34998","0.001249"],["34981.7","0"],["34970.07","0"],["34977.23","0"]],"u":20010580,"seq":14108045492}}'
2023-11-02 14:54:34,449 DEBUG ++Rcv decoded: fin=1 opcode=1 data=b'{"topic":"orderbook.50.BTCUSDC","ts":1698936874363,"type":"delta","data":{"s":"BTCUSDC","b":[["34964.42","0.013136"],["34949.55","0.051546"],["34964.4","0"],["34943.59","0"]],"a":[["34987.52","0.112508"],["34997.9","1.094688"],["34998","0.001249"],["34981.7","0"],["34970.07","0"],["34977.23","0"]],"u":20010580,"seq":14108045492}}'
2023-11-02 14:54:34,469 DEBUG ++Rcv raw: b'\x81~\x01\xd7{"topic":"orderbook.50.BTCUSDC","ts":1698936874384,"type":"delta","data":{"s":"BTCUSDC","b":[["34959.91","0.114416"],["34956.59","0.036"],["34950.49","0.286118"],["34964.39","0"],["34954.72","0"],["34943.75","0"]],"a":[["34973.41","0.057186"],["34977.05","0.051549"],["34979.93","0.114351"],["34980.2","0.1875"],["34980.46","0.045793"],["34989.35","0.285801"],["34997.55","0"],["34998","0"],["34995","0"],["34997.54","0"],["34997.9","0"]],"u":20010581,"seq":14108045524}}'
2023-11-02 14:54:34,470 DEBUG ++Rcv decoded: fin=1 opcode=1 data=b'{"topic":"orderbook.50.BTCUSDC","ts":1698936874384,"type":"delta","data":{"s":"BTCUSDC","b":[["34959.91","0.114416"],["34956.59","0.036"],["34950.49","0.286118"],["34964.39","0"],["34954.72","0"],["34943.75","0"]],"a":[["34973.41","0.057186"],["34977.05","0.051549"],["34979.93","0.114351"],["34980.2","0.1875"],["34980.46","0.045793"],["34989.35","0.285801"],["34997.55","0"],["34998","0"],["34995","0"],["34997.54","0"],["34997.9","0"]],"u":20010581,"seq":14108045524}}'
2023-11-02 14:54:34,491 DEBUG ++Rcv raw: b'\x81~\x01e{"topic":"orderbook.50.BTCUSDC","ts":1698936874404,"type":"delta","data":{"s":"BTCUSDC","b":[["34958.15","0.051541"],["34954.73","0.112502"],["34943.75","0.1875"],["34943.59","0.1875"],["34956.59","0"],["34956.44","0"],["34944.38","0"]],"a":[["34979.92","0.112503"],["34989.34","0.171484"],["34980.46","0"],["34994.86","0"]],"u":20010582,"seq":14108045547}}'
2023-11-02 14:54:34,491 DEBUG ++Rcv decoded: fin=1 opcode=1 data=b'{"topic":"orderbook.50.BTCUSDC","ts":1698936874404,"type":"delta","data":{"s":"BTCUSDC","b":[["34958.15","0.051541"],["34954.73","0.112502"],["34943.75","0.1875"],["34943.59","0.1875"],["34956.59","0"],["34956.44","0"],["34944.38","0"]],"a":[["34979.92","0.112503"],["34989.34","0.171484"],["34980.46","0"],["34994.86","0"]],"u":20010582,"seq":14108045547}}'
2023-11-02 14:54:34,509 DEBUG ++Rcv raw: b'\x81~\x00\xfb{"topic":"orderbook.50.BTCUSDC","ts":1698936874424,"type":"delta","data":{"s":"BTCUSDC","b":[["34943.36","0.028"],["34950.49","0"]],"a":[["34982.53","0.02831"],["34988.01","0.029854"],["34991.96","0"],["34992.54","0"]],"u":20010583,"seq":14108045565}}'
2023-11-02 14:54:34,510 DEBUG ++Rcv decoded: fin=1 opcode=1 data=b'{"topic":"orderbook.50.BTCUSDC","ts":1698936874424,"type":"delta","data":{"s":"BTCUSDC","b":[["34943.36","0.028"],["34950.49","0"]],"a":[["34982.53","0.02831"],["34988.01","0.029854"],["34991.96","0"],["34992.54","0"]],"u":20010583,"seq":14108045565}}'
2023-11-02 14:54:34,529 DEBUG ++Rcv raw: b'\x81~\x01\'{"topic":"orderbook.50.BTCUSDC","ts":1698936874443,"type":"delta","data":{"s":"BTCUSDC","b":[["34954.74","0.003561"],["34961.5","0"]],"a":[["34991.96","0.002812"],["34992.54","0.001425"],["34994.86","0.002023"],["34973.41","0"],["34979.93","0"],["34989.35","0"]],"u":20010584,"seq":14108045588}}'
2023-11-02 14:54:34,530 DEBUG ++Rcv decoded: fin=1 opcode=1 data=b'{"topic":"orderbook.50.BTCUSDC","ts":1698936874443,"type":"delta","data":{"s":"BTCUSDC","b":[["34954.74","0.003561"],["34961.5","0"]],"a":[["34991.96","0.002812"],["34992.54","0.001425"],["34994.86","0.002023"],["34973.41","0"],["34979.93","0"],["34989.35","0"]],"u":20010584,"seq":14108045588}}'
2023-11-02 14:54:34,548 DEBUG ++Rcv raw: b'\x81~\x01u{"topic":"orderbook.50.BTCUSDC","ts":1698936874463,"type":"delta","data":{"s":"BTCUSDC","b":[["34965.16","0.095173"],["34950.49","0.043453"],["34943.36","0"],["34955.38","0"]],"a":[["34968.67","0.079507"],["34971.84","0.014129"],["34974","0.0324"],["34985.86","0.084782"],["34992.54","0"],["34989.34","0"],["34990.49","0"],["34994.86","0"]],"u":20010585,"seq":14108045609}}'
2023-11-02 14:54:34,549 DEBUG ++Rcv decoded: fin=1 opcode=1 data=b'{"topic":"orderbook.50.BTCUSDC","ts":1698936874463,"type":"delta","data":{"s":"BTCUSDC","b":[["34965.16","0.095173"],["34950.49","0.043453"],["34943.36","0"],["34955.38","0"]],"a":[["34968.67","0.079507"],["34971.84","0.014129"],["34974","0.0324"],["34985.86","0.084782"],["34992.54","0"],["34989.34","0"],["34990.49","0"],["34994.86","0"]],"u":20010585,"seq":14108045609}}'
2023-11-02 14:54:34,569 DEBUG ++Rcv raw: b'\x81~\x01y{"topic":"orderbook.50.BTCUSDC","ts":1698936874484,"type":"delta","data":{"s":"BTCUSDC","b":[["34965.51","0.057199"],["34965.17","0.013136"],["34950.41","0.286119"],["34943.59","0"],["34964.42","0"],["34965.16","0"]],"a":[["34974.25","0.057184"],["34981.2","0.114347"],["34990.96","0.285788"],["34986.01","0"],["34991.45","0"],["34991.96","0"]],"u":20010586,"seq":14108045638}}'
2023-11-02 14:54:34,569 DEBUG ++Rcv decoded: fin=1 opcode=1 data=b'{"topic":"orderbook.50.BTCUSDC","ts":1698936874484,"type":"delta","data":{"s":"BTCUSDC","b":[["34965.51","0.057199"],["34965.17","0.013136"],["34950.41","0.286119"],["34943.59","0"],["34964.42","0"],["34965.16","0"]],"a":[["34974.25","0.057184"],["34981.2","0.114347"],["34990.96","0.285788"],["34986.01","0"],["34991.45","0"],["34991.96","0"]],"u":20010586,"seq":14108045638}}'
2023-11-02 14:54:34,589 DEBUG ++Rcv raw: b'\x81~\x01J{"topic":"orderbook.50.BTCUSDC","ts":1698936874503,"type":"delta","data":{"s":"BTCUSDC","b":[["34943.59","0.1875"],["34943.36","0.028"],["34943.35","0.02598"],["34950.41","0"],["34965.51","0"],["34946.1","0"]],"a":[["34981.19","0.068614"],["34991.45","0.000286"],["34982.53","0"],["34974.25","0"]],"u":20010587,"seq":14108045652}}'
2023-11-02 14:54:34,589 DEBUG ++Rcv decoded: fin=1 opcode=1 data=b'{"topic":"orderbook.50.BTCUSDC","ts":1698936874503,"type":"delta","data":{"s":"BTCUSDC","b":[["34943.59","0.1875"],["34943.36","0.028"],["34943.35","0.02598"],["34950.41","0"],["34965.51","0"],["34946.1","0"]],"a":[["34981.19","0.068614"],["34991.45","0.000286"],["34982.53","0"],["34974.25","0"]],"u":20010587,"seq":14108045652}}'
2023-11-02 14:54:34,610 DEBUG ++Rcv raw: b'\x81~\x00\xd6{"topic":"orderbook.50.BTCUSDC","ts":1698936874524,"type":"delta","data":{"s":"BTCUSDC","b":[["34942.51","0.029619"],["34946.11","0"]],"a":[["34991.96","0.002812"],["34974.59","0"]],"u":20010588,"seq":14108045656}}'
2023-11-02 14:54:34,610 DEBUG ++Rcv decoded: fin=1 opcode=1 data=b'{"topic":"orderbook.50.BTCUSDC","ts":1698936874524,"type":"delta","data":{"s":"BTCUSDC","b":[["34942.51","0.029619"],["34946.11","0"]],"a":[["34991.96","0.002812"],["34974.59","0"]],"u":20010588,"seq":14108045656}}'
2023-11-02 14:54:34,629 DEBUG ++Rcv raw: b'\x81~\x00\xd5{"topic":"orderbook.50.BTCUSDC","ts":1698936874544,"type":"delta","data":{"s":"BTCUSDC","b":[["34964.43","0.00572"],["34942.51","0"]],"a":[["34992.54","0.001425"],["34971.84","0"]],"u":20010589,"seq":14108045671}}'
2023-11-02 14:54:34,629 DEBUG ++Rcv decoded: fin=1 opcode=1 data=b'{"topic":"orderbook.50.BTCUSDC","ts":1698936874544,"type":"delta","data":{"s":"BTCUSDC","b":[["34964.43","0.00572"],["34942.51","0"]],"a":[["34992.54","0.001425"],["34971.84","0"]],"u":20010589,"seq":14108045671}}'
2023-11-02 14:54:34,649 DEBUG ++Rcv raw: b'\x81~\x01s{"topic":"orderbook.50.BTCUSDC","ts":1698936874563,"type":"delta","data":{"s":"BTCUSDC","b":[["34961.24","0.047154"],["34957.18","0.362177"],["34947.77","0.000261"],["34943.35","0"],["34959.91","0"],["34964.41","0"]],"a":[["34977.33","0.046915"],["34994.86","0.002023"],["34995","0.001"],["34982.54","0"],["34981.2","0"],["34990.96","0"]],"u":20010590,"seq":14108045717}}'
2023-11-02 14:54:34,649 DEBUG ++Rcv decoded: fin=1 opcode=1 data=b'{"topic":"orderbook.50.BTCUSDC","ts":1698936874563,"type":"delta","data":{"s":"BTCUSDC","b":[["34961.24","0.047154"],["34957.18","0.362177"],["34947.77","0.000261"],["34943.35","0"],["34959.91","0"],["34964.41","0"]],"a":[["34977.33","0.046915"],["34994.86","0.002023"],["34995","0.001"],["34982.54","0"],["34981.2","0"],["34990.96","0"]],"u":20010590,"seq":14108045717}}'
2023-11-02 14:54:34,670 DEBUG ++Rcv raw: b'\x81~\x01\xc5{"topic":"orderbook.50.BTCUSDC","ts":1698936874584,"type":"delta","data":{"s":"BTCUSDC","b":[["34965.19","0.057199"],["34958.25","0.114422"],["34957.19","0.217314"],["34949.3","0.286128"],["34958.15","0"],["34964","0"],["34943.36","0"],["34943.59","0"]],"a":[["34973.41","0.057186"],["34978.77","0.051549"],["34979.89","0.114351"],["34989.64","0.285798"],["34992.54","0"],["34981.19","0"],["34994.86","0"],["34995","0"]],"u":20010591,"seq":14108045736}}'
2023-11-02 14:54:34,670 DEBUG ++Rcv decoded: fin=1 opcode=1 data=b'{"topic":"orderbook.50.BTCUSDC","ts":1698936874584,"type":"delta","data":{"s":"BTCUSDC","b":[["34965.19","0.057199"],["34958.25","0.114422"],["34957.19","0.217314"],["34949.3","0.286128"],["34958.15","0"],["34964","0"],["34943.36","0"],["34943.59","0"]],"a":[["34973.41","0.057186"],["34978.77","0.051549"],["34979.89","0.114351"],["34989.64","0.285798"],["34992.54","0"],["34981.19","0"],["34994.86","0"],["34995","0"]],"u":20010591,"seq":14108045736}}'
2023-11-02 14:54:34,689 DEBUG ++Rcv raw: b'\x81~\x00\xe8{"topic":"orderbook.50.BTCUSDC","ts":1698936874604,"type":"delta","data":{"s":"BTCUSDC","b":[["34965.19","0.003"],["34943.59","0.1875"],["34949.3","0"]],"a":[["34989.63","0.171478"],["34973.41","0"]],"u":20010592,"seq":14108045752}}'
2023-11-02 14:54:34,689 DEBUG ++Rcv decoded: fin=1 opcode=1 data=b'{"topic":"orderbook.50.BTCUSDC","ts":1698936874604,"type":"delta","data":{"s":"BTCUSDC","b":[["34965.19","0.003"],["34943.59","0.1875"],["34949.3","0"]],"a":[["34989.63","0.171478"],["34973.41","0"]],"u":20010592,"seq":14108045752}}'
2023-11-02 14:54:34,709 DEBUG ++Rcv raw: b'\x81~\x00\xac{"topic":"orderbook.50.BTCUSDC","ts":1698936874624,"type":"delta","data":{"s":"BTCUSDC","b":[],"a":[["34975.67","0.1875"],["34991.96","0"]],"u":20010593,"seq":14108045755}}'
2023-11-02 14:54:34,709 DEBUG ++Rcv decoded: fin=1 opcode=1 data=b'{"topic":"orderbook.50.BTCUSDC","ts":1698936874624,"type":"delta","data":{"s":"BTCUSDC","b":[],"a":[["34975.67","0.1875"],["34991.96","0"]],"u":20010593,"seq":14108045755}}'
2023-11-02 14:54:34,729 DEBUG ++Rcv raw: b'\x81~\x00\xab{"topic":"orderbook.50.BTCUSDC","ts":1698936874644,"type":"delta","data":{"s":"BTCUSDC","b":[["34943.36","0.028"],["34964.43","0"]],"a":[],"u":20010594,"seq":14108045761}}'
2023-11-02 14:54:34,729 DEBUG ++Rcv decoded: fin=1 opcode=1 data=b'{"topic":"orderbook.50.BTCUSDC","ts":1698936874644,"type":"delta","data":{"s":"BTCUSDC","b":[["34943.36","0.028"],["34964.43","0"]],"a":[],"u":20010594,"seq":14108045761}}'
2023-11-02 14:54:34,749 DEBUG ++Rcv raw: b'\x81~\x00\xac{"topic":"orderbook.50.BTCUSDC","ts":1698936874664,"type":"delta","data":{"s":"BTCUSDC","b":[],"a":[["34974.93","0.0441"],["34991.45","0"]],"u":20010595,"seq":14108045772}}'
2023-11-02 14:54:34,749 DEBUG ++Rcv decoded: fin=1 opcode=1 data=b'{"topic":"orderbook.50.BTCUSDC","ts":1698936874664,"type":"delta","data":{"s":"BTCUSDC","b":[],"a":[["34974.93","0.0441"],["34991.45","0"]],"u":20010595,"seq":14108045772}}'
2023-11-02 14:54:34,789 DEBUG ++Rcv raw: b'\x81~\x00\xfa{"topic":"orderbook.50.BTCUSDC","ts":1698936874704,"type":"delta","data":{"s":"BTCUSDC","b":[["34943.35","0.02598"],["34961.49","0"]],"a":[["34970.18","0.0859"],["34986.98","0.0005"],["34991.03","0"],["34991.24","0"]],"u":20010596,"seq":14108045795}}'
2023-11-02 14:54:34,789 DEBUG ++Rcv decoded: fin=1 opcode=1 data=b'{"topic":"orderbook.50.BTCUSDC","ts":1698936874704,"type":"delta","data":{"s":"BTCUSDC","b":[["34943.35","0.02598"],["34961.49","0"]],"a":[["34970.18","0.0859"],["34986.98","0.0005"],["34991.03","0"],["34991.24","0"]],"u":20010596,"seq":14108045795}}'
2023-11-02 14:54:34,811 DEBUG ++Rcv raw: b'\x81~\x02\x0b{"topic":"orderbook.50.BTCUSDC","ts":1698936874725,"type":"delta","data":{"s":"BTCUSDC","b":[["34965.2","0.00572"],["34964.54","0.0572"],["34957.18","0.476602"],["34947.85","0.28614"],["34963.3","0"],["34958.25","0"],["34943.35","0"]],"a":[["34966.48","0.044761"],["34969.7","0.073374"],["34972.3","0.057188"],["34973.61","0.051542"],["34978.77","0.165904"],["34986.15","0.02859"],["34988.53","0.285807"],["34989.64","0"],["34968.67","0"],["34971.89","0"],["34990.48","0"],["34979.89","0"]],"u":20010597,"seq":14108045820}}'
2023-11-02 14:54:34,811 DEBUG ++Rcv decoded: fin=1 opcode=1 data=b'{"topic":"orderbook.50.BTCUSDC","ts":1698936874725,"type":"delta","data":{"s":"BTCUSDC","b":[["34965.2","0.00572"],["34964.54","0.0572"],["34957.18","0.476602"],["34947.85","0.28614"],["34963.3","0"],["34958.25","0"],["34943.35","0"]],"a":[["34966.48","0.044761"],["34969.7","0.073374"],["34972.3","0.057188"],["34973.61","0.051542"],["34978.77","0.165904"],["34986.15","0.02859"],["34988.53","0.285807"],["34989.64","0"],["34968.67","0"],["34971.89","0"],["34990.48","0"],["34979.89","0"]],"u":20010597,"seq":14108045820}}'
2023-11-02 14:54:34,828 DEBUG ++Rcv raw: b'\x81~\x02\x07{"topic":"orderbook.50.BTCUSDC","ts":1698936874743,"type":"delta","data":{"s":"BTCUSDC","b":[["34961.59","0.079836"],["34958.15","0.002633"],["34947.86","0.171689"],["34943.35","0.02598"],["34942.51","0.029619"],["34942.5","0.049354"],["34940.87","0.00154"],["34965.17","0"],["34965.19","0"],["34963.31","0"],["34960.01","0"],["34947.83","0"],["34959.51","0"],["34964.54","0"]],"a":[["34978.76","0.068619"],["34978.77","0.114355"],["34990.48","0.1125"],["34972.3","0"],["34989.63","0"]],"u":20010598,"seq":14108045847}}'
2023-11-02 14:54:34,829 DEBUG ++Rcv decoded: fin=1 opcode=1 data=b'{"topic":"orderbook.50.BTCUSDC","ts":1698936874743,"type":"delta","data":{"s":"BTCUSDC","b":[["34961.59","0.079836"],["34958.15","0.002633"],["34947.86","0.171689"],["34943.35","0.02598"],["34942.51","0.029619"],["34942.5","0.049354"],["34940.87","0.00154"],["34965.17","0"],["34965.19","0"],["34963.31","0"],["34960.01","0"],["34947.83","0"],["34959.51","0"],["34964.54","0"]],"a":[["34978.76","0.068619"],["34978.77","0.114355"],["34990.48","0.1125"],["34972.3","0"],["34989.63","0"]],"u":20010598,"seq":14108045847}}'
2023-11-02 14:54:34,849 DEBUG ++Rcv raw: b'\x81~\x00\xfc{"topic":"orderbook.50.BTCUSDC","ts":1698936874763,"type":"delta","data":{"s":"BTCUSDC","b":[["34960.78","0.036"],["34947.13","0.000261"],["34944.68","0.156757"],["34954.74","0"],["34940.87","0"],["34942.5","0"]],"a":[],"u":20010599,"seq":14108045867}}'
2023-11-02 14:54:34,849 DEBUG ++Rcv decoded: fin=1 opcode=1 data=b'{"topic":"orderbook.50.BTCUSDC","ts":1698936874763,"type":"delta","data":{"s":"BTCUSDC","b":[["34960.78","0.036"],["34947.13","0.000261"],["34944.68","0.156757"],["34954.74","0"],["34940.87","0"],["34942.5","0"]],"a":[],"u":20010599,"seq":14108045867}}'
2023-11-02 14:54:34,869 DEBUG ++Rcv raw: b'\x81~\x00\xae{"topic":"orderbook.50.BTCUSDC","ts":1698936874783,"type":"delta","data":{"s":"BTCUSDC","b":[["34944.69","0.094061"],["34942.51","0"]],"a":[],"u":20010600,"seq":14108045872}}'
2023-11-02 14:54:34,869 DEBUG ++Rcv decoded: fin=1 opcode=1 data=b'{"topic":"orderbook.50.BTCUSDC","ts":1698936874783,"type":"delta","data":{"s":"BTCUSDC","b":[["34944.69","0.094061"],["34942.51","0"]],"a":[],"u":20010600,"seq":14108045872}}'
2023-11-02 14:54:34,889 DEBUG ++Rcv raw: b'\x81~\x01\r{"topic":"orderbook.50.BTCUSDC","ts":1698936874803,"type":"delta","data":{"s":"BTCUSDC","b":[["34960.26","0.022766"],["34942.51","0.029619"],["34962","0"],["34965.2","0"]],"a":[["34968","0.0324"],["34969.7","0.095914"],["34990.48","0"]],"u":20010601,"seq":14108045885}}'
2023-11-02 14:54:34,889 DEBUG ++Rcv decoded: fin=1 opcode=1 data=b'{"topic":"orderbook.50.BTCUSDC","ts":1698936874803,"type":"delta","data":{"s":"BTCUSDC","b":[["34960.26","0.022766"],["34942.51","0.029619"],["34962","0"],["34965.2","0"]],"a":[["34968","0.0324"],["34969.7","0.095914"],["34990.48","0"]],"u":20010601,"seq":14108045885}}'
2023-11-02 14:54:34,909 DEBUG ++Rcv raw: b'\x81~\x01L{"topic":"orderbook.50.BTCUSDC","ts":1698936874823,"type":"delta","data":{"s":"BTCUSDC","b":[["34962.01","0.013136"],["34956.7","0.00057"],["34954.49","0"],["34942.51","0"]],"a":[["34965.37","0.067892"],["34968.46","0.0859"],["34975.21","0.80318"],["34990.07","0"],["34966.48","0"],["34974.81","0"]],"u":20010602,"seq":14108045901}}'
2023-11-02 14:54:34,909 DEBUG ++Rcv decoded: fin=1 opcode=1 data=b'{"topic":"orderbook.50.BTCUSDC","ts":1698936874823,"type":"delta","data":{"s":"BTCUSDC","b":[["34962.01","0.013136"],["34956.7","0.00057"],["34954.49","0"],["34942.51","0"]],"a":[["34965.37","0.067892"],["34968.46","0.0859"],["34975.21","0.80318"],["34990.07","0"],["34966.48","0"],["34974.81","0"]],"u":20010602,"seq":14108045901}}'
2023-11-02 14:54:34,928 DEBUG ++Rcv raw: b'\x81~\x01\'{"topic":"orderbook.50.BTCUSDC","ts":1698936874843,"type":"delta","data":{"s":"BTCUSDC","b":[["34954.73","0.051549"]],"a":[["34967.99","0.07098"],["34969.7","0.02254"],["34970","0.0324"],["34971.89","0.051541"],["34973.61","0"],["34988.01","0"],["34988.53","0"]],"u":20010603,"seq":14108045913}}'
2023-11-02 14:54:34,928 DEBUG ++Rcv decoded: fin=1 opcode=1 data=b'{"topic":"orderbook.50.BTCUSDC","ts":1698936874843,"type":"delta","data":{"s":"BTCUSDC","b":[["34954.73","0.051549"]],"a":[["34967.99","0.07098"],["34969.7","0.02254"],["34970","0.0324"],["34971.89","0.051541"],["34973.61","0"],["34988.01","0"],["34988.53","0"]],"u":20010603,"seq":14108045913}}'
2023-11-02 14:54:34,949 DEBUG ++Rcv raw: b'\x81~\x00\xff{"topic":"orderbook.50.BTCUSDC","ts":1698936874863,"type":"delta","data":{"s":"BTCUSDC","b":[["34962.34","0.057204"],["34943.35","0"]],"a":[["34971.78","0.057188"],["34972.46","0.000239"],["34987.53","0"],["34987.52","0"]],"u":20010604,"seq":14108045923}}'
2023-11-02 14:54:34,949 DEBUG ++Rcv decoded: fin=1 opcode=1 data=b'{"topic":"orderbook.50.BTCUSDC","ts":1698936874863,"type":"delta","data":{"s":"BTCUSDC","b":[["34962.34","0.057204"],["34943.35","0"]],"a":[["34971.78","0.057188"],["34972.46","0.000239"],["34987.53","0"],["34987.52","0"]],"u":20010604,"seq":14108045923}}'
2023-11-02 14:54:34,969 DEBUG ++Rcv raw: b'\x81~\x01i{"topic":"orderbook.50.BTCUSDC","ts":1698936874883,"type":"delta","data":{"s":"BTCUSDC","b":[["34962.35","0.042206"],["34961.59","0.051543"],["34960.01","0.051544"],["34952.86","0.042349"],["34943.36","0"],["34943.59","0"],["34962.34","0"]],"a":[["34974.04","0.028597"],["34975.99","0.042864"],["34968.46","0"],["34986.98","0"]],"u":20010605,"seq":14108045942}}'
2023-11-02 14:54:34,969 DEBUG ++Rcv decoded: fin=1 opcode=1 data=b'{"topic":"orderbook.50.BTCUSDC","ts":1698936874883,"type":"delta","data":{"s":"BTCUSDC","b":[["34962.35","0.042206"],["34961.59","0.051543"],["34960.01","0.051544"],["34952.86","0.042349"],["34943.36","0"],["34943.59","0"],["34962.34","0"]],"a":[["34974.04","0.028597"],["34975.99","0.042864"],["34968.46","0"],["34986.98","0"]],"u":20010605,"seq":14108045942}}'
2023-11-02 14:54:34,989 DEBUG ++Rcv raw: b'\x81~\x01\xb3{"topic":"orderbook.50.BTCUSDC","ts":1698936874903,"type":"delta","data":{"s":"BTCUSDC","b":[["34962.36","0.013136"],["34961.59","0.073395"],["34943.59","0.1875"],["34943.36","0.028"],["34943.35","0.02598"],["34962.01","0"],["34947.85","0"],["34962.35","0"],["34960.01","0"]],"a":[["34969.99","0.095863"],["34973.61","0.051547"],["34986.98","0.0005"],["34971.89","0"],["34971.78","0"],["34967.99","0"]],"u":20010606,"seq":14108045958}}'
2023-11-02 14:54:34,989 DEBUG ++Rcv decoded: fin=1 opcode=1 data=b'{"topic":"orderbook.50.BTCUSDC","ts":1698936874903,"type":"delta","data":{"s":"BTCUSDC","b":[["34962.36","0.013136"],["34961.59","0.073395"],["34943.59","0.1875"],["34943.36","0.028"],["34943.35","0.02598"],["34962.01","0"],["34947.85","0"],["34962.35","0"],["34960.01","0"]],"a":[["34969.99","0.095863"],["34973.61","0.051547"],["34986.98","0.0005"],["34971.89","0"],["34971.78","0"],["34967.99","0"]],"u":20010606,"seq":14108045958}}'
2023-11-02 14:54:35,009 DEBUG ++Rcv raw: b'\x81~\x00\xd7{"topic":"orderbook.50.BTCUSDC","ts":1698936874924,"type":"delta","data":{"s":"BTCUSDC","b":[["34947.83","0.112508"],["34946.72","0.286149"],["34947.86","0"],["34943.35","0"]],"a":[],"u":20010607,"seq":14108045962}}'
2023-11-02 14:54:35,009 DEBUG ++Rcv decoded: fin=1 opcode=1 data=b'{"topic":"orderbook.50.BTCUSDC","ts":1698936874924,"type":"delta","data":{"s":"BTCUSDC","b":[["34947.83","0.112508"],["34946.72","0.286149"],["34947.86","0"],["34943.35","0"]],"a":[],"u":20010607,"seq":14108045962}}'
2023-11-02 14:54:35,029 DEBUG ++Rcv raw: b'\x81~\x00\xc5{"topic":"orderbook.50.BTCUSDC","ts":1698936874943,"type":"delta","data":{"s":"BTCUSDC","b":[["34957.18","0.362177"]],"a":[["34987.52","0.112508"],["34975.99","0"]],"u":20010608,"seq":14108045969}}'
2023-11-02 14:54:35,031 DEBUG ++Rcv decoded: fin=1 opcode=1 data=b'{"topic":"orderbook.50.BTCUSDC","ts":1698936874943,"type":"delta","data":{"s":"BTCUSDC","b":[["34957.18","0.362177"]],"a":[["34987.52","0.112508"],["34975.99","0"]],"u":20010608,"seq":14108045969}}'
2023-11-02 14:54:35,049 DEBUG ++Rcv raw: b'\x81~\x01\xa3{"topic":"orderbook.50.BTCUSDC","ts":1698936874963,"type":"delta","data":{"s":"BTCUSDC","b":[["34962.37","0.028598"],["34956.05","0.114429"],["34947.25","0.171698"],["34943.59","0"],["34943.36","0"],["34947.83","0"]],"a":[["34964.41","0.054685"],["34972.55","0.014532"],["34977.67","0.114358"],["34987.47","0.285816"],["34985.86","0"],["34978.77","0"],["34965.37","0"],["34974.04","0"]],"u":20010609,"seq":14108045994}}'
2023-11-02 14:54:35,049 DEBUG ++Rcv decoded: fin=1 opcode=1 data=b'{"topic":"orderbook.50.BTCUSDC","ts":1698936874963,"type":"delta","data":{"s":"BTCUSDC","b":[["34962.37","0.028598"],["34956.05","0.114429"],["34947.25","0.171698"],["34943.59","0"],["34943.36","0"],["34947.83","0"]],"a":[["34964.41","0.054685"],["34972.55","0.014532"],["34977.67","0.114358"],["34987.47","0.285816"],["34985.86","0"],["34978.77","0"],["34965.37","0"],["34974.04","0"]],"u":20010609,"seq":14108045994}}'
2023-11-02 14:54:35,068 DEBUG ++Rcv raw: b'\x81~\x01p{"topic":"orderbook.50.BTCUSDC","ts":1698936874983,"type":"delta","data":{"s":"BTCUSDC","b":[["34962.66","0.057203"],["34943.59","0.1875"],["34943.36","0.028"],["34957.18","0"],["34956.7","0"],["34947.77","0"]],"a":[["34970.66","0.0441"],["34970.68","0.05719"],["34972.4","0.000239"],["34987.47","0"],["34987.52","0"],["34978.76","0"]],"u":20010610,"seq":14108046011}}'
2023-11-02 14:54:35,069 DEBUG ++Rcv decoded: fin=1 opcode=1 data=b'{"topic":"orderbook.50.BTCUSDC","ts":1698936874983,"type":"delta","data":{"s":"BTCUSDC","b":[["34962.66","0.057203"],["34943.59","0.1875"],["34943.36","0.028"],["34957.18","0"],["34956.7","0"],["34947.77","0"]],"a":[["34970.66","0.0441"],["34970.68","0.05719"],["34972.4","0.000239"],["34987.47","0"],["34987.52","0"],["34978.76","0"]],"u":20010610,"seq":14108046011}}'
2023-11-02 14:54:35,089 DEBUG ++Rcv raw: b'\x81~\x01\x91{"topic":"orderbook.50.BTCUSDC","ts":1698936875003,"type":"delta","data":{"s":"BTCUSDC","b":[["34958.15","0.054173"],["34956.44","0.436785"],["34953.75","0.046415"],["34943.35","0.02598"],["34942.51","0.029619"],["34954.73","0"],["34946.72","0"],["34962.66","0"],["34957.19","0"]],"a":[["34971.89","0.051543"],["34987.47","0.285816"],["34973.61","0"],["34970.68","0"]],"u":20010611,"seq":14108046028}}'
2023-11-02 14:54:35,089 DEBUG ++Rcv decoded: fin=1 opcode=1 data=b'{"topic":"orderbook.50.BTCUSDC","ts":1698936875003,"type":"delta","data":{"s":"BTCUSDC","b":[["34958.15","0.054173"],["34956.44","0.436785"],["34953.75","0.046415"],["34943.35","0.02598"],["34942.51","0.029619"],["34954.73","0"],["34946.72","0"],["34962.66","0"],["34957.19","0"]],"a":[["34971.89","0.051543"],["34987.47","0.285816"],["34973.61","0"],["34970.68","0"]],"u":20010611,"seq":14108046028}}'
2023-11-02 14:54:35,111 DEBUG ++Rcv raw: b'\x81~\x01A{"topic":"orderbook.50.BTCUSDC","ts":1698936875025,"type":"delta","data":{"s":"BTCUSDC","b":[["34956.45","0.262075"],["34956.44","0.368127"],["34954.71","0.051545"],["34947.83","0.112506"],["34945.23","0.286162"],["34943.35","0"],["34942.51","0"],["34947.25","0"],["34953.75","0"]],"a":[],"u":20010612,"seq":14108046039}}'
2023-11-02 14:54:35,111 DEBUG ++Rcv decoded: fin=1 opcode=1 data=b'{"topic":"orderbook.50.BTCUSDC","ts":1698936875025,"type":"delta","data":{"s":"BTCUSDC","b":[["34956.45","0.262075"],["34956.44","0.368127"],["34954.71","0.051545"],["34947.83","0.112506"],["34945.23","0.286162"],["34943.35","0"],["34942.51","0"],["34947.25","0"],["34953.75","0"]],"a":[],"u":20010612,"seq":14108046039}}'
2023-11-02 14:54:35,130 DEBUG ++Rcv raw: b'\x81~\x01#{"topic":"orderbook.50.BTCUSDC","ts":1698936875044,"type":"delta","data":{"s":"BTCUSDC","b":[["34945.24","0.171704"],["34943.35","0.02598"],["34956.05","0"],["34944.69","0"]],"a":[["34968.46","0.0859"],["34987.53","0.1875"],["34977.67","0"],["34987.47","0"]],"u":20010613,"seq":14108046053}}'
2023-11-02 14:54:35,130 DEBUG ++Rcv decoded: fin=1 opcode=1 data=b'{"topic":"orderbook.50.BTCUSDC","ts":1698936875044,"type":"delta","data":{"s":"BTCUSDC","b":[["34945.24","0.171704"],["34943.35","0.02598"],["34956.05","0"],["34944.69","0"]],"a":[["34968.46","0.0859"],["34987.53","0.1875"],["34977.67","0"],["34987.47","0"]],"u":20010613,"seq":14108046053}}'
2023-11-02 14:54:35,149 DEBUG ++Rcv raw: b'\x81~\x01\xc6{"topic":"orderbook.50.BTCUSDC","ts":1698936875063,"type":"delta","data":{"s":"BTCUSDC","b":[["34959.36","0.0286"],["34954.72","0.114433"],["34942.51","0.029619"],["34942.5","0.049354"],["34940.87","0.00154"],["34956.44","0"],["34952.71","0"],["34952.91","0"],["34953.73","0"],["34962.37","0"]],"a":[["34967.99","0.070988"],["34971.45","0.0286"],["34976.43","0.114362"],["34969.99","0"],["34986.98","0"],["34987.53","0"]],"u":20010614,"seq":14108046074}}'
2023-11-02 14:54:35,149 DEBUG ++Rcv decoded: fin=1 opcode=1 data=b'{"topic":"orderbook.50.BTCUSDC","ts":1698936875063,"type":"delta","data":{"s":"BTCUSDC","b":[["34959.36","0.0286"],["34954.72","0.114433"],["34942.51","0.029619"],["34942.5","0.049354"],["34940.87","0.00154"],["34956.44","0"],["34952.71","0"],["34952.91","0"],["34953.73","0"],["34962.37","0"]],"a":[["34967.99","0.070988"],["34971.45","0.0286"],["34976.43","0.114362"],["34969.99","0"],["34986.98","0"],["34987.53","0"]],"u":20010614,"seq":14108046074}}'
2023-11-02 14:54:35,169 DEBUG ++Rcv raw: b'\x81~\x01&{"topic":"orderbook.50.BTCUSDC","ts":1698936875084,"type":"delta","data":{"s":"BTCUSDC","b":[["34962.57","0.057204"],["34954.73","0.068668"],["34956.45","0"],["34954.71","0"]],"a":[["34970.36","0.057191"],["34971.41","0.1875"],["34986.15","0"],["34977.05","0"]],"u":20010615,"seq":14108046089}}'
2023-11-02 14:54:35,169 DEBUG ++Rcv decoded: fin=1 opcode=1 data=b'{"topic":"orderbook.50.BTCUSDC","ts":1698936875084,"type":"delta","data":{"s":"BTCUSDC","b":[["34962.57","0.057204"],["34954.73","0.068668"],["34956.45","0"],["34954.71","0"]],"a":[["34970.36","0.057191"],["34971.41","0.1875"],["34986.15","0"],["34977.05","0"]],"u":20010615,"seq":14108046089}}'
2023-11-02 14:54:35,189 DEBUG ++Rcv raw: b'\x81~\x00\xd6{"topic":"orderbook.50.BTCUSDC","ts":1698936875103,"type":"delta","data":{"s":"BTCUSDC","b":[],"a":[["34971.4","0.112501"],["34973.61","0.051542"],["34986.02","0"],["34971.89","0"]],"u":20010616,"seq":14108046095}}'
2023-11-02 14:54:35,189 DEBUG ++Rcv decoded: fin=1 opcode=1 data=b'{"topic":"orderbook.50.BTCUSDC","ts":1698936875103,"type":"delta","data":{"s":"BTCUSDC","b":[],"a":[["34971.4","0.112501"],["34973.61","0.051542"],["34986.02","0"],["34971.89","0"]],"u":20010616,"seq":14108046095}}'
2023-11-02 14:54:35,210 DEBUG ++Rcv raw: b'\x81~\x01({"topic":"orderbook.50.BTCUSDC","ts":1698936875123,"type":"delta","data":{"s":"BTCUSDC","b":[["34959.45","0.046685"],["34950.23","0.026208"],["34940.31","0.112505"],["34950.49","0"],["34961.24","0"],["34960.78","0"]],"a":[["34975.53","0.053874"],["34977.33","0"]],"u":20010617,"seq":14108046115}}'
2023-11-02 14:54:35,210 DEBUG ++Rcv decoded: fin=1 opcode=1 data=b'{"topic":"orderbook.50.BTCUSDC","ts":1698936875123,"type":"delta","data":{"s":"BTCUSDC","b":[["34959.45","0.046685"],["34950.23","0.026208"],["34940.31","0.112505"],["34950.49","0"],["34961.24","0"],["34960.78","0"]],"a":[["34975.53","0.053874"],["34977.33","0"]],"u":20010617,"seq":14108046115}}'
2023-11-02 14:54:35,229 DEBUG ++Rcv raw: b'\x81~\x00\xfd{"topic":"orderbook.50.BTCUSDC","ts":1698936875143,"type":"delta","data":{"s":"BTCUSDC","b":[["34956.46","0.036386"],["34954.74","0.002116"],["34940.31","0"],["34962.57","0"]],"a":[["34986.02","0.4055"],["34970.36","0"]],"u":20010618,"seq":14108046138}}'
2023-11-02 14:54:35,229 DEBUG ++Rcv decoded: fin=1 opcode=1 data=b'{"topic":"orderbook.50.BTCUSDC","ts":1698936875143,"type":"delta","data":{"s":"BTCUSDC","b":[["34956.46","0.036386"],["34954.74","0.002116"],["34940.31","0"],["34962.57","0"]],"a":[["34986.02","0.4055"],["34970.36","0"]],"u":20010618,"seq":14108046138}}'
2023-11-02 14:54:35,249 DEBUG ++Rcv raw: b'\x81~\x01\x01{"topic":"orderbook.50.BTCUSDC","ts":1698936875163,"type":"delta","data":{"s":"BTCUSDC","b":[["34962.36","0.003"],["34958.15","0.05154"],["34940.31","0.112505"],["34939.86","2.2125"],["34961.58","0"],["34950.99","0"]],"a":[],"u":20010619,"seq":14108046184}}'
2023-11-02 14:54:35,249 DEBUG ++Rcv decoded: fin=1 opcode=1 data=b'{"topic":"orderbook.50.BTCUSDC","ts":1698936875163,"type":"delta","data":{"s":"BTCUSDC","b":[["34962.36","0.003"],["34958.15","0.05154"],["34940.31","0.112505"],["34939.86","2.2125"],["34961.58","0"],["34950.99","0"]],"a":[],"u":20010619,"seq":14108046184}}'
2023-11-02 14:54:35,268 DEBUG ++Rcv raw: b'\x81~\x01\x13{"topic":"orderbook.50.BTCUSDC","ts":1698936875183,"type":"delta","data":{"s":"BTCUSDC","b":[["34960.01","0.116154"],["34956.47","0.051544"],["34951.27","0.051545"],["34939.85","0.1875"],["34960","0"],["34958.15","0"],["34961.59","0"]],"a":[],"u":20010620,"seq":14108046208}}'
2023-11-02 14:54:35,269 DEBUG ++Rcv decoded: fin=1 opcode=1 data=b'{"topic":"orderbook.50.BTCUSDC","ts":1698936875183,"type":"delta","data":{"s":"BTCUSDC","b":[["34960.01","0.116154"],["34956.47","0.051544"],["34951.27","0.051545"],["34939.85","0.1875"],["34960","0"],["34958.15","0"],["34961.59","0"]],"a":[],"u":20010620,"seq":14108046208}}'
2023-11-02 14:54:35,309 DEBUG ++Rcv raw: b'\x81~\x00\xae{"topic":"orderbook.50.BTCUSDC","ts":1698936875223,"type":"delta","data":{"s":"BTCUSDC","b":[],"a":[["34976.12","0.043812"],["34972.46","0"]],"u":20010621,"seq":14108046238}}'
2023-11-02 14:54:35,309 DEBUG ++Rcv decoded: fin=1 opcode=1 data=b'{"topic":"orderbook.50.BTCUSDC","ts":1698936875223,"type":"delta","data":{"s":"BTCUSDC","b":[],"a":[["34976.12","0.043812"],["34972.46","0"]],"u":20010621,"seq":14108046238}}'
2023-11-02 14:54:35,330 DEBUG ++Rcv raw: b'\x81~\x00\xae{"topic":"orderbook.50.BTCUSDC","ts":1698936875244,"type":"delta","data":{"s":"BTCUSDC","b":[],"a":[["34976.42","0.364006"],["34986.02","0"]],"u":20010622,"seq":14108046251}}'
2023-11-02 14:54:35,330 DEBUG ++Rcv decoded: fin=1 opcode=1 data=b'{"topic":"orderbook.50.BTCUSDC","ts":1698936875244,"type":"delta","data":{"s":"BTCUSDC","b":[],"a":[["34976.42","0.364006"],["34986.02","0"]],"u":20010622,"seq":14108046251}}'
2023-11-02 14:54:35,350 DEBUG ++Rcv raw: b'\x81~\x01%{"topic":"orderbook.50.BTCUSDC","ts":1698936875263,"type":"delta","data":{"s":"BTCUSDC","b":[["34961.84","0.057205"],["34944.94","0.078186"],["34939.86","0"],["34939.85","0"]],"a":[["34968.85","0.057193"],["34979.99","0.058397"],["34985","0"],["34985.12","0"]],"u":20010623,"seq":14108046269}}'
2023-11-02 14:54:35,350 DEBUG ++Rcv decoded: fin=1 opcode=1 data=b'{"topic":"orderbook.50.BTCUSDC","ts":1698936875263,"type":"delta","data":{"s":"BTCUSDC","b":[["34961.84","0.057205"],["34944.94","0.078186"],["34939.86","0"],["34939.85","0"]],"a":[["34968.85","0.057193"],["34979.99","0.058397"],["34985","0"],["34985.12","0"]],"u":20010623,"seq":14108046269}}'
2023-11-02 14:54:35,369 DEBUG ++Rcv raw: b'\x81~\x00\xd6{"topic":"orderbook.50.BTCUSDC","ts":1698936875283,"type":"delta","data":{"s":"BTCUSDC","b":[["34954.75","0.365725"],["34940.31","0"]],"a":[["34969.69","0.051546"],["34976.42","0"]],"u":20010624,"seq":14108046277}}'
2023-11-02 14:54:35,369 DEBUG ++Rcv decoded: fin=1 opcode=1 data=b'{"topic":"orderbook.50.BTCUSDC","ts":1698936875283,"type":"delta","data":{"s":"BTCUSDC","b":[["34954.75","0.365725"],["34940.31","0"]],"a":[["34969.69","0.051546"],["34976.42","0"]],"u":20010624,"seq":14108046277}}'
2023-11-02 14:54:35,388 DEBUG ++Rcv raw: b'\x81~\x00\xae{"topic":"orderbook.50.BTCUSDC","ts":1698936875303,"type":"delta","data":{"s":"BTCUSDC","b":[["34954.76","0.219442"],["34954.73","0"]],"a":[],"u":20010625,"seq":14108046280}}'
2023-11-02 14:54:35,389 DEBUG ++Rcv decoded: fin=1 opcode=1 data=b'{"topic":"orderbook.50.BTCUSDC","ts":1698936875303,"type":"delta","data":{"s":"BTCUSDC","b":[["34954.76","0.219442"],["34954.73","0"]],"a":[],"u":20010625,"seq":14108046280}}'
2023-11-02 14:54:35,408 DEBUG ++Rcv raw: b'\x81~\x00\xd6{"topic":"orderbook.50.BTCUSDC","ts":1698936875323,"type":"delta","data":{"s":"BTCUSDC","b":[["34940.31","0.112505"],["34959.45","0"]],"a":[["34980.25","0.052186"],["34975.53","0"]],"u":20010626,"seq":14108046294}}'
2023-11-02 14:54:35,409 DEBUG ++Rcv decoded: fin=1 opcode=1 data=b'{"topic":"orderbook.50.BTCUSDC","ts":1698936875323,"type":"delta","data":{"s":"BTCUSDC","b":[["34940.31","0.112505"],["34959.45","0"]],"a":[["34980.25","0.052186"],["34975.53","0"]],"u":20010626,"seq":14108046294}}'
2023-11-02 14:54:35,429 DEBUG ++Rcv raw: b'\x81~\x00\xc6{"topic":"orderbook.50.BTCUSDC","ts":1698936875344,"type":"delta","data":{"s":"BTCUSDC","b":[["34960.01","0.068708"],["34954.33","0.045608"],["34940.31","0"]],"a":[],"u":20010627,"seq":14108046309}}'
2023-11-02 14:54:35,429 DEBUG ++Rcv decoded: fin=1 opcode=1 data=b'{"topic":"orderbook.50.BTCUSDC","ts":1698936875344,"type":"delta","data":{"s":"BTCUSDC","b":[["34960.01","0.068708"],["34954.33","0.045608"],["34940.31","0"]],"a":[],"u":20010627,"seq":14108046309}}'
2023-11-02 14:54:35,449 DEBUG ++Rcv raw: b'\x81~\x00\xae{"topic":"orderbook.50.BTCUSDC","ts":1698936875363,"type":"delta","data":{"s":"BTCUSDC","b":[["34940.31","0.112505"],["34961.84","0"]],"a":[],"u":20010628,"seq":14108046320}}'
2023-11-02 14:54:35,449 DEBUG ++Rcv decoded: fin=1 opcode=1 data=b'{"topic":"orderbook.50.BTCUSDC","ts":1698936875363,"type":"delta","data":{"s":"BTCUSDC","b":[["34940.31","0.112505"],["34961.84","0"]],"a":[],"u":20010628,"seq":14108046320}}'
2023-11-02 14:54:35,469 DEBUG ++Rcv raw: b'\x81~\x00\xfc{"topic":"orderbook.50.BTCUSDC","ts":1698936875384,"type":"delta","data":{"s":"BTCUSDC","b":[["34960.27","0.013136"],["34962.36","0"]],"a":[["34963.4","0.064801"],["34966.74","0.0859"],["34964.41","0"],["34984.95","0"]],"u":20010629,"seq":14108046355}}'
2023-11-02 14:54:35,469 DEBUG ++Rcv decoded: fin=1 opcode=1 data=b'{"topic":"orderbook.50.BTCUSDC","ts":1698936875384,"type":"delta","data":{"s":"BTCUSDC","b":[["34960.27","0.013136"],["34962.36","0"]],"a":[["34963.4","0.064801"],["34966.74","0.0859"],["34964.41","0"],["34984.95","0"]],"u":20010629,"seq":14108046355}}'
2023-11-02 14:54:35,489 DEBUG ++Rcv raw: b'\x81~\x01i{"topic":"orderbook.50.BTCUSDC","ts":1698936875403,"type":"delta","data":{"s":"BTCUSDC","b":[["34955.38","0.00057"],["34955.02","0.036"],["34940.87","0"],["34940.31","0"]],"a":[["34962.71","0.003"],["34966","0.0324"],["34966.73","0.051549"],["34978.62","0.03"],["34984.8","0"],["34967.99","0"],["34984.79","0"],["34984.83","0"]],"u":20010630,"seq":14108046388}}'
2023-11-02 14:54:35,489 DEBUG ++Rcv decoded: fin=1 opcode=1 data=b'{"topic":"orderbook.50.BTCUSDC","ts":1698936875403,"type":"delta","data":{"s":"BTCUSDC","b":[["34955.38","0.00057"],["34955.02","0.036"],["34940.87","0"],["34940.31","0"]],"a":[["34962.71","0.003"],["34966","0.0324"],["34966.73","0.051549"],["34978.62","0.03"],["34984.8","0"],["34967.99","0"],["34984.79","0"],["34984.83","0"]],"u":20010630,"seq":14108046388}}'
2023-11-02 14:54:35,509 DEBUG ++Rcv raw: b'\x81~\x02\xa3{"topic":"orderbook.50.BTCUSDC","ts":1698936875423,"type":"delta","data":{"s":"BTCUSDC","b":[["34940.87","0.00154"],["34940.31","0.112505"],["34939.86","2.2125"],["34939.85","0.1875"],["34939.27","0.029858"],["34939.12","0.034348"],["34939.11","0.057242"],["34937.39","0.278379"],["34937.36","0.4234"],["34945.23","0"],["34960.26","0"],["34959.86","0"],["34955.38","0"],["34944.94","0"],["34954.72","0"],["34957.17","0"],["34942.5","0"],["34956.43","0"]],"a":[["34963.4","0.001992"],["34964.4","0.01143"],["34984.79","0.317399"],["34984.8","0.528984"],["34984.83","0.0002"],["34979.99","0"],["34971.45","0"],["34968.85","0"],["34976.43","0"]],"u":20010631,"seq":14108046422}}'
2023-11-02 14:54:35,509 DEBUG ++Rcv decoded: fin=1 opcode=1 data=b'{"topic":"orderbook.50.BTCUSDC","ts":1698936875423,"type":"delta","data":{"s":"BTCUSDC","b":[["34940.87","0.00154"],["34940.31","0.112505"],["34939.86","2.2125"],["34939.85","0.1875"],["34939.27","0.029858"],["34939.12","0.034348"],["34939.11","0.057242"],["34937.39","0.278379"],["34937.36","0.4234"],["34945.23","0"],["34960.26","0"],["34959.86","0"],["34955.38","0"],["34944.94","0"],["34954.72","0"],["34957.17","0"],["34942.5","0"],["34956.43","0"]],"a":[["34963.4","0.001992"],["34964.4","0.01143"],["34984.79","0.317399"],["34984.8","0.528984"],["34984.83","0.0002"],["34979.99","0"],["34971.45","0"],["34968.85","0"],["34976.43","0"]],"u":20010631,"seq":14108046422}}'
2023-11-02 14:54:35,528 DEBUG ++Rcv raw: b'\x81~\x02[{"topic":"orderbook.50.BTCUSDC","ts":1698936875443,"type":"delta","data":{"s":"BTCUSDC","b":[["34960.51","0.057207"],["34958.15","0.05154"],["34955.03","0.021601"],["34954.77","0.001545"],["34953.57","0.114437"],["34945.24","0.094056"],["34943.78","0.286173"],["34936.36","0.823809"],["34954.75","0"],["34960.27","0"],["34960.01","0"],["34956.47","0"],["34942.51","0"],["34947.13","0"],["34959.36","0"]],"a":[["34962.7","0.089523"],["34967.97","0.057195"],["34974.97","0.114367"],["34984.77","0.285838"],["34972.4","0"],["34984.8","0"],["34984.83","0"],["34984.79","0"]],"u":20010632,"seq":14108046477}}'
2023-11-02 14:54:35,529 DEBUG ++Rcv decoded: fin=1 opcode=1 data=b'{"topic":"orderbook.50.BTCUSDC","ts":1698936875443,"type":"delta","data":{"s":"BTCUSDC","b":[["34960.51","0.057207"],["34958.15","0.05154"],["34955.03","0.021601"],["34954.77","0.001545"],["34953.57","0.114437"],["34945.24","0.094056"],["34943.78","0.286173"],["34936.36","0.823809"],["34954.75","0"],["34960.27","0"],["34960.01","0"],["34956.47","0"],["34942.51","0"],["34947.13","0"],["34959.36","0"]],"a":[["34962.7","0.089523"],["34967.97","0.057195"],["34974.97","0.114367"],["34984.77","0.285838"],["34972.4","0"],["34984.8","0"],["34984.83","0"],["34984.79","0"]],"u":20010632,"seq":14108046477}}'
2023-11-02 14:54:35,550 DEBUG ++Rcv raw: b'\x81~\x024{"topic":"orderbook.50.BTCUSDC","ts":1698936875464,"type":"delta","data":{"s":"BTCUSDC","b":[["34956.42","0.114502"],["34953.75","0.068665"],["34944.01","0.171707"],["34936.35","0.1875"],["34935.91","1.373003"],["34931.32","0.112504"],["34931.31","0.1875"],["34954.76","0"],["34943.78","0"],["34960.51","0"],["34943.76","0"],["34953.11","0"],["34953.57","0"]],"a":[["34962.7","0.04333"],["34968.46","0.114502"],["34984.79","0.317399"],["34984.8","0.528984"],["34984.83","0.0002"],["34974.97","0"],["34967.97","0"],["34984.77","0"]],"u":20010633,"seq":14108046518}}'
2023-11-02 14:54:35,550 DEBUG ++Rcv decoded: fin=1 opcode=1 data=b'{"topic":"orderbook.50.BTCUSDC","ts":1698936875464,"type":"delta","data":{"s":"BTCUSDC","b":[["34956.42","0.114502"],["34953.75","0.068665"],["34944.01","0.171707"],["34936.35","0.1875"],["34935.91","1.373003"],["34931.32","0.112504"],["34931.31","0.1875"],["34954.76","0"],["34943.78","0"],["34960.51","0"],["34943.76","0"],["34953.11","0"],["34953.57","0"]],"a":[["34962.7","0.04333"],["34968.46","0.114502"],["34984.79","0.317399"],["34984.8","0.528984"],["34984.83","0.0002"],["34974.97","0"],["34967.97","0"],["34984.77","0"]],"u":20010633,"seq":14108046518}}'
2023-11-02 14:54:35,569 DEBUG ++Rcv raw: b'\x81~\x01\xdf{"topic":"orderbook.50.BTCUSDC","ts":1698936875484,"type":"delta","data":{"s":"BTCUSDC","b":[["34958.16","0.004376"],["34956.47","0.068706"],["34954.71","0.051546"],["34953.26","0.00057"],["34953.11","0.051547"],["34944.01","0.112508"],["34955.03","0"],["34954.74","0"],["34931.32","0"],["34953.75","0"],["34931.31","0"]],"a":[["34962.68","0.00438"],["34962.69","0.03895"],["34967.99","0.06871"],["34969.69","0"],["34984.83","0"],["34962.7","0"]],"u":20010634,"seq":14108046556}}'
2023-11-02 14:54:35,569 DEBUG ++Rcv decoded: fin=1 opcode=1 data=b'{"topic":"orderbook.50.BTCUSDC","ts":1698936875484,"type":"delta","data":{"s":"BTCUSDC","b":[["34958.16","0.004376"],["34956.47","0.068706"],["34954.71","0.051546"],["34953.26","0.00057"],["34953.11","0.051547"],["34944.01","0.112508"],["34955.03","0"],["34954.74","0"],["34931.32","0"],["34953.75","0"],["34931.31","0"]],"a":[["34962.68","0.00438"],["34962.69","0.03895"],["34967.99","0.06871"],["34969.69","0"],["34984.83","0"],["34962.7","0"]],"u":20010634,"seq":14108046556}}'
2023-11-02 14:54:35,589 DEBUG ++Rcv raw: b'\x81~\x00\xd5{"topic":"orderbook.50.BTCUSDC","ts":1698936875504,"type":"delta","data":{"s":"BTCUSDC","b":[],"a":[["34978.53","0.114411"],["34980.1","0.027166"],["34962.69","0"],["34984.8","0"]],"u":20010635,"seq":14108046564}}'
2023-11-02 14:54:35,590 DEBUG ++Rcv decoded: fin=1 opcode=1 data=b'{"topic":"orderbook.50.BTCUSDC","ts":1698936875504,"type":"delta","data":{"s":"BTCUSDC","b":[],"a":[["34978.53","0.114411"],["34980.1","0.027166"],["34962.69","0"],["34984.8","0"]],"u":20010635,"seq":14108046564}}'
2023-11-02 14:54:35,609 DEBUG ++Rcv raw: b'\x81~\x00\xd4{"topic":"orderbook.50.BTCUSDC","ts":1698936875523,"type":"delta","data":{"s":"BTCUSDC","b":[["34945.51","0.114411"],["34935.91","0"]],"a":[["34984.8","0.528984"],["34964.4","0"]],"u":20010636,"seq":14108046569}}'
2023-11-02 14:54:35,609 DEBUG ++Rcv decoded: fin=1 opcode=1 data=b'{"topic":"orderbook.50.BTCUSDC","ts":1698936875523,"type":"delta","data":{"s":"BTCUSDC","b":[["34945.51","0.114411"],["34935.91","0"]],"a":[["34984.8","0.528984"],["34964.4","0"]],"u":20010636,"seq":14108046569}}'
2023-11-02 14:54:35,630 DEBUG ++Rcv raw: b'\x81~\x01\xc6{"topic":"orderbook.50.BTCUSDC","ts":1698936875544,"type":"delta","data":{"s":"BTCUSDC","b":[["34956.49","0.057213"],["34950.11","0.114448"],["34940.32","0.286202"],["34958.15","0"],["34936.35","0"],["34936.36","0"]],"a":[["34963.94","0.057201"],["34964","0.0324"],["34971.54","0.114378"],["34974.92","0.357646"],["34978.52","0.068647"],["34984.8","0"],["34983.46","0"],["34984.79","0"],["34983.74","0"],["34983.47","0"]],"u":20010637,"seq":14108046588}}'
2023-11-02 14:54:35,631 DEBUG ++Rcv decoded: fin=1 opcode=1 data=b'{"topic":"orderbook.50.BTCUSDC","ts":1698936875544,"type":"delta","data":{"s":"BTCUSDC","b":[["34956.49","0.057213"],["34950.11","0.114448"],["34940.32","0.286202"],["34958.15","0"],["34936.35","0"],["34936.36","0"]],"a":[["34963.94","0.057201"],["34964","0.0324"],["34971.54","0.114378"],["34974.92","0.357646"],["34978.52","0.068647"],["34984.8","0"],["34983.46","0"],["34984.79","0"],["34983.74","0"],["34983.47","0"]],"u":20010637,"seq":14108046588}}'
2023-11-02 14:54:35,649 DEBUG ++Rcv raw: b'\x81~\x02G{"topic":"orderbook.50.BTCUSDC","ts":1698936875563,"type":"delta","data":{"s":"BTCUSDC","b":[["34956.5","0.124863"],["34956.42","0.0859"],["34954.88","0.028603"],["34954.34","0.046417"],["34952.44","0.049994"],["34936.36","0.823809"],["34936.35","0.1875"],["34940.32","0"],["34954.71","0"],["34956.47","0"],["34950.11","0"],["34956.49","0"],["34954.33","0"]],"a":[["34963.93","0.053765"],["34966.92","0.028603"],["34968.46","0.0859"],["34978.36","0.054434"],["34983.46","0.167031"],["34963.94","0"],["34971.54","0"],["34974.92","0"],["34980.25","0"]],"u":20010638,"seq":14108046621}}'
2023-11-02 14:54:35,650 DEBUG ++Rcv decoded: fin=1 opcode=1 data=b'{"topic":"orderbook.50.BTCUSDC","ts":1698936875563,"type":"delta","data":{"s":"BTCUSDC","b":[["34956.5","0.124863"],["34956.42","0.0859"],["34954.88","0.028603"],["34954.34","0.046417"],["34952.44","0.049994"],["34936.36","0.823809"],["34936.35","0.1875"],["34940.32","0"],["34954.71","0"],["34956.47","0"],["34950.11","0"],["34956.49","0"],["34954.33","0"]],"a":[["34963.93","0.053765"],["34966.92","0.028603"],["34968.46","0.0859"],["34978.36","0.054434"],["34983.46","0.167031"],["34963.94","0"],["34971.54","0"],["34974.92","0"],["34980.25","0"]],"u":20010638,"seq":14108046621}}'
2023-11-02 14:54:35,669 DEBUG ++Rcv raw: b'\x81~\x00\xed{"topic":"orderbook.50.BTCUSDC","ts":1698936875583,"type":"delta","data":{"s":"BTCUSDC","b":[["34956.5","0.073377"]],"a":[["34969.69","0.051547"],["34983.47","0.278379"],["34963.93","0"],["34967.99","0"]],"u":20010639,"seq":14108046637}}'
2023-11-02 14:54:35,670 DEBUG ++Rcv decoded: fin=1 opcode=1 data=b'{"topic":"orderbook.50.BTCUSDC","ts":1698936875583,"type":"delta","data":{"s":"BTCUSDC","b":[["34956.5","0.073377"]],"a":[["34969.69","0.051547"],["34983.47","0.278379"],["34963.93","0"],["34967.99","0"]],"u":20010639,"seq":14108046637}}'
2023-11-02 14:54:35,690 DEBUG ++Rcv raw: b'\x81~\x01&{"topic":"orderbook.50.BTCUSDC","ts":1698936875603,"type":"delta","data":{"s":"BTCUSDC","b":[["34951.28","0.364237"],["34935.91","1.373003"],["34950.23","0"],["34952.86","0"]],"a":[["34965.02","0.0859"],["34977.05","0.051548"],["34983.47","0"],["34983.46","0"]],"u":20010640,"seq":14108046659}}'
2023-11-02 14:54:35,691 DEBUG ++Rcv decoded: fin=1 opcode=1 data=b'{"topic":"orderbook.50.BTCUSDC","ts":1698936875603,"type":"delta","data":{"s":"BTCUSDC","b":[["34951.28","0.364237"],["34935.91","1.373003"],["34950.23","0"],["34952.86","0"]],"a":[["34965.02","0.0859"],["34977.05","0.051548"],["34983.47","0"],["34983.46","0"]],"u":20010640,"seq":14108046659}}'
2023-11-02 14:54:35,709 DEBUG ++Rcv raw: b'\x81~\x01O{"topic":"orderbook.50.BTCUSDC","ts":1698936875624,"type":"delta","data":{"s":"BTCUSDC","b":[["34951.29","0.218551"],["34951.27","0"]],"a":[["34960.53","0.085681"],["34965.01","0.05154"],["34967.57","0.00057"],["34967.99","0.051541"],["34981.28","0"],["34969.69","0"],["34980.47","0"],["34980.48","0"]],"u":20010641,"seq":14108046674}}'
2023-11-02 14:54:35,710 DEBUG ++Rcv decoded: fin=1 opcode=1 data=b'{"topic":"orderbook.50.BTCUSDC","ts":1698936875624,"type":"delta","data":{"s":"BTCUSDC","b":[["34951.29","0.218551"],["34951.27","0"]],"a":[["34960.53","0.085681"],["34965.01","0.05154"],["34967.57","0.00057"],["34967.99","0.051541"],["34981.28","0"],["34969.69","0"],["34980.47","0"],["34980.48","0"]],"u":20010641,"seq":14108046674}}'
2023-11-02 14:54:35,729 DEBUG ++Rcv raw: b'\x81~\x01s{"topic":"orderbook.50.BTCUSDC","ts":1698936875643,"type":"delta","data":{"s":"BTCUSDC","b":[["34957.88","0.022496"],["34947.51","0.026208"],["34937.76","0.107991"],["34931.31","0.1875"],["34958.14","0"],["34956.46","0"],["34953.26","0"],["34953.74","0"]],"a":[["34966.79","0.0441"],["34967.53","0.1875"],["34967.57","0"],["34980.2","0"]],"u":20010642,"seq":14108046703}}'
2023-11-02 14:54:35,729 DEBUG ++Rcv decoded: fin=1 opcode=1 data=b'{"topic":"orderbook.50.BTCUSDC","ts":1698936875643,"type":"delta","data":{"s":"BTCUSDC","b":[["34957.88","0.022496"],["34947.51","0.026208"],["34937.76","0.107991"],["34931.31","0.1875"],["34958.14","0"],["34956.46","0"],["34953.26","0"],["34953.74","0"]],"a":[["34966.79","0.0441"],["34967.53","0.1875"],["34967.57","0"],["34980.2","0"]],"u":20010642,"seq":14108046703}}'
2023-11-02 14:54:35,750 DEBUG ++Rcv raw: b'\x81~\x01\xdc{"topic":"orderbook.50.BTCUSDC","ts":1698936875663,"type":"delta","data":{"s":"BTCUSDC","b":[["34956.5","0.051542"],["34955.44","0.057215"],["34949.74","0.077355"],["34949","0.114452"],["34939.4","0.286209"],["34943.36","0"],["34954.34","0"],["34957.88","0"],["34931.31","0"]],"a":[["34962.9","0.057203"],["34967.52","0.112503"],["34969.69","0.051544"],["34970.42","0.114382"],["34980.1","0"],["34979.92","0"],["34967.99","0"],["34978.9","0"]],"u":20010643,"seq":14108046743}}'
2023-11-02 14:54:35,750 DEBUG ++Rcv decoded: fin=1 opcode=1 data=b'{"topic":"orderbook.50.BTCUSDC","ts":1698936875663,"type":"delta","data":{"s":"BTCUSDC","b":[["34956.5","0.051542"],["34955.44","0.057215"],["34949.74","0.077355"],["34949","0.114452"],["34939.4","0.286209"],["34943.36","0"],["34954.34","0"],["34957.88","0"],["34931.31","0"]],"a":[["34962.9","0.057203"],["34967.52","0.112503"],["34969.69","0.051544"],["34970.42","0.114382"],["34980.1","0"],["34979.92","0"],["34967.99","0"],["34978.9","0"]],"u":20010643,"seq":14108046743}}'
2023-11-02 14:54:35,768 DEBUG ++Rcv raw: b'\x81~\x00\xfe{"topic":"orderbook.50.BTCUSDC","ts":1698936875683,"type":"delta","data":{"s":"BTCUSDC","b":[],"a":[["34960.52","0.00438"],["34962.89","0.035522"],["34978.9","0.002162"],["34960.53","0"],["34962.68","0"],["34967.53","0"]],"u":20010644,"seq":14108046772}}'
2023-11-02 14:54:35,769 DEBUG ++Rcv decoded: fin=1 opcode=1 data=b'{"topic":"orderbook.50.BTCUSDC","ts":1698936875683,"type":"delta","data":{"s":"BTCUSDC","b":[],"a":[["34960.52","0.00438"],["34962.89","0.035522"],["34978.9","0.002162"],["34960.53","0"],["34962.68","0"],["34967.53","0"]],"u":20010644,"seq":14108046772}}'
2023-11-02 14:54:35,790 DEBUG ++Rcv raw: b'\x81~\x01\x15{"topic":"orderbook.50.BTCUSDC","ts":1698936875704,"type":"delta","data":{"s":"BTCUSDC","b":[],"a":[["34967.52","0.1875"],["34967.99","0.051546"],["34969.99","0.068636"],["34976.59","0.049844"],["34969.69","0"],["34978.9","0"],["34978.78","0"]],"u":20010645,"seq":14108046799}}'
2023-11-02 14:54:35,790 DEBUG ++Rcv decoded: fin=1 opcode=1 data=b'{"topic":"orderbook.50.BTCUSDC","ts":1698936875704,"type":"delta","data":{"s":"BTCUSDC","b":[],"a":[["34967.52","0.1875"],["34967.99","0.051546"],["34969.99","0.068636"],["34976.59","0.049844"],["34969.69","0"],["34978.9","0"],["34978.78","0"]],"u":20010645,"seq":14108046799}}'
2023-11-02 14:54:35,831 DEBUG ++Rcv raw: b'\x81~\x00\xcf{"topic":"orderbook.50.BTCUSDC","ts":1698936875744,"type":"delta","data":{"s":"BTCUSDC","b":[["34951.3","0.00174"],["34958.16","0"]],"a":[["34962","0.0324"],["34978.62","0"]],"u":20010646,"seq":14108046843}}'
2023-11-02 14:54:35,831 DEBUG ++Rcv decoded: fin=1 opcode=1 data=b'{"topic":"orderbook.50.BTCUSDC","ts":1698936875744,"type":"delta","data":{"s":"BTCUSDC","b":[["34951.3","0.00174"],["34958.16","0"]],"a":[["34962","0.0324"],["34978.62","0"]],"u":20010646,"seq":14108046843}}'
2023-11-02 14:54:35,849 DEBUG ++Rcv raw: b'\x81~\x01J{"topic":"orderbook.50.BTCUSDC","ts":1698936875763,"type":"delta","data":{"s":"BTCUSDC","b":[["34956.51","0.004376"],["34951.61","0.00057"],["34954.77","0"],["34947.24","0"]],"a":[["34960.51","0.03895"],["34962.67","0.01143"],["34975.97","0.03"],["34978.53","0"],["34978.36","0"],["34978.52","0"]],"u":20010647,"seq":14108046874}}'
2023-11-02 14:54:35,849 DEBUG ++Rcv decoded: fin=1 opcode=1 data=b'{"topic":"orderbook.50.BTCUSDC","ts":1698936875763,"type":"delta","data":{"s":"BTCUSDC","b":[["34956.51","0.004376"],["34951.61","0.00057"],["34954.77","0"],["34947.24","0"]],"a":[["34960.51","0.03895"],["34962.67","0.01143"],["34975.97","0.03"],["34978.53","0"],["34978.36","0"],["34978.52","0"]],"u":20010647,"seq":14108046874}}'
2023-11-02 14:54:35,869 DEBUG ++Rcv raw: b'\x81~\x00\xed{"topic":"orderbook.50.BTCUSDC","ts":1698936875783,"type":"delta","data":{"s":"BTCUSDC","b":[["34949.13","0.000261"],["34947.83","0.05154"],["34951.28","0"]],"a":[["34970.33","0.000239"],["34978.28","0"]],"u":20010648,"seq":14108046886}}'
2023-11-02 14:54:35,869 DEBUG ++Rcv decoded: fin=1 opcode=1 data=b'{"topic":"orderbook.50.BTCUSDC","ts":1698936875783,"type":"delta","data":{"s":"BTCUSDC","b":[["34949.13","0.000261"],["34947.83","0.05154"],["34951.28","0"]],"a":[["34970.33","0.000239"],["34978.28","0"]],"u":20010648,"seq":14108046886}}'
2023-11-02 14:54:35,888 DEBUG ++Rcv raw: b'\x81~\x00\x9d{"topic":"orderbook.50.BTCUSDC","ts":1698936875803,"type":"delta","data":{"s":"BTCUSDC","b":[["34951.29","0.051541"]],"a":[],"u":20010649,"seq":14108046902}}'
2023-11-02 14:54:35,889 DEBUG ++Rcv decoded: fin=1 opcode=1 data=b'{"topic":"orderbook.50.BTCUSDC","ts":1698936875803,"type":"delta","data":{"s":"BTCUSDC","b":[["34951.29","0.051541"]],"a":[],"u":20010649,"seq":14108046902}}'
2023-11-02 14:54:35,929 DEBUG ++Rcv raw: b'\x81~\x01N{"topic":"orderbook.50.BTCUSDC","ts":1698936875843,"type":"delta","data":{"s":"BTCUSDC","b":[["34955.99","0.057214"],["34955.44","0"]],"a":[["34960.5","0.00438"],["34963.41","0.057202"],["34972.54","0.361262"],["34978.28","0.001447"],["34962.9","0"],["34960.52","0"],["34962.67","0"],["34960.51","0"]],"u":20010650,"seq":14108046956}}'
2023-11-02 14:54:35,929 DEBUG ++Rcv decoded: fin=1 opcode=1 data=b'{"topic":"orderbook.50.BTCUSDC","ts":1698936875843,"type":"delta","data":{"s":"BTCUSDC","b":[["34955.99","0.057214"],["34955.44","0"]],"a":[["34960.5","0.00438"],["34963.41","0.057202"],["34972.54","0.361262"],["34978.28","0.001447"],["34962.9","0"],["34960.52","0"],["34962.67","0"],["34960.51","0"]],"u":20010650,"seq":14108046956}}'
2023-11-02 14:54:35,949 DEBUG ++Rcv raw: b'\x81~\x00\xd7{"topic":"orderbook.50.BTCUSDC","ts":1698936875863,"type":"delta","data":{"s":"BTCUSDC","b":[],"a":[["34972.53","0.216759"],["34978.36","0.054434"],["34973.61","0"],["34975.97","0"]],"u":20010651,"seq":14108046963}}'
2023-11-02 14:54:35,949 DEBUG ++Rcv decoded: fin=1 opcode=1 data=b'{"topic":"orderbook.50.BTCUSDC","ts":1698936875863,"type":"delta","data":{"s":"BTCUSDC","b":[],"a":[["34972.53","0.216759"],["34978.36","0.054434"],["34973.61","0"],["34975.97","0"]],"u":20010651,"seq":14108046963}}'
2023-11-02 14:54:35,969 DEBUG ++Rcv raw: b'\x81~\x00\xaa{"topic":"orderbook.50.BTCUSDC","ts":1698936875883,"type":"delta","data":{"s":"BTCUSDC","b":[["34943.6","0.028"],["34935.91","0"]],"a":[],"u":20010652,"seq":14108046982}}'
2023-11-02 14:54:35,969 DEBUG ++Rcv decoded: fin=1 opcode=1 data=b'{"topic":"orderbook.50.BTCUSDC","ts":1698936875883,"type":"delta","data":{"s":"BTCUSDC","b":[["34943.6","0.028"],["34935.91","0"]],"a":[],"u":20010652,"seq":14108046982}}'
2023-11-02 14:54:35,989 DEBUG ++Rcv raw: b'\x81~\x01:{"topic":"orderbook.50.BTCUSDC","ts":1698936875903,"type":"delta","data":{"s":"BTCUSDC","b":[["34956.5","0.035715"],["34950.01","0.365612"],["34944.38","0.0859"],["34956.42","0"],["34936.35","0"]],"a":[["34959.38","0.076919"],["34963.3","0.0859"],["34972.54","0"],["34978.36","0"]],"u":20010653,"seq":14108047008}}'
2023-11-02 14:54:35,989 DEBUG ++Rcv decoded: fin=1 opcode=1 data=b'{"topic":"orderbook.50.BTCUSDC","ts":1698936875903,"type":"delta","data":{"s":"BTCUSDC","b":[["34956.5","0.035715"],["34950.01","0.365612"],["34944.38","0.0859"],["34956.42","0"],["34936.35","0"]],"a":[["34959.38","0.076919"],["34963.3","0.0859"],["34972.54","0"],["34978.36","0"]],"u":20010653,"seq":14108047008}}'
2023-11-02 14:54:36,012 DEBUG ++Rcv raw: b'\x81~\x01\xe4{"topic":"orderbook.50.BTCUSDC","ts":1698936875926,"type":"delta","data":{"s":"BTCUSDC","b":[["34954.71","0.051544"],["34953.44","0.028604"],["34950.02","0.219372"],["34949.97","0.047772"],["34949.15","0.000261"],["34955.99","0"],["34954.88","0"],["34953.11","0"],["34952.44","0"],["34951.29","0"]],"a":[["34962.89","0.082622"],["34973.61","0.051547"],["34975.89","0.050202"],["34978.52","0.068647"],["34972.53","0"],["34963.41","0"],["34966.92","0"]],"u":20010654,"seq":14108047049}}'
2023-11-02 14:54:36,012 DEBUG ++Rcv decoded: fin=1 opcode=1 data=b'{"topic":"orderbook.50.BTCUSDC","ts":1698936875926,"type":"delta","data":{"s":"BTCUSDC","b":[["34954.71","0.051544"],["34953.44","0.028604"],["34950.02","0.219372"],["34949.97","0.047772"],["34949.15","0.000261"],["34955.99","0"],["34954.88","0"],["34953.11","0"],["34952.44","0"],["34951.29","0"]],"a":[["34962.89","0.082622"],["34973.61","0.051547"],["34975.89","0.050202"],["34978.52","0.068647"],["34972.53","0"],["34963.41","0"],["34966.92","0"]],"u":20010654,"seq":14108047049}}'
2023-11-02 14:54:36,029 DEBUG ++Rcv raw: b'\x81~\x01e{"topic":"orderbook.50.BTCUSDC","ts":1698936875943,"type":"delta","data":{"s":"BTCUSDC","b":[["34955.28","0.057215"],["34955.03","0.021608"],["34953.11","0.051549"],["34936.36","0"],["34939.4","0"],["34956.5","0"]],"a":[["34959.37","0.00438"],["34960.49","0.028603"],["34962.89","0.035522"],["34960.5","0"],["34959.38","0"]],"u":20010655,"seq":14108047081}}'
2023-11-02 14:54:36,029 DEBUG ++Rcv decoded: fin=1 opcode=1 data=b'{"topic":"orderbook.50.BTCUSDC","ts":1698936875943,"type":"delta","data":{"s":"BTCUSDC","b":[["34955.28","0.057215"],["34955.03","0.021608"],["34953.11","0.051549"],["34936.36","0"],["34939.4","0"],["34956.5","0"]],"a":[["34959.37","0.00438"],["34960.49","0.028603"],["34962.89","0.035522"],["34960.5","0"],["34959.38","0"]],"u":20010655,"seq":14108047081}}'
2023-11-02 14:54:36,049 DEBUG ++Rcv raw: b'\x81~\x01\x9f{"topic":"orderbook.50.BTCUSDC","ts":1698936875963,"type":"delta","data":{"s":"BTCUSDC","b":[["34955.29","0.055929"],["34950.03","0.002029"],["34938.35","0.286218"],["34936.36","0.823809"],["34936.35","0.1875"],["34937.76","0"],["34955.03","0"],["34955.28","0"],["34950.01","0"],["34951.3","0"]],"a":[["34962.9","0.057203"],["34966.13","0.022371"],["34978.28","0"],["34978.52","0"]],"u":20010656,"seq":14108047114}}'
2023-11-02 14:54:36,049 DEBUG ++Rcv decoded: fin=1 opcode=1 data=b'{"topic":"orderbook.50.BTCUSDC","ts":1698936875963,"type":"delta","data":{"s":"BTCUSDC","b":[["34955.29","0.055929"],["34950.03","0.002029"],["34938.35","0.286218"],["34936.36","0.823809"],["34936.35","0.1875"],["34937.76","0"],["34955.03","0"],["34955.28","0"],["34950.01","0"],["34951.3","0"]],"a":[["34962.9","0.057203"],["34966.13","0.022371"],["34978.28","0"],["34978.52","0"]],"u":20010656,"seq":14108047114}}'
2023-11-02 14:54:36,069 DEBUG ++Rcv raw: b'\x81~\x00\xe3{"topic":"orderbook.50.BTCUSDC","ts":1698936875984,"type":"delta","data":{"s":"BTCUSDC","b":[["34955.29","0.021601"],["34950.02","0.046415"],["34940.31","1.31344"]],"a":[["34962.89","0.082621"]],"u":20010657,"seq":14108047132}}'
2023-11-02 14:54:36,070 DEBUG ++Rcv decoded: fin=1 opcode=1 data=b'{"topic":"orderbook.50.BTCUSDC","ts":1698936875984,"type":"delta","data":{"s":"BTCUSDC","b":[["34955.29","0.021601"],["34950.02","0.046415"],["34940.31","1.31344"]],"a":[["34962.89","0.082621"]],"u":20010657,"seq":14108047132}}'
2023-11-02 14:54:36,089 DEBUG ++Rcv raw: b'\x81~\x00\xae{"topic":"orderbook.50.BTCUSDC","ts":1698936876004,"type":"delta","data":{"s":"BTCUSDC","b":[],"a":[["34971.39","0.076322"],["34977.06","0"]],"u":20010658,"seq":14108047138}}'
2023-11-02 14:54:36,089 DEBUG ++Rcv decoded: fin=1 opcode=1 data=b'{"topic":"orderbook.50.BTCUSDC","ts":1698936876004,"type":"delta","data":{"s":"BTCUSDC","b":[],"a":[["34971.39","0.076322"],["34977.06","0"]],"u":20010658,"seq":14108047138}}'
2023-11-02 14:54:36,109 DEBUG ++Rcv raw: b'\x81~\x00\xff{"topic":"orderbook.50.BTCUSDC","ts":1698936876023,"type":"delta","data":{"s":"BTCUSDC","b":[["34935.91","1.373003"],["34947.51","0"]],"a":[["34967.51","0.112505"],["34970.28","0.000239"],["34977.05","0"],["34967.99","0"]],"u":20010659,"seq":14108047151}}'
2023-11-02 14:54:36,109 DEBUG ++Rcv decoded: fin=1 opcode=1 data=b'{"topic":"orderbook.50.BTCUSDC","ts":1698936876023,"type":"delta","data":{"s":"BTCUSDC","b":[["34935.91","1.373003"],["34947.51","0"]],"a":[["34967.51","0.112505"],["34970.28","0.000239"],["34977.05","0"],["34967.99","0"]],"u":20010659,"seq":14108047151}}'
2023-11-02 14:54:36,129 DEBUG ++Rcv raw: b'\x81~\x00\xd4{"topic":"orderbook.50.BTCUSDC","ts":1698936876044,"type":"delta","data":{"s":"BTCUSDC","b":[["34955.3","0.004376"],["34956.51","0"]],"a":[["34959.36","0.03895"],["34976.59","0"]],"u":20010660,"seq":14108047162}}'
2023-11-02 14:54:36,129 DEBUG ++Rcv decoded: fin=1 opcode=1 data=b'{"topic":"orderbook.50.BTCUSDC","ts":1698936876044,"type":"delta","data":{"s":"BTCUSDC","b":[["34955.3","0.004376"],["34956.51","0"]],"a":[["34959.36","0.03895"],["34976.59","0"]],"u":20010660,"seq":14108047162}}'
2023-11-02 14:54:36,151 DEBUG ++Rcv raw: b'\x81~\x00\xd5{"topic":"orderbook.50.BTCUSDC","ts":1698936876066,"type":"delta","data":{"s":"BTCUSDC","b":[["34955.59","0.057215"],["34949.74","0"]],"a":[["34959.35","0.00438"],["34959.37","0"]],"u":20010661,"seq":14108047179}}'
2023-11-02 14:54:36,151 DEBUG ++Rcv decoded: fin=1 opcode=1 data=b'{"topic":"orderbook.50.BTCUSDC","ts":1698936876066,"type":"delta","data":{"s":"BTCUSDC","b":[["34955.59","0.057215"],["34949.74","0"]],"a":[["34959.35","0.00438"],["34959.37","0"]],"u":20010661,"seq":14108047179}}'
2023-11-02 14:54:36,174 DEBUG ++Rcv raw: b'\x81~\x019{"topic":"orderbook.50.BTCUSDC","ts":1698936876083,"type":"delta","data":{"s":"BTCUSDC","b":[["34955.6","0.062936"],["34950.02","0.02867"],["34946.19","0.077355"],["34944.27","0.026205"],["34935.91","0"],["34955.3","0"],["34955.29","0"]],"a":[["34972.43","0.03"],["34959.36","0"]],"u":20010662,"seq":14108047195}}'
2023-11-02 14:54:36,174 DEBUG ++Rcv decoded: fin=1 opcode=1 data=b'{"topic":"orderbook.50.BTCUSDC","ts":1698936876083,"type":"delta","data":{"s":"BTCUSDC","b":[["34955.6","0.062936"],["34950.02","0.02867"],["34946.19","0.077355"],["34944.27","0.026205"],["34935.91","0"],["34955.3","0"],["34955.29","0"]],"a":[["34972.43","0.03"],["34959.36","0"]],"u":20010662,"seq":14108047195}}'
2023-11-02 14:54:36,188 DEBUG ++Rcv raw: b'\x81~\x00\xae{"topic":"orderbook.50.BTCUSDC","ts":1698936876103,"type":"delta","data":{"s":"BTCUSDC","b":[["34935.91","1.373003"],["34955.59","0"]],"a":[],"u":20010663,"seq":14108047199}}'
2023-11-02 14:54:36,189 DEBUG ++Rcv decoded: fin=1 opcode=1 data=b'{"topic":"orderbook.50.BTCUSDC","ts":1698936876103,"type":"delta","data":{"s":"BTCUSDC","b":[["34935.91","1.373003"],["34955.59","0"]],"a":[],"u":20010663,"seq":14108047199}}'
2023-11-02 14:54:36,209 DEBUG ++Rcv raw: b'\x81~\x00\xed{"topic":"orderbook.50.BTCUSDC","ts":1698936876123,"type":"delta","data":{"s":"BTCUSDC","b":[["34955.61","0.059369"],["34955.6","0.004376"],["34935.91","0"]],"a":[["34974.66","0.067949"],["34976.12","0"]],"u":20010664,"seq":14108047211}}'
2023-11-02 14:54:36,209 DEBUG ++Rcv decoded: fin=1 opcode=1 data=b'{"topic":"orderbook.50.BTCUSDC","ts":1698936876123,"type":"delta","data":{"s":"BTCUSDC","b":[["34955.61","0.059369"],["34955.6","0.004376"],["34935.91","0"]],"a":[["34974.66","0.067949"],["34976.12","0"]],"u":20010664,"seq":14108047211}}'
2023-11-02 14:54:36,230 DEBUG ++Rcv raw: b'\x81~\x01={"topic":"orderbook.50.BTCUSDC","ts":1698936876143,"type":"delta","data":{"s":"BTCUSDC","b":[["34955.61","0.024234"],["34935.91","1.373003"],["34931.31","0.1875"],["34955.02","0"],["34949.13","0"]],"a":[["34959.34","0.03895"],["34971.38","0.358055"],["34970.33","0"],["34975.89","0"]],"u":20010665,"seq":14108047235}}'
2023-11-02 14:54:36,230 DEBUG ++Rcv decoded: fin=1 opcode=1 data=b'{"topic":"orderbook.50.BTCUSDC","ts":1698936876143,"type":"delta","data":{"s":"BTCUSDC","b":[["34955.61","0.024234"],["34935.91","1.373003"],["34931.31","0.1875"],["34955.02","0"],["34949.13","0"]],"a":[["34959.34","0.03895"],["34971.38","0.358055"],["34970.33","0"],["34975.89","0"]],"u":20010665,"seq":14108047235}}'
2023-11-02 14:54:36,249 DEBUG ++Rcv raw: b'\x81~\x01M{"topic":"orderbook.50.BTCUSDC","ts":1698936876163,"type":"delta","data":{"s":"BTCUSDC","b":[["34956.28","0.098972"],["34955.62","0.004376"],["34951.27","0.051542"],["34942.66","0.0859"],["34955.6","0"],["34950.02","0"],["34953.11","0"],["34955.61","0"]],"a":[["34971.37","0.214836"],["34971.4","0"]],"u":20010666,"seq":14108047251}}'
2023-11-02 14:54:36,249 DEBUG ++Rcv decoded: fin=1 opcode=1 data=b'{"topic":"orderbook.50.BTCUSDC","ts":1698936876163,"type":"delta","data":{"s":"BTCUSDC","b":[["34956.28","0.098972"],["34955.62","0.004376"],["34951.27","0.051542"],["34942.66","0.0859"],["34955.6","0"],["34950.02","0"],["34953.11","0"],["34955.61","0"]],"a":[["34971.37","0.214836"],["34971.4","0"]],"u":20010666,"seq":14108047251}}'
2023-11-02 14:54:36,269 DEBUG ++Rcv raw: b'\x81~\x00\xff{"topic":"orderbook.50.BTCUSDC","ts":1698936876183,"type":"delta","data":{"s":"BTCUSDC","b":[["34956.29","0.004376"],["34942.67","0.051544"],["34931.31","0"],["34955.62","0"]],"a":[["34975.89","0.050202"],["34960.49","0"]],"u":20010667,"seq":14108047266}}'
2023-11-02 14:54:36,269 DEBUG ++Rcv decoded: fin=1 opcode=1 data=b'{"topic":"orderbook.50.BTCUSDC","ts":1698936876183,"type":"delta","data":{"s":"BTCUSDC","b":[["34956.29","0.004376"],["34942.67","0.051544"],["34931.31","0"],["34955.62","0"]],"a":[["34975.89","0.050202"],["34960.49","0"]],"u":20010667,"seq":14108047266}}'
2023-11-02 14:54:36,289 DEBUG ++Rcv raw: b'\x81~\x00\xd5{"topic":"orderbook.50.BTCUSDC","ts":1698936876203,"type":"delta","data":{"s":"BTCUSDC","b":[["34949.74","0.354868"],["34956.28","0"]],"a":[["34976.12","0.043812"],["34962.9","0"]],"u":20010668,"seq":14108047276}}'
2023-11-02 14:54:36,289 DEBUG ++Rcv decoded: fin=1 opcode=1 data=b'{"topic":"orderbook.50.BTCUSDC","ts":1698936876203,"type":"delta","data":{"s":"BTCUSDC","b":[["34949.74","0.354868"],["34956.28","0"]],"a":[["34976.12","0.043812"],["34962.9","0"]],"u":20010668,"seq":14108047276}}'
2023-11-02 14:54:36,309 DEBUG ++Rcv raw: b'\x81~\x01\x17{"topic":"orderbook.50.BTCUSDC","ts":1698936876224,"type":"delta","data":{"s":"BTCUSDC","b":[["34955.67","0.057215"],["34950.01","0.212925"],["34949.55","0"],["34951.27","0"]],"a":[["34962.89","0.035522"],["34963.42","0.057202"],["34976.12","0"]],"u":20010669,"seq":14108047288}}'
2023-11-02 14:54:36,309 DEBUG ++Rcv decoded: fin=1 opcode=1 data=b'{"topic":"orderbook.50.BTCUSDC","ts":1698936876224,"type":"delta","data":{"s":"BTCUSDC","b":[["34955.67","0.057215"],["34950.01","0.212925"],["34949.55","0"],["34951.27","0"]],"a":[["34962.89","0.035522"],["34963.42","0.057202"],["34976.12","0"]],"u":20010669,"seq":14108047288}}'
2023-11-02 14:54:36,329 DEBUG ++Rcv raw: b'\x81~\x01\x17{"topic":"orderbook.50.BTCUSDC","ts":1698936876244,"type":"delta","data":{"s":"BTCUSDC","b":[["34955.68","0.034335"],["34953.11","0.051547"],["34950.02","0.002269"],["34936.35","0"],["34936.36","0"],["34935.91","0"]],"a":[["34962.89","0.082624"]],"u":20010670,"seq":14108047305}}'
2023-11-02 14:54:36,329 DEBUG ++Rcv decoded: fin=1 opcode=1 data=b'{"topic":"orderbook.50.BTCUSDC","ts":1698936876244,"type":"delta","data":{"s":"BTCUSDC","b":[["34955.68","0.034335"],["34953.11","0.051547"],["34950.02","0.002269"],["34936.35","0"],["34936.36","0"],["34935.91","0"]],"a":[["34962.89","0.082624"]],"u":20010670,"seq":14108047305}}'
2023-11-02 14:54:36,349 DEBUG ++Rcv raw: b'\x81~\x00\xfe{"topic":"orderbook.50.BTCUSDC","ts":1698936876264,"type":"delta","data":{"s":"BTCUSDC","b":[["34936.36","0.823809"],["34936.35","0.1875"],["34935.91","1.373003"],["34950.03","0"],["34955.67","0"],["34938.35","0"]],"a":[],"u":20010671,"seq":14108047326}}'
2023-11-02 14:54:36,349 DEBUG ++Rcv decoded: fin=1 opcode=1 data=b'{"topic":"orderbook.50.BTCUSDC","ts":1698936876264,"type":"delta","data":{"s":"BTCUSDC","b":[["34936.36","0.823809"],["34936.35","0.1875"],["34935.91","1.373003"],["34950.03","0"],["34955.67","0"],["34938.35","0"]],"a":[],"u":20010671,"seq":14108047326}}'
2023-11-02 14:54:36,369 DEBUG ++Rcv raw: b'\x81~\x00\xd5{"topic":"orderbook.50.BTCUSDC","ts":1698936876284,"type":"delta","data":{"s":"BTCUSDC","b":[["34939.55","0.286208"],["34931.31","0.1875"],["34953.11","0"],["34955.68","0"]],"a":[],"u":20010672,"seq":14108047334}}'
2023-11-02 14:54:36,369 DEBUG ++Rcv decoded: fin=1 opcode=1 data=b'{"topic":"orderbook.50.BTCUSDC","ts":1698936876284,"type":"delta","data":{"s":"BTCUSDC","b":[["34939.55","0.286208"],["34931.31","0.1875"],["34953.11","0"],["34955.68","0"]],"a":[],"u":20010672,"seq":14108047334}}'
2023-11-02 14:54:36,389 DEBUG ++Rcv raw: b'\x81~\x00\xab{"topic":"orderbook.50.BTCUSDC","ts":1698936876304,"type":"delta","data":{"s":"BTCUSDC","b":[["34951.62","0.026"],["34931.31","0"]],"a":[],"u":20010673,"seq":14108047349}}'
2023-11-02 14:54:36,389 DEBUG ++Rcv decoded: fin=1 opcode=1 data=b'{"topic":"orderbook.50.BTCUSDC","ts":1698936876304,"type":"delta","data":{"s":"BTCUSDC","b":[["34951.62","0.026"],["34931.31","0"]],"a":[],"u":20010673,"seq":14108047349}}'
2023-11-02 14:54:36,429 DEBUG ++Rcv raw: b'\x81~\x00\xfc{"topic":"orderbook.50.BTCUSDC","ts":1698936876344,"type":"delta","data":{"s":"BTCUSDC","b":[["34931.31","0.1875"],["34939.27","0"]],"a":[["34974.5","0.057184"],["34976.12","0.043812"],["34970.28","0"],["34959.35","0"]],"u":20010674,"seq":14108047374}}'
2023-11-02 14:54:36,429 DEBUG ++Rcv decoded: fin=1 opcode=1 data=b'{"topic":"orderbook.50.BTCUSDC","ts":1698936876344,"type":"delta","data":{"s":"BTCUSDC","b":[["34931.31","0.1875"],["34939.27","0"]],"a":[["34974.5","0.057184"],["34976.12","0.043812"],["34970.28","0"],["34959.35","0"]],"u":20010674,"seq":14108047374}}'
2023-11-02 14:54:36,490 DEBUG ++Rcv raw: b'\x81~\x00\xae{"topic":"orderbook.50.BTCUSDC","ts":1698936876404,"type":"delta","data":{"s":"BTCUSDC","b":[["34957.45","0.107707"],["34931.31","0"]],"a":[],"u":20010675,"seq":14108047389}}'
2023-11-02 14:54:36,490 DEBUG ++Rcv decoded: fin=1 opcode=1 data=b'{"topic":"orderbook.50.BTCUSDC","ts":1698936876404,"type":"delta","data":{"s":"BTCUSDC","b":[["34957.45","0.107707"],["34931.31","0"]],"a":[],"u":20010675,"seq":14108047389}}'
2023-11-02 14:54:36,509 DEBUG ++Rcv raw: b'\x81~\x00\xf9{"topic":"orderbook.50.BTCUSDC","ts":1698936876424,"type":"delta","data":{"s":"BTCUSDC","b":[["34953.05","0.036"],["34946.1","0.0859"],["34935.91","0"],["34951.61","0"]],"a":[["34976.59","0.049844"],["34967.52","0"]],"u":20010676,"seq":14108047404}}'
2023-11-02 14:54:36,509 DEBUG ++Rcv decoded: fin=1 opcode=1 data=b'{"topic":"orderbook.50.BTCUSDC","ts":1698936876424,"type":"delta","data":{"s":"BTCUSDC","b":[["34953.05","0.036"],["34946.1","0.0859"],["34935.91","0"],["34951.61","0"]],"a":[["34976.59","0.049844"],["34967.52","0"]],"u":20010676,"seq":14108047404}}'
2023-11-02 14:54:36,528 DEBUG ++Rcv raw: b'\x81~\x00\xd7{"topic":"orderbook.50.BTCUSDC","ts":1698936876443,"type":"delta","data":{"s":"BTCUSDC","b":[],"a":[["34959.33","0.028604"],["34967.99","0.051549"],["34967.51","0"],["34976.59","0"]],"u":20010677,"seq":14108047415}}'
2023-11-02 14:54:36,529 DEBUG ++Rcv decoded: fin=1 opcode=1 data=b'{"topic":"orderbook.50.BTCUSDC","ts":1698936876443,"type":"delta","data":{"s":"BTCUSDC","b":[],"a":[["34959.33","0.028604"],["34967.99","0.051549"],["34967.51","0"],["34976.59","0"]],"u":20010677,"seq":14108047415}}'
2023-11-02 14:54:36,549 DEBUG ++Rcv raw: b'\x81~\x00\xae{"topic":"orderbook.50.BTCUSDC","ts":1698936876464,"type":"delta","data":{"s":"BTCUSDC","b":[],"a":[["34976.59","0.049844"],["34959.34","0"]],"u":20010678,"seq":14108047421}}'
2023-11-02 14:54:36,549 DEBUG ++Rcv decoded: fin=1 opcode=1 data=b'{"topic":"orderbook.50.BTCUSDC","ts":1698936876464,"type":"delta","data":{"s":"BTCUSDC","b":[],"a":[["34976.59","0.049844"],["34959.34","0"]],"u":20010678,"seq":14108047421}}'
2023-11-02 14:54:36,568 DEBUG ++Rcv raw: b'\x81~\x00\xae{"topic":"orderbook.50.BTCUSDC","ts":1698936876483,"type":"delta","data":{"s":"BTCUSDC","b":[["34956.33","0.057214"],["34956.29","0"]],"a":[],"u":20010679,"seq":14108047443}}'
2023-11-02 14:54:36,568 DEBUG ++Rcv decoded: fin=1 opcode=1 data=b'{"topic":"orderbook.50.BTCUSDC","ts":1698936876483,"type":"delta","data":{"s":"BTCUSDC","b":[["34956.33","0.057214"],["34956.29","0"]],"a":[],"u":20010679,"seq":14108047443}}'
2023-11-02 14:54:36,589 DEBUG ++Rcv raw: b'\x81~\x00\xd6{"topic":"orderbook.50.BTCUSDC","ts":1698936876504,"type":"delta","data":{"s":"BTCUSDC","b":[["34956.34","0.02939"],["34953.11","0.051541"],["34936.35","0"],["34954.71","0"]],"a":[],"u":20010680,"seq":14108047450}}'
2023-11-02 14:54:36,589 DEBUG ++Rcv decoded: fin=1 opcode=1 data=b'{"topic":"orderbook.50.BTCUSDC","ts":1698936876504,"type":"delta","data":{"s":"BTCUSDC","b":[["34956.34","0.02939"],["34953.11","0.051541"],["34936.35","0"],["34954.71","0"]],"a":[],"u":20010680,"seq":14108047450}}'
2023-11-02 14:54:36,610 DEBUG ++Rcv raw: b'\x81~\x00\xae{"topic":"orderbook.50.BTCUSDC","ts":1698936876524,"type":"delta","data":{"s":"BTCUSDC","b":[["34957.46","0.004376"],["34949.15","0"]],"a":[],"u":20010681,"seq":14108047452}}'
2023-11-02 14:54:36,611 DEBUG ++Rcv decoded: fin=1 opcode=1 data=b'{"topic":"orderbook.50.BTCUSDC","ts":1698936876524,"type":"delta","data":{"s":"BTCUSDC","b":[["34957.46","0.004376"],["34949.15","0"]],"a":[],"u":20010681,"seq":14108047452}}'
2023-11-02 14:54:36,629 DEBUG ++Rcv raw: b'\x81~\x00\xac{"topic":"orderbook.50.BTCUSDC","ts":1698936876543,"type":"delta","data":{"s":"BTCUSDC","b":[["34956.42","0.0859"],["34957.45","0"]],"a":[],"u":20010682,"seq":14108047463}}'
2023-11-02 14:54:36,629 DEBUG ++Rcv decoded: fin=1 opcode=1 data=b'{"topic":"orderbook.50.BTCUSDC","ts":1698936876543,"type":"delta","data":{"s":"BTCUSDC","b":[["34956.42","0.0859"],["34957.45","0"]],"a":[],"u":20010682,"seq":14108047463}}'
2023-11-02 14:54:36,650 DEBUG ++Rcv raw: b'\x81~\x01J{"topic":"orderbook.50.BTCUSDC","ts":1698936876564,"type":"delta","data":{"s":"BTCUSDC","b":[["34956.43","0.044667"],["34936.35","0.1875"],["34956.33","0"],["34956.34","0"]],"a":[["34977.05","0.051548"],["34977.06","0.0859"],["34978.28","0.279826"],["34962","0"],["34959.33","0"],["34963.42","0"]],"u":20010683,"seq":14108047497}}'
2023-11-02 14:54:36,650 DEBUG ++Rcv decoded: fin=1 opcode=1 data=b'{"topic":"orderbook.50.BTCUSDC","ts":1698936876564,"type":"delta","data":{"s":"BTCUSDC","b":[["34956.43","0.044667"],["34936.35","0.1875"],["34956.33","0"],["34956.34","0"]],"a":[["34977.05","0.051548"],["34977.06","0.0859"],["34978.28","0.279826"],["34962","0"],["34959.33","0"],["34963.42","0"]],"u":20010683,"seq":14108047497}}'
2023-11-02 14:54:36,669 DEBUG ++Rcv raw: b'\x81~\x01:{"topic":"orderbook.50.BTCUSDC","ts":1698936876583,"type":"delta","data":{"s":"BTCUSDC","b":[["34952.57","0.00057"],["34936.35","0"]],"a":[["34962.7","0.00438"],["34962.89","0.035522"],["34963.91","0.057201"],["34967.6","0.00057"],["34977.06","0"],["34963.4","0"],["34978.28","0"]],"u":20010684,"seq":14108047514}}'
2023-11-02 14:54:36,669 DEBUG ++Rcv decoded: fin=1 opcode=1 data=b'{"topic":"orderbook.50.BTCUSDC","ts":1698936876583,"type":"delta","data":{"s":"BTCUSDC","b":[["34952.57","0.00057"],["34936.35","0"]],"a":[["34962.7","0.00438"],["34962.89","0.035522"],["34963.91","0.057201"],["34967.6","0.00057"],["34977.06","0"],["34963.4","0"],["34978.28","0"]],"u":20010684,"seq":14108047514}}'
2023-11-02 14:54:36,689 DEBUG ++Rcv raw: b'\x81~\x00\xab{"topic":"orderbook.50.BTCUSDC","ts":1698936876604,"type":"delta","data":{"s":"BTCUSDC","b":[["34936.35","0.1875"],["34943.6","0"]],"a":[],"u":20010685,"seq":14108047526}}'
2023-11-02 14:54:36,690 DEBUG ++Rcv decoded: fin=1 opcode=1 data=b'{"topic":"orderbook.50.BTCUSDC","ts":1698936876604,"type":"delta","data":{"s":"BTCUSDC","b":[["34936.35","0.1875"],["34943.6","0"]],"a":[],"u":20010685,"seq":14108047526}}'
2023-11-02 14:54:36,729 DEBUG ++Rcv raw: b'\x81~\x00\xab{"topic":"orderbook.50.BTCUSDC","ts":1698936876643,"type":"delta","data":{"s":"BTCUSDC","b":[],"a":[["34977.06","0.0859"],["34963.3","0"]],"u":20010686,"seq":14108047542}}'
2023-11-02 14:54:36,729 DEBUG ++Rcv decoded: fin=1 opcode=1 data=b'{"topic":"orderbook.50.BTCUSDC","ts":1698936876643,"type":"delta","data":{"s":"BTCUSDC","b":[],"a":[["34977.06","0.0859"],["34963.3","0"]],"u":20010686,"seq":14108047542}}'
2023-11-02 14:54:36,749 DEBUG ++Rcv raw: b'\x81~\x00\xae{"topic":"orderbook.50.BTCUSDC","ts":1698936876663,"type":"delta","data":{"s":"BTCUSDC","b":[],"a":[["34978.28","0.279826"],["34962.89","0"]],"u":20010687,"seq":14108047546}}'
2023-11-02 14:54:36,749 DEBUG ++Rcv decoded: fin=1 opcode=1 data=b'{"topic":"orderbook.50.BTCUSDC","ts":1698936876663,"type":"delta","data":{"s":"BTCUSDC","b":[],"a":[["34978.28","0.279826"],["34962.89","0"]],"u":20010687,"seq":14108047546}}'
2023-11-02 14:54:36,769 DEBUG ++Rcv raw: b'\x81~\x00\xd5{"topic":"orderbook.50.BTCUSDC","ts":1698936876684,"type":"delta","data":{"s":"BTCUSDC","b":[],"a":[["34962.68","0.00438"],["34962.69","0.028601"],["34962.7","0"],["34978.28","0"]],"u":20010688,"seq":14108047564}}'
2023-11-02 14:54:36,769 DEBUG ++Rcv decoded: fin=1 opcode=1 data=b'{"topic":"orderbook.50.BTCUSDC","ts":1698936876684,"type":"delta","data":{"s":"BTCUSDC","b":[],"a":[["34962.68","0.00438"],["34962.69","0.028601"],["34962.7","0"],["34978.28","0"]],"u":20010688,"seq":14108047564}}'
2023-11-02 14:54:36,869 DEBUG ++Rcv raw: b'\x81~\x00\xd6{"topic":"orderbook.50.BTCUSDC","ts":1698936876783,"type":"delta","data":{"s":"BTCUSDC","b":[["34935.91","1.373003"],["34957.46","0"]],"a":[["34978.28","0.279826"],["34962.69","0"]],"u":20010689,"seq":14108047618}}'
2023-11-02 14:54:36,869 DEBUG ++Rcv decoded: fin=1 opcode=1 data=b'{"topic":"orderbook.50.BTCUSDC","ts":1698936876783,"type":"delta","data":{"s":"BTCUSDC","b":[["34935.91","1.373003"],["34957.46","0"]],"a":[["34978.28","0.279826"],["34962.69","0"]],"u":20010689,"seq":14108047618}}'
2023-11-02 14:54:36,890 DEBUG ++Rcv raw: b'\x81~\x01w{"topic":"orderbook.50.BTCUSDC","ts":1698936876803,"type":"delta","data":{"s":"BTCUSDC","b":[["34957.69","0.004376"],["34957.68","0.099986"],["34949.31","0.000261"],["34940.32","0.028"],["34936.36","0"],["34937.36","0"],["34936.35","0"],["34935.91","0"]],"a":[["34961.19","0.076775"],["34970.01","0.000239"],["34977.06","0"],["34978.28","0"]],"u":20010690,"seq":14108047634}}'
2023-11-02 14:54:36,890 DEBUG ++Rcv decoded: fin=1 opcode=1 data=b'{"topic":"orderbook.50.BTCUSDC","ts":1698936876803,"type":"delta","data":{"s":"BTCUSDC","b":[["34957.69","0.004376"],["34957.68","0.099986"],["34949.31","0.000261"],["34940.32","0.028"],["34936.36","0"],["34937.36","0"],["34936.35","0"],["34935.91","0"]],"a":[["34961.19","0.076775"],["34970.01","0.000239"],["34977.06","0"],["34978.28","0"]],"u":20010690,"seq":14108047634}}'
2023-11-02 14:54:36,909 DEBUG ++Rcv raw: b'\x81~\x00\xd5{"topic":"orderbook.50.BTCUSDC","ts":1698936876824,"type":"delta","data":{"s":"BTCUSDC","b":[["34956.32","0.057214"],["34947.18","0.1875"],["34957.68","0"],["34937.39","0"]],"a":[],"u":20010691,"seq":14108047641}}'
2023-11-02 14:54:36,909 DEBUG ++Rcv decoded: fin=1 opcode=1 data=b'{"topic":"orderbook.50.BTCUSDC","ts":1698936876824,"type":"delta","data":{"s":"BTCUSDC","b":[["34956.32","0.057214"],["34947.18","0.1875"],["34957.68","0"],["34937.39","0"]],"a":[],"u":20010691,"seq":14108047641}}'
2023-11-02 14:54:36,929 DEBUG ++Rcv raw: b'\x81~\x00\x9d{"topic":"orderbook.50.BTCUSDC","ts":1698936876843,"type":"delta","data":{"s":"BTCUSDC","b":[["34956.43","0.067801"]],"a":[],"u":20010692,"seq":14108047645}}'
2023-11-02 14:54:36,929 DEBUG ++Rcv decoded: fin=1 opcode=1 data=b'{"topic":"orderbook.50.BTCUSDC","ts":1698936876843,"type":"delta","data":{"s":"BTCUSDC","b":[["34956.43","0.067801"]],"a":[],"u":20010692,"seq":14108047645}}'
2023-11-02 14:54:36,949 DEBUG ++Rcv raw: b'\x81~\x01\xcd{"topic":"orderbook.50.BTCUSDC","ts":1698936876863,"type":"delta","data":{"s":"BTCUSDC","b":[["34954.71","0.051545"],["34947.83","0.106063"],["34937.39","0.278379"],["34937.36","0.4234"],["34936.36","0.823809"],["34956.43","0"],["34953.11","0"],["34947.18","0"],["34956.42","0"]],"a":[["34961.17","0.076344"],["34961.18","0.00438"],["34961.19","0.026078"],["34963.3","0.0859"],["34962.68","0"],["34977.05","0"],["34976.59","0"]],"u":20010693,"seq":14108047676}}'
2023-11-02 14:54:36,949 DEBUG ++Rcv decoded: fin=1 opcode=1 data=b'{"topic":"orderbook.50.BTCUSDC","ts":1698936876863,"type":"delta","data":{"s":"BTCUSDC","b":[["34954.71","0.051545"],["34947.83","0.106063"],["34937.39","0.278379"],["34937.36","0.4234"],["34936.36","0.823809"],["34956.43","0"],["34953.11","0"],["34947.18","0"],["34956.42","0"]],"a":[["34961.17","0.076344"],["34961.18","0.00438"],["34961.19","0.026078"],["34963.3","0.0859"],["34962.68","0"],["34977.05","0"],["34976.59","0"]],"u":20010693,"seq":14108047676}}'
2023-11-02 14:54:36,969 DEBUG ++Rcv raw: b'\x81~\x01<{"topic":"orderbook.50.BTCUSDC","ts":1698936876884,"type":"delta","data":{"s":"BTCUSDC","b":[["34947.83","0.05154"],["34936.35","0.1875"],["34937.36","0"]],"a":[["34961.16","0.00438"],["34962.67","0.028601"],["34963.29","0.051549"],["34961.19","0"],["34961.18","0"],["34961.17","0"]],"u":20010694,"seq":14108047697}}'
2023-11-02 14:54:36,969 DEBUG ++Rcv decoded: fin=1 opcode=1 data=b'{"topic":"orderbook.50.BTCUSDC","ts":1698936876884,"type":"delta","data":{"s":"BTCUSDC","b":[["34947.83","0.05154"],["34936.35","0.1875"],["34937.36","0"]],"a":[["34961.16","0.00438"],["34962.67","0.028601"],["34963.29","0.051549"],["34961.19","0"],["34961.18","0"],["34961.17","0"]],"u":20010694,"seq":14108047697}}'
2023-11-02 14:54:36,989 DEBUG ++Rcv raw: b'\x81~\x00\xa9{"topic":"orderbook.50.BTCUSDC","ts":1698936876904,"type":"delta","data":{"s":"BTCUSDC","b":[],"a":[["34962","0.0324"],["34976.12","0"]],"u":20010695,"seq":14108047718}}'
2023-11-02 14:54:36,989 DEBUG ++Rcv decoded: fin=1 opcode=1 data=b'{"topic":"orderbook.50.BTCUSDC","ts":1698936876904,"type":"delta","data":{"s":"BTCUSDC","b":[],"a":[["34962","0.0324"],["34976.12","0"]],"u":20010695,"seq":14108047718}}'
2023-11-02 14:54:37,009 DEBUG ++Rcv raw: b'\x81~\x00\xfe{"topic":"orderbook.50.BTCUSDC","ts":1698936876923,"type":"delta","data":{"s":"BTCUSDC","b":[["34935.91","1.373003"],["34957.69","0"]],"a":[["34961.14","0.025998"],["34961.15","0.03895"],["34975.89","0"],["34975.67","0"]],"u":20010696,"seq":14108047727}}'
2023-11-02 14:54:37,009 DEBUG ++Rcv decoded: fin=1 opcode=1 data=b'{"topic":"orderbook.50.BTCUSDC","ts":1698936876923,"type":"delta","data":{"s":"BTCUSDC","b":[["34935.91","1.373003"],["34957.69","0"]],"a":[["34961.14","0.025998"],["34961.15","0.03895"],["34975.89","0"],["34975.67","0"]],"u":20010696,"seq":14108047727}}'
2023-11-02 14:54:37,029 DEBUG ++Rcv raw: b'\x81~\x01?{"topic":"orderbook.50.BTCUSDC","ts":1698936876943,"type":"delta","data":{"s":"BTCUSDC","b":[["34949.33","0.000261"],["34935.91","0"]],"a":[["34961.12","0.049369"],["34961.13","0.03895"],["34961.15","0.001992"],["34969.97","0.000239"],["34975.22","0"],["34975.34","0"],["34961.14","0"]],"u":20010697,"seq":14108047739}}'
2023-11-02 14:54:37,029 DEBUG ++Rcv decoded: fin=1 opcode=1 data=b'{"topic":"orderbook.50.BTCUSDC","ts":1698936876943,"type":"delta","data":{"s":"BTCUSDC","b":[["34949.33","0.000261"],["34935.91","0"]],"a":[["34961.12","0.049369"],["34961.13","0.03895"],["34961.15","0.001992"],["34969.97","0.000239"],["34975.22","0"],["34975.34","0"],["34961.14","0"]],"u":20010697,"seq":14108047739}}'
2023-11-02 14:54:37,049 DEBUG ++Rcv raw: b'\x81~\x00\xed{"topic":"orderbook.50.BTCUSDC","ts":1698936876964,"type":"delta","data":{"s":"BTCUSDC","b":[],"a":[["34961.12","0.027195"],["34975.22","1.372918"],["34975.34","0.0859"],["34962.67","0"],["34961.13","0"]],"u":20010698,"seq":14108047767}}'
2023-11-02 14:54:37,049 DEBUG ++Rcv decoded: fin=1 opcode=1 data=b'{"topic":"orderbook.50.BTCUSDC","ts":1698936876964,"type":"delta","data":{"s":"BTCUSDC","b":[],"a":[["34961.12","0.027195"],["34975.22","1.372918"],["34975.34","0.0859"],["34962.67","0"],["34961.13","0"]],"u":20010698,"seq":14108047767}}'
2023-11-02 14:54:37,069 DEBUG ++Rcv raw: b'\x81~\x00\xd5{"topic":"orderbook.50.BTCUSDC","ts":1698936876983,"type":"delta","data":{"s":"BTCUSDC","b":[],"a":[["34961.14","0.008756"],["34975.67","0.1875"],["34961.16","0"],["34961.12","0"]],"u":20010699,"seq":14108047800}}'
2023-11-02 14:54:37,069 DEBUG ++Rcv decoded: fin=1 opcode=1 data=b'{"topic":"orderbook.50.BTCUSDC","ts":1698936876983,"type":"delta","data":{"s":"BTCUSDC","b":[],"a":[["34961.14","0.008756"],["34975.67","0.1875"],["34961.16","0"],["34961.12","0"]],"u":20010699,"seq":14108047800}}'
2023-11-02 14:54:37,149 DEBUG ++Rcv raw: b'\x81~\x00\xab{"topic":"orderbook.50.BTCUSDC","ts":1698936877064,"type":"delta","data":{"s":"BTCUSDC","b":[],"a":[["34975.89","0.050202"],["34962","0"]],"u":20010700,"seq":14108047853}}'
2023-11-02 14:54:37,150 DEBUG ++Rcv decoded: fin=1 opcode=1 data=b'{"topic":"orderbook.50.BTCUSDC","ts":1698936877064,"type":"delta","data":{"s":"BTCUSDC","b":[],"a":[["34975.89","0.050202"],["34962","0"]],"u":20010700,"seq":14108047853}}'
2023-11-02 14:54:37,169 DEBUG ++Rcv raw: b'\x81~\x00\xd6{"topic":"orderbook.50.BTCUSDC","ts":1698936877084,"type":"delta","data":{"s":"BTCUSDC","b":[],"a":[["34961.1","0.023613"],["34961.11","0.028603"],["34975.89","0"],["34975.67","0"]],"u":20010701,"seq":14108047869}}'
2023-11-02 14:54:37,169 DEBUG ++Rcv decoded: fin=1 opcode=1 data=b'{"topic":"orderbook.50.BTCUSDC","ts":1698936877084,"type":"delta","data":{"s":"BTCUSDC","b":[],"a":[["34961.1","0.023613"],["34961.11","0.028603"],["34975.89","0"],["34975.67","0"]],"u":20010701,"seq":14108047869}}'
2023-11-02 14:54:37,188 DEBUG ++Rcv raw: b'\x81~\x00\xfa{"topic":"orderbook.50.BTCUSDC","ts":1698936877103,"type":"delta","data":{"s":"BTCUSDC","b":[["34956.61","0.095268"],["34949.31","0"]],"a":[["34960.11","0.075498"],["34966.7","0.03"],["34970.01","0"],["34972.43","0"]],"u":20010702,"seq":14108047887}}'
2023-11-02 14:54:37,189 DEBUG ++Rcv decoded: fin=1 opcode=1 data=b'{"topic":"orderbook.50.BTCUSDC","ts":1698936877103,"type":"delta","data":{"s":"BTCUSDC","b":[["34956.61","0.095268"],["34949.31","0"]],"a":[["34960.11","0.075498"],["34966.7","0.03"],["34970.01","0"],["34972.43","0"]],"u":20010702,"seq":14108047887}}'
2023-11-02 14:54:37,209 DEBUG ++Rcv raw: b'\x81~\x00\xab{"topic":"orderbook.50.BTCUSDC","ts":1698936877124,"type":"delta","data":{"s":"BTCUSDC","b":[],"a":[["34975.67","0.1875"],["34967.6","0"]],"u":20010703,"seq":14108047896}}'
2023-11-02 14:54:37,209 DEBUG ++Rcv decoded: fin=1 opcode=1 data=b'{"topic":"orderbook.50.BTCUSDC","ts":1698936877124,"type":"delta","data":{"s":"BTCUSDC","b":[],"a":[["34975.67","0.1875"],["34967.6","0"]],"u":20010703,"seq":14108047896}}'
2023-11-02 14:54:37,271 DEBUG ++Rcv raw: b'\x81~\x00\xae{"topic":"orderbook.50.BTCUSDC","ts":1698936877183,"type":"delta","data":{"s":"BTCUSDC","b":[],"a":[["34975.89","0.050202"],["34961.11","0"]],"u":20010704,"seq":14108047911}}'
2023-11-02 14:54:37,271 DEBUG ++Rcv decoded: fin=1 opcode=1 data=b'{"topic":"orderbook.50.BTCUSDC","ts":1698936877183,"type":"delta","data":{"s":"BTCUSDC","b":[],"a":[["34975.89","0.050202"],["34961.11","0"]],"u":20010704,"seq":14108047911}}'
2023-11-02 14:54:37,289 DEBUG ++Rcv raw: b'\x81~\x00\xad{"topic":"orderbook.50.BTCUSDC","ts":1698936877203,"type":"delta","data":{"s":"BTCUSDC","b":[],"a":[["34976.12","0.043812"],["34961.1","0"]],"u":20010705,"seq":14108047916}}'
2023-11-02 14:54:37,289 DEBUG ++Rcv decoded: fin=1 opcode=1 data=b'{"topic":"orderbook.50.BTCUSDC","ts":1698936877203,"type":"delta","data":{"s":"BTCUSDC","b":[],"a":[["34976.12","0.043812"],["34961.1","0"]],"u":20010705,"seq":14108047916}}'
2023-11-02 14:54:37,329 DEBUG ++Rcv raw: b'\x81~\x00\xae{"topic":"orderbook.50.BTCUSDC","ts":1698936877243,"type":"delta","data":{"s":"BTCUSDC","b":[],"a":[["34976.59","0.049844"],["34961.14","0"]],"u":20010706,"seq":14108047954}}'
2023-11-02 14:54:37,329 DEBUG ++Rcv decoded: fin=1 opcode=1 data=b'{"topic":"orderbook.50.BTCUSDC","ts":1698936877243,"type":"delta","data":{"s":"BTCUSDC","b":[],"a":[["34976.59","0.049844"],["34961.14","0"]],"u":20010706,"seq":14108047954}}'
2023-11-02 14:54:37,410 DEBUG ++Rcv raw: b'\x81~\x00\xae{"topic":"orderbook.50.BTCUSDC","ts":1698936877325,"type":"delta","data":{"s":"BTCUSDC","b":[],"a":[["34977.05","0.051548"],["34975.22","0"]],"u":20010707,"seq":14108047972}}'
2023-11-02 14:54:37,411 DEBUG ++Rcv decoded: fin=1 opcode=1 data=b'{"topic":"orderbook.50.BTCUSDC","ts":1698936877325,"type":"delta","data":{"s":"BTCUSDC","b":[],"a":[["34977.05","0.051548"],["34975.22","0"]],"u":20010707,"seq":14108047972}}'
2023-11-02 14:54:37,429 DEBUG ++Rcv raw: b'\x81~\x00\xc6{"topic":"orderbook.50.BTCUSDC","ts":1698936877344,"type":"delta","data":{"s":"BTCUSDC","b":[],"a":[["34974.59","1.373003"],["34975.21","0.112504"],["34977.05","0"]],"u":20010708,"seq":14108047979}}'
2023-11-02 14:54:37,430 DEBUG ++Rcv decoded: fin=1 opcode=1 data=b'{"topic":"orderbook.50.BTCUSDC","ts":1698936877344,"type":"delta","data":{"s":"BTCUSDC","b":[],"a":[["34974.59","1.373003"],["34975.21","0.112504"],["34977.05","0"]],"u":20010708,"seq":14108047979}}'
2023-11-02 14:54:37,510 DEBUG ++Rcv raw: b'\x81~\x00\xad{"topic":"orderbook.50.BTCUSDC","ts":1698936877425,"type":"delta","data":{"s":"BTCUSDC","b":[],"a":[["34960.1","0.028604"],["34976.59","0"]],"u":20010709,"seq":14108047994}}'
2023-11-02 14:54:37,510 DEBUG ++Rcv decoded: fin=1 opcode=1 data=b'{"topic":"orderbook.50.BTCUSDC","ts":1698936877425,"type":"delta","data":{"s":"BTCUSDC","b":[],"a":[["34960.1","0.028604"],["34976.59","0"]],"u":20010709,"seq":14108047994}}'
2023-11-02 14:54:37,529 DEBUG ++Rcv raw: b'\x81~\x00\xae{"topic":"orderbook.50.BTCUSDC","ts":1698936877443,"type":"delta","data":{"s":"BTCUSDC","b":[],"a":[["34976.59","0.049844"],["34960.11","0"]],"u":20010710,"seq":14108047998}}'
2023-11-02 14:54:37,530 DEBUG ++Rcv decoded: fin=1 opcode=1 data=b'{"topic":"orderbook.50.BTCUSDC","ts":1698936877443,"type":"delta","data":{"s":"BTCUSDC","b":[],"a":[["34976.59","0.049844"],["34960.11","0"]],"u":20010710,"seq":14108047998}}'
2023-11-02 14:54:37,649 DEBUG ++Rcv raw: b'\x81~\x00\xd5{"topic":"orderbook.50.BTCUSDC","ts":1698936877563,"type":"delta","data":{"s":"BTCUSDC","b":[["34941.97","0.114422"],["34945.51","0"]],"a":[["34961.14","0.008756"],["34960.1","0"]],"u":20010711,"seq":14108048037}}'
2023-11-02 14:54:37,649 DEBUG ++Rcv decoded: fin=1 opcode=1 data=b'{"topic":"orderbook.50.BTCUSDC","ts":1698936877563,"type":"delta","data":{"s":"BTCUSDC","b":[["34941.97","0.114422"],["34945.51","0"]],"a":[["34961.14","0.008756"],["34960.1","0"]],"u":20010711,"seq":14108048037}}'
2023-11-02 14:54:37,670 DEBUG ++Rcv raw: b'\x81~\x00\xd5{"topic":"orderbook.50.BTCUSDC","ts":1698936877584,"type":"delta","data":{"s":"BTCUSDC","b":[],"a":[["34977.05","0.051548"],["34977.06","0.0859"],["34974.66","0"],["34969.97","0"]],"u":20010712,"seq":14108048043}}'
2023-11-02 14:54:37,670 DEBUG ++Rcv decoded: fin=1 opcode=1 data=b'{"topic":"orderbook.50.BTCUSDC","ts":1698936877584,"type":"delta","data":{"s":"BTCUSDC","b":[],"a":[["34977.05","0.051548"],["34977.06","0.0859"],["34974.66","0"],["34969.97","0"]],"u":20010712,"seq":14108048043}}'
2023-11-02 14:54:37,729 DEBUG ++Rcv raw: b'\x81~\x00\xae{"topic":"orderbook.50.BTCUSDC","ts":1698936877643,"type":"delta","data":{"s":"BTCUSDC","b":[],"a":[["34960.09","0.028604"],["34977.06","0"]],"u":20010713,"seq":14108048053}}'
2023-11-02 14:54:37,729 DEBUG ++Rcv decoded: fin=1 opcode=1 data=b'{"topic":"orderbook.50.BTCUSDC","ts":1698936877643,"type":"delta","data":{"s":"BTCUSDC","b":[],"a":[["34960.09","0.028604"],["34977.06","0"]],"u":20010713,"seq":14108048053}}'
2023-11-02 14:54:37,749 DEBUG ++Rcv raw: b'\x81~\x00\xd7{"topic":"orderbook.50.BTCUSDC","ts":1698936877664,"type":"delta","data":{"s":"BTCUSDC","b":[],"a":[["34959.83","0.074363"],["34960.08","0.008756"],["34977.05","0"],["34961.14","0"]],"u":20010714,"seq":14108048058}}'
2023-11-02 14:54:37,749 DEBUG ++Rcv decoded: fin=1 opcode=1 data=b'{"topic":"orderbook.50.BTCUSDC","ts":1698936877664,"type":"delta","data":{"s":"BTCUSDC","b":[],"a":[["34959.83","0.074363"],["34960.08","0.008756"],["34977.05","0"],["34961.14","0"]],"u":20010714,"seq":14108048058}}'
2023-11-02 14:54:37,769 DEBUG ++Rcv raw: b'\x81~\x00\xae{"topic":"orderbook.50.BTCUSDC","ts":1698936877683,"type":"delta","data":{"s":"BTCUSDC","b":[["34936.12","0.116531"],["34949.33","0"]],"a":[],"u":20010715,"seq":14108048059}}'
2023-11-02 14:54:37,769 DEBUG ++Rcv decoded: fin=1 opcode=1 data=b'{"topic":"orderbook.50.BTCUSDC","ts":1698936877683,"type":"delta","data":{"s":"BTCUSDC","b":[["34936.12","0.116531"],["34949.33","0"]],"a":[],"u":20010715,"seq":14108048059}}'
2023-11-02 14:54:37,829 DEBUG ++Rcv raw: b'\x81~\x00\xae{"topic":"orderbook.50.BTCUSDC","ts":1698936877744,"type":"delta","data":{"s":"BTCUSDC","b":[],"a":[["34977.05","0.051548"],["34960.09","0"]],"u":20010716,"seq":14108048078}}'
2023-11-02 14:54:37,829 DEBUG ++Rcv decoded: fin=1 opcode=1 data=b'{"topic":"orderbook.50.BTCUSDC","ts":1698936877744,"type":"delta","data":{"s":"BTCUSDC","b":[],"a":[["34977.05","0.051548"],["34960.09","0"]],"u":20010716,"seq":14108048078}}'
2023-11-02 14:54:37,908 DEBUG ++Rcv raw: b'\x81~\x00\xd5{"topic":"orderbook.50.BTCUSDC","ts":1698936877823,"type":"delta","data":{"s":"BTCUSDC","b":[],"a":[["34959.82","0.008756"],["34977.06","0.0859"],["34960.08","0"],["34959.83","0"]],"u":20010717,"seq":14108048101}}'
2023-11-02 14:54:37,909 DEBUG ++Rcv decoded: fin=1 opcode=1 data=b'{"topic":"orderbook.50.BTCUSDC","ts":1698936877823,"type":"delta","data":{"s":"BTCUSDC","b":[],"a":[["34959.82","0.008756"],["34977.06","0.0859"],["34960.08","0"],["34959.83","0"]],"u":20010717,"seq":14108048101}}'
2023-11-02 14:54:37,929 DEBUG ++Rcv raw: b'\x81~\x00\x9c{"topic":"orderbook.50.BTCUSDC","ts":1698936877843,"type":"delta","data":{"s":"BTCUSDC","b":[],"a":[["34959.82","0.03736"]],"u":20010718,"seq":14108048103}}'
2023-11-02 14:54:37,929 DEBUG ++Rcv decoded: fin=1 opcode=1 data=b'{"topic":"orderbook.50.BTCUSDC","ts":1698936877843,"type":"delta","data":{"s":"BTCUSDC","b":[],"a":[["34959.82","0.03736"]],"u":20010718,"seq":14108048103}}'
2023-11-02 14:54:37,949 DEBUG ++Rcv raw: b'\x81~\x00\xd0{"topic":"orderbook.50.BTCUSDC","ts":1698936877863,"type":"delta","data":{"s":"BTCUSDC","b":[],"a":[["34962","0.0324"],["34966.82","0.1875"],["34977.06","0"],["34977.05","0"]],"u":20010719,"seq":14108048119}}'
2023-11-02 14:54:37,949 DEBUG ++Rcv decoded: fin=1 opcode=1 data=b'{"topic":"orderbook.50.BTCUSDC","ts":1698936877863,"type":"delta","data":{"s":"BTCUSDC","b":[],"a":[["34962","0.0324"],["34966.82","0.1875"],["34977.06","0"],["34977.05","0"]],"u":20010719,"seq":14108048119}}'
2023-11-02 14:54:37,969 DEBUG ++Rcv raw: b'\x81~\x00\xc6{"topic":"orderbook.50.BTCUSDC","ts":1698936877883,"type":"delta","data":{"s":"BTCUSDC","b":[],"a":[["34966.73","0.106063"],["34977.05","0.051548"],["34967.99","0"]],"u":20010720,"seq":14108048128}}'
2023-11-02 14:54:37,969 DEBUG ++Rcv decoded: fin=1 opcode=1 data=b'{"topic":"orderbook.50.BTCUSDC","ts":1698936877883,"type":"delta","data":{"s":"BTCUSDC","b":[],"a":[["34966.73","0.106063"],["34977.05","0.051548"],["34967.99","0"]],"u":20010720,"seq":14108048128}}'
2023-11-02 14:54:37,988 DEBUG ++Rcv raw: b'\x81~\x00\xad{"topic":"orderbook.50.BTCUSDC","ts":1698936877903,"type":"delta","data":{"s":"BTCUSDC","b":[],"a":[["34975.4","0.031411"],["34977.05","0"]],"u":20010721,"seq":14108048132}}'
2023-11-02 14:54:37,989 DEBUG ++Rcv decoded: fin=1 opcode=1 data=b'{"topic":"orderbook.50.BTCUSDC","ts":1698936877903,"type":"delta","data":{"s":"BTCUSDC","b":[],"a":[["34975.4","0.031411"],["34977.05","0"]],"u":20010721,"seq":14108048132}}'
2023-11-02 14:54:38,129 DEBUG ++Rcv raw: b'\x81~\x00\xc5{"topic":"orderbook.50.BTCUSDC","ts":1698936878044,"type":"delta","data":{"s":"BTCUSDC","b":[["34949.54","0.086161"]],"a":[["34969.59","0.000239"],["34976.59","0"]],"u":20010722,"seq":14108048169}}'
2023-11-02 14:54:38,129 DEBUG ++Rcv decoded: fin=1 opcode=1 data=b'{"topic":"orderbook.50.BTCUSDC","ts":1698936878044,"type":"delta","data":{"s":"BTCUSDC","b":[["34949.54","0.086161"]],"a":[["34969.59","0.000239"],["34976.59","0"]],"u":20010722,"seq":14108048169}}'
2023-11-02 14:54:38,149 DEBUG ++Rcv raw: b'\x81~\x00\xae{"topic":"orderbook.50.BTCUSDC","ts":1698936878064,"type":"delta","data":{"s":"BTCUSDC","b":[],"a":[["34974.49","0.823809"],["34975.21","0"]],"u":20010723,"seq":14108048185}}'
2023-11-02 14:54:38,150 DEBUG ++Rcv decoded: fin=1 opcode=1 data=b'{"topic":"orderbook.50.BTCUSDC","ts":1698936878064,"type":"delta","data":{"s":"BTCUSDC","b":[],"a":[["34974.49","0.823809"],["34975.21","0"]],"u":20010723,"seq":14108048185}}'
2023-11-02 14:54:38,169 DEBUG ++Rcv raw: b'\x81~\x00\x9d{"topic":"orderbook.50.BTCUSDC","ts":1698936878083,"type":"delta","data":{"s":"BTCUSDC","b":[],"a":[["34959.82","0.008756"]],"u":20010724,"seq":14108048199}}'
2023-11-02 14:54:38,169 DEBUG ++Rcv decoded: fin=1 opcode=1 data=b'{"topic":"orderbook.50.BTCUSDC","ts":1698936878083,"type":"delta","data":{"s":"BTCUSDC","b":[],"a":[["34959.82","0.008756"]],"u":20010724,"seq":14108048199}}'
2023-11-02 14:54:38,229 DEBUG ++Rcv raw: b'\x81~\x00\xae{"topic":"orderbook.50.BTCUSDC","ts":1698936878144,"type":"delta","data":{"s":"BTCUSDC","b":[],"a":[["34976.59","0.049844"],["34959.82","0"]],"u":20010725,"seq":14108048205}}'
2023-11-02 14:54:38,229 DEBUG ++Rcv decoded: fin=1 opcode=1 data=b'{"topic":"orderbook.50.BTCUSDC","ts":1698936878144,"type":"delta","data":{"s":"BTCUSDC","b":[],"a":[["34976.59","0.049844"],["34959.82","0"]],"u":20010725,"seq":14108048205}}'
2023-11-02 14:54:38,250 DEBUG ++Rcv raw: b'\x81~\x00\xd7{"topic":"orderbook.50.BTCUSDC","ts":1698936878164,"type":"delta","data":{"s":"BTCUSDC","b":[],"a":[["34959.38","0.079738"],["34961.14","0.008756"],["34976.59","0"],["34966.82","0"]],"u":20010726,"seq":14108048208}}'
2023-11-02 14:54:38,250 DEBUG ++Rcv decoded: fin=1 opcode=1 data=b'{"topic":"orderbook.50.BTCUSDC","ts":1698936878164,"type":"delta","data":{"s":"BTCUSDC","b":[],"a":[["34959.38","0.079738"],["34961.14","0.008756"],["34976.59","0"],["34966.82","0"]],"u":20010726,"seq":14108048208}}'
2023-11-02 14:54:38,268 DEBUG ++Rcv raw: b'\x81~\x01\x17{"topic":"orderbook.50.BTCUSDC","ts":1698936878183,"type":"delta","data":{"s":"BTCUSDC","b":[["34949.57","0.000261"],["34952.57","0"]],"a":[["34966.73","0.051549"],["34967.99","0.051549"],["34969.53","0.000239"],["34976.12","0"],["34975.89","0"]],"u":20010727,"seq":14108048218}}'
2023-11-02 14:54:38,269 DEBUG ++Rcv decoded: fin=1 opcode=1 data=b'{"topic":"orderbook.50.BTCUSDC","ts":1698936878183,"type":"delta","data":{"s":"BTCUSDC","b":[["34949.57","0.000261"],["34952.57","0"]],"a":[["34966.73","0.051549"],["34967.99","0.051549"],["34969.53","0.000239"],["34976.12","0"],["34975.89","0"]],"u":20010727,"seq":14108048218}}'
2023-11-02 14:54:38,350 DEBUG ++Rcv raw: b'\x81~\x01L{"topic":"orderbook.50.BTCUSDC","ts":1698936878263,"type":"delta","data":{"s":"BTCUSDC","b":[["34935.91","1.373003"],["34931.31","0.1875"],["34956.61","0"],["34956.32","0"]],"a":[["34959.36","0.03895"],["34959.37","0.008756"],["34966.38","0.1875"],["34961.14","0"],["34963.91","0"],["34959.38","0"]],"u":20010728,"seq":14108048249}}'
2023-11-02 14:54:38,350 DEBUG ++Rcv decoded: fin=1 opcode=1 data=b'{"topic":"orderbook.50.BTCUSDC","ts":1698936878263,"type":"delta","data":{"s":"BTCUSDC","b":[["34935.91","1.373003"],["34931.31","0.1875"],["34956.61","0"],["34956.32","0"]],"a":[["34959.36","0.03895"],["34959.37","0.008756"],["34966.38","0.1875"],["34961.14","0"],["34963.91","0"],["34959.38","0"]],"u":20010728,"seq":14108048249}}'
2023-11-02 14:54:38,369 DEBUG ++Rcv raw: b'\x81~\x01${"topic":"orderbook.50.BTCUSDC","ts":1698936878283,"type":"delta","data":{"s":"BTCUSDC","b":[["34955.81","0.023585"],["34949.82","0.00057"],["34931.31","0"],["34935.91","0"]],"a":[["34963.4","0.057202"],["34966.12","0.1125"],["34975.67","0"],["34966.73","0"]],"u":20010729,"seq":14108048275}}'
2023-11-02 14:54:38,369 DEBUG ++Rcv decoded: fin=1 opcode=1 data=b'{"topic":"orderbook.50.BTCUSDC","ts":1698936878283,"type":"delta","data":{"s":"BTCUSDC","b":[["34955.81","0.023585"],["34949.82","0.00057"],["34931.31","0"],["34935.91","0"]],"a":[["34963.4","0.057202"],["34966.12","0.1125"],["34975.67","0"],["34966.73","0"]],"u":20010729,"seq":14108048275}}'
2023-11-02 14:54:38,389 DEBUG ++Rcv raw: b'\x81~\x00\xc5{"topic":"orderbook.50.BTCUSDC","ts":1698936878304,"type":"delta","data":{"s":"BTCUSDC","b":[["34935.91","1.373003"],["34955.81","0"]],"a":[["34963.29","0.079419"]],"u":20010730,"seq":14108048277}}'
2023-11-02 14:54:38,389 DEBUG ++Rcv decoded: fin=1 opcode=1 data=b'{"topic":"orderbook.50.BTCUSDC","ts":1698936878304,"type":"delta","data":{"s":"BTCUSDC","b":[["34935.91","1.373003"],["34955.81","0"]],"a":[["34963.29","0.079419"]],"u":20010730,"seq":14108048277}}'
2023-11-02 14:54:38,410 DEBUG ++Rcv raw: b'\x81~\x00\xd4{"topic":"orderbook.50.BTCUSDC","ts":1698936878324,"type":"delta","data":{"s":"BTCUSDC","b":[],"a":[["34959.35","0.008756"],["34961.58","0.0859"],["34959.37","0"],["34975.4","0"]],"u":20010731,"seq":14108048305}}'
2023-11-02 14:54:38,410 DEBUG ++Rcv decoded: fin=1 opcode=1 data=b'{"topic":"orderbook.50.BTCUSDC","ts":1698936878324,"type":"delta","data":{"s":"BTCUSDC","b":[],"a":[["34959.35","0.008756"],["34961.58","0.0859"],["34959.37","0"],["34975.4","0"]],"u":20010731,"seq":14108048305}}'
2023-11-02 14:54:38,433 DEBUG ++Rcv raw: b'\x81~\x01\xd7{"topic":"orderbook.50.BTCUSDC","ts":1698936878344,"type":"delta","data":{"s":"BTCUSDC","b":[["34931.31","0.1875"],["34930.19","0.274841"],["34927.27","0.1875"],["34954.7","0"],["34949","0"],["34939.55","0"]],"a":[["34961.57","0.051543"],["34963.29","0.051549"],["34975.4","0.031411"],["34975.67","0.1875"],["34975.89","0.050202"],["34976.12","0.043812"],["34971.38","0"],["34966.7","0"],["34963.4","0"],["34970.42","0"],["34959.36","0"]],"u":20010732,"seq":14108048348}}'
2023-11-02 14:54:38,433 DEBUG ++Rcv decoded: fin=1 opcode=1 data=b'{"topic":"orderbook.50.BTCUSDC","ts":1698936878344,"type":"delta","data":{"s":"BTCUSDC","b":[["34931.31","0.1875"],["34930.19","0.274841"],["34927.27","0.1875"],["34954.7","0"],["34949","0"],["34939.55","0"]],"a":[["34961.57","0.051543"],["34963.29","0.051549"],["34975.4","0.031411"],["34975.67","0.1875"],["34975.89","0.050202"],["34976.12","0.043812"],["34971.38","0"],["34966.7","0"],["34963.4","0"],["34970.42","0"],["34959.36","0"]],"u":20010732,"seq":14108048348}}'
2023-11-02 14:54:38,449 DEBUG ++Rcv raw: b'\x81~\x02E{"topic":"orderbook.50.BTCUSDC","ts":1698936878364,"type":"delta","data":{"s":"BTCUSDC","b":[["34953.11","0.086604"],["34952.25","0.028605"],["34949.54","0.0859"],["34937.33","0.286226"],["34927.86","0.458086"],["34925.66","0.128166"],["34925.01","1.32582"],["34954.71","0"],["34936.36","0"],["34930.19","0"],["34953.44","0"],["34936.12","0"],["34949.74","0"]],"a":[["34959.34","0.03895"],["34959.81","0.028604"],["34960","0.0324"],["34970.31","0.363886"],["34971.37","0.112506"],["34975.89","0"],["34969.59","0"],["34969.99","0"],["34976.12","0"]],"u":20010733,"seq":14108048420}}'
2023-11-02 14:54:38,449 DEBUG ++Rcv decoded: fin=1 opcode=1 data=b'{"topic":"orderbook.50.BTCUSDC","ts":1698936878364,"type":"delta","data":{"s":"BTCUSDC","b":[["34953.11","0.086604"],["34952.25","0.028605"],["34949.54","0.0859"],["34937.33","0.286226"],["34927.86","0.458086"],["34925.66","0.128166"],["34925.01","1.32582"],["34954.71","0"],["34936.36","0"],["34930.19","0"],["34953.44","0"],["34936.12","0"],["34949.74","0"]],"a":[["34959.34","0.03895"],["34959.81","0.028604"],["34960","0.0324"],["34970.31","0.363886"],["34971.37","0.112506"],["34975.89","0"],["34969.59","0"],["34969.99","0"],["34976.12","0"]],"u":20010733,"seq":14108048420}}'
2023-11-02 14:54:38,469 DEBUG ++Rcv raw: b'\x81~\x01\xfb{"topic":"orderbook.50.BTCUSDC","ts":1698936878383,"type":"delta","data":{"s":"BTCUSDC","b":[["34953.33","0.034333"],["34953.32","0.057219"],["34950.01","0.028671"],["34949.55","0.051549"],["34948.01","0.358156"],["34927.87","0.274851"],["34953.05","0"],["34925.66","0"],["34927.27","0"],["34927.86","0"],["34925.01","0"]],"a":[["34959.33","0.076336"],["34959.34","0.046193"],["34960.95","0.057206"],["34969.69","0.218332"],["34959.35","0"],["34975.4","0"],["34975.67","0"]],"u":20010734,"seq":14108048472}}'
2023-11-02 14:54:38,469 DEBUG ++Rcv decoded: fin=1 opcode=1 data=b'{"topic":"orderbook.50.BTCUSDC","ts":1698936878383,"type":"delta","data":{"s":"BTCUSDC","b":[["34953.33","0.034333"],["34953.32","0.057219"],["34950.01","0.028671"],["34949.55","0.051549"],["34948.01","0.358156"],["34927.87","0.274851"],["34953.05","0"],["34925.66","0"],["34927.27","0"],["34927.86","0"],["34925.01","0"]],"a":[["34959.33","0.076336"],["34959.34","0.046193"],["34960.95","0.057206"],["34969.69","0.218332"],["34959.35","0"],["34975.4","0"],["34975.67","0"]],"u":20010734,"seq":14108048472}}'
2023-11-02 14:54:38,489 DEBUG ++Rcv raw: b'\x81~\x01\x8d{"topic":"orderbook.50.BTCUSDC","ts":1698936878404,"type":"delta","data":{"s":"BTCUSDC","b":[["34953.11","0.051543"],["34951.27","0.051544"],["34948.02","0.214898"],["34927.86","0.458086"],["34927.27","0.1875"],["34949.55","0"],["34953.32","0"],["34950.01","0"],["34927.87","0"]],"a":[["34975.4","0.031411"],["34975.67","0.1875"],["34959.34","0"],["34960.95","0"]],"u":20010735,"seq":14108048505}}'
2023-11-02 14:54:38,489 DEBUG ++Rcv decoded: fin=1 opcode=1 data=b'{"topic":"orderbook.50.BTCUSDC","ts":1698936878404,"type":"delta","data":{"s":"BTCUSDC","b":[["34953.11","0.051543"],["34951.27","0.051544"],["34948.02","0.214898"],["34927.86","0.458086"],["34927.27","0.1875"],["34949.55","0"],["34953.32","0"],["34950.01","0"],["34927.87","0"]],"a":[["34975.4","0.031411"],["34975.67","0.1875"],["34959.34","0"],["34960.95","0"]],"u":20010735,"seq":14108048505}}'
2023-11-02 14:54:38,510 DEBUG ++Rcv raw: b'\x81~\x01%{"topic":"orderbook.50.BTCUSDC","ts":1698936878424,"type":"delta","data":{"s":"BTCUSDC","b":[["34950.01","0.02867"],["34927.87","0.274859"],["34951.27","0"],["34953.33","0"]],"a":[["34959.32","0.03895"],["34969.86","0.043525"],["34975.67","0"],["34975.4","0"]],"u":20010736,"seq":14108048535}}'
2023-11-02 14:54:38,510 DEBUG ++Rcv decoded: fin=1 opcode=1 data=b'{"topic":"orderbook.50.BTCUSDC","ts":1698936878424,"type":"delta","data":{"s":"BTCUSDC","b":[["34950.01","0.02867"],["34927.87","0.274859"],["34951.27","0"],["34953.33","0"]],"a":[["34959.32","0.03895"],["34969.86","0.043525"],["34975.67","0"],["34975.4","0"]],"u":20010736,"seq":14108048535}}'
2023-11-02 14:54:38,529 DEBUG ++Rcv raw: b'\x81~\x00\xc4{"topic":"orderbook.50.BTCUSDC","ts":1698936878443,"type":"delta","data":{"s":"BTCUSDC","b":[["34925.66","0.128167"],["34950.02","0"]],"a":[["34959.33","0.02863"]],"u":20010737,"seq":14108048556}}'
2023-11-02 14:54:38,529 DEBUG ++Rcv decoded: fin=1 opcode=1 data=b'{"topic":"orderbook.50.BTCUSDC","ts":1698936878443,"type":"delta","data":{"s":"BTCUSDC","b":[["34925.66","0.128167"],["34950.02","0"]],"a":[["34959.33","0.02863"]],"u":20010737,"seq":14108048556}}'
2023-11-02 14:54:38,550 DEBUG ++Rcv raw: b'\x81~\x01O{"topic":"orderbook.50.BTCUSDC","ts":1698936878464,"type":"delta","data":{"s":"BTCUSDC","b":[["34948.03","0.001246"],["34947.78","0.114456"],["34953.1","0"],["34946.18","0"]],"a":[["34959.31","0.05914"],["34969.23","0.114386"],["34973.99","0.040256"],["34959.33","0"],["34959.32","0"],["34959.81","0"]],"u":20010738,"seq":14108048584}}'
2023-11-02 14:54:38,550 DEBUG ++Rcv decoded: fin=1 opcode=1 data=b'{"topic":"orderbook.50.BTCUSDC","ts":1698936878464,"type":"delta","data":{"s":"BTCUSDC","b":[["34948.03","0.001246"],["34947.78","0.114456"],["34953.1","0"],["34946.18","0"]],"a":[["34959.31","0.05914"],["34969.23","0.114386"],["34973.99","0.040256"],["34959.33","0"],["34959.32","0"],["34959.81","0"]],"u":20010738,"seq":14108048584}}'
2023-11-02 14:54:38,569 DEBUG ++Rcv raw: b'\x81~\x01<{"topic":"orderbook.50.BTCUSDC","ts":1698936878484,"type":"delta","data":{"s":"BTCUSDC","b":[["34954.69","0.057216"],["34925.66","0"]],"a":[["34958.09","0.077803"],["34959.3","0.049267"],["34959.31","0.008756"],["34962.31","0.057204"],["34974.93","0"],["34975","0"],["34975.34","0"]],"u":20010739,"seq":14108048611}}'
2023-11-02 14:54:38,569 DEBUG ++Rcv decoded: fin=1 opcode=1 data=b'{"topic":"orderbook.50.BTCUSDC","ts":1698936878484,"type":"delta","data":{"s":"BTCUSDC","b":[["34954.69","0.057216"],["34925.66","0"]],"a":[["34958.09","0.077803"],["34959.3","0.049267"],["34959.31","0.008756"],["34962.31","0.057204"],["34974.93","0"],["34975","0"],["34975.34","0"]],"u":20010739,"seq":14108048611}}'
2023-11-02 14:54:38,589 DEBUG ++Rcv raw: b'\x81~\x00\x9c{"topic":"orderbook.50.BTCUSDC","ts":1698936878503,"type":"delta","data":{"s":"BTCUSDC","b":[],"a":[["34959.3","0.024694"]],"u":20010740,"seq":14108048620}}'
2023-11-02 14:54:38,589 DEBUG ++Rcv decoded: fin=1 opcode=1 data=b'{"topic":"orderbook.50.BTCUSDC","ts":1698936878503,"type":"delta","data":{"s":"BTCUSDC","b":[],"a":[["34959.3","0.024694"]],"u":20010740,"seq":14108048620}}'
2023-11-02 14:54:38,609 DEBUG ++Rcv raw: b'\x81~\x00\xae{"topic":"orderbook.50.BTCUSDC","ts":1698936878523,"type":"delta","data":{"s":"BTCUSDC","b":[],"a":[["34958.08","0.008756"],["34959.31","0"]],"u":20010741,"seq":14108048631}}'
2023-11-02 14:54:38,610 DEBUG ++Rcv decoded: fin=1 opcode=1 data=b'{"topic":"orderbook.50.BTCUSDC","ts":1698936878523,"type":"delta","data":{"s":"BTCUSDC","b":[],"a":[["34958.08","0.008756"],["34959.31","0"]],"u":20010741,"seq":14108048631}}'
2023-11-02 14:54:38,633 DEBUG ++Rcv raw: b'\x81~\x00\xe8{"topic":"orderbook.50.BTCUSDC","ts":1698936878544,"type":"delta","data":{"s":"BTCUSDC","b":[["34925.01","1.32582"],["34954.69","0"]],"a":[["34962.71","0.033"],["34974.93","0.0441"],["34958.09","0"]],"u":20010742,"seq":14108048651}}'
2023-11-02 14:54:38,634 DEBUG ++Rcv decoded: fin=1 opcode=1 data=b'{"topic":"orderbook.50.BTCUSDC","ts":1698936878544,"type":"delta","data":{"s":"BTCUSDC","b":[["34925.01","1.32582"],["34954.69","0"]],"a":[["34962.71","0.033"],["34974.93","0.0441"],["34958.09","0"]],"u":20010742,"seq":14108048651}}'
2023-11-02 14:54:38,649 DEBUG ++Rcv raw: b'\x81~\x01^{"topic":"orderbook.50.BTCUSDC","ts":1698936878564,"type":"delta","data":{"s":"BTCUSDC","b":[["34925","2.2097"],["34924.42","0.4207"],["34923.58","0.1875"],["34947.78","0"],["34939.86","0"],["34937.33","0"]],"a":[["34958.06","0.008756"],["34958.07","0.03895"],["34959.3","0.053298"],["34958.08","0"],["34962.31","0"]],"u":20010743,"seq":14108048676}}'
2023-11-02 14:54:38,651 DEBUG ++Rcv decoded: fin=1 opcode=1 data=b'{"topic":"orderbook.50.BTCUSDC","ts":1698936878564,"type":"delta","data":{"s":"BTCUSDC","b":[["34925","2.2097"],["34924.42","0.4207"],["34923.58","0.1875"],["34947.78","0"],["34939.86","0"],["34937.33","0"]],"a":[["34958.06","0.008756"],["34958.07","0.03895"],["34959.3","0.053298"],["34958.08","0"],["34962.31","0"]],"u":20010743,"seq":14108048676}}'
2023-11-02 14:54:38,669 DEBUG ++Rcv raw: b'\x81~\x01\x8d{"topic":"orderbook.50.BTCUSDC","ts":1698936878583,"type":"delta","data":{"s":"BTCUSDC","b":[["34954.07","0.057217"],["34946.47","0.11446"],["34945.91","0.04271"],["34940.31","0.112505"],["34936.36","0.823804"],["34936.22","0.286235"],["34925","0"],["34939.12","0"],["34924.42","0"],["34923.58","0"],["34925.01","0"]],"a":[["34961.72","0.057205"],["34958.07","0"]],"u":20010744,"seq":14108048691}}'
2023-11-02 14:54:38,670 DEBUG ++Rcv decoded: fin=1 opcode=1 data=b'{"topic":"orderbook.50.BTCUSDC","ts":1698936878583,"type":"delta","data":{"s":"BTCUSDC","b":[["34954.07","0.057217"],["34946.47","0.11446"],["34945.91","0.04271"],["34940.31","0.112505"],["34936.36","0.823804"],["34936.22","0.286235"],["34925","0"],["34939.12","0"],["34924.42","0"],["34923.58","0"],["34925.01","0"]],"a":[["34961.72","0.057205"],["34958.07","0"]],"u":20010744,"seq":14108048691}}'
2023-11-02 14:54:38,690 DEBUG ++Rcv raw: b'\x81~\x00\xfc{"topic":"orderbook.50.BTCUSDC","ts":1698936878603,"type":"delta","data":{"s":"BTCUSDC","b":[["34952.17","0.036"],["34950.85","0.028606"],["34927.27","0"],["34952.25","0"]],"a":[["34962.65","0.028606"],["34961.72","0"]],"u":20010745,"seq":14108048715}}'
2023-11-02 14:54:38,690 DEBUG ++Rcv decoded: fin=1 opcode=1 data=b'{"topic":"orderbook.50.BTCUSDC","ts":1698936878603,"type":"delta","data":{"s":"BTCUSDC","b":[["34952.17","0.036"],["34950.85","0.028606"],["34927.27","0"],["34952.25","0"]],"a":[["34962.65","0.028606"],["34961.72","0"]],"u":20010745,"seq":14108048715}}'
2023-11-02 14:54:38,729 DEBUG ++Rcv raw: b'\x81~\x00\x9c{"topic":"orderbook.50.BTCUSDC","ts":1698936878643,"type":"delta","data":{"s":"BTCUSDC","b":[],"a":[["34959.3","0.024694"]],"u":20010746,"seq":14108048737}}'
2023-11-02 14:54:38,729 DEBUG ++Rcv decoded: fin=1 opcode=1 data=b'{"topic":"orderbook.50.BTCUSDC","ts":1698936878643,"type":"delta","data":{"s":"BTCUSDC","b":[],"a":[["34959.3","0.024694"]],"u":20010746,"seq":14108048737}}'
2023-11-02 14:54:38,748 DEBUG ++Rcv raw: b'\x81~\x00\xcf{"topic":"orderbook.50.BTCUSDC","ts":1698936878663,"type":"delta","data":{"s":"BTCUSDC","b":[["34953.05","0.023226"],["34927.86","0"]],"a":[["34975","0.001"],["34969.7","0"]],"u":20010747,"seq":14108048752}}'
2023-11-02 14:54:38,749 DEBUG ++Rcv decoded: fin=1 opcode=1 data=b'{"topic":"orderbook.50.BTCUSDC","ts":1698936878663,"type":"delta","data":{"s":"BTCUSDC","b":[["34953.05","0.023226"],["34927.86","0"]],"a":[["34975","0.001"],["34969.7","0"]],"u":20010747,"seq":14108048752}}'
2023-11-02 14:54:38,789 DEBUG ++Rcv raw: b'\x81~\x01J{"topic":"orderbook.50.BTCUSDC","ts":1698936878703,"type":"delta","data":{"s":"BTCUSDC","b":[["34940.94","0.0859"],["34927.86","0.458086"],["34927.27","0.1875"],["34946.47","0"],["34936.22","0"],["34954.07","0"]],"a":[["34975.34","0.0859"],["34975.4","0.031411"],["34969.53","0"],["34969.23","0"]],"u":20010748,"seq":14108048775}}'
2023-11-02 14:54:38,789 DEBUG ++Rcv decoded: fin=1 opcode=1 data=b'{"topic":"orderbook.50.BTCUSDC","ts":1698936878703,"type":"delta","data":{"s":"BTCUSDC","b":[["34940.94","0.0859"],["34927.86","0.458086"],["34927.27","0.1875"],["34946.47","0"],["34936.22","0"],["34954.07","0"]],"a":[["34975.34","0.0859"],["34975.4","0.031411"],["34969.53","0"],["34969.23","0"]],"u":20010748,"seq":14108048775}}'
2023-11-02 14:54:38,809 DEBUG ++Rcv raw: b'\x81~\x01&{"topic":"orderbook.50.BTCUSDC","ts":1698936878724,"type":"delta","data":{"s":"BTCUSDC","b":[["34947.73","0.114456"],["34937.34","0.286226"],["34952.17","0"],["34927.27","0"]],"a":[["34958.05","0.03895"],["34970.62","0.114381"],["34975.34","0"],["34975.4","0"]],"u":20010749,"seq":14108048789}}'
2023-11-02 14:54:38,809 DEBUG ++Rcv decoded: fin=1 opcode=1 data=b'{"topic":"orderbook.50.BTCUSDC","ts":1698936878724,"type":"delta","data":{"s":"BTCUSDC","b":[["34947.73","0.114456"],["34937.34","0.286226"],["34952.17","0"],["34927.27","0"]],"a":[["34958.05","0.03895"],["34970.62","0.114381"],["34975.34","0"],["34975.4","0"]],"u":20010749,"seq":14108048789}}'
2023-11-02 14:54:38,829 DEBUG ++Rcv raw: b'\x81~\x03#{"topic":"orderbook.50.BTCUSDC","ts":1698936878743,"type":"delta","data":{"s":"BTCUSDC","b":[["34959.86","0.0859"],["34955.97","0.008756"],["34955.96","0.098944"],["34954.7","0.0859"],["34954","0.0324"],["34953.12","0.053806"],["34936.36","0"],["34931.31","0"],["34927.86","0"],["34935.91","0"],["34936.35","0"],["34927.87","0"]],"a":[["34975.34","0.0859"],["34975.4","0.031411"],["34975.67","0.1875"],["34975.89","0.050202"],["34976.12","0.043812"],["34976.59","0.049844"],["34977.05","0.051548"],["34977.06","0.0859"],["34978.28","0.279826"],["34978.9","0.002162"],["34980.2","0.1875"],["34961.57","0"],["34958.06","0"],["34963.29","0"],["34958.05","0"],["34965.02","0"],["34966.74","0"],["34961.58","0"],["34963.3","0"],["34959.3","0"],["34960","0"],["34966.38","0"]],"u":20010750,"seq":14108048940}}'
2023-11-02 14:54:38,829 DEBUG ++Rcv decoded: fin=1 opcode=1 data=b'{"topic":"orderbook.50.BTCUSDC","ts":1698936878743,"type":"delta","data":{"s":"BTCUSDC","b":[["34959.86","0.0859"],["34955.97","0.008756"],["34955.96","0.098944"],["34954.7","0.0859"],["34954","0.0324"],["34953.12","0.053806"],["34936.36","0"],["34931.31","0"],["34927.86","0"],["34935.91","0"],["34936.35","0"],["34927.87","0"]],"a":[["34975.34","0.0859"],["34975.4","0.031411"],["34975.67","0.1875"],["34975.89","0.050202"],["34976.12","0.043812"],["34976.59","0.049844"],["34977.05","0.051548"],["34977.06","0.0859"],["34978.28","0.279826"],["34978.9","0.002162"],["34980.2","0.1875"],["34961.57","0"],["34958.06","0"],["34963.29","0"],["34958.05","0"],["34965.02","0"],["34966.74","0"],["34961.58","0"],["34963.3","0"],["34959.3","0"],["34960","0"],["34966.38","0"]],"u":20010750,"seq":14108048940}}'
2023-11-02 14:54:38,850 DEBUG ++Rcv raw: b'\x81~\x01\xf1{"topic":"orderbook.50.BTCUSDC","ts":1698936878764,"type":"delta","data":{"s":"BTCUSDC","b":[["34958.14","0.0859"],["34955.97","0.033217"],["34953.13","0.032292"],["34951.27","0.05154"],["34936.36","0.823804"],["34936.35","0.1875"],["34935.91","1.373003"],["34959.86","0"],["34955.96","0"],["34950.01","0"],["34953.12","0"],["34950.85","0"],["34949.82","0"]],"a":[["34961.42","0.02327"],["34966.12","0.039883"],["34966.74","0.0859"],["34965.01","0"],["34962","0"]],"u":20010751,"seq":14108048999}}'
2023-11-02 14:54:38,850 DEBUG ++Rcv decoded: fin=1 opcode=1 data=b'{"topic":"orderbook.50.BTCUSDC","ts":1698936878764,"type":"delta","data":{"s":"BTCUSDC","b":[["34958.14","0.0859"],["34955.97","0.033217"],["34953.13","0.032292"],["34951.27","0.05154"],["34936.36","0.823804"],["34936.35","0.1875"],["34935.91","1.373003"],["34959.86","0"],["34955.96","0"],["34950.01","0"],["34953.12","0"],["34950.85","0"],["34949.82","0"]],"a":[["34961.42","0.02327"],["34966.12","0.039883"],["34966.74","0.0859"],["34965.01","0"],["34962","0"]],"u":20010751,"seq":14108048999}}'
2023-11-02 14:54:38,869 DEBUG ++Rcv raw: b'\x81~\x01\xb7{"topic":"orderbook.50.BTCUSDC","ts":1698936878784,"type":"delta","data":{"s":"BTCUSDC","b":[["34958.15","0.008756"],["34954.71","0.051542"],["34953.25","0.00057"],["34952.84","0.028605"],["34947.64","0.1875"],["34953.13","0"],["34940.32","0"],["34953.11","0"],["34935.91","0"],["34955.97","0"]],"a":[["34964.63","0.028605"],["34966.12","0.08644"],["34980.48","0.023472"],["34967.99","0"],["34962.65","0"]],"u":20010752,"seq":14108049031}}'
2023-11-02 14:54:38,869 DEBUG ++Rcv decoded: fin=1 opcode=1 data=b'{"topic":"orderbook.50.BTCUSDC","ts":1698936878784,"type":"delta","data":{"s":"BTCUSDC","b":[["34958.15","0.008756"],["34954.71","0.051542"],["34953.25","0.00057"],["34952.84","0.028605"],["34947.64","0.1875"],["34953.13","0"],["34940.32","0"],["34953.11","0"],["34935.91","0"],["34955.97","0"]],"a":[["34964.63","0.028605"],["34966.12","0.08644"],["34980.48","0.023472"],["34967.99","0"],["34962.65","0"]],"u":20010752,"seq":14108049031}}'
2023-11-02 14:54:38,889 DEBUG ++Rcv raw: b'\x81~\x00\xee{"topic":"orderbook.50.BTCUSDC","ts":1698936878804,"type":"delta","data":{"s":"BTCUSDC","b":[["34947.83","0.106061"]],"a":[["34980.96","0.285869"],["34981.28","0.000562"],["34969.86","0"],["34961.42","0"]],"u":20010753,"seq":14108049068}}'
2023-11-02 14:54:38,889 DEBUG ++Rcv decoded: fin=1 opcode=1 data=b'{"topic":"orderbook.50.BTCUSDC","ts":1698936878804,"type":"delta","data":{"s":"BTCUSDC","b":[["34947.83","0.106061"]],"a":[["34980.96","0.285869"],["34981.28","0.000562"],["34969.86","0"],["34961.42","0"]],"u":20010753,"seq":14108049068}}'
2023-11-02 14:54:38,910 DEBUG ++Rcv raw: b'\x81~\x01#{"topic":"orderbook.50.BTCUSDC","ts":1698936878824,"type":"delta","data":{"s":"BTCUSDC","b":[["34953.12","0.01144"],["34935.91","1.373003"],["34931.31","0.1875"],["34948.01","0"],["34947.73","0"],["34937.34","0"]],"a":[["34983.74","0.1875"],["34970.62","0"]],"u":20010754,"seq":14108049122}}'
2023-11-02 14:54:38,910 DEBUG ++Rcv decoded: fin=1 opcode=1 data=b'{"topic":"orderbook.50.BTCUSDC","ts":1698936878824,"type":"delta","data":{"s":"BTCUSDC","b":[["34953.12","0.01144"],["34935.91","1.373003"],["34931.31","0.1875"],["34948.01","0"],["34947.73","0"],["34937.34","0"]],"a":[["34983.74","0.1875"],["34970.62","0"]],"u":20010754,"seq":14108049122}}'
2023-11-02 14:54:38,929 DEBUG ++Rcv raw: b'\x81~\x01\xfa{"topic":"orderbook.50.BTCUSDC","ts":1698936878843,"type":"delta","data":{"s":"BTCUSDC","b":[["34955.8","0.057215"],["34951.28","0.003486"],["34948.93","0.114452"],["34938.49","0.286217"],["34948.02","0"],["34940.94","0"],["34931.31","0"],["34935.91","0"]],"a":[["34962.71","0.029303"],["34963.94","0.057201"],["34963.99","0.028229"],["34966.12","0.039883"],["34967.99","0.051546"],["34971.8","0.114377"],["34981.28","0"],["34961.15","0"],["34983.74","0"],["34980.96","0"]],"u":20010755,"seq":14108049150}}'
2023-11-02 14:54:38,929 DEBUG ++Rcv decoded: fin=1 opcode=1 data=b'{"topic":"orderbook.50.BTCUSDC","ts":1698936878843,"type":"delta","data":{"s":"BTCUSDC","b":[["34955.8","0.057215"],["34951.28","0.003486"],["34948.93","0.114452"],["34938.49","0.286217"],["34948.02","0"],["34940.94","0"],["34931.31","0"],["34935.91","0"]],"a":[["34962.71","0.029303"],["34963.94","0.057201"],["34963.99","0.028229"],["34966.12","0.039883"],["34967.99","0.051546"],["34971.8","0.114377"],["34981.28","0"],["34961.15","0"],["34983.74","0"],["34980.96","0"]],"u":20010755,"seq":14108049150}}'
2023-11-02 14:54:38,951 DEBUG ++Rcv raw: b'\x81~\x01w{"topic":"orderbook.50.BTCUSDC","ts":1698936878864,"type":"delta","data":{"s":"BTCUSDC","b":[["34958.17","0.008756"],["34955.81","0.034336"],["34953.06","0.051548"],["34949.58","0.369386"],["34955.8","0"],["34954.71","0"],["34958.15","0"],["34948.03","0"]],"a":[["34963.93","0.070932"],["34967.6","0.00057"],["34963.99","0"],["34963.94","0"]],"u":20010756,"seq":14108049193}}'
2023-11-02 14:54:38,951 DEBUG ++Rcv decoded: fin=1 opcode=1 data=b'{"topic":"orderbook.50.BTCUSDC","ts":1698936878864,"type":"delta","data":{"s":"BTCUSDC","b":[["34958.17","0.008756"],["34955.81","0.034336"],["34953.06","0.051548"],["34949.58","0.369386"],["34955.8","0"],["34954.71","0"],["34958.15","0"],["34948.03","0"]],"a":[["34963.93","0.070932"],["34967.6","0.00057"],["34963.99","0"],["34963.94","0"]],"u":20010756,"seq":14108049193}}'
2023-11-02 14:54:38,969 DEBUG ++Rcv raw: b'\x81~\x01\x87{"topic":"orderbook.50.BTCUSDC","ts":1698936878884,"type":"delta","data":{"s":"BTCUSDC","b":[["34958.16","0.003"],["34954.71","0.05154"],["34954.21","0.028604"],["34951.9","0.001"],["34949.45","0.036"],["34953.06","0"],["34952.84","0"],["34936.35","0"],["34949.57","0"],["34955.81","0"]],"a":[["34963.93","0.036604"],["34974.71","0.075313"],["34980.48","0"]],"u":20010757,"seq":14108049221}}'
2023-11-02 14:54:38,969 DEBUG ++Rcv decoded: fin=1 opcode=1 data=b'{"topic":"orderbook.50.BTCUSDC","ts":1698936878884,"type":"delta","data":{"s":"BTCUSDC","b":[["34958.16","0.003"],["34954.71","0.05154"],["34954.21","0.028604"],["34951.9","0.001"],["34949.45","0.036"],["34953.06","0"],["34952.84","0"],["34936.35","0"],["34949.57","0"],["34955.81","0"]],"a":[["34963.93","0.036604"],["34974.71","0.075313"],["34980.48","0"]],"u":20010757,"seq":14108049221}}'
2023-11-02 14:54:38,989 DEBUG ++Rcv raw: b'\x81~\x00\xc3{"topic":"orderbook.50.BTCUSDC","ts":1698936878904,"type":"delta","data":{"s":"BTCUSDC","b":[],"a":[["34966","0.061004"],["34980.48","0.023472"],["34964.63","0"]],"u":20010758,"seq":14108049231}}'
2023-11-02 14:54:38,989 DEBUG ++Rcv decoded: fin=1 opcode=1 data=b'{"topic":"orderbook.50.BTCUSDC","ts":1698936878904,"type":"delta","data":{"s":"BTCUSDC","b":[],"a":[["34966","0.061004"],["34980.48","0.023472"],["34964.63","0"]],"u":20010758,"seq":14108049231}}'
2023-11-02 14:54:39,012 DEBUG ++Rcv raw: b'\x81~\x01={"topic":"orderbook.50.BTCUSDC","ts":1698936878926,"type":"delta","data":{"s":"BTCUSDC","b":[["34949.59","0.221633"],["34936.35","0.1875"],["34953.12","0"],["34958.14","0"]],"a":[["34966.12","0.08644"],["34981.28","0.000562"],["34982.56","0.285856"],["34963.93","0"],["34967.99","0"]],"u":20010759,"seq":14108049255}}'
2023-11-02 14:54:39,012 DEBUG ++Rcv decoded: fin=1 opcode=1 data=b'{"topic":"orderbook.50.BTCUSDC","ts":1698936878926,"type":"delta","data":{"s":"BTCUSDC","b":[["34949.59","0.221633"],["34936.35","0.1875"],["34953.12","0"],["34958.14","0"]],"a":[["34966.12","0.08644"],["34981.28","0.000562"],["34982.56","0.285856"],["34963.93","0"],["34967.99","0"]],"u":20010759,"seq":14108049255}}'
2023-11-02 14:54:39,029 DEBUG ++Rcv raw: b'\x81~\x00\xf9{"topic":"orderbook.50.BTCUSDC","ts":1698936878943,"type":"delta","data":{"s":"BTCUSDC","b":[["34956.42","0.0859"],["34936.35","0"]],"a":[["34965.02","0.0859"],["34974.99","0.0005"],["34982.56","0"],["34981.28","0"]],"u":20010760,"seq":14108049276}}'
2023-11-02 14:54:39,029 DEBUG ++Rcv decoded: fin=1 opcode=1 data=b'{"topic":"orderbook.50.BTCUSDC","ts":1698936878943,"type":"delta","data":{"s":"BTCUSDC","b":[["34956.42","0.0859"],["34936.35","0"]],"a":[["34965.02","0.0859"],["34974.99","0.0005"],["34982.56","0"],["34981.28","0"]],"u":20010760,"seq":14108049276}}'
2023-11-02 14:54:39,048 DEBUG ++Rcv raw: b'\x81~\x01:{"topic":"orderbook.50.BTCUSDC","ts":1698936878963,"type":"delta","data":{"s":"BTCUSDC","b":[["34956","0.0324"],["34936.36","0"]],"a":[["34965.01","0.051544"],["34966.12","0.039883"],["34967.99","0.051545"],["34970.83","0.043104"],["34980.48","0"],["34980.2","0"],["34974.71","0"]],"u":20010761,"seq":14108049298}}'
2023-11-02 14:54:39,048 DEBUG ++Rcv decoded: fin=1 opcode=1 data=b'{"topic":"orderbook.50.BTCUSDC","ts":1698936878963,"type":"delta","data":{"s":"BTCUSDC","b":[["34956","0.0324"],["34936.36","0"]],"a":[["34965.01","0.051544"],["34966.12","0.039883"],["34967.99","0.051545"],["34970.83","0.043104"],["34980.48","0"],["34980.2","0"],["34974.71","0"]],"u":20010761,"seq":14108049298}}'
2023-11-02 14:54:39,068 DEBUG ++Rcv raw: b'\x81~\x00\xed{"topic":"orderbook.50.BTCUSDC","ts":1698936878983,"type":"delta","data":{"s":"BTCUSDC","b":[["34955.76","0.057215"],["34942.67","0.079544"],["34937.39","0"]],"a":[["34963.96","0.057201"],["34978.9","0"]],"u":20010762,"seq":14108049311}}'
2023-11-02 14:54:39,068 DEBUG ++Rcv decoded: fin=1 opcode=1 data=b'{"topic":"orderbook.50.BTCUSDC","ts":1698936878983,"type":"delta","data":{"s":"BTCUSDC","b":[["34955.76","0.057215"],["34942.67","0.079544"],["34937.39","0"]],"a":[["34963.96","0.057201"],["34978.9","0"]],"u":20010762,"seq":14108049311}}'
2023-11-02 14:54:39,109 DEBUG ++Rcv raw: b'\x81~\x00\xad{"topic":"orderbook.50.BTCUSDC","ts":1698936879023,"type":"delta","data":{"s":"BTCUSDC","b":[["34958.18","0.01144"],["34938.49","0"]],"a":[],"u":20010763,"seq":14108049324}}'
2023-11-02 14:54:39,109 DEBUG ++Rcv decoded: fin=1 opcode=1 data=b'{"topic":"orderbook.50.BTCUSDC","ts":1698936879023,"type":"delta","data":{"s":"BTCUSDC","b":[["34958.18","0.01144"],["34938.49","0"]],"a":[],"u":20010763,"seq":14108049324}}'
2023-11-02 14:54:39,129 DEBUG ++Rcv raw: b'\x81~\x00\xfc{"topic":"orderbook.50.BTCUSDC","ts":1698936879043,"type":"delta","data":{"s":"BTCUSDC","b":[],"a":[["34960.85","0.048709"],["34960.86","0.081173"],["34963.17","0.03"],["34977.06","0"],["34977.05","0"],["34978.28","0"]],"u":20010764,"seq":14108049329}}'
2023-11-02 14:54:39,129 DEBUG ++Rcv decoded: fin=1 opcode=1 data=b'{"topic":"orderbook.50.BTCUSDC","ts":1698936879043,"type":"delta","data":{"s":"BTCUSDC","b":[],"a":[["34960.85","0.048709"],["34960.86","0.081173"],["34963.17","0.03"],["34977.06","0"],["34977.05","0"],["34978.28","0"]],"u":20010764,"seq":14108049329}}'
2023-11-02 14:54:39,149 DEBUG ++Rcv raw: b'\x81~\x01"{"topic":"orderbook.50.BTCUSDC","ts":1698936879063,"type":"delta","data":{"s":"BTCUSDC","b":[["34952.43","0.036"],["34938.49","0.286217"],["34958.16","0"],["34953.25","0"]],"a":[["34977.05","0.051548"],["34977.06","0.0859"],["34960.86","0"],["34967.6","0"]],"u":20010765,"seq":14108049340}}'
2023-11-02 14:54:39,149 DEBUG ++Rcv decoded: fin=1 opcode=1 data=b'{"topic":"orderbook.50.BTCUSDC","ts":1698936879063,"type":"delta","data":{"s":"BTCUSDC","b":[["34952.43","0.036"],["34938.49","0.286217"],["34958.16","0"],["34953.25","0"]],"a":[["34977.05","0.051548"],["34977.06","0.0859"],["34960.86","0"],["34967.6","0"]],"u":20010765,"seq":14108049340}}'
2023-11-02 14:54:39,168 DEBUG ++Rcv raw: b'\x81~\x00\xad{"topic":"orderbook.50.BTCUSDC","ts":1698936879083,"type":"delta","data":{"s":"BTCUSDC","b":[],"a":[["34962.7","0.035588"],["34960.85","0"]],"u":20010766,"seq":14108049346}}'
2023-11-02 14:54:39,169 DEBUG ++Rcv decoded: fin=1 opcode=1 data=b'{"topic":"orderbook.50.BTCUSDC","ts":1698936879083,"type":"delta","data":{"s":"BTCUSDC","b":[],"a":[["34962.7","0.035588"],["34960.85","0"]],"u":20010766,"seq":14108049346}}'
2023-11-02 14:54:39,188 DEBUG ++Rcv raw: b'\x81~\x00\xd4{"topic":"orderbook.50.BTCUSDC","ts":1698936879103,"type":"delta","data":{"s":"BTCUSDC","b":[["34953.29","0.00057"],["34938.49","0"]],"a":[["34967.59","0.00057"],["34963.17","0"]],"u":20010767,"seq":14108049358}}'
2023-11-02 14:54:39,189 DEBUG ++Rcv decoded: fin=1 opcode=1 data=b'{"topic":"orderbook.50.BTCUSDC","ts":1698936879103,"type":"delta","data":{"s":"BTCUSDC","b":[["34953.29","0.00057"],["34938.49","0"]],"a":[["34967.59","0.00057"],["34963.17","0"]],"u":20010767,"seq":14108049358}}'
2023-11-02 14:54:39,209 DEBUG ++Rcv raw: b'\x81~\x01#{"topic":"orderbook.50.BTCUSDC","ts":1698936879124,"type":"delta","data":{"s":"BTCUSDC","b":[["34938.49","0.286217"],["34958.17","0"]],"a":[["34978.28","0.279826"],["34978.9","0.002162"],["34980.08","0.001"],["34973.99","0"],["34976.59","0"],["34962.7","0"]],"u":20010768,"seq":14108049370}}'
2023-11-02 14:54:39,209 DEBUG ++Rcv decoded: fin=1 opcode=1 data=b'{"topic":"orderbook.50.BTCUSDC","ts":1698936879124,"type":"delta","data":{"s":"BTCUSDC","b":[["34938.49","0.286217"],["34958.17","0"]],"a":[["34978.28","0.279826"],["34978.9","0.002162"],["34980.08","0.001"],["34973.99","0"],["34976.59","0"],["34962.7","0"]],"u":20010768,"seq":14108049370}}'
2023-11-02 14:54:39,270 DEBUG ++Rcv raw: b'\x81~\x00\xae{"topic":"orderbook.50.BTCUSDC","ts":1698936879184,"type":"delta","data":{"s":"BTCUSDC","b":[["34958.19","0.008756"],["34938.49","0"]],"a":[],"u":20010769,"seq":14108049403}}'
2023-11-02 14:54:39,270 DEBUG ++Rcv decoded: fin=1 opcode=1 data=b'{"topic":"orderbook.50.BTCUSDC","ts":1698936879184,"type":"delta","data":{"s":"BTCUSDC","b":[["34958.19","0.008756"],["34938.49","0"]],"a":[],"u":20010769,"seq":14108049403}}'
2023-11-02 14:54:39,293 DEBUG ++Rcv raw: b'\x81~\x00\xae{"topic":"orderbook.50.BTCUSDC","ts":1698936879204,"type":"delta","data":{"s":"BTCUSDC","b":[["34939.34","0.105001"],["34939.11","0"]],"a":[],"u":20010770,"seq":14108049413}}'
2023-11-02 14:54:39,293 DEBUG ++Rcv decoded: fin=1 opcode=1 data=b'{"topic":"orderbook.50.BTCUSDC","ts":1698936879204,"type":"delta","data":{"s":"BTCUSDC","b":[["34939.34","0.105001"],["34939.11","0"]],"a":[],"u":20010770,"seq":14108049413}}'
2023-11-02 14:54:39,329 DEBUG ++Rcv raw: b'\x81~\x00\xfe{"topic":"orderbook.50.BTCUSDC","ts":1698936879244,"type":"delta","data":{"s":"BTCUSDC","b":[["34950.01","0.00263"],["34947.63","0.000261"],["34939.85","0"],["34939.34","0"]],"a":[["34971.31","0.000239"],["34980.08","0"]],"u":20010771,"seq":14108049428}}'
2023-11-02 14:54:39,329 DEBUG ++Rcv decoded: fin=1 opcode=1 data=b'{"topic":"orderbook.50.BTCUSDC","ts":1698936879244,"type":"delta","data":{"s":"BTCUSDC","b":[["34950.01","0.00263"],["34947.63","0.000261"],["34939.85","0"],["34939.34","0"]],"a":[["34971.31","0.000239"],["34980.08","0"]],"u":20010771,"seq":14108049428}}'
2023-11-02 14:54:39,370 DEBUG ++Rcv raw: b'\x81~\x00\xac{"topic":"orderbook.50.BTCUSDC","ts":1698936879284,"type":"delta","data":{"s":"BTCUSDC","b":[["34939.85","0.1875"],["34951.28","0"]],"a":[],"u":20010772,"seq":14108049443}}'
2023-11-02 14:54:39,370 DEBUG ++Rcv decoded: fin=1 opcode=1 data=b'{"topic":"orderbook.50.BTCUSDC","ts":1698936879284,"type":"delta","data":{"s":"BTCUSDC","b":[["34939.85","0.1875"],["34951.28","0"]],"a":[],"u":20010772,"seq":14108049443}}'
2023-11-02 14:54:39,409 DEBUG ++Rcv raw: b'\x81~\x00\xac{"topic":"orderbook.50.BTCUSDC","ts":1698936879324,"type":"delta","data":{"s":"BTCUSDC","b":[],"a":[["34961.45","0.08795"],["34978.9","0"]],"u":20010773,"seq":14108049463}}'
2023-11-02 14:54:39,409 DEBUG ++Rcv decoded: fin=1 opcode=1 data=b'{"topic":"orderbook.50.BTCUSDC","ts":1698936879324,"type":"delta","data":{"s":"BTCUSDC","b":[],"a":[["34961.45","0.08795"],["34978.9","0"]],"u":20010773,"seq":14108049463}}'
2023-11-02 14:54:39,429 DEBUG ++Rcv raw: b'\x81~\x00\xc5{"topic":"orderbook.50.BTCUSDC","ts":1698936879344,"type":"delta","data":{"s":"BTCUSDC","b":[["34939.76","0.029858"],["34947.64","0"]],"a":[["34962.71","0.055381"]],"u":20010774,"seq":14108049473}}'
2023-11-02 14:54:39,429 DEBUG ++Rcv decoded: fin=1 opcode=1 data=b'{"topic":"orderbook.50.BTCUSDC","ts":1698936879344,"type":"delta","data":{"s":"BTCUSDC","b":[["34939.76","0.029858"],["34947.64","0"]],"a":[["34962.71","0.055381"]],"u":20010774,"seq":14108049473}}'
2023-11-02 14:54:39,449 DEBUG ++Rcv raw: b'\x81~\x00\xed{"topic":"orderbook.50.BTCUSDC","ts":1698936879364,"type":"delta","data":{"s":"BTCUSDC","b":[["34947.83","0.05154"],["34939.34","0.105001"],["34958.18","0"]],"a":[["34961.44","0.052779"],["34961.45","0"]],"u":20010775,"seq":14108049484}}'
2023-11-02 14:54:39,449 DEBUG ++Rcv decoded: fin=1 opcode=1 data=b'{"topic":"orderbook.50.BTCUSDC","ts":1698936879364,"type":"delta","data":{"s":"BTCUSDC","b":[["34947.83","0.05154"],["34939.34","0.105001"],["34958.18","0"]],"a":[["34961.44","0.052779"],["34961.45","0"]],"u":20010775,"seq":14108049484}}'
2023-11-02 14:54:39,469 DEBUG ++Rcv raw: b'\x81~\x00\xfe{"topic":"orderbook.50.BTCUSDC","ts":1698936879384,"type":"delta","data":{"s":"BTCUSDC","b":[["34947.65","0.000261"],["34939.34","0"]],"a":[["34962.7","0.033228"],["34971.24","0.000239"],["34978.28","0"],["34961.44","0"]],"u":20010776,"seq":14108049495}}'
2023-11-02 14:54:39,469 DEBUG ++Rcv decoded: fin=1 opcode=1 data=b'{"topic":"orderbook.50.BTCUSDC","ts":1698936879384,"type":"delta","data":{"s":"BTCUSDC","b":[["34947.65","0.000261"],["34939.34","0"]],"a":[["34962.7","0.033228"],["34971.24","0.000239"],["34978.28","0"],["34961.44","0"]],"u":20010776,"seq":14108049495}}'
2023-11-02 14:54:39,490 DEBUG ++Rcv raw: b'\x81~\x00\x9d{"topic":"orderbook.50.BTCUSDC","ts":1698936879404,"type":"delta","data":{"s":"BTCUSDC","b":[["34958.19","0.011756"]],"a":[],"u":20010777,"seq":14108049502}}'
2023-11-02 14:54:39,490 DEBUG ++Rcv decoded: fin=1 opcode=1 data=b'{"topic":"orderbook.50.BTCUSDC","ts":1698936879404,"type":"delta","data":{"s":"BTCUSDC","b":[["34958.19","0.011756"]],"a":[],"u":20010777,"seq":14108049502}}'
2023-11-02 14:54:39,613 DEBUG ++Rcv raw: b'\x81~\x00\xac{"topic":"orderbook.50.BTCUSDC","ts":1698936879523,"type":"delta","data":{"s":"BTCUSDC","b":[["34947.69","0.1875"],["34939.76","0"]],"a":[],"u":20010778,"seq":14108049543}}'
2023-11-02 14:54:39,614 DEBUG ++Rcv decoded: fin=1 opcode=1 data=b'{"topic":"orderbook.50.BTCUSDC","ts":1698936879523,"type":"delta","data":{"s":"BTCUSDC","b":[["34947.69","0.1875"],["34939.76","0"]],"a":[],"u":20010778,"seq":14108049543}}'
2023-11-02 14:54:39,649 DEBUG ++Rcv raw: b'\x81~\x00\xd6{"topic":"orderbook.50.BTCUSDC","ts":1698936879564,"type":"delta","data":{"s":"BTCUSDC","b":[["34939.76","0.029858"],["34947.63","0"]],"a":[["34978.28","0.279826"],["34971.31","0"]],"u":20010779,"seq":14108049553}}'
2023-11-02 14:54:39,649 DEBUG ++Rcv decoded: fin=1 opcode=1 data=b'{"topic":"orderbook.50.BTCUSDC","ts":1698936879564,"type":"delta","data":{"s":"BTCUSDC","b":[["34939.76","0.029858"],["34947.63","0"]],"a":[["34978.28","0.279826"],["34971.31","0"]],"u":20010779,"seq":14108049553}}'
2023-11-02 14:54:39,709 DEBUG ++Rcv raw: b'\x81~\x00\xac{"topic":"orderbook.50.BTCUSDC","ts":1698936879624,"type":"delta","data":{"s":"BTCUSDC","b":[["34958.2","0.01144"],["34939.76","0"]],"a":[],"u":20010780,"seq":14108049557}}'
2023-11-02 14:54:39,710 DEBUG ++Rcv decoded: fin=1 opcode=1 data=b'{"topic":"orderbook.50.BTCUSDC","ts":1698936879624,"type":"delta","data":{"s":"BTCUSDC","b":[["34958.2","0.01144"],["34939.76","0"]],"a":[],"u":20010780,"seq":14108049557}}'
2023-11-02 14:54:39,729 DEBUG ++Rcv raw: b'\x81~\x01\x17{"topic":"orderbook.50.BTCUSDC","ts":1698936879644,"type":"delta","data":{"s":"BTCUSDC","b":[["34958.19","0.008756"],["34939.76","0.029858"],["34947.69","0"]],"a":[["34960.41","0.046181"],["34960.42","0.076968"],["34977.06","0"],["34978.28","0"]],"u":20010781,"seq":14108049562}}'
2023-11-02 14:54:39,729 DEBUG ++Rcv decoded: fin=1 opcode=1 data=b'{"topic":"orderbook.50.BTCUSDC","ts":1698936879644,"type":"delta","data":{"s":"BTCUSDC","b":[["34958.19","0.008756"],["34939.76","0.029858"],["34947.69","0"]],"a":[["34960.41","0.046181"],["34960.42","0.076968"],["34977.06","0"],["34978.28","0"]],"u":20010781,"seq":14108049562}}'
2023-11-02 14:54:39,749 DEBUG ++Rcv raw: b'\x81~\x01${"topic":"orderbook.50.BTCUSDC","ts":1698936879664,"type":"delta","data":{"s":"BTCUSDC","b":[["34939.34","0.105001"],["34953.29","0"]],"a":[["34977.06","0.0859"],["34978.28","0.279826"],["34978.9","0.002162"],["34962.7","0"],["34967.59","0"],["34960.42","0"]],"u":20010782,"seq":14108049569}}'
2023-11-02 14:54:39,750 DEBUG ++Rcv decoded: fin=1 opcode=1 data=b'{"topic":"orderbook.50.BTCUSDC","ts":1698936879664,"type":"delta","data":{"s":"BTCUSDC","b":[["34939.34","0.105001"],["34953.29","0"]],"a":[["34977.06","0.0859"],["34978.28","0.279826"],["34978.9","0.002162"],["34962.7","0"],["34967.59","0"],["34960.42","0"]],"u":20010782,"seq":14108049569}}'
2023-11-02 14:54:39,770 DEBUG ++Rcv raw: b'\x81~\x00\xf7{"topic":"orderbook.50.BTCUSDC","ts":1698936879684,"type":"delta","data":{"s":"BTCUSDC","b":[["34947.7","0.1875"],["34958.19","0"]],"a":[["34962.7","0.03323"],["34980.2","0.1875"],["34960.41","0"],["34974.99","0"]],"u":20010783,"seq":14108049577}}'
2023-11-02 14:54:39,770 DEBUG ++Rcv decoded: fin=1 opcode=1 data=b'{"topic":"orderbook.50.BTCUSDC","ts":1698936879684,"type":"delta","data":{"s":"BTCUSDC","b":[["34947.7","0.1875"],["34958.19","0"]],"a":[["34962.7","0.03323"],["34980.2","0.1875"],["34960.41","0"],["34974.99","0"]],"u":20010783,"seq":14108049577}}'
2023-11-02 14:54:39,790 DEBUG ++Rcv raw: b'\x81~\x00\xd3{"topic":"orderbook.50.BTCUSDC","ts":1698936879704,"type":"delta","data":{"s":"BTCUSDC","b":[["34953.31","0.00057"],["34939.34","0"]],"a":[["34967.59","0.00057"],["34980.2","0"]],"u":20010784,"seq":14108049580}}'
2023-11-02 14:54:39,790 DEBUG ++Rcv decoded: fin=1 opcode=1 data=b'{"topic":"orderbook.50.BTCUSDC","ts":1698936879704,"type":"delta","data":{"s":"BTCUSDC","b":[["34953.31","0.00057"],["34939.34","0"]],"a":[["34967.59","0.00057"],["34980.2","0"]],"u":20010784,"seq":14108049580}}'
2023-11-02 14:54:39,809 DEBUG ++Rcv raw: b'\x81~\x00\x9d{"topic":"orderbook.50.BTCUSDC","ts":1698936879723,"type":"delta","data":{"s":"BTCUSDC","b":[["34942.67","0.051544"]],"a":[],"u":20010785,"seq":14108049584}}'
2023-11-02 14:54:39,810 DEBUG ++Rcv decoded: fin=1 opcode=1 data=b'{"topic":"orderbook.50.BTCUSDC","ts":1698936879723,"type":"delta","data":{"s":"BTCUSDC","b":[["34942.67","0.051544"]],"a":[],"u":20010785,"seq":14108049584}}'
2023-11-02 14:54:39,870 DEBUG ++Rcv raw: b'\x81~\x00\xfb{"topic":"orderbook.50.BTCUSDC","ts":1698936879784,"type":"delta","data":{"s":"BTCUSDC","b":[["34939.34","0.105001"],["34939.11","0.057242"],["34958.2","0"],["34945.91","0"]],"a":[["34980.2","0.1875"],["34971.24","0"]],"u":20010786,"seq":14108049595}}'
2023-11-02 14:54:39,870 DEBUG ++Rcv decoded: fin=1 opcode=1 data=b'{"topic":"orderbook.50.BTCUSDC","ts":1698936879784,"type":"delta","data":{"s":"BTCUSDC","b":[["34939.34","0.105001"],["34939.11","0.057242"],["34958.2","0"],["34945.91","0"]],"a":[["34980.2","0.1875"],["34971.24","0"]],"u":20010786,"seq":14108049595}}'
2023-11-02 14:54:39,889 DEBUG ++Rcv raw: b'\x81~\x01${"topic":"orderbook.50.BTCUSDC","ts":1698936879804,"type":"delta","data":{"s":"BTCUSDC","b":[["34956.43","0.008756"],["34938.49","0.286217"],["34953.31","0"],["34947.7","0"]],"a":[["34962.68","0.056601"],["34962.69","0.03895"],["34962.7","0"],["34980.2","0"]],"u":20010787,"seq":14108049609}}'
2023-11-02 14:54:39,890 DEBUG ++Rcv decoded: fin=1 opcode=1 data=b'{"topic":"orderbook.50.BTCUSDC","ts":1698936879804,"type":"delta","data":{"s":"BTCUSDC","b":[["34956.43","0.008756"],["34938.49","0.286217"],["34953.31","0"],["34947.7","0"]],"a":[["34962.68","0.056601"],["34962.69","0.03895"],["34962.7","0"],["34980.2","0"]],"u":20010787,"seq":14108049609}}'
2023-11-02 14:54:39,909 DEBUG ++Rcv raw: b'\x81~\x00\xd2{"topic":"orderbook.50.BTCUSDC","ts":1698936879824,"type":"delta","data":{"s":"BTCUSDC","b":[["34951.54","0.00057"],["34938.49","0"]],"a":[["34980.2","0.1875"],["34962.69","0"]],"u":20010788,"seq":14108049613}}'
2023-11-02 14:54:39,909 DEBUG ++Rcv decoded: fin=1 opcode=1 data=b'{"topic":"orderbook.50.BTCUSDC","ts":1698936879824,"type":"delta","data":{"s":"BTCUSDC","b":[["34951.54","0.00057"],["34938.49","0"]],"a":[["34980.2","0.1875"],["34962.69","0"]],"u":20010788,"seq":14108049613}}'
2023-11-02 14:54:39,929 DEBUG ++Rcv raw: b'\x81~\x00\x9d{"topic":"orderbook.50.BTCUSDC","ts":1698936879843,"type":"delta","data":{"s":"BTCUSDC","b":[],"a":[["34962.68","0.033232"]],"u":20010789,"seq":14108049623}}'
2023-11-02 14:54:39,929 DEBUG ++Rcv decoded: fin=1 opcode=1 data=b'{"topic":"orderbook.50.BTCUSDC","ts":1698936879843,"type":"delta","data":{"s":"BTCUSDC","b":[],"a":[["34962.68","0.033232"]],"u":20010789,"seq":14108049623}}'
2023-11-02 14:54:39,949 DEBUG ++Rcv raw: b'\x81~\x01+{"topic":"orderbook.50.BTCUSDC","ts":1698936879863,"type":"delta","data":{"s":"BTCUSDC","b":[["34958.84","0.095365"],["34956.43","0.11407"],["34949.43","0.1875"],["34939.34","0"],["34939.11","0"]],"a":[["34962.34","0.08154"],["34962.71","0.029303"],["34962.68","0"]],"u":20010790,"seq":14108049699}}'
2023-11-02 14:54:39,949 DEBUG ++Rcv decoded: fin=1 opcode=1 data=b'{"topic":"orderbook.50.BTCUSDC","ts":1698936879863,"type":"delta","data":{"s":"BTCUSDC","b":[["34958.84","0.095365"],["34956.43","0.11407"],["34949.43","0.1875"],["34939.34","0"],["34939.11","0"]],"a":[["34962.34","0.08154"],["34962.71","0.029303"],["34962.68","0"]],"u":20010790,"seq":14108049699}}'
2023-11-02 14:54:39,969 DEBUG ++Rcv raw: b'\x81~\x01\xb9{"topic":"orderbook.50.BTCUSDC","ts":1698936879883,"type":"delta","data":{"s":"BTCUSDC","b":[["34958.85","0.008756"],["34958.14","0.0859"],["34956.43","0.116754"],["34953.06","0.051547"],["34939.34","0.105001"],["34954.71","0"],["34951.54","0"],["34949.45","0"],["34958.84","0"]],"a":[["34962.33","0.066511"],["34980.48","0.023472"],["34981.28","0.000562"],["34965.02","0"],["34962.34","0"],["34962.71","0"]],"u":20010791,"seq":14108049761}}'
2023-11-02 14:54:39,969 DEBUG ++Rcv decoded: fin=1 opcode=1 data=b'{"topic":"orderbook.50.BTCUSDC","ts":1698936879883,"type":"delta","data":{"s":"BTCUSDC","b":[["34958.85","0.008756"],["34958.14","0.0859"],["34956.43","0.116754"],["34953.06","0.051547"],["34939.34","0.105001"],["34954.71","0"],["34951.54","0"],["34949.45","0"],["34958.84","0"]],"a":[["34962.33","0.066511"],["34980.48","0.023472"],["34981.28","0.000562"],["34965.02","0"],["34962.34","0"],["34962.71","0"]],"u":20010791,"seq":14108049761}}'
2023-11-02 14:54:39,989 DEBUG ++Rcv raw: b'\x81~\x01<{"topic":"orderbook.50.BTCUSDC","ts":1698936879904,"type":"delta","data":{"s":"BTCUSDC","b":[["34958.84","0.003"],["34953.96","0.00057"],["34939.34","0"],["34939.76","0"]],"a":[["34963.95","0.053768"],["34974.49","0.853667"],["34976.26","0.075313"],["34962.33","0"],["34965.01","0"]],"u":20010792,"seq":14108049785}}'
2023-11-02 14:54:39,990 DEBUG ++Rcv decoded: fin=1 opcode=1 data=b'{"topic":"orderbook.50.BTCUSDC","ts":1698936879904,"type":"delta","data":{"s":"BTCUSDC","b":[["34958.84","0.003"],["34953.96","0.00057"],["34939.34","0"],["34939.76","0"]],"a":[["34963.95","0.053768"],["34974.49","0.853667"],["34976.26","0.075313"],["34962.33","0"],["34965.01","0"]],"u":20010792,"seq":14108049785}}'
2023-11-02 14:54:40,009 DEBUG ++Rcv raw: b'\x81~\x01\x13{"topic":"orderbook.50.BTCUSDC","ts":1698936879924,"type":"delta","data":{"s":"BTCUSDC","b":[["34956.43","0.01144"],["34954.71","0.068711"],["34945.86","0.042731"],["34943.6","0.028"],["34939.85","0"],["34958.84","0"],["34953.06","0"]],"a":[],"u":20010793,"seq":14108049831}}'
2023-11-02 14:54:40,009 DEBUG ++Rcv decoded: fin=1 opcode=1 data=b'{"topic":"orderbook.50.BTCUSDC","ts":1698936879924,"type":"delta","data":{"s":"BTCUSDC","b":[["34956.43","0.01144"],["34954.71","0.068711"],["34945.86","0.042731"],["34943.6","0.028"],["34939.85","0"],["34958.84","0"],["34953.06","0"]],"a":[],"u":20010793,"seq":14108049831}}'
2023-11-02 14:54:40,049 DEBUG ++Rcv raw: b'\x81~\x00\xac{"topic":"orderbook.50.BTCUSDC","ts":1698936879964,"type":"delta","data":{"s":"BTCUSDC","b":[["34939.85","0.1875"],["34947.65","0"]],"a":[],"u":20010794,"seq":14108049884}}'
2023-11-02 14:54:40,050 DEBUG ++Rcv decoded: fin=1 opcode=1 data=b'{"topic":"orderbook.50.BTCUSDC","ts":1698936879964,"type":"delta","data":{"s":"BTCUSDC","b":[["34939.85","0.1875"],["34947.65","0"]],"a":[],"u":20010794,"seq":14108049884}}'
2023-11-02 14:54:40,069 DEBUG ++Rcv raw: b'\x81~\x00\xd6{"topic":"orderbook.50.BTCUSDC","ts":1698936879984,"type":"delta","data":{"s":"BTCUSDC","b":[["34939.76","0.029858"],["34956.43","0"]],"a":[["34974.99","0.028662"],["34981.28","0"]],"u":20010795,"seq":14108049916}}'
2023-11-02 14:54:40,070 DEBUG ++Rcv decoded: fin=1 opcode=1 data=b'{"topic":"orderbook.50.BTCUSDC","ts":1698936879984,"type":"delta","data":{"s":"BTCUSDC","b":[["34939.76","0.029858"],["34956.43","0"]],"a":[["34974.99","0.028662"],["34981.28","0"]],"u":20010795,"seq":14108049916}}'
2023-11-02 14:54:40,129 DEBUG ++Rcv raw: b'\x81~\x00\xae{"topic":"orderbook.50.BTCUSDC","ts":1698936880043,"type":"delta","data":{"s":"BTCUSDC","b":[["34939.34","0.105001"],["34944.68","0"]],"a":[],"u":20010796,"seq":14108049948}}'
2023-11-02 14:54:40,129 DEBUG ++Rcv decoded: fin=1 opcode=1 data=b'{"topic":"orderbook.50.BTCUSDC","ts":1698936880043,"type":"delta","data":{"s":"BTCUSDC","b":[["34939.34","0.105001"],["34944.68","0"]],"a":[],"u":20010796,"seq":14108049948}}'
2023-11-02 14:54:40,151 DEBUG ++Rcv raw: b'\x81~\x01%{"topic":"orderbook.50.BTCUSDC","ts":1698936880064,"type":"delta","data":{"s":"BTCUSDC","b":[["34958.86","0.01144"],["34956.28","0.057214"],["34939.57","0.286208"],["34945.24","0"],["34955.76","0"],["34949.43","0"]],"a":[["34963.94","0.0286"],["34980.48","0"]],"u":20010797,"seq":14108049982}}'
2023-11-02 14:54:40,151 DEBUG ++Rcv decoded: fin=1 opcode=1 data=b'{"topic":"orderbook.50.BTCUSDC","ts":1698936880064,"type":"delta","data":{"s":"BTCUSDC","b":[["34958.86","0.01144"],["34956.28","0.057214"],["34939.57","0.286208"],["34945.24","0"],["34955.76","0"],["34949.43","0"]],"a":[["34963.94","0.0286"],["34980.48","0"]],"u":20010797,"seq":14108049982}}'
2023-11-02 14:54:40,169 DEBUG ++Rcv raw: b'\x81~\x01>{"topic":"orderbook.50.BTCUSDC","ts":1698936880084,"type":"delta","data":{"s":"BTCUSDC","b":[["34939.86","0.171724"],["34939.11","0.057242"],["34940.31","0"],["34949.58","0"]],"a":[["34963.93","0.088924"],["34963.94","0.0586"],["34980.48","0.023472"],["34963.95","0"],["34976.26","0"]],"u":20010798,"seq":14108050024}}'
2023-11-02 14:54:40,169 DEBUG ++Rcv decoded: fin=1 opcode=1 data=b'{"topic":"orderbook.50.BTCUSDC","ts":1698936880084,"type":"delta","data":{"s":"BTCUSDC","b":[["34939.86","0.171724"],["34939.11","0.057242"],["34940.31","0"],["34949.58","0"]],"a":[["34963.93","0.088924"],["34963.94","0.0586"],["34980.48","0.023472"],["34963.95","0"],["34976.26","0"]],"u":20010798,"seq":14108050024}}'
2023-11-02 14:54:40,189 DEBUG ++Rcv raw: b'\x81~\x01:{"topic":"orderbook.50.BTCUSDC","ts":1698936880103,"type":"delta","data":{"s":"BTCUSDC","b":[["34949.59","0.068676"],["34937.39","0.278379"],["34958.14","0"]],"a":[["34960.32","0.045179"],["34960.33","0.075288"],["34963.92","0.03"],["34980.48","0"],["34978.9","0"],["34980.2","0"]],"u":20010799,"seq":14108050040}}'
2023-11-02 14:54:40,189 DEBUG ++Rcv decoded: fin=1 opcode=1 data=b'{"topic":"orderbook.50.BTCUSDC","ts":1698936880103,"type":"delta","data":{"s":"BTCUSDC","b":[["34949.59","0.068676"],["34937.39","0.278379"],["34958.14","0"]],"a":[["34960.32","0.045179"],["34960.33","0.075288"],["34963.92","0.03"],["34980.48","0"],["34978.9","0"],["34980.2","0"]],"u":20010799,"seq":14108050040}}'
2023-11-02 14:54:40,209 DEBUG ++Rcv raw: b'\x81~\x01J{"topic":"orderbook.50.BTCUSDC","ts":1698936880123,"type":"delta","data":{"s":"BTCUSDC","b":[["34948.94","0.357877"],["34953.96","0"]],"a":[["34965.02","0.0859"],["34978.9","0.002162"],["34980.2","0.1875"],["34980.48","0.023472"],["34967.59","0"],["34960.33","0"],["34963.93","0"],["34975.4","0"]],"u":20010800,"seq":14108050064}}'
2023-11-02 14:54:40,209 DEBUG ++Rcv decoded: fin=1 opcode=1 data=b'{"topic":"orderbook.50.BTCUSDC","ts":1698936880123,"type":"delta","data":{"s":"BTCUSDC","b":[["34948.94","0.357877"],["34953.96","0"]],"a":[["34965.02","0.0859"],["34978.9","0.002162"],["34980.2","0.1875"],["34980.48","0.023472"],["34967.59","0"],["34960.33","0"],["34963.93","0"],["34975.4","0"]],"u":20010800,"seq":14108050064}}'
2023-11-02 14:54:40,228 DEBUG ++Rcv raw: b'\x81~\x00\xd8{"topic":"orderbook.50.BTCUSDC","ts":1698936880143,"type":"delta","data":{"s":"BTCUSDC","b":[["34949.59","0.20615"]],"a":[["34963.91","0.106929"],["34963.94","0.03"],["34960.32","0"]],"u":20010801,"seq":14108050080}}'
2023-11-02 14:54:40,229 DEBUG ++Rcv decoded: fin=1 opcode=1 data=b'{"topic":"orderbook.50.BTCUSDC","ts":1698936880143,"type":"delta","data":{"s":"BTCUSDC","b":[["34949.59","0.20615"]],"a":[["34963.91","0.106929"],["34963.94","0.03"],["34960.32","0"]],"u":20010801,"seq":14108050080}}'
2023-11-02 14:54:40,250 DEBUG ++Rcv raw: b'\x81~\x01\x1e{"topic":"orderbook.50.BTCUSDC","ts":1698936880164,"type":"delta","data":{"s":"BTCUSDC","b":[["34953.97","0.00057"],["34948.36","0.1875"],["34939.11","0"],["34937.39","0"]],"a":[["34963.9","0.03"],["34968.8","0.00057"],["34980.48","0"],["34963.92","0"]],"u":20010802,"seq":14108050089}}'
2023-11-02 14:54:40,251 DEBUG ++Rcv decoded: fin=1 opcode=1 data=b'{"topic":"orderbook.50.BTCUSDC","ts":1698936880164,"type":"delta","data":{"s":"BTCUSDC","b":[["34953.97","0.00057"],["34948.36","0.1875"],["34939.11","0"],["34937.39","0"]],"a":[["34963.9","0.03"],["34968.8","0.00057"],["34980.48","0"],["34963.92","0"]],"u":20010802,"seq":14108050089}}'
2023-11-02 14:54:40,269 DEBUG ++Rcv raw: b'\x81~\x00\xd5{"topic":"orderbook.50.BTCUSDC","ts":1698936880184,"type":"delta","data":{"s":"BTCUSDC","b":[],"a":[["34963.89","0.08976"],["34980.48","0.023472"],["34963.9","0"],["34963.91","0"]],"u":20010803,"seq":14108050097}}'
2023-11-02 14:54:40,269 DEBUG ++Rcv decoded: fin=1 opcode=1 data=b'{"topic":"orderbook.50.BTCUSDC","ts":1698936880184,"type":"delta","data":{"s":"BTCUSDC","b":[],"a":[["34963.89","0.08976"],["34980.48","0.023472"],["34963.9","0"],["34963.91","0"]],"u":20010803,"seq":14108050097}}'
2023-11-02 14:54:40,289 DEBUG ++Rcv raw: b'\x81~\x00\xaa{"topic":"orderbook.50.BTCUSDC","ts":1698936880204,"type":"delta","data":{"s":"BTCUSDC","b":[],"a":[["34963.88","0.03"],["34980.48","0"]],"u":20010804,"seq":14108050099}}'
2023-11-02 14:54:40,290 DEBUG ++Rcv decoded: fin=1 opcode=1 data=b'{"topic":"orderbook.50.BTCUSDC","ts":1698936880204,"type":"delta","data":{"s":"BTCUSDC","b":[],"a":[["34963.88","0.03"],["34980.48","0"]],"u":20010804,"seq":14108050099}}'
2023-11-02 14:54:40,309 DEBUG ++Rcv raw: b'\x81~\x00\xae{"topic":"orderbook.50.BTCUSDC","ts":1698936880224,"type":"delta","data":{"s":"BTCUSDC","b":[],"a":[["34980.48","0.023472"],["34963.88","0"]],"u":20010805,"seq":14108050109}}'
2023-11-02 14:54:40,309 DEBUG ++Rcv decoded: fin=1 opcode=1 data=b'{"topic":"orderbook.50.BTCUSDC","ts":1698936880224,"type":"delta","data":{"s":"BTCUSDC","b":[],"a":[["34980.48","0.023472"],["34963.88","0"]],"u":20010805,"seq":14108050109}}'
2023-11-02 14:54:40,329 DEBUG ++Rcv raw: b'\x81~\x00\xab{"topic":"orderbook.50.BTCUSDC","ts":1698936880244,"type":"delta","data":{"s":"BTCUSDC","b":[],"a":[["34963.9","0.0286"],["34980.48","0"]],"u":20010806,"seq":14108050127}}'
2023-11-02 14:54:40,330 DEBUG ++Rcv decoded: fin=1 opcode=1 data=b'{"topic":"orderbook.50.BTCUSDC","ts":1698936880244,"type":"delta","data":{"s":"BTCUSDC","b":[],"a":[["34963.9","0.0286"],["34980.48","0"]],"u":20010806,"seq":14108050127}}'
2023-11-02 14:54:40,369 DEBUG ++Rcv raw: b'\x81~\x00\xd5{"topic":"orderbook.50.BTCUSDC","ts":1698936880284,"type":"delta","data":{"s":"BTCUSDC","b":[["34947.88","0.000261"],["34939.34","0"]],"a":[["34970.85","0.000239"],["34980.2","0"]],"u":20010807,"seq":14108050145}}'
2023-11-02 14:54:40,369 DEBUG ++Rcv decoded: fin=1 opcode=1 data=b'{"topic":"orderbook.50.BTCUSDC","ts":1698936880284,"type":"delta","data":{"s":"BTCUSDC","b":[["34947.88","0.000261"],["34939.34","0"]],"a":[["34970.85","0.000239"],["34980.2","0"]],"u":20010807,"seq":14108050145}}'
2023-11-02 14:54:40,389 DEBUG ++Rcv raw: b'\x81~\x00\xae{"topic":"orderbook.50.BTCUSDC","ts":1698936880304,"type":"delta","data":{"s":"BTCUSDC","b":[],"a":[["34972.95","0.053025"],["34975.89","0"]],"u":20010808,"seq":14108050157}}'
2023-11-02 14:54:40,389 DEBUG ++Rcv decoded: fin=1 opcode=1 data=b'{"topic":"orderbook.50.BTCUSDC","ts":1698936880304,"type":"delta","data":{"s":"BTCUSDC","b":[],"a":[["34972.95","0.053025"],["34975.89","0"]],"u":20010808,"seq":14108050157}}'
2023-11-02 14:54:40,409 DEBUG ++Rcv raw: b'\x81~\x00\xae{"topic":"orderbook.50.BTCUSDC","ts":1698936880324,"type":"delta","data":{"s":"BTCUSDC","b":[["34958.87","0.008756"],["34958.85","0"]],"a":[],"u":20010809,"seq":14108050181}}'
2023-11-02 14:54:40,409 DEBUG ++Rcv decoded: fin=1 opcode=1 data=b'{"topic":"orderbook.50.BTCUSDC","ts":1698936880324,"type":"delta","data":{"s":"BTCUSDC","b":[["34958.87","0.008756"],["34958.85","0"]],"a":[],"u":20010809,"seq":14108050181}}'
2023-11-02 14:54:40,429 DEBUG ++Rcv raw: b'\x81~\x00\xd5{"topic":"orderbook.50.BTCUSDC","ts":1698936880344,"type":"delta","data":{"s":"BTCUSDC","b":[],"a":[["34960.82","0.045724"],["34960.83","0.076205"],["34963.9","0"],["34978.9","0"]],"u":20010810,"seq":14108050205}}'
2023-11-02 14:54:40,429 DEBUG ++Rcv decoded: fin=1 opcode=1 data=b'{"topic":"orderbook.50.BTCUSDC","ts":1698936880344,"type":"delta","data":{"s":"BTCUSDC","b":[],"a":[["34960.82","0.045724"],["34960.83","0.076205"],["34963.9","0"],["34978.9","0"]],"u":20010810,"seq":14108050205}}'
2023-11-02 14:54:40,449 DEBUG ++Rcv raw: b'\x81~\x01K{"topic":"orderbook.50.BTCUSDC","ts":1698936880364,"type":"delta","data":{"s":"BTCUSDC","b":[["34939.34","0.105001"],["34953.97","0"]],"a":[["34965.01","0.051542"],["34978.9","0.002162"],["34980.2","0.1875"],["34980.48","0.023472"],["34963.89","0"],["34960.83","0"],["34968.8","0"],["34971.8","0"]],"u":20010811,"seq":14108050233}}'
2023-11-02 14:54:40,449 DEBUG ++Rcv decoded: fin=1 opcode=1 data=b'{"topic":"orderbook.50.BTCUSDC","ts":1698936880364,"type":"delta","data":{"s":"BTCUSDC","b":[["34939.34","0.105001"],["34953.97","0"]],"a":[["34965.01","0.051542"],["34978.9","0.002162"],["34980.2","0.1875"],["34980.48","0.023472"],["34963.89","0"],["34960.83","0"],["34968.8","0"],["34971.8","0"]],"u":20010811,"seq":14108050233}}'
2023-11-02 14:54:40,469 DEBUG ++Rcv raw: b'\x81~\x00\xae{"topic":"orderbook.50.BTCUSDC","ts":1698936880383,"type":"delta","data":{"s":"BTCUSDC","b":[],"a":[["34970.72","0.114381"],["34960.82","0"]],"u":20010812,"seq":14108050238}}'
2023-11-02 14:54:40,469 DEBUG ++Rcv decoded: fin=1 opcode=1 data=b'{"topic":"orderbook.50.BTCUSDC","ts":1698936880383,"type":"delta","data":{"s":"BTCUSDC","b":[],"a":[["34970.72","0.114381"],["34960.82","0"]],"u":20010812,"seq":14108050238}}'
2023-11-02 14:54:40,489 DEBUG ++Rcv raw: b'\x81~\x01\x15{"topic":"orderbook.50.BTCUSDC","ts":1698936880403,"type":"delta","data":{"s":"BTCUSDC","b":[["34958.87","0.011756"],["34953.98","0.00057"],["34939.34","0"]],"a":[["34963.81","0.057202"],["34968.83","0.00057"],["34963.96","0"],["34980.48","0"]],"u":20010813,"seq":14108050257}}'
2023-11-02 14:54:40,489 DEBUG ++Rcv decoded: fin=1 opcode=1 data=b'{"topic":"orderbook.50.BTCUSDC","ts":1698936880403,"type":"delta","data":{"s":"BTCUSDC","b":[["34958.87","0.011756"],["34953.98","0.00057"],["34939.34","0"]],"a":[["34963.81","0.057202"],["34968.83","0.00057"],["34963.96","0"],["34980.48","0"]],"u":20010813,"seq":14108050257}}'
2023-11-02 14:54:40,509 DEBUG ++Rcv raw: b'\x81~\x00\xd5{"topic":"orderbook.50.BTCUSDC","ts":1698936880424,"type":"delta","data":{"s":"BTCUSDC","b":[["34939.34","0.105001"],["34958.86","0"]],"a":[["34963.8","0.101765"],["34965.01","0"]],"u":20010814,"seq":14108050273}}'
2023-11-02 14:54:40,510 DEBUG ++Rcv decoded: fin=1 opcode=1 data=b'{"topic":"orderbook.50.BTCUSDC","ts":1698936880424,"type":"delta","data":{"s":"BTCUSDC","b":[["34939.34","0.105001"],["34958.86","0"]],"a":[["34963.8","0.101765"],["34965.01","0"]],"u":20010814,"seq":14108050273}}'
2023-11-02 14:54:40,529 DEBUG ++Rcv raw: b'\x81~\x00\xe5{"topic":"orderbook.50.BTCUSDC","ts":1698936880444,"type":"delta","data":{"s":"BTCUSDC","b":[],"a":[["34963.78","0.107766"],["34963.79","0.03"],["34963.8","0.03"],["34980.2","0"],["34963.81","0"]],"u":20010815,"seq":14108050287}}'
2023-11-02 14:54:40,529 DEBUG ++Rcv decoded: fin=1 opcode=1 data=b'{"topic":"orderbook.50.BTCUSDC","ts":1698936880444,"type":"delta","data":{"s":"BTCUSDC","b":[],"a":[["34963.78","0.107766"],["34963.79","0.03"],["34963.8","0.03"],["34980.2","0"],["34963.81","0"]],"u":20010815,"seq":14108050287}}'
2023-11-02 14:54:40,550 DEBUG ++Rcv raw: b'\x81~\x00\xf0{"topic":"orderbook.50.BTCUSDC","ts":1698936880464,"type":"delta","data":{"s":"BTCUSDC","b":[["34939.11","0.057242"],["34954.21","0"]],"a":[["34963.78","0.073446"],["34963.79","0.028605"],["34966","0.0324"]],"u":20010816,"seq":14108050300}}'
2023-11-02 14:54:40,550 DEBUG ++Rcv decoded: fin=1 opcode=1 data=b'{"topic":"orderbook.50.BTCUSDC","ts":1698936880464,"type":"delta","data":{"s":"BTCUSDC","b":[["34939.11","0.057242"],["34954.21","0"]],"a":[["34963.78","0.073446"],["34963.79","0.028605"],["34966","0.0324"]],"u":20010816,"seq":14108050300}}'
2023-11-02 14:54:40,569 DEBUG ++Rcv raw: b'\x81~\x00\xab{"topic":"orderbook.50.BTCUSDC","ts":1698936880484,"type":"delta","data":{"s":"BTCUSDC","b":[["34938","0.156485"],["34949.73","0"]],"a":[],"u":20010817,"seq":14108050307}}'
2023-11-02 14:54:40,569 DEBUG ++Rcv decoded: fin=1 opcode=1 data=b'{"topic":"orderbook.50.BTCUSDC","ts":1698936880484,"type":"delta","data":{"s":"BTCUSDC","b":[["34938","0.156485"],["34949.73","0"]],"a":[],"u":20010817,"seq":14108050307}}'
2023-11-02 14:54:40,609 DEBUG ++Rcv raw: b'\x81~\x00\xfa{"topic":"orderbook.50.BTCUSDC","ts":1698936880523,"type":"delta","data":{"s":"BTCUSDC","b":[["34958.88","0.01144"],["34947.94","0.000261"],["34939.11","0"],["34938","0"]],"a":[["34970.74","0.000239"],["34978.9","0"]],"u":20010818,"seq":14108050317}}'
2023-11-02 14:54:40,609 DEBUG ++Rcv decoded: fin=1 opcode=1 data=b'{"topic":"orderbook.50.BTCUSDC","ts":1698936880523,"type":"delta","data":{"s":"BTCUSDC","b":[["34958.88","0.01144"],["34947.94","0.000261"],["34939.11","0"],["34938","0"]],"a":[["34970.74","0.000239"],["34978.9","0"]],"u":20010818,"seq":14108050317}}'
2023-11-02 14:54:40,629 DEBUG ++Rcv raw: b'\x81~\x00\xe9{"topic":"orderbook.50.BTCUSDC","ts":1698936880543,"type":"delta","data":{"s":"BTCUSDC","b":[["34958.87","0.008756"],["34949.6","0.002485"],["34939.34","0"]],"a":[["34963.77","0.03"],["34978.28","0"]],"u":20010819,"seq":14108050339}}'
2023-11-02 14:54:40,629 DEBUG ++Rcv decoded: fin=1 opcode=1 data=b'{"topic":"orderbook.50.BTCUSDC","ts":1698936880543,"type":"delta","data":{"s":"BTCUSDC","b":[["34958.87","0.008756"],["34949.6","0.002485"],["34939.34","0"]],"a":[["34963.77","0.03"],["34978.28","0"]],"u":20010819,"seq":14108050339}}'
2023-11-02 14:54:40,649 DEBUG ++Rcv raw: b'\x81~\x00\xfc{"topic":"orderbook.50.BTCUSDC","ts":1698936880564,"type":"delta","data":{"s":"BTCUSDC","b":[["34939.34","0.105001"],["34950.01","0"]],"a":[["34960.41","0.08677"],["34963.88","0.0286"],["34963.77","0"],["34977.06","0"]],"u":20010820,"seq":14108050351}}'
2023-11-02 14:54:40,649 DEBUG ++Rcv decoded: fin=1 opcode=1 data=b'{"topic":"orderbook.50.BTCUSDC","ts":1698936880564,"type":"delta","data":{"s":"BTCUSDC","b":[["34939.34","0.105001"],["34950.01","0"]],"a":[["34960.41","0.08677"],["34963.88","0.0286"],["34963.77","0"],["34977.06","0"]],"u":20010820,"seq":14108050351}}'
2023-11-02 14:54:40,669 DEBUG ++Rcv raw: b'\x81~\x01t{"topic":"orderbook.50.BTCUSDC","ts":1698936880584,"type":"delta","data":{"s":"BTCUSDC","b":[["34939.11","0.057242"],["34938","0.156485"],["34937.39","0.278379"],["34958.87","0"],["34953.98","0"],["34958.88","0"]],"a":[["34960.4","0.052069"],["34965.01","0.051548"],["34977.06","0.0859"],["34960.41","0"],["34968.83","0"],["34963.78","0"]],"u":20010821,"seq":14108050367}}'
2023-11-02 14:54:40,669 DEBUG ++Rcv decoded: fin=1 opcode=1 data=b'{"topic":"orderbook.50.BTCUSDC","ts":1698936880584,"type":"delta","data":{"s":"BTCUSDC","b":[["34939.11","0.057242"],["34938","0.156485"],["34937.39","0.278379"],["34958.87","0"],["34953.98","0"],["34958.88","0"]],"a":[["34960.4","0.052069"],["34965.01","0.051548"],["34977.06","0.0859"],["34960.41","0"],["34968.83","0"],["34963.78","0"]],"u":20010821,"seq":14108050367}}'
2023-11-02 14:54:40,689 DEBUG ++Rcv raw: b'\x81~\x01%{"topic":"orderbook.50.BTCUSDC","ts":1698936880603,"type":"delta","data":{"s":"BTCUSDC","b":[["34951.53","0.00057"],["34936.36","0.823804"],["34948.36","0"],["34951.9","0"]],"a":[["34963.77","0.008756"],["34963.78","0.089772"],["34965.01","0"],["34960.4","0"]],"u":20010822,"seq":14108050382}}'
2023-11-02 14:54:40,689 DEBUG ++Rcv decoded: fin=1 opcode=1 data=b'{"topic":"orderbook.50.BTCUSDC","ts":1698936880603,"type":"delta","data":{"s":"BTCUSDC","b":[["34951.53","0.00057"],["34936.36","0.823804"],["34948.36","0"],["34951.9","0"]],"a":[["34963.77","0.008756"],["34963.78","0.089772"],["34965.01","0"],["34960.4","0"]],"u":20010822,"seq":14108050382}}'
2023-11-02 14:54:40,709 DEBUG ++Rcv raw: b'\x81~\x00\xff{"topic":"orderbook.50.BTCUSDC","ts":1698936880624,"type":"delta","data":{"s":"BTCUSDC","b":[],"a":[["34963.75","0.011548"],["34963.76","0.023096"],["34968.66","0.00057"],["34977.05","0"],["34976.12","0"],["34977.06","0"]],"u":20010823,"seq":14108050389}}'
2023-11-02 14:54:40,709 DEBUG ++Rcv decoded: fin=1 opcode=1 data=b'{"topic":"orderbook.50.BTCUSDC","ts":1698936880624,"type":"delta","data":{"s":"BTCUSDC","b":[],"a":[["34963.75","0.011548"],["34963.76","0.023096"],["34968.66","0.00057"],["34977.05","0"],["34976.12","0"],["34977.06","0"]],"u":20010823,"seq":14108050389}}'
2023-11-02 14:54:40,729 DEBUG ++Rcv raw: b'\x81~\x01%{"topic":"orderbook.50.BTCUSDC","ts":1698936880644,"type":"delta","data":{"s":"BTCUSDC","b":[["34936.35","0.1875"],["34943.6","0"]],"a":[["34963.74","0.008756"],["34976.12","0.043812"],["34977.05","0.051548"],["34963.76","0"],["34963.75","0"],["34963.77","0"]],"u":20010824,"seq":14108050397}}'
2023-11-02 14:54:40,729 DEBUG ++Rcv decoded: fin=1 opcode=1 data=b'{"topic":"orderbook.50.BTCUSDC","ts":1698936880644,"type":"delta","data":{"s":"BTCUSDC","b":[["34936.35","0.1875"],["34943.6","0"]],"a":[["34963.74","0.008756"],["34976.12","0.043812"],["34977.05","0.051548"],["34963.76","0"],["34963.75","0"],["34963.77","0"]],"u":20010824,"seq":14108050397}}'
2023-11-02 14:54:40,749 DEBUG ++Rcv raw: b'\x81~\x00\xd4{"topic":"orderbook.50.BTCUSDC","ts":1698936880664,"type":"delta","data":{"s":"BTCUSDC","b":[["34935.91","1.373003"],["34956.28","0"]],"a":[["34977.06","0.0859"],["34963.88","0"]],"u":20010825,"seq":14108050412}}'
2023-11-02 14:54:40,750 DEBUG ++Rcv decoded: fin=1 opcode=1 data=b'{"topic":"orderbook.50.BTCUSDC","ts":1698936880664,"type":"delta","data":{"s":"BTCUSDC","b":[["34935.91","1.373003"],["34956.28","0"]],"a":[["34977.06","0.0859"],["34963.88","0"]],"u":20010825,"seq":14108050412}}'
2023-11-02 14:54:40,769 DEBUG ++Rcv raw: b'\x81~\x00\xff{"topic":"orderbook.50.BTCUSDC","ts":1698936880684,"type":"delta","data":{"s":"BTCUSDC","b":[["34955.77","0.057215"],["34935.91","0"]],"a":[["34963.71","0.031852"],["34963.72","0.057202"],["34963.74","0"],["34977.06","0"]],"u":20010826,"seq":14108050424}}'
2023-11-02 14:54:40,769 DEBUG ++Rcv decoded: fin=1 opcode=1 data=b'{"topic":"orderbook.50.BTCUSDC","ts":1698936880684,"type":"delta","data":{"s":"BTCUSDC","b":[["34955.77","0.057215"],["34935.91","0"]],"a":[["34963.71","0.031852"],["34963.72","0.057202"],["34963.74","0"],["34977.06","0"]],"u":20010826,"seq":14108050424}}'
2023-11-02 14:54:40,789 DEBUG ++Rcv raw: b'\x81~\x00\xd6{"topic":"orderbook.50.BTCUSDC","ts":1698936880704,"type":"delta","data":{"s":"BTCUSDC","b":[],"a":[["34963.69","0.008756"],["34963.7","0.011548"],["34963.71","0"],["34963.72","0"]],"u":20010827,"seq":14108050438}}'
2023-11-02 14:54:40,789 DEBUG ++Rcv decoded: fin=1 opcode=1 data=b'{"topic":"orderbook.50.BTCUSDC","ts":1698936880704,"type":"delta","data":{"s":"BTCUSDC","b":[],"a":[["34963.69","0.008756"],["34963.7","0.011548"],["34963.71","0"],["34963.72","0"]],"u":20010827,"seq":14108050438}}'
2023-11-02 14:54:40,810 DEBUG ++Rcv raw: b'\x81~\x00\xfc{"topic":"orderbook.50.BTCUSDC","ts":1698936880724,"type":"delta","data":{"s":"BTCUSDC","b":[["34935.91","1.373003"],["34947.88","0"]],"a":[["34977.06","0.0859"],["34978.28","0.279826"],["34970.85","0"],["34963.7","0"]],"u":20010828,"seq":14108050447}}'
2023-11-02 14:54:40,811 DEBUG ++Rcv decoded: fin=1 opcode=1 data=b'{"topic":"orderbook.50.BTCUSDC","ts":1698936880724,"type":"delta","data":{"s":"BTCUSDC","b":[["34935.91","1.373003"],["34947.88","0"]],"a":[["34977.06","0.0859"],["34978.28","0.279826"],["34970.85","0"],["34963.7","0"]],"u":20010828,"seq":14108050447}}'
2023-11-02 14:54:40,950 DEBUG ++Rcv raw: b'\x81~\x00\xab{"topic":"orderbook.50.BTCUSDC","ts":1698936880864,"type":"delta","data":{"s":"BTCUSDC","b":[["34939.87","0.028"],["34935.91","0"]],"a":[],"u":20010829,"seq":14108050502}}'
2023-11-02 14:54:40,950 DEBUG ++Rcv decoded: fin=1 opcode=1 data=b'{"topic":"orderbook.50.BTCUSDC","ts":1698936880864,"type":"delta","data":{"s":"BTCUSDC","b":[["34939.87","0.028"],["34935.91","0"]],"a":[],"u":20010829,"seq":14108050502}}'
2023-11-02 14:54:40,970 DEBUG ++Rcv raw: b'\x81~\x00\xad{"topic":"orderbook.50.BTCUSDC","ts":1698936880885,"type":"delta","data":{"s":"BTCUSDC","b":[],"a":[["34978.9","0.002162"],["34970.74","0"]],"u":20010830,"seq":14108050513}}'
2023-11-02 14:54:40,971 DEBUG ++Rcv decoded: fin=1 opcode=1 data=b'{"topic":"orderbook.50.BTCUSDC","ts":1698936880885,"type":"delta","data":{"s":"BTCUSDC","b":[],"a":[["34978.9","0.002162"],["34970.74","0"]],"u":20010830,"seq":14108050513}}'
2023-11-02 14:54:40,989 DEBUG ++Rcv raw: b'\x81~\x00\xad{"topic":"orderbook.50.BTCUSDC","ts":1698936880903,"type":"delta","data":{"s":"BTCUSDC","b":[],"a":[["34963.73","0.028601"],["34978.9","0"]],"u":20010831,"seq":14108050524}}'
2023-11-02 14:54:40,989 DEBUG ++Rcv decoded: fin=1 opcode=1 data=b'{"topic":"orderbook.50.BTCUSDC","ts":1698936880903,"type":"delta","data":{"s":"BTCUSDC","b":[],"a":[["34963.73","0.028601"],["34978.9","0"]],"u":20010831,"seq":14108050524}}'
2023-11-02 14:54:41,089 DEBUG ++Rcv raw: b'\x81~\x00\xad{"topic":"orderbook.50.BTCUSDC","ts":1698936881003,"type":"delta","data":{"s":"BTCUSDC","b":[],"a":[["34978.9","0.002162"],["34963.73","0"]],"u":20010832,"seq":14108050579}}'
2023-11-02 14:54:41,089 DEBUG ++Rcv decoded: fin=1 opcode=1 data=b'{"topic":"orderbook.50.BTCUSDC","ts":1698936881003,"type":"delta","data":{"s":"BTCUSDC","b":[],"a":[["34978.9","0.002162"],["34963.73","0"]],"u":20010832,"seq":14108050579}}'
2023-11-02 14:54:41,109 DEBUG ++Rcv raw: b'\x81~\x00\xfd{"topic":"orderbook.50.BTCUSDC","ts":1698936881024,"type":"delta","data":{"s":"BTCUSDC","b":[["34957.13","0.091584"],["34947.94","0"]],"a":[["34960.64","0.08406"],["34963.77","0.008756"],["34963.69","0"],["34978.9","0"]],"u":20010833,"seq":14108050596}}'
2023-11-02 14:54:41,110 DEBUG ++Rcv decoded: fin=1 opcode=1 data=b'{"topic":"orderbook.50.BTCUSDC","ts":1698936881024,"type":"delta","data":{"s":"BTCUSDC","b":[["34957.13","0.091584"],["34947.94","0"]],"a":[["34960.64","0.08406"],["34963.77","0.008756"],["34963.69","0"],["34978.9","0"]],"u":20010833,"seq":14108050596}}'
2023-11-02 14:54:41,128 DEBUG ++Rcv raw: b'\x81~\x01\x14{"topic":"orderbook.50.BTCUSDC","ts":1698936881043,"type":"delta","data":{"s":"BTCUSDC","b":[["34956.42","0.0889"]],"a":[["34960.63","0.050436"],["34965.01","0.051541"],["34978.9","0.002162"],["34963.78","0"],["34960.64","0"],["34968.66","0"]],"u":20010834,"seq":14108050611}}'
2023-11-02 14:54:41,129 DEBUG ++Rcv decoded: fin=1 opcode=1 data=b'{"topic":"orderbook.50.BTCUSDC","ts":1698936881043,"type":"delta","data":{"s":"BTCUSDC","b":[["34956.42","0.0889"]],"a":[["34960.63","0.050436"],["34965.01","0.051541"],["34978.9","0.002162"],["34963.78","0"],["34960.64","0"],["34968.66","0"]],"u":20010834,"seq":14108050611}}'
2023-11-02 14:54:41,149 DEBUG ++Rcv raw: b'\x81~\x00\xc2{"topic":"orderbook.50.BTCUSDC","ts":1698936881064,"type":"delta","data":{"s":"BTCUSDC","b":[["34956.42","0.0859"]],"a":[["34965.52","0.00057"],["34960.63","0"]],"u":20010835,"seq":14108050622}}'
2023-11-02 14:54:41,150 DEBUG ++Rcv decoded: fin=1 opcode=1 data=b'{"topic":"orderbook.50.BTCUSDC","ts":1698936881064,"type":"delta","data":{"s":"BTCUSDC","b":[["34956.42","0.0859"]],"a":[["34965.52","0.00057"],["34960.63","0"]],"u":20010835,"seq":14108050622}}'
2023-11-02 14:54:41,169 DEBUG ++Rcv raw: b'\x81~\x00\xab{"topic":"orderbook.50.BTCUSDC","ts":1698936881083,"type":"delta","data":{"s":"BTCUSDC","b":[],"a":[["34980.2","0.1875"],["34965.52","0"]],"u":20010836,"seq":14108050630}}'
2023-11-02 14:54:41,169 DEBUG ++Rcv decoded: fin=1 opcode=1 data=b'{"topic":"orderbook.50.BTCUSDC","ts":1698936881083,"type":"delta","data":{"s":"BTCUSDC","b":[],"a":[["34980.2","0.1875"],["34965.52","0"]],"u":20010836,"seq":14108050630}}'
