2023-11-02 14:54:22,049 DEBUG ++Rcv decoded: fin=1 opcode=1 data=b'{"topic":"orderbook.50.BTCUSDC","ts":1698936861963,"type":"delta","data":{"s":"BTCUSDC","b":[],"a":[["34963.12","0.034325"],["34965.01","0.051545"],["34978.76","0"]],"u":20010193,"seq":14108039950}}'
2023-11-02 14:54:22,108 DEBUG ++Rcv raw: b'\x81~\x00\xae{"topic":"orderbook.50.BTCUSDC","ts":1698936862023,"type":"delta","data":{"s":"BTCUSDC","b":[["34960.41","0.028603"],["34940.14","0"]],"a":[],"u":20010194,"seq":14108039978}}'
2023-11-02 14:54:22,109 DEBUG ++Rcv decoded: fin=1 opcode=1 data=b'{"topic":"orderbook.50.BTCUSDC","ts":1698936862023,"type":"delta","data":{"s":"BTCUSDC","b":[["34960.41","0.028603"],["34940.14","0"]],"a":[],"u":20010194,"seq":14108039978}}'
2023-11-02 14:54:22,131 DEBUG ++Rcv raw: b'\x81~\x00\xc4{"topic":"orderbook.50.BTCUSDC","ts":1698936862043,"type":"delta","data":{"s":"BTCUSDC","b":[["34958.15","0.05215"],["34951.27","0.001531"],["34940.3","0"]],"a":[],"u":20010195,"seq":14108039993}}'
2023-11-02 14:54:22,131 DEBUG ++Rcv decoded: fin=1 opcode=1 data=b'{"topic":"orderbook.50.BTCUSDC","ts":1698936862043,"type":"delta","data":{"s":"BTCUSDC","b":[["34958.15","0.05215"],["34951.27","0.001531"],["34940.3","0"]],"a":[],"u":20010195,"seq":14108039993}}'
2023-11-02 14:54:22,149 DEBUG ++Rcv raw: b'\x81~\x00\xfd{"topic":"orderbook.50.BTCUSDC","ts":1698936862063,"type":"delta","data":{"s":"BTCUSDC","b":[["34940.3","0.025298"],["34940.14","0.286203"],["34950.02","0"],["34960.4","0"]],"a":[["34978.76","0.285887"],["34977.05","0"]],"u":20010196,"seq":14108040004}}'
2023-11-02 14:54:22,149 DEBUG ++Rcv decoded: fin=1 opcode=1 data=b'{"topic":"orderbook.50.BTCUSDC","ts":1698936862063,"type":"delta","data":{"s":"BTCUSDC","b":[["34940.3","0.025298"],["34940.14","0.286203"],["34950.02","0"],["34960.4","0"]],"a":[["34978.76","0.285887"],["34977.05","0"]],"u":20010196,"seq":14108040004}}'
2023-11-02 14:54:22,188 DEBUG ++Rcv raw: b'\x81~\x00\xad{"topic":"orderbook.50.BTCUSDC","ts":1698936862103,"type":"delta","data":{"s":"BTCUSDC","b":[],"a":[["34978.9","0.002162"],["34976.36","0"]],"u":20010197,"seq":14108040019}}'
2023-11-02 14:54:22,189 DEBUG ++Rcv decoded: fin=1 opcode=1 data=b'{"topic":"orderbook.50.BTCUSDC","ts":1698936862103,"type":"delta","data":{"s":"BTCUSDC","b":[],"a":[["34978.9","0.002162"],["34976.36","0"]],"u":20010197,"seq":14108040019}}'
2023-11-02 14:54:22,270 DEBUG ++Rcv raw: b'\x81~\x00\xad{"topic":"orderbook.50.BTCUSDC","ts":1698936862184,"type":"delta","data":{"s":"BTCUSDC","b":[],"a":[["34963.11","0.028601"],["34978.9","0"]],"u":20010198,"seq":14108040048}}'
2023-11-02 14:54:22,270 DEBUG ++Rcv decoded: fin=1 opcode=1 data=b'{"topic":"orderbook.50.BTCUSDC","ts":1698936862184,"type":"delta","data":{"s":"BTCUSDC","b":[],"a":[["34963.11","0.028601"],["34978.9","0"]],"u":20010198,"seq":14108040048}}'
2023-11-02 14:54:22,289 DEBUG ++Rcv raw: b'\x81~\x00\xd3{"topic":"orderbook.50.BTCUSDC","ts":1698936862203,"type":"delta","data":{"s":"BTCUSDC","b":[["34947.67","0.042371"],["34940.31","0.028"],["34940.3","0"],["34940.14","0"]],"a":[],"u":20010199,"seq":14108040068}}'
2023-11-02 14:54:22,289 DEBUG ++Rcv decoded: fin=1 opcode=1 data=b'{"topic":"orderbook.50.BTCUSDC","ts":1698936862203,"type":"delta","data":{"s":"BTCUSDC","b":[["34947.67","0.042371"],["34940.31","0.028"],["34940.3","0"],["34940.14","0"]],"a":[],"u":20010199,"seq":14108040068}}'
2023-11-02 14:54:22,329 DEBUG ++Rcv raw: b'\x81~\x00\xae{"topic":"orderbook.50.BTCUSDC","ts":1698936862243,"type":"delta","data":{"s":"BTCUSDC","b":[["34950.02","0.002848"],["34940.31","0"]],"a":[],"u":20010200,"seq":14108040081}}'
2023-11-02 14:54:22,329 DEBUG ++Rcv decoded: fin=1 opcode=1 data=b'{"topic":"orderbook.50.BTCUSDC","ts":1698936862243,"type":"delta","data":{"s":"BTCUSDC","b":[["34950.02","0.002848"],["34940.31","0"]],"a":[],"u":20010200,"seq":14108040081}}'
2023-11-02 14:54:22,349 DEBUG ++Rcv raw: b'\x81~\x01#{"topic":"orderbook.50.BTCUSDC","ts":1698936862263,"type":"delta","data":{"s":"BTCUSDC","b":[["34960.9","0.105398"],["34958.16","0.008756"],["34940.31","0.028"],["34951.27","0"],["34960.41","0"],["34958.14","0"]],"a":[["34978.9","0.002162"],["34963.11","0"]],"u":20010201,"seq":14108040108}}'
2023-11-02 14:54:22,349 DEBUG ++Rcv decoded: fin=1 opcode=1 data=b'{"topic":"orderbook.50.BTCUSDC","ts":1698936862263,"type":"delta","data":{"s":"BTCUSDC","b":[["34960.9","0.105398"],["34958.16","0.008756"],["34940.31","0.028"],["34951.27","0"],["34960.41","0"],["34958.14","0"]],"a":[["34978.9","0.002162"],["34963.11","0"]],"u":20010201,"seq":14108040108}}'
2023-11-02 14:54:22,369 DEBUG ++Rcv raw: b'\x81~\x00\xec{"topic":"orderbook.50.BTCUSDC","ts":1698936862283,"type":"delta","data":{"s":"BTCUSDC","b":[["34958.15","0.027558"],["34958.14","0.0859"],["34940.31","0"]],"a":[["34980.48","0.023472"],["34965.02","0"]],"u":20010202,"seq":14108040113}}'
2023-11-02 14:54:22,369 DEBUG ++Rcv decoded: fin=1 opcode=1 data=b'{"topic":"orderbook.50.BTCUSDC","ts":1698936862283,"type":"delta","data":{"s":"BTCUSDC","b":[["34958.15","0.027558"],["34958.14","0.0859"],["34940.31","0"]],"a":[["34980.48","0.023472"],["34965.02","0"]],"u":20010202,"seq":14108040113}}'
2023-11-02 14:54:22,391 DEBUG ++Rcv raw: b'\x81~\x00\xc5{"topic":"orderbook.50.BTCUSDC","ts":1698936862303,"type":"delta","data":{"s":"BTCUSDC","b":[["34958.15","0.069074"]],"a":[["34981.28","0.000562"],["34965.01","0"]],"u":20010203,"seq":14108040120}}'
2023-11-02 14:54:22,391 DEBUG ++Rcv decoded: fin=1 opcode=1 data=b'{"topic":"orderbook.50.BTCUSDC","ts":1698936862303,"type":"delta","data":{"s":"BTCUSDC","b":[["34958.15","0.069074"]],"a":[["34981.28","0.000562"],["34965.01","0"]],"u":20010203,"seq":14108040120}}'
2023-11-02 14:54:22,449 DEBUG ++Rcv raw: b'\x81~\x00\xd5{"topic":"orderbook.50.BTCUSDC","ts":1698936862364,"type":"delta","data":{"s":"BTCUSDC","b":[["34960.91","0.028603"],["34960.9","0"]],"a":[["34963.11","0.028601"],["34981.28","0"]],"u":20010204,"seq":14108040154}}'
2023-11-02 14:54:22,449 DEBUG ++Rcv decoded: fin=1 opcode=1 data=b'{"topic":"orderbook.50.BTCUSDC","ts":1698936862364,"type":"delta","data":{"s":"BTCUSDC","b":[["34960.91","0.028603"],["34960.9","0"]],"a":[["34963.11","0.028601"],["34981.28","0"]],"u":20010204,"seq":14108040154}}'
2023-11-02 14:54:22,469 DEBUG ++Rcv raw: b'\x81~\x00\xc3{"topic":"orderbook.50.BTCUSDC","ts":1698936862384,"type":"delta","data":{"s":"BTCUSDC","b":[["34958.15","0.066074"]],"a":[["34965.02","0.0859"],["34980.48","0"]],"u":20010205,"seq":14108040160}}'
2023-11-02 14:54:22,469 DEBUG ++Rcv decoded: fin=1 opcode=1 data=b'{"topic":"orderbook.50.BTCUSDC","ts":1698936862384,"type":"delta","data":{"s":"BTCUSDC","b":[["34958.15","0.066074"]],"a":[["34965.02","0.0859"],["34980.48","0"]],"u":20010205,"seq":14108040160}}'
2023-11-02 14:54:22,490 DEBUG ++Rcv raw: b'\x81~\x00\xad{"topic":"orderbook.50.BTCUSDC","ts":1698936862404,"type":"delta","data":{"s":"BTCUSDC","b":[],"a":[["34965.01","0.051548"],["34978.9","0"]],"u":20010206,"seq":14108040163}}'
2023-11-02 14:54:22,490 DEBUG ++Rcv decoded: fin=1 opcode=1 data=b'{"topic":"orderbook.50.BTCUSDC","ts":1698936862404,"type":"delta","data":{"s":"BTCUSDC","b":[],"a":[["34965.01","0.051548"],["34978.9","0"]],"u":20010206,"seq":14108040163}}'
2023-11-02 14:54:22,590 DEBUG ++Rcv raw: b'\x81~\x00\xae{"topic":"orderbook.50.BTCUSDC","ts":1698936862503,"type":"delta","data":{"s":"BTCUSDC","b":[],"a":[["34962.91","0.057203"],["34963.13","0"]],"u":20010207,"seq":14108040197}}'
2023-11-02 14:54:22,591 DEBUG ++Rcv decoded: fin=1 opcode=1 data=b'{"topic":"orderbook.50.BTCUSDC","ts":1698936862503,"type":"delta","data":{"s":"BTCUSDC","b":[],"a":[["34962.91","0.057203"],["34963.13","0"]],"u":20010207,"seq":14108040197}}'
2023-11-02 14:54:22,609 DEBUG ++Rcv raw: b'\x81~\x00\xd5{"topic":"orderbook.50.BTCUSDC","ts":1698936862524,"type":"delta","data":{"s":"BTCUSDC","b":[["34948.03","0.213771"],["34940.87","0"]],"a":[["34962.9","0.031783"],["34963.12","0"]],"u":20010208,"seq":14108040208}}'
2023-11-02 14:54:22,610 DEBUG ++Rcv decoded: fin=1 opcode=1 data=b'{"topic":"orderbook.50.BTCUSDC","ts":1698936862524,"type":"delta","data":{"s":"BTCUSDC","b":[["34948.03","0.213771"],["34940.87","0"]],"a":[["34962.9","0.031783"],["34963.12","0"]],"u":20010208,"seq":14108040208}}'
2023-11-02 14:54:22,649 DEBUG ++Rcv raw: b'\x81~\x00\xae{"topic":"orderbook.50.BTCUSDC","ts":1698936862564,"type":"delta","data":{"s":"BTCUSDC","b":[["34951.27","0.001883"],["34950.02","0"]],"a":[],"u":20010209,"seq":14108040222}}'
2023-11-02 14:54:22,650 DEBUG ++Rcv decoded: fin=1 opcode=1 data=b'{"topic":"orderbook.50.BTCUSDC","ts":1698936862564,"type":"delta","data":{"s":"BTCUSDC","b":[["34951.27","0.001883"],["34950.02","0"]],"a":[],"u":20010209,"seq":14108040222}}'
2023-11-02 14:54:22,689 DEBUG ++Rcv raw: b'\x81~\x01#{"topic":"orderbook.50.BTCUSDC","ts":1698936862603,"type":"delta","data":{"s":"BTCUSDC","b":[["34960.01","0.104946"],["34940.87","0.00154"],["34940.31","0.028"],["34960.91","0"],["34958.14","0"],["34958.16","0"]],"a":[["34978.9","0.002162"],["34963.11","0"]],"u":20010210,"seq":14108040231}}'
2023-11-02 14:54:22,689 DEBUG ++Rcv decoded: fin=1 opcode=1 data=b'{"topic":"orderbook.50.BTCUSDC","ts":1698936862603,"type":"delta","data":{"s":"BTCUSDC","b":[["34960.01","0.104946"],["34940.87","0.00154"],["34940.31","0.028"],["34960.91","0"],["34958.14","0"],["34958.16","0"]],"a":[["34978.9","0.002162"],["34963.11","0"]],"u":20010210,"seq":14108040231}}'
2023-11-02 14:54:22,709 DEBUG ++Rcv raw: b'\x81~\x00\xec{"topic":"orderbook.50.BTCUSDC","ts":1698936862624,"type":"delta","data":{"s":"BTCUSDC","b":[["34958.15","0.024558"],["34958.14","0.0859"],["34955.12","0.00057"],["34940.31","0"],["34940.87","0"]],"a":[],"u":20010211,"seq":14108040234}}'
2023-11-02 14:54:22,710 DEBUG ++Rcv decoded: fin=1 opcode=1 data=b'{"topic":"orderbook.50.BTCUSDC","ts":1698936862624,"type":"delta","data":{"s":"BTCUSDC","b":[["34958.15","0.024558"],["34958.14","0.0859"],["34955.12","0.00057"],["34940.31","0"],["34940.87","0"]],"a":[],"u":20010211,"seq":14108040234}}'
2023-11-02 14:54:22,730 DEBUG ++Rcv raw: b'\x81~\x00\xc3{"topic":"orderbook.50.BTCUSDC","ts":1698936862644,"type":"delta","data":{"s":"BTCUSDC","b":[["34958.15","0.056982"]],"a":[["34967.79","0.00057"],["34978.9","0"]],"u":20010212,"seq":14108040239}}'
2023-11-02 14:54:22,730 DEBUG ++Rcv decoded: fin=1 opcode=1 data=b'{"topic":"orderbook.50.BTCUSDC","ts":1698936862644,"type":"delta","data":{"s":"BTCUSDC","b":[["34958.15","0.056982"]],"a":[["34967.79","0.00057"],["34978.9","0"]],"u":20010212,"seq":14108040239}}'
2023-11-02 14:54:22,769 DEBUG ++Rcv raw: b'\x81~\x00\xae{"topic":"orderbook.50.BTCUSDC","ts":1698936862683,"type":"delta","data":{"s":"BTCUSDC","b":[["34960.02","0.008756"],["34960.01","0"]],"a":[],"u":20010213,"seq":14108040241}}'
2023-11-02 14:54:22,769 DEBUG ++Rcv decoded: fin=1 opcode=1 data=b'{"topic":"orderbook.50.BTCUSDC","ts":1698936862683,"type":"delta","data":{"s":"BTCUSDC","b":[["34960.02","0.008756"],["34960.01","0"]],"a":[],"u":20010213,"seq":14108040241}}'
2023-11-02 14:54:22,790 DEBUG ++Rcv raw: b'\x81~\x00\xec{"topic":"orderbook.50.BTCUSDC","ts":1698936862703,"type":"delta","data":{"s":"BTCUSDC","b":[["34960.02","0.03736"],["34940.87","0.00154"],["34958.14","0"]],"a":[["34962.89","0.028601"],["34978.76","0"]],"u":20010214,"seq":14108040246}}'
2023-11-02 14:54:22,790 DEBUG ++Rcv decoded: fin=1 opcode=1 data=b'{"topic":"orderbook.50.BTCUSDC","ts":1698936862703,"type":"delta","data":{"s":"BTCUSDC","b":[["34960.02","0.03736"],["34940.87","0.00154"],["34958.14","0"]],"a":[["34962.89","0.028601"],["34978.76","0"]],"u":20010214,"seq":14108040246}}'
2023-11-02 14:54:22,810 DEBUG ++Rcv raw: b'\x81~\x00\xc6{"topic":"orderbook.50.BTCUSDC","ts":1698936862724,"type":"delta","data":{"s":"BTCUSDC","b":[["34958.15","0.024558"],["34956.43","0.051543"],["34940.87","0"]],"a":[],"u":20010215,"seq":14108040248}}'
2023-11-02 14:54:22,810 DEBUG ++Rcv decoded: fin=1 opcode=1 data=b'{"topic":"orderbook.50.BTCUSDC","ts":1698936862724,"type":"delta","data":{"s":"BTCUSDC","b":[["34958.15","0.024558"],["34956.43","0.051543"],["34940.87","0"]],"a":[],"u":20010215,"seq":14108040248}}'
2023-11-02 14:54:22,889 DEBUG ++Rcv raw: b'\x81~\x00\x9d{"topic":"orderbook.50.BTCUSDC","ts":1698936862804,"type":"delta","data":{"s":"BTCUSDC","b":[["34960.02","0.008756"]],"a":[],"u":20010216,"seq":14108040281}}'
2023-11-02 14:54:22,889 DEBUG ++Rcv decoded: fin=1 opcode=1 data=b'{"topic":"orderbook.50.BTCUSDC","ts":1698936862804,"type":"delta","data":{"s":"BTCUSDC","b":[["34960.02","0.008756"]],"a":[],"u":20010216,"seq":14108040281}}'
2023-11-02 14:54:22,910 DEBUG ++Rcv raw: b'\x81~\x00\x9d{"topic":"orderbook.50.BTCUSDC","ts":1698936862824,"type":"delta","data":{"s":"BTCUSDC","b":[["34960.02","0.011756"]],"a":[],"u":20010217,"seq":14108040283}}'
2023-11-02 14:54:22,910 DEBUG ++Rcv decoded: fin=1 opcode=1 data=b'{"topic":"orderbook.50.BTCUSDC","ts":1698936862824,"type":"delta","data":{"s":"BTCUSDC","b":[["34960.02","0.011756"]],"a":[],"u":20010217,"seq":14108040283}}'
2023-11-02 14:54:22,989 DEBUG ++Rcv raw: b'\x81~\x00\xab{"topic":"orderbook.50.BTCUSDC","ts":1698936862904,"type":"delta","data":{"s":"BTCUSDC","b":[["34960.03","0.028604"],["34942","0"]],"a":[],"u":20010218,"seq":14108040302}}'
2023-11-02 14:54:22,990 DEBUG ++Rcv decoded: fin=1 opcode=1 data=b'{"topic":"orderbook.50.BTCUSDC","ts":1698936862904,"type":"delta","data":{"s":"BTCUSDC","b":[["34960.03","0.028604"],["34942","0"]],"a":[],"u":20010218,"seq":14108040302}}'
2023-11-02 14:54:23,010 DEBUG ++Rcv raw: b'\x81~\x00\xfb{"topic":"orderbook.50.BTCUSDC","ts":1698936862923,"type":"delta","data":{"s":"BTCUSDC","b":[["34960.8","0.106971"],["34958.14","0.0859"],["34960.02","0"],["34942.2","0"]],"a":[["34978.76","0.285887"],["34965.02","0"]],"u":20010219,"seq":14108040307}}'
2023-11-02 14:54:23,011 DEBUG ++Rcv decoded: fin=1 opcode=1 data=b'{"topic":"orderbook.50.BTCUSDC","ts":1698936862923,"type":"delta","data":{"s":"BTCUSDC","b":[["34960.8","0.106971"],["34958.14","0.0859"],["34960.02","0"],["34942.2","0"]],"a":[["34978.76","0.285887"],["34965.02","0"]],"u":20010219,"seq":14108040307}}'
2023-11-02 14:54:23,033 DEBUG ++Rcv raw: b'\x81~\x01f{"topic":"orderbook.50.BTCUSDC","ts":1698936862948,"type":"delta","data":{"s":"BTCUSDC","b":[["34958.15","0.048206"],["34953.12","0.001796"],["34942.2","0.043599"],["34955.12","0"],["34956.43","0"]],"a":[["34978.9","0.002162"],["34980.48","0.023472"],["34981.28","0.000562"],["34967.79","0"],["34965.01","0"],["34962.9","0"]],"u":20010220,"seq":14108040319}}'
2023-11-02 14:54:23,033 DEBUG ++Rcv decoded: fin=1 opcode=1 data=b'{"topic":"orderbook.50.BTCUSDC","ts":1698936862948,"type":"delta","data":{"s":"BTCUSDC","b":[["34958.15","0.048206"],["34953.12","0.001796"],["34942.2","0.043599"],["34955.12","0"],["34956.43","0"]],"a":[["34978.9","0.002162"],["34980.48","0.023472"],["34981.28","0.000562"],["34967.79","0"],["34965.01","0"],["34962.9","0"]],"u":20010220,"seq":14108040319}}'
2023-11-02 14:54:23,049 DEBUG ++Rcv raw: b'\x81~\x00\xd8{"topic":"orderbook.50.BTCUSDC","ts":1698936862963,"type":"delta","data":{"s":"BTCUSDC","b":[["34958.15","0.080547"],["34942","0.0341"],["34951.27","0"]],"a":[["34966.47","0.076183"]],"u":20010221,"seq":14108040326}}'
2023-11-02 14:54:23,049 DEBUG ++Rcv decoded: fin=1 opcode=1 data=b'{"topic":"orderbook.50.BTCUSDC","ts":1698936862963,"type":"delta","data":{"s":"BTCUSDC","b":[["34958.15","0.080547"],["34942","0.0341"],["34951.27","0"]],"a":[["34966.47","0.076183"]],"u":20010221,"seq":14108040326}}'
2023-11-02 14:54:23,069 DEBUG ++Rcv raw: b'\x81~\x01\x9d{"topic":"orderbook.50.BTCUSDC","ts":1698936862983,"type":"delta","data":{"s":"BTCUSDC","b":[["34961.87","0.101887"],["34960.81","0.008756"],["34951.37","0.1875"],["34940.87","0.00154"],["34940.3","0.025298"],["34949.75","0"],["34956.24","0"],["34960.8","0"],["34954.71","0"],["34946.15","0"]],"a":[["34982.24","0.02859"],["34983.73","0.112508"],["34962.91","0"],["34966.75","0"]],"u":20010222,"seq":14108040354}}'
2023-11-02 14:54:23,069 DEBUG ++Rcv decoded: fin=1 opcode=1 data=b'{"topic":"orderbook.50.BTCUSDC","ts":1698936862983,"type":"delta","data":{"s":"BTCUSDC","b":[["34961.87","0.101887"],["34960.81","0.008756"],["34951.37","0.1875"],["34940.87","0.00154"],["34940.3","0.025298"],["34949.75","0"],["34956.24","0"],["34960.8","0"],["34954.71","0"],["34946.15","0"]],"a":[["34982.24","0.02859"],["34983.73","0.112508"],["34962.91","0"],["34966.75","0"]],"u":20010222,"seq":14108040354}}'
2023-11-02 14:54:23,089 DEBUG ++Rcv raw: b'\x81~\x01s{"topic":"orderbook.50.BTCUSDC","ts":1698936863004,"type":"delta","data":{"s":"BTCUSDC","b":[["34956.94","0.057213"],["34956.5","0.028602"],["34950.8","0.114446"],["34941.13","0.286195"],["34960.03","0"],["34950.01","0"],["34940.3","0"],["34940.87","0"]],"a":[["34963.58","0.057202"],["34968.4","0.028602"],["34966","0"],["34969.65","0"]],"u":20010223,"seq":14108040371}}'
2023-11-02 14:54:23,090 DEBUG ++Rcv decoded: fin=1 opcode=1 data=b'{"topic":"orderbook.50.BTCUSDC","ts":1698936863004,"type":"delta","data":{"s":"BTCUSDC","b":[["34956.94","0.057213"],["34956.5","0.028602"],["34950.8","0.114446"],["34941.13","0.286195"],["34960.03","0"],["34950.01","0"],["34940.3","0"],["34940.87","0"]],"a":[["34963.58","0.057202"],["34968.4","0.028602"],["34966","0"],["34969.65","0"]],"u":20010223,"seq":14108040371}}'
2023-11-02 14:54:23,110 DEBUG ++Rcv raw: b'\x81~\x01?{"topic":"orderbook.50.BTCUSDC","ts":1698936863024,"type":"delta","data":{"s":"BTCUSDC","b":[["34940.87","0.00154"],["34957.17","0"]],"a":[["34963.57","0.029816"],["34966.47","0.051544"],["34969.23","0.068639"],["34970.31","0.360085"],["34969.64","0"],["34983.73","0"],["34982.24","0"]],"u":20010224,"seq":14108040384}}'
2023-11-02 14:54:23,110 DEBUG ++Rcv decoded: fin=1 opcode=1 data=b'{"topic":"orderbook.50.BTCUSDC","ts":1698936863024,"type":"delta","data":{"s":"BTCUSDC","b":[["34940.87","0.00154"],["34957.17","0"]],"a":[["34963.57","0.029816"],["34966.47","0.051544"],["34969.23","0.068639"],["34970.31","0.360085"],["34969.64","0"],["34983.73","0"],["34982.24","0"]],"u":20010224,"seq":14108040384}}'
2023-11-02 14:54:23,129 DEBUG ++Rcv raw: b'\x81~\x00\xfd{"topic":"orderbook.50.BTCUSDC","ts":1698936863044,"type":"delta","data":{"s":"BTCUSDC","b":[["34951.38","0.00318"],["34940.87","0"]],"a":[["34969.99","0.21606"],["34971.89","0.025339"],["34971.29","0"],["34969.23","0"]],"u":20010225,"seq":14108040396}}'
2023-11-02 14:54:23,130 DEBUG ++Rcv decoded: fin=1 opcode=1 data=b'{"topic":"orderbook.50.BTCUSDC","ts":1698936863044,"type":"delta","data":{"s":"BTCUSDC","b":[["34951.38","0.00318"],["34940.87","0"]],"a":[["34969.99","0.21606"],["34971.89","0.025339"],["34971.29","0"],["34969.23","0"]],"u":20010225,"seq":14108040396}}'
2023-11-02 14:54:23,155 DEBUG ++Rcv raw: b'\x81~\x01%{"topic":"orderbook.50.BTCUSDC","ts":1698936863063,"type":"delta","data":{"s":"BTCUSDC","b":[["34940.87","0.00154"],["34940.3","0.025298"],["34953.12","0"],["34948.02","0"]],"a":[["34982.24","0.02859"],["34983.73","0.112508"],["34970.31","0"],["34971.89","0"]],"u":20010226,"seq":14108040413}}'
2023-11-02 14:54:23,155 DEBUG ++Rcv decoded: fin=1 opcode=1 data=b'{"topic":"orderbook.50.BTCUSDC","ts":1698936863063,"type":"delta","data":{"s":"BTCUSDC","b":[["34940.87","0.00154"],["34940.3","0.025298"],["34953.12","0"],["34948.02","0"]],"a":[["34982.24","0.02859"],["34983.73","0.112508"],["34970.31","0"],["34971.89","0"]],"u":20010226,"seq":14108040413}}'
2023-11-02 14:54:23,169 DEBUG ++Rcv raw: b'\x81~\x01@{"topic":"orderbook.50.BTCUSDC","ts":1698936863083,"type":"delta","data":{"s":"BTCUSDC","b":[["34961.88","0.008756"],["34949.55","0.362783"],["34948.03","0"],["34960.81","0"]],"a":[["34962.89","0.000001"],["34969.23","0.068632"],["34971.89","0.051542"],["34969.99","0"],["34983.73","0"]],"u":20010227,"seq":14108040436}}'
2023-11-02 14:54:23,169 DEBUG ++Rcv decoded: fin=1 opcode=1 data=b'{"topic":"orderbook.50.BTCUSDC","ts":1698936863083,"type":"delta","data":{"s":"BTCUSDC","b":[["34961.88","0.008756"],["34949.55","0.362783"],["34948.03","0"],["34960.81","0"]],"a":[["34962.89","0.000001"],["34969.23","0.068632"],["34971.89","0.051542"],["34969.99","0"],["34983.73","0"]],"u":20010227,"seq":14108040436}}'
2023-11-02 14:54:23,191 DEBUG ++Rcv raw: b'\x81~\x00\xbf{"topic":"orderbook.50.BTCUSDC","ts":1698936863104,"type":"delta","data":{"s":"BTCUSDC","b":[["34961.87","0.002"],["34943.37","0.028"],["34940.3","0"]],"a":[],"u":20010228,"seq":14108040448}}'
2023-11-02 14:54:23,191 DEBUG ++Rcv decoded: fin=1 opcode=1 data=b'{"topic":"orderbook.50.BTCUSDC","ts":1698936863104,"type":"delta","data":{"s":"BTCUSDC","b":[["34961.87","0.002"],["34943.37","0.028"],["34940.3","0"]],"a":[],"u":20010228,"seq":14108040448}}'
2023-11-02 14:54:23,249 DEBUG ++Rcv raw: b'\x81~\x01?{"topic":"orderbook.50.BTCUSDC","ts":1698936863163,"type":"delta","data":{"s":"BTCUSDC","b":[["34957.37","0.057212"],["34942.1","0.286187"],["34956.94","0"],["34941.13","0"]],"a":[["34964.03","0.057201"],["34970.18","0.200283"],["34983.73","0.112508"],["34963.58","0"],["34969.24","0"]],"u":20010229,"seq":14108040484}}'
2023-11-02 14:54:23,249 DEBUG ++Rcv decoded: fin=1 opcode=1 data=b'{"topic":"orderbook.50.BTCUSDC","ts":1698936863163,"type":"delta","data":{"s":"BTCUSDC","b":[["34957.37","0.057212"],["34942.1","0.286187"],["34956.94","0"],["34941.13","0"]],"a":[["34964.03","0.057201"],["34970.18","0.200283"],["34983.73","0.112508"],["34963.58","0"],["34969.24","0"]],"u":20010229,"seq":14108040484}}'
2023-11-02 14:54:23,270 DEBUG ++Rcv raw: b'\x81~\x01H{"topic":"orderbook.50.BTCUSDC","ts":1698936863184,"type":"delta","data":{"s":"BTCUSDC","b":[["34960","0.0324"],["34940.87","0"]],"a":[["34964.02","0.034325"],["34969.99","0.120173"],["34978.78","0.0859"],["34983.74","0.1875"],["34963.57","0"],["34962.89","0"],["34971.89","0"],["34969.23","0"]],"u":20010230,"seq":14108040505}}'
2023-11-02 14:54:23,270 DEBUG ++Rcv decoded: fin=1 opcode=1 data=b'{"topic":"orderbook.50.BTCUSDC","ts":1698936863184,"type":"delta","data":{"s":"BTCUSDC","b":[["34960","0.0324"],["34940.87","0"]],"a":[["34964.02","0.034325"],["34969.99","0.120173"],["34978.78","0.0859"],["34983.74","0.1875"],["34963.57","0"],["34962.89","0"],["34971.89","0"],["34969.23","0"]],"u":20010230,"seq":14108040505}}'
2023-11-02 14:54:23,289 DEBUG ++Rcv raw: b'\x81~\x00\xee{"topic":"orderbook.50.BTCUSDC","ts":1698936863204,"type":"delta","data":{"s":"BTCUSDC","b":[["34961.88","0.008518"]],"a":[["34972.86","0.092373"],["34983.35","0.175365"],["34983.73","0"],["34983.74","0"]],"u":20010231,"seq":14108040517}}'
2023-11-02 14:54:23,290 DEBUG ++Rcv decoded: fin=1 opcode=1 data=b'{"topic":"orderbook.50.BTCUSDC","ts":1698936863204,"type":"delta","data":{"s":"BTCUSDC","b":[["34961.88","0.008518"]],"a":[["34972.86","0.092373"],["34983.35","0.175365"],["34983.73","0"],["34983.74","0"]],"u":20010231,"seq":14108040517}}'
2023-11-02 14:54:23,309 DEBUG ++Rcv raw: b'\x81~\x00\xc4{"topic":"orderbook.50.BTCUSDC","ts":1698936863223,"type":"delta","data":{"s":"BTCUSDC","b":[["34961.88","0.03712"],["34940.87","0.00154"],["34961.87","0"]],"a":[],"u":20010232,"seq":14108040523}}'
2023-11-02 14:54:23,309 DEBUG ++Rcv decoded: fin=1 opcode=1 data=b'{"topic":"orderbook.50.BTCUSDC","ts":1698936863223,"type":"delta","data":{"s":"BTCUSDC","b":[["34961.88","0.03712"],["34940.87","0.00154"],["34961.87","0"]],"a":[],"u":20010232,"seq":14108040523}}'
2023-11-02 14:54:23,349 DEBUG ++Rcv raw: b'\x81~\x00\xab{"topic":"orderbook.50.BTCUSDC","ts":1698936863263,"type":"delta","data":{"s":"BTCUSDC","b":[["34954.63","0.036"],["34951.85","0"]],"a":[],"u":20010233,"seq":14108040539}}'
2023-11-02 14:54:23,349 DEBUG ++Rcv decoded: fin=1 opcode=1 data=b'{"topic":"orderbook.50.BTCUSDC","ts":1698936863263,"type":"delta","data":{"s":"BTCUSDC","b":[["34954.63","0.036"],["34951.85","0"]],"a":[],"u":20010233,"seq":14108040539}}'
2023-11-02 14:54:23,369 DEBUG ++Rcv raw: b'\x81~\x00\xd5{"topic":"orderbook.50.BTCUSDC","ts":1698936863283,"type":"delta","data":{"s":"BTCUSDC","b":[["34957.3","0.022334"],["34940.87","0"]],"a":[["34964.01","0.022318"],["34983.35","0"]],"u":20010234,"seq":14108040549}}'
2023-11-02 14:54:23,369 DEBUG ++Rcv decoded: fin=1 opcode=1 data=b'{"topic":"orderbook.50.BTCUSDC","ts":1698936863283,"type":"delta","data":{"s":"BTCUSDC","b":[["34957.3","0.022334"],["34940.87","0"]],"a":[["34964.01","0.022318"],["34983.35","0"]],"u":20010234,"seq":14108040549}}'
2023-11-02 14:54:23,388 DEBUG ++Rcv raw: b'\x81~\x00\xae{"topic":"orderbook.50.BTCUSDC","ts":1698936863303,"type":"delta","data":{"s":"BTCUSDC","b":[],"a":[["34971.89","0.371522"],["34982.24","0"]],"u":20010235,"seq":14108040554}}'
2023-11-02 14:54:23,389 DEBUG ++Rcv decoded: fin=1 opcode=1 data=b'{"topic":"orderbook.50.BTCUSDC","ts":1698936863303,"type":"delta","data":{"s":"BTCUSDC","b":[],"a":[["34971.89","0.371522"],["34982.24","0"]],"u":20010235,"seq":14108040554}}'
2023-11-02 14:54:23,409 DEBUG ++Rcv raw: b'\x81~\x00\xc5{"topic":"orderbook.50.BTCUSDC","ts":1698936863324,"type":"delta","data":{"s":"BTCUSDC","b":[["34961.88","0.008518"]],"a":[["34971.88","0.222919"],["34981.28","0"]],"u":20010236,"seq":14108040556}}'
2023-11-02 14:54:23,409 DEBUG ++Rcv decoded: fin=1 opcode=1 data=b'{"topic":"orderbook.50.BTCUSDC","ts":1698936863324,"type":"delta","data":{"s":"BTCUSDC","b":[["34961.88","0.008518"]],"a":[["34971.88","0.222919"],["34981.28","0"]],"u":20010236,"seq":14108040556}}'
2023-11-02 14:54:23,429 DEBUG ++Rcv raw: b'\x81~\x00\xed{"topic":"orderbook.50.BTCUSDC","ts":1698936863344,"type":"delta","data":{"s":"BTCUSDC","b":[["34961.88","0.011518"],["34940.87","0.00154"],["34946.38","0"]],"a":[["34971.42","0.000238"],["34980.48","0"]],"u":20010237,"seq":14108040563}}'
2023-11-02 14:54:23,429 DEBUG ++Rcv decoded: fin=1 opcode=1 data=b'{"topic":"orderbook.50.BTCUSDC","ts":1698936863344,"type":"delta","data":{"s":"BTCUSDC","b":[["34961.88","0.011518"],["34940.87","0.00154"],["34946.38","0"]],"a":[["34971.42","0.000238"],["34980.48","0"]],"u":20010237,"seq":14108040563}}'
2023-11-02 14:54:23,449 DEBUG ++Rcv raw: b'\x81~\x00\xae{"topic":"orderbook.50.BTCUSDC","ts":1698936863363,"type":"delta","data":{"s":"BTCUSDC","b":[],"a":[["34980.48","0.023472"],["34971.89","0"]],"u":20010238,"seq":14108040567}}'
2023-11-02 14:54:23,449 DEBUG ++Rcv decoded: fin=1 opcode=1 data=b'{"topic":"orderbook.50.BTCUSDC","ts":1698936863363,"type":"delta","data":{"s":"BTCUSDC","b":[],"a":[["34980.48","0.023472"],["34971.89","0"]],"u":20010238,"seq":14108040567}}'
2023-11-02 14:54:23,469 DEBUG ++Rcv raw: b'\x81~\x00\xae{"topic":"orderbook.50.BTCUSDC","ts":1698936863384,"type":"delta","data":{"s":"BTCUSDC","b":[],"a":[["34981.28","0.000562"],["34971.88","0"]],"u":20010239,"seq":14108040569}}'
2023-11-02 14:54:23,469 DEBUG ++Rcv decoded: fin=1 opcode=1 data=b'{"topic":"orderbook.50.BTCUSDC","ts":1698936863384,"type":"delta","data":{"s":"BTCUSDC","b":[],"a":[["34981.28","0.000562"],["34971.88","0"]],"u":20010239,"seq":14108040569}}'
2023-11-02 14:54:23,489 DEBUG ++Rcv raw: b'\x81~\x00\xd7{"topic":"orderbook.50.BTCUSDC","ts":1698936863404,"type":"delta","data":{"s":"BTCUSDC","b":[["34961.89","0.028602"],["34957.79","0.057211"],["34957.37","0"],["34940.87","0"]],"a":[],"u":20010240,"seq":14108040575}}'
2023-11-02 14:54:23,489 DEBUG ++Rcv decoded: fin=1 opcode=1 data=b'{"topic":"orderbook.50.BTCUSDC","ts":1698936863404,"type":"delta","data":{"s":"BTCUSDC","b":[["34961.89","0.028602"],["34957.79","0.057211"],["34957.37","0"],["34940.87","0"]],"a":[],"u":20010240,"seq":14108040575}}'
2023-11-02 14:54:23,509 DEBUG ++Rcv raw: b'\x81~\x00\x9d{"topic":"orderbook.50.BTCUSDC","ts":1698936863424,"type":"delta","data":{"s":"BTCUSDC","b":[["34958.15","0.110833"]],"a":[],"u":20010241,"seq":14108040577}}'
2023-11-02 14:54:23,509 DEBUG ++Rcv decoded: fin=1 opcode=1 data=b'{"topic":"orderbook.50.BTCUSDC","ts":1698936863424,"type":"delta","data":{"s":"BTCUSDC","b":[["34958.15","0.110833"]],"a":[],"u":20010241,"seq":14108040577}}'
2023-11-02 14:54:23,530 DEBUG ++Rcv raw: b'\x81~\x00\xc3{"topic":"orderbook.50.BTCUSDC","ts":1698936863444,"type":"delta","data":{"s":"BTCUSDC","b":[["34961.88","0.008518"],["34958.16","0.000352"],["34942","0"]],"a":[],"u":20010242,"seq":14108040586}}'
2023-11-02 14:54:23,530 DEBUG ++Rcv decoded: fin=1 opcode=1 data=b'{"topic":"orderbook.50.BTCUSDC","ts":1698936863444,"type":"delta","data":{"s":"BTCUSDC","b":[["34961.88","0.008518"],["34958.16","0.000352"],["34942","0"]],"a":[],"u":20010242,"seq":14108040586}}'
2023-11-02 14:54:23,549 DEBUG ++Rcv raw: b'\x81~\x00\xd1{"topic":"orderbook.50.BTCUSDC","ts":1698936863464,"type":"delta","data":{"s":"BTCUSDC","b":[["34942","0.0341"],["34951.38","0"]],"a":[["34978.89","0.029858"],["34981.28","0"]],"u":20010243,"seq":14108040592}}'
2023-11-02 14:54:23,549 DEBUG ++Rcv decoded: fin=1 opcode=1 data=b'{"topic":"orderbook.50.BTCUSDC","ts":1698936863464,"type":"delta","data":{"s":"BTCUSDC","b":[["34942","0.0341"],["34951.38","0"]],"a":[["34978.89","0.029858"],["34981.28","0"]],"u":20010243,"seq":14108040592}}'
2023-11-02 14:54:23,609 DEBUG ++Rcv raw: b'\x81~\x00\xae{"topic":"orderbook.50.BTCUSDC","ts":1698936863524,"type":"delta","data":{"s":"BTCUSDC","b":[],"a":[["34972.13","0.000237"],["34980.48","0"]],"u":20010244,"seq":14108040606}}'
2023-11-02 14:54:23,610 DEBUG ++Rcv decoded: fin=1 opcode=1 data=b'{"topic":"orderbook.50.BTCUSDC","ts":1698936863524,"type":"delta","data":{"s":"BTCUSDC","b":[],"a":[["34972.13","0.000237"],["34980.48","0"]],"u":20010244,"seq":14108040606}}'
2023-11-02 14:54:23,629 DEBUG ++Rcv raw: b'\x81~\x00\xab{"topic":"orderbook.50.BTCUSDC","ts":1698936863544,"type":"delta","data":{"s":"BTCUSDC","b":[["34949.56","0.217677"],["34942","0"]],"a":[],"u":20010245,"seq":14108040610}}'
2023-11-02 14:54:23,629 DEBUG ++Rcv decoded: fin=1 opcode=1 data=b'{"topic":"orderbook.50.BTCUSDC","ts":1698936863544,"type":"delta","data":{"s":"BTCUSDC","b":[["34949.56","0.217677"],["34942","0"]],"a":[],"u":20010245,"seq":14108040610}}'
2023-11-02 14:54:23,709 DEBUG ++Rcv raw: b'\x81~\x00\x9d{"topic":"orderbook.50.BTCUSDC","ts":1698936863624,"type":"delta","data":{"s":"BTCUSDC","b":[],"a":[["34971.42","0.365981"]],"u":20010246,"seq":14108040625}}'
2023-11-02 14:54:23,709 DEBUG ++Rcv decoded: fin=1 opcode=1 data=b'{"topic":"orderbook.50.BTCUSDC","ts":1698936863624,"type":"delta","data":{"s":"BTCUSDC","b":[],"a":[["34971.42","0.365981"]],"u":20010246,"seq":14108040625}}'
2023-11-02 14:54:23,729 DEBUG ++Rcv raw: b'\x81~\x00\xd0{"topic":"orderbook.50.BTCUSDC","ts":1698936863644,"type":"delta","data":{"s":"BTCUSDC","b":[["34942","0.0341"],["34961.88","0"]],"a":[["34971.41","0.219588"],["34978.9","0"]],"u":20010247,"seq":14108040628}}'
2023-11-02 14:54:23,730 DEBUG ++Rcv decoded: fin=1 opcode=1 data=b'{"topic":"orderbook.50.BTCUSDC","ts":1698936863644,"type":"delta","data":{"s":"BTCUSDC","b":[["34942","0.0341"],["34961.88","0"]],"a":[["34971.41","0.219588"],["34978.9","0"]],"u":20010247,"seq":14108040628}}'
2023-11-02 14:54:23,749 DEBUG ++Rcv raw: b'\x81~\x00\xab{"topic":"orderbook.50.BTCUSDC","ts":1698936863664,"type":"delta","data":{"s":"BTCUSDC","b":[],"a":[["34964","0.000238"],["34978.89","0"]],"u":20010248,"seq":14108040630}}'
2023-11-02 14:54:23,750 DEBUG ++Rcv decoded: fin=1 opcode=1 data=b'{"topic":"orderbook.50.BTCUSDC","ts":1698936863664,"type":"delta","data":{"s":"BTCUSDC","b":[],"a":[["34964","0.000238"],["34978.89","0"]],"u":20010248,"seq":14108040630}}'
2023-11-02 14:54:23,769 DEBUG ++Rcv raw: b'\x81~\x00\xc6{"topic":"orderbook.50.BTCUSDC","ts":1698936863684,"type":"delta","data":{"s":"BTCUSDC","b":[["34961.89","0.000002"],["34951.38","0.112501"],["34951.37","0"]],"a":[],"u":20010249,"seq":14108040637}}'
2023-11-02 14:54:23,770 DEBUG ++Rcv decoded: fin=1 opcode=1 data=b'{"topic":"orderbook.50.BTCUSDC","ts":1698936863684,"type":"delta","data":{"s":"BTCUSDC","b":[["34961.89","0.000002"],["34951.38","0.112501"],["34951.37","0"]],"a":[],"u":20010249,"seq":14108040637}}'
2023-11-02 14:54:23,790 DEBUG ++Rcv raw: b'\x81~\x02\x1a{"topic":"orderbook.50.BTCUSDC","ts":1698936863704,"type":"delta","data":{"s":"BTCUSDC","b":[["34962.25","0.1092"],["34960.01","0.008518"],["34960","0.05683"],["34959.86","0.0859"],["34951.39","0.1875"],["34951.38","0.068669"],["34942.1","0"],["34961.89","0"],["34957.79","0"],["34950.8","0"]],"a":[["34964","0.023215"],["34970.18","0.0859"],["34978.89","0.029858"],["34978.9","0.002162"],["34980.48","0.023472"],["34981.28","0.000562"],["34964.02","0"],["34964.03","0"],["34976.72","0"],["34978.76","0"]],"u":20010250,"seq":14108040664}}'
2023-11-02 14:54:23,790 DEBUG ++Rcv decoded: fin=1 opcode=1 data=b'{"topic":"orderbook.50.BTCUSDC","ts":1698936863704,"type":"delta","data":{"s":"BTCUSDC","b":[["34962.25","0.1092"],["34960.01","0.008518"],["34960","0.05683"],["34959.86","0.0859"],["34951.39","0.1875"],["34951.38","0.068669"],["34942.1","0"],["34961.89","0"],["34957.79","0"],["34950.8","0"]],"a":[["34964","0.023215"],["34970.18","0.0859"],["34978.89","0.029858"],["34978.9","0.002162"],["34980.48","0.023472"],["34981.28","0.000562"],["34964.02","0"],["34964.03","0"],["34976.72","0"],["34978.76","0"]],"u":20010250,"seq":14108040664}}'
2023-11-02 14:54:23,808 DEBUG ++Rcv raw: b'\x81~\x01\xec{"topic":"orderbook.50.BTCUSDC","ts":1698936863723,"type":"delta","data":{"s":"BTCUSDC","b":[["34958.89","0.05721"],["34952.07","0.114442"],["34951.4","0.112504"],["34943.02","0.28618"],["34942","0"],["34951.38","0"],["34942.2","0"],["34953.11","0"]],"a":[["34965.76","0.057198"],["34968.52","0.04507"],["34969.99","0.051545"],["34971.16","0.114379"],["34971.2","0.03"],["34981.23","0.285867"],["34966.74","0"],["34981.28","0"],["34967.23","0"],["34964","0"]],"u":20010251,"seq":14108040690}}'
2023-11-02 14:54:23,809 DEBUG ++Rcv decoded: fin=1 opcode=1 data=b'{"topic":"orderbook.50.BTCUSDC","ts":1698936863723,"type":"delta","data":{"s":"BTCUSDC","b":[["34958.89","0.05721"],["34952.07","0.114442"],["34951.4","0.112504"],["34943.02","0.28618"],["34942","0"],["34951.38","0"],["34942.2","0"],["34953.11","0"]],"a":[["34965.76","0.057198"],["34968.52","0.04507"],["34969.99","0.051545"],["34971.16","0.114379"],["34971.2","0.03"],["34981.23","0.285867"],["34966.74","0"],["34981.28","0"],["34967.23","0"],["34964","0"]],"u":20010251,"seq":14108040690}}'
2023-11-02 14:54:23,829 DEBUG ++Rcv raw: b'\x81~\x01\xc8{"topic":"orderbook.50.BTCUSDC","ts":1698936863743,"type":"delta","data":{"s":"BTCUSDC","b":[["34962.26","0.008756"],["34954.73","0.002064"],["34949.53","0.000264"],["34942.2","0.043599"],["34960.01","0"],["34956.5","0"],["34962.25","0"],["34958.89","0"]],"a":[["34965.75","0.034324"],["34981.28","0.000562"],["34982.24","0.02859"],["34983.35","0.175365"],["34972.13","0"],["34965.76","0"],["34966.47","0"],["34968.4","0"]],"u":20010252,"seq":14108040715}}'
2023-11-02 14:54:23,829 DEBUG ++Rcv decoded: fin=1 opcode=1 data=b'{"topic":"orderbook.50.BTCUSDC","ts":1698936863743,"type":"delta","data":{"s":"BTCUSDC","b":[["34962.26","0.008756"],["34954.73","0.002064"],["34949.53","0.000264"],["34942.2","0.043599"],["34960.01","0"],["34956.5","0"],["34962.25","0"],["34958.89","0"]],"a":[["34965.75","0.034324"],["34981.28","0.000562"],["34982.24","0.02859"],["34983.35","0.175365"],["34972.13","0"],["34965.76","0"],["34966.47","0"],["34968.4","0"]],"u":20010252,"seq":14108040715}}'
2023-11-02 14:54:23,849 DEBUG ++Rcv raw: b'\x81~\x01\xbd{"topic":"orderbook.50.BTCUSDC","ts":1698936863764,"type":"delta","data":{"s":"BTCUSDC","b":[["34960.01","0.065631"],["34957.95","0.028601"],["34956.43","0.051548"],["34958.16","0"],["34958.15","0"],["34949.55","0"]],"a":[["34967.99","0.091588"],["34968.52","0.001"],["34969.79","0.028601"],["34971.42","0.000238"],["34983.73","0.112508"],["34983.74","0.1875"],["34969.99","0"],["34965.75","0"],["34964.01","0"]],"u":20010253,"seq":14108040744}}'
2023-11-02 14:54:23,849 DEBUG ++Rcv decoded: fin=1 opcode=1 data=b'{"topic":"orderbook.50.BTCUSDC","ts":1698936863764,"type":"delta","data":{"s":"BTCUSDC","b":[["34960.01","0.065631"],["34957.95","0.028601"],["34956.43","0.051548"],["34958.16","0"],["34958.15","0"],["34949.55","0"]],"a":[["34967.99","0.091588"],["34968.52","0.001"],["34969.79","0.028601"],["34971.42","0.000238"],["34983.73","0.112508"],["34983.74","0.1875"],["34969.99","0"],["34965.75","0"],["34964.01","0"]],"u":20010253,"seq":14108040744}}'
2023-11-02 14:54:23,870 DEBUG ++Rcv raw: b'\x81~\x00\xfd{"topic":"orderbook.50.BTCUSDC","ts":1698936863784,"type":"delta","data":{"s":"BTCUSDC","b":[["34957.37","0.00057"],["34949.56","0"]],"a":[["34971.15","0.068627"],["34971.37","0.00057"],["34983.74","0"],["34971.41","0"]],"u":20010254,"seq":14108040767}}'
2023-11-02 14:54:23,870 DEBUG ++Rcv decoded: fin=1 opcode=1 data=b'{"topic":"orderbook.50.BTCUSDC","ts":1698936863784,"type":"delta","data":{"s":"BTCUSDC","b":[["34957.37","0.00057"],["34949.56","0"]],"a":[["34971.15","0.068627"],["34971.37","0.00057"],["34983.74","0"],["34971.41","0"]],"u":20010254,"seq":14108040767}}'
2023-11-02 14:54:23,909 DEBUG ++Rcv raw: b'\x81~\x00\xe9{"topic":"orderbook.50.BTCUSDC","ts":1698936863823,"type":"delta","data":{"s":"BTCUSDC","b":[["34962.26","0.037358"],["34942","0.0341"],["34940.87","0.00154"],["34942.66","0"],["34943.37","0"]],"a":[],"u":20010255,"seq":14108040787}}'
2023-11-02 14:54:23,909 DEBUG ++Rcv decoded: fin=1 opcode=1 data=b'{"topic":"orderbook.50.BTCUSDC","ts":1698936863823,"type":"delta","data":{"s":"BTCUSDC","b":[["34962.26","0.037358"],["34942","0.0341"],["34940.87","0.00154"],["34942.66","0"],["34943.37","0"]],"a":[],"u":20010255,"seq":14108040787}}'
2023-11-02 14:54:23,929 DEBUG ++Rcv raw: b'\x81~\x00\xd3{"topic":"orderbook.50.BTCUSDC","ts":1698936863843,"type":"delta","data":{"s":"BTCUSDC","b":[],"a":[["34983.74","0.1875"],["34984.83","0.0002"],["34972.86","0"],["34983.35","0"]],"u":20010256,"seq":14108040797}}'
2023-11-02 14:54:23,929 DEBUG ++Rcv decoded: fin=1 opcode=1 data=b'{"topic":"orderbook.50.BTCUSDC","ts":1698936863843,"type":"delta","data":{"s":"BTCUSDC","b":[],"a":[["34983.74","0.1875"],["34984.83","0.0002"],["34972.86","0"],["34983.35","0"]],"u":20010256,"seq":14108040797}}'
2023-11-02 14:54:23,949 DEBUG ++Rcv raw: b'\x81~\x00\xd5{"topic":"orderbook.50.BTCUSDC","ts":1698936863863,"type":"delta","data":{"s":"BTCUSDC","b":[["34953.11","0.003129"],["34942.2","0"]],"a":[["34966.47","0.022318"],["34966.48","0"]],"u":20010257,"seq":14108040813}}'
2023-11-02 14:54:23,949 DEBUG ++Rcv decoded: fin=1 opcode=1 data=b'{"topic":"orderbook.50.BTCUSDC","ts":1698936863863,"type":"delta","data":{"s":"BTCUSDC","b":[["34953.11","0.003129"],["34942.2","0"]],"a":[["34966.47","0.022318"],["34966.48","0"]],"u":20010257,"seq":14108040813}}'
2023-11-02 14:54:23,969 DEBUG ++Rcv raw: b'\x81~\x00\xc5{"topic":"orderbook.50.BTCUSDC","ts":1698936863884,"type":"delta","data":{"s":"BTCUSDC","b":[["34962.26","0.040358"],["34940.3","0.025298"],["34954.73","0"]],"a":[],"u":20010258,"seq":14108040823}}'
2023-11-02 14:54:23,969 DEBUG ++Rcv decoded: fin=1 opcode=1 data=b'{"topic":"orderbook.50.BTCUSDC","ts":1698936863884,"type":"delta","data":{"s":"BTCUSDC","b":[["34962.26","0.040358"],["34940.3","0.025298"],["34954.73","0"]],"a":[],"u":20010258,"seq":14108040823}}'
2023-11-02 14:54:23,989 DEBUG ++Rcv raw: b'\x81~\x00\x9d{"topic":"orderbook.50.BTCUSDC","ts":1698936863904,"type":"delta","data":{"s":"BTCUSDC","b":[["34962.26","0.011756"]],"a":[],"u":20010259,"seq":14108040826}}'
2023-11-02 14:54:23,989 DEBUG ++Rcv decoded: fin=1 opcode=1 data=b'{"topic":"orderbook.50.BTCUSDC","ts":1698936863904,"type":"delta","data":{"s":"BTCUSDC","b":[["34962.26","0.011756"]],"a":[],"u":20010259,"seq":14108040826}}'
2023-11-02 14:54:24,009 DEBUG ++Rcv raw: b'\x81~\x00\xfe{"topic":"orderbook.50.BTCUSDC","ts":1698936863924,"type":"delta","data":{"s":"BTCUSDC","b":[["34949.77","0.000265"],["34940.3","0"]],"a":[["34971.89","0.356399"],["34978.84","0.075313"],["34984.83","0"],["34983.74","0"]],"u":20010260,"seq":14108040832}}'
2023-11-02 14:54:24,009 DEBUG ++Rcv decoded: fin=1 opcode=1 data=b'{"topic":"orderbook.50.BTCUSDC","ts":1698936863924,"type":"delta","data":{"s":"BTCUSDC","b":[["34949.77","0.000265"],["34940.3","0"]],"a":[["34971.89","0.356399"],["34978.84","0.075313"],["34984.83","0"],["34983.74","0"]],"u":20010260,"seq":14108040832}}'
2023-11-02 14:54:24,029 DEBUG ++Rcv raw: b'\x81~\x00\xff{"topic":"orderbook.50.BTCUSDC","ts":1698936863944,"type":"delta","data":{"s":"BTCUSDC","b":[["34958.09","0.057211"],["34940.87","0"]],"a":[["34965.37","0.057199"],["34971.88","0.213841"],["34983.73","0"],["34971.15","0"]],"u":20010261,"seq":14108040848}}'
2023-11-02 14:54:24,029 DEBUG ++Rcv decoded: fin=1 opcode=1 data=b'{"topic":"orderbook.50.BTCUSDC","ts":1698936863944,"type":"delta","data":{"s":"BTCUSDC","b":[["34958.09","0.057211"],["34940.87","0"]],"a":[["34965.37","0.057199"],["34971.88","0.213841"],["34983.73","0"],["34971.15","0"]],"u":20010261,"seq":14108040848}}'
2023-11-02 14:54:24,049 DEBUG ++Rcv raw: b'\x81~\x00\xc6{"topic":"orderbook.50.BTCUSDC","ts":1698936863963,"type":"delta","data":{"s":"BTCUSDC","b":[],"a":[["34965.36","0.034322"],["34967.99","0.051544"],["34966.47","0"]],"u":20010262,"seq":14108040856}}'
2023-11-02 14:54:24,049 DEBUG ++Rcv decoded: fin=1 opcode=1 data=b'{"topic":"orderbook.50.BTCUSDC","ts":1698936863963,"type":"delta","data":{"s":"BTCUSDC","b":[],"a":[["34965.36","0.034322"],["34967.99","0.051544"],["34966.47","0"]],"u":20010262,"seq":14108040856}}'
2023-11-02 14:54:24,068 DEBUG ++Rcv raw: b'\x81~\x00\xc2{"topic":"orderbook.50.BTCUSDC","ts":1698936863983,"type":"delta","data":{"s":"BTCUSDC","b":[["34955.16","0.041869"],["34942","0"]],"a":[["34967.99","0.074114"]],"u":20010263,"seq":14108040869}}'
2023-11-02 14:54:24,068 DEBUG ++Rcv decoded: fin=1 opcode=1 data=b'{"topic":"orderbook.50.BTCUSDC","ts":1698936863983,"type":"delta","data":{"s":"BTCUSDC","b":[["34955.16","0.041869"],["34942","0"]],"a":[["34967.99","0.074114"]],"u":20010263,"seq":14108040869}}'
2023-11-02 14:54:24,089 DEBUG ++Rcv raw: b'\x81~\x00\xae{"topic":"orderbook.50.BTCUSDC","ts":1698936864003,"type":"delta","data":{"s":"BTCUSDC","b":[["34962.27","0.028602"],["34943.02","0"]],"a":[],"u":20010264,"seq":14108040874}}'
2023-11-02 14:54:24,090 DEBUG ++Rcv decoded: fin=1 opcode=1 data=b'{"topic":"orderbook.50.BTCUSDC","ts":1698936864003,"type":"delta","data":{"s":"BTCUSDC","b":[["34962.27","0.028602"],["34943.02","0"]],"a":[],"u":20010264,"seq":14108040874}}'
2023-11-02 14:54:24,108 DEBUG ++Rcv raw: b'\x81~\x00\x9d{"topic":"orderbook.50.BTCUSDC","ts":1698936864023,"type":"delta","data":{"s":"BTCUSDC","b":[["34962.26","0.008756"]],"a":[],"u":20010265,"seq":14108040877}}'
2023-11-02 14:54:24,108 DEBUG ++Rcv decoded: fin=1 opcode=1 data=b'{"topic":"orderbook.50.BTCUSDC","ts":1698936864023,"type":"delta","data":{"s":"BTCUSDC","b":[["34962.26","0.008756"]],"a":[],"u":20010265,"seq":14108040877}}'
2023-11-02 14:54:24,148 DEBUG ++Rcv raw: b'\x81~\x00\xd6{"topic":"orderbook.50.BTCUSDC","ts":1698936864063,"type":"delta","data":{"s":"BTCUSDC","b":[["34950.01","0.360985"],["34943.35","0"]],"a":[["34965.35","0.022318"],["34965.37","0"]],"u":20010266,"seq":14108040896}}'
2023-11-02 14:54:24,149 DEBUG ++Rcv decoded: fin=1 opcode=1 data=b'{"topic":"orderbook.50.BTCUSDC","ts":1698936864063,"type":"delta","data":{"s":"BTCUSDC","b":[["34950.01","0.360985"],["34943.35","0"]],"a":[["34965.35","0.022318"],["34965.37","0"]],"u":20010266,"seq":14108040896}}'
2023-11-02 14:54:24,169 DEBUG ++Rcv raw: b'\x81~\x01<{"topic":"orderbook.50.BTCUSDC","ts":1698936864083,"type":"delta","data":{"s":"BTCUSDC","b":[],"a":[["34965.1","0.034324"],["34965.11","0.057199"],["34967.98","0.085126"],["34967.99","0.02257"],["34980.5","0.0859"],["34982.24","0"],["34981.23","0"],["34981.28","0"],["34965.36","0"]],"u":20010267,"seq":14108040907}}'
2023-11-02 14:54:24,169 DEBUG ++Rcv decoded: fin=1 opcode=1 data=b'{"topic":"orderbook.50.BTCUSDC","ts":1698936864083,"type":"delta","data":{"s":"BTCUSDC","b":[],"a":[["34965.1","0.034324"],["34965.11","0.057199"],["34967.98","0.085126"],["34967.99","0.02257"],["34980.5","0.0859"],["34982.24","0"],["34981.23","0"],["34981.28","0"],["34965.36","0"]],"u":20010267,"seq":14108040907}}'
2023-11-02 14:54:24,189 DEBUG ++Rcv raw: b'\x81~\x00\x9d{"topic":"orderbook.50.BTCUSDC","ts":1698936864104,"type":"delta","data":{"s":"BTCUSDC","b":[],"a":[["34967.98","0.051546"]],"u":20010268,"seq":14108040910}}'
2023-11-02 14:54:24,189 DEBUG ++Rcv decoded: fin=1 opcode=1 data=b'{"topic":"orderbook.50.BTCUSDC","ts":1698936864104,"type":"delta","data":{"s":"BTCUSDC","b":[],"a":[["34967.98","0.051546"]],"u":20010268,"seq":14108040910}}'
2023-11-02 14:54:24,209 DEBUG ++Rcv raw: b'\x81~\x00\xad{"topic":"orderbook.50.BTCUSDC","ts":1698936864124,"type":"delta","data":{"s":"BTCUSDC","b":[["34943.35","0.02598"],["34962.26","0"]],"a":[],"u":20010269,"seq":14108040922}}'
2023-11-02 14:54:24,209 DEBUG ++Rcv decoded: fin=1 opcode=1 data=b'{"topic":"orderbook.50.BTCUSDC","ts":1698936864124,"type":"delta","data":{"s":"BTCUSDC","b":[["34943.35","0.02598"],["34962.26","0"]],"a":[],"u":20010269,"seq":14108040922}}'
2023-11-02 14:54:24,230 DEBUG ++Rcv raw: b'\x81~\x00\xae{"topic":"orderbook.50.BTCUSDC","ts":1698936864144,"type":"delta","data":{"s":"BTCUSDC","b":[],"a":[["34981.23","0.285867"],["34965.35","0"]],"u":20010270,"seq":14108040927}}'
2023-11-02 14:54:24,230 DEBUG ++Rcv decoded: fin=1 opcode=1 data=b'{"topic":"orderbook.50.BTCUSDC","ts":1698936864144,"type":"delta","data":{"s":"BTCUSDC","b":[],"a":[["34981.23","0.285867"],["34965.35","0"]],"u":20010270,"seq":14108040927}}'
2023-11-02 14:54:24,249 DEBUG ++Rcv raw: b'\x81~\x00\xae{"topic":"orderbook.50.BTCUSDC","ts":1698936864163,"type":"delta","data":{"s":"BTCUSDC","b":[],"a":[["34981.28","0.000562"],["34965.11","0"]],"u":20010271,"seq":14108040931}}'
2023-11-02 14:54:24,249 DEBUG ++Rcv decoded: fin=1 opcode=1 data=b'{"topic":"orderbook.50.BTCUSDC","ts":1698936864163,"type":"delta","data":{"s":"BTCUSDC","b":[],"a":[["34981.28","0.000562"],["34965.11","0"]],"u":20010271,"seq":14108040931}}'
2023-11-02 14:54:24,269 DEBUG ++Rcv raw: b'\x81~\x00\xc5{"topic":"orderbook.50.BTCUSDC","ts":1698936864183,"type":"delta","data":{"s":"BTCUSDC","b":[],"a":[["34965.16","0.032853"],["34967.98","0.078686"],["34965.1","0"]],"u":20010272,"seq":14108040938}}'
2023-11-02 14:54:24,269 DEBUG ++Rcv decoded: fin=1 opcode=1 data=b'{"topic":"orderbook.50.BTCUSDC","ts":1698936864183,"type":"delta","data":{"s":"BTCUSDC","b":[],"a":[["34965.16","0.032853"],["34967.98","0.078686"],["34965.1","0"]],"u":20010272,"seq":14108040938}}'
2023-11-02 14:54:24,309 DEBUG ++Rcv raw: b'\x81~\x00\xad{"topic":"orderbook.50.BTCUSDC","ts":1698936864224,"type":"delta","data":{"s":"BTCUSDC","b":[["34943.02","0.28618"],["34962.27","0"]],"a":[],"u":20010273,"seq":14108040941}}'
2023-11-02 14:54:24,309 DEBUG ++Rcv decoded: fin=1 opcode=1 data=b'{"topic":"orderbook.50.BTCUSDC","ts":1698936864224,"type":"delta","data":{"s":"BTCUSDC","b":[["34943.02","0.28618"],["34962.27","0"]],"a":[],"u":20010273,"seq":14108040941}}'
2023-11-02 14:54:24,329 DEBUG ++Rcv raw: b'\x81~\x00\xfb{"topic":"orderbook.50.BTCUSDC","ts":1698936864244,"type":"delta","data":{"s":"BTCUSDC","b":[["34961.66","0.103932"],["34942.67","0.028"],["34957.37","0"],["34949.53","0"]],"a":[["34982.24","0.02859"],["34971.42","0"]],"u":20010274,"seq":14108040948}}'
2023-11-02 14:54:24,329 DEBUG ++Rcv decoded: fin=1 opcode=1 data=b'{"topic":"orderbook.50.BTCUSDC","ts":1698936864244,"type":"delta","data":{"s":"BTCUSDC","b":[["34961.66","0.103932"],["34942.67","0.028"],["34957.37","0"],["34949.53","0"]],"a":[["34982.24","0.02859"],["34971.42","0"]],"u":20010274,"seq":14108040948}}'
2023-11-02 14:54:24,349 DEBUG ++Rcv raw: b'\x81~\x00\xd6{"topic":"orderbook.50.BTCUSDC","ts":1698936864264,"type":"delta","data":{"s":"BTCUSDC","b":[["34961.67","0.008756"],["34956.77","0.00057"],["34942.67","0"],["34943.02","0"]],"a":[],"u":20010275,"seq":14108040953}}'
2023-11-02 14:54:24,349 DEBUG ++Rcv decoded: fin=1 opcode=1 data=b'{"topic":"orderbook.50.BTCUSDC","ts":1698936864264,"type":"delta","data":{"s":"BTCUSDC","b":[["34961.67","0.008756"],["34956.77","0.00057"],["34942.67","0"],["34943.02","0"]],"a":[],"u":20010275,"seq":14108040953}}'
2023-11-02 14:54:24,369 DEBUG ++Rcv raw: b'\x81~\x00\xad{"topic":"orderbook.50.BTCUSDC","ts":1698936864284,"type":"delta","data":{"s":"BTCUSDC","b":[["34943.02","0.28618"],["34961.66","0"]],"a":[],"u":20010276,"seq":14108040956}}'
2023-11-02 14:54:24,370 DEBUG ++Rcv decoded: fin=1 opcode=1 data=b'{"topic":"orderbook.50.BTCUSDC","ts":1698936864284,"type":"delta","data":{"s":"BTCUSDC","b":[["34943.02","0.28618"],["34961.66","0"]],"a":[],"u":20010276,"seq":14108040956}}'
2023-11-02 14:54:24,429 DEBUG ++Rcv raw: b'\x81~\x00\xae{"topic":"orderbook.50.BTCUSDC","ts":1698936864344,"type":"delta","data":{"s":"BTCUSDC","b":[["34954.73","0.000545"],["34943.02","0"]],"a":[],"u":20010277,"seq":14108040966}}'
2023-11-02 14:54:24,429 DEBUG ++Rcv decoded: fin=1 opcode=1 data=b'{"topic":"orderbook.50.BTCUSDC","ts":1698936864344,"type":"delta","data":{"s":"BTCUSDC","b":[["34954.73","0.000545"],["34943.02","0"]],"a":[],"u":20010277,"seq":14108040966}}'
2023-11-02 14:54:24,449 DEBUG ++Rcv raw: b'\x81~\x00\xf7{"topic":"orderbook.50.BTCUSDC","ts":1698936864364,"type":"delta","data":{"s":"BTCUSDC","b":[["34942.67","0.028"],["34942","0.0341"],["34953.11","0"],["34958.09","0"]],"a":[["34983.73","0.112508"],["34981.23","0"]],"u":20010278,"seq":14108040970}}'
2023-11-02 14:54:24,450 DEBUG ++Rcv decoded: fin=1 opcode=1 data=b'{"topic":"orderbook.50.BTCUSDC","ts":1698936864364,"type":"delta","data":{"s":"BTCUSDC","b":[["34942.67","0.028"],["34942","0.0341"],["34953.11","0"],["34958.09","0"]],"a":[["34983.73","0.112508"],["34981.23","0"]],"u":20010278,"seq":14108040970}}'
2023-11-02 14:54:24,468 DEBUG ++Rcv raw: b'\x81~\x01"{"topic":"orderbook.50.BTCUSDC","ts":1698936864383,"type":"delta","data":{"s":"BTCUSDC","b":[["34957.53","0.057212"],["34942","0"]],"a":[["34964.86","0.0572"],["34965.09","0.022318"],["34980.2","0.285876"],["34983.73","0"],["34965.16","0"],["34982.24","0"]],"u":20010279,"seq":14108040976}}'
2023-11-02 14:54:24,469 DEBUG ++Rcv decoded: fin=1 opcode=1 data=b'{"topic":"orderbook.50.BTCUSDC","ts":1698936864383,"type":"delta","data":{"s":"BTCUSDC","b":[["34957.53","0.057212"],["34942","0"]],"a":[["34964.86","0.0572"],["34965.09","0.022318"],["34980.2","0.285876"],["34983.73","0"],["34965.16","0"],["34982.24","0"]],"u":20010279,"seq":14108040976}}'
2023-11-02 14:54:24,489 DEBUG ++Rcv raw: b'\x81~\x00\xc1{"topic":"orderbook.50.BTCUSDC","ts":1698936864404,"type":"delta","data":{"s":"BTCUSDC","b":[["34961.67","0.011756"],["34942","0.0341"],["34949.77","0"]],"a":[],"u":20010280,"seq":14108040981}}'
2023-11-02 14:54:24,489 DEBUG ++Rcv decoded: fin=1 opcode=1 data=b'{"topic":"orderbook.50.BTCUSDC","ts":1698936864404,"type":"delta","data":{"s":"BTCUSDC","b":[["34961.67","0.011756"],["34942","0.0341"],["34949.77","0"]],"a":[],"u":20010280,"seq":14108040981}}'
2023-11-02 14:54:24,549 DEBUG ++Rcv raw: b'\x81~\x00\xab{"topic":"orderbook.50.BTCUSDC","ts":1698936864463,"type":"delta","data":{"s":"BTCUSDC","b":[["34960.02","0.028604"],["34942","0"]],"a":[],"u":20010281,"seq":14108040983}}'
2023-11-02 14:54:24,549 DEBUG ++Rcv decoded: fin=1 opcode=1 data=b'{"topic":"orderbook.50.BTCUSDC","ts":1698936864463,"type":"delta","data":{"s":"BTCUSDC","b":[["34960.02","0.028604"],["34942","0"]],"a":[],"u":20010281,"seq":14108040983}}'
2023-11-02 14:54:24,568 DEBUG ++Rcv raw: b'\x81~\x00\xad{"topic":"orderbook.50.BTCUSDC","ts":1698936864483,"type":"delta","data":{"s":"BTCUSDC","b":[],"a":[["34982.24","0.02859"],["34965.09","0"]],"u":20010282,"seq":14108040991}}'
2023-11-02 14:54:24,569 DEBUG ++Rcv decoded: fin=1 opcode=1 data=b'{"topic":"orderbook.50.BTCUSDC","ts":1698936864483,"type":"delta","data":{"s":"BTCUSDC","b":[],"a":[["34982.24","0.02859"],["34965.09","0"]],"u":20010282,"seq":14108040991}}'
2023-11-02 14:54:24,649 DEBUG ++Rcv raw: b'\x81~\x00\xa9{"topic":"orderbook.50.BTCUSDC","ts":1698936864564,"type":"delta","data":{"s":"BTCUSDC","b":[["34942","0.0341"],["34960.02","0"]],"a":[],"u":20010283,"seq":14108041014}}'
2023-11-02 14:54:24,650 DEBUG ++Rcv decoded: fin=1 opcode=1 data=b'{"topic":"orderbook.50.BTCUSDC","ts":1698936864564,"type":"delta","data":{"s":"BTCUSDC","b":[["34942","0.0341"],["34960.02","0"]],"a":[],"u":20010283,"seq":14108041014}}'
2023-11-02 14:54:24,670 DEBUG ++Rcv raw: b'\x81~\x00\xea{"topic":"orderbook.50.BTCUSDC","ts":1698936864584,"type":"delta","data":{"s":"BTCUSDC","b":[["34950.02","0.216599"],["34942","0"]],"a":[["34964.85","0.022318"],["34972.04","0.04247"],["34982.24","0"]],"u":20010284,"seq":14108041036}}'
2023-11-02 14:54:24,670 DEBUG ++Rcv decoded: fin=1 opcode=1 data=b'{"topic":"orderbook.50.BTCUSDC","ts":1698936864584,"type":"delta","data":{"s":"BTCUSDC","b":[["34950.02","0.216599"],["34942","0"]],"a":[["34964.85","0.022318"],["34972.04","0.04247"],["34982.24","0"]],"u":20010284,"seq":14108041036}}'
2023-11-02 14:54:24,690 DEBUG ++Rcv raw: b'\x81~\x01\x12{"topic":"orderbook.50.BTCUSDC","ts":1698936864604,"type":"delta","data":{"s":"BTCUSDC","b":[["34962.09","0.008756"],["34962.08","0.106562"],["34961.67","0.003"],["34943.35","0"],["34942.67","0"]],"a":[["34964.75","0.0572"],["34964.86","0"]],"u":20010285,"seq":14108041050}}'
2023-11-02 14:54:24,690 DEBUG ++Rcv decoded: fin=1 opcode=1 data=b'{"topic":"orderbook.50.BTCUSDC","ts":1698936864604,"type":"delta","data":{"s":"BTCUSDC","b":[["34962.09","0.008756"],["34962.08","0.106562"],["34961.67","0.003"],["34943.35","0"],["34942.67","0"]],"a":[["34964.75","0.0572"],["34964.86","0"]],"u":20010285,"seq":14108041050}}'
2023-11-02 14:54:24,709 DEBUG ++Rcv raw: b'\x81~\x01\x1e{"topic":"orderbook.50.BTCUSDC","ts":1698936864623,"type":"delta","data":{"s":"BTCUSDC","b":[["34943.35","0.02598"],["34942.67","0.028"],["34942","0.0341"],["34956.77","0"],["34962.08","0"],["34961.67","0"]],"a":[["34982.24","0.02859"],["34971.37","0"]],"u":20010286,"seq":14108041061}}'
2023-11-02 14:54:24,709 DEBUG ++Rcv decoded: fin=1 opcode=1 data=b'{"topic":"orderbook.50.BTCUSDC","ts":1698936864623,"type":"delta","data":{"s":"BTCUSDC","b":[["34943.35","0.02598"],["34942.67","0.028"],["34942","0.0341"],["34956.77","0"],["34962.08","0"],["34961.67","0"]],"a":[["34982.24","0.02859"],["34971.37","0"]],"u":20010286,"seq":14108041061}}'
2023-11-02 14:54:24,728 DEBUG ++Rcv raw: b'\x81~\x00\xab{"topic":"orderbook.50.BTCUSDC","ts":1698936864643,"type":"delta","data":{"s":"BTCUSDC","b":[["34953.11","0.002176"],["34942","0"]],"a":[],"u":20010287,"seq":14108041063}}'
2023-11-02 14:54:24,729 DEBUG ++Rcv decoded: fin=1 opcode=1 data=b'{"topic":"orderbook.50.BTCUSDC","ts":1698936864643,"type":"delta","data":{"s":"BTCUSDC","b":[["34953.11","0.002176"],["34942","0"]],"a":[],"u":20010287,"seq":14108041063}}'
2023-11-02 14:54:24,749 DEBUG ++Rcv raw: b'\x81~\x00\xa9{"topic":"orderbook.50.BTCUSDC","ts":1698936864663,"type":"delta","data":{"s":"BTCUSDC","b":[["34942","0.0341"],["34954.73","0"]],"a":[],"u":20010288,"seq":14108041065}}'
2023-11-02 14:54:24,749 DEBUG ++Rcv decoded: fin=1 opcode=1 data=b'{"topic":"orderbook.50.BTCUSDC","ts":1698936864663,"type":"delta","data":{"s":"BTCUSDC","b":[["34942","0.0341"],["34954.73","0"]],"a":[],"u":20010288,"seq":14108041065}}'
2023-11-02 14:54:24,789 DEBUG ++Rcv raw: b'\x81~\x00\xae{"topic":"orderbook.50.BTCUSDC","ts":1698936864704,"type":"delta","data":{"s":"BTCUSDC","b":[],"a":[["34983.73","0.112508"],["34964.85","0"]],"u":20010289,"seq":14108041071}}'
2023-11-02 14:54:24,790 DEBUG ++Rcv decoded: fin=1 opcode=1 data=b'{"topic":"orderbook.50.BTCUSDC","ts":1698936864704,"type":"delta","data":{"s":"BTCUSDC","b":[],"a":[["34983.73","0.112508"],["34964.85","0"]],"u":20010289,"seq":14108041071}}'
2023-11-02 14:54:24,829 DEBUG ++Rcv raw: b'\x81~\x00\xae{"topic":"orderbook.50.BTCUSDC","ts":1698936864744,"type":"delta","data":{"s":"BTCUSDC","b":[["34941.89","0.286189"],["34942.67","0"]],"a":[],"u":20010290,"seq":14108041074}}'
2023-11-02 14:54:24,830 DEBUG ++Rcv decoded: fin=1 opcode=1 data=b'{"topic":"orderbook.50.BTCUSDC","ts":1698936864744,"type":"delta","data":{"s":"BTCUSDC","b":[["34941.89","0.286189"],["34942.67","0"]],"a":[],"u":20010290,"seq":14108041074}}'
2023-11-02 14:54:24,869 DEBUG ++Rcv raw: b'\x81~\x00\xae{"topic":"orderbook.50.BTCUSDC","ts":1698936864784,"type":"delta","data":{"s":"BTCUSDC","b":[],"a":[["34964.74","0.022318"],["34983.73","0"]],"u":20010291,"seq":14108041085}}'
2023-11-02 14:54:24,870 DEBUG ++Rcv decoded: fin=1 opcode=1 data=b'{"topic":"orderbook.50.BTCUSDC","ts":1698936864784,"type":"delta","data":{"s":"BTCUSDC","b":[],"a":[["34964.74","0.022318"],["34983.73","0"]],"u":20010291,"seq":14108041085}}'
2023-11-02 14:54:24,888 DEBUG ++Rcv raw: b'\x81~\x00\xd6{"topic":"orderbook.50.BTCUSDC","ts":1698936864803,"type":"delta","data":{"s":"BTCUSDC","b":[["34961.68","0.028602"],["34941.89","0"]],"a":[["34972.01","0.000236"],["34982.24","0"]],"u":20010292,"seq":14108041091}}'
2023-11-02 14:54:24,889 DEBUG ++Rcv decoded: fin=1 opcode=1 data=b'{"topic":"orderbook.50.BTCUSDC","ts":1698936864803,"type":"delta","data":{"s":"BTCUSDC","b":[["34961.68","0.028602"],["34941.89","0"]],"a":[["34972.01","0.000236"],["34982.24","0"]],"u":20010292,"seq":14108041091}}'
2023-11-02 14:54:24,949 DEBUG ++Rcv raw: b'\x81~\x00\xad{"topic":"orderbook.50.BTCUSDC","ts":1698936864864,"type":"delta","data":{"s":"BTCUSDC","b":[],"a":[["34982.24","0.02859"],["34964.75","0"]],"u":20010293,"seq":14108041106}}'
2023-11-02 14:54:24,949 DEBUG ++Rcv decoded: fin=1 opcode=1 data=b'{"topic":"orderbook.50.BTCUSDC","ts":1698936864864,"type":"delta","data":{"s":"BTCUSDC","b":[],"a":[["34982.24","0.02859"],["34964.75","0"]],"u":20010293,"seq":14108041106}}'
2023-11-02 14:54:24,969 DEBUG ++Rcv raw: b'\x81~\x00\xac{"topic":"orderbook.50.BTCUSDC","ts":1698936864883,"type":"delta","data":{"s":"BTCUSDC","b":[],"a":[["34964.58","0.0572"],["34982.24","0"]],"u":20010294,"seq":14108041114}}'
2023-11-02 14:54:24,970 DEBUG ++Rcv decoded: fin=1 opcode=1 data=b'{"topic":"orderbook.50.BTCUSDC","ts":1698936864883,"type":"delta","data":{"s":"BTCUSDC","b":[],"a":[["34964.58","0.0572"],["34982.24","0"]],"u":20010294,"seq":14108041114}}'
2023-11-02 14:54:24,988 DEBUG ++Rcv raw: b'\x81~\x00\xc6{"topic":"orderbook.50.BTCUSDC","ts":1698936864903,"type":"delta","data":{"s":"BTCUSDC","b":[["34962.36","0.107532"],["34962.09","0.011756"],["34961.68","0"]],"a":[],"u":20010295,"seq":14108041129}}'
2023-11-02 14:54:24,989 DEBUG ++Rcv decoded: fin=1 opcode=1 data=b'{"topic":"orderbook.50.BTCUSDC","ts":1698936864903,"type":"delta","data":{"s":"BTCUSDC","b":[["34962.36","0.107532"],["34962.09","0.011756"],["34961.68","0"]],"a":[],"u":20010295,"seq":14108041129}}'
2023-11-02 14:54:25,049 DEBUG ++Rcv raw: b'\x81~\x00\xa8{"topic":"orderbook.50.BTCUSDC","ts":1698936864964,"type":"delta","data":{"s":"BTCUSDC","b":[["34943.37","0.028"],["34942","0"]],"a":[],"u":20010296,"seq":14108041140}}'
2023-11-02 14:54:25,050 DEBUG ++Rcv decoded: fin=1 opcode=1 data=b'{"topic":"orderbook.50.BTCUSDC","ts":1698936864964,"type":"delta","data":{"s":"BTCUSDC","b":[["34943.37","0.028"],["34942","0"]],"a":[],"u":20010296,"seq":14108041140}}'
2023-11-02 14:54:25,069 DEBUG ++Rcv raw: b'\x81~\x01d{"topic":"orderbook.50.BTCUSDC","ts":1698936864984,"type":"delta","data":{"s":"BTCUSDC","b":[["34962.37","0.008756"],["34962.1","0.028602"],["34962.09","0.003"],["34951.05","0.114445"],["34952.07","0"],["34943.36","0"],["34943.35","0"]],"a":[["34982.24","0.02859"],["34983.73","0.112508"],["34964.58","0"],["34964.74","0"]],"u":20010297,"seq":14108041157}}'
2023-11-02 14:54:25,069 DEBUG ++Rcv decoded: fin=1 opcode=1 data=b'{"topic":"orderbook.50.BTCUSDC","ts":1698936864984,"type":"delta","data":{"s":"BTCUSDC","b":[["34962.37","0.008756"],["34962.1","0.028602"],["34962.09","0.003"],["34951.05","0.114445"],["34952.07","0"],["34943.36","0"],["34943.35","0"]],"a":[["34982.24","0.02859"],["34983.73","0.112508"],["34964.58","0"],["34964.74","0"]],"u":20010297,"seq":14108041157}}'
2023-11-02 14:54:25,089 DEBUG ++Rcv raw: b'\x81~\x00\xfc{"topic":"orderbook.50.BTCUSDC","ts":1698936865004,"type":"delta","data":{"s":"BTCUSDC","b":[["34962.38","0.026903"],["34957.48","0.00057"],["34962.09","0"],["34962.36","0"]],"a":[["34983.74","0.1875"],["34973.48","0"]],"u":20010298,"seq":14108041171}}'
2023-11-02 14:54:25,089 DEBUG ++Rcv decoded: fin=1 opcode=1 data=b'{"topic":"orderbook.50.BTCUSDC","ts":1698936865004,"type":"delta","data":{"s":"BTCUSDC","b":[["34962.38","0.026903"],["34957.48","0.00057"],["34962.09","0"],["34962.36","0"]],"a":[["34983.74","0.1875"],["34973.48","0"]],"u":20010298,"seq":14108041171}}'
2023-11-02 14:54:25,109 DEBUG ++Rcv raw: b'\x81~\x01E{"topic":"orderbook.50.BTCUSDC","ts":1698936865023,"type":"delta","data":{"s":"BTCUSDC","b":[["34962.37","0.010756"],["34951.42","0.000264"],["34962.38","0"]],"a":[["34967.97","0.03895"],["34972.04","0.042233"],["34972.87","0.00057"],["34973.47","0.051541"],["34968.52","0"],["34983.74","0"]],"u":20010299,"seq":14108041181}}'
2023-11-02 14:54:25,109 DEBUG ++Rcv decoded: fin=1 opcode=1 data=b'{"topic":"orderbook.50.BTCUSDC","ts":1698936865023,"type":"delta","data":{"s":"BTCUSDC","b":[["34962.37","0.010756"],["34951.42","0.000264"],["34962.38","0"]],"a":[["34967.97","0.03895"],["34972.04","0.042233"],["34972.87","0.00057"],["34973.47","0.051541"],["34968.52","0"],["34983.74","0"]],"u":20010299,"seq":14108041181}}'
2023-11-02 14:54:25,149 DEBUG ++Rcv raw: b'\x81~\x00\xd6{"topic":"orderbook.50.BTCUSDC","ts":1698936865063,"type":"delta","data":{"s":"BTCUSDC","b":[["34954.73","0.001244"],["34943.36","0.079497"],["34962.1","0"],["34953.11","0"]],"a":[],"u":20010300,"seq":14108041199}}'
2023-11-02 14:54:25,149 DEBUG ++Rcv decoded: fin=1 opcode=1 data=b'{"topic":"orderbook.50.BTCUSDC","ts":1698936865063,"type":"delta","data":{"s":"BTCUSDC","b":[["34954.73","0.001244"],["34943.36","0.079497"],["34962.1","0"],["34953.11","0"]],"a":[],"u":20010300,"seq":14108041199}}'
2023-11-02 14:54:25,251 DEBUG ++Rcv raw: b'\x81~\x00\xae{"topic":"orderbook.50.BTCUSDC","ts":1698936865164,"type":"delta","data":{"s":"BTCUSDC","b":[["34962.38","0.028602"],["34943.36","0"]],"a":[],"u":20010301,"seq":14108041238}}'
2023-11-02 14:54:25,251 DEBUG ++Rcv decoded: fin=1 opcode=1 data=b'{"topic":"orderbook.50.BTCUSDC","ts":1698936865164,"type":"delta","data":{"s":"BTCUSDC","b":[["34962.38","0.028602"],["34943.36","0"]],"a":[],"u":20010301,"seq":14108041238}}'
2023-11-02 14:54:25,269 DEBUG ++Rcv raw: b'\x81~\x00\xc3{"topic":"orderbook.50.BTCUSDC","ts":1698936865183,"type":"delta","data":{"s":"BTCUSDC","b":[["34962.39","0.008756"],["34962.37","0.002"],["34943.37","0"]],"a":[],"u":20010302,"seq":14108041243}}'
2023-11-02 14:54:25,269 DEBUG ++Rcv decoded: fin=1 opcode=1 data=b'{"topic":"orderbook.50.BTCUSDC","ts":1698936865183,"type":"delta","data":{"s":"BTCUSDC","b":[["34962.39","0.008756"],["34962.37","0.002"],["34943.37","0"]],"a":[],"u":20010302,"seq":14108041243}}'
2023-11-02 14:54:25,309 DEBUG ++Rcv raw: b'\x81~\x01\xba{"topic":"orderbook.50.BTCUSDC","ts":1698936865223,"type":"delta","data":{"s":"BTCUSDC","b":[["34960.02","0.008756"],["34943.37","0.028"],["34943.36","0.079497"],["34943.35","0.02598"],["34942","0.0341"],["34962.39","0"],["34962.38","0"],["34962.37","0"],["34951.39","0"],["34960","0"]],"a":[["34963.52","0.03835"],["34966","0.0324"],["34967.96","0.046193"],["34981.28","0"],["34983.73","0"],["34982.24","0"]],"u":20010303,"seq":14108041255}}'
2023-11-02 14:54:25,309 DEBUG ++Rcv decoded: fin=1 opcode=1 data=b'{"topic":"orderbook.50.BTCUSDC","ts":1698936865223,"type":"delta","data":{"s":"BTCUSDC","b":[["34960.02","0.008756"],["34943.37","0.028"],["34943.36","0.079497"],["34943.35","0.02598"],["34942","0.0341"],["34962.39","0"],["34962.38","0"],["34962.37","0"],["34951.39","0"],["34960","0"]],"a":[["34963.52","0.03835"],["34966","0.0324"],["34967.96","0.046193"],["34981.28","0"],["34983.73","0"],["34982.24","0"]],"u":20010303,"seq":14108041255}}'
2023-11-02 14:54:25,328 DEBUG ++Rcv raw: b'\x81~\x01v{"topic":"orderbook.50.BTCUSDC","ts":1698936865243,"type":"delta","data":{"s":"BTCUSDC","b":[["34953.11","0.060137"],["34941.89","0.286189"],["34951.4","0"],["34957.48","0"]],"a":[["34966.74","0.0859"],["34967.95","0.13561"],["34981.28","0.000562"],["34981.71","0.056401"],["34972.01","0"],["34972.87","0"],["34967.98","0"],["34967.96","0"]],"u":20010304,"seq":14108041267}}'
2023-11-02 14:54:25,329 DEBUG ++Rcv decoded: fin=1 opcode=1 data=b'{"topic":"orderbook.50.BTCUSDC","ts":1698936865243,"type":"delta","data":{"s":"BTCUSDC","b":[["34953.11","0.060137"],["34941.89","0.286189"],["34951.4","0"],["34957.48","0"]],"a":[["34966.74","0.0859"],["34967.95","0.13561"],["34981.28","0.000562"],["34981.71","0.056401"],["34972.01","0"],["34972.87","0"],["34967.98","0"],["34967.96","0"]],"u":20010304,"seq":14108041267}}'
2023-11-02 14:54:25,349 DEBUG ++Rcv raw: b'\x81~\x00\xfe{"topic":"orderbook.50.BTCUSDC","ts":1698936865263,"type":"delta","data":{"s":"BTCUSDC","b":[["34955.13","0.00057"],["34941.89","0"]],"a":[["34966.73","0.051544"],["34969.78","0.051545"],["34967.95","0"],["34971.89","0"]],"u":20010305,"seq":14108041274}}'
2023-11-02 14:54:25,349 DEBUG ++Rcv decoded: fin=1 opcode=1 data=b'{"topic":"orderbook.50.BTCUSDC","ts":1698936865263,"type":"delta","data":{"s":"BTCUSDC","b":[["34955.13","0.00057"],["34941.89","0"]],"a":[["34966.73","0.051544"],["34969.78","0.051545"],["34967.95","0"],["34971.89","0"]],"u":20010305,"seq":14108041274}}'
2023-11-02 14:54:25,369 DEBUG ++Rcv raw: b'\x81~\x00\xd6{"topic":"orderbook.50.BTCUSDC","ts":1698936865283,"type":"delta","data":{"s":"BTCUSDC","b":[],"a":[["34968.41","0.00057"],["34971.15","0.428357"],["34981.71","0"],["34971.88","0"]],"u":20010306,"seq":14108041280}}'
2023-11-02 14:54:25,369 DEBUG ++Rcv decoded: fin=1 opcode=1 data=b'{"topic":"orderbook.50.BTCUSDC","ts":1698936865283,"type":"delta","data":{"s":"BTCUSDC","b":[],"a":[["34968.41","0.00057"],["34971.15","0.428357"],["34981.71","0"],["34971.88","0"]],"u":20010306,"seq":14108041280}}'
2023-11-02 14:54:25,388 DEBUG ++Rcv raw: b'\x81~\x00\xc6{"topic":"orderbook.50.BTCUSDC","ts":1698936865303,"type":"delta","data":{"s":"BTCUSDC","b":[],"a":[["34971.14","0.257022"],["34971.15","0.359724"],["34981.28","0"]],"u":20010307,"seq":14108041284}}'
2023-11-02 14:54:25,389 DEBUG ++Rcv decoded: fin=1 opcode=1 data=b'{"topic":"orderbook.50.BTCUSDC","ts":1698936865303,"type":"delta","data":{"s":"BTCUSDC","b":[],"a":[["34971.14","0.257022"],["34971.15","0.359724"],["34981.28","0"]],"u":20010307,"seq":14108041284}}'
2023-11-02 14:54:25,411 DEBUG ++Rcv raw: b'\x81~\x00\xab{"topic":"orderbook.50.BTCUSDC","ts":1698936865323,"type":"delta","data":{"s":"BTCUSDC","b":[["34960.03","0.022876"],["34942","0"]],"a":[],"u":20010308,"seq":14108041292}}'
2023-11-02 14:54:25,411 DEBUG ++Rcv decoded: fin=1 opcode=1 data=b'{"topic":"orderbook.50.BTCUSDC","ts":1698936865323,"type":"delta","data":{"s":"BTCUSDC","b":[["34960.03","0.022876"],["34942","0"]],"a":[],"u":20010308,"seq":14108041292}}'
2023-11-02 14:54:25,431 DEBUG ++Rcv raw: b'\x81~\x00\xfa{"topic":"orderbook.50.BTCUSDC","ts":1698936865344,"type":"delta","data":{"s":"BTCUSDC","b":[["34960.43","0.092532"],["34942","0.0341"],["34951.42","0"],["34954.73","0"]],"a":[["34981.28","0.000562"],["34966.74","0"]],"u":20010309,"seq":14108041305}}'
2023-11-02 14:54:25,437 DEBUG ++Rcv decoded: fin=1 opcode=1 data=b'{"topic":"orderbook.50.BTCUSDC","ts":1698936865344,"type":"delta","data":{"s":"BTCUSDC","b":[["34960.43","0.092532"],["34942","0.0341"],["34951.42","0"],["34954.73","0"]],"a":[["34981.28","0.000562"],["34966.74","0"]],"u":20010309,"seq":14108041305}}'
2023-11-02 14:54:25,449 DEBUG ++Rcv raw: b'\x81~\x00\xd7{"topic":"orderbook.50.BTCUSDC","ts":1698936865364,"type":"delta","data":{"s":"BTCUSDC","b":[],"a":[["34967.96","0.108243"],["34981.71","0.056401"],["34969.78","0"],["34966.73","0"]],"u":20010310,"seq":14108041308}}'
2023-11-02 14:54:25,450 DEBUG ++Rcv decoded: fin=1 opcode=1 data=b'{"topic":"orderbook.50.BTCUSDC","ts":1698936865364,"type":"delta","data":{"s":"BTCUSDC","b":[],"a":[["34967.96","0.108243"],["34981.71","0.056401"],["34969.78","0"],["34966.73","0"]],"u":20010310,"seq":14108041308}}'
2023-11-02 14:54:25,530 DEBUG ++Rcv raw: b'\x81~\x00\x9d{"topic":"orderbook.50.BTCUSDC","ts":1698936865444,"type":"delta","data":{"s":"BTCUSDC","b":[],"a":[["34963.52","0.001099"]],"u":20010311,"seq":14108041375}}'
2023-11-02 14:54:25,530 DEBUG ++Rcv decoded: fin=1 opcode=1 data=b'{"topic":"orderbook.50.BTCUSDC","ts":1698936865444,"type":"delta","data":{"s":"BTCUSDC","b":[],"a":[["34963.52","0.001099"]],"u":20010311,"seq":14108041375}}'
2023-11-02 14:54:25,549 DEBUG ++Rcv raw: b'\x81~\x00\x9d{"topic":"orderbook.50.BTCUSDC","ts":1698936865464,"type":"delta","data":{"s":"BTCUSDC","b":[["34960.43","0.095532"]],"a":[],"u":20010312,"seq":14108041387}}'
2023-11-02 14:54:25,550 DEBUG ++Rcv decoded: fin=1 opcode=1 data=b'{"topic":"orderbook.50.BTCUSDC","ts":1698936865464,"type":"delta","data":{"s":"BTCUSDC","b":[["34960.43","0.095532"]],"a":[],"u":20010312,"seq":14108041387}}'
2023-11-02 14:54:25,569 DEBUG ++Rcv raw: b'\x81~\x00\xfc{"topic":"orderbook.50.BTCUSDC","ts":1698936865483,"type":"delta","data":{"s":"BTCUSDC","b":[["34955.86","0.001"],["34960.02","0"]],"a":[["34964.13","0.057201"],["34971.95","0.000237"],["34981.71","0"],["34981.28","0"]],"u":20010313,"seq":14108041404}}'
2023-11-02 14:54:25,569 DEBUG ++Rcv decoded: fin=1 opcode=1 data=b'{"topic":"orderbook.50.BTCUSDC","ts":1698936865483,"type":"delta","data":{"s":"BTCUSDC","b":[["34955.86","0.001"],["34960.02","0"]],"a":[["34964.13","0.057201"],["34971.95","0.000237"],["34981.71","0"],["34981.28","0"]],"u":20010313,"seq":14108041404}}'
2023-11-02 14:54:25,589 DEBUG ++Rcv raw: b'\x81~\x00\xd7{"topic":"orderbook.50.BTCUSDC","ts":1698936865503,"type":"delta","data":{"s":"BTCUSDC","b":[["34958.15","0.138055"],["34955.17","0.025122"],["34960.01","0"],["34956.43","0"]],"a":[],"u":20010314,"seq":14108041408}}'
2023-11-02 14:54:25,589 DEBUG ++Rcv decoded: fin=1 opcode=1 data=b'{"topic":"orderbook.50.BTCUSDC","ts":1698936865503,"type":"delta","data":{"s":"BTCUSDC","b":[["34958.15","0.138055"],["34955.17","0.025122"],["34960.01","0"],["34956.43","0"]],"a":[],"u":20010314,"seq":14108041408}}'
2023-11-02 14:54:25,629 DEBUG ++Rcv raw: b'\x81~\x00\xab{"topic":"orderbook.50.BTCUSDC","ts":1698936865543,"type":"delta","data":{"s":"BTCUSDC","b":[["34954.73","0.001232"],["34942","0"]],"a":[],"u":20010315,"seq":14108041419}}'
2023-11-02 14:54:25,629 DEBUG ++Rcv decoded: fin=1 opcode=1 data=b'{"topic":"orderbook.50.BTCUSDC","ts":1698936865543,"type":"delta","data":{"s":"BTCUSDC","b":[["34954.73","0.001232"],["34942","0"]],"a":[],"u":20010315,"seq":14108041419}}'
2023-11-02 14:54:25,670 DEBUG ++Rcv raw: b'\x81~\x00\xa9{"topic":"orderbook.50.BTCUSDC","ts":1698936865584,"type":"delta","data":{"s":"BTCUSDC","b":[["34942","0.0341"],["34960.03","0"]],"a":[],"u":20010316,"seq":14108041440}}'
2023-11-02 14:54:25,670 DEBUG ++Rcv decoded: fin=1 opcode=1 data=b'{"topic":"orderbook.50.BTCUSDC","ts":1698936865584,"type":"delta","data":{"s":"BTCUSDC","b":[["34942","0.0341"],["34960.03","0"]],"a":[],"u":20010316,"seq":14108041440}}'
2023-11-02 14:54:25,690 DEBUG ++Rcv raw: b'\x81~\x01S{"topic":"orderbook.50.BTCUSDC","ts":1698936865604,"type":"delta","data":{"s":"BTCUSDC","b":[["34959.87","0.040195"],["34956.43","0.051543"],["34952.42","0.000264"],["34947.83","0.106061"],["34958.15","0"],["34955.17","0"],["34942","0"]],"a":[["34971.14","0.17466"],["34971.93","0.000236"],["34980.5","0"]],"u":20010317,"seq":14108041453}}'
2023-11-02 14:54:25,690 DEBUG ++Rcv decoded: fin=1 opcode=1 data=b'{"topic":"orderbook.50.BTCUSDC","ts":1698936865604,"type":"delta","data":{"s":"BTCUSDC","b":[["34959.87","0.040195"],["34956.43","0.051543"],["34952.42","0.000264"],["34947.83","0.106061"],["34958.15","0"],["34955.17","0"],["34942","0"]],"a":[["34971.14","0.17466"],["34971.93","0.000236"],["34980.5","0"]],"u":20010317,"seq":14108041453}}'
2023-11-02 14:54:25,749 DEBUG ++Rcv raw: b'\x81~\x00\xce{"topic":"orderbook.50.BTCUSDC","ts":1698936865663,"type":"delta","data":{"s":"BTCUSDC","b":[["34942","0.0341"],["34943.37","0"]],"a":[["34980.5","0.0859"],["34963.52","0"]],"u":20010318,"seq":14108041462}}'
2023-11-02 14:54:25,749 DEBUG ++Rcv decoded: fin=1 opcode=1 data=b'{"topic":"orderbook.50.BTCUSDC","ts":1698936865663,"type":"delta","data":{"s":"BTCUSDC","b":[["34942","0.0341"],["34943.37","0"]],"a":[["34980.5","0.0859"],["34963.52","0"]],"u":20010318,"seq":14108041462}}'
2023-11-02 14:54:25,769 DEBUG ++Rcv raw: b'\x81~\x00\xc0{"topic":"orderbook.50.BTCUSDC","ts":1698936865684,"type":"delta","data":{"s":"BTCUSDC","b":[["34960.44","0.022876"],["34960.43","0.003"],["34942","0"]],"a":[],"u":20010319,"seq":14108041468}}'
2023-11-02 14:54:25,769 DEBUG ++Rcv decoded: fin=1 opcode=1 data=b'{"topic":"orderbook.50.BTCUSDC","ts":1698936865684,"type":"delta","data":{"s":"BTCUSDC","b":[["34960.44","0.022876"],["34960.43","0.003"],["34942","0"]],"a":[],"u":20010319,"seq":14108041468}}'
2023-11-02 14:54:25,789 DEBUG ++Rcv raw: b'\x81~\x00\xa9{"topic":"orderbook.50.BTCUSDC","ts":1698936865704,"type":"delta","data":{"s":"BTCUSDC","b":[["34942","0.0341"],["34960.43","0"]],"a":[],"u":20010320,"seq":14108041481}}'
2023-11-02 14:54:25,789 DEBUG ++Rcv decoded: fin=1 opcode=1 data=b'{"topic":"orderbook.50.BTCUSDC","ts":1698936865704,"type":"delta","data":{"s":"BTCUSDC","b":[["34942","0.0341"],["34960.43","0"]],"a":[],"u":20010320,"seq":14108041481}}'
2023-11-02 14:54:25,829 DEBUG ++Rcv raw: b'\x81~\x00\xd6{"topic":"orderbook.50.BTCUSDC","ts":1698936865744,"type":"delta","data":{"s":"BTCUSDC","b":[["34941.89","0.286189"],["34940.87","0.00154"],["34955.16","0"],["34954.73","0"]],"a":[],"u":20010321,"seq":14108041499}}'
2023-11-02 14:54:25,829 DEBUG ++Rcv decoded: fin=1 opcode=1 data=b'{"topic":"orderbook.50.BTCUSDC","ts":1698936865744,"type":"delta","data":{"s":"BTCUSDC","b":[["34941.89","0.286189"],["34940.87","0.00154"],["34955.16","0"],["34954.73","0"]],"a":[],"u":20010321,"seq":14108041499}}'
2023-11-02 14:54:25,849 DEBUG ++Rcv raw: b'\x81~\x00\xc5{"topic":"orderbook.50.BTCUSDC","ts":1698936865764,"type":"delta","data":{"s":"BTCUSDC","b":[["34960.45","0.053806"],["34940.87","0"]],"a":[["34964.13","0.034621"]],"u":20010322,"seq":14108041506}}'
2023-11-02 14:54:25,850 DEBUG ++Rcv decoded: fin=1 opcode=1 data=b'{"topic":"orderbook.50.BTCUSDC","ts":1698936865764,"type":"delta","data":{"s":"BTCUSDC","b":[["34960.45","0.053806"],["34940.87","0"]],"a":[["34964.13","0.034621"]],"u":20010322,"seq":14108041506}}'
2023-11-02 14:54:25,869 DEBUG ++Rcv raw: b'\x81~\x00\xfa{"topic":"orderbook.50.BTCUSDC","ts":1698936865784,"type":"delta","data":{"s":"BTCUSDC","b":[["34940.87","0.00154"],["34940.3","0.025298"],["34960.45","0"],["34950.01","0"]],"a":[["34971.13","0.1875"],["34980.5","0"]],"u":20010323,"seq":14108041522}}'
2023-11-02 14:54:25,870 DEBUG ++Rcv decoded: fin=1 opcode=1 data=b'{"topic":"orderbook.50.BTCUSDC","ts":1698936865784,"type":"delta","data":{"s":"BTCUSDC","b":[["34940.87","0.00154"],["34940.3","0.025298"],["34960.45","0"],["34950.01","0"]],"a":[["34971.13","0.1875"],["34980.5","0"]],"u":20010323,"seq":14108041522}}'
2023-11-02 14:54:25,889 DEBUG ++Rcv raw: b'\x81~\x00\xfd{"topic":"orderbook.50.BTCUSDC","ts":1698936865804,"type":"delta","data":{"s":"BTCUSDC","b":[["34949.55","0.370753"],["34939.85","0.1875"],["34939.11","0.057242"],["34960.44","0"],["34950.02","0"],["34957.3","0"]],"a":[],"u":20010324,"seq":14108041527}}'
2023-11-02 14:54:25,889 DEBUG ++Rcv decoded: fin=1 opcode=1 data=b'{"topic":"orderbook.50.BTCUSDC","ts":1698936865804,"type":"delta","data":{"s":"BTCUSDC","b":[["34949.55","0.370753"],["34939.85","0.1875"],["34939.11","0.057242"],["34960.44","0"],["34950.02","0"],["34957.3","0"]],"a":[],"u":20010324,"seq":14108041527}}'
2023-11-02 14:54:25,909 DEBUG ++Rcv raw: b'\x81~\x01\x14{"topic":"orderbook.50.BTCUSDC","ts":1698936865823,"type":"delta","data":{"s":"BTCUSDC","b":[["34959.87","0.051548"],["34958.15","0.138062"],["34956.43","0"]],"a":[["34964.12","0.008756"],["34980.5","0.0859"],["34971.16","0"],["34964.13","0"]],"u":20010325,"seq":14108041546}}'
2023-11-02 14:54:25,909 DEBUG ++Rcv decoded: fin=1 opcode=1 data=b'{"topic":"orderbook.50.BTCUSDC","ts":1698936865823,"type":"delta","data":{"s":"BTCUSDC","b":[["34959.87","0.051548"],["34958.15","0.138062"],["34956.43","0"]],"a":[["34964.12","0.008756"],["34980.5","0.0859"],["34971.16","0"],["34964.13","0"]],"u":20010325,"seq":14108041546}}'
2023-11-02 14:54:25,930 DEBUG ++Rcv raw: b'\x81~\x01x{"topic":"orderbook.50.BTCUSDC","ts":1698936865844,"type":"delta","data":{"s":"BTCUSDC","b":[["34956.43","0.051549"],["34953.12","0.00142"],["34952.81","0.000265"],["34958.15","0"],["34949.55","0"],["34939.11","0"]],"a":[["34964.03","0.057201"],["34970.23","0.114383"],["34979.16","0.285884"],["34971.13","0"],["34980.2","0"],["34971.95","0"]],"u":20010326,"seq":14108041570}}'
2023-11-02 14:54:25,930 DEBUG ++Rcv decoded: fin=1 opcode=1 data=b'{"topic":"orderbook.50.BTCUSDC","ts":1698936865844,"type":"delta","data":{"s":"BTCUSDC","b":[["34956.43","0.051549"],["34953.12","0.00142"],["34952.81","0.000265"],["34958.15","0"],["34949.55","0"],["34939.11","0"]],"a":[["34964.03","0.057201"],["34970.23","0.114383"],["34979.16","0.285884"],["34971.13","0"],["34980.2","0"],["34971.95","0"]],"u":20010326,"seq":14108041570}}'
2023-11-02 14:54:25,949 DEBUG ++Rcv raw: b'\x81~\x00\xd2{"topic":"orderbook.50.BTCUSDC","ts":1698936865864,"type":"delta","data":{"s":"BTCUSDC","b":[["34944.01","0.028"],["34939.85","0"]],"a":[["34969.78","0.068629"],["34980.5","0"]],"u":20010327,"seq":14108041583}}'
2023-11-02 14:54:25,949 DEBUG ++Rcv decoded: fin=1 opcode=1 data=b'{"topic":"orderbook.50.BTCUSDC","ts":1698936865864,"type":"delta","data":{"s":"BTCUSDC","b":[["34944.01","0.028"],["34939.85","0"]],"a":[["34969.78","0.068629"],["34980.5","0"]],"u":20010327,"seq":14108041583}}'
2023-11-02 14:54:25,968 DEBUG ++Rcv raw: b'\x81~\x00\xad{"topic":"orderbook.50.BTCUSDC","ts":1698936865883,"type":"delta","data":{"s":"BTCUSDC","b":[["34960.45","0.022876"],["34940.3","0"]],"a":[],"u":20010328,"seq":14108041592}}'
2023-11-02 14:54:25,969 DEBUG ++Rcv decoded: fin=1 opcode=1 data=b'{"topic":"orderbook.50.BTCUSDC","ts":1698936865883,"type":"delta","data":{"s":"BTCUSDC","b":[["34960.45","0.022876"],["34940.3","0"]],"a":[],"u":20010328,"seq":14108041592}}'
2023-11-02 14:54:25,989 DEBUG ++Rcv raw: b'\x81~\x00\xae{"topic":"orderbook.50.BTCUSDC","ts":1698936865904,"type":"delta","data":{"s":"BTCUSDC","b":[["34960.88","0.096657"],["34940.87","0"]],"a":[],"u":20010329,"seq":14108041599}}'
2023-11-02 14:54:25,989 DEBUG ++Rcv decoded: fin=1 opcode=1 data=b'{"topic":"orderbook.50.BTCUSDC","ts":1698936865904,"type":"delta","data":{"s":"BTCUSDC","b":[["34960.88","0.096657"],["34940.87","0"]],"a":[],"u":20010329,"seq":14108041599}}'
2023-11-02 14:54:26,050 DEBUG ++Rcv raw: b'\x81~\x00\xac{"topic":"orderbook.50.BTCUSDC","ts":1698936865964,"type":"delta","data":{"s":"BTCUSDC","b":[],"a":[["34971.03","0.1875"],["34980.48","0"]],"u":20010330,"seq":14108041620}}'
2023-11-02 14:54:26,050 DEBUG ++Rcv decoded: fin=1 opcode=1 data=b'{"topic":"orderbook.50.BTCUSDC","ts":1698936865964,"type":"delta","data":{"s":"BTCUSDC","b":[],"a":[["34971.03","0.1875"],["34980.48","0"]],"u":20010330,"seq":14108041620}}'
2023-11-02 14:54:26,089 DEBUG ++Rcv raw: b'\x81~\x00\xd2{"topic":"orderbook.50.BTCUSDC","ts":1698936866004,"type":"delta","data":{"s":"BTCUSDC","b":[],"a":[["34963.98","0.002918"],["34967.33","0.03"],["34979.16","0"],["34971.2","0"]],"u":20010331,"seq":14108041632}}'
2023-11-02 14:54:26,089 DEBUG ++Rcv decoded: fin=1 opcode=1 data=b'{"topic":"orderbook.50.BTCUSDC","ts":1698936866004,"type":"delta","data":{"s":"BTCUSDC","b":[],"a":[["34963.98","0.002918"],["34967.33","0.03"],["34979.16","0"],["34971.2","0"]],"u":20010331,"seq":14108041632}}'
2023-11-02 14:54:26,109 DEBUG ++Rcv raw: b'\x81~\x00\xd7{"topic":"orderbook.50.BTCUSDC","ts":1698936866024,"type":"delta","data":{"s":"BTCUSDC","b":[],"a":[["34963.87","0.057201"],["34979.16","0.285884"],["34967.33","0"],["34964.03","0"]],"u":20010332,"seq":14108041638}}'
2023-11-02 14:54:26,109 DEBUG ++Rcv decoded: fin=1 opcode=1 data=b'{"topic":"orderbook.50.BTCUSDC","ts":1698936866024,"type":"delta","data":{"s":"BTCUSDC","b":[],"a":[["34963.87","0.057201"],["34979.16","0.285884"],["34967.33","0"],["34964.03","0"]],"u":20010332,"seq":14108041638}}'
2023-11-02 14:54:26,129 DEBUG ++Rcv raw: b'\x81~\x00\xc5{"topic":"orderbook.50.BTCUSDC","ts":1698936866044,"type":"delta","data":{"s":"BTCUSDC","b":[["34960.88","0.099657"]],"a":[["34980.48","0.023472"],["34963.98","0"]],"u":20010333,"seq":14108041643}}'
2023-11-02 14:54:26,129 DEBUG ++Rcv decoded: fin=1 opcode=1 data=b'{"topic":"orderbook.50.BTCUSDC","ts":1698936866044,"type":"delta","data":{"s":"BTCUSDC","b":[["34960.88","0.099657"]],"a":[["34980.48","0.023472"],["34963.98","0"]],"u":20010333,"seq":14108041643}}'
2023-11-02 14:54:26,149 DEBUG ++Rcv raw: b'\x81~\x00\xd2{"topic":"orderbook.50.BTCUSDC","ts":1698936866064,"type":"delta","data":{"s":"BTCUSDC","b":[["34941.17","0.157107"],["34952.42","0"]],"a":[["34967.33","0.03"],["34971.93","0"]],"u":20010334,"seq":14108041650}}'
2023-11-02 14:54:26,150 DEBUG ++Rcv decoded: fin=1 opcode=1 data=b'{"topic":"orderbook.50.BTCUSDC","ts":1698936866064,"type":"delta","data":{"s":"BTCUSDC","b":[["34941.17","0.157107"],["34952.42","0"]],"a":[["34967.33","0.03"],["34971.93","0"]],"u":20010334,"seq":14108041650}}'
2023-11-02 14:54:26,169 DEBUG ++Rcv raw: b'\x81~\x00\x9d{"topic":"orderbook.50.BTCUSDC","ts":1698936866083,"type":"delta","data":{"s":"BTCUSDC","b":[["34959.87","0.025742"]],"a":[],"u":20010335,"seq":14108041654}}'
2023-11-02 14:54:26,169 DEBUG ++Rcv decoded: fin=1 opcode=1 data=b'{"topic":"orderbook.50.BTCUSDC","ts":1698936866083,"type":"delta","data":{"s":"BTCUSDC","b":[["34959.87","0.025742"]],"a":[],"u":20010335,"seq":14108041654}}'
2023-11-02 14:54:26,189 DEBUG ++Rcv raw: b'\x81~\x00\xad{"topic":"orderbook.50.BTCUSDC","ts":1698936866103,"type":"delta","data":{"s":"BTCUSDC","b":[["34949.55","0.35506"],["34941.17","0"]],"a":[],"u":20010336,"seq":14108041655}}'
2023-11-02 14:54:26,189 DEBUG ++Rcv decoded: fin=1 opcode=1 data=b'{"topic":"orderbook.50.BTCUSDC","ts":1698936866103,"type":"delta","data":{"s":"BTCUSDC","b":[["34949.55","0.35506"],["34941.17","0"]],"a":[],"u":20010336,"seq":14108041655}}'
2023-11-02 14:54:26,209 DEBUG ++Rcv raw: b'\x81~\x00\xd3{"topic":"orderbook.50.BTCUSDC","ts":1698936866123,"type":"delta","data":{"s":"BTCUSDC","b":[["34941.17","0.157107"],["34960.45","0"]],"a":[["34980.5","0.0859"],["34967.33","0"]],"u":20010337,"seq":14108041657}}'
2023-11-02 14:54:26,210 DEBUG ++Rcv decoded: fin=1 opcode=1 data=b'{"topic":"orderbook.50.BTCUSDC","ts":1698936866123,"type":"delta","data":{"s":"BTCUSDC","b":[["34941.17","0.157107"],["34960.45","0"]],"a":[["34980.5","0.0859"],["34967.33","0"]],"u":20010337,"seq":14108041657}}'
2023-11-02 14:54:26,229 DEBUG ++Rcv raw: b'\x81~\x00\xab{"topic":"orderbook.50.BTCUSDC","ts":1698936866143,"type":"delta","data":{"s":"BTCUSDC","b":[],"a":[["34966.74","0.0859"],["34980.5","0"]],"u":20010338,"seq":14108041658}}'
2023-11-02 14:54:26,229 DEBUG ++Rcv decoded: fin=1 opcode=1 data=b'{"topic":"orderbook.50.BTCUSDC","ts":1698936866143,"type":"delta","data":{"s":"BTCUSDC","b":[],"a":[["34966.74","0.0859"],["34980.5","0"]],"u":20010338,"seq":14108041658}}'
2023-11-02 14:54:26,249 DEBUG ++Rcv raw: b'\x81~\x01<{"topic":"orderbook.50.BTCUSDC","ts":1698936866164,"type":"delta","data":{"s":"BTCUSDC","b":[["34960.88","0.003"],["34958.15","0.138057"],["34940.87","0.00154"],["34956.43","0"],["34959.87","0"]],"a":[["34963.86","0.008756"],["34966.73","0.051543"],["34964.12","0"],["34967.96","0"]],"u":20010339,"seq":14108041670}}'
2023-11-02 14:54:26,249 DEBUG ++Rcv decoded: fin=1 opcode=1 data=b'{"topic":"orderbook.50.BTCUSDC","ts":1698936866164,"type":"delta","data":{"s":"BTCUSDC","b":[["34960.88","0.003"],["34958.15","0.138057"],["34940.87","0.00154"],["34956.43","0"],["34959.87","0"]],"a":[["34963.86","0.008756"],["34966.73","0.051543"],["34964.12","0"],["34967.96","0"]],"u":20010339,"seq":14108041670}}'
2023-11-02 14:54:26,269 DEBUG ++Rcv raw: b'\x81~\x00\xfa{"topic":"orderbook.50.BTCUSDC","ts":1698936866184,"type":"delta","data":{"s":"BTCUSDC","b":[["34940.3","0.025298"],["34959.86","0"]],"a":[["34963.74","0.057202"],["34970.54","0.03"],["34980.48","0"],["34963.87","0"]],"u":20010340,"seq":14108041677}}'
2023-11-02 14:54:26,269 DEBUG ++Rcv decoded: fin=1 opcode=1 data=b'{"topic":"orderbook.50.BTCUSDC","ts":1698936866184,"type":"delta","data":{"s":"BTCUSDC","b":[["34940.3","0.025298"],["34959.86","0"]],"a":[["34963.74","0.057202"],["34970.54","0.03"],["34980.48","0"],["34963.87","0"]],"u":20010340,"seq":14108041677}}'
2023-11-02 14:54:26,289 DEBUG ++Rcv raw: b'\x81~\x00\xae{"topic":"orderbook.50.BTCUSDC","ts":1698936866204,"type":"delta","data":{"s":"BTCUSDC","b":[],"a":[["34963.73","0.008756"],["34963.86","0"]],"u":20010341,"seq":14108041679}}'
2023-11-02 14:54:26,289 DEBUG ++Rcv decoded: fin=1 opcode=1 data=b'{"topic":"orderbook.50.BTCUSDC","ts":1698936866204,"type":"delta","data":{"s":"BTCUSDC","b":[],"a":[["34963.73","0.008756"],["34963.86","0"]],"u":20010341,"seq":14108041679}}'
2023-11-02 14:54:26,369 DEBUG ++Rcv raw: b'\x81~\x00\xac{"topic":"orderbook.50.BTCUSDC","ts":1698936866284,"type":"delta","data":{"s":"BTCUSDC","b":[["34939.85","0.1875"],["34952.81","0"]],"a":[],"u":20010342,"seq":14108041685}}'
2023-11-02 14:54:26,369 DEBUG ++Rcv decoded: fin=1 opcode=1 data=b'{"topic":"orderbook.50.BTCUSDC","ts":1698936866284,"type":"delta","data":{"s":"BTCUSDC","b":[["34939.85","0.1875"],["34952.81","0"]],"a":[],"u":20010342,"seq":14108041685}}'
2023-11-02 14:54:26,429 DEBUG ++Rcv raw: b'\x81~\x00\xd6{"topic":"orderbook.50.BTCUSDC","ts":1698936866344,"type":"delta","data":{"s":"BTCUSDC","b":[["34960.89","0.022876"],["34951.27","0.002381"],["34940.3","0"],["34939.85","0"]],"a":[],"u":20010343,"seq":14108041726}}'
2023-11-02 14:54:26,429 DEBUG ++Rcv decoded: fin=1 opcode=1 data=b'{"topic":"orderbook.50.BTCUSDC","ts":1698936866344,"type":"delta","data":{"s":"BTCUSDC","b":[["34960.89","0.022876"],["34951.27","0.002381"],["34940.3","0"],["34939.85","0"]],"a":[],"u":20010343,"seq":14108041726}}'
2023-11-02 14:54:26,449 DEBUG ++Rcv raw: b'\x81~\x01v{"topic":"orderbook.50.BTCUSDC","ts":1698936866364,"type":"delta","data":{"s":"BTCUSDC","b":[["34940.3","0.025298"],["34939.85","0.1875"],["34939.11","0.057242"],["34960.88","0"],["34960.89","0"],["34953.12","0"]],"a":[["34961.84","0.003093"],["34963.63","0.057202"],["34963.72","0.046193"],["34963.74","0"],["34978.9","0"],["34979.16","0"]],"u":20010344,"seq":14108041743}}'
2023-11-02 14:54:26,449 DEBUG ++Rcv decoded: fin=1 opcode=1 data=b'{"topic":"orderbook.50.BTCUSDC","ts":1698936866364,"type":"delta","data":{"s":"BTCUSDC","b":[["34940.3","0.025298"],["34939.85","0.1875"],["34939.11","0.057242"],["34960.88","0"],["34960.89","0"],["34953.12","0"]],"a":[["34961.84","0.003093"],["34963.63","0.057202"],["34963.72","0.046193"],["34963.74","0"],["34978.9","0"],["34979.16","0"]],"u":20010344,"seq":14108041743}}'
2023-11-02 14:54:26,469 DEBUG ++Rcv raw: b'\x81~\x01\x15{"topic":"orderbook.50.BTCUSDC","ts":1698936866384,"type":"delta","data":{"s":"BTCUSDC","b":[["34951.27","0.071052"],["34938.46","0.029858"],["34937.4","0.823835"],["34955.13","0"],["34955.86","0"]],"a":[["34978.9","0.002162"],["34963.72","0"]],"u":20010345,"seq":14108041753}}'
2023-11-02 14:54:26,469 DEBUG ++Rcv decoded: fin=1 opcode=1 data=b'{"topic":"orderbook.50.BTCUSDC","ts":1698936866384,"type":"delta","data":{"s":"BTCUSDC","b":[["34951.27","0.071052"],["34938.46","0.029858"],["34937.4","0.823835"],["34955.13","0"],["34955.86","0"]],"a":[["34978.9","0.002162"],["34963.72","0"]],"u":20010345,"seq":14108041753}}'
2023-11-02 14:54:26,489 DEBUG ++Rcv raw: b'\x81~\x00\xd0{"topic":"orderbook.50.BTCUSDC","ts":1698936866403,"type":"delta","data":{"s":"BTCUSDC","b":[["34953.26","0.00057"],["34937.4","0"]],"a":[["34961.23","0.003"],["34978.9","0"]],"u":20010346,"seq":14108041759}}'
2023-11-02 14:54:26,489 DEBUG ++Rcv decoded: fin=1 opcode=1 data=b'{"topic":"orderbook.50.BTCUSDC","ts":1698936866403,"type":"delta","data":{"s":"BTCUSDC","b":[["34953.26","0.00057"],["34937.4","0"]],"a":[["34961.23","0.003"],["34978.9","0"]],"u":20010346,"seq":14108041759}}'
2023-11-02 14:54:26,509 DEBUG ++Rcv raw: b'\x81~\x00\xd6{"topic":"orderbook.50.BTCUSDC","ts":1698936866423,"type":"delta","data":{"s":"BTCUSDC","b":[],"a":[["34978.9","0.002162"],["34979.16","0.285884"],["34968.41","0"],["34961.84","0"]],"u":20010347,"seq":14108041761}}'
2023-11-02 14:54:26,509 DEBUG ++Rcv decoded: fin=1 opcode=1 data=b'{"topic":"orderbook.50.BTCUSDC","ts":1698936866423,"type":"delta","data":{"s":"BTCUSDC","b":[],"a":[["34978.9","0.002162"],["34979.16","0.285884"],["34968.41","0"],["34961.84","0"]],"u":20010347,"seq":14108041761}}'
2023-11-02 14:54:26,529 DEBUG ++Rcv raw: b'\x81~\x00\xd5{"topic":"orderbook.50.BTCUSDC","ts":1698936866443,"type":"delta","data":{"s":"BTCUSDC","b":[],"a":[["34966.12","0.00057"],["34971.84","0.000237"],["34978.9","0"],["34979.16","0"]],"u":20010348,"seq":14108041765}}'
2023-11-02 14:54:26,529 DEBUG ++Rcv decoded: fin=1 opcode=1 data=b'{"topic":"orderbook.50.BTCUSDC","ts":1698936866443,"type":"delta","data":{"s":"BTCUSDC","b":[],"a":[["34966.12","0.00057"],["34971.84","0.000237"],["34978.9","0"],["34979.16","0"]],"u":20010348,"seq":14108041765}}'
2023-11-02 14:54:26,548 DEBUG ++Rcv raw: b'\x81~\x00\xad{"topic":"orderbook.50.BTCUSDC","ts":1698936866463,"type":"delta","data":{"s":"BTCUSDC","b":[["34937.4","0.823835"],["34957.53","0"]],"a":[],"u":20010349,"seq":14108041769}}'
2023-11-02 14:54:26,549 DEBUG ++Rcv decoded: fin=1 opcode=1 data=b'{"topic":"orderbook.50.BTCUSDC","ts":1698936866463,"type":"delta","data":{"s":"BTCUSDC","b":[["34937.4","0.823835"],["34957.53","0"]],"a":[],"u":20010349,"seq":14108041769}}'
2023-11-02 14:54:26,569 DEBUG ++Rcv raw: b'\x81~\x00\xd3{"topic":"orderbook.50.BTCUSDC","ts":1698936866484,"type":"delta","data":{"s":"BTCUSDC","b":[["34957.1","0.057212"],["34937.4","0"]],"a":[["34978.9","0.002162"],["34963.73","0"]],"u":20010350,"seq":14108041771}}'
2023-11-02 14:54:26,569 DEBUG ++Rcv decoded: fin=1 opcode=1 data=b'{"topic":"orderbook.50.BTCUSDC","ts":1698936866484,"type":"delta","data":{"s":"BTCUSDC","b":[["34957.1","0.057212"],["34937.4","0"]],"a":[["34978.9","0.002162"],["34963.73","0"]],"u":20010350,"seq":14108041771}}'
2023-11-02 14:54:26,668 DEBUG ++Rcv raw: b'\x81~\x00\xad{"topic":"orderbook.50.BTCUSDC","ts":1698936866583,"type":"delta","data":{"s":"BTCUSDC","b":[],"a":[["34978.26","0.285891"],["34978.9","0"]],"u":20010351,"seq":14108041784}}'
2023-11-02 14:54:26,669 DEBUG ++Rcv decoded: fin=1 opcode=1 data=b'{"topic":"orderbook.50.BTCUSDC","ts":1698936866583,"type":"delta","data":{"s":"BTCUSDC","b":[],"a":[["34978.26","0.285891"],["34978.9","0"]],"u":20010351,"seq":14108041784}}'
2023-11-02 14:54:26,689 DEBUG ++Rcv raw: b'\x81~\x00\xae{"topic":"orderbook.50.BTCUSDC","ts":1698936866603,"type":"delta","data":{"s":"BTCUSDC","b":[],"a":[["34971.82","0.000236"],["34978.89","0"]],"u":20010352,"seq":14108041785}}'
2023-11-02 14:54:26,689 DEBUG ++Rcv decoded: fin=1 opcode=1 data=b'{"topic":"orderbook.50.BTCUSDC","ts":1698936866603,"type":"delta","data":{"s":"BTCUSDC","b":[],"a":[["34971.82","0.000236"],["34978.89","0"]],"u":20010352,"seq":14108041785}}'
2023-11-02 14:54:26,709 DEBUG ++Rcv raw: b'\x81~\x00\xae{"topic":"orderbook.50.BTCUSDC","ts":1698936866624,"type":"delta","data":{"s":"BTCUSDC","b":[["34949.56","0.213041"],["34938.46","0"]],"a":[],"u":20010353,"seq":14108041802}}'
2023-11-02 14:54:26,709 DEBUG ++Rcv decoded: fin=1 opcode=1 data=b'{"topic":"orderbook.50.BTCUSDC","ts":1698936866624,"type":"delta","data":{"s":"BTCUSDC","b":[["34949.56","0.213041"],["34938.46","0"]],"a":[],"u":20010353,"seq":14108041802}}'
2023-11-02 14:54:26,769 DEBUG ++Rcv raw: b'\x81~\x00\xae{"topic":"orderbook.50.BTCUSDC","ts":1698936866684,"type":"delta","data":{"s":"BTCUSDC","b":[],"a":[["34969.35","0.114385"],["34970.23","0"]],"u":20010354,"seq":14108041827}}'
2023-11-02 14:54:26,769 DEBUG ++Rcv decoded: fin=1 opcode=1 data=b'{"topic":"orderbook.50.BTCUSDC","ts":1698936866684,"type":"delta","data":{"s":"BTCUSDC","b":[],"a":[["34969.35","0.114385"],["34970.23","0"]],"u":20010354,"seq":14108041827}}'
2023-11-02 14:54:26,790 DEBUG ++Rcv raw: b'\x81~\x00\xae{"topic":"orderbook.50.BTCUSDC","ts":1698936866704,"type":"delta","data":{"s":"BTCUSDC","b":[],"a":[["34969.34","0.068638"],["34969.78","0"]],"u":20010355,"seq":14108041829}}'
2023-11-02 14:54:26,791 DEBUG ++Rcv decoded: fin=1 opcode=1 data=b'{"topic":"orderbook.50.BTCUSDC","ts":1698936866704,"type":"delta","data":{"s":"BTCUSDC","b":[],"a":[["34969.34","0.068638"],["34969.78","0"]],"u":20010355,"seq":14108041829}}'
2023-11-02 14:54:26,850 DEBUG ++Rcv raw: b'\x81~\x00\xae{"topic":"orderbook.50.BTCUSDC","ts":1698936866764,"type":"delta","data":{"s":"BTCUSDC","b":[["34938.46","0.029858"],["34948.01","0"]],"a":[],"u":20010356,"seq":14108041839}}'
2023-11-02 14:54:26,850 DEBUG ++Rcv decoded: fin=1 opcode=1 data=b'{"topic":"orderbook.50.BTCUSDC","ts":1698936866764,"type":"delta","data":{"s":"BTCUSDC","b":[["34938.46","0.029858"],["34948.01","0"]],"a":[],"u":20010356,"seq":14108041839}}'
2023-11-02 14:54:26,890 DEBUG ++Rcv raw: b'\x81~\x01L{"topic":"orderbook.50.BTCUSDC","ts":1698936866804,"type":"delta","data":{"s":"BTCUSDC","b":[["34959.2","0.039226"],["34959.19","0.091558"],["34954.53","0.000264"],["34954.01","0.026"],["34939.11","0"],["34940.3","0"],["34939.85","0"],["34938.46","0"]],"a":[["34978.89","0.029858"],["34971.84","0"]],"u":20010357,"seq":14108041851}}'
2023-11-02 14:54:26,890 DEBUG ++Rcv decoded: fin=1 opcode=1 data=b'{"topic":"orderbook.50.BTCUSDC","ts":1698936866804,"type":"delta","data":{"s":"BTCUSDC","b":[["34959.2","0.039226"],["34959.19","0.091558"],["34954.53","0.000264"],["34954.01","0.026"],["34939.11","0"],["34940.3","0"],["34939.85","0"],["34938.46","0"]],"a":[["34978.89","0.029858"],["34971.84","0"]],"u":20010357,"seq":14108041851}}'
2023-11-02 14:54:26,910 DEBUG ++Rcv raw: b'\x81~\x01%{"topic":"orderbook.50.BTCUSDC","ts":1698936866824,"type":"delta","data":{"s":"BTCUSDC","b":[["34957.19","0.034336"],["34956.43","0.05154"],["34940.3","0.025298"],["34959.19","0"],["34953.26","0"],["34958.15","0"]],"a":[["34978.9","0.002162"],["34966.12","0"]],"u":20010358,"seq":14108041861}}'
2023-11-02 14:54:26,910 DEBUG ++Rcv decoded: fin=1 opcode=1 data=b'{"topic":"orderbook.50.BTCUSDC","ts":1698936866824,"type":"delta","data":{"s":"BTCUSDC","b":[["34957.19","0.034336"],["34956.43","0.05154"],["34940.3","0.025298"],["34959.19","0"],["34953.26","0"],["34958.15","0"]],"a":[["34978.9","0.002162"],["34966.12","0"]],"u":20010358,"seq":14108041861}}'
2023-11-02 14:54:26,929 DEBUG ++Rcv raw: b'\x81~\x01>{"topic":"orderbook.50.BTCUSDC","ts":1698936866844,"type":"delta","data":{"s":"BTCUSDC","b":[["34958.15","0.103729"],["34951.27","0.068671"],["34942.81","0.286181"],["34939.85","0.1875"],["34939.11","0.057242"],["34957.19","0"],["34956.43","0"],["34941.89","0"],["34959.2","0"]],"a":[],"u":20010359,"seq":14108041875}}'
2023-11-02 14:54:26,930 DEBUG ++Rcv decoded: fin=1 opcode=1 data=b'{"topic":"orderbook.50.BTCUSDC","ts":1698936866844,"type":"delta","data":{"s":"BTCUSDC","b":[["34958.15","0.103729"],["34951.27","0.068671"],["34942.81","0.286181"],["34939.85","0.1875"],["34939.11","0.057242"],["34957.19","0"],["34956.43","0"],["34941.89","0"],["34959.2","0"]],"a":[],"u":20010359,"seq":14108041875}}'
2023-11-02 14:54:26,949 DEBUG ++Rcv raw: b'\x81~\x00\xd3{"topic":"orderbook.50.BTCUSDC","ts":1698936866864,"type":"delta","data":{"s":"BTCUSDC","b":[["34953.26","0.00057"],["34939.11","0"]],"a":[["34966.12","0.00057"],["34978.9","0"]],"u":20010360,"seq":14108041882}}'
2023-11-02 14:54:26,949 DEBUG ++Rcv decoded: fin=1 opcode=1 data=b'{"topic":"orderbook.50.BTCUSDC","ts":1698936866864,"type":"delta","data":{"s":"BTCUSDC","b":[["34953.26","0.00057"],["34939.11","0"]],"a":[["34966.12","0.00057"],["34978.9","0"]],"u":20010360,"seq":14108041882}}'
2023-11-02 14:54:27,029 DEBUG ++Rcv raw: b'\x81~\x00\xfd{"topic":"orderbook.50.BTCUSDC","ts":1698936866943,"type":"delta","data":{"s":"BTCUSDC","b":[["34954.82","0.000265"],["34951.28","0.001821"],["34939.85","0"],["34940.3","0"]],"a":[["34978.9","0.002162"],["34971.82","0"]],"u":20010361,"seq":14108041896}}'
2023-11-02 14:54:27,029 DEBUG ++Rcv decoded: fin=1 opcode=1 data=b'{"topic":"orderbook.50.BTCUSDC","ts":1698936866943,"type":"delta","data":{"s":"BTCUSDC","b":[["34954.82","0.000265"],["34951.28","0.001821"],["34939.85","0"],["34940.3","0"]],"a":[["34978.9","0.002162"],["34971.82","0"]],"u":20010361,"seq":14108041896}}'
2023-11-02 14:54:27,128 DEBUG ++Rcv raw: b'\x81~\x00\xad{"topic":"orderbook.50.BTCUSDC","ts":1698936867043,"type":"delta","data":{"s":"BTCUSDC","b":[["34959.5","0.108371"],["34940.87","0"]],"a":[],"u":20010362,"seq":14108041935}}'
2023-11-02 14:54:27,129 DEBUG ++Rcv decoded: fin=1 opcode=1 data=b'{"topic":"orderbook.50.BTCUSDC","ts":1698936867043,"type":"delta","data":{"s":"BTCUSDC","b":[["34959.5","0.108371"],["34940.87","0"]],"a":[],"u":20010362,"seq":14108041935}}'
2023-11-02 14:54:27,149 DEBUG ++Rcv raw: b'\x81~\x01#{"topic":"orderbook.50.BTCUSDC","ts":1698936867064,"type":"delta","data":{"s":"BTCUSDC","b":[["34940.87","0.00154"],["34940.3","0.025298"],["34953.26","0"],["34951.28","0"]],"a":[["34980.48","0.023472"],["34980.5","0.0859"],["34966.12","0"],["34970.54","0"]],"u":20010363,"seq":14108041967}}'
2023-11-02 14:54:27,149 DEBUG ++Rcv decoded: fin=1 opcode=1 data=b'{"topic":"orderbook.50.BTCUSDC","ts":1698936867064,"type":"delta","data":{"s":"BTCUSDC","b":[["34940.87","0.00154"],["34940.3","0.025298"],["34953.26","0"],["34951.28","0"]],"a":[["34980.48","0.023472"],["34980.5","0.0859"],["34966.12","0"],["34970.54","0"]],"u":20010363,"seq":14108041967}}'
2023-11-02 14:54:27,169 DEBUG ++Rcv raw: b'\x81~\x00\xac{"topic":"orderbook.50.BTCUSDC","ts":1698936867084,"type":"delta","data":{"s":"BTCUSDC","b":[["34939.85","0.1875"],["34954.53","0"]],"a":[],"u":20010364,"seq":14108041976}}'
2023-11-02 14:54:27,169 DEBUG ++Rcv decoded: fin=1 opcode=1 data=b'{"topic":"orderbook.50.BTCUSDC","ts":1698936867084,"type":"delta","data":{"s":"BTCUSDC","b":[["34939.85","0.1875"],["34954.53","0"]],"a":[],"u":20010364,"seq":14108041976}}'
2023-11-02 14:54:27,269 DEBUG ++Rcv raw: b'\x81~\x00\xd6{"topic":"orderbook.50.BTCUSDC","ts":1698936867184,"type":"delta","data":{"s":"BTCUSDC","b":[["34957.49","0.057212"],["34951.91","0.114442"],["34951.05","0"],["34957.1","0"]],"a":[],"u":20010365,"seq":14108042031}}'
2023-11-02 14:54:27,270 DEBUG ++Rcv decoded: fin=1 opcode=1 data=b'{"topic":"orderbook.50.BTCUSDC","ts":1698936867184,"type":"delta","data":{"s":"BTCUSDC","b":[["34957.49","0.057212"],["34951.91","0.114442"],["34951.05","0"],["34957.1","0"]],"a":[],"u":20010365,"seq":14108042031}}'
2023-11-02 14:54:27,289 DEBUG ++Rcv raw: b'\x81~\x00\xae{"topic":"orderbook.50.BTCUSDC","ts":1698936867204,"type":"delta","data":{"s":"BTCUSDC","b":[["34939.11","0.057242"],["34951.27","0"]],"a":[],"u":20010366,"seq":14108042038}}'
2023-11-02 14:54:27,289 DEBUG ++Rcv decoded: fin=1 opcode=1 data=b'{"topic":"orderbook.50.BTCUSDC","ts":1698936867204,"type":"delta","data":{"s":"BTCUSDC","b":[["34939.11","0.057242"],["34951.27","0"]],"a":[],"u":20010366,"seq":14108042038}}'
2023-11-02 14:54:27,329 DEBUG ++Rcv raw: b'\x81~\x00\xae{"topic":"orderbook.50.BTCUSDC","ts":1698936867244,"type":"delta","data":{"s":"BTCUSDC","b":[["34938.46","0.029858"],["34944.01","0"]],"a":[],"u":20010367,"seq":14108042050}}'
2023-11-02 14:54:27,330 DEBUG ++Rcv decoded: fin=1 opcode=1 data=b'{"topic":"orderbook.50.BTCUSDC","ts":1698936867244,"type":"delta","data":{"s":"BTCUSDC","b":[["34938.46","0.029858"],["34944.01","0"]],"a":[],"u":20010367,"seq":14108042050}}'
2023-11-02 14:54:27,429 DEBUG ++Rcv raw: b'\x81~\x00\xa9{"topic":"orderbook.50.BTCUSDC","ts":1698936867344,"type":"delta","data":{"s":"BTCUSDC","b":[],"a":[["34970.23","0.03"],["34980.5","0"]],"u":20010368,"seq":14108042070}}'
2023-11-02 14:54:27,429 DEBUG ++Rcv decoded: fin=1 opcode=1 data=b'{"topic":"orderbook.50.BTCUSDC","ts":1698936867344,"type":"delta","data":{"s":"BTCUSDC","b":[],"a":[["34970.23","0.03"],["34980.5","0"]],"u":20010368,"seq":14108042070}}'
2023-11-02 14:54:27,549 DEBUG ++Rcv raw: b'\x81~\x00\xab{"topic":"orderbook.50.BTCUSDC","ts":1698936867464,"type":"delta","data":{"s":"BTCUSDC","b":[["34943.37","0.028"],["34938.46","0"]],"a":[],"u":20010369,"seq":14108042085}}'
2023-11-02 14:54:27,550 DEBUG ++Rcv decoded: fin=1 opcode=1 data=b'{"topic":"orderbook.50.BTCUSDC","ts":1698936867464,"type":"delta","data":{"s":"BTCUSDC","b":[["34943.37","0.028"],["34938.46","0"]],"a":[],"u":20010369,"seq":14108042085}}'
2023-11-02 14:54:27,569 DEBUG ++Rcv raw: b'\x81~\x00\xd6{"topic":"orderbook.50.BTCUSDC","ts":1698936867483,"type":"delta","data":{"s":"BTCUSDC","b":[["34938.46","0.029858"],["34954.82","0"]],"a":[["34971.71","0.000237"],["34980.48","0"]],"u":20010370,"seq":14108042090}}'
2023-11-02 14:54:27,569 DEBUG ++Rcv decoded: fin=1 opcode=1 data=b'{"topic":"orderbook.50.BTCUSDC","ts":1698936867483,"type":"delta","data":{"s":"BTCUSDC","b":[["34938.46","0.029858"],["34954.82","0"]],"a":[["34971.71","0.000237"],["34980.48","0"]],"u":20010370,"seq":14108042090}}'
2023-11-02 14:54:27,689 DEBUG ++Rcv raw: b'\x81~\x00\xad{"topic":"orderbook.50.BTCUSDC","ts":1698936867603,"type":"delta","data":{"s":"BTCUSDC","b":[],"a":[["34966.48","0.008081"],["34978.9","0"]],"u":20010371,"seq":14108042105}}'
2023-11-02 14:54:27,689 DEBUG ++Rcv decoded: fin=1 opcode=1 data=b'{"topic":"orderbook.50.BTCUSDC","ts":1698936867603,"type":"delta","data":{"s":"BTCUSDC","b":[],"a":[["34966.48","0.008081"],["34978.9","0"]],"u":20010371,"seq":14108042105}}'
2023-11-02 14:54:27,789 DEBUG ++Rcv raw: b'\x81~\x00\xad{"topic":"orderbook.50.BTCUSDC","ts":1698936867703,"type":"delta","data":{"s":"BTCUSDC","b":[],"a":[["34978.9","0.002162"],["34971.71","0"]],"u":20010372,"seq":14108042135}}'
2023-11-02 14:54:27,789 DEBUG ++Rcv decoded: fin=1 opcode=1 data=b'{"topic":"orderbook.50.BTCUSDC","ts":1698936867703,"type":"delta","data":{"s":"BTCUSDC","b":[],"a":[["34978.9","0.002162"],["34971.71","0"]],"u":20010372,"seq":14108042135}}'
2023-11-02 14:54:27,809 DEBUG ++Rcv raw: b'\x81~\x00\xae{"topic":"orderbook.50.BTCUSDC","ts":1698936867723,"type":"delta","data":{"s":"BTCUSDC","b":[["34940.31","0.112505"],["34938.46","0"]],"a":[],"u":20010373,"seq":14108042138}}'
2023-11-02 14:54:27,809 DEBUG ++Rcv decoded: fin=1 opcode=1 data=b'{"topic":"orderbook.50.BTCUSDC","ts":1698936867723,"type":"delta","data":{"s":"BTCUSDC","b":[["34940.31","0.112505"],["34938.46","0"]],"a":[],"u":20010373,"seq":14108042138}}'
2023-11-02 14:54:27,849 DEBUG ++Rcv raw: b'\x81~\x00\xad{"topic":"orderbook.50.BTCUSDC","ts":1698936867764,"type":"delta","data":{"s":"BTCUSDC","b":[],"a":[["34964.03","0.02343"],["34978.26","0"]],"u":20010374,"seq":14108042153}}'
2023-11-02 14:54:27,850 DEBUG ++Rcv decoded: fin=1 opcode=1 data=b'{"topic":"orderbook.50.BTCUSDC","ts":1698936867764,"type":"delta","data":{"s":"BTCUSDC","b":[],"a":[["34964.03","0.02343"],["34978.26","0"]],"u":20010374,"seq":14108042153}}'
2023-11-02 14:54:27,868 DEBUG ++Rcv raw: b'\x81~\x00\xad{"topic":"orderbook.50.BTCUSDC","ts":1698936867783,"type":"delta","data":{"s":"BTCUSDC","b":[],"a":[["34977.38","0.285899"],["34978.9","0"]],"u":20010375,"seq":14108042155}}'
2023-11-02 14:54:27,869 DEBUG ++Rcv decoded: fin=1 opcode=1 data=b'{"topic":"orderbook.50.BTCUSDC","ts":1698936867783,"type":"delta","data":{"s":"BTCUSDC","b":[],"a":[["34977.38","0.285899"],["34978.9","0"]],"u":20010375,"seq":14108042155}}'
2023-11-02 14:54:27,909 DEBUG ++Rcv raw: b'\x81~\x00\xae{"topic":"orderbook.50.BTCUSDC","ts":1698936867823,"type":"delta","data":{"s":"BTCUSDC","b":[["34956.38","0.000264"],["34939.11","0"]],"a":[],"u":20010376,"seq":14108042163}}'
2023-11-02 14:54:27,909 DEBUG ++Rcv decoded: fin=1 opcode=1 data=b'{"topic":"orderbook.50.BTCUSDC","ts":1698936867823,"type":"delta","data":{"s":"BTCUSDC","b":[["34956.38","0.000264"],["34939.11","0"]],"a":[],"u":20010376,"seq":14108042163}}'
2023-11-02 14:54:27,989 DEBUG ++Rcv raw: b'\x81~\x00\xd5{"topic":"orderbook.50.BTCUSDC","ts":1698936867904,"type":"delta","data":{"s":"BTCUSDC","b":[["34939.11","0.057242"],["34942.81","0"]],"a":[["34978.9","0.002162"],["34963.63","0"]],"u":20010377,"seq":14108042186}}'
2023-11-02 14:54:27,990 DEBUG ++Rcv decoded: fin=1 opcode=1 data=b'{"topic":"orderbook.50.BTCUSDC","ts":1698936867904,"type":"delta","data":{"s":"BTCUSDC","b":[["34939.11","0.057242"],["34942.81","0"]],"a":[["34978.9","0.002162"],["34963.63","0"]],"u":20010377,"seq":14108042186}}'
2023-11-02 14:54:28,009 DEBUG ++Rcv raw: b'\x81~\x00\xfe{"topic":"orderbook.50.BTCUSDC","ts":1698936867923,"type":"delta","data":{"s":"BTCUSDC","b":[["34956.82","0.000264"],["34943.66","0.286174"],["34939.85","0"],["34939.11","0"]],"a":[["34963.26","0.057202"],["34978.9","0"]],"u":20010378,"seq":14108042192}}'
2023-11-02 14:54:28,009 DEBUG ++Rcv decoded: fin=1 opcode=1 data=b'{"topic":"orderbook.50.BTCUSDC","ts":1698936867923,"type":"delta","data":{"s":"BTCUSDC","b":[["34956.82","0.000264"],["34943.66","0.286174"],["34939.85","0"],["34939.11","0"]],"a":[["34963.26","0.057202"],["34978.9","0"]],"u":20010378,"seq":14108042192}}'
2023-11-02 14:54:28,049 DEBUG ++Rcv raw: b'\x81~\x00\xae{"topic":"orderbook.50.BTCUSDC","ts":1698936867964,"type":"delta","data":{"s":"BTCUSDC","b":[["34955.36","0.052046"],["34949.48","0"]],"a":[],"u":20010379,"seq":14108042205}}'
2023-11-02 14:54:28,049 DEBUG ++Rcv decoded: fin=1 opcode=1 data=b'{"topic":"orderbook.50.BTCUSDC","ts":1698936867964,"type":"delta","data":{"s":"BTCUSDC","b":[["34955.36","0.052046"],["34949.48","0"]],"a":[],"u":20010379,"seq":14108042205}}'
2023-11-02 14:54:28,069 DEBUG ++Rcv raw: b'\x81~\x00\xd5{"topic":"orderbook.50.BTCUSDC","ts":1698936867984,"type":"delta","data":{"s":"BTCUSDC","b":[["34956.01","0.031233"],["34940.3","0"]],"a":[["34973.36","0.045647"],["34977.74","0"]],"u":20010380,"seq":14108042209}}'
2023-11-02 14:54:28,069 DEBUG ++Rcv decoded: fin=1 opcode=1 data=b'{"topic":"orderbook.50.BTCUSDC","ts":1698936867984,"type":"delta","data":{"s":"BTCUSDC","b":[["34956.01","0.031233"],["34940.3","0"]],"a":[["34973.36","0.045647"],["34977.74","0"]],"u":20010380,"seq":14108042209}}'
2023-11-02 14:54:28,129 DEBUG ++Rcv raw: b'\x81~\x00\xad{"topic":"orderbook.50.BTCUSDC","ts":1698936868043,"type":"delta","data":{"s":"BTCUSDC","b":[],"a":[["34978.9","0.002162"],["34969.35","0"]],"u":20010381,"seq":14108042220}}'
2023-11-02 14:54:28,129 DEBUG ++Rcv decoded: fin=1 opcode=1 data=b'{"topic":"orderbook.50.BTCUSDC","ts":1698936868043,"type":"delta","data":{"s":"BTCUSDC","b":[],"a":[["34978.9","0.002162"],["34969.35","0"]],"u":20010381,"seq":14108042220}}'
2023-11-02 14:54:28,149 DEBUG ++Rcv raw: b'\x81~\x00\xc6{"topic":"orderbook.50.BTCUSDC","ts":1698936868063,"type":"delta","data":{"s":"BTCUSDC","b":[],"a":[["34968.46","0.200288"],["34969.78","0.051547"],["34969.34","0"]],"u":20010382,"seq":14108042231}}'
2023-11-02 14:54:28,149 DEBUG ++Rcv decoded: fin=1 opcode=1 data=b'{"topic":"orderbook.50.BTCUSDC","ts":1698936868063,"type":"delta","data":{"s":"BTCUSDC","b":[],"a":[["34968.46","0.200288"],["34969.78","0.051547"],["34969.34","0"]],"u":20010382,"seq":14108042231}}'
2023-11-02 14:54:28,169 DEBUG ++Rcv raw: b'\x81~\x00\xad{"topic":"orderbook.50.BTCUSDC","ts":1698936868084,"type":"delta","data":{"s":"BTCUSDC","b":[],"a":[["34967.96","0.12018"],["34969.78","0"]],"u":20010383,"seq":14108042238}}'
2023-11-02 14:54:28,169 DEBUG ++Rcv decoded: fin=1 opcode=1 data=b'{"topic":"orderbook.50.BTCUSDC","ts":1698936868084,"type":"delta","data":{"s":"BTCUSDC","b":[],"a":[["34967.96","0.12018"],["34969.78","0"]],"u":20010383,"seq":14108042238}}'
2023-11-02 14:54:28,228 DEBUG ++Rcv raw: b'\x81~\x00\xad{"topic":"orderbook.50.BTCUSDC","ts":1698936868143,"type":"delta","data":{"s":"BTCUSDC","b":[["34940.3","0.025298"],["34957.91","0"]],"a":[],"u":20010384,"seq":14108042304}}'
2023-11-02 14:54:28,228 DEBUG ++Rcv decoded: fin=1 opcode=1 data=b'{"topic":"orderbook.50.BTCUSDC","ts":1698936868143,"type":"delta","data":{"s":"BTCUSDC","b":[["34940.3","0.025298"],["34957.91","0"]],"a":[],"u":20010384,"seq":14108042304}}'
2023-11-02 14:54:28,289 DEBUG ++Rcv raw: b'\x81~\x00\xad{"topic":"orderbook.50.BTCUSDC","ts":1698936868203,"type":"delta","data":{"s":"BTCUSDC","b":[],"a":[["34971.63","0.000237"],["34978.9","0"]],"u":20010385,"seq":14108042336}}'
2023-11-02 14:54:28,289 DEBUG ++Rcv decoded: fin=1 opcode=1 data=b'{"topic":"orderbook.50.BTCUSDC","ts":1698936868203,"type":"delta","data":{"s":"BTCUSDC","b":[],"a":[["34971.63","0.000237"],["34978.9","0"]],"u":20010385,"seq":14108042336}}'
2023-11-02 14:54:28,309 DEBUG ++Rcv raw: b'\x81~\x00\xac{"topic":"orderbook.50.BTCUSDC","ts":1698936868224,"type":"delta","data":{"s":"BTCUSDC","b":[["34939.85","0.1875"],["34956.38","0"]],"a":[],"u":20010386,"seq":14108042337}}'
2023-11-02 14:54:28,309 DEBUG ++Rcv decoded: fin=1 opcode=1 data=b'{"topic":"orderbook.50.BTCUSDC","ts":1698936868224,"type":"delta","data":{"s":"BTCUSDC","b":[["34939.85","0.1875"],["34956.38","0"]],"a":[],"u":20010386,"seq":14108042337}}'
2023-11-02 14:54:28,349 DEBUG ++Rcv raw: b'\x81~\x00\xae{"topic":"orderbook.50.BTCUSDC","ts":1698936868264,"type":"delta","data":{"s":"BTCUSDC","b":[["34939.11","0.057242"],["34943.37","0"]],"a":[],"u":20010387,"seq":14108042359}}'
2023-11-02 14:54:28,349 DEBUG ++Rcv decoded: fin=1 opcode=1 data=b'{"topic":"orderbook.50.BTCUSDC","ts":1698936868264,"type":"delta","data":{"s":"BTCUSDC","b":[["34939.11","0.057242"],["34943.37","0"]],"a":[],"u":20010387,"seq":14108042359}}'
2023-11-02 14:54:28,369 DEBUG ++Rcv raw: b'\x81~\x00\x9b{"topic":"orderbook.50.BTCUSDC","ts":1698936868284,"type":"delta","data":{"s":"BTCUSDC","b":[["34952.98","0.0859"]],"a":[],"u":20010388,"seq":14108042364}}'
2023-11-02 14:54:28,369 DEBUG ++Rcv decoded: fin=1 opcode=1 data=b'{"topic":"orderbook.50.BTCUSDC","ts":1698936868284,"type":"delta","data":{"s":"BTCUSDC","b":[["34952.98","0.0859"]],"a":[],"u":20010388,"seq":14108042364}}'
2023-11-02 14:54:28,429 DEBUG ++Rcv raw: b'\x81~\x00\xad{"topic":"orderbook.50.BTCUSDC","ts":1698936868344,"type":"delta","data":{"s":"BTCUSDC","b":[],"a":[["34971.6","0.000238"],["34978.89","0"]],"u":20010389,"seq":14108042376}}'
2023-11-02 14:54:28,429 DEBUG ++Rcv decoded: fin=1 opcode=1 data=b'{"topic":"orderbook.50.BTCUSDC","ts":1698936868344,"type":"delta","data":{"s":"BTCUSDC","b":[],"a":[["34971.6","0.000238"],["34978.89","0"]],"u":20010389,"seq":14108042376}}'
2023-11-02 14:54:28,550 DEBUG ++Rcv raw: b'\x81~\x00\xab{"topic":"orderbook.50.BTCUSDC","ts":1698936868464,"type":"delta","data":{"s":"BTCUSDC","b":[["34942.82","0.028"],["34939.11","0"]],"a":[],"u":20010390,"seq":14108042429}}'
2023-11-02 14:54:28,550 DEBUG ++Rcv decoded: fin=1 opcode=1 data=b'{"topic":"orderbook.50.BTCUSDC","ts":1698936868464,"type":"delta","data":{"s":"BTCUSDC","b":[["34942.82","0.028"],["34939.11","0"]],"a":[],"u":20010390,"seq":14108042429}}'
2023-11-02 14:54:28,619 DEBUG ++Rcv raw: b'\x81~\x00\xd6{"topic":"orderbook.50.BTCUSDC","ts":1698936868523,"type":"delta","data":{"s":"BTCUSDC","b":[["34939.11","0.057242"],["34956.82","0"]],"a":[["34978.89","0.029858"],["34971.63","0"]],"u":20010391,"seq":14108042459}}'
2023-11-02 14:54:28,623 DEBUG ++Rcv decoded: fin=1 opcode=1 data=b'{"topic":"orderbook.50.BTCUSDC","ts":1698936868523,"type":"delta","data":{"s":"BTCUSDC","b":[["34939.11","0.057242"],["34956.82","0"]],"a":[["34978.89","0.029858"],["34971.63","0"]],"u":20010391,"seq":14108042459}}'
2023-11-02 14:54:28,750 DEBUG ++Rcv raw: b'\x81~\x00\xac{"topic":"orderbook.50.BTCUSDC","ts":1698936868663,"type":"delta","data":{"s":"BTCUSDC","b":[],"a":[["34978.9","0.002162"],["34971.6","0"]],"u":20010392,"seq":14108042492}}'
2023-11-02 14:54:28,750 DEBUG ++Rcv decoded: fin=1 opcode=1 data=b'{"topic":"orderbook.50.BTCUSDC","ts":1698936868663,"type":"delta","data":{"s":"BTCUSDC","b":[],"a":[["34978.9","0.002162"],["34971.6","0"]],"u":20010392,"seq":14108042492}}'
2023-11-02 14:54:28,768 DEBUG ++Rcv raw: b'\x81~\x00\xae{"topic":"orderbook.50.BTCUSDC","ts":1698936868683,"type":"delta","data":{"s":"BTCUSDC","b":[],"a":[["34980.48","0.023472"],["34978.89","0"]],"u":20010393,"seq":14108042494}}'
2023-11-02 14:54:28,769 DEBUG ++Rcv decoded: fin=1 opcode=1 data=b'{"topic":"orderbook.50.BTCUSDC","ts":1698936868683,"type":"delta","data":{"s":"BTCUSDC","b":[],"a":[["34980.48","0.023472"],["34978.89","0"]],"u":20010393,"seq":14108042494}}'
2023-11-02 14:54:28,829 DEBUG ++Rcv raw: b'\x81~\x00\xab{"topic":"orderbook.50.BTCUSDC","ts":1698936868743,"type":"delta","data":{"s":"BTCUSDC","b":[["34939.12","0.823802"],["34958","0"]],"a":[],"u":20010394,"seq":14108042509}}'
2023-11-02 14:54:28,829 DEBUG ++Rcv decoded: fin=1 opcode=1 data=b'{"topic":"orderbook.50.BTCUSDC","ts":1698936868743,"type":"delta","data":{"s":"BTCUSDC","b":[["34939.12","0.823802"],["34958","0"]],"a":[],"u":20010394,"seq":14108042509}}'
2023-11-02 14:54:28,869 DEBUG ++Rcv raw: b'\x81~\x00\xd6{"topic":"orderbook.50.BTCUSDC","ts":1698936868784,"type":"delta","data":{"s":"BTCUSDC","b":[["34938.76","1.373004"],["34937.39","0.278379"],["34959.5","0"],["34957.18","0"]],"a":[],"u":20010395,"seq":14108042516}}'
2023-11-02 14:54:28,870 DEBUG ++Rcv decoded: fin=1 opcode=1 data=b'{"topic":"orderbook.50.BTCUSDC","ts":1698936868784,"type":"delta","data":{"s":"BTCUSDC","b":[["34938.76","1.373004"],["34937.39","0.278379"],["34959.5","0"],["34957.18","0"]],"a":[],"u":20010395,"seq":14108042516}}'
2023-11-02 14:54:28,889 DEBUG ++Rcv raw: b'\x81~\x00\xd6{"topic":"orderbook.50.BTCUSDC","ts":1698936868803,"type":"delta","data":{"s":"BTCUSDC","b":[["34953.26","0.00057"],["34950.32","0.013945"],["34937.39","0"],["34938.76","0"]],"a":[],"u":20010396,"seq":14108042532}}'
2023-11-02 14:54:28,889 DEBUG ++Rcv decoded: fin=1 opcode=1 data=b'{"topic":"orderbook.50.BTCUSDC","ts":1698936868803,"type":"delta","data":{"s":"BTCUSDC","b":[["34953.26","0.00057"],["34950.32","0.013945"],["34937.39","0"],["34938.76","0"]],"a":[],"u":20010396,"seq":14108042532}}'
2023-11-02 14:54:28,909 DEBUG ++Rcv raw: b'\x81~\x00\xd5{"topic":"orderbook.50.BTCUSDC","ts":1698936868823,"type":"delta","data":{"s":"BTCUSDC","b":[["34958.81","0.000264"],["34939.11","0"]],"a":[["34966.12","0.00057"],["34980.48","0"]],"u":20010397,"seq":14108042539}}'
2023-11-02 14:54:28,909 DEBUG ++Rcv decoded: fin=1 opcode=1 data=b'{"topic":"orderbook.50.BTCUSDC","ts":1698936868823,"type":"delta","data":{"s":"BTCUSDC","b":[["34958.81","0.000264"],["34939.11","0"]],"a":[["34966.12","0.00057"],["34980.48","0"]],"u":20010397,"seq":14108042539}}'
2023-11-02 14:54:28,929 DEBUG ++Rcv raw: b'\x81~\x00\xd6{"topic":"orderbook.50.BTCUSDC","ts":1698936868843,"type":"delta","data":{"s":"BTCUSDC","b":[["34939.11","0.057242"],["34953.26","0"]],"a":[["34980.48","0.023472"],["34966.12","0"]],"u":20010398,"seq":14108042544}}'
2023-11-02 14:54:28,929 DEBUG ++Rcv decoded: fin=1 opcode=1 data=b'{"topic":"orderbook.50.BTCUSDC","ts":1698936868843,"type":"delta","data":{"s":"BTCUSDC","b":[["34939.11","0.057242"],["34953.26","0"]],"a":[["34980.48","0.023472"],["34966.12","0"]],"u":20010398,"seq":14108042544}}'
2023-11-02 14:54:29,029 DEBUG ++Rcv raw: b'\x81~\x00\xac{"topic":"orderbook.50.BTCUSDC","ts":1698936868944,"type":"delta","data":{"s":"BTCUSDC","b":[],"a":[["34965.02","0.0859"],["34980.48","0"]],"u":20010399,"seq":14108042566}}'
2023-11-02 14:54:29,029 DEBUG ++Rcv decoded: fin=1 opcode=1 data=b'{"topic":"orderbook.50.BTCUSDC","ts":1698936868944,"type":"delta","data":{"s":"BTCUSDC","b":[],"a":[["34965.02","0.0859"],["34980.48","0"]],"u":20010399,"seq":14108042566}}'
2023-11-02 14:54:29,049 DEBUG ++Rcv raw: b'\x81~\x00\xd6{"topic":"orderbook.50.BTCUSDC","ts":1698936868963,"type":"delta","data":{"s":"BTCUSDC","b":[],"a":[["34963.25","0.034324"],["34965.01","0.051544"],["34978.84","0"],["34978.9","0"]],"u":20010400,"seq":14108042586}}'
2023-11-02 14:54:29,049 DEBUG ++Rcv decoded: fin=1 opcode=1 data=b'{"topic":"orderbook.50.BTCUSDC","ts":1698936868963,"type":"delta","data":{"s":"BTCUSDC","b":[],"a":[["34963.25","0.034324"],["34965.01","0.051544"],["34978.84","0"],["34978.9","0"]],"u":20010400,"seq":14108042586}}'
2023-11-02 14:54:29,069 DEBUG ++Rcv raw: b'\x81~\x00\xad{"topic":"orderbook.50.BTCUSDC","ts":1698936868984,"type":"delta","data":{"s":"BTCUSDC","b":[],"a":[["34960.26","0.00343"],["34978.78","0"]],"u":20010401,"seq":14108042608}}'
2023-11-02 14:54:29,069 DEBUG ++Rcv decoded: fin=1 opcode=1 data=b'{"topic":"orderbook.50.BTCUSDC","ts":1698936868984,"type":"delta","data":{"s":"BTCUSDC","b":[],"a":[["34960.26","0.00343"],["34978.78","0"]],"u":20010401,"seq":14108042608}}'
2023-11-02 14:54:29,089 DEBUG ++Rcv raw: b'\x81~\x00\xfd{"topic":"orderbook.50.BTCUSDC","ts":1698936869003,"type":"delta","data":{"s":"BTCUSDC","b":[["34938.76","1.373004"],["34937.39","0.278379"],["34947.41","0"],["34958.14","0"]],"a":[["34978.78","0.0859"],["34963.25","0"]],"u":20010402,"seq":14108042617}}'
2023-11-02 14:54:29,089 DEBUG ++Rcv decoded: fin=1 opcode=1 data=b'{"topic":"orderbook.50.BTCUSDC","ts":1698936869003,"type":"delta","data":{"s":"BTCUSDC","b":[["34938.76","1.373004"],["34937.39","0.278379"],["34947.41","0"],["34958.14","0"]],"a":[["34978.78","0.0859"],["34963.25","0"]],"u":20010402,"seq":14108042617}}'
2023-11-02 14:54:29,109 DEBUG ++Rcv raw: b'\x81~\x01\x07{"topic":"orderbook.50.BTCUSDC","ts":1698936869024,"type":"delta","data":{"s":"BTCUSDC","b":[["34959.27","0.000264"],["34958.15","0.051492"],["34956.43","0.051546"],["34947.83","0.051547"],["34956.01","0"],["34937.39","0"]],"a":[],"u":20010403,"seq":14108042642}}'
2023-11-02 14:54:29,109 DEBUG ++Rcv decoded: fin=1 opcode=1 data=b'{"topic":"orderbook.50.BTCUSDC","ts":1698936869024,"type":"delta","data":{"s":"BTCUSDC","b":[["34959.27","0.000264"],["34958.15","0.051492"],["34956.43","0.051546"],["34947.83","0.051547"],["34956.01","0"],["34937.39","0"]],"a":[],"u":20010403,"seq":14108042642}}'
2023-11-02 14:54:29,129 DEBUG ++Rcv raw: b'\x81~\x00\xfe{"topic":"orderbook.50.BTCUSDC","ts":1698936869043,"type":"delta","data":{"s":"BTCUSDC","b":[["34937.39","0.278379"],["34937.08","0.064686"],["34936.35","0.1875"],["34958.81","0"],["34958.15","0"],["34959.27","0"]],"a":[],"u":20010404,"seq":14108042655}}'
2023-11-02 14:54:29,129 DEBUG ++Rcv decoded: fin=1 opcode=1 data=b'{"topic":"orderbook.50.BTCUSDC","ts":1698936869043,"type":"delta","data":{"s":"BTCUSDC","b":[["34937.39","0.278379"],["34937.08","0.064686"],["34936.35","0.1875"],["34958.81","0"],["34958.15","0"],["34959.27","0"]],"a":[],"u":20010404,"seq":14108042655}}'
2023-11-02 14:54:29,150 DEBUG ++Rcv raw: b'\x81~\x02\x98{"topic":"orderbook.50.BTCUSDC","ts":1698936869064,"type":"delta","data":{"s":"BTCUSDC","b":[["34933.41","0.274814"],["34933.4","0.458014"],["34931.31","0.1875"],["34927.28","0.1125"],["34927.27","0.1875"],["34926.6","0.16261"],["34925.01","1.32582"],["34957.95","0"],["34951.91","0"],["34957.49","0"],["34954.72","0"],["34956.42","0"],["34943.66","0"],["34956","0"]],"a":[["34959.33","0.008756"],["34959.34","0.002929"],["34962","0.0324"],["34963.25","0.034329"],["34963.3","0.0859"],["34967.26","0.1875"],["34968.46","0.0859"],["34978.02","0"],["34978.28","0"],["34960.26","0"],["34978.78","0"],["34977.38","0"],["34963.26","0"]],"u":20010405,"seq":14108042718}}'
2023-11-02 14:54:29,150 DEBUG ++Rcv decoded: fin=1 opcode=1 data=b'{"topic":"orderbook.50.BTCUSDC","ts":1698936869064,"type":"delta","data":{"s":"BTCUSDC","b":[["34933.41","0.274814"],["34933.4","0.458014"],["34931.31","0.1875"],["34927.28","0.1125"],["34927.27","0.1875"],["34926.6","0.16261"],["34925.01","1.32582"],["34957.95","0"],["34951.91","0"],["34957.49","0"],["34954.72","0"],["34956.42","0"],["34943.66","0"],["34956","0"]],"a":[["34959.33","0.008756"],["34959.34","0.002929"],["34962","0.0324"],["34963.25","0.034329"],["34963.3","0.0859"],["34967.26","0.1875"],["34968.46","0.0859"],["34978.02","0"],["34978.28","0"],["34960.26","0"],["34978.78","0"],["34977.38","0"],["34963.26","0"]],"u":20010405,"seq":14108042718}}'
2023-11-02 14:54:29,169 DEBUG ++Rcv raw: b'\x81~\x02\xf8{"topic":"orderbook.50.BTCUSDC","ts":1698936869083,"type":"delta","data":{"s":"BTCUSDC","b":[["34956.89","0.028602"],["34956.29","0.057214"],["34955.37","0.031236"],["34954.71","0.05154"],["34951.54","0.00057"],["34951.09","0.114445"],["34942.72","0.286182"],["34950.32","0"],["34925.01","0"],["34927.27","0"],["34927.28","0"],["34956.43","0"],["34926.6","0"],["34931.31","0"]],"a":[["34959.31","0.008756"],["34959.32","0.03895"],["34960.26","0.002"],["34962","0.089604"],["34963.29","0.051541"],["34967.25","0.112502"],["34967.57","0.114391"],["34969.78","0.051543"],["34975.95","0.28591"],["34969.79","0"],["34967.96","0"],["34977.23","0"],["34959.34","0"],["34963.25","0"],["34976.85","0"],["34977.06","0"],["34959.33","0"]],"u":20010406,"seq":14108042766}}'
2023-11-02 14:54:29,169 DEBUG ++Rcv decoded: fin=1 opcode=1 data=b'{"topic":"orderbook.50.BTCUSDC","ts":1698936869083,"type":"delta","data":{"s":"BTCUSDC","b":[["34956.89","0.028602"],["34956.29","0.057214"],["34955.37","0.031236"],["34954.71","0.05154"],["34951.54","0.00057"],["34951.09","0.114445"],["34942.72","0.286182"],["34950.32","0"],["34925.01","0"],["34927.27","0"],["34927.28","0"],["34956.43","0"],["34926.6","0"],["34931.31","0"]],"a":[["34959.31","0.008756"],["34959.32","0.03895"],["34960.26","0.002"],["34962","0.089604"],["34963.29","0.051541"],["34967.25","0.112502"],["34967.57","0.114391"],["34969.78","0.051543"],["34975.95","0.28591"],["34969.79","0"],["34967.96","0"],["34977.23","0"],["34959.34","0"],["34963.25","0"],["34976.85","0"],["34977.06","0"],["34959.33","0"]],"u":20010406,"seq":14108042766}}'
2023-11-02 14:54:29,189 DEBUG ++Rcv raw: b'\x81~\x01J{"topic":"orderbook.50.BTCUSDC","ts":1698936869103,"type":"delta","data":{"s":"BTCUSDC","b":[["34951.27","0.068671"],["34931.31","0.1875"],["34951.54","0"],["34956.29","0"]],"a":[["34976.85","0.05718"],["34977.06","0.0859"],["34977.23","0.1875"],["34959.32","0"],["34969.78","0"],["34976.22","0"]],"u":20010407,"seq":14108042776}}'
2023-11-02 14:54:29,190 DEBUG ++Rcv decoded: fin=1 opcode=1 data=b'{"topic":"orderbook.50.BTCUSDC","ts":1698936869103,"type":"delta","data":{"s":"BTCUSDC","b":[["34951.27","0.068671"],["34931.31","0.1875"],["34951.54","0"],["34956.29","0"]],"a":[["34976.85","0.05718"],["34977.06","0.0859"],["34977.23","0.1875"],["34959.32","0"],["34969.78","0"],["34976.22","0"]],"u":20010407,"seq":14108042776}}'
2023-11-02 14:54:29,209 DEBUG ++Rcv raw: b'\x81~\x00\xab{"topic":"orderbook.50.BTCUSDC","ts":1698936869123,"type":"delta","data":{"s":"BTCUSDC","b":[["34953.12","0.026"],["34954.01","0"]],"a":[],"u":20010408,"seq":14108042801}}'
2023-11-02 14:54:29,209 DEBUG ++Rcv decoded: fin=1 opcode=1 data=b'{"topic":"orderbook.50.BTCUSDC","ts":1698936869123,"type":"delta","data":{"s":"BTCUSDC","b":[["34953.12","0.026"],["34954.01","0"]],"a":[],"u":20010408,"seq":14108042801}}'
2023-11-02 14:54:29,229 DEBUG ++Rcv raw: b'\x81~\x017{"topic":"orderbook.50.BTCUSDC","ts":1698936869143,"type":"delta","data":{"s":"BTCUSDC","b":[["34927.28","0.1125"],["34927.27","0.1875"],["34942.72","0"],["34951.09","0"]],"a":[["34962","0.0324"],["34978.02","0.114412"],["34978.28","0.001447"],["34975.95","0"],["34967.57","0"]],"u":20010409,"seq":14108042822}}'
2023-11-02 14:54:29,229 DEBUG ++Rcv decoded: fin=1 opcode=1 data=b'{"topic":"orderbook.50.BTCUSDC","ts":1698936869143,"type":"delta","data":{"s":"BTCUSDC","b":[["34927.28","0.1125"],["34927.27","0.1875"],["34942.72","0"],["34951.09","0"]],"a":[["34962","0.0324"],["34978.02","0.114412"],["34978.28","0.001447"],["34975.95","0"],["34967.57","0"]],"u":20010409,"seq":14108042822}}'
2023-11-02 14:54:29,249 DEBUG ++Rcv raw: b'\x81~\x00\xd4{"topic":"orderbook.50.BTCUSDC","ts":1698936869163,"type":"delta","data":{"s":"BTCUSDC","b":[["34926.6","0.16261"],["34951.27","0"]],"a":[["34969.99","0.051545"],["34978.28","0"]],"u":20010410,"seq":14108042828}}'
2023-11-02 14:54:29,249 DEBUG ++Rcv decoded: fin=1 opcode=1 data=b'{"topic":"orderbook.50.BTCUSDC","ts":1698936869163,"type":"delta","data":{"s":"BTCUSDC","b":[["34926.6","0.16261"],["34951.27","0"]],"a":[["34969.99","0.051545"],["34978.28","0"]],"u":20010410,"seq":14108042828}}'
2023-11-02 14:54:29,309 DEBUG ++Rcv raw: b'\x81~\x00\xad{"topic":"orderbook.50.BTCUSDC","ts":1698936869223,"type":"delta","data":{"s":"BTCUSDC","b":[],"a":[["34961.22","0.01144"],["34978.02","0"]],"u":20010411,"seq":14108042857}}'
2023-11-02 14:54:29,309 DEBUG ++Rcv decoded: fin=1 opcode=1 data=b'{"topic":"orderbook.50.BTCUSDC","ts":1698936869223,"type":"delta","data":{"s":"BTCUSDC","b":[],"a":[["34961.22","0.01144"],["34978.02","0"]],"u":20010411,"seq":14108042857}}'
2023-11-02 14:54:29,349 DEBUG ++Rcv raw: b'\x81~\x01x{"topic":"orderbook.50.BTCUSDC","ts":1698936869263,"type":"delta","data":{"s":"BTCUSDC","b":[["34956.23","0.057214"],["34951.04","0.114445"],["34942.67","0.286182"],["34926.6","0"],["34927.27","0"],["34942.82","0"]],"a":[["34961.93","0.057205"],["34967.12","0.114393"],["34975.5","0.285914"],["34977.23","0"],["34976.85","0"],["34977.06","0"]],"u":20010412,"seq":14108042889}}'
2023-11-02 14:54:29,349 DEBUG ++Rcv decoded: fin=1 opcode=1 data=b'{"topic":"orderbook.50.BTCUSDC","ts":1698936869263,"type":"delta","data":{"s":"BTCUSDC","b":[["34956.23","0.057214"],["34951.04","0.114445"],["34942.67","0.286182"],["34926.6","0"],["34927.27","0"],["34942.82","0"]],"a":[["34961.93","0.057205"],["34967.12","0.114393"],["34975.5","0.285914"],["34977.23","0"],["34976.85","0"],["34977.06","0"]],"u":20010412,"seq":14108042889}}'
2023-11-02 14:54:29,369 DEBUG ++Rcv raw: b'\x81~\x00\xae{"topic":"orderbook.50.BTCUSDC","ts":1698936869284,"type":"delta","data":{"s":"BTCUSDC","b":[["34951.27","0.068673"],["34927.28","0"]],"a":[],"u":20010413,"seq":14108042890}}'
2023-11-02 14:54:29,370 DEBUG ++Rcv decoded: fin=1 opcode=1 data=b'{"topic":"orderbook.50.BTCUSDC","ts":1698936869284,"type":"delta","data":{"s":"BTCUSDC","b":[["34951.27","0.068673"],["34927.28","0"]],"a":[],"u":20010413,"seq":14108042890}}'
2023-11-02 14:54:29,389 DEBUG ++Rcv raw: b'\x81~\x00\xd4{"topic":"orderbook.50.BTCUSDC","ts":1698936869303,"type":"delta","data":{"s":"BTCUSDC","b":[["34927.28","0.1125"],["34954.63","0"]],"a":[["34958.81","0.003351"],["34970.23","0"]],"u":20010414,"seq":14108042895}}'
2023-11-02 14:54:29,389 DEBUG ++Rcv decoded: fin=1 opcode=1 data=b'{"topic":"orderbook.50.BTCUSDC","ts":1698936869303,"type":"delta","data":{"s":"BTCUSDC","b":[["34927.28","0.1125"],["34954.63","0"]],"a":[["34958.81","0.003351"],["34970.23","0"]],"u":20010414,"seq":14108042895}}'
2023-11-02 14:54:29,409 DEBUG ++Rcv raw: b'\x81~\x00\xad{"topic":"orderbook.50.BTCUSDC","ts":1698936869324,"type":"delta","data":{"s":"BTCUSDC","b":[],"a":[["34976.85","0.05718"],["34961.22","0"]],"u":20010415,"seq":14108042903}}'
2023-11-02 14:54:29,409 DEBUG ++Rcv decoded: fin=1 opcode=1 data=b'{"topic":"orderbook.50.BTCUSDC","ts":1698936869324,"type":"delta","data":{"s":"BTCUSDC","b":[],"a":[["34976.85","0.05718"],["34961.22","0"]],"u":20010415,"seq":14108042903}}'
2023-11-02 14:54:29,429 DEBUG ++Rcv raw: b'\x81~\x00\xae{"topic":"orderbook.50.BTCUSDC","ts":1698936869343,"type":"delta","data":{"s":"BTCUSDC","b":[],"a":[["34971.45","0.000237"],["34976.85","0"]],"u":20010416,"seq":14108042908}}'
2023-11-02 14:54:29,429 DEBUG ++Rcv decoded: fin=1 opcode=1 data=b'{"topic":"orderbook.50.BTCUSDC","ts":1698936869343,"type":"delta","data":{"s":"BTCUSDC","b":[],"a":[["34971.45","0.000237"],["34976.85","0"]],"u":20010416,"seq":14108042908}}'
2023-11-02 14:54:29,489 DEBUG ++Rcv raw: b'\x81~\x00\xad{"topic":"orderbook.50.BTCUSDC","ts":1698936869404,"type":"delta","data":{"s":"BTCUSDC","b":[],"a":[["34976.85","0.05718"],["34959.31","0"]],"u":20010417,"seq":14108042930}}'
2023-11-02 14:54:29,489 DEBUG ++Rcv decoded: fin=1 opcode=1 data=b'{"topic":"orderbook.50.BTCUSDC","ts":1698936869404,"type":"delta","data":{"s":"BTCUSDC","b":[],"a":[["34976.85","0.05718"],["34959.31","0"]],"u":20010417,"seq":14108042930}}'
2023-11-02 14:54:29,509 DEBUG ++Rcv raw: b'\x81~\x00\xac{"topic":"orderbook.50.BTCUSDC","ts":1698936869424,"type":"delta","data":{"s":"BTCUSDC","b":[["34942.66","0.0859"],["34927.28","0"]],"a":[],"u":20010418,"seq":14108042938}}'
2023-11-02 14:54:29,510 DEBUG ++Rcv decoded: fin=1 opcode=1 data=b'{"topic":"orderbook.50.BTCUSDC","ts":1698936869424,"type":"delta","data":{"s":"BTCUSDC","b":[["34942.66","0.0859"],["34927.28","0"]],"a":[],"u":20010418,"seq":14108042938}}'
2023-11-02 14:54:29,529 DEBUG ++Rcv raw: b'\x81~\x00\xae{"topic":"orderbook.50.BTCUSDC","ts":1698936869444,"type":"delta","data":{"s":"BTCUSDC","b":[["34937.84","0.040649"],["34931.31","0"]],"a":[],"u":20010419,"seq":14108042955}}'
2023-11-02 14:54:29,529 DEBUG ++Rcv decoded: fin=1 opcode=1 data=b'{"topic":"orderbook.50.BTCUSDC","ts":1698936869444,"type":"delta","data":{"s":"BTCUSDC","b":[["34937.84","0.040649"],["34931.31","0"]],"a":[],"u":20010419,"seq":14108042955}}'
2023-11-02 14:54:29,550 DEBUG ++Rcv raw: b'\x81~\x00\xd0{"topic":"orderbook.50.BTCUSDC","ts":1698936869464,"type":"delta","data":{"s":"BTCUSDC","b":[["34943.37","0.028"],["34933.4","0"]],"a":[["34958.8","0.01144"],["34958.81","0"]],"u":20010420,"seq":14108042976}}'
2023-11-02 14:54:29,551 DEBUG ++Rcv decoded: fin=1 opcode=1 data=b'{"topic":"orderbook.50.BTCUSDC","ts":1698936869464,"type":"delta","data":{"s":"BTCUSDC","b":[["34943.37","0.028"],["34933.4","0"]],"a":[["34958.8","0.01144"],["34958.81","0"]],"u":20010420,"seq":14108042976}}'
2023-11-02 14:54:29,570 DEBUG ++Rcv raw: b'\x81~\x00\xcf{"topic":"orderbook.50.BTCUSDC","ts":1698936869484,"type":"delta","data":{"s":"BTCUSDC","b":[["34951.19","0.036"],["34933.41","0"]],"a":[["34964.02","0.03"],["34976.85","0"]],"u":20010421,"seq":14108042982}}'
2023-11-02 14:54:29,570 DEBUG ++Rcv decoded: fin=1 opcode=1 data=b'{"topic":"orderbook.50.BTCUSDC","ts":1698936869484,"type":"delta","data":{"s":"BTCUSDC","b":[["34951.19","0.036"],["34933.41","0"]],"a":[["34964.02","0.03"],["34976.85","0"]],"u":20010421,"seq":14108042982}}'
2023-11-02 14:54:29,649 DEBUG ++Rcv raw: b'\x81~\x00\xfa{"topic":"orderbook.50.BTCUSDC","ts":1698936869564,"type":"delta","data":{"s":"BTCUSDC","b":[["34950.2","0.014376"],["34956.23","0"]],"a":[["34976.85","0.05718"],["34977.06","0.0859"],["34958.8","0"],["34961.93","0"]],"u":20010422,"seq":14108043007}}'
2023-11-02 14:54:29,650 DEBUG ++Rcv decoded: fin=1 opcode=1 data=b'{"topic":"orderbook.50.BTCUSDC","ts":1698936869564,"type":"delta","data":{"s":"BTCUSDC","b":[["34950.2","0.014376"],["34956.23","0"]],"a":[["34976.85","0.05718"],["34977.06","0.0859"],["34958.8","0"],["34961.93","0"]],"u":20010422,"seq":14108043007}}'
2023-11-02 14:54:29,669 DEBUG ++Rcv raw: b'\x81~\x01M{"topic":"orderbook.50.BTCUSDC","ts":1698936869583,"type":"delta","data":{"s":"BTCUSDC","b":[["34956.71","0.057213"],["34952","0.00057"],["34948.63","0.000261"],["34936.35","0"],["34937.39","0"],["34937.08","0"]],"a":[["34962.34","0.057204"],["34971.42","0.000239"],["34976.85","0"],["34977.06","0"]],"u":20010423,"seq":14108043020}}'
2023-11-02 14:54:29,669 DEBUG ++Rcv decoded: fin=1 opcode=1 data=b'{"topic":"orderbook.50.BTCUSDC","ts":1698936869583,"type":"delta","data":{"s":"BTCUSDC","b":[["34956.71","0.057213"],["34952","0.00057"],["34948.63","0.000261"],["34936.35","0"],["34937.39","0"],["34937.08","0"]],"a":[["34962.34","0.057204"],["34971.42","0.000239"],["34976.85","0"],["34977.06","0"]],"u":20010423,"seq":14108043020}}'
2023-11-02 14:54:29,729 DEBUG ++Rcv raw: b'\x81~\x01v{"topic":"orderbook.50.BTCUSDC","ts":1698936869643,"type":"delta","data":{"s":"BTCUSDC","b":[["34949.57","0.00131"],["34943.58","0.286175"],["34937.39","0.278379"],["34951.04","0"],["34942.67","0"],["34956.71","0"]],"a":[["34958.79","0.01144"],["34976.35","0.285907"],["34976.85","0.05718"],["34962.34","0"],["34967.12","0"],["34975.5","0"]],"u":20010424,"seq":14108043053}}'
2023-11-02 14:54:29,729 DEBUG ++Rcv decoded: fin=1 opcode=1 data=b'{"topic":"orderbook.50.BTCUSDC","ts":1698936869643,"type":"delta","data":{"s":"BTCUSDC","b":[["34949.57","0.00131"],["34943.58","0.286175"],["34937.39","0.278379"],["34951.04","0"],["34942.67","0"],["34956.71","0"]],"a":[["34958.79","0.01144"],["34976.35","0.285907"],["34976.85","0.05718"],["34962.34","0"],["34967.12","0"],["34975.5","0"]],"u":20010424,"seq":14108043053}}'
2023-11-02 14:54:29,749 DEBUG ++Rcv raw: b'\x81~\x00\xea{"topic":"orderbook.50.BTCUSDC","ts":1698936869663,"type":"delta","data":{"s":"BTCUSDC","b":[["34951.95","0.114442"],["34937.08","0.064686"],["34951.27","0"],["34952","0"]],"a":[["34967.97","0.15334"]],"u":20010425,"seq":14108043061}}'
2023-11-02 14:54:29,749 DEBUG ++Rcv decoded: fin=1 opcode=1 data=b'{"topic":"orderbook.50.BTCUSDC","ts":1698936869663,"type":"delta","data":{"s":"BTCUSDC","b":[["34951.95","0.114442"],["34937.08","0.064686"],["34951.27","0"],["34952","0"]],"a":[["34967.97","0.15334"]],"u":20010425,"seq":14108043061}}'
2023-11-02 14:54:29,789 DEBUG ++Rcv raw: b'\x81~\x00\xae{"topic":"orderbook.50.BTCUSDC","ts":1698936869704,"type":"delta","data":{"s":"BTCUSDC","b":[["34957.26","0.099605"],["34937.08","0"]],"a":[],"u":20010426,"seq":14108043069}}'
2023-11-02 14:54:29,789 DEBUG ++Rcv decoded: fin=1 opcode=1 data=b'{"topic":"orderbook.50.BTCUSDC","ts":1698936869704,"type":"delta","data":{"s":"BTCUSDC","b":[["34957.26","0.099605"],["34937.08","0"]],"a":[],"u":20010426,"seq":14108043069}}'
2023-11-02 14:54:29,809 DEBUG ++Rcv raw: b'\x81~\x00\xae{"topic":"orderbook.50.BTCUSDC","ts":1698936869723,"type":"delta","data":{"s":"BTCUSDC","b":[["34937.08","0.064686"],["34954.71","0"]],"a":[],"u":20010427,"seq":14108043071}}'
2023-11-02 14:54:29,809 DEBUG ++Rcv decoded: fin=1 opcode=1 data=b'{"topic":"orderbook.50.BTCUSDC","ts":1698936869723,"type":"delta","data":{"s":"BTCUSDC","b":[["34937.08","0.064686"],["34954.71","0"]],"a":[],"u":20010427,"seq":14108043071}}'
2023-11-02 14:54:29,829 DEBUG ++Rcv raw: b'\x81~\x00\xfd{"topic":"orderbook.50.BTCUSDC","ts":1698936869743,"type":"delta","data":{"s":"BTCUSDC","b":[["34948.64","0.000262"],["34941.18","0.094271"],["34937.08","0"],["34937.39","0"]],"a":[["34977.06","0.0859"],["34958.79","0"]],"u":20010428,"seq":14108043077}}'
2023-11-02 14:54:29,829 DEBUG ++Rcv decoded: fin=1 opcode=1 data=b'{"topic":"orderbook.50.BTCUSDC","ts":1698936869743,"type":"delta","data":{"s":"BTCUSDC","b":[["34948.64","0.000262"],["34941.18","0.094271"],["34937.08","0"],["34937.39","0"]],"a":[["34977.06","0.0859"],["34958.79","0"]],"u":20010428,"seq":14108043077}}'
2023-11-02 14:54:29,849 DEBUG ++Rcv raw: b'\x81~\x00\xad{"topic":"orderbook.50.BTCUSDC","ts":1698936869763,"type":"delta","data":{"s":"BTCUSDC","b":[["34952.37","0.00057"],["34937.84","0"]],"a":[],"u":20010429,"seq":14108043088}}'
2023-11-02 14:54:29,849 DEBUG ++Rcv decoded: fin=1 opcode=1 data=b'{"topic":"orderbook.50.BTCUSDC","ts":1698936869763,"type":"delta","data":{"s":"BTCUSDC","b":[["34952.37","0.00057"],["34937.84","0"]],"a":[],"u":20010429,"seq":14108043088}}'
2023-11-02 14:54:29,910 DEBUG ++Rcv raw: b'\x81~\x01\xe0{"topic":"orderbook.50.BTCUSDC","ts":1698936869824,"type":"delta","data":{"s":"BTCUSDC","b":[["34937.84","0.040649"],["34937.39","0.278379"],["34937.08","0.064686"],["34936.35","0.1875"],["34933.41","0.274814"],["34953.12","0"],["34943.58","0"],["34957.26","0"],["34951.95","0"],["34947.67","0"]],"a":[["34958.78","0.01144"],["34959.77","0.003199"],["34960.25","0.008756"],["34967.97","0.03895"],["34976.35","0"],["34977.06","0"],["34976.85","0"]],"u":20010430,"seq":14108043114}}'
2023-11-02 14:54:29,910 DEBUG ++Rcv decoded: fin=1 opcode=1 data=b'{"topic":"orderbook.50.BTCUSDC","ts":1698936869824,"type":"delta","data":{"s":"BTCUSDC","b":[["34937.84","0.040649"],["34937.39","0.278379"],["34937.08","0.064686"],["34936.35","0.1875"],["34933.41","0.274814"],["34953.12","0"],["34943.58","0"],["34957.26","0"],["34951.95","0"],["34947.67","0"]],"a":[["34958.78","0.01144"],["34959.77","0.003199"],["34960.25","0.008756"],["34967.97","0.03895"],["34976.35","0"],["34977.06","0"],["34976.85","0"]],"u":20010430,"seq":14108043114}}'
2023-11-02 14:54:29,929 DEBUG ++Rcv raw: b'\x81~\x02N{"topic":"orderbook.50.BTCUSDC","ts":1698936869844,"type":"delta","data":{"s":"BTCUSDC","b":[["34954.71","0.051548"],["34954.54","0.057217"],["34950","0.148549"],["34941.63","0.286191"],["34933.4","0.458014"],["34931.31","0.1875"],["34954.7","0"],["34955.37","0"],["34952.37","0"],["34956.89","0"],["34954","0"]],"a":[["34958.77","0.031852"],["34960","0.0324"],["34960.21","0.057207"],["34961.58","0.0859"],["34966.04","0.114396"],["34974.42","0.285923"],["34971.45","0"],["34959.77","0"],["34960.25","0"],["34976.23","0"],["34976.24","0"],["34975.34","0"]],"u":20010431,"seq":14108043149}}'
2023-11-02 14:54:29,930 DEBUG ++Rcv decoded: fin=1 opcode=1 data=b'{"topic":"orderbook.50.BTCUSDC","ts":1698936869844,"type":"delta","data":{"s":"BTCUSDC","b":[["34954.71","0.051548"],["34954.54","0.057217"],["34950","0.148549"],["34941.63","0.286191"],["34933.4","0.458014"],["34931.31","0.1875"],["34954.7","0"],["34955.37","0"],["34952.37","0"],["34956.89","0"],["34954","0"]],"a":[["34958.77","0.031852"],["34960","0.0324"],["34960.21","0.057207"],["34961.58","0.0859"],["34966.04","0.114396"],["34974.42","0.285923"],["34971.45","0"],["34959.77","0"],["34960.25","0"],["34976.23","0"],["34976.24","0"],["34975.34","0"]],"u":20010431,"seq":14108043149}}'
2023-11-02 14:54:29,949 DEBUG ++Rcv raw: b'\x81~\x01\x7f{"topic":"orderbook.50.BTCUSDC","ts":1698936869864,"type":"delta","data":{"s":"BTCUSDC","b":[["34954.71","0.034339"],["34950.47","0.00057"],["34950.01","0.089129"],["34954.54","0"],["34941.18","0"]],"a":[["34958.76","0.03895"],["34958.77","0.008756"],["34961.57","0.051541"],["34965.99","0.068639"],["34975.22","0"],["34960.21","0"],["34966.73","0"]],"u":20010432,"seq":14108043177}}'
2023-11-02 14:54:29,949 DEBUG ++Rcv decoded: fin=1 opcode=1 data=b'{"topic":"orderbook.50.BTCUSDC","ts":1698936869864,"type":"delta","data":{"s":"BTCUSDC","b":[["34954.71","0.034339"],["34950.47","0.00057"],["34950.01","0.089129"],["34954.54","0"],["34941.18","0"]],"a":[["34958.76","0.03895"],["34958.77","0.008756"],["34961.57","0.051541"],["34965.99","0.068639"],["34975.22","0"],["34960.21","0"],["34966.73","0"]],"u":20010432,"seq":14108043177}}'
2023-11-02 14:54:29,969 DEBUG ++Rcv raw: b'\x81~\x015{"topic":"orderbook.50.BTCUSDC","ts":1698936869883,"type":"delta","data":{"s":"BTCUSDC","b":[["34950","0.0341"],["34927.28","0.1125"],["34927.27","0.1875"],["34954.71","0"],["34941.63","0"]],"a":[["34975.22","1.372918"],["34975.34","0.0859"],["34966.04","0"],["34974.42","0"]],"u":20010433,"seq":14108043188}}'
2023-11-02 14:54:29,969 DEBUG ++Rcv decoded: fin=1 opcode=1 data=b'{"topic":"orderbook.50.BTCUSDC","ts":1698936869883,"type":"delta","data":{"s":"BTCUSDC","b":[["34950","0.0341"],["34927.28","0.1125"],["34927.27","0.1875"],["34954.71","0"],["34941.63","0"]],"a":[["34975.22","1.372918"],["34975.34","0.0859"],["34966.04","0"],["34974.42","0"]],"u":20010433,"seq":14108043188}}'
2023-11-02 14:54:29,988 DEBUG ++Rcv raw: b'\x81~\x00\xd4{"topic":"orderbook.50.BTCUSDC","ts":1698936869903,"type":"delta","data":{"s":"BTCUSDC","b":[["34926.6","0.16261"],["34950.01","0"]],"a":[["34966.73","0.051543"],["34965.99","0"]],"u":20010434,"seq":14108043194}}'
2023-11-02 14:54:29,989 DEBUG ++Rcv decoded: fin=1 opcode=1 data=b'{"topic":"orderbook.50.BTCUSDC","ts":1698936869903,"type":"delta","data":{"s":"BTCUSDC","b":[["34926.6","0.16261"],["34950.01","0"]],"a":[["34966.73","0.051543"],["34965.99","0"]],"u":20010434,"seq":14108043194}}'
2023-11-02 14:54:30,029 DEBUG ++Rcv raw: b'\x81~\x00\xae{"topic":"orderbook.50.BTCUSDC","ts":1698936869943,"type":"delta","data":{"s":"BTCUSDC","b":[],"a":[["34958.75","0.008756"],["34958.77","0"]],"u":20010435,"seq":14108043199}}'
2023-11-02 14:54:30,029 DEBUG ++Rcv decoded: fin=1 opcode=1 data=b'{"topic":"orderbook.50.BTCUSDC","ts":1698936869943,"type":"delta","data":{"s":"BTCUSDC","b":[],"a":[["34958.75","0.008756"],["34958.77","0"]],"u":20010435,"seq":14108043199}}'
2023-11-02 14:54:30,051 DEBUG ++Rcv raw: b'\x81~\x01y{"topic":"orderbook.50.BTCUSDC","ts":1698936869964,"type":"delta","data":{"s":"BTCUSDC","b":[["34957.02","0.057213"],["34951.83","0.114443"],["34947.39","0.042687"],["34942.67","0.286183"],["34927.28","0"],["34948.63","0"],["34927.27","0"],["34926.6","0"]],"a":[["34962.65","0.057203"],["34967.07","0.114393"],["34971.42","0"],["34958.76","0"]],"u":20010436,"seq":14108043222}}'
2023-11-02 14:54:30,051 DEBUG ++Rcv decoded: fin=1 opcode=1 data=b'{"topic":"orderbook.50.BTCUSDC","ts":1698936869964,"type":"delta","data":{"s":"BTCUSDC","b":[["34957.02","0.057213"],["34951.83","0.114443"],["34947.39","0.042687"],["34942.67","0.286183"],["34927.28","0"],["34948.63","0"],["34927.27","0"],["34926.6","0"]],"a":[["34962.65","0.057203"],["34967.07","0.114393"],["34971.42","0"],["34958.76","0"]],"u":20010436,"seq":14108043222}}'
2023-11-02 14:54:30,068 DEBUG ++Rcv raw: b'\x81~\x00\xfa{"topic":"orderbook.50.BTCUSDC","ts":1698936869983,"type":"delta","data":{"s":"BTCUSDC","b":[["34954.7","0.0859"],["34927.28","0.1125"],["34942.67","0"],["34950.47","0"]],"a":[["34976.23","0.080337"],["34967.07","0"]],"u":20010437,"seq":14108043234}}'
2023-11-02 14:54:30,068 DEBUG ++Rcv decoded: fin=1 opcode=1 data=b'{"topic":"orderbook.50.BTCUSDC","ts":1698936869983,"type":"delta","data":{"s":"BTCUSDC","b":[["34954.7","0.0859"],["34927.28","0.1125"],["34942.67","0"],["34950.47","0"]],"a":[["34976.23","0.080337"],["34967.07","0"]],"u":20010437,"seq":14108043234}}'
2023-11-02 14:54:30,089 DEBUG ++Rcv raw: b'\x81~\x00\xd6{"topic":"orderbook.50.BTCUSDC","ts":1698936870003,"type":"delta","data":{"s":"BTCUSDC","b":[["34954.71","0.051544"],["34951.84","0.06867"],["34953.11","0"],["34927.28","0"]],"a":[],"u":20010438,"seq":14108043246}}'
2023-11-02 14:54:30,089 DEBUG ++Rcv decoded: fin=1 opcode=1 data=b'{"topic":"orderbook.50.BTCUSDC","ts":1698936870003,"type":"delta","data":{"s":"BTCUSDC","b":[["34954.71","0.051544"],["34951.84","0.06867"],["34953.11","0"],["34927.28","0"]],"a":[],"u":20010438,"seq":14108043246}}'
2023-11-02 14:54:30,109 DEBUG ++Rcv raw: b'\x81~\x00\xac{"topic":"orderbook.50.BTCUSDC","ts":1698936870023,"type":"delta","data":{"s":"BTCUSDC","b":[["34927.28","0.1125"],["34957.02","0"]],"a":[],"u":20010439,"seq":14108043249}}'
2023-11-02 14:54:30,109 DEBUG ++Rcv decoded: fin=1 opcode=1 data=b'{"topic":"orderbook.50.BTCUSDC","ts":1698936870023,"type":"delta","data":{"s":"BTCUSDC","b":[["34927.28","0.1125"],["34957.02","0"]],"a":[],"u":20010439,"seq":14108043249}}'
2023-11-02 14:54:30,128 DEBUG ++Rcv raw: b'\x81~\x00\xad{"topic":"orderbook.50.BTCUSDC","ts":1698936870043,"type":"delta","data":{"s":"BTCUSDC","b":[["34950.47","0.00057"],["34927.28","0"]],"a":[],"u":20010440,"seq":14108043251}}'
2023-11-02 14:54:30,129 DEBUG ++Rcv decoded: fin=1 opcode=1 data=b'{"topic":"orderbook.50.BTCUSDC","ts":1698936870043,"type":"delta","data":{"s":"BTCUSDC","b":[["34950.47","0.00057"],["34927.28","0"]],"a":[],"u":20010440,"seq":14108043251}}'
2023-11-02 14:54:30,149 DEBUG ++Rcv raw: b'\x81~\x00\xd3{"topic":"orderbook.50.BTCUSDC","ts":1698936870063,"type":"delta","data":{"s":"BTCUSDC","b":[["34927.28","0.1125"],["34950.2","0"]],"a":[["34976.24","0.278379"],["34958.78","0"]],"u":20010441,"seq":14108043259}}'
2023-11-02 14:54:30,149 DEBUG ++Rcv decoded: fin=1 opcode=1 data=b'{"topic":"orderbook.50.BTCUSDC","ts":1698936870063,"type":"delta","data":{"s":"BTCUSDC","b":[["34927.28","0.1125"],["34950.2","0"]],"a":[["34976.24","0.278379"],["34958.78","0"]],"u":20010441,"seq":14108043259}}'
2023-11-02 14:54:30,169 DEBUG ++Rcv raw: b'\x81~\x01\'{"topic":"orderbook.50.BTCUSDC","ts":1698936870083,"type":"delta","data":{"s":"BTCUSDC","b":[["34957.37","0.057212"],["34943.56","0.286175"],["34931.31","0"],["34927.28","0"]],"a":[["34963.07","0.057203"],["34967.94","0.11439"],["34962.65","0"],["34976.24","0"]],"u":20010442,"seq":14108043284}}'
2023-11-02 14:54:30,169 DEBUG ++Rcv decoded: fin=1 opcode=1 data=b'{"topic":"orderbook.50.BTCUSDC","ts":1698936870083,"type":"delta","data":{"s":"BTCUSDC","b":[["34957.37","0.057212"],["34943.56","0.286175"],["34931.31","0"],["34927.28","0"]],"a":[["34963.07","0.057203"],["34967.94","0.11439"],["34962.65","0"],["34976.24","0"]],"u":20010442,"seq":14108043284}}'
2023-11-02 14:54:30,189 DEBUG ++Rcv raw: b'\x81~\x00\xd6{"topic":"orderbook.50.BTCUSDC","ts":1698936870103,"type":"delta","data":{"s":"BTCUSDC","b":[["34949.73","0.014633"],["34950.47","0"]],"a":[["34976.24","0.278379"],["34961.58","0"]],"u":20010443,"seq":14108043293}}'
2023-11-02 14:54:30,189 DEBUG ++Rcv decoded: fin=1 opcode=1 data=b'{"topic":"orderbook.50.BTCUSDC","ts":1698936870103,"type":"delta","data":{"s":"BTCUSDC","b":[["34949.73","0.014633"],["34950.47","0"]],"a":[["34976.24","0.278379"],["34961.58","0"]],"u":20010443,"seq":14108043293}}'
2023-11-02 14:54:30,209 DEBUG ++Rcv raw: b'\x81~\x00\xd7{"topic":"orderbook.50.BTCUSDC","ts":1698936870123,"type":"delta","data":{"s":"BTCUSDC","b":[],"a":[["34963.06","0.085867"],["34976.31","0.285907"],["34963.29","0"],["34961.57","0"]],"u":20010444,"seq":14108043300}}'
2023-11-02 14:54:30,209 DEBUG ++Rcv decoded: fin=1 opcode=1 data=b'{"topic":"orderbook.50.BTCUSDC","ts":1698936870123,"type":"delta","data":{"s":"BTCUSDC","b":[],"a":[["34963.06","0.085867"],["34976.31","0.285907"],["34963.29","0"],["34961.57","0"]],"u":20010444,"seq":14108043300}}'
2023-11-02 14:54:30,249 DEBUG ++Rcv raw: b'\x81~\x00\xad{"topic":"orderbook.50.BTCUSDC","ts":1698936870163,"type":"delta","data":{"s":"BTCUSDC","b":[],"a":[["34958.74","0.01144"],["34976.31","0"]],"u":20010445,"seq":14108043355}}'
2023-11-02 14:54:30,249 DEBUG ++Rcv decoded: fin=1 opcode=1 data=b'{"topic":"orderbook.50.BTCUSDC","ts":1698936870163,"type":"delta","data":{"s":"BTCUSDC","b":[],"a":[["34958.74","0.01144"],["34976.31","0"]],"u":20010445,"seq":14108043355}}'
2023-11-02 14:54:30,309 DEBUG ++Rcv raw: b'\x81~\x00\xae{"topic":"orderbook.50.BTCUSDC","ts":1698936870224,"type":"delta","data":{"s":"BTCUSDC","b":[],"a":[["34976.31","0.285907"],["34958.75","0"]],"u":20010446,"seq":14108043378}}'
2023-11-02 14:54:30,309 DEBUG ++Rcv decoded: fin=1 opcode=1 data=b'{"topic":"orderbook.50.BTCUSDC","ts":1698936870224,"type":"delta","data":{"s":"BTCUSDC","b":[],"a":[["34976.31","0.285907"],["34958.75","0"]],"u":20010446,"seq":14108043378}}'
2023-11-02 14:54:30,349 DEBUG ++Rcv raw: b'\x81~\x00\xac{"topic":"orderbook.50.BTCUSDC","ts":1698936870263,"type":"delta","data":{"s":"BTCUSDC","b":[["34931.31","0.1875"],["34943.37","0"]],"a":[],"u":20010447,"seq":14108043394}}'
2023-11-02 14:54:30,349 DEBUG ++Rcv decoded: fin=1 opcode=1 data=b'{"topic":"orderbook.50.BTCUSDC","ts":1698936870263,"type":"delta","data":{"s":"BTCUSDC","b":[["34931.31","0.1875"],["34943.37","0"]],"a":[],"u":20010447,"seq":14108043394}}'
2023-11-02 14:54:30,409 DEBUG ++Rcv raw: b'\x81~\x00\xad{"topic":"orderbook.50.BTCUSDC","ts":1698936870324,"type":"delta","data":{"s":"BTCUSDC","b":[["34930.71","0.07761"],["34948.64","0"]],"a":[],"u":20010448,"seq":14108043420}}'
2023-11-02 14:54:30,410 DEBUG ++Rcv decoded: fin=1 opcode=1 data=b'{"topic":"orderbook.50.BTCUSDC","ts":1698936870324,"type":"delta","data":{"s":"BTCUSDC","b":[["34930.71","0.07761"],["34948.64","0"]],"a":[],"u":20010448,"seq":14108043420}}'
2023-11-02 14:54:30,490 DEBUG ++Rcv raw: b'\x81~\x00\xaa{"topic":"orderbook.50.BTCUSDC","ts":1698936870404,"type":"delta","data":{"s":"BTCUSDC","b":[],"a":[["34976.85","0.05718"],["34960","0"]],"u":20010449,"seq":14108043441}}'
2023-11-02 14:54:30,491 DEBUG ++Rcv decoded: fin=1 opcode=1 data=b'{"topic":"orderbook.50.BTCUSDC","ts":1698936870404,"type":"delta","data":{"s":"BTCUSDC","b":[],"a":[["34976.85","0.05718"],["34960","0"]],"u":20010449,"seq":14108043441}}'
2023-11-02 14:54:30,529 DEBUG ++Rcv raw: b'\x81~\x01H{"topic":"orderbook.50.BTCUSDC","ts":1698936870443,"type":"delta","data":{"s":"BTCUSDC","b":[["34957.74","0.057211"],["34957.69","0.1094"],["34957.37","0"],["34930.71","0"]],"a":[["34977.06","0.0859"],["34977.23","0.1875"],["34977.49","0.085364"],["34962","0"],["34967.26","0"],["34958.74","0"]],"u":20010450,"seq":14108043480}}'
2023-11-02 14:54:30,529 DEBUG ++Rcv decoded: fin=1 opcode=1 data=b'{"topic":"orderbook.50.BTCUSDC","ts":1698936870443,"type":"delta","data":{"s":"BTCUSDC","b":[["34957.74","0.057211"],["34957.69","0.1094"],["34957.37","0"],["34930.71","0"]],"a":[["34977.06","0.0859"],["34977.23","0.1875"],["34977.49","0.085364"],["34962","0"],["34967.26","0"],["34958.74","0"]],"u":20010450,"seq":14108043480}}'
2023-11-02 14:54:30,548 DEBUG ++Rcv raw: b'\x81~\x01!{"topic":"orderbook.50.BTCUSDC","ts":1698936870463,"type":"delta","data":{"s":"BTCUSDC","b":[["34947.24","0.1875"],["34942.67","0.028"],["34951.83","0"],["34957.69","0"]],"a":[["34967.93","0.068641"],["34978.01","0.0005"],["34967.25","0"],["34963.07","0"]],"u":20010451,"seq":14108043497}}'
2023-11-02 14:54:30,549 DEBUG ++Rcv decoded: fin=1 opcode=1 data=b'{"topic":"orderbook.50.BTCUSDC","ts":1698936870463,"type":"delta","data":{"s":"BTCUSDC","b":[["34947.24","0.1875"],["34942.67","0.028"],["34951.83","0"],["34957.69","0"]],"a":[["34967.93","0.068641"],["34978.01","0.0005"],["34967.25","0"],["34963.07","0"]],"u":20010451,"seq":14108043497}}'
2023-11-02 14:54:30,569 DEBUG ++Rcv raw: b'\x81~\x01={"topic":"orderbook.50.BTCUSDC","ts":1698936870483,"type":"delta","data":{"s":"BTCUSDC","b":[["34955.37","0.031122"],["34952.69","0.11444"],["34951.27","0.051549"],["34931.31","0"],["34951.84","0"],["34933.4","0"]],"a":[["34963.06","0.05154"],["34963.45","0.057202"],["34978.01","0"]],"u":20010452,"seq":14108043510}}'
2023-11-02 14:54:30,569 DEBUG ++Rcv decoded: fin=1 opcode=1 data=b'{"topic":"orderbook.50.BTCUSDC","ts":1698936870483,"type":"delta","data":{"s":"BTCUSDC","b":[["34955.37","0.031122"],["34952.69","0.11444"],["34951.27","0.051549"],["34931.31","0"],["34951.84","0"],["34933.4","0"]],"a":[["34963.06","0.05154"],["34963.45","0.057202"],["34978.01","0"]],"u":20010452,"seq":14108043510}}'
2023-11-02 14:54:30,589 DEBUG ++Rcv raw: b'\x81~\x00\xdd{"topic":"orderbook.50.BTCUSDC","ts":1698936870504,"type":"delta","data":{"s":"BTCUSDC","b":[["34955.36","0.095167"],["34953.11","0.068665"],["34951.27","0"]],"a":[["34963.06","0.079421"]],"u":20010453,"seq":14108043521}}'
2023-11-02 14:54:30,589 DEBUG ++Rcv decoded: fin=1 opcode=1 data=b'{"topic":"orderbook.50.BTCUSDC","ts":1698936870504,"type":"delta","data":{"s":"BTCUSDC","b":[["34955.36","0.095167"],["34953.11","0.068665"],["34951.27","0"]],"a":[["34963.06","0.079421"]],"u":20010453,"seq":14108043521}}'
2023-11-02 14:54:30,609 DEBUG ++Rcv raw: b'\x81~\x00\xad{"topic":"orderbook.50.BTCUSDC","ts":1698936870523,"type":"delta","data":{"s":"BTCUSDC","b":[["34933.4","0.458014"],["34954.71","0"]],"a":[],"u":20010454,"seq":14108043528}}'
2023-11-02 14:54:30,609 DEBUG ++Rcv decoded: fin=1 opcode=1 data=b'{"topic":"orderbook.50.BTCUSDC","ts":1698936870523,"type":"delta","data":{"s":"BTCUSDC","b":[["34933.4","0.458014"],["34954.71","0"]],"a":[],"u":20010454,"seq":14108043528}}'
2023-11-02 14:54:30,629 DEBUG ++Rcv raw: b'\x81~\x00\xae{"topic":"orderbook.50.BTCUSDC","ts":1698936870544,"type":"delta","data":{"s":"BTCUSDC","b":[],"a":[["34971.26","0.000239"],["34977.49","0"]],"u":20010455,"seq":14108043535}}'
2023-11-02 14:54:30,629 DEBUG ++Rcv decoded: fin=1 opcode=1 data=b'{"topic":"orderbook.50.BTCUSDC","ts":1698936870544,"type":"delta","data":{"s":"BTCUSDC","b":[],"a":[["34971.26","0.000239"],["34977.49","0"]],"u":20010455,"seq":14108043535}}'
2023-11-02 14:54:30,670 DEBUG ++Rcv raw: b'\x81~\x00\xad{"topic":"orderbook.50.BTCUSDC","ts":1698936870584,"type":"delta","data":{"s":"BTCUSDC","b":[],"a":[["34960.25","0.00127"],["34977.23","0"]],"u":20010456,"seq":14108043553}}'
2023-11-02 14:54:30,670 DEBUG ++Rcv decoded: fin=1 opcode=1 data=b'{"topic":"orderbook.50.BTCUSDC","ts":1698936870584,"type":"delta","data":{"s":"BTCUSDC","b":[],"a":[["34960.25","0.00127"],["34977.23","0"]],"u":20010456,"seq":14108043553}}'
2023-11-02 14:54:30,709 DEBUG ++Rcv raw: b'\x81~\x00\x9d{"topic":"orderbook.50.BTCUSDC","ts":1698936870623,"type":"delta","data":{"s":"BTCUSDC","b":[["34955.36","0.052046"]],"a":[],"u":20010457,"seq":14108043573}}'
2023-11-02 14:54:30,709 DEBUG ++Rcv decoded: fin=1 opcode=1 data=b'{"topic":"orderbook.50.BTCUSDC","ts":1698936870623,"type":"delta","data":{"s":"BTCUSDC","b":[["34955.36","0.052046"]],"a":[],"u":20010457,"seq":14108043573}}'
2023-11-02 14:54:30,729 DEBUG ++Rcv raw: b'\x81~\x00\xad{"topic":"orderbook.50.BTCUSDC","ts":1698936870643,"type":"delta","data":{"s":"BTCUSDC","b":[["34954.71","0.051543"],["34933.4","0"]],"a":[],"u":20010458,"seq":14108043579}}'
2023-11-02 14:54:30,729 DEBUG ++Rcv decoded: fin=1 opcode=1 data=b'{"topic":"orderbook.50.BTCUSDC","ts":1698936870643,"type":"delta","data":{"s":"BTCUSDC","b":[["34954.71","0.051543"],["34933.4","0"]],"a":[],"u":20010458,"seq":14108043579}}'
2023-11-02 14:54:30,749 DEBUG ++Rcv raw: b'\x81~\x00\xd6{"topic":"orderbook.50.BTCUSDC","ts":1698936870664,"type":"delta","data":{"s":"BTCUSDC","b":[["34948.74","0.000261"],["34933.41","0"]],"a":[["34971.24","0.000239"],["34977.06","0"]],"u":20010459,"seq":14108043595}}'
2023-11-02 14:54:30,749 DEBUG ++Rcv decoded: fin=1 opcode=1 data=b'{"topic":"orderbook.50.BTCUSDC","ts":1698936870664,"type":"delta","data":{"s":"BTCUSDC","b":[["34948.74","0.000261"],["34933.41","0"]],"a":[["34971.24","0.000239"],["34977.06","0"]],"u":20010459,"seq":14108043595}}'
2023-11-02 14:54:30,769 DEBUG ++Rcv raw: b'\x81~\x00\xd3{"topic":"orderbook.50.BTCUSDC","ts":1698936870684,"type":"delta","data":{"s":"BTCUSDC","b":[["34952.7","0.037364"],["34936.35","0"]],"a":[["34977.06","0.0859"],["34960.25","0"]],"u":20010460,"seq":14108043601}}'
2023-11-02 14:54:30,769 DEBUG ++Rcv decoded: fin=1 opcode=1 data=b'{"topic":"orderbook.50.BTCUSDC","ts":1698936870684,"type":"delta","data":{"s":"BTCUSDC","b":[["34952.7","0.037364"],["34936.35","0"]],"a":[["34977.06","0.0859"],["34960.25","0"]],"u":20010460,"seq":14108043601}}'
2023-11-02 14:54:30,870 DEBUG ++Rcv raw: b'\x81~\x00\xad{"topic":"orderbook.50.BTCUSDC","ts":1698936870783,"type":"delta","data":{"s":"BTCUSDC","b":[["34957.95","0.10471"],["34937.08","0"]],"a":[],"u":20010461,"seq":14108043632}}'
2023-11-02 14:54:30,870 DEBUG ++Rcv decoded: fin=1 opcode=1 data=b'{"topic":"orderbook.50.BTCUSDC","ts":1698936870783,"type":"delta","data":{"s":"BTCUSDC","b":[["34957.95","0.10471"],["34937.08","0"]],"a":[],"u":20010461,"seq":14108043632}}'
2023-11-02 14:54:30,889 DEBUG ++Rcv raw: b'\x81~\x00\xae{"topic":"orderbook.50.BTCUSDC","ts":1698936870804,"type":"delta","data":{"s":"BTCUSDC","b":[["34941.18","0.094268"],["34954.71","0"]],"a":[],"u":20010462,"seq":14108043636}}'
2023-11-02 14:54:30,889 DEBUG ++Rcv decoded: fin=1 opcode=1 data=b'{"topic":"orderbook.50.BTCUSDC","ts":1698936870804,"type":"delta","data":{"s":"BTCUSDC","b":[["34941.18","0.094268"],["34954.71","0"]],"a":[],"u":20010462,"seq":14108043636}}'
2023-11-02 14:54:30,909 DEBUG ++Rcv raw: b'\x81~\x00\xd4{"topic":"orderbook.50.BTCUSDC","ts":1698936870824,"type":"delta","data":{"s":"BTCUSDC","b":[["34948.75","0.000262"],["34937.39","0"]],"a":[["34977.23","0.1875"],["34971.26","0"]],"u":20010463,"seq":14108043640}}'
2023-11-02 14:54:30,910 DEBUG ++Rcv decoded: fin=1 opcode=1 data=b'{"topic":"orderbook.50.BTCUSDC","ts":1698936870824,"type":"delta","data":{"s":"BTCUSDC","b":[["34948.75","0.000262"],["34937.39","0"]],"a":[["34977.23","0.1875"],["34971.26","0"]],"u":20010463,"seq":14108043640}}'
2023-11-02 14:54:30,950 DEBUG ++Rcv raw: b'\x81~\x00\xd6{"topic":"orderbook.50.BTCUSDC","ts":1698936870864,"type":"delta","data":{"s":"BTCUSDC","b":[["34937.39","0.278379"],["34957.74","0"]],"a":[["34977.49","0.085364"],["34963.45","0"]],"u":20010464,"seq":14108043648}}'
2023-11-02 14:54:30,950 DEBUG ++Rcv decoded: fin=1 opcode=1 data=b'{"topic":"orderbook.50.BTCUSDC","ts":1698936870864,"type":"delta","data":{"s":"BTCUSDC","b":[["34937.39","0.278379"],["34957.74","0"]],"a":[["34977.49","0.085364"],["34963.45","0"]],"u":20010464,"seq":14108043648}}'
2023-11-02 14:54:30,969 DEBUG ++Rcv raw: b'\x81~\x00\xed{"topic":"orderbook.50.BTCUSDC","ts":1698936870884,"type":"delta","data":{"s":"BTCUSDC","b":[["34957.38","0.057212"],["34937.39","0"]],"a":[["34962.99","0.057203"],["34963.06","0.05154"],["34977.49","0"]],"u":20010465,"seq":14108043651}}'
2023-11-02 14:54:30,969 DEBUG ++Rcv decoded: fin=1 opcode=1 data=b'{"topic":"orderbook.50.BTCUSDC","ts":1698936870884,"type":"delta","data":{"s":"BTCUSDC","b":[["34957.38","0.057212"],["34937.39","0"]],"a":[["34962.99","0.057203"],["34963.06","0.05154"],["34977.49","0"]],"u":20010465,"seq":14108043651}}'
2023-11-02 14:54:30,988 DEBUG ++Rcv raw: b'\x81~\x00\xae{"topic":"orderbook.50.BTCUSDC","ts":1698936870903,"type":"delta","data":{"s":"BTCUSDC","b":[],"a":[["34962.98","0.085867"],["34963.06","0"]],"u":20010466,"seq":14108043658}}'
2023-11-02 14:54:30,989 DEBUG ++Rcv decoded: fin=1 opcode=1 data=b'{"topic":"orderbook.50.BTCUSDC","ts":1698936870903,"type":"delta","data":{"s":"BTCUSDC","b":[],"a":[["34962.98","0.085867"],["34963.06","0"]],"u":20010466,"seq":14108043658}}'
2023-11-02 14:54:31,009 DEBUG ++Rcv raw: b'\x81~\x00\xae{"topic":"orderbook.50.BTCUSDC","ts":1698936870923,"type":"delta","data":{"s":"BTCUSDC","b":[["34955.25","0.041885"],["34937.84","0"]],"a":[],"u":20010467,"seq":14108043661}}'
2023-11-02 14:54:31,009 DEBUG ++Rcv decoded: fin=1 opcode=1 data=b'{"topic":"orderbook.50.BTCUSDC","ts":1698936870923,"type":"delta","data":{"s":"BTCUSDC","b":[["34955.25","0.041885"],["34937.84","0"]],"a":[],"u":20010467,"seq":14108043661}}'
2023-11-02 14:54:31,029 DEBUG ++Rcv raw: b'\x81~\x00\xad{"topic":"orderbook.50.BTCUSDC","ts":1698936870943,"type":"delta","data":{"s":"BTCUSDC","b":[],"a":[["34960.25","0.00127"],["34977.23","0"]],"u":20010468,"seq":14108043665}}'
2023-11-02 14:54:31,029 DEBUG ++Rcv decoded: fin=1 opcode=1 data=b'{"topic":"orderbook.50.BTCUSDC","ts":1698936870943,"type":"delta","data":{"s":"BTCUSDC","b":[],"a":[["34960.25","0.00127"],["34977.23","0"]],"u":20010468,"seq":14108043665}}'
2023-11-02 14:54:31,129 DEBUG ++Rcv raw: b'\x81~\x00\xd4{"topic":"orderbook.50.BTCUSDC","ts":1698936871043,"type":"delta","data":{"s":"BTCUSDC","b":[["34937.84","0.040649"],["34948.74","0"]],"a":[["34977.22","0.0005"],["34971.24","0"]],"u":20010469,"seq":14108043684}}'
2023-11-02 14:54:31,130 DEBUG ++Rcv decoded: fin=1 opcode=1 data=b'{"topic":"orderbook.50.BTCUSDC","ts":1698936871043,"type":"delta","data":{"s":"BTCUSDC","b":[["34937.84","0.040649"],["34948.74","0"]],"a":[["34977.22","0.0005"],["34971.24","0"]],"u":20010469,"seq":14108043684}}'
2023-11-02 14:54:31,189 DEBUG ++Rcv raw: b'\x81~\x00\xae{"topic":"orderbook.50.BTCUSDC","ts":1698936871104,"type":"delta","data":{"s":"BTCUSDC","b":[["34939.27","0.029858"],["34937.84","0"]],"a":[],"u":20010470,"seq":14108043711}}'
2023-11-02 14:54:31,190 DEBUG ++Rcv decoded: fin=1 opcode=1 data=b'{"topic":"orderbook.50.BTCUSDC","ts":1698936871104,"type":"delta","data":{"s":"BTCUSDC","b":[["34939.27","0.029858"],["34937.84","0"]],"a":[],"u":20010470,"seq":14108043711}}'
2023-11-02 14:54:31,309 DEBUG ++Rcv raw: b'\x81~\x00\xfb{"topic":"orderbook.50.BTCUSDC","ts":1698936871223,"type":"delta","data":{"s":"BTCUSDC","b":[["34956.42","0.0859"],["34938.76","0"]],"a":[["34977.23","0.1875"],["34977.49","0.085364"],["34960.25","0"],["34960.26","0"]],"u":20010471,"seq":14108043756}}'
2023-11-02 14:54:31,309 DEBUG ++Rcv decoded: fin=1 opcode=1 data=b'{"topic":"orderbook.50.BTCUSDC","ts":1698936871223,"type":"delta","data":{"s":"BTCUSDC","b":[["34956.42","0.0859"],["34938.76","0"]],"a":[["34977.23","0.1875"],["34977.49","0.085364"],["34960.25","0"],["34960.26","0"]],"u":20010471,"seq":14108043756}}'
2023-11-02 14:54:31,328 DEBUG ++Rcv raw: b'\x81~\x00\xfd{"topic":"orderbook.50.BTCUSDC","ts":1698936871243,"type":"delta","data":{"s":"BTCUSDC","b":[["34953.06","0.00057"],["34949.74","0.001994"],["34939.11","0"],["34939.12","0"]],"a":[["34966.12","0.00057"],["34977.49","0"]],"u":20010472,"seq":14108043766}}'
2023-11-02 14:54:31,329 DEBUG ++Rcv decoded: fin=1 opcode=1 data=b'{"topic":"orderbook.50.BTCUSDC","ts":1698936871243,"type":"delta","data":{"s":"BTCUSDC","b":[["34953.06","0.00057"],["34949.74","0.001994"],["34939.11","0"],["34939.12","0"]],"a":[["34966.12","0.00057"],["34977.49","0"]],"u":20010472,"seq":14108043766}}'
2023-11-02 14:54:31,349 DEBUG ++Rcv raw: b'\x81~\x00\xc2{"topic":"orderbook.50.BTCUSDC","ts":1698936871263,"type":"delta","data":{"s":"BTCUSDC","b":[["34957.95","0.13062"],["34954.11","0.001"],["34949.57","0"]],"a":[],"u":20010473,"seq":14108043774}}'
2023-11-02 14:54:31,349 DEBUG ++Rcv decoded: fin=1 opcode=1 data=b'{"topic":"orderbook.50.BTCUSDC","ts":1698936871263,"type":"delta","data":{"s":"BTCUSDC","b":[["34957.95","0.13062"],["34954.11","0.001"],["34949.57","0"]],"a":[],"u":20010473,"seq":14108043774}}'
2023-11-02 14:54:31,369 DEBUG ++Rcv raw: b'\x81~\x00\xae{"topic":"orderbook.50.BTCUSDC","ts":1698936871283,"type":"delta","data":{"s":"BTCUSDC","b":[["34939.12","0.823802"],["34942.67","0"]],"a":[],"u":20010474,"seq":14108043786}}'
2023-11-02 14:54:31,369 DEBUG ++Rcv decoded: fin=1 opcode=1 data=b'{"topic":"orderbook.50.BTCUSDC","ts":1698936871283,"type":"delta","data":{"s":"BTCUSDC","b":[["34939.12","0.823802"],["34942.67","0"]],"a":[],"u":20010474,"seq":14108043786}}'
2023-11-02 14:54:31,469 DEBUG ++Rcv raw: b'\x81~\x00\xae{"topic":"orderbook.50.BTCUSDC","ts":1698936871383,"type":"delta","data":{"s":"BTCUSDC","b":[["34939.11","0.057242"],["34948.75","0"]],"a":[],"u":20010475,"seq":14108043824}}'
2023-11-02 14:54:31,469 DEBUG ++Rcv decoded: fin=1 opcode=1 data=b'{"topic":"orderbook.50.BTCUSDC","ts":1698936871383,"type":"delta","data":{"s":"BTCUSDC","b":[["34939.11","0.057242"],["34948.75","0"]],"a":[],"u":20010475,"seq":14108043824}}'
2023-11-02 14:54:31,531 DEBUG ++Rcv raw: b'\x81~\x00\xd5{"topic":"orderbook.50.BTCUSDC","ts":1698936871443,"type":"delta","data":{"s":"BTCUSDC","b":[["34938.76","1.373004"],["34956.42","0"]],"a":[["34961.1","0.095133"],["34977.23","0"]],"u":20010476,"seq":14108043865}}'
2023-11-02 14:54:31,531 DEBUG ++Rcv decoded: fin=1 opcode=1 data=b'{"topic":"orderbook.50.BTCUSDC","ts":1698936871443,"type":"delta","data":{"s":"BTCUSDC","b":[["34938.76","1.373004"],["34956.42","0"]],"a":[["34961.1","0.095133"],["34977.23","0"]],"u":20010476,"seq":14108043865}}'
2023-11-02 14:54:31,549 DEBUG ++Rcv raw: b'\x81~\x00\xd4{"topic":"orderbook.50.BTCUSDC","ts":1698936871463,"type":"delta","data":{"s":"BTCUSDC","b":[],"a":[["34961.09","0.037687"],["34977.23","0.1875"],["34962.98","0"],["34961.1","0"]],"u":20010477,"seq":14108043880}}'
2023-11-02 14:54:31,549 DEBUG ++Rcv decoded: fin=1 opcode=1 data=b'{"topic":"orderbook.50.BTCUSDC","ts":1698936871463,"type":"delta","data":{"s":"BTCUSDC","b":[],"a":[["34961.09","0.037687"],["34977.23","0.1875"],["34962.98","0"],["34961.1","0"]],"u":20010477,"seq":14108043880}}'
2023-11-02 14:54:31,569 DEBUG ++Rcv raw: b'\x81~\x00\xd7{"topic":"orderbook.50.BTCUSDC","ts":1698936871483,"type":"delta","data":{"s":"BTCUSDC","b":[],"a":[["34961.08","0.008756"],["34962.98","0.085869"],["34977.23","0"],["34961.09","0"]],"u":20010478,"seq":14108043894}}'
2023-11-02 14:54:31,569 DEBUG ++Rcv decoded: fin=1 opcode=1 data=b'{"topic":"orderbook.50.BTCUSDC","ts":1698936871483,"type":"delta","data":{"s":"BTCUSDC","b":[],"a":[["34961.08","0.008756"],["34962.98","0.085869"],["34977.23","0"],["34961.09","0"]],"u":20010478,"seq":14108043894}}'
2023-11-02 14:54:31,590 DEBUG ++Rcv raw: b'\x81~\x00\xab{"topic":"orderbook.50.BTCUSDC","ts":1698936871504,"type":"delta","data":{"s":"BTCUSDC","b":[["34940.32","0.028"],["34938.76","0"]],"a":[],"u":20010479,"seq":14108043898}}'
2023-11-02 14:54:31,590 DEBUG ++Rcv decoded: fin=1 opcode=1 data=b'{"topic":"orderbook.50.BTCUSDC","ts":1698936871504,"type":"delta","data":{"s":"BTCUSDC","b":[["34940.32","0.028"],["34938.76","0"]],"a":[],"u":20010479,"seq":14108043898}}'
2023-11-02 14:54:31,649 DEBUG ++Rcv raw: b'\x81~\x00\xf8{"topic":"orderbook.50.BTCUSDC","ts":1698936871563,"type":"delta","data":{"s":"BTCUSDC","b":[["34956.42","0.0859"],["34949.57","0.0017"],["34939.11","0"],["34949.74","0"]],"a":[["34977.23","0.1875"],["34963.3","0"]],"u":20010480,"seq":14108043928}}'
2023-11-02 14:54:31,649 DEBUG ++Rcv decoded: fin=1 opcode=1 data=b'{"topic":"orderbook.50.BTCUSDC","ts":1698936871563,"type":"delta","data":{"s":"BTCUSDC","b":[["34956.42","0.0859"],["34949.57","0.0017"],["34939.11","0"],["34949.74","0"]],"a":[["34977.23","0.1875"],["34963.3","0"]],"u":20010480,"seq":14108043928}}'
2023-11-02 14:54:31,669 DEBUG ++Rcv raw: b'\x81~\x00\xc5{"topic":"orderbook.50.BTCUSDC","ts":1698936871584,"type":"delta","data":{"s":"BTCUSDC","b":[["34956.43","0.051549"],["34955.37","0"]],"a":[["34962.98","0.034321"]],"u":20010481,"seq":14108043938}}'
2023-11-02 14:54:31,669 DEBUG ++Rcv decoded: fin=1 opcode=1 data=b'{"topic":"orderbook.50.BTCUSDC","ts":1698936871584,"type":"delta","data":{"s":"BTCUSDC","b":[["34956.43","0.051549"],["34955.37","0"]],"a":[["34962.98","0.034321"]],"u":20010481,"seq":14108043938}}'
2023-11-02 14:54:31,690 DEBUG ++Rcv raw: b'\x81~\x00\xae{"topic":"orderbook.50.BTCUSDC","ts":1698936871603,"type":"delta","data":{"s":"BTCUSDC","b":[],"a":[["34977.49","0.085364"],["34961.08","0"]],"u":20010482,"seq":14108043964}}'
2023-11-02 14:54:31,690 DEBUG ++Rcv decoded: fin=1 opcode=1 data=b'{"topic":"orderbook.50.BTCUSDC","ts":1698936871603,"type":"delta","data":{"s":"BTCUSDC","b":[],"a":[["34977.49","0.085364"],["34961.08","0"]],"u":20010482,"seq":14108043964}}'
2023-11-02 14:54:31,709 DEBUG ++Rcv raw: b'\x81~\x00\xed{"topic":"orderbook.50.BTCUSDC","ts":1698936871623,"type":"delta","data":{"s":"BTCUSDC","b":[["34957.95","0.02591"],["34950.65","0.000261"],["34939.12","0"]],"a":[["34969.24","0.000239"],["34977.49","0"]],"u":20010483,"seq":14108043977}}'
2023-11-02 14:54:31,709 DEBUG ++Rcv decoded: fin=1 opcode=1 data=b'{"topic":"orderbook.50.BTCUSDC","ts":1698936871623,"type":"delta","data":{"s":"BTCUSDC","b":[["34957.95","0.02591"],["34950.65","0.000261"],["34939.12","0"]],"a":[["34969.24","0.000239"],["34977.49","0"]],"u":20010483,"seq":14108043977}}'
2023-11-02 14:54:31,728 DEBUG ++Rcv raw: b'\x81~\x00\xae{"topic":"orderbook.50.BTCUSDC","ts":1698936871643,"type":"delta","data":{"s":"BTCUSDC","b":[["34939.12","0.823802"],["34954.11","0"]],"a":[],"u":20010484,"seq":14108043985}}'
2023-11-02 14:54:31,729 DEBUG ++Rcv decoded: fin=1 opcode=1 data=b'{"topic":"orderbook.50.BTCUSDC","ts":1698936871643,"type":"delta","data":{"s":"BTCUSDC","b":[["34939.12","0.823802"],["34954.11","0"]],"a":[],"u":20010484,"seq":14108043985}}'
2023-11-02 14:54:31,748 DEBUG ++Rcv raw: b'\x81~\x00\xae{"topic":"orderbook.50.BTCUSDC","ts":1698936871663,"type":"delta","data":{"s":"BTCUSDC","b":[],"a":[["34977.49","0.085364"],["34977.22","0"]],"u":20010485,"seq":14108043993}}'
2023-11-02 14:54:31,749 DEBUG ++Rcv decoded: fin=1 opcode=1 data=b'{"topic":"orderbook.50.BTCUSDC","ts":1698936871663,"type":"delta","data":{"s":"BTCUSDC","b":[],"a":[["34977.49","0.085364"],["34977.22","0"]],"u":20010485,"seq":14108043993}}'
2023-11-02 14:54:31,768 DEBUG ++Rcv raw: b'\x81~\x00\xae{"topic":"orderbook.50.BTCUSDC","ts":1698936871683,"type":"delta","data":{"s":"BTCUSDC","b":[["34957.96","0.008756"],["34957.95","0"]],"a":[],"u":20010486,"seq":14108043997}}'
2023-11-02 14:54:31,769 DEBUG ++Rcv decoded: fin=1 opcode=1 data=b'{"topic":"orderbook.50.BTCUSDC","ts":1698936871683,"type":"delta","data":{"s":"BTCUSDC","b":[["34957.96","0.008756"],["34957.95","0"]],"a":[],"u":20010486,"seq":14108043997}}'
2023-11-02 14:54:31,789 DEBUG ++Rcv raw: b'\x81~\x00\xd5{"topic":"orderbook.50.BTCUSDC","ts":1698936871703,"type":"delta","data":{"s":"BTCUSDC","b":[["34957.95","0.02591"],["34939.12","0"]],"a":[["34977.11","0.029858"],["34977.49","0"]],"u":20010487,"seq":14108043999}}'
2023-11-02 14:54:31,789 DEBUG ++Rcv decoded: fin=1 opcode=1 data=b'{"topic":"orderbook.50.BTCUSDC","ts":1698936871703,"type":"delta","data":{"s":"BTCUSDC","b":[["34957.95","0.02591"],["34939.12","0"]],"a":[["34977.11","0.029858"],["34977.49","0"]],"u":20010487,"seq":14108043999}}'
2023-11-02 14:54:31,829 DEBUG ++Rcv raw: b'\x81~\x00\xee{"topic":"orderbook.50.BTCUSDC","ts":1698936871744,"type":"delta","data":{"s":"BTCUSDC","b":[["34957.96","0.020196"],["34950.67","0.000261"],["34939.27","0"]],"a":[["34969.22","0.000239"],["34977.23","0"]],"u":20010488,"seq":14108044011}}'
2023-11-02 14:54:31,830 DEBUG ++Rcv decoded: fin=1 opcode=1 data=b'{"topic":"orderbook.50.BTCUSDC","ts":1698936871744,"type":"delta","data":{"s":"BTCUSDC","b":[["34957.96","0.020196"],["34950.67","0.000261"],["34939.27","0"]],"a":[["34969.22","0.000239"],["34977.23","0"]],"u":20010488,"seq":14108044011}}'
2023-11-02 14:54:31,870 DEBUG ++Rcv raw: b'\x81~\x01\x15{"topic":"orderbook.50.BTCUSDC","ts":1698936871783,"type":"delta","data":{"s":"BTCUSDC","b":[["34957.76","0.057211"],["34957.38","0.023187"],["34939.85","0"]],"a":[["34963.37","0.057202"],["34977.23","0.1875"],["34964.03","0"],["34962.99","0"]],"u":20010489,"seq":14108044019}}'
2023-11-02 14:54:31,870 DEBUG ++Rcv decoded: fin=1 opcode=1 data=b'{"topic":"orderbook.50.BTCUSDC","ts":1698936871783,"type":"delta","data":{"s":"BTCUSDC","b":[["34957.76","0.057211"],["34957.38","0.023187"],["34939.85","0"]],"a":[["34963.37","0.057202"],["34977.23","0.1875"],["34964.03","0"],["34962.99","0"]],"u":20010489,"seq":14108044019}}'
2023-11-02 14:54:31,929 DEBUG ++Rcv raw: b'\x81~\x00\xd6{"topic":"orderbook.50.BTCUSDC","ts":1698936871844,"type":"delta","data":{"s":"BTCUSDC","b":[["34959.44","0.108877"],["34950.01","0.002151"],["34940.3","0"],["34940.31","0"]],"a":[],"u":20010490,"seq":14108044035}}'
2023-11-02 14:54:31,930 DEBUG ++Rcv decoded: fin=1 opcode=1 data=b'{"topic":"orderbook.50.BTCUSDC","ts":1698936871844,"type":"delta","data":{"s":"BTCUSDC","b":[["34959.44","0.108877"],["34950.01","0.002151"],["34940.3","0"],["34940.31","0"]],"a":[],"u":20010490,"seq":14108044035}}'
2023-11-02 14:54:31,950 DEBUG ++Rcv raw: b'\x81~\x01\x8f{"topic":"orderbook.50.BTCUSDC","ts":1698936871864,"type":"delta","data":{"s":"BTCUSDC","b":[["34947.83","0.106058"],["34940.31","0.112505"],["34940.3","0.025298"],["34939.85","0.1875"],["34949.57","0"],["34953.06","0"],["34943.56","0"]],"a":[["34977.49","0.085364"],["34978.02","0.114412"],["34978.28","0.001447"],["34976.31","0"],["34966.12","0"],["34967.94","0"]],"u":20010491,"seq":14108044047}}'
2023-11-02 14:54:31,950 DEBUG ++Rcv decoded: fin=1 opcode=1 data=b'{"topic":"orderbook.50.BTCUSDC","ts":1698936871864,"type":"delta","data":{"s":"BTCUSDC","b":[["34947.83","0.106058"],["34940.31","0.112505"],["34940.3","0.025298"],["34939.85","0.1875"],["34949.57","0"],["34953.06","0"],["34943.56","0"]],"a":[["34977.49","0.085364"],["34978.02","0.114412"],["34978.28","0.001447"],["34976.31","0"],["34966.12","0"],["34967.94","0"]],"u":20010491,"seq":14108044047}}'
2023-11-02 14:54:31,969 DEBUG ++Rcv raw: b'\x81~\x00\xfd{"topic":"orderbook.50.BTCUSDC","ts":1698936871884,"type":"delta","data":{"s":"BTCUSDC","b":[["34944.52","0.286167"],["34939.85","0"]],"a":[["34968.89","0.114387"],["34977.26","0.2859"],["34978.28","0"],["34967.93","0"]],"u":20010492,"seq":14108044052}}'
2023-11-02 14:54:31,970 DEBUG ++Rcv decoded: fin=1 opcode=1 data=b'{"topic":"orderbook.50.BTCUSDC","ts":1698936871884,"type":"delta","data":{"s":"BTCUSDC","b":[["34944.52","0.286167"],["34939.85","0"]],"a":[["34968.89","0.114387"],["34977.26","0.2859"],["34978.28","0"],["34967.93","0"]],"u":20010492,"seq":14108044052}}'
2023-11-02 14:54:31,989 DEBUG ++Rcv raw: b'\x81~\x00\xfd{"topic":"orderbook.50.BTCUSDC","ts":1698936871904,"type":"delta","data":{"s":"BTCUSDC","b":[["34939.85","0.1875"],["34950.65","0"]],"a":[["34968.88","0.068635"],["34978.28","0.001447"],["34969.99","0"],["34969.24","0"]],"u":20010493,"seq":14108044059}}'
2023-11-02 14:54:31,990 DEBUG ++Rcv decoded: fin=1 opcode=1 data=b'{"topic":"orderbook.50.BTCUSDC","ts":1698936871904,"type":"delta","data":{"s":"BTCUSDC","b":[["34939.85","0.1875"],["34950.65","0"]],"a":[["34968.88","0.068635"],["34978.28","0.001447"],["34969.99","0"],["34969.24","0"]],"u":20010493,"seq":14108044059}}'
2023-11-02 14:54:32,029 DEBUG ++Rcv raw: b'\x81~\x00\x9d{"topic":"orderbook.50.BTCUSDC","ts":1698936871943,"type":"delta","data":{"s":"BTCUSDC","b":[["34957.96","0.008756"]],"a":[],"u":20010494,"seq":14108044065}}'
2023-11-02 14:54:32,029 DEBUG ++Rcv decoded: fin=1 opcode=1 data=b'{"topic":"orderbook.50.BTCUSDC","ts":1698936871943,"type":"delta","data":{"s":"BTCUSDC","b":[["34957.96","0.008756"]],"a":[],"u":20010494,"seq":14108044065}}'
2023-11-02 14:54:32,048 DEBUG ++Rcv raw: b'\x81~\x00\xd6{"topic":"orderbook.50.BTCUSDC","ts":1698936871963,"type":"delta","data":{"s":"BTCUSDC","b":[["34939.27","0.029858"],["34941.17","0"]],"a":[["34964.19","0.022947"],["34978.28","0"]],"u":20010495,"seq":14108044074}}'
2023-11-02 14:54:32,049 DEBUG ++Rcv decoded: fin=1 opcode=1 data=b'{"topic":"orderbook.50.BTCUSDC","ts":1698936871963,"type":"delta","data":{"s":"BTCUSDC","b":[["34939.27","0.029858"],["34941.17","0"]],"a":[["34964.19","0.022947"],["34978.28","0"]],"u":20010495,"seq":14108044074}}'
2023-11-02 14:54:32,068 DEBUG ++Rcv raw: b'\x81~\x00\xae{"topic":"orderbook.50.BTCUSDC","ts":1698936871983,"type":"delta","data":{"s":"BTCUSDC","b":[["34939.12","0.823802"],["34941.18","0"]],"a":[],"u":20010496,"seq":14108044081}}'
2023-11-02 14:54:32,069 DEBUG ++Rcv decoded: fin=1 opcode=1 data=b'{"topic":"orderbook.50.BTCUSDC","ts":1698936871983,"type":"delta","data":{"s":"BTCUSDC","b":[["34939.12","0.823802"],["34941.18","0"]],"a":[],"u":20010496,"seq":14108044081}}'
2023-11-02 14:54:32,109 DEBUG ++Rcv raw: b'\x81~\x00\xad{"topic":"orderbook.50.BTCUSDC","ts":1698936872024,"type":"delta","data":{"s":"BTCUSDC","b":[["34959.45","0.01144"],["34939.12","0"]],"a":[],"u":20010497,"seq":14108044087}}'
2023-11-02 14:54:32,109 DEBUG ++Rcv decoded: fin=1 opcode=1 data=b'{"topic":"orderbook.50.BTCUSDC","ts":1698936872024,"type":"delta","data":{"s":"BTCUSDC","b":[["34959.45","0.01144"],["34939.12","0"]],"a":[],"u":20010497,"seq":14108044087}}'
2023-11-02 14:54:32,129 DEBUG ++Rcv raw: b'\x81~\x00\xff{"topic":"orderbook.50.BTCUSDC","ts":1698936872044,"type":"delta","data":{"s":"BTCUSDC","b":[["34939.12","0.823802"],["34939.11","0.057242"],["34959.44","0"],["34950.67","0"]],"a":[["34978.28","0.001447"],["34969.22","0"]],"u":20010498,"seq":14108044090}}'
2023-11-02 14:54:32,130 DEBUG ++Rcv decoded: fin=1 opcode=1 data=b'{"topic":"orderbook.50.BTCUSDC","ts":1698936872044,"type":"delta","data":{"s":"BTCUSDC","b":[["34939.12","0.823802"],["34939.11","0.057242"],["34959.44","0"],["34950.67","0"]],"a":[["34978.28","0.001447"],["34969.22","0"]],"u":20010498,"seq":14108044090}}'
2023-11-02 14:54:32,209 DEBUG ++Rcv raw: b'\x81~\x00\xae{"topic":"orderbook.50.BTCUSDC","ts":1698936872124,"type":"delta","data":{"s":"BTCUSDC","b":[["34938.76","1.373004"],["34959.45","0"]],"a":[],"u":20010499,"seq":14108044107}}'
2023-11-02 14:54:32,209 DEBUG ++Rcv decoded: fin=1 opcode=1 data=b'{"topic":"orderbook.50.BTCUSDC","ts":1698936872124,"type":"delta","data":{"s":"BTCUSDC","b":[["34938.76","1.373004"],["34959.45","0"]],"a":[],"u":20010499,"seq":14108044107}}'
2023-11-02 14:54:32,228 DEBUG ++Rcv raw: b'\x81~\x00\xfd{"topic":"orderbook.50.BTCUSDC","ts":1698936872143,"type":"delta","data":{"s":"BTCUSDC","b":[["34953.07","0.00057"],["34949.57","0.002279"],["34939.11","0"],["34938.76","0"]],"a":[["34966.12","0.00057"],["34978.28","0"]],"u":20010500,"seq":14108044117}}'
2023-11-02 14:54:32,229 DEBUG ++Rcv decoded: fin=1 opcode=1 data=b'{"topic":"orderbook.50.BTCUSDC","ts":1698936872143,"type":"delta","data":{"s":"BTCUSDC","b":[["34953.07","0.00057"],["34949.57","0.002279"],["34939.11","0"],["34938.76","0"]],"a":[["34966.12","0.00057"],["34978.28","0"]],"u":20010500,"seq":14108044117}}'
2023-11-02 14:54:32,249 DEBUG ++Rcv raw: b'\x81~\x00\xae{"topic":"orderbook.50.BTCUSDC","ts":1698936872163,"type":"delta","data":{"s":"BTCUSDC","b":[["34939.11","0.057242"],["34950.01","0"]],"a":[],"u":20010501,"seq":14108044126}}'
2023-11-02 14:54:32,249 DEBUG ++Rcv decoded: fin=1 opcode=1 data=b'{"topic":"orderbook.50.BTCUSDC","ts":1698936872163,"type":"delta","data":{"s":"BTCUSDC","b":[["34939.11","0.057242"],["34950.01","0"]],"a":[],"u":20010501,"seq":14108044126}}'
2023-11-02 14:54:32,289 DEBUG ++Rcv raw: b'\x81~\x00\xad{"topic":"orderbook.50.BTCUSDC","ts":1698936872203,"type":"delta","data":{"s":"BTCUSDC","b":[["34959.46","0.01144"],["34939.11","0"]],"a":[],"u":20010502,"seq":14108044132}}'
2023-11-02 14:54:32,289 DEBUG ++Rcv decoded: fin=1 opcode=1 data=b'{"topic":"orderbook.50.BTCUSDC","ts":1698936872203,"type":"delta","data":{"s":"BTCUSDC","b":[["34959.46","0.01144"],["34939.11","0"]],"a":[],"u":20010502,"seq":14108044132}}'
2023-11-02 14:54:32,309 DEBUG ++Rcv raw: b'\x81~\x00\xff{"topic":"orderbook.50.BTCUSDC","ts":1698936872224,"type":"delta","data":{"s":"BTCUSDC","b":[["34939.11","0.057242"],["34938.76","1.373004"],["34940.32","0"],["34953.07","0"]],"a":[["34978.28","0.001447"],["34966.12","0"]],"u":20010503,"seq":14108044135}}'
2023-11-02 14:54:32,310 DEBUG ++Rcv decoded: fin=1 opcode=1 data=b'{"topic":"orderbook.50.BTCUSDC","ts":1698936872224,"type":"delta","data":{"s":"BTCUSDC","b":[["34939.11","0.057242"],["34938.76","1.373004"],["34940.32","0"],["34953.07","0"]],"a":[["34978.28","0.001447"],["34966.12","0"]],"u":20010503,"seq":14108044135}}'
2023-11-02 14:54:32,330 DEBUG ++Rcv raw: b'\x81~\x00\xad{"topic":"orderbook.50.BTCUSDC","ts":1698936872244,"type":"delta","data":{"s":"BTCUSDC","b":[["34938.2","0.155904"],["34957.96","0"]],"a":[],"u":20010504,"seq":14108044138}}'
2023-11-02 14:54:32,330 DEBUG ++Rcv decoded: fin=1 opcode=1 data=b'{"topic":"orderbook.50.BTCUSDC","ts":1698936872244,"type":"delta","data":{"s":"BTCUSDC","b":[["34938.2","0.155904"],["34957.96","0"]],"a":[],"u":20010504,"seq":14108044138}}'
2023-11-02 14:54:32,389 DEBUG ++Rcv raw: b'\x81~\x00\xae{"topic":"orderbook.50.BTCUSDC","ts":1698936872304,"type":"delta","data":{"s":"BTCUSDC","b":[["34937.84","0.040649"],["34959.46","0"]],"a":[],"u":20010505,"seq":14108044143}}'
2023-11-02 14:54:32,389 DEBUG ++Rcv decoded: fin=1 opcode=1 data=b'{"topic":"orderbook.50.BTCUSDC","ts":1698936872304,"type":"delta","data":{"s":"BTCUSDC","b":[["34937.84","0.040649"],["34959.46","0"]],"a":[],"u":20010505,"seq":14108044143}}'
2023-11-02 14:54:32,409 DEBUG ++Rcv raw: b'\x81~\x00\xd6{"topic":"orderbook.50.BTCUSDC","ts":1698936872324,"type":"delta","data":{"s":"BTCUSDC","b":[["34959.27","0.089717"],["34953.06","0.00057"],["34957.95","0"],["34937.84","0"]],"a":[],"u":20010506,"seq":14108044148}}'
2023-11-02 14:54:32,409 DEBUG ++Rcv decoded: fin=1 opcode=1 data=b'{"topic":"orderbook.50.BTCUSDC","ts":1698936872324,"type":"delta","data":{"s":"BTCUSDC","b":[["34959.27","0.089717"],["34953.06","0.00057"],["34957.95","0"],["34937.84","0"]],"a":[],"u":20010506,"seq":14108044148}}'
2023-11-02 14:54:32,429 DEBUG ++Rcv raw: b'\x81~\x00\xd7{"topic":"orderbook.50.BTCUSDC","ts":1698936872344,"type":"delta","data":{"s":"BTCUSDC","b":[["34957.96","0.057211"],["34937.84","0.040649"],["34957.76","0"],["34953.06","0"]],"a":[],"u":20010507,"seq":14108044160}}'
2023-11-02 14:54:32,429 DEBUG ++Rcv decoded: fin=1 opcode=1 data=b'{"topic":"orderbook.50.BTCUSDC","ts":1698936872344,"type":"delta","data":{"s":"BTCUSDC","b":[["34957.96","0.057211"],["34937.84","0.040649"],["34957.76","0"],["34953.06","0"]],"a":[],"u":20010507,"seq":14108044160}}'
2023-11-02 14:54:32,449 DEBUG ++Rcv raw: b'\x81~\x00\xae{"topic":"orderbook.50.BTCUSDC","ts":1698936872364,"type":"delta","data":{"s":"BTCUSDC","b":[["34937.39","0.278379"],["34957.96","0"]],"a":[],"u":20010508,"seq":14108044169}}'
2023-11-02 14:54:32,449 DEBUG ++Rcv decoded: fin=1 opcode=1 data=b'{"topic":"orderbook.50.BTCUSDC","ts":1698936872364,"type":"delta","data":{"s":"BTCUSDC","b":[["34937.39","0.278379"],["34957.96","0"]],"a":[],"u":20010508,"seq":14108044169}}'
2023-11-02 14:54:32,489 DEBUG ++Rcv raw: b'\x81~\x00\xfe{"topic":"orderbook.50.BTCUSDC","ts":1698936872404,"type":"delta","data":{"s":"BTCUSDC","b":[["34957.96","0.01144"],["34950.74","0.000261"],["34937.84","0"],["34937.39","0"]],"a":[["34969.08","0.000239"],["34978.28","0"]],"u":20010509,"seq":14108044178}}'
2023-11-02 14:54:32,490 DEBUG ++Rcv decoded: fin=1 opcode=1 data=b'{"topic":"orderbook.50.BTCUSDC","ts":1698936872404,"type":"delta","data":{"s":"BTCUSDC","b":[["34957.96","0.01144"],["34950.74","0.000261"],["34937.84","0"],["34937.39","0"]],"a":[["34969.08","0.000239"],["34978.28","0"]],"u":20010509,"seq":14108044178}}'
2023-11-02 14:54:32,508 DEBUG ++Rcv raw: b'\x81~\x00\xaa{"topic":"orderbook.50.BTCUSDC","ts":1698936872423,"type":"delta","data":{"s":"BTCUSDC","b":[["34941.19","0.028"],["34938.2","0"]],"a":[],"u":20010510,"seq":14108044179}}'
2023-11-02 14:54:32,509 DEBUG ++Rcv decoded: fin=1 opcode=1 data=b'{"topic":"orderbook.50.BTCUSDC","ts":1698936872423,"type":"delta","data":{"s":"BTCUSDC","b":[["34941.19","0.028"],["34938.2","0"]],"a":[],"u":20010510,"seq":14108044179}}'
2023-11-02 14:54:32,589 DEBUG ++Rcv raw: b'\x81~\x00\xad{"topic":"orderbook.50.BTCUSDC","ts":1698936872503,"type":"delta","data":{"s":"BTCUSDC","b":[["34938.2","0.155904"],["34957.96","0"]],"a":[],"u":20010511,"seq":14108044194}}'
2023-11-02 14:54:32,589 DEBUG ++Rcv decoded: fin=1 opcode=1 data=b'{"topic":"orderbook.50.BTCUSDC","ts":1698936872503,"type":"delta","data":{"s":"BTCUSDC","b":[["34938.2","0.155904"],["34957.96","0"]],"a":[],"u":20010511,"seq":14108044194}}'
2023-11-02 14:54:32,669 DEBUG ++Rcv raw: b'\x81~\x00\xd6{"topic":"orderbook.50.BTCUSDC","ts":1698936872583,"type":"delta","data":{"s":"BTCUSDC","b":[["34950.76","0.000261"],["34938.76","0"]],"a":[["34969.06","0.000239"],["34978.02","0"]],"u":20010512,"seq":14108044213}}'
2023-11-02 14:54:32,669 DEBUG ++Rcv decoded: fin=1 opcode=1 data=b'{"topic":"orderbook.50.BTCUSDC","ts":1698936872583,"type":"delta","data":{"s":"BTCUSDC","b":[["34950.76","0.000261"],["34938.76","0"]],"a":[["34969.06","0.000239"],["34978.02","0"]],"u":20010512,"seq":14108044213}}'
2023-11-02 14:54:32,689 DEBUG ++Rcv raw: b'\x81~\x01O{"topic":"orderbook.50.BTCUSDC","ts":1698936872604,"type":"delta","data":{"s":"BTCUSDC","b":[["34959.28","0.01144"],["34937.84","0.040649"],["34937.39","0.278379"],["34937.08","0.064686"],["34936.35","0.1875"],["34947.39","0"],["34959.27","0"],["34955.25","0"],["34957.38","0"],["34939.12","0"]],"a":[],"u":20010513,"seq":14108044223}}'
2023-11-02 14:54:32,689 DEBUG ++Rcv decoded: fin=1 opcode=1 data=b'{"topic":"orderbook.50.BTCUSDC","ts":1698936872604,"type":"delta","data":{"s":"BTCUSDC","b":[["34959.28","0.01144"],["34937.84","0.040649"],["34937.39","0.278379"],["34937.08","0.064686"],["34936.35","0.1875"],["34947.39","0"],["34959.27","0"],["34955.25","0"],["34957.38","0"],["34939.12","0"]],"a":[],"u":20010513,"seq":14108044223}}'
2023-11-02 14:54:32,709 DEBUG ++Rcv raw: b'\x81~\x00\xad{"topic":"orderbook.50.BTCUSDC","ts":1698936872624,"type":"delta","data":{"s":"BTCUSDC","b":[["34935.91","1.373003"],["34938.2","0"]],"a":[],"u":20010514,"seq":14108044226}}'
2023-11-02 14:54:32,709 DEBUG ++Rcv decoded: fin=1 opcode=1 data=b'{"topic":"orderbook.50.BTCUSDC","ts":1698936872624,"type":"delta","data":{"s":"BTCUSDC","b":[["34935.91","1.373003"],["34938.2","0"]],"a":[],"u":20010514,"seq":14108044226}}'
2023-11-02 14:54:32,789 DEBUG ++Rcv raw: b'\x81~\x00\xae{"topic":"orderbook.50.BTCUSDC","ts":1698936872704,"type":"delta","data":{"s":"BTCUSDC","b":[["34935.36","0.457988"],["34959.28","0"]],"a":[],"u":20010515,"seq":14108044252}}'
2023-11-02 14:54:32,789 DEBUG ++Rcv decoded: fin=1 opcode=1 data=b'{"topic":"orderbook.50.BTCUSDC","ts":1698936872704,"type":"delta","data":{"s":"BTCUSDC","b":[["34935.36","0.457988"],["34959.28","0"]],"a":[],"u":20010515,"seq":14108044252}}'
2023-11-02 14:54:32,809 DEBUG ++Rcv raw: b'\x81~\x00\xc5{"topic":"orderbook.50.BTCUSDC","ts":1698936872723,"type":"delta","data":{"s":"BTCUSDC","b":[["34956.43","0.077459"],["34951.54","0.00057"],["34935.36","0"]],"a":[],"u":20010516,"seq":14108044261}}'
2023-11-02 14:54:32,809 DEBUG ++Rcv decoded: fin=1 opcode=1 data=b'{"topic":"orderbook.50.BTCUSDC","ts":1698936872723,"type":"delta","data":{"s":"BTCUSDC","b":[["34956.43","0.077459"],["34951.54","0.00057"],["34935.36","0"]],"a":[],"u":20010516,"seq":14108044261}}'
2023-11-02 14:54:32,829 DEBUG ++Rcv raw: b'\x81~\x00\xfd{"topic":"orderbook.50.BTCUSDC","ts":1698936872743,"type":"delta","data":{"s":"BTCUSDC","b":[["34956.44","0.008756"],["34938.2","0.157044"],["34935.91","0"],["34936.35","0"]],"a":[["34966.12","0.00057"],["34977.49","0"]],"u":20010517,"seq":14108044269}}'
2023-11-02 14:54:32,829 DEBUG ++Rcv decoded: fin=1 opcode=1 data=b'{"topic":"orderbook.50.BTCUSDC","ts":1698936872743,"type":"delta","data":{"s":"BTCUSDC","b":[["34956.44","0.008756"],["34938.2","0.157044"],["34935.91","0"],["34936.35","0"]],"a":[["34966.12","0.00057"],["34977.49","0"]],"u":20010517,"seq":14108044269}}'
2023-11-02 14:54:32,850 DEBUG ++Rcv raw: b'\x81~\x00\xab{"topic":"orderbook.50.BTCUSDC","ts":1698936872763,"type":"delta","data":{"s":"BTCUSDC","b":[["34936.35","0.1875"],["34952.7","0"]],"a":[],"u":20010518,"seq":14108044273}}'
2023-11-02 14:54:32,850 DEBUG ++Rcv decoded: fin=1 opcode=1 data=b'{"topic":"orderbook.50.BTCUSDC","ts":1698936872763,"type":"delta","data":{"s":"BTCUSDC","b":[["34936.35","0.1875"],["34952.7","0"]],"a":[],"u":20010518,"seq":14108044273}}'
2023-11-02 14:54:32,868 DEBUG ++Rcv raw: b'\x81~\x00\xad{"topic":"orderbook.50.BTCUSDC","ts":1698936872783,"type":"delta","data":{"s":"BTCUSDC","b":[["34959.29","0.01144"],["34936.35","0"]],"a":[],"u":20010519,"seq":14108044281}}'
2023-11-02 14:54:32,868 DEBUG ++Rcv decoded: fin=1 opcode=1 data=b'{"topic":"orderbook.50.BTCUSDC","ts":1698936872783,"type":"delta","data":{"s":"BTCUSDC","b":[["34959.29","0.01144"],["34936.35","0"]],"a":[],"u":20010519,"seq":14108044281}}'
2023-11-02 14:54:32,889 DEBUG ++Rcv raw: b'\x81~\x01&{"topic":"orderbook.50.BTCUSDC","ts":1698936872803,"type":"delta","data":{"s":"BTCUSDC","b":[["34936.35","0.1875"],["34935.91","1.373003"],["34951.54","0"],["34950.74","0"]],"a":[["34977.49","0.085364"],["34978.02","0.114412"],["34966.12","0"],["34969.08","0"]],"u":20010520,"seq":14108044302}}'
2023-11-02 14:54:32,889 DEBUG ++Rcv decoded: fin=1 opcode=1 data=b'{"topic":"orderbook.50.BTCUSDC","ts":1698936872803,"type":"delta","data":{"s":"BTCUSDC","b":[["34936.35","0.1875"],["34935.91","1.373003"],["34951.54","0"],["34950.74","0"]],"a":[["34977.49","0.085364"],["34978.02","0.114412"],["34966.12","0"],["34969.08","0"]],"u":20010520,"seq":14108044302}}'
2023-11-02 14:54:32,929 DEBUG ++Rcv raw: b'\x81~\x00\xae{"topic":"orderbook.50.BTCUSDC","ts":1698936872844,"type":"delta","data":{"s":"BTCUSDC","b":[["34952.71","0.034795"],["34935.91","0"]],"a":[],"u":20010521,"seq":14108044321}}'
2023-11-02 14:54:32,929 DEBUG ++Rcv decoded: fin=1 opcode=1 data=b'{"topic":"orderbook.50.BTCUSDC","ts":1698936872844,"type":"delta","data":{"s":"BTCUSDC","b":[["34952.71","0.034795"],["34935.91","0"]],"a":[],"u":20010521,"seq":14108044321}}'
2023-11-02 14:54:32,949 DEBUG ++Rcv raw: b'\x81~\x00\xae{"topic":"orderbook.50.BTCUSDC","ts":1698936872864,"type":"delta","data":{"s":"BTCUSDC","b":[["34946.18","0.042984"],["34936.35","0"]],"a":[],"u":20010522,"seq":14108044348}}'
2023-11-02 14:54:32,949 DEBUG ++Rcv decoded: fin=1 opcode=1 data=b'{"topic":"orderbook.50.BTCUSDC","ts":1698936872864,"type":"delta","data":{"s":"BTCUSDC","b":[["34946.18","0.042984"],["34936.35","0"]],"a":[],"u":20010522,"seq":14108044348}}'
2023-11-02 14:54:32,969 DEBUG ++Rcv raw: b'\x81~\x00\xc6{"topic":"orderbook.50.BTCUSDC","ts":1698936872884,"type":"delta","data":{"s":"BTCUSDC","b":[["34959.41","0.096345"],["34945.02","0.163124"],["34959.29","0"]],"a":[],"u":20010523,"seq":14108044383}}'
2023-11-02 14:54:32,969 DEBUG ++Rcv decoded: fin=1 opcode=1 data=b'{"topic":"orderbook.50.BTCUSDC","ts":1698936872884,"type":"delta","data":{"s":"BTCUSDC","b":[["34959.41","0.096345"],["34945.02","0.163124"],["34959.29","0"]],"a":[],"u":20010523,"seq":14108044383}}'
2023-11-02 14:54:33,069 DEBUG ++Rcv raw: b'\x81~\x00\xc6{"topic":"orderbook.50.BTCUSDC","ts":1698936872983,"type":"delta","data":{"s":"BTCUSDC","b":[["34959.42","0.008756"],["34959.41","0.122255"],["34956.44","0"]],"a":[],"u":20010524,"seq":14108044415}}'
2023-11-02 14:54:33,069 DEBUG ++Rcv decoded: fin=1 opcode=1 data=b'{"topic":"orderbook.50.BTCUSDC","ts":1698936872983,"type":"delta","data":{"s":"BTCUSDC","b":[["34959.42","0.008756"],["34959.41","0.122255"],["34956.44","0"]],"a":[],"u":20010524,"seq":14108044415}}'
2023-11-02 14:54:33,089 DEBUG ++Rcv raw: b'\x81~\x01\x8d{"topic":"orderbook.50.BTCUSDC","ts":1698936873004,"type":"delta","data":{"s":"BTCUSDC","b":[["34960.68","0.09878"],["34959.41","0.02591"],["34958.14","0.0859"],["34952.69","0"],["34944.52","0"]],"a":[["34978.28","0.001447"],["34978.9","0.002162"],["34980.48","0.023472"],["34981.28","0.000562"],["34977.26","0"],["34961.23","0"],["34968.89","0"],["34963.37","0"]],"u":20010525,"seq":14108044432}}'
2023-11-02 14:54:33,090 DEBUG ++Rcv decoded: fin=1 opcode=1 data=b'{"topic":"orderbook.50.BTCUSDC","ts":1698936873004,"type":"delta","data":{"s":"BTCUSDC","b":[["34960.68","0.09878"],["34959.41","0.02591"],["34958.14","0.0859"],["34952.69","0"],["34944.52","0"]],"a":[["34978.28","0.001447"],["34978.9","0.002162"],["34980.48","0.023472"],["34981.28","0.000562"],["34977.26","0"],["34961.23","0"],["34968.89","0"],["34963.37","0"]],"u":20010525,"seq":14108044432}}'
2023-11-02 14:54:33,109 DEBUG ++Rcv raw: b'\x81~\x02\x1d{"topic":"orderbook.50.BTCUSDC","ts":1698936873024,"type":"delta","data":{"s":"BTCUSDC","b":[["34960.69","0.008756"],["34960.68","0.10078"],["34959.3","0.057209"],["34953.53","0.114437"],["34951.27","0.051547"],["34945.74","0.286157"],["34945.02","0.068655"],["34937.08","0"],["34937.84","0"],["34938.2","0"],["34937.39","0"],["34959.42","0"]],"a":[["34964.9","0.0572"],["34969.99","0.051548"],["34970.1","0.114383"],["34978.47","0.28589"],["34962.98","0"],["34971.03","0"],["34965.02","0"],["34968.88","0"]],"u":20010526,"seq":14108044454}}'
2023-11-02 14:54:33,109 DEBUG ++Rcv decoded: fin=1 opcode=1 data=b'{"topic":"orderbook.50.BTCUSDC","ts":1698936873024,"type":"delta","data":{"s":"BTCUSDC","b":[["34960.69","0.008756"],["34960.68","0.10078"],["34959.3","0.057209"],["34953.53","0.114437"],["34951.27","0.051547"],["34945.74","0.286157"],["34945.02","0.068655"],["34937.08","0"],["34937.84","0"],["34938.2","0"],["34937.39","0"],["34959.42","0"]],"a":[["34964.9","0.0572"],["34969.99","0.051548"],["34970.1","0.114383"],["34978.47","0.28589"],["34962.98","0"],["34971.03","0"],["34965.02","0"],["34968.88","0"]],"u":20010526,"seq":14108044454}}'
2023-11-02 14:54:33,129 DEBUG ++Rcv raw: b'\x81~\x01\xaf{"topic":"orderbook.50.BTCUSDC","ts":1698936873043,"type":"delta","data":{"s":"BTCUSDC","b":[["34960.68","0.005"],["34955.8","0.00057"],["34953.54","0.068671"],["34951.28","0.003021"],["34959.3","0"],["34953.11","0"],["34945.02","0"]],"a":[["34964.21","0.03"],["34964.89","0.034321"],["34981.7","0.034346"],["34981.71","0.056401"],["34965.01","0"],["34964.02","0"],["34964.9","0"],["34964.19","0"]],"u":20010527,"seq":14108044473}}'
2023-11-02 14:54:33,129 DEBUG ++Rcv decoded: fin=1 opcode=1 data=b'{"topic":"orderbook.50.BTCUSDC","ts":1698936873043,"type":"delta","data":{"s":"BTCUSDC","b":[["34960.68","0.005"],["34955.8","0.00057"],["34953.54","0.068671"],["34951.28","0.003021"],["34959.3","0"],["34953.11","0"],["34945.02","0"]],"a":[["34964.21","0.03"],["34964.89","0.034321"],["34981.7","0.034346"],["34981.71","0.056401"],["34965.01","0"],["34964.02","0"],["34964.9","0"],["34964.19","0"]],"u":20010527,"seq":14108044473}}'
2023-11-02 14:54:33,149 DEBUG ++Rcv raw: b'\x81~\x01\x88{"topic":"orderbook.50.BTCUSDC","ts":1698936873064,"type":"delta","data":{"s":"BTCUSDC","b":[["34960.68","0.002"],["34956.52","0.028602"],["34938.2","0.157044"],["34937.84","0.040649"],["34940.3","0"],["34945.74","0"],["34949.57","0"]],"a":[["34968.91","0.00057"],["34971.21","0.1875"],["34982.24","0.02859"],["34978.47","0"],["34970.1","0"],["34964.89","0"]],"u":20010528,"seq":14108044488}}'
2023-11-02 14:54:33,149 DEBUG ++Rcv decoded: fin=1 opcode=1 data=b'{"topic":"orderbook.50.BTCUSDC","ts":1698936873064,"type":"delta","data":{"s":"BTCUSDC","b":[["34960.68","0.002"],["34956.52","0.028602"],["34938.2","0.157044"],["34937.84","0.040649"],["34940.3","0"],["34945.74","0"],["34949.57","0"]],"a":[["34968.91","0.00057"],["34971.21","0.1875"],["34982.24","0.02859"],["34978.47","0"],["34970.1","0"],["34964.89","0"]],"u":20010528,"seq":14108044488}}'
2023-11-02 14:54:33,170 DEBUG ++Rcv raw: b'\x81~\x00\xec{"topic":"orderbook.50.BTCUSDC","ts":1698936873084,"type":"delta","data":{"s":"BTCUSDC","b":[["34956.53","0.08425"],["34956.43","0.02591"],["34952.91","0.026208"],["34937.84","0"],["34938.2","0"]],"a":[],"u":20010529,"seq":14108044495}}'
2023-11-02 14:54:33,170 DEBUG ++Rcv decoded: fin=1 opcode=1 data=b'{"topic":"orderbook.50.BTCUSDC","ts":1698936873084,"type":"delta","data":{"s":"BTCUSDC","b":[["34956.53","0.08425"],["34956.43","0.02591"],["34952.91","0.026208"],["34937.84","0"],["34938.2","0"]],"a":[],"u":20010529,"seq":14108044495}}'
2023-11-02 14:54:33,209 DEBUG ++Rcv raw: b'\x81~\x00\xd4{"topic":"orderbook.50.BTCUSDC","ts":1698936873124,"type":"delta","data":{"s":"BTCUSDC","b":[["34959.3","0.01144"],["34939.11","0"]],"a":[["34976.56","0.075313"],["34982.24","0"]],"u":20010530,"seq":14108044505}}'
2023-11-02 14:54:33,210 DEBUG ++Rcv decoded: fin=1 opcode=1 data=b'{"topic":"orderbook.50.BTCUSDC","ts":1698936873124,"type":"delta","data":{"s":"BTCUSDC","b":[["34959.3","0.01144"],["34939.11","0"]],"a":[["34976.56","0.075313"],["34982.24","0"]],"u":20010530,"seq":14108044505}}'
2023-11-02 14:54:33,228 DEBUG ++Rcv raw: b'\x81~\x00\xae{"topic":"orderbook.50.BTCUSDC","ts":1698936873143,"type":"delta","data":{"s":"BTCUSDC","b":[["34939.11","0.057242"],["34941.19","0"]],"a":[],"u":20010531,"seq":14108044510}}'
2023-11-02 14:54:33,229 DEBUG ++Rcv decoded: fin=1 opcode=1 data=b'{"topic":"orderbook.50.BTCUSDC","ts":1698936873143,"type":"delta","data":{"s":"BTCUSDC","b":[["34939.11","0.057242"],["34941.19","0"]],"a":[],"u":20010531,"seq":14108044510}}'
2023-11-02 14:54:33,249 DEBUG ++Rcv raw: b'\x81~\x01P{"topic":"orderbook.50.BTCUSDC","ts":1698936873164,"type":"delta","data":{"s":"BTCUSDC","b":[["34944.78","0.286165"],["34939.11","0"]],"a":[["34964.07","0.052325"],["34964.08","0.057201"],["34969.14","0.114386"],["34977.52","0.285897"],["34981.7","0"],["34981.71","0"],["34980.48","0"],["34981.28","0"]],"u":20010532,"seq":14108044522}}'
2023-11-02 14:54:33,249 DEBUG ++Rcv decoded: fin=1 opcode=1 data=b'{"topic":"orderbook.50.BTCUSDC","ts":1698936873164,"type":"delta","data":{"s":"BTCUSDC","b":[["34944.78","0.286165"],["34939.11","0"]],"a":[["34964.07","0.052325"],["34964.08","0.057201"],["34969.14","0.114386"],["34977.52","0.285897"],["34981.7","0"],["34981.71","0"],["34980.48","0"],["34981.28","0"]],"u":20010532,"seq":14108044522}}'
2023-11-02 14:54:33,268 DEBUG ++Rcv raw: b'\x81~\x00\xd7{"topic":"orderbook.50.BTCUSDC","ts":1698936873183,"type":"delta","data":{"s":"BTCUSDC","b":[],"a":[["34969.13","0.068637"],["34980.48","0.023472"],["34969.99","0"],["34964.08","0"]],"u":20010533,"seq":14108044530}}'
2023-11-02 14:54:33,268 DEBUG ++Rcv decoded: fin=1 opcode=1 data=b'{"topic":"orderbook.50.BTCUSDC","ts":1698936873183,"type":"delta","data":{"s":"BTCUSDC","b":[],"a":[["34969.13","0.068637"],["34980.48","0.023472"],["34969.99","0"],["34964.08","0"]],"u":20010533,"seq":14108044530}}'
2023-11-02 14:54:33,289 DEBUG ++Rcv raw: b'\x81~\x00\xae{"topic":"orderbook.50.BTCUSDC","ts":1698936873204,"type":"delta","data":{"s":"BTCUSDC","b":[],"a":[["34981.28","0.000562"],["34964.07","0"]],"u":20010534,"seq":14108044533}}'
2023-11-02 14:54:33,289 DEBUG ++Rcv decoded: fin=1 opcode=1 data=b'{"topic":"orderbook.50.BTCUSDC","ts":1698936873204,"type":"delta","data":{"s":"BTCUSDC","b":[],"a":[["34981.28","0.000562"],["34964.07","0"]],"u":20010534,"seq":14108044533}}'
2023-11-02 14:54:33,309 DEBUG ++Rcv raw: b'\x81~\x00\xad{"topic":"orderbook.50.BTCUSDC","ts":1698936873224,"type":"delta","data":{"s":"BTCUSDC","b":[["34939.11","0.057242"],["34959.3","0"]],"a":[],"u":20010535,"seq":14108044540}}'
2023-11-02 14:54:33,309 DEBUG ++Rcv decoded: fin=1 opcode=1 data=b'{"topic":"orderbook.50.BTCUSDC","ts":1698936873224,"type":"delta","data":{"s":"BTCUSDC","b":[["34939.11","0.057242"],["34959.3","0"]],"a":[],"u":20010535,"seq":14108044540}}'
2023-11-02 14:54:33,329 DEBUG ++Rcv raw: b'\x81~\x00\xae{"topic":"orderbook.50.BTCUSDC","ts":1698936873244,"type":"delta","data":{"s":"BTCUSDC","b":[["34956.54","0.001875"],["34939.11","0"]],"a":[],"u":20010536,"seq":14108044545}}'
2023-11-02 14:54:33,329 DEBUG ++Rcv decoded: fin=1 opcode=1 data=b'{"topic":"orderbook.50.BTCUSDC","ts":1698936873244,"type":"delta","data":{"s":"BTCUSDC","b":[["34956.54","0.001875"],["34939.11","0"]],"a":[],"u":20010536,"seq":14108044545}}'
2023-11-02 14:54:33,349 DEBUG ++Rcv raw: b'\x81~\x00\xae{"topic":"orderbook.50.BTCUSDC","ts":1698936873264,"type":"delta","data":{"s":"BTCUSDC","b":[["34939.11","0.057242"],["34951.28","0"]],"a":[],"u":20010537,"seq":14108044550}}'
2023-11-02 14:54:33,349 DEBUG ++Rcv decoded: fin=1 opcode=1 data=b'{"topic":"orderbook.50.BTCUSDC","ts":1698936873264,"type":"delta","data":{"s":"BTCUSDC","b":[["34939.11","0.057242"],["34951.28","0"]],"a":[],"u":20010537,"seq":14108044550}}'
2023-11-02 14:54:33,369 DEBUG ++Rcv raw: b'\x81~\x00\xac{"topic":"orderbook.50.BTCUSDC","ts":1698936873284,"type":"delta","data":{"s":"BTCUSDC","b":[],"a":[["34978.78","0.0859"],["34981.28","0"]],"u":20010538,"seq":14108044559}}'
2023-11-02 14:54:33,369 DEBUG ++Rcv decoded: fin=1 opcode=1 data=b'{"topic":"orderbook.50.BTCUSDC","ts":1698936873284,"type":"delta","data":{"s":"BTCUSDC","b":[],"a":[["34978.78","0.0859"],["34981.28","0"]],"u":20010538,"seq":14108044559}}'
2023-11-02 14:54:33,429 DEBUG ++Rcv raw: b'\x81~\x00\xab{"topic":"orderbook.50.BTCUSDC","ts":1698936873343,"type":"delta","data":{"s":"BTCUSDC","b":[["34939.86","0.028"],["34939.11","0"]],"a":[],"u":20010539,"seq":14108044590}}'
2023-11-02 14:54:33,429 DEBUG ++Rcv decoded: fin=1 opcode=1 data=b'{"topic":"orderbook.50.BTCUSDC","ts":1698936873343,"type":"delta","data":{"s":"BTCUSDC","b":[["34939.86","0.028"],["34939.11","0"]],"a":[],"u":20010539,"seq":14108044590}}'
2023-11-02 14:54:33,468 DEBUG ++Rcv raw: b'\x81~\x00\xd6{"topic":"orderbook.50.BTCUSDC","ts":1698936873383,"type":"delta","data":{"s":"BTCUSDC","b":[["34961.46","0.098391"],["34960.69","0"]],"a":[["34981.28","0.000562"],["34971.21","0"]],"u":20010540,"seq":14108044617}}'
2023-11-02 14:54:33,469 DEBUG ++Rcv decoded: fin=1 opcode=1 data=b'{"topic":"orderbook.50.BTCUSDC","ts":1698936873383,"type":"delta","data":{"s":"BTCUSDC","b":[["34961.46","0.098391"],["34960.69","0"]],"a":[["34981.28","0.000562"],["34971.21","0"]],"u":20010540,"seq":14108044617}}'
2023-11-02 14:54:33,489 DEBUG ++Rcv raw: b'\x81~\x00\xcf{"topic":"orderbook.50.BTCUSDC","ts":1698936873404,"type":"delta","data":{"s":"BTCUSDC","b":[["34950.96","0.1875"],["34955.8","0"]],"a":[["34964.62","0.03"],["34968.91","0"]],"u":20010541,"seq":14108044625}}'
