2023-11-02 14:54:10,699 INFO WebSocket Unified V5 (Auth) attempting connection...
2023-11-02 14:54:10,801 DEBUG --- request header ---
2023-11-02 14:54:10,812 DEBUG GET /v5/public/spot HTTP/1.1
Upgrade: websocket
Host: stream.bybit.com
Origin: https://stream.bybit.com
Sec-WebSocket-Key: YR84IVv0VdHSUHSMWxP4rA==
Sec-WebSocket-Version: 13
Connection: Upgrade


2023-11-02 14:54:10,813 DEBUG -----------------------
2023-11-02 14:54:10,813 DEBUG --- response header ---
2023-11-02 14:54:11,285 DEBUG HTTP/1.1 101 Switching Protocols
2023-11-02 14:54:11,286 DEBUG Connection: upgrade
2023-11-02 14:54:11,308 DEBUG Date: Thu, 02 Nov 2023 14:54:11 GMT
2023-11-02 14:54:11,308 DEBUG Upgrade: websocket
2023-11-02 14:54:11,308 DEBUG Sec-WebSocket-Accept: iV9NXoY22HAAmFx19aq6nDxUC9s=
2023-11-02 14:54:11,308 DEBUG X-Cache: Miss from cloudfront
2023-11-02 14:54:11,308 DEBUG Via: 1.1 c813ed55721b9ee3209e2abab7207a00.cloudfront.net (CloudFront)
2023-11-02 14:54:11,308 DEBUG X-Amz-Cf-Pop: FRA56-P4
2023-11-02 14:54:11,308 DEBUG X-Amz-Cf-Id: lPdj4x_3jGO8Pt4Nyam7r4J83brThpeArqd70DFKfJbvrAUvRL-6IQ==
2023-11-02 14:54:11,308 DEBUG -----------------------
2023-11-02 14:54:11,308 INFO Websocket connected
2023-11-02 14:54:11,308 INFO WebSocket Unified V5 (Auth) connected
2023-11-02 14:54:11,309 DEBUG ++Sent raw: b'\x81\xe7Q\xf2\xa7$*\xd0\xc8Ts\xc8\x87\x06"\x87\xc5W2\x80\xceF4\xd0\x8b\x04s\x80\xc2U\x0e\x9b\xc3\x06k\xd2\x85\x15b\x91\x94\x11i\xcb\x90\t`\xc3\x95\x12|\xc6\x97Ed\xdf\x9f\x1db\xc5\x8aA`\xc6\xc2\x13c\xc0\xc3\x12`\xc3\x9f\x06}\xd2\x85E#\x95\xd4\x06k\xd2\xfc\x06>\x80\xc3A#\x90\xc8K:\xdc\x92\x14\x7f\xb0\xf3g\x04\xa1\xe3gs\xaf\xda'
2023-11-02 14:54:11,309 DEBUG ++Sent decoded: fin=1 opcode=1 data=b'{"op": "subscribe", "req_id": "13c35897-1126-40a5-8937-e14e722d6118", "args": ["orderbook.50.BTCUSDC"]}'
2023-11-02 14:54:11,309 DEBUG WebSocket Unified V5 (Auth) opened.
2023-11-02 14:54:11,480 DEBUG ++Rcv raw: b'\x81~\x00\x98{"success":true,"ret_msg":"subscribe","conn_id":"36cddb9a-6200-4dc8-bc1e-003c36ee8b3b","req_id":"13c35897-1126-40a5-8937-e14e722d6118","op":"subscribe"}'
2023-11-02 14:54:11,481 DEBUG ++Rcv decoded: fin=1 opcode=1 data=b'{"success":true,"ret_msg":"subscribe","conn_id":"36cddb9a-6200-4dc8-bc1e-003c36ee8b3b","req_id":"13c35897-1126-40a5-8937-e14e722d6118","op":"subscribe"}'
2023-11-02 14:54:11,481 DEBUG Subscription to {"op": "subscribe", "req_id": "13c35897-1126-40a5-8937-e14e722d6118", "args": ["orderbook.50.BTCUSDC"]} successful.
2023-11-02 14:54:11,481 DEBUG ++Rcv raw: b'\x81~\tO{"topic":"orderbook.50.BTCUSDC","ts":1698936842984,"type":"snapshot","data":{"s":"BTCUSDC","b":[["34951.96","0.095296"],["34951.71","0.0002"],["34951.7","0.036"],["34951.26","0.0859"],["34950","0.0341"],["34949.55","0.068706"],["34949.54","0.0859"],["34948.01","0.031901"],["34948","0.0341"],["34947.82","0.0859"],["34947.18","0.028609"],["34947.07","0.00057"],["34946.14","0.002315"],["34946.13","0.216841"],["34946.12","0.361394"],["34946.1","0.0859"],["34946","0.0341"],["34945.47","0.054454"],["34944.38","0.0859"],["34944.24","0.114468"],["34944.01","0.109203"],["34944","0.0341"],["34943.75","0.1875"],["34943.35","0.02598"],["34942.66","0.0859"],["34942","0.0341"],["34941.48","0.082683"],["34941.47","0.051549"],["34941.44","0.025298"],["34940.94","0.0859"],["34940.13","0.1405"],["34940","0.0341"],["34939.85","0.1875"],["34939.49","0.08919"],["34939.22","0.0859"],["34936.36","0.112508"],["34936.35","0.1875"],["34936.09","0.207263"],["34936","0.0341"],["34935.14","0.823909"],["34935.13","1.373172"],["34934.24","0.000261"],["34934.2","0.000262"],["34933.8","0.286255"],["34932.72","0.029859"],["34932.01","0.112502"],["34931.31","0.1875"],["34931.09","0.057255"],["34929","0.164334"],["34928","0.026"]],"a":[["34954.84","0.01144"],["34954.85","0.008556"],["34954.86","0.003"],["34957.99","0.089253"],["34958","0.0341"],["34958.13","0.03895"],["34958.14","0.0859"],["34959.86","0.0859"],["34960","0.033905"],["34960.42","0.057207"],["34960.85","0.028609"],["34961.39","0.051544"],["34961.58","0.0859"],["34962","0.0341"],["34963.17","0.065242"],["34963.18","0.022829"],["34963.3","0.0859"],["34963.84","0.03"],["34963.99","0.04411"],["34964.01","0.014572"],["34964.7","0.112502"],["34964.71","0.1875"],["34965","0.001"],["34965.02","0.0859"],["34966.56","0.000501"],["34966.73","0.051543"],["34966.74","0.0859"],["34967.69","0.220851"],["34967.7","0.368084"],["34967.73","0.042736"],["34968.19","0.025347"],["34968.25","0.114389"],["34968.46","0.0859"],["34968.57","0.1875"],["34969.46","0.04418"],["34969.88","0.051549"],["34969.89","0.077787"],["34970.08","0.0406"],["34970.13","0.03"],["34970.18","0.0859"],["34970.32","0.000863"],["34971.82","0.803171"],["34971.9","0.0859"],["34972","1.373405"],["34973.09","0.004801"],["34973.24","0.00039"],["34973.62","0.0859"],["34973.64","0.001028"],["34973.66","0.1875"],["34974.49","0.048631"]],"u":20009549,"seq":14108027278}}'
2023-11-02 14:54:11,481 DEBUG ++Rcv decoded: fin=1 opcode=1 data=b'{"topic":"orderbook.50.BTCUSDC","ts":1698936842984,"type":"snapshot","data":{"s":"BTCUSDC","b":[["34951.96","0.095296"],["34951.71","0.0002"],["34951.7","0.036"],["34951.26","0.0859"],["34950","0.0341"],["34949.55","0.068706"],["34949.54","0.0859"],["34948.01","0.031901"],["34948","0.0341"],["34947.82","0.0859"],["34947.18","0.028609"],["34947.07","0.00057"],["34946.14","0.002315"],["34946.13","0.216841"],["34946.12","0.361394"],["34946.1","0.0859"],["34946","0.0341"],["34945.47","0.054454"],["34944.38","0.0859"],["34944.24","0.114468"],["34944.01","0.109203"],["34944","0.0341"],["34943.75","0.1875"],["34943.35","0.02598"],["34942.66","0.0859"],["34942","0.0341"],["34941.48","0.082683"],["34941.47","0.051549"],["34941.44","0.025298"],["34940.94","0.0859"],["34940.13","0.1405"],["34940","0.0341"],["34939.85","0.1875"],["34939.49","0.08919"],["34939.22","0.0859"],["34936.36","0.112508"],["34936.35","0.1875"],["34936.09","0.207263"],["34936","0.0341"],["34935.14","0.823909"],["34935.13","1.373172"],["34934.24","0.000261"],["34934.2","0.000262"],["34933.8","0.286255"],["34932.72","0.029859"],["34932.01","0.112502"],["34931.31","0.1875"],["34931.09","0.057255"],["34929","0.164334"],["34928","0.026"]],"a":[["34954.84","0.01144"],["34954.85","0.008556"],["34954.86","0.003"],["34957.99","0.089253"],["34958","0.0341"],["34958.13","0.03895"],["34958.14","0.0859"],["34959.86","0.0859"],["34960","0.033905"],["34960.42","0.057207"],["34960.85","0.028609"],["34961.39","0.051544"],["34961.58","0.0859"],["34962","0.0341"],["34963.17","0.065242"],["34963.18","0.022829"],["34963.3","0.0859"],["34963.84","0.03"],["34963.99","0.04411"],["34964.01","0.014572"],["34964.7","0.112502"],["34964.71","0.1875"],["34965","0.001"],["34965.02","0.0859"],["34966.56","0.000501"],["34966.73","0.051543"],["34966.74","0.0859"],["34967.69","0.220851"],["34967.7","0.368084"],["34967.73","0.042736"],["34968.19","0.025347"],["34968.25","0.114389"],["34968.46","0.0859"],["34968.57","0.1875"],["34969.46","0.04418"],["34969.88","0.051549"],["34969.89","0.077787"],["34970.08","0.0406"],["34970.13","0.03"],["34970.18","0.0859"],["34970.32","0.000863"],["34971.82","0.803171"],["34971.9","0.0859"],["34972","1.373405"],["34973.09","0.004801"],["34973.24","0.00039"],["34973.62","0.0859"],["34973.64","0.001028"],["34973.66","0.1875"],["34974.49","0.048631"]],"u":20009549,"seq":14108027278}}'
2023-11-02 14:54:11,482 DEBUG ++Rcv raw: b'\x81~\x00\xae{"topic":"orderbook.50.BTCUSDC","ts":1698936843004,"type":"delta","data":{"s":"BTCUSDC","b":[["34952.07","0.057221"],["34951.96","0"]],"a":[],"u":20009550,"seq":14108027283}}'
2023-11-02 14:54:11,482 DEBUG ++Rcv decoded: fin=1 opcode=1 data=b'{"topic":"orderbook.50.BTCUSDC","ts":1698936843004,"type":"delta","data":{"s":"BTCUSDC","b":[["34952.07","0.057221"],["34951.96","0"]],"a":[],"u":20009550,"seq":14108027283}}'
2023-11-02 14:54:11,482 DEBUG ++Rcv raw: b'\x81~\x00\xac{"topic":"orderbook.50.BTCUSDC","ts":1698936843023,"type":"delta","data":{"s":"BTCUSDC","b":[["34927.27","0.1875"],["34947.07","0"]],"a":[],"u":20009551,"seq":14108027286}}'
2023-11-02 14:54:11,482 DEBUG ++Rcv decoded: fin=1 opcode=1 data=b'{"topic":"orderbook.50.BTCUSDC","ts":1698936843023,"type":"delta","data":{"s":"BTCUSDC","b":[["34927.27","0.1875"],["34947.07","0"]],"a":[],"u":20009551,"seq":14108027286}}'
2023-11-02 14:54:11,483 DEBUG ++Rcv raw: b'\x81~\x00\xaa{"topic":"orderbook.50.BTCUSDC","ts":1698936843043,"type":"delta","data":{"s":"BTCUSDC","b":[["34927.18","0.026"],["34951.7","0"]],"a":[],"u":20009552,"seq":14108027294}}'
2023-11-02 14:54:11,483 DEBUG ++Rcv decoded: fin=1 opcode=1 data=b'{"topic":"orderbook.50.BTCUSDC","ts":1698936843043,"type":"delta","data":{"s":"BTCUSDC","b":[["34927.18","0.026"],["34951.7","0"]],"a":[],"u":20009552,"seq":14108027294}}'
2023-11-02 14:54:11,483 DEBUG ++Rcv raw: b'\x81~\x00\xd6{"topic":"orderbook.50.BTCUSDC","ts":1698936843063,"type":"delta","data":{"s":"BTCUSDC","b":[["34927.11","0.278379"],["34951.71","0"]],"a":[["34974.75","0.114425"],["34954.84","0"]],"u":20009553,"seq":14108027299}}'
2023-11-02 14:54:11,483 DEBUG ++Rcv decoded: fin=1 opcode=1 data=b'{"topic":"orderbook.50.BTCUSDC","ts":1698936843063,"type":"delta","data":{"s":"BTCUSDC","b":[["34927.11","0.278379"],["34951.71","0"]],"a":[["34974.75","0.114425"],["34954.84","0"]],"u":20009553,"seq":14108027299}}'
2023-11-02 14:54:11,483 DEBUG ++Rcv raw: b'\x81~\x00\xad{"topic":"orderbook.50.BTCUSDC","ts":1698936843103,"type":"delta","data":{"s":"BTCUSDC","b":[["34942.2","0.043599"],["34927.11","0"]],"a":[],"u":20009554,"seq":14108027318}}'
2023-11-02 14:54:11,483 DEBUG ++Rcv decoded: fin=1 opcode=1 data=b'{"topic":"orderbook.50.BTCUSDC","ts":1698936843103,"type":"delta","data":{"s":"BTCUSDC","b":[["34942.2","0.043599"],["34927.11","0"]],"a":[],"u":20009554,"seq":14108027318}}'
2023-11-02 14:54:11,483 DEBUG ++Rcv raw: b'\x81~\x00\xf4{"topic":"orderbook.50.BTCUSDC","ts":1698936843124,"type":"delta","data":{"s":"BTCUSDC","b":[["34952.08","0.0002"],["34927.28","0.167031"],["34929","0"],["34939.49","0"]],"a":[["34975","0.001"],["34954.85","0"]],"u":20009555,"seq":14108027332}}'
2023-11-02 14:54:11,483 DEBUG ++Rcv decoded: fin=1 opcode=1 data=b'{"topic":"orderbook.50.BTCUSDC","ts":1698936843124,"type":"delta","data":{"s":"BTCUSDC","b":[["34952.08","0.0002"],["34927.28","0.167031"],["34929","0"],["34939.49","0"]],"a":[["34975","0.001"],["34954.85","0"]],"u":20009555,"seq":14108027332}}'
2023-11-02 14:54:11,484 DEBUG ++Rcv raw: b'\x81~\x00\xd1{"topic":"orderbook.50.BTCUSDC","ts":1698936843143,"type":"delta","data":{"s":"BTCUSDC","b":[["34952.35","0.05722"],["34952.07","0"]],"a":[["34971.58","0.00024"],["34975","0"]],"u":20009556,"seq":14108027340}}'
2023-11-02 14:54:11,484 DEBUG ++Rcv decoded: fin=1 opcode=1 data=b'{"topic":"orderbook.50.BTCUSDC","ts":1698936843143,"type":"delta","data":{"s":"BTCUSDC","b":[["34952.35","0.05722"],["34952.07","0"]],"a":[["34971.58","0.00024"],["34975","0"]],"u":20009556,"seq":14108027340}}'
2023-11-02 14:54:11,484 DEBUG ++Rcv raw: b'\x81~\x00\xce{"topic":"orderbook.50.BTCUSDC","ts":1698936843163,"type":"delta","data":{"s":"BTCUSDC","b":[["34952.36","0.0002"],["34952.08","0"]],"a":[["34975","0.001"],["34958.14","0"]],"u":20009557,"seq":14108027358}}'
2023-11-02 14:54:11,484 DEBUG ++Rcv decoded: fin=1 opcode=1 data=b'{"topic":"orderbook.50.BTCUSDC","ts":1698936843163,"type":"delta","data":{"s":"BTCUSDC","b":[["34952.36","0.0002"],["34952.08","0"]],"a":[["34975","0.001"],["34958.14","0"]],"u":20009557,"seq":14108027358}}'
2023-11-02 14:54:11,484 DEBUG ++Rcv raw: b'\x81~\x00\xeb{"topic":"orderbook.50.BTCUSDC","ts":1698936843184,"type":"delta","data":{"s":"BTCUSDC","b":[["34927.11","0.278379"],["34952.35","0"]],"a":[["34957.99","0.048963"],["34959.85","0.051546"],["34975","0"]],"u":20009558,"seq":14108027380}}'
2023-11-02 14:54:11,484 DEBUG ++Rcv decoded: fin=1 opcode=1 data=b'{"topic":"orderbook.50.BTCUSDC","ts":1698936843184,"type":"delta","data":{"s":"BTCUSDC","b":[["34927.11","0.278379"],["34952.35","0"]],"a":[["34957.99","0.048963"],["34959.85","0.051546"],["34975","0"]],"u":20009558,"seq":14108027380}}'
2023-11-02 14:54:11,484 DEBUG ++Rcv raw: b'\x81~\x00\xae{"topic":"orderbook.50.BTCUSDC","ts":1698936843224,"type":"delta","data":{"s":"BTCUSDC","b":[],"a":[["34971.23","0.123515"],["34974.75","0"]],"u":20009559,"seq":14108027400}}'
2023-11-02 14:54:11,484 DEBUG ++Rcv decoded: fin=1 opcode=1 data=b'{"topic":"orderbook.50.BTCUSDC","ts":1698936843224,"type":"delta","data":{"s":"BTCUSDC","b":[],"a":[["34971.23","0.123515"],["34974.75","0"]],"u":20009559,"seq":14108027400}}'
2023-11-02 14:54:11,485 DEBUG ++Rcv raw: b'\x81~\x00\xa8{"topic":"orderbook.50.BTCUSDC","ts":1698936843243,"type":"delta","data":{"s":"BTCUSDC","b":[["34925","0.0002"],["34934.2","0"]],"a":[],"u":20009560,"seq":14108027407}}'
2023-11-02 14:54:11,485 DEBUG ++Rcv decoded: fin=1 opcode=1 data=b'{"topic":"orderbook.50.BTCUSDC","ts":1698936843243,"type":"delta","data":{"s":"BTCUSDC","b":[["34925","0.0002"],["34934.2","0"]],"a":[],"u":20009560,"seq":14108027407}}'
2023-11-02 14:54:11,485 DEBUG ++Rcv raw: b'\x81~\x00\x9b{"topic":"orderbook.50.BTCUSDC","ts":1698936843264,"type":"delta","data":{"s":"BTCUSDC","b":[],"a":[["34954.86","0.0028"]],"u":20009561,"seq":14108027412}}'
2023-11-02 14:54:11,485 DEBUG ++Rcv decoded: fin=1 opcode=1 data=b'{"topic":"orderbook.50.BTCUSDC","ts":1698936843264,"type":"delta","data":{"s":"BTCUSDC","b":[],"a":[["34954.86","0.0028"]],"u":20009561,"seq":14108027412}}'
2023-11-02 14:54:11,486 DEBUG ++Rcv raw: b'\x81~\x00\xad{"topic":"orderbook.50.BTCUSDC","ts":1698936843284,"type":"delta","data":{"s":"BTCUSDC","b":[],"a":[["34954.83","0.01144"],["34974.49","0"]],"u":20009562,"seq":14108027421}}'
2023-11-02 14:54:11,486 DEBUG ++Rcv decoded: fin=1 opcode=1 data=b'{"topic":"orderbook.50.BTCUSDC","ts":1698936843284,"type":"delta","data":{"s":"BTCUSDC","b":[],"a":[["34954.83","0.01144"],["34974.49","0"]],"u":20009562,"seq":14108027421}}'
2023-11-02 14:54:11,486 DEBUG ++Rcv raw: b'\x81~\x00\xea{"topic":"orderbook.50.BTCUSDC","ts":1698936843303,"type":"delta","data":{"s":"BTCUSDC","b":[["34952.36","0.0032"],["34924.43","0.274892"],["34932.72","0"]],"a":[["34958.14","0.0859"],["34970.13","0"]],"u":20009563,"seq":14108027433}}'
2023-11-02 14:54:11,486 DEBUG ++Rcv decoded: fin=1 opcode=1 data=b'{"topic":"orderbook.50.BTCUSDC","ts":1698936843303,"type":"delta","data":{"s":"BTCUSDC","b":[["34952.36","0.0032"],["34924.43","0.274892"],["34932.72","0"]],"a":[["34958.14","0.0859"],["34970.13","0"]],"u":20009563,"seq":14108027433}}'
2023-11-02 14:54:11,486 DEBUG ++Rcv raw: b'\x81~\x00\xeb{"topic":"orderbook.50.BTCUSDC","ts":1698936843323,"type":"delta","data":{"s":"BTCUSDC","b":[["34950.73","0.036"],["34924.43","0"]],"a":[["34957.99","0.089257"],["34974.49","0.048631"],["34959.85","0"]],"u":20009564,"seq":14108027437}}'
2023-11-02 14:54:11,487 DEBUG ++Rcv decoded: fin=1 opcode=1 data=b'{"topic":"orderbook.50.BTCUSDC","ts":1698936843323,"type":"delta","data":{"s":"BTCUSDC","b":[["34950.73","0.036"],["34924.43","0"]],"a":[["34957.99","0.089257"],["34974.49","0.048631"],["34959.85","0"]],"u":20009564,"seq":14108027437}}'
2023-11-02 14:54:11,487 DEBUG ++Rcv raw: b'\x81~\x00\xad{"topic":"orderbook.50.BTCUSDC","ts":1698936843384,"type":"delta","data":{"s":"BTCUSDC","b":[],"a":[["34971.54","0.00024"],["34954.83","0"]],"u":20009565,"seq":14108027475}}'
2023-11-02 14:54:11,487 DEBUG ++Rcv decoded: fin=1 opcode=1 data=b'{"topic":"orderbook.50.BTCUSDC","ts":1698936843384,"type":"delta","data":{"s":"BTCUSDC","b":[],"a":[["34971.54","0.00024"],["34954.83","0"]],"u":20009565,"seq":14108027475}}'
2023-11-02 14:54:11,487 DEBUG ++Rcv raw: b'\x81~\x00\x9d{"topic":"orderbook.50.BTCUSDC","ts":1698936843403,"type":"delta","data":{"s":"BTCUSDC","b":[],"a":[["34954.86","0.090157"]],"u":20009566,"seq":14108027481}}'
2023-11-02 14:54:11,488 DEBUG ++Rcv decoded: fin=1 opcode=1 data=b'{"topic":"orderbook.50.BTCUSDC","ts":1698936843403,"type":"delta","data":{"s":"BTCUSDC","b":[],"a":[["34954.86","0.090157"]],"u":20009566,"seq":14108027481}}'
2023-11-02 14:54:11,488 DEBUG ++Rcv raw: b'\x81~\x00\xae{"topic":"orderbook.50.BTCUSDC","ts":1698936843424,"type":"delta","data":{"s":"BTCUSDC","b":[["34924.43","0.274892"],["34951.26","0"]],"a":[],"u":20009567,"seq":14108027487}}'
2023-11-02 14:54:11,488 DEBUG ++Rcv decoded: fin=1 opcode=1 data=b'{"topic":"orderbook.50.BTCUSDC","ts":1698936843424,"type":"delta","data":{"s":"BTCUSDC","b":[["34924.43","0.274892"],["34951.26","0"]],"a":[],"u":20009567,"seq":14108027487}}'
2023-11-02 14:54:11,489 DEBUG ++Rcv raw: b'\x81~\x00\xfd{"topic":"orderbook.50.BTCUSDC","ts":1698936843444,"type":"delta","data":{"s":"BTCUSDC","b":[["34950.74","0.021608"],["34949.19","0.023176"],["34947.83","0.051549"],["34924.43","0"],["34927.11","0"],["34925","0"]],"a":[],"u":20009568,"seq":14108027494}}'
2023-11-02 14:54:11,489 DEBUG ++Rcv decoded: fin=1 opcode=1 data=b'{"topic":"orderbook.50.BTCUSDC","ts":1698936843444,"type":"delta","data":{"s":"BTCUSDC","b":[["34950.74","0.021608"],["34949.19","0.023176"],["34947.83","0.051549"],["34924.43","0"],["34927.11","0"],["34925","0"]],"a":[],"u":20009568,"seq":14108027494}}'
2023-11-02 14:54:11,489 DEBUG ++Rcv raw: b'\x81~\x00\xad{"topic":"orderbook.50.BTCUSDC","ts":1698936843463,"type":"delta","data":{"s":"BTCUSDC","b":[],"a":[["34954.82","0.01144"],["34974.49","0"]],"u":20009569,"seq":14108027516}}'
2023-11-02 14:54:11,489 DEBUG ++Rcv decoded: fin=1 opcode=1 data=b'{"topic":"orderbook.50.BTCUSDC","ts":1698936843463,"type":"delta","data":{"s":"BTCUSDC","b":[],"a":[["34954.82","0.01144"],["34974.49","0"]],"u":20009569,"seq":14108027516}}'
2023-11-02 14:54:11,490 DEBUG ++Rcv raw: b'\x81~\x00\x9b{"topic":"orderbook.50.BTCUSDC","ts":1698936843484,"type":"delta","data":{"s":"BTCUSDC","b":[],"a":[["34954.86","0.0028"]],"u":20009570,"seq":14108027525}}'
2023-11-02 14:54:11,490 DEBUG ++Rcv decoded: fin=1 opcode=1 data=b'{"topic":"orderbook.50.BTCUSDC","ts":1698936843484,"type":"delta","data":{"s":"BTCUSDC","b":[],"a":[["34954.86","0.0028"]],"u":20009570,"seq":14108027525}}'
2023-11-02 14:54:11,490 DEBUG ++Rcv raw: b'\x81~\x00\x9b{"topic":"orderbook.50.BTCUSDC","ts":1698936843503,"type":"delta","data":{"s":"BTCUSDC","b":[["34940.13","0.1125"]],"a":[],"u":20009571,"seq":14108027537}}'
2023-11-02 14:54:11,490 DEBUG ++Rcv decoded: fin=1 opcode=1 data=b'{"topic":"orderbook.50.BTCUSDC","ts":1698936843503,"type":"delta","data":{"s":"BTCUSDC","b":[["34940.13","0.1125"]],"a":[],"u":20009571,"seq":14108027537}}'
2023-11-02 14:54:11,490 DEBUG ++Rcv raw: b'\x81~\x01"{"topic":"orderbook.50.BTCUSDC","ts":1698936843563,"type":"delta","data":{"s":"BTCUSDC","b":[["34927.11","0.278379"],["34925","0.0002"],["34934.24","0"],["34933.8","0"]],"a":[["34974.49","0.048631"],["34974.75","0.114425"],["34954.82","0"],["34971.54","0"]],"u":20009572,"seq":14108027564}}'
2023-11-02 14:54:11,491 DEBUG ++Rcv decoded: fin=1 opcode=1 data=b'{"topic":"orderbook.50.BTCUSDC","ts":1698936843563,"type":"delta","data":{"s":"BTCUSDC","b":[["34927.11","0.278379"],["34925","0.0002"],["34934.24","0"],["34933.8","0"]],"a":[["34974.49","0.048631"],["34974.75","0.114425"],["34954.82","0"],["34971.54","0"]],"u":20009572,"seq":14108027564}}'
2023-11-02 14:54:11,491 DEBUG ++Rcv raw: b'\x81~\x01\x0f{"topic":"orderbook.50.BTCUSDC","ts":1698936843583,"type":"delta","data":{"s":"BTCUSDC","b":[["34952.62","0.0002"],["34952.61","0.05722"],["34952.36","0.003"],["34934.92","0.286246"],["34927.18","0"],["34927.11","0"],["34925","0"]],"a":[],"u":20009573,"seq":14108027572}}'
2023-11-02 14:54:11,491 DEBUG ++Rcv decoded: fin=1 opcode=1 data=b'{"topic":"orderbook.50.BTCUSDC","ts":1698936843583,"type":"delta","data":{"s":"BTCUSDC","b":[["34952.62","0.0002"],["34952.61","0.05722"],["34952.36","0.003"],["34934.92","0.286246"],["34927.18","0"],["34927.11","0"],["34925","0"]],"a":[],"u":20009573,"seq":14108027572}}'
2023-11-02 14:54:11,491 DEBUG ++Rcv raw: b'\x81~\x00\xd4{"topic":"orderbook.50.BTCUSDC","ts":1698936843603,"type":"delta","data":{"s":"BTCUSDC","b":[["34927.18","0.026"],["34927.11","0.278379"],["34952.61","0"],["34952.36","0"]],"a":[],"u":20009574,"seq":14108027576}}'
2023-11-02 14:54:11,492 DEBUG ++Rcv decoded: fin=1 opcode=1 data=b'{"topic":"orderbook.50.BTCUSDC","ts":1698936843603,"type":"delta","data":{"s":"BTCUSDC","b":[["34927.18","0.026"],["34927.11","0.278379"],["34952.61","0"],["34952.36","0"]],"a":[],"u":20009574,"seq":14108027576}}'
2023-11-02 14:54:11,492 DEBUG ++Rcv raw: b'\x81~\x00\xad{"topic":"orderbook.50.BTCUSDC","ts":1698936843664,"type":"delta","data":{"s":"BTCUSDC","b":[],"a":[["34954.85","0.01144"],["34974.75","0"]],"u":20009575,"seq":14108027585}}'
2023-11-02 14:54:11,492 DEBUG ++Rcv decoded: fin=1 opcode=1 data=b'{"topic":"orderbook.50.BTCUSDC","ts":1698936843664,"type":"delta","data":{"s":"BTCUSDC","b":[],"a":[["34954.85","0.01144"],["34974.75","0"]],"u":20009575,"seq":14108027585}}'
2023-11-02 14:54:11,493 DEBUG ++Rcv raw: b'\x81~\x00\xab{"topic":"orderbook.50.BTCUSDC","ts":1698936843683,"type":"delta","data":{"s":"BTCUSDC","b":[["34937.5","0.0859"],["34927.11","0"]],"a":[],"u":20009576,"seq":14108027590}}'
2023-11-02 14:54:11,493 DEBUG ++Rcv decoded: fin=1 opcode=1 data=b'{"topic":"orderbook.50.BTCUSDC","ts":1698936843683,"type":"delta","data":{"s":"BTCUSDC","b":[["34937.5","0.0859"],["34927.11","0"]],"a":[],"u":20009576,"seq":14108027590}}'
2023-11-02 14:54:11,493 DEBUG ++Rcv raw: b'\x81~\x00\xd2{"topic":"orderbook.50.BTCUSDC","ts":1698936843704,"type":"delta","data":{"s":"BTCUSDC","b":[["34937.51","0.05154"],["34936.1","0.028"],["34927.27","0"],["34927.18","0"]],"a":[],"u":20009577,"seq":14108027600}}'
2023-11-02 14:54:11,493 DEBUG ++Rcv decoded: fin=1 opcode=1 data=b'{"topic":"orderbook.50.BTCUSDC","ts":1698936843704,"type":"delta","data":{"s":"BTCUSDC","b":[["34937.51","0.05154"],["34936.1","0.028"],["34927.27","0"],["34927.18","0"]],"a":[],"u":20009577,"seq":14108027600}}'
2023-11-02 14:54:11,494 DEBUG ++Rcv raw: b'\x81~\x00\xd6{"topic":"orderbook.50.BTCUSDC","ts":1698936843724,"type":"delta","data":{"s":"BTCUSDC","b":[["34952.69","0.05722"],["34945.38","0.114464"],["34944.24","0"],["34927.28","0"]],"a":[],"u":20009578,"seq":14108027613}}'
2023-11-02 14:54:11,494 DEBUG ++Rcv decoded: fin=1 opcode=1 data=b'{"topic":"orderbook.50.BTCUSDC","ts":1698936843724,"type":"delta","data":{"s":"BTCUSDC","b":[["34952.69","0.05722"],["34945.38","0.114464"],["34944.24","0"],["34927.28","0"]],"a":[],"u":20009578,"seq":14108027613}}'
2023-11-02 14:54:11,494 DEBUG ++Rcv raw: b'\x81~\x00\xf1{"topic":"orderbook.50.BTCUSDC","ts":1698936843864,"type":"delta","data":{"s":"BTCUSDC","b":[["34951.26","0.0859"],["34928","0"]],"a":[["34974.75","0.114425"],["34975","0.001"],["34958","0"],["34958.14","0"]],"u":20009579,"seq":14108027638}}'
2023-11-02 14:54:11,494 DEBUG ++Rcv decoded: fin=1 opcode=1 data=b'{"topic":"orderbook.50.BTCUSDC","ts":1698936843864,"type":"delta","data":{"s":"BTCUSDC","b":[["34951.26","0.0859"],["34928","0"]],"a":[["34974.75","0.114425"],["34975","0.001"],["34958","0"],["34958.14","0"]],"u":20009579,"seq":14108027638}}'
2023-11-02 14:54:11,494 DEBUG ++Rcv raw: b'\x81~\x00\xe8{"topic":"orderbook.50.BTCUSDC","ts":1698936843884,"type":"delta","data":{"s":"BTCUSDC","b":[["34928","0.026"],["34949.55","0"]],"a":[["34957.99","0.023371"],["34959.85","0.051542"],["34954.85","0"]],"u":20009580,"seq":14108027657}}'
2023-11-02 14:54:11,494 DEBUG ++Rcv decoded: fin=1 opcode=1 data=b'{"topic":"orderbook.50.BTCUSDC","ts":1698936843884,"type":"delta","data":{"s":"BTCUSDC","b":[["34928","0.026"],["34949.55","0"]],"a":[["34957.99","0.023371"],["34959.85","0.051542"],["34954.85","0"]],"u":20009580,"seq":14108027657}}'
2023-11-02 14:54:11,495 DEBUG ++Rcv raw: b'\x81~\x01I{"topic":"orderbook.50.BTCUSDC","ts":1698936843904,"type":"delta","data":{"s":"BTCUSDC","b":[["34954.68","0.099448"],["34952.7","0.0002"],["34944.18","0.1875"],["34952.69","0"],["34952.62","0"],["34928","0"]],"a":[["34957.98","0.008556"],["34976.24","0.278379"],["34960.42","0"],["34954.86","0"]],"u":20009581,"seq":14108027683}}'
2023-11-02 14:54:11,495 DEBUG ++Rcv decoded: fin=1 opcode=1 data=b'{"topic":"orderbook.50.BTCUSDC","ts":1698936843904,"type":"delta","data":{"s":"BTCUSDC","b":[["34954.68","0.099448"],["34952.7","0.0002"],["34944.18","0.1875"],["34952.69","0"],["34952.62","0"],["34928","0"]],"a":[["34957.98","0.008556"],["34976.24","0.278379"],["34960.42","0"],["34954.86","0"]],"u":20009581,"seq":14108027683}}'
2023-11-02 14:54:11,495 DEBUG ++Rcv raw: b'\x81~\x01e{"topic":"orderbook.50.BTCUSDC","ts":1698936843923,"type":"delta","data":{"s":"BTCUSDC","b":[["34953.26","0.057219"],["34949.79","0.00057"],["34944.39","0.112503"],["34931.09","0"],["34944.01","0"],["34931.31","0"]],"a":[["34957.99","0.025371"],["34961.13","0.057206"],["34976.84","0.001"],["34958.13","0"],["34964.71","0"]],"u":20009582,"seq":14108027698}}'
2023-11-02 14:54:11,495 DEBUG ++Rcv decoded: fin=1 opcode=1 data=b'{"topic":"orderbook.50.BTCUSDC","ts":1698936843923,"type":"delta","data":{"s":"BTCUSDC","b":[["34953.26","0.057219"],["34949.79","0.00057"],["34944.39","0.112503"],["34931.09","0"],["34944.01","0"],["34931.31","0"]],"a":[["34957.99","0.025371"],["34961.13","0.057206"],["34976.84","0.001"],["34958.13","0"],["34964.71","0"]],"u":20009582,"seq":14108027698}}'
2023-11-02 14:54:11,495 DEBUG ++Rcv raw: b'\x81~\x01\x8e{"topic":"orderbook.50.BTCUSDC","ts":1698936843944,"type":"delta","data":{"s":"BTCUSDC","b":[["34954.69","0.0002"],["34952.69","0.003"],["34951.27","0.073144"],["34948.02","0.002962"],["34952.7","0"],["34932.01","0"],["34934.92","0"],["34950.74","0"]],"a":[["34957.98","0.008356"],["34957.99","0.002"],["34962.87","0.00057"],["34964.7","0.051545"],["34966.73","0"]],"u":20009583,"seq":14108027727}}'
2023-11-02 14:54:11,495 DEBUG ++Rcv decoded: fin=1 opcode=1 data=b'{"topic":"orderbook.50.BTCUSDC","ts":1698936843944,"type":"delta","data":{"s":"BTCUSDC","b":[["34954.69","0.0002"],["34952.69","0.003"],["34951.27","0.073144"],["34948.02","0.002962"],["34952.7","0"],["34932.01","0"],["34934.92","0"],["34950.74","0"]],"a":[["34957.98","0.008356"],["34957.99","0.002"],["34962.87","0.00057"],["34964.7","0.051545"],["34966.73","0"]],"u":20009583,"seq":14108027727}}'
2023-11-02 14:54:11,495 DEBUG ++Rcv raw: b'\x81~\x00\xd5{"topic":"orderbook.50.BTCUSDC","ts":1698936843964,"type":"delta","data":{"s":"BTCUSDC","b":[["34932.01","0.112502"],["34931.31","0.1875"],["34954.68","0"],["34946.14","0"]],"a":[],"u":20009584,"seq":14108027742}}'
2023-11-02 14:54:11,496 DEBUG ++Rcv decoded: fin=1 opcode=1 data=b'{"topic":"orderbook.50.BTCUSDC","ts":1698936843964,"type":"delta","data":{"s":"BTCUSDC","b":[["34932.01","0.112502"],["34931.31","0.1875"],["34954.68","0"],["34946.14","0"]],"a":[],"u":20009584,"seq":14108027742}}'
2023-11-02 14:54:11,496 DEBUG ++Rcv raw: b'\x81~\x00\xd5{"topic":"orderbook.50.BTCUSDC","ts":1698936843984,"type":"delta","data":{"s":"BTCUSDC","b":[["34936.06","0.286237"],["34931.31","0"]],"a":[["34954.85","0.01144"],["34976.84","0"]],"u":20009585,"seq":14108027757}}'
2023-11-02 14:54:11,496 DEBUG ++Rcv decoded: fin=1 opcode=1 data=b'{"topic":"orderbook.50.BTCUSDC","ts":1698936843984,"type":"delta","data":{"s":"BTCUSDC","b":[["34936.06","0.286237"],["34931.31","0"]],"a":[["34954.85","0.01144"],["34976.84","0"]],"u":20009585,"seq":14108027757}}'
2023-11-02 14:54:11,496 DEBUG ++Rcv raw: b'\x81~\x01"{"topic":"orderbook.50.BTCUSDC","ts":1698936844003,"type":"delta","data":{"s":"BTCUSDC","b":[["34934.43","0.000262"],["34949.79","0"]],"a":[["34964.98","0.1875"],["34976.84","0.001"],["34976.85","0.05718"],["34954.85","0"],["34962.87","0"],["34971.58","0"]],"u":20009586,"seq":14108027775}}'
2023-11-02 14:54:11,496 DEBUG ++Rcv decoded: fin=1 opcode=1 data=b'{"topic":"orderbook.50.BTCUSDC","ts":1698936844003,"type":"delta","data":{"s":"BTCUSDC","b":[["34934.43","0.000262"],["34949.79","0"]],"a":[["34964.98","0.1875"],["34976.84","0.001"],["34976.85","0.05718"],["34954.85","0"],["34962.87","0"],["34971.58","0"]],"u":20009586,"seq":14108027775}}'
2023-11-02 14:54:11,496 DEBUG ++Rcv raw: b'\x81~\x01_{"topic":"orderbook.50.BTCUSDC","ts":1698936844023,"type":"delta","data":{"s":"BTCUSDC","b":[["34949.8","0.00057"],["34949.5","0.001"],["34932.01","0"],["34934.43","0"]],"a":[["34962.87","0.00057"],["34964.7","0.106063"],["34966.73","0.051547"],["34971.99","0.0005"],["34976.84","0"],["34976.85","0"],["34957.99","0"]],"u":20009587,"seq":14108027797}}'
2023-11-02 14:54:11,496 DEBUG ++Rcv decoded: fin=1 opcode=1 data=b'{"topic":"orderbook.50.BTCUSDC","ts":1698936844023,"type":"delta","data":{"s":"BTCUSDC","b":[["34949.8","0.00057"],["34949.5","0.001"],["34932.01","0"],["34934.43","0"]],"a":[["34962.87","0.00057"],["34964.7","0.106063"],["34966.73","0.051547"],["34971.99","0.0005"],["34976.84","0"],["34976.85","0"],["34957.99","0"]],"u":20009587,"seq":14108027797}}'
2023-11-02 14:54:11,496 DEBUG ++Rcv raw: b'\x81~\x00\xae{"topic":"orderbook.50.BTCUSDC","ts":1698936844044,"type":"delta","data":{"s":"BTCUSDC","b":[["34945.69","0.014021"],["34935.13","0"]],"a":[],"u":20009588,"seq":14108027837}}'
2023-11-02 14:54:11,497 DEBUG ++Rcv decoded: fin=1 opcode=1 data=b'{"topic":"orderbook.50.BTCUSDC","ts":1698936844044,"type":"delta","data":{"s":"BTCUSDC","b":[["34945.69","0.014021"],["34935.13","0"]],"a":[],"u":20009588,"seq":14108027837}}'
2023-11-02 14:54:11,497 DEBUG ++Rcv raw: b'\x81~\x00\xd3{"topic":"orderbook.50.BTCUSDC","ts":1698936844127,"type":"delta","data":{"s":"BTCUSDC","b":[["34949","0.028607"],["34947.18","0"]],"a":[["34962.56","0.028607"],["34960.85","0"]],"u":20009589,"seq":14108027937}}'
2023-11-02 14:54:11,497 DEBUG ++Rcv decoded: fin=1 opcode=1 data=b'{"topic":"orderbook.50.BTCUSDC","ts":1698936844127,"type":"delta","data":{"s":"BTCUSDC","b":[["34949","0.028607"],["34947.18","0"]],"a":[["34962.56","0.028607"],["34960.85","0"]],"u":20009589,"seq":14108027937}}'
2023-11-02 14:54:11,497 DEBUG ++Rcv raw: b'\x81~\x00\xc2{"topic":"orderbook.50.BTCUSDC","ts":1698936844143,"type":"delta","data":{"s":"BTCUSDC","b":[["34936.36","0.157687"]],"a":[["34976.84","0.001"],["34961.39","0"]],"u":20009590,"seq":14108027943}}'
2023-11-02 14:54:11,497 DEBUG ++Rcv decoded: fin=1 opcode=1 data=b'{"topic":"orderbook.50.BTCUSDC","ts":1698936844143,"type":"delta","data":{"s":"BTCUSDC","b":[["34936.36","0.157687"]],"a":[["34976.84","0.001"],["34961.39","0"]],"u":20009590,"seq":14108027943}}'
2023-11-02 14:54:11,497 DEBUG ++Rcv raw: b'\x81~\x01i{"topic":"orderbook.50.BTCUSDC","ts":1698936844163,"type":"delta","data":{"s":"BTCUSDC","b":[["34957.63","0.08954"],["34954","0.0341"],["34952.98","0.0859"],["34935.14","0"],["34936.06","0"],["34936","0"]],"a":[["34976.85","0.05718"],["34977.23","0.1875"],["34978.28","0.001447"],["34960","0"],["34964.98","0"],["34957.98","0"]],"u":20009591,"seq":14108027995}}'
2023-11-02 14:54:11,498 DEBUG ++Rcv decoded: fin=1 opcode=1 data=b'{"topic":"orderbook.50.BTCUSDC","ts":1698936844163,"type":"delta","data":{"s":"BTCUSDC","b":[["34957.63","0.08954"],["34954","0.0341"],["34952.98","0.0859"],["34935.14","0"],["34936.06","0"],["34936","0"]],"a":[["34976.85","0.05718"],["34977.23","0.1875"],["34978.28","0.001447"],["34960","0"],["34964.98","0"],["34957.98","0"]],"u":20009591,"seq":14108027995}}'
2023-11-02 14:54:11,498 DEBUG ++Rcv raw: b'\x81~\x02i{"topic":"orderbook.50.BTCUSDC","ts":1698936844183,"type":"delta","data":{"s":"BTCUSDC","b":[["34957.64","0.0004"],["34953.27","0.034332"],["34951.27","0.051542"],["34949.55","0.051543"],["34947.69","0.1875"],["34936","0.0341"],["34945.38","0"],["34954.69","0"],["34949.8","0"],["34957.63","0"],["34953.26","0"]],"a":[["34964.7","0.051545"],["34978.69","0.171532"],["34978.9","0.002162"],["34979.79","0.02859"],["34980.89","0.317395"],["34980.9","0.528984"],["34981.28","0.000562"],["34968.25","0"],["34968.57","0"],["34962.87","0"],["34966.73","0"],["34959.86","0"],["34961.13","0"]],"u":20009592,"seq":14108028042}}'
2023-11-02 14:54:11,498 DEBUG ++Rcv decoded: fin=1 opcode=1 data=b'{"topic":"orderbook.50.BTCUSDC","ts":1698936844183,"type":"delta","data":{"s":"BTCUSDC","b":[["34957.64","0.0004"],["34953.27","0.034332"],["34951.27","0.051542"],["34949.55","0.051543"],["34947.69","0.1875"],["34936","0.0341"],["34945.38","0"],["34954.69","0"],["34949.8","0"],["34957.63","0"],["34953.26","0"]],"a":[["34964.7","0.051545"],["34978.69","0.171532"],["34978.9","0.002162"],["34979.79","0.02859"],["34980.89","0.317395"],["34980.9","0.528984"],["34981.28","0.000562"],["34968.25","0"],["34968.57","0"],["34962.87","0"],["34966.73","0"],["34959.86","0"],["34961.13","0"]],"u":20009592,"seq":14108028042}}'
2023-11-02 14:54:11,499 DEBUG ++Rcv raw: b'\x81~\x01\xe0{"topic":"orderbook.50.BTCUSDC","ts":1698936844203,"type":"delta","data":{"s":"BTCUSDC","b":[["34955.16","0.057216"],["34952.99","0.053344"],["34948.3","0.114454"],["34947.83","0.106061"],["34938.21","0.286219"],["34953.27","0"],["34936","0"],["34936.09","0"],["34951.27","0"]],"a":[["34961.56","0.008356"],["34961.57","0.051546"],["34962.92","0.057203"],["34970.81","0.114381"],["34963.99","0"],["34978.69","0"],["34981.28","0"],["34959.85","0"]],"u":20009593,"seq":14108028081}}'
2023-11-02 14:54:11,499 DEBUG ++Rcv decoded: fin=1 opcode=1 data=b'{"topic":"orderbook.50.BTCUSDC","ts":1698936844203,"type":"delta","data":{"s":"BTCUSDC","b":[["34955.16","0.057216"],["34952.99","0.053344"],["34948.3","0.114454"],["34947.83","0.106061"],["34938.21","0.286219"],["34953.27","0"],["34936","0"],["34936.09","0"],["34951.27","0"]],"a":[["34961.56","0.008356"],["34961.57","0.051546"],["34962.92","0.057203"],["34970.81","0.114381"],["34963.99","0"],["34978.69","0"],["34981.28","0"],["34959.85","0"]],"u":20009593,"seq":14108028081}}'
2023-11-02 14:54:11,635 DEBUG ++Rcv raw: b'\x81~\x01\x1a{"topic":"orderbook.50.BTCUSDC","ts":1698936844224,"type":"delta","data":{"s":"BTCUSDC","b":[["34956","0.0341"],["34952.75","0.00057"],["34936.1","0"],["34937.51","0"]],"a":[["34966.45","0.00057"],["34968.57","0.1875"],["34962","0"],["34980.9","0"]],"u":20009594,"seq":14108028109}}'
2023-11-02 14:54:11,635 DEBUG ++Rcv decoded: fin=1 opcode=1 data=b'{"topic":"orderbook.50.BTCUSDC","ts":1698936844224,"type":"delta","data":{"s":"BTCUSDC","b":[["34956","0.0341"],["34952.75","0.00057"],["34936.1","0"],["34937.51","0"]],"a":[["34966.45","0.00057"],["34968.57","0.1875"],["34962","0"],["34980.9","0"]],"u":20009594,"seq":14108028109}}'
2023-11-02 14:54:11,635 DEBUG ++Rcv raw: b'\x81~\x00\xcf{"topic":"orderbook.50.BTCUSDC","ts":1698936844243,"type":"delta","data":{"s":"BTCUSDC","b":[["34954.7","0.0859"],["34949","0"]],"a":[["34980.9","0.528984"],["34961.58","0"]],"u":20009595,"seq":14108028147}}'
2023-11-02 14:54:11,636 DEBUG ++Rcv decoded: fin=1 opcode=1 data=b'{"topic":"orderbook.50.BTCUSDC","ts":1698936844243,"type":"delta","data":{"s":"BTCUSDC","b":[["34954.7","0.0859"],["34949","0"]],"a":[["34980.9","0.528984"],["34961.58","0"]],"u":20009595,"seq":14108028147}}'
2023-11-02 14:54:11,636 DEBUG ++Rcv raw: b'\x81~\x01\xba{"topic":"orderbook.50.BTCUSDC","ts":1698936844263,"type":"delta","data":{"s":"BTCUSDC","b":[["34955.17","0.034336"],["34954.71","0.051548"],["34950.73","0.064606"],["34949.56","0.003561"],["34936.35","0"],["34948.02","0"],["34957.64","0"]],"a":[["34962.91","0.099568"],["34964.27","0.028606"],["34974.59","0.075313"],["34980.91","0.28587"],["34961.57","0"],["34968.57","0"],["34963.17","0"],["34962.56","0"]],"u":20009596,"seq":14108028196}}'
2023-11-02 14:54:11,636 DEBUG ++Rcv decoded: fin=1 opcode=1 data=b'{"topic":"orderbook.50.BTCUSDC","ts":1698936844263,"type":"delta","data":{"s":"BTCUSDC","b":[["34955.17","0.034336"],["34954.71","0.051548"],["34950.73","0.064606"],["34949.56","0.003561"],["34936.35","0"],["34948.02","0"],["34957.64","0"]],"a":[["34962.91","0.099568"],["34964.27","0.028606"],["34974.59","0.075313"],["34980.91","0.28587"],["34961.57","0"],["34968.57","0"],["34963.17","0"],["34962.56","0"]],"u":20009596,"seq":14108028196}}'
2023-11-02 14:54:11,636 DEBUG ++Rcv raw: b'\x81~\x00\xc2{"topic":"orderbook.50.BTCUSDC","ts":1698936844284,"type":"delta","data":{"s":"BTCUSDC","b":[["34936.35","0.1875"],["34949.5","0"]],"a":[["34961.56","0.010156"]],"u":20009597,"seq":14108028225}}'
2023-11-02 14:54:11,636 DEBUG ++Rcv decoded: fin=1 opcode=1 data=b'{"topic":"orderbook.50.BTCUSDC","ts":1698936844284,"type":"delta","data":{"s":"BTCUSDC","b":[["34936.35","0.1875"],["34949.5","0"]],"a":[["34961.56","0.010156"]],"u":20009597,"seq":14108028225}}'
2023-11-02 14:54:11,637 DEBUG ++Rcv raw: b'\x81~\x00\xd3{"topic":"orderbook.50.BTCUSDC","ts":1698936844303,"type":"delta","data":{"s":"BTCUSDC","b":[["34956.01","0.0002"],["34936.35","0"]],"a":[["34981.28","0.000562"],["34967.7","0"]],"u":20009598,"seq":14108028259}}'
2023-11-02 14:54:11,637 DEBUG ++Rcv decoded: fin=1 opcode=1 data=b'{"topic":"orderbook.50.BTCUSDC","ts":1698936844303,"type":"delta","data":{"s":"BTCUSDC","b":[["34956.01","0.0002"],["34936.35","0"]],"a":[["34981.28","0.000562"],["34967.7","0"]],"u":20009598,"seq":14108028259}}'
2023-11-02 14:54:11,637 DEBUG ++Rcv raw: b'\x81~\x019{"topic":"orderbook.50.BTCUSDC","ts":1698936844324,"type":"delta","data":{"s":"BTCUSDC","b":[["34950.8","0.001"],["34936.36","0"]],"a":[["34961.56","0.008156"],["34967.68","0.357065"],["34968.18","0.05154"],["34968.56","0.1875"],["34981.28","0"],["34967.69","0"],["34980.91","0"]],"u":20009599,"seq":14108028306}}'
2023-11-02 14:54:11,637 DEBUG ++Rcv decoded: fin=1 opcode=1 data=b'{"topic":"orderbook.50.BTCUSDC","ts":1698936844324,"type":"delta","data":{"s":"BTCUSDC","b":[["34950.8","0.001"],["34936.36","0"]],"a":[["34961.56","0.008156"],["34967.68","0.357065"],["34968.18","0.05154"],["34968.56","0.1875"],["34981.28","0"],["34967.69","0"],["34980.91","0"]],"u":20009599,"seq":14108028306}}'
2023-11-02 14:54:11,638 DEBUG ++Rcv raw: b'\x81~\x00\xd4{"topic":"orderbook.50.BTCUSDC","ts":1698936844343,"type":"delta","data":{"s":"BTCUSDC","b":[["34936.36","0.112508"],["34937.5","0"]],"a":[["34967.67","0.21424"],["34968.18","0"]],"u":20009600,"seq":14108028331}}'
2023-11-02 14:54:11,639 DEBUG ++Rcv decoded: fin=1 opcode=1 data=b'{"topic":"orderbook.50.BTCUSDC","ts":1698936844343,"type":"delta","data":{"s":"BTCUSDC","b":[["34936.36","0.112508"],["34937.5","0"]],"a":[["34967.67","0.21424"],["34968.18","0"]],"u":20009600,"seq":14108028331}}'
2023-11-02 14:54:11,639 DEBUG ++Rcv raw: b'\x81~\x00\xac{"topic":"orderbook.50.BTCUSDC","ts":1698936844364,"type":"delta","data":{"s":"BTCUSDC","b":[["34936.35","0.1875"],["34936.36","0"]],"a":[],"u":20009601,"seq":14108028350}}'
2023-11-02 14:54:11,639 DEBUG ++Rcv decoded: fin=1 opcode=1 data=b'{"topic":"orderbook.50.BTCUSDC","ts":1698936844364,"type":"delta","data":{"s":"BTCUSDC","b":[["34936.35","0.1875"],["34936.36","0"]],"a":[],"u":20009601,"seq":14108028350}}'
2023-11-02 14:54:11,640 DEBUG ++Rcv raw: b'\x81~\x01&{"topic":"orderbook.50.BTCUSDC","ts":1698936844384,"type":"delta","data":{"s":"BTCUSDC","b":[["34954.57","0.057217"],["34955.16","0"]],"a":[["34962.4","0.057204"],["34969.61","0.114385"],["34979.78","0.285879"],["34962.92","0"],["34980.9","0"],["34970.81","0"]],"u":20009602,"seq":14108028389}}'
2023-11-02 14:54:11,640 DEBUG ++Rcv decoded: fin=1 opcode=1 data=b'{"topic":"orderbook.50.BTCUSDC","ts":1698936844384,"type":"delta","data":{"s":"BTCUSDC","b":[["34954.57","0.057217"],["34955.16","0"]],"a":[["34962.4","0.057204"],["34969.61","0.114385"],["34979.78","0.285879"],["34962.92","0"],["34980.9","0"],["34970.81","0"]],"u":20009602,"seq":14108028389}}'
2023-11-02 14:54:11,640 DEBUG ++Rcv raw: b'\x81~\x01\x05{"topic":"orderbook.50.BTCUSDC","ts":1698936844403,"type":"delta","data":{"s":"BTCUSDC","b":[["34957.64","0.01144"],["34954.71","0.079429"],["34951.27","0.051543"],["34955.17","0"],["34952.99","0"]],"a":[["34962.91","0.065241"]],"u":20009603,"seq":14108028415}}'
2023-11-02 14:54:11,640 DEBUG ++Rcv decoded: fin=1 opcode=1 data=b'{"topic":"orderbook.50.BTCUSDC","ts":1698936844403,"type":"delta","data":{"s":"BTCUSDC","b":[["34957.64","0.01144"],["34954.71","0.079429"],["34951.27","0.051543"],["34955.17","0"],["34952.99","0"]],"a":[["34962.91","0.065241"]],"u":20009603,"seq":14108028415}}'
2023-11-02 14:54:11,641 DEBUG ++Rcv raw: b'\x81~\x01D{"topic":"orderbook.50.BTCUSDC","ts":1698936844424,"type":"delta","data":{"s":"BTCUSDC","b":[["34957.65","0.0002"],["34936.1","0.028"],["34936","0.0341"],["34956.01","0"],["34938.21","0"],["34948.3","0"]],"a":[["34959.07","0.000053"],["34980.9","0.528984"],["34963.84","0"],["34968.56","0"]],"u":20009604,"seq":14108028453}}'
2023-11-02 14:54:11,641 DEBUG ++Rcv decoded: fin=1 opcode=1 data=b'{"topic":"orderbook.50.BTCUSDC","ts":1698936844424,"type":"delta","data":{"s":"BTCUSDC","b":[["34957.65","0.0002"],["34936.1","0.028"],["34936","0.0341"],["34956.01","0"],["34938.21","0"],["34948.3","0"]],"a":[["34959.07","0.000053"],["34980.9","0.528984"],["34963.84","0"],["34968.56","0"]],"u":20009604,"seq":14108028453}}'
2023-11-02 14:54:11,641 DEBUG ++Rcv raw: b'\x81~\x01]{"topic":"orderbook.50.BTCUSDC","ts":1698936844444,"type":"delta","data":{"s":"BTCUSDC","b":[["34950.73","0.036"],["34947","0.114459"],["34936.95","0.286229"],["34936.1","0"],["34936","0"]],"a":[["34981.28","0.000562"],["34981.81","0.094142"],["34983.74","0.1875"],["34964.27","0"],["34969.88","0"],["34967.68","0"]],"u":20009605,"seq":14108028472}}'
2023-11-02 14:54:11,641 DEBUG ++Rcv decoded: fin=1 opcode=1 data=b'{"topic":"orderbook.50.BTCUSDC","ts":1698936844444,"type":"delta","data":{"s":"BTCUSDC","b":[["34950.73","0.036"],["34947","0.114459"],["34936.95","0.286229"],["34936.1","0"],["34936","0"]],"a":[["34981.28","0.000562"],["34981.81","0.094142"],["34983.74","0.1875"],["34964.27","0"],["34969.88","0"],["34967.68","0"]],"u":20009605,"seq":14108028472}}'
2023-11-02 14:54:11,641 DEBUG ++Rcv raw: b'\x81~\x01\'{"topic":"orderbook.50.BTCUSDC","ts":1698936844464,"type":"delta","data":{"s":"BTCUSDC","b":[],"a":[["34965.96","0.028604"],["34966.73","0.051545"],["34968.18","0.051546"],["34971.38","0.000239"],["34967.67","0"],["34962.4","0"],["34983.74","0"],["34964.7","0"]],"u":20009606,"seq":14108028487}}'
2023-11-02 14:54:11,642 DEBUG ++Rcv decoded: fin=1 opcode=1 data=b'{"topic":"orderbook.50.BTCUSDC","ts":1698936844464,"type":"delta","data":{"s":"BTCUSDC","b":[],"a":[["34965.96","0.028604"],["34966.73","0.051545"],["34968.18","0.051546"],["34971.38","0.000239"],["34967.67","0"],["34962.4","0"],["34983.74","0"],["34964.7","0"]],"u":20009606,"seq":14108028487}}'
2023-11-02 14:54:11,642 DEBUG ++Rcv raw: b'\x81~\x00\xaa{"topic":"orderbook.50.BTCUSDC","ts":1698936844484,"type":"delta","data":{"s":"BTCUSDC","b":[["34936.1","0.028"],["34954.57","0"]],"a":[],"u":20009607,"seq":14108028490}}'
2023-11-02 14:54:11,642 DEBUG ++Rcv decoded: fin=1 opcode=1 data=b'{"topic":"orderbook.50.BTCUSDC","ts":1698936844484,"type":"delta","data":{"s":"BTCUSDC","b":[["34936.1","0.028"],["34954.57","0"]],"a":[],"u":20009607,"seq":14108028490}}'
2023-11-02 14:54:11,642 DEBUG ++Rcv raw: b'\x81~\x01<{"topic":"orderbook.50.BTCUSDC","ts":1698936844504,"type":"delta","data":{"s":"BTCUSDC","b":[["34954.71","0.051548"],["34953.96","0.057218"],["34957.64","0"]],"a":[["34961.78","0.057205"],["34983.74","0.1875"],["34984.83","0.0002"],["34961.56","0"],["34959.07","0"],["34976.84","0"]],"u":20009608,"seq":14108028502}}'
2023-11-02 14:54:11,642 DEBUG ++Rcv decoded: fin=1 opcode=1 data=b'{"topic":"orderbook.50.BTCUSDC","ts":1698936844504,"type":"delta","data":{"s":"BTCUSDC","b":[["34954.71","0.051548"],["34953.96","0.057218"],["34957.64","0"]],"a":[["34961.78","0.057205"],["34983.74","0.1875"],["34984.83","0.0002"],["34961.56","0"],["34959.07","0"],["34976.84","0"]],"u":20009608,"seq":14108028502}}'
2023-11-02 14:54:11,642 DEBUG ++Rcv raw: b'\x81~\x00\xfe{"topic":"orderbook.50.BTCUSDC","ts":1698936844523,"type":"delta","data":{"s":"BTCUSDC","b":[],"a":[["34961.76","0.060055"],["34961.77","0.008556"],["34969.6","0.06864"],["34981.81","0"],["34984.83","0"],["34983.74","0"]],"u":20009609,"seq":14108028514}}'
2023-11-02 14:54:11,643 DEBUG ++Rcv decoded: fin=1 opcode=1 data=b'{"topic":"orderbook.50.BTCUSDC","ts":1698936844523,"type":"delta","data":{"s":"BTCUSDC","b":[],"a":[["34961.76","0.060055"],["34961.77","0.008556"],["34969.6","0.06864"],["34981.81","0"],["34984.83","0"],["34983.74","0"]],"u":20009609,"seq":14108028514}}'
2023-11-02 14:54:11,643 DEBUG ++Rcv raw: b'\x81~\x00\xed{"topic":"orderbook.50.BTCUSDC","ts":1698936844544,"type":"delta","data":{"s":"BTCUSDC","b":[],"a":[["34961.58","0.0859"],["34961.75","0.008556"],["34961.76","0.039457"],["34961.77","0"],["34981.28","0"]],"u":20009610,"seq":14108028529}}'
2023-11-02 14:54:11,643 DEBUG ++Rcv decoded: fin=1 opcode=1 data=b'{"topic":"orderbook.50.BTCUSDC","ts":1698936844544,"type":"delta","data":{"s":"BTCUSDC","b":[],"a":[["34961.58","0.0859"],["34961.75","0.008556"],["34961.76","0.039457"],["34961.77","0"],["34981.28","0"]],"u":20009610,"seq":14108028529}}'
2023-11-02 14:54:11,643 DEBUG ++Rcv raw: b'\x81~\x01N{"topic":"orderbook.50.BTCUSDC","ts":1698936844564,"type":"delta","data":{"s":"BTCUSDC","b":[["34948.02","0.003561"],["34936.1","0"]],"a":[["34961.57","0.096133"],["34965.01","0.051544"],["34968.75","0.1875"],["34981.28","0.000562"],["34961.76","0"],["34961.58","0"],["34962.91","0"],["34961.78","0"]],"u":20009611,"seq":14108028552}}'
2023-11-02 14:54:11,643 DEBUG ++Rcv decoded: fin=1 opcode=1 data=b'{"topic":"orderbook.50.BTCUSDC","ts":1698936844564,"type":"delta","data":{"s":"BTCUSDC","b":[["34948.02","0.003561"],["34936.1","0"]],"a":[["34961.57","0.096133"],["34965.01","0.051544"],["34968.75","0.1875"],["34981.28","0.000562"],["34961.76","0"],["34961.58","0"],["34962.91","0"],["34961.78","0"]],"u":20009611,"seq":14108028552}}'
2023-11-02 14:54:11,644 DEBUG ++Rcv raw: b'\x81~\x01c{"topic":"orderbook.50.BTCUSDC","ts":1698936844584,"type":"delta","data":{"s":"BTCUSDC","b":[["34936.1","0.028"],["34949.56","0"]],"a":[["34963.17","0.065242"],["34968.18","0.106063"],["34978.66","0.285888"],["34981.81","0.094142"],["34983.74","0.1875"],["34979.78","0"],["34965.01","0"],["34961.57","0"],["34968.75","0"]],"u":20009612,"seq":14108028567}}'
2023-11-02 14:54:11,644 DEBUG ++Rcv decoded: fin=1 opcode=1 data=b'{"topic":"orderbook.50.BTCUSDC","ts":1698936844584,"type":"delta","data":{"s":"BTCUSDC","b":[["34936.1","0.028"],["34949.56","0"]],"a":[["34963.17","0.065242"],["34968.18","0.106063"],["34978.66","0.285888"],["34981.81","0.094142"],["34983.74","0.1875"],["34979.78","0"],["34965.01","0"],["34961.57","0"],["34968.75","0"]],"u":20009612,"seq":14108028567}}'
2023-11-02 14:54:11,644 DEBUG ++Rcv raw: b'\x81~\x00\xc3{"topic":"orderbook.50.BTCUSDC","ts":1698936844604,"type":"delta","data":{"s":"BTCUSDC","b":[["34957.66","0.01144"],["34936.1","0"]],"a":[["34968.18","0.051546"]],"u":20009613,"seq":14108028580}}'
2023-11-02 14:54:11,644 DEBUG ++Rcv decoded: fin=1 opcode=1 data=b'{"topic":"orderbook.50.BTCUSDC","ts":1698936844604,"type":"delta","data":{"s":"BTCUSDC","b":[["34957.66","0.01144"],["34936.1","0"]],"a":[["34968.18","0.051546"]],"u":20009613,"seq":14108028580}}'
2023-11-02 14:54:11,644 DEBUG ++Rcv raw: b'\x81~\x00\xf6{"topic":"orderbook.50.BTCUSDC","ts":1698936844623,"type":"delta","data":{"s":"BTCUSDC","b":[["34936.1","0.028"],["34936","0.0341"],["34957.66","0"],["34957.65","0"]],"a":[["34967.72","0.357869"],["34983.74","0"]],"u":20009614,"seq":14108028585}}'
2023-11-02 14:54:11,644 DEBUG ++Rcv decoded: fin=1 opcode=1 data=b'{"topic":"orderbook.50.BTCUSDC","ts":1698936844623,"type":"delta","data":{"s":"BTCUSDC","b":[["34936.1","0.028"],["34936","0.0341"],["34957.66","0"],["34957.65","0"]],"a":[["34967.72","0.357869"],["34983.74","0"]],"u":20009614,"seq":14108028585}}'
2023-11-02 14:54:11,645 DEBUG ++Rcv raw: b'\x81~\x01q{"topic":"orderbook.50.BTCUSDC","ts":1698936844643,"type":"delta","data":{"s":"BTCUSDC","b":[["34956.01","0.0002"],["34936","0"]],"a":[["34961.52","0.057205"],["34967.71","0.214728"],["34968.48","0.114388"],["34968.75","0.1875"],["34972.9","0.000239"],["34980.9","0"],["34981.28","0"],["34981.81","0"],["34969.61","0"],["34968.18","0"]],"u":20009615,"seq":14108028596}}'
2023-11-02 14:54:11,645 DEBUG ++Rcv decoded: fin=1 opcode=1 data=b'{"topic":"orderbook.50.BTCUSDC","ts":1698936844643,"type":"delta","data":{"s":"BTCUSDC","b":[["34956.01","0.0002"],["34936","0"]],"a":[["34961.52","0.057205"],["34967.71","0.214728"],["34968.48","0.114388"],["34968.75","0.1875"],["34972.9","0.000239"],["34980.9","0"],["34981.28","0"],["34981.81","0"],["34969.61","0"],["34968.18","0"]],"u":20009615,"seq":14108028596}}'
2023-11-02 14:54:11,645 DEBUG ++Rcv raw: b'\x81~\x00\xae{"topic":"orderbook.50.BTCUSDC","ts":1698936844664,"type":"delta","data":{"s":"BTCUSDC","b":[],"a":[["34961.51","0.039464"],["34980.89","0"]],"u":20009616,"seq":14108028599}}'
2023-11-02 14:54:11,645 DEBUG ++Rcv decoded: fin=1 opcode=1 data=b'{"topic":"orderbook.50.BTCUSDC","ts":1698936844664,"type":"delta","data":{"s":"BTCUSDC","b":[],"a":[["34961.51","0.039464"],["34980.89","0"]],"u":20009616,"seq":14108028599}}'
2023-11-02 14:54:11,646 DEBUG ++Rcv raw: b'\x81~\x00\xf8{"topic":"orderbook.50.BTCUSDC","ts":1698936844684,"type":"delta","data":{"s":"BTCUSDC","b":[["34936","0.0341"],["34936.1","0"]],"a":[["34961.5","0.008756"],["34980.89","0.317395"],["34961.52","0"],["34961.75","0"]],"u":20009617,"seq":14108028612}}'
2023-11-02 14:54:11,646 DEBUG ++Rcv decoded: fin=1 opcode=1 data=b'{"topic":"orderbook.50.BTCUSDC","ts":1698936844684,"type":"delta","data":{"s":"BTCUSDC","b":[["34936","0.0341"],["34936.1","0"]],"a":[["34961.5","0.008756"],["34980.89","0.317395"],["34961.52","0"],["34961.75","0"]],"u":20009617,"seq":14108028612}}'
2023-11-02 14:54:11,646 DEBUG ++Rcv raw: b'\x81~\x00\xad{"topic":"orderbook.50.BTCUSDC","ts":1698936844704,"type":"delta","data":{"s":"BTCUSDC","b":[],"a":[["34980.9","0.528984"],["34961.51","0"]],"u":20009618,"seq":14108028618}}'
2023-11-02 14:54:11,646 DEBUG ++Rcv decoded: fin=1 opcode=1 data=b'{"topic":"orderbook.50.BTCUSDC","ts":1698936844704,"type":"delta","data":{"s":"BTCUSDC","b":[],"a":[["34980.9","0.528984"],["34961.51","0"]],"u":20009618,"seq":14108028618}}'
2023-11-02 14:54:11,646 DEBUG ++Rcv raw: b'\x81~\x00\xae{"topic":"orderbook.50.BTCUSDC","ts":1698936844724,"type":"delta","data":{"s":"BTCUSDC","b":[],"a":[["34981.28","0.000562"],["34971.99","0"]],"u":20009619,"seq":14108028621}}'
2023-11-02 14:54:11,647 DEBUG ++Rcv decoded: fin=1 opcode=1 data=b'{"topic":"orderbook.50.BTCUSDC","ts":1698936844724,"type":"delta","data":{"s":"BTCUSDC","b":[],"a":[["34981.28","0.000562"],["34971.99","0"]],"u":20009619,"seq":14108028621}}'
2023-11-02 14:54:11,647 DEBUG ++Rcv raw: b'\x81~\x00\xae{"topic":"orderbook.50.BTCUSDC","ts":1698936844763,"type":"delta","data":{"s":"BTCUSDC","b":[["34935.14","0.823909"],["34953.96","0"]],"a":[],"u":20009620,"seq":14108028633}}'
2023-11-02 14:54:11,647 DEBUG ++Rcv decoded: fin=1 opcode=1 data=b'{"topic":"orderbook.50.BTCUSDC","ts":1698936844763,"type":"delta","data":{"s":"BTCUSDC","b":[["34935.14","0.823909"],["34953.96","0"]],"a":[],"u":20009620,"seq":14108028633}}'
2023-11-02 14:54:11,647 DEBUG ++Rcv raw: b'\x81~\x00\xfe{"topic":"orderbook.50.BTCUSDC","ts":1698936844783,"type":"delta","data":{"s":"BTCUSDC","b":[["34953.43","0.057218"],["34935.14","0"]],"a":[["34961.15","0.048342"],["34961.16","0.057206"],["34961.5","0"],["34981.28","0"]],"u":20009621,"seq":14108028649}}'
2023-11-02 14:54:11,647 DEBUG ++Rcv decoded: fin=1 opcode=1 data=b'{"topic":"orderbook.50.BTCUSDC","ts":1698936844783,"type":"delta","data":{"s":"BTCUSDC","b":[["34953.43","0.057218"],["34935.14","0"]],"a":[["34961.15","0.048342"],["34961.16","0.057206"],["34961.5","0"],["34981.28","0"]],"u":20009621,"seq":14108028649}}'
2023-11-02 14:54:11,647 DEBUG ++Rcv raw: b'\x81~\x01\x12{"topic":"orderbook.50.BTCUSDC","ts":1698936844803,"type":"delta","data":{"s":"BTCUSDC","b":[["34935.14","0.823909"],["34947.69","0"]],"a":[["34961.14","0.068582"],["34961.15","0.008756"],["34969.06","0.03"],["34980.9","0"],["34961.16","0"]],"u":20009622,"seq":14108028665}}'
2023-11-02 14:54:11,647 DEBUG ++Rcv decoded: fin=1 opcode=1 data=b'{"topic":"orderbook.50.BTCUSDC","ts":1698936844803,"type":"delta","data":{"s":"BTCUSDC","b":[["34935.14","0.823909"],["34947.69","0"]],"a":[["34961.14","0.068582"],["34961.15","0.008756"],["34969.06","0.03"],["34980.9","0"],["34961.16","0"]],"u":20009622,"seq":14108028665}}'
2023-11-02 14:54:11,648 DEBUG ++Rcv raw: b'\x81~\x00\xc3{"topic":"orderbook.50.BTCUSDC","ts":1698936844823,"type":"delta","data":{"s":"BTCUSDC","b":[["34947.83","0.051549"]],"a":[["34975.34","0.0859"],["34961.14","0"]],"u":20009623,"seq":14108028685}}'
2023-11-02 14:54:11,648 DEBUG ++Rcv decoded: fin=1 opcode=1 data=b'{"topic":"orderbook.50.BTCUSDC","ts":1698936844823,"type":"delta","data":{"s":"BTCUSDC","b":[["34947.83","0.051549"]],"a":[["34975.34","0.0859"],["34961.14","0"]],"u":20009623,"seq":14108028685}}'
2023-11-02 14:54:11,648 DEBUG ++Rcv raw: b'\x81~\x00\xad{"topic":"orderbook.50.BTCUSDC","ts":1698936844843,"type":"delta","data":{"s":"BTCUSDC","b":[],"a":[["34980.9","0.528984"],["34971.38","0"]],"u":20009624,"seq":14108028693}}'
2023-11-02 14:54:11,648 DEBUG ++Rcv decoded: fin=1 opcode=1 data=b'{"topic":"orderbook.50.BTCUSDC","ts":1698936844843,"type":"delta","data":{"s":"BTCUSDC","b":[],"a":[["34980.9","0.528984"],["34971.38","0"]],"u":20009624,"seq":14108028693}}'
2023-11-02 14:54:11,648 DEBUG ++Rcv raw: b'\x81~\x00\xab{"topic":"orderbook.50.BTCUSDC","ts":1698936844863,"type":"delta","data":{"s":"BTCUSDC","b":[["34946.11","0.028"],["34935.14","0"]],"a":[],"u":20009625,"seq":14108028705}}'
2023-11-02 14:54:11,648 DEBUG ++Rcv decoded: fin=1 opcode=1 data=b'{"topic":"orderbook.50.BTCUSDC","ts":1698936844863,"type":"delta","data":{"s":"BTCUSDC","b":[["34946.11","0.028"],["34935.14","0"]],"a":[],"u":20009625,"seq":14108028705}}'
2023-11-02 14:54:11,649 DEBUG ++Rcv raw: b'\x81~\x00\xab{"topic":"orderbook.50.BTCUSDC","ts":1698936844923,"type":"delta","data":{"s":"BTCUSDC","b":[],"a":[["34978.69","0.0005"],["34980.9","0"]],"u":20009626,"seq":14108028747}}'
2023-11-02 14:54:11,649 DEBUG ++Rcv decoded: fin=1 opcode=1 data=b'{"topic":"orderbook.50.BTCUSDC","ts":1698936844923,"type":"delta","data":{"s":"BTCUSDC","b":[],"a":[["34978.69","0.0005"],["34980.9","0"]],"u":20009626,"seq":14108028747}}'
2023-11-02 14:54:11,649 DEBUG ++Rcv raw: b'\x81~\x00\xc2{"topic":"orderbook.50.BTCUSDC","ts":1698936844944,"type":"delta","data":{"s":"BTCUSDC","b":[["34956.02","0.053806"],["34936","0"]],"a":[["34961.15","0.008556"]],"u":20009627,"seq":14108028762}}'
2023-11-02 14:54:11,649 DEBUG ++Rcv decoded: fin=1 opcode=1 data=b'{"topic":"orderbook.50.BTCUSDC","ts":1698936844944,"type":"delta","data":{"s":"BTCUSDC","b":[["34956.02","0.053806"],["34936","0"]],"a":[["34961.15","0.008556"]],"u":20009627,"seq":14108028762}}'
2023-11-02 14:54:11,649 DEBUG ++Rcv raw: b'\x81~\x00\xf8{"topic":"orderbook.50.BTCUSDC","ts":1698936844964,"type":"delta","data":{"s":"BTCUSDC","b":[["34956.03","0.0002"],["34936","0.0341"],["34935.14","0.823909"],["34950.8","0"],["34956.01","0"],["34956.02","0"]],"a":[],"u":20009628,"seq":14108028778}}'
2023-11-02 14:54:11,649 DEBUG ++Rcv decoded: fin=1 opcode=1 data=b'{"topic":"orderbook.50.BTCUSDC","ts":1698936844964,"type":"delta","data":{"s":"BTCUSDC","b":[["34956.03","0.0002"],["34936","0.0341"],["34935.14","0.823909"],["34950.8","0"],["34956.01","0"],["34956.02","0"]],"a":[],"u":20009628,"seq":14108028778}}'
2023-11-02 14:54:11,650 DEBUG ++Rcv raw: b'\x81~\x00\xac{"topic":"orderbook.50.BTCUSDC","ts":1698936845004,"type":"delta","data":{"s":"BTCUSDC","b":[],"a":[["34980.9","0.528984"],["34972.9","0"]],"u":20009629,"seq":14108028807}}'
2023-11-02 14:54:11,650 DEBUG ++Rcv decoded: fin=1 opcode=1 data=b'{"topic":"orderbook.50.BTCUSDC","ts":1698936845004,"type":"delta","data":{"s":"BTCUSDC","b":[],"a":[["34980.9","0.528984"],["34972.9","0"]],"u":20009629,"seq":14108028807}}'
2023-11-02 14:54:11,650 DEBUG ++Rcv raw: b'\x81~\x00\xae{"topic":"orderbook.50.BTCUSDC","ts":1698936845064,"type":"delta","data":{"s":"BTCUSDC","b":[["34935.13","1.373172"],["34952.69","0"]],"a":[],"u":20009630,"seq":14108028832}}'
2023-11-02 14:54:11,650 DEBUG ++Rcv decoded: fin=1 opcode=1 data=b'{"topic":"orderbook.50.BTCUSDC","ts":1698936845064,"type":"delta","data":{"s":"BTCUSDC","b":[["34935.13","1.373172"],["34952.69","0"]],"a":[],"u":20009630,"seq":14108028832}}'
2023-11-02 14:54:11,651 DEBUG ++Rcv raw: b'\x81~\x00\xae{"topic":"orderbook.50.BTCUSDC","ts":1698936845084,"type":"delta","data":{"s":"BTCUSDC","b":[],"a":[["34981.28","0.000562"],["34961.15","0"]],"u":20009631,"seq":14108028845}}'
2023-11-02 14:54:11,651 DEBUG ++Rcv decoded: fin=1 opcode=1 data=b'{"topic":"orderbook.50.BTCUSDC","ts":1698936845084,"type":"delta","data":{"s":"BTCUSDC","b":[],"a":[["34981.28","0.000562"],["34961.15","0"]],"u":20009631,"seq":14108028845}}'
2023-11-02 14:54:11,651 DEBUG ++Rcv raw: b'\x81~\x00\x9d{"topic":"orderbook.50.BTCUSDC","ts":1698936845103,"type":"delta","data":{"s":"BTCUSDC","b":[],"a":[["34963.17","0.091262"]],"u":20009632,"seq":14108028857}}'
2023-11-02 14:54:11,652 DEBUG ++Rcv decoded: fin=1 opcode=1 data=b'{"topic":"orderbook.50.BTCUSDC","ts":1698936845103,"type":"delta","data":{"s":"BTCUSDC","b":[],"a":[["34963.17","0.091262"]],"u":20009632,"seq":14108028857}}'
2023-11-02 14:54:11,652 DEBUG ++Rcv raw: b'\x81~\x00\xc4{"topic":"orderbook.50.BTCUSDC","ts":1698936845123,"type":"delta","data":{"s":"BTCUSDC","b":[["34956.03","0.0032"],["34935.63","0.207183"],["34935.13","0"]],"a":[],"u":20009633,"seq":14108028873}}'
2023-11-02 14:54:11,652 DEBUG ++Rcv decoded: fin=1 opcode=1 data=b'{"topic":"orderbook.50.BTCUSDC","ts":1698936845123,"type":"delta","data":{"s":"BTCUSDC","b":[["34956.03","0.0032"],["34935.63","0.207183"],["34935.13","0"]],"a":[],"u":20009633,"seq":14108028873}}'
2023-11-02 14:54:11,652 DEBUG ++Rcv raw: b'\x81~\x00\xae{"topic":"orderbook.50.BTCUSDC","ts":1698936845144,"type":"delta","data":{"s":"BTCUSDC","b":[],"a":[["34963.16","0.008556"],["34981.28","0"]],"u":20009634,"seq":14108028881}}'
2023-11-02 14:54:11,652 DEBUG ++Rcv decoded: fin=1 opcode=1 data=b'{"topic":"orderbook.50.BTCUSDC","ts":1698936845144,"type":"delta","data":{"s":"BTCUSDC","b":[],"a":[["34963.16","0.008556"],["34981.28","0"]],"u":20009634,"seq":14108028881}}'
2023-11-02 14:54:11,652 DEBUG ++Rcv raw: b'\x81~\x00\xd5{"topic":"orderbook.50.BTCUSDC","ts":1698936845163,"type":"delta","data":{"s":"BTCUSDC","b":[["34947.01","0.002204"],["34948.02","0"]],"a":[["34978.65","0.171534"],["34980.9","0"]],"u":20009635,"seq":14108028897}}'
2023-11-02 14:54:11,653 DEBUG ++Rcv decoded: fin=1 opcode=1 data=b'{"topic":"orderbook.50.BTCUSDC","ts":1698936845163,"type":"delta","data":{"s":"BTCUSDC","b":[["34947.01","0.002204"],["34948.02","0"]],"a":[["34978.65","0.171534"],["34980.9","0"]],"u":20009635,"seq":14108028897}}'
2023-11-02 14:54:11,653 DEBUG ++Rcv raw: b'\x81~\x01\x17{"topic":"orderbook.50.BTCUSDC","ts":1698936845304,"type":"delta","data":{"s":"BTCUSDC","b":[["34956.04","0.053806"],["34935.14","0"]],"a":[["34961.08","0.057206"],["34963.16","0.008356"],["34977.57","0.285897"],["34978.66","0"],["34980.89","0"]],"u":20009636,"seq":14108028973}}'
2023-11-02 14:54:11,653 DEBUG ++Rcv decoded: fin=1 opcode=1 data=b'{"topic":"orderbook.50.BTCUSDC","ts":1698936845304,"type":"delta","data":{"s":"BTCUSDC","b":[["34956.04","0.053806"],["34935.14","0"]],"a":[["34961.08","0.057206"],["34963.16","0.008356"],["34977.57","0.285897"],["34978.66","0"],["34980.89","0"]],"u":20009636,"seq":14108028973}}'
2023-11-02 14:54:11,653 DEBUG ++Rcv raw: b'\x81~\x00\xe9{"topic":"orderbook.50.BTCUSDC","ts":1698936845324,"type":"delta","data":{"s":"BTCUSDC","b":[["34950","0.0351"],["34935.14","0.823909"],["34956.04","0"]],"a":[["34961.07","0.034326"],["34978.65","0"]],"u":20009637,"seq":14108028982}}'
2023-11-02 14:54:11,653 DEBUG ++Rcv decoded: fin=1 opcode=1 data=b'{"topic":"orderbook.50.BTCUSDC","ts":1698936845324,"type":"delta","data":{"s":"BTCUSDC","b":[["34950","0.0351"],["34935.14","0.823909"],["34956.04","0"]],"a":[["34961.07","0.034326"],["34978.65","0"]],"u":20009637,"seq":14108028982}}'
2023-11-02 14:54:11,653 DEBUG ++Rcv raw: b'\x81~\x00\xc3{"topic":"orderbook.50.BTCUSDC","ts":1698936845344,"type":"delta","data":{"s":"BTCUSDC","b":[["34956.03","0.0002"]],"a":[["34980.89","0.317395"],["34961.08","0"]],"u":20009638,"seq":14108028989}}'
2023-11-02 14:54:11,654 DEBUG ++Rcv decoded: fin=1 opcode=1 data=b'{"topic":"orderbook.50.BTCUSDC","ts":1698936845344,"type":"delta","data":{"s":"BTCUSDC","b":[["34956.03","0.0002"]],"a":[["34980.89","0.317395"],["34961.08","0"]],"u":20009638,"seq":14108028989}}'
2023-11-02 14:54:11,654 DEBUG ++Rcv raw: b'\x81~\x00\xfe{"topic":"orderbook.50.BTCUSDC","ts":1698936845363,"type":"delta","data":{"s":"BTCUSDC","b":[["34935.13","1.373172"],["34956.03","0"]],"a":[["34961.06","0.008356"],["34980.9","0.528984"],["34963.16","0"],["34961.07","0"]],"u":20009639,"seq":14108028995}}'
2023-11-02 14:54:11,654 DEBUG ++Rcv decoded: fin=1 opcode=1 data=b'{"topic":"orderbook.50.BTCUSDC","ts":1698936845363,"type":"delta","data":{"s":"BTCUSDC","b":[["34935.13","1.373172"],["34956.03","0"]],"a":[["34961.06","0.008356"],["34980.9","0.528984"],["34963.16","0"],["34961.07","0"]],"u":20009639,"seq":14108028995}}'
2023-11-02 14:54:11,655 DEBUG ++Rcv raw: b'\x81~\x00\xac{"topic":"orderbook.50.BTCUSDC","ts":1698936845383,"type":"delta","data":{"s":"BTCUSDC","b":[["34956.01","0.0004"],["34935.13","0"]],"a":[],"u":20009640,"seq":14108029002}}'
2023-11-02 14:54:11,655 DEBUG ++Rcv decoded: fin=1 opcode=1 data=b'{"topic":"orderbook.50.BTCUSDC","ts":1698936845383,"type":"delta","data":{"s":"BTCUSDC","b":[["34956.01","0.0004"],["34935.13","0"]],"a":[],"u":20009640,"seq":14108029002}}'
2023-11-02 14:54:11,655 DEBUG ++Rcv raw: b'\x81~\x00\xd5{"topic":"orderbook.50.BTCUSDC","ts":1698936845543,"type":"delta","data":{"s":"BTCUSDC","b":[["34953.24","0.022877"],["34935.14","0"]],"a":[["34974.33","0.000239"],["34980.9","0"]],"u":20009641,"seq":14108029077}}'
2023-11-02 14:54:11,655 DEBUG ++Rcv decoded: fin=1 opcode=1 data=b'{"topic":"orderbook.50.BTCUSDC","ts":1698936845543,"type":"delta","data":{"s":"BTCUSDC","b":[["34953.24","0.022877"],["34935.14","0"]],"a":[["34974.33","0.000239"],["34980.9","0"]],"u":20009641,"seq":14108029077}}'
2023-11-02 14:54:11,656 DEBUG ++Rcv raw: b'\x81~\x00\xae{"topic":"orderbook.50.BTCUSDC","ts":1698936845564,"type":"delta","data":{"s":"BTCUSDC","b":[["34935.14","0.823909"],["34946.11","0"]],"a":[],"u":20009642,"seq":14108029082}}'
2023-11-02 14:54:11,656 DEBUG ++Rcv decoded: fin=1 opcode=1 data=b'{"topic":"orderbook.50.BTCUSDC","ts":1698936845564,"type":"delta","data":{"s":"BTCUSDC","b":[["34935.14","0.823909"],["34946.11","0"]],"a":[],"u":20009642,"seq":14108029082}}'
2023-11-02 14:54:11,656 DEBUG ++Rcv raw: b'\x81~\x00\xae{"topic":"orderbook.50.BTCUSDC","ts":1698936845644,"type":"delta","data":{"s":"BTCUSDC","b":[["34948.02","0.002311"],["34935.14","0"]],"a":[],"u":20009643,"seq":14108029095}}'
2023-11-02 14:54:11,656 DEBUG ++Rcv decoded: fin=1 opcode=1 data=b'{"topic":"orderbook.50.BTCUSDC","ts":1698936845644,"type":"delta","data":{"s":"BTCUSDC","b":[["34948.02","0.002311"],["34935.14","0"]],"a":[],"u":20009643,"seq":14108029095}}'
2023-11-02 14:54:11,657 DEBUG ++Rcv raw: b'\x81~\x00\xd5{"topic":"orderbook.50.BTCUSDC","ts":1698936845664,"type":"delta","data":{"s":"BTCUSDC","b":[["34935.14","0.823909"],["34947.01","0"]],"a":[["34980.9","0.528984"],["34978.69","0"]],"u":20009644,"seq":14108029099}}'
2023-11-02 14:54:11,657 DEBUG ++Rcv decoded: fin=1 opcode=1 data=b'{"topic":"orderbook.50.BTCUSDC","ts":1698936845664,"type":"delta","data":{"s":"BTCUSDC","b":[["34935.14","0.823909"],["34947.01","0"]],"a":[["34980.9","0.528984"],["34978.69","0"]],"u":20009644,"seq":14108029099}}'
2023-11-02 14:54:11,657 DEBUG ++Rcv raw: b'\x81~\x00\xad{"topic":"orderbook.50.BTCUSDC","ts":1698936845683,"type":"delta","data":{"s":"BTCUSDC","b":[],"a":[["34974.31","0.000239"],["34980.9","0"]],"u":20009645,"seq":14108029102}}'
2023-11-02 14:54:11,658 DEBUG ++Rcv decoded: fin=1 opcode=1 data=b'{"topic":"orderbook.50.BTCUSDC","ts":1698936845683,"type":"delta","data":{"s":"BTCUSDC","b":[],"a":[["34974.31","0.000239"],["34980.9","0"]],"u":20009645,"seq":14108029102}}'
2023-11-02 14:54:11,658 DEBUG ++Rcv raw: b'\x81~\x00\xfc{"topic":"orderbook.50.BTCUSDC","ts":1698936845704,"type":"delta","data":{"s":"BTCUSDC","b":[["34956.02","0.0004"],["34956.01","0"]],"a":[["34961.05","0.008356"],["34980.9","0.528984"],["34961.06","0"],["34974.59","0"]],"u":20009646,"seq":14108029109}}'
2023-11-02 14:54:11,658 DEBUG ++Rcv decoded: fin=1 opcode=1 data=b'{"topic":"orderbook.50.BTCUSDC","ts":1698936845704,"type":"delta","data":{"s":"BTCUSDC","b":[["34956.02","0.0004"],["34956.01","0"]],"a":[["34961.05","0.008356"],["34980.9","0.528984"],["34961.06","0"],["34974.59","0"]],"u":20009646,"seq":14108029109}}'
2023-11-02 14:54:11,658 DEBUG ++Rcv raw: b'\x81~\x01\x0c{"topic":"orderbook.50.BTCUSDC","ts":1698936845723,"type":"delta","data":{"s":"BTCUSDC","b":[["34956.06","0.0004"],["34956.05","0.094456"],["34956.02","0.003"],["34935.63","0"],["34935.14","0"]],"a":[["34964.8","0.03"],["34980.9","0"]],"u":20009647,"seq":14108029120}}'
2023-11-02 14:54:11,659 DEBUG ++Rcv decoded: fin=1 opcode=1 data=b'{"topic":"orderbook.50.BTCUSDC","ts":1698936845723,"type":"delta","data":{"s":"BTCUSDC","b":[["34956.06","0.0004"],["34956.05","0.094456"],["34956.02","0.003"],["34935.63","0"],["34935.14","0"]],"a":[["34964.8","0.03"],["34980.9","0"]],"u":20009647,"seq":14108029120}}'
2023-11-02 14:54:11,659 DEBUG ++Rcv raw: b'\x81~\x00\xee{"topic":"orderbook.50.BTCUSDC","ts":1698936845743,"type":"delta","data":{"s":"BTCUSDC","b":[["34935.63","0.207183"],["34935.14","0.823909"],["34956.02","0"],["34956.05","0"]],"a":[["34963.17","0.065242"]],"u":20009648,"seq":14108029124}}'
2023-11-02 14:54:11,659 DEBUG ++Rcv decoded: fin=1 opcode=1 data=b'{"topic":"orderbook.50.BTCUSDC","ts":1698936845743,"type":"delta","data":{"s":"BTCUSDC","b":[["34935.63","0.207183"],["34935.14","0.823909"],["34956.02","0"],["34956.05","0"]],"a":[["34963.17","0.065242"]],"u":20009648,"seq":14108029124}}'
2023-11-02 14:54:11,659 DEBUG ++Rcv raw: b'\x81~\x00\xae{"topic":"orderbook.50.BTCUSDC","ts":1698936845763,"type":"delta","data":{"s":"BTCUSDC","b":[["34935.13","1.373172"],["34953.43","0"]],"a":[],"u":20009649,"seq":14108029150}}'
2023-11-02 14:54:11,659 DEBUG ++Rcv decoded: fin=1 opcode=1 data=b'{"topic":"orderbook.50.BTCUSDC","ts":1698936845763,"type":"delta","data":{"s":"BTCUSDC","b":[["34935.13","1.373172"],["34953.43","0"]],"a":[],"u":20009649,"seq":14108029150}}'
2023-11-02 14:54:11,660 DEBUG ++Rcv raw: b'\x81~\x01%{"topic":"orderbook.50.BTCUSDC","ts":1698936845783,"type":"delta","data":{"s":"BTCUSDC","b":[["34954.12","0.057217"],["34940.95","0.028"],["34935.14","0"],["34935.13","0"]],"a":[["34960.87","0.039341"],["34960.88","0.057206"],["34980.89","0"],["34968.75","0"]],"u":20009650,"seq":14108029167}}'
2023-11-02 14:54:11,660 DEBUG ++Rcv decoded: fin=1 opcode=1 data=b'{"topic":"orderbook.50.BTCUSDC","ts":1698936845783,"type":"delta","data":{"s":"BTCUSDC","b":[["34954.12","0.057217"],["34940.95","0.028"],["34935.14","0"],["34935.13","0"]],"a":[["34960.87","0.039341"],["34960.88","0.057206"],["34980.89","0"],["34968.75","0"]],"u":20009650,"seq":14108029167}}'
2023-11-02 14:54:11,660 DEBUG ++Rcv raw: b'\x81~\x00\xc5{"topic":"orderbook.50.BTCUSDC","ts":1698936845803,"type":"delta","data":{"s":"BTCUSDC","b":[["34954.71","0.079432"]],"a":[["34980.89","0.317395"],["34969.06","0"]],"u":20009651,"seq":14108029175}}'
2023-11-02 14:54:11,660 DEBUG ++Rcv decoded: fin=1 opcode=1 data=b'{"topic":"orderbook.50.BTCUSDC","ts":1698936845803,"type":"delta","data":{"s":"BTCUSDC","b":[["34954.71","0.079432"]],"a":[["34980.89","0.317395"],["34969.06","0"]],"u":20009651,"seq":14108029175}}'
2023-11-02 14:54:11,660 DEBUG ++Rcv raw: b'\x81~\x00\xd4{"topic":"orderbook.50.BTCUSDC","ts":1698936845843,"type":"delta","data":{"s":"BTCUSDC","b":[["34949.06","0.1875"],["34935.63","0"]],"a":[["34960.86","0.008356"],["34961.05","0"]],"u":20009652,"seq":14108029192}}'
2023-11-02 14:54:11,660 DEBUG ++Rcv decoded: fin=1 opcode=1 data=b'{"topic":"orderbook.50.BTCUSDC","ts":1698936845843,"type":"delta","data":{"s":"BTCUSDC","b":[["34949.06","0.1875"],["34935.63","0"]],"a":[["34960.86","0.008356"],["34961.05","0"]],"u":20009652,"seq":14108029192}}'
2023-11-02 14:54:11,661 DEBUG ++Rcv raw: b'\x81~\x00\xc6{"topic":"orderbook.50.BTCUSDC","ts":1698936845863,"type":"delta","data":{"s":"BTCUSDC","b":[["34949.55","0.106063"],["34935.63","0.207183"],["34949.06","0"]],"a":[],"u":20009653,"seq":14108029205}}'
2023-11-02 14:54:11,661 DEBUG ++Rcv decoded: fin=1 opcode=1 data=b'{"topic":"orderbook.50.BTCUSDC","ts":1698936845863,"type":"delta","data":{"s":"BTCUSDC","b":[["34949.55","0.106063"],["34935.63","0.207183"],["34949.06","0"]],"a":[],"u":20009653,"seq":14108029205}}'
2023-11-02 14:54:11,661 DEBUG ++Rcv raw: b'\x81~\x00\xeb{"topic":"orderbook.50.BTCUSDC","ts":1698936845883,"type":"delta","data":{"s":"BTCUSDC","b":[["34949.55","0.051543"],["34949.06","0.1875"],["34935.63","0"]],"a":[["34980.9","0.528984"],["34974.33","0"]],"u":20009654,"seq":14108029222}}'
2023-11-02 14:54:11,661 DEBUG ++Rcv decoded: fin=1 opcode=1 data=b'{"topic":"orderbook.50.BTCUSDC","ts":1698936845883,"type":"delta","data":{"s":"BTCUSDC","b":[["34949.55","0.051543"],["34949.06","0.1875"],["34935.63","0"]],"a":[["34980.9","0.528984"],["34974.33","0"]],"u":20009654,"seq":14108029222}}'
2023-11-02 14:54:11,661 DEBUG ++Rcv raw: b'\x81~\x00\x9d{"topic":"orderbook.50.BTCUSDC","ts":1698936845903,"type":"delta","data":{"s":"BTCUSDC","b":[["34949.55","0.106064"]],"a":[],"u":20009655,"seq":14108029224}}'
2023-11-02 14:54:11,661 DEBUG ++Rcv decoded: fin=1 opcode=1 data=b'{"topic":"orderbook.50.BTCUSDC","ts":1698936845903,"type":"delta","data":{"s":"BTCUSDC","b":[["34949.55","0.106064"]],"a":[],"u":20009655,"seq":14108029224}}'
2023-11-02 14:54:11,662 DEBUG ++Rcv raw: b'\x81~\x00\xeb{"topic":"orderbook.50.BTCUSDC","ts":1698936845983,"type":"delta","data":{"s":"BTCUSDC","b":[["34935.63","0.207183"],["34956.06","0"]],"a":[["34960.86","0.008156"],["34981.28","0.000562"],["34972","0"]],"u":20009656,"seq":14108029276}}'
2023-11-02 14:54:11,662 DEBUG ++Rcv decoded: fin=1 opcode=1 data=b'{"topic":"orderbook.50.BTCUSDC","ts":1698936845983,"type":"delta","data":{"s":"BTCUSDC","b":[["34935.63","0.207183"],["34956.06","0"]],"a":[["34960.86","0.008156"],["34981.28","0.000562"],["34972","0"]],"u":20009656,"seq":14108029276}}'
2023-11-02 14:54:11,662 DEBUG ++Rcv raw: b'\x81~\x00\xd4{"topic":"orderbook.50.BTCUSDC","ts":1698936846003,"type":"delta","data":{"s":"BTCUSDC","b":[["34956.01","0.0006"],["34949.06","0"]],"a":[["34973.97","1.373119"],["34971.82","0"]],"u":20009657,"seq":14108029285}}'
2023-11-02 14:54:11,662 DEBUG ++Rcv decoded: fin=1 opcode=1 data=b'{"topic":"orderbook.50.BTCUSDC","ts":1698936846003,"type":"delta","data":{"s":"BTCUSDC","b":[["34956.01","0.0006"],["34949.06","0"]],"a":[["34973.97","1.373119"],["34971.82","0"]],"u":20009657,"seq":14108029285}}'
2023-11-02 14:54:11,662 DEBUG ++Rcv raw: b'\x81~\x01\x15{"topic":"orderbook.50.BTCUSDC","ts":1698936846024,"type":"delta","data":{"s":"BTCUSDC","b":[["34956.83","0.0006"],["34956.82","0.095863"],["34949.55","0.051543"],["34935.63","0"],["34956.01","0"]],"a":[["34981.81","0.094142"],["34974.31","0"]],"u":20009658,"seq":14108029293}}'
2023-11-02 14:54:11,662 DEBUG ++Rcv decoded: fin=1 opcode=1 data=b'{"topic":"orderbook.50.BTCUSDC","ts":1698936846024,"type":"delta","data":{"s":"BTCUSDC","b":[["34956.83","0.0006"],["34956.82","0.095863"],["34949.55","0.051543"],["34935.63","0"],["34956.01","0"]],"a":[["34981.81","0.094142"],["34974.31","0"]],"u":20009658,"seq":14108029293}}'
2023-11-02 14:54:11,663 DEBUG ++Rcv raw: b'\x81~\x00\xae{"topic":"orderbook.50.BTCUSDC","ts":1698936846044,"type":"delta","data":{"s":"BTCUSDC","b":[["34935.63","0.207183"],["34956.82","0"]],"a":[],"u":20009659,"seq":14108029301}}'
2023-11-02 14:54:11,663 DEBUG ++Rcv decoded: fin=1 opcode=1 data=b'{"topic":"orderbook.50.BTCUSDC","ts":1698936846044,"type":"delta","data":{"s":"BTCUSDC","b":[["34935.63","0.207183"],["34956.82","0"]],"a":[],"u":20009659,"seq":14108029301}}'
2023-11-02 14:54:11,663 DEBUG ++Rcv raw: b'\x81~\x00\xae{"topic":"orderbook.50.BTCUSDC","ts":1698936846104,"type":"delta","data":{"s":"BTCUSDC","b":[],"a":[["34960.85","0.008156"],["34960.86","0"]],"u":20009660,"seq":14108029361}}'
2023-11-02 14:54:11,663 DEBUG ++Rcv decoded: fin=1 opcode=1 data=b'{"topic":"orderbook.50.BTCUSDC","ts":1698936846104,"type":"delta","data":{"s":"BTCUSDC","b":[],"a":[["34960.85","0.008156"],["34960.86","0"]],"u":20009660,"seq":14108029361}}'
2023-11-02 14:54:11,663 DEBUG ++Rcv raw: b'\x81~\x00\xac{"topic":"orderbook.50.BTCUSDC","ts":1698936846144,"type":"delta","data":{"s":"BTCUSDC","b":[],"a":[["34983.74","0.1875"],["34960.87","0"]],"u":20009661,"seq":14108029367}}'
2023-11-02 14:54:11,663 DEBUG ++Rcv decoded: fin=1 opcode=1 data=b'{"topic":"orderbook.50.BTCUSDC","ts":1698936846144,"type":"delta","data":{"s":"BTCUSDC","b":[],"a":[["34983.74","0.1875"],["34960.87","0"]],"u":20009661,"seq":14108029367}}'
2023-11-02 14:54:11,664 DEBUG ++Rcv raw: b'\x81~\x00\xad{"topic":"orderbook.50.BTCUSDC","ts":1698936846164,"type":"delta","data":{"s":"BTCUSDC","b":[],"a":[["34973.61","0.82388"],["34983.74","0"]],"u":20009662,"seq":14108029374}}'
2023-11-02 14:54:11,664 DEBUG ++Rcv decoded: fin=1 opcode=1 data=b'{"topic":"orderbook.50.BTCUSDC","ts":1698936846164,"type":"delta","data":{"s":"BTCUSDC","b":[],"a":[["34973.61","0.82388"],["34983.74","0"]],"u":20009662,"seq":14108029374}}'
2023-11-02 14:54:11,664 DEBUG ++Rcv raw: b'\x81~\x00\xae{"topic":"orderbook.50.BTCUSDC","ts":1698936846184,"type":"delta","data":{"s":"BTCUSDC","b":[["34936.96","0.171738"],["34935.63","0"]],"a":[],"u":20009663,"seq":14108029381}}'
2023-11-02 14:54:11,664 DEBUG ++Rcv decoded: fin=1 opcode=1 data=b'{"topic":"orderbook.50.BTCUSDC","ts":1698936846184,"type":"delta","data":{"s":"BTCUSDC","b":[["34936.96","0.171738"],["34935.63","0"]],"a":[],"u":20009663,"seq":14108029381}}'
2023-11-02 14:54:11,664 DEBUG ++Rcv raw: b'\x81~\x00\xaf{"topic":"orderbook.50.BTCUSDC","ts":1698936846324,"type":"delta","data":{"s":"BTCUSDC","b":[["34950","0.0341"]],"a":[["34960.85","0.007956"]],"u":20009664,"seq":14108029464}}'
2023-11-02 14:54:11,664 DEBUG ++Rcv decoded: fin=1 opcode=1 data=b'{"topic":"orderbook.50.BTCUSDC","ts":1698936846324,"type":"delta","data":{"s":"BTCUSDC","b":[["34950","0.0341"]],"a":[["34960.85","0.007956"]],"u":20009664,"seq":14108029464}}'
2023-11-02 14:54:11,664 DEBUG ++Rcv raw: b'\x81~\x00\xae{"topic":"orderbook.50.BTCUSDC","ts":1698936846343,"type":"delta","data":{"s":"BTCUSDC","b":[],"a":[["34960.87","0.029131"],["34981.81","0"]],"u":20009665,"seq":14108029466}}'
2023-11-02 14:54:11,665 DEBUG ++Rcv decoded: fin=1 opcode=1 data=b'{"topic":"orderbook.50.BTCUSDC","ts":1698936846343,"type":"delta","data":{"s":"BTCUSDC","b":[],"a":[["34960.87","0.029131"],["34981.81","0"]],"u":20009665,"seq":14108029466}}'
2023-11-02 14:54:11,665 DEBUG ++Rcv raw: b'\x81~\x00\xd7{"topic":"orderbook.50.BTCUSDC","ts":1698936846363,"type":"delta","data":{"s":"BTCUSDC","b":[["34957.33","0.09348"],["34956.83","0.0036"],["34936","0"]],"a":[["34960.85","0.009956"]],"u":20009666,"seq":14108029495}}'
2023-11-02 14:54:11,665 DEBUG ++Rcv decoded: fin=1 opcode=1 data=b'{"topic":"orderbook.50.BTCUSDC","ts":1698936846363,"type":"delta","data":{"s":"BTCUSDC","b":[["34957.33","0.09348"],["34956.83","0.0036"],["34936","0"]],"a":[["34960.85","0.009956"]],"u":20009666,"seq":14108029495}}'
2023-11-02 14:54:11,665 DEBUG ++Rcv raw: b'\x81~\x00\xe4{"topic":"orderbook.50.BTCUSDC","ts":1698936846383,"type":"delta","data":{"s":"BTCUSDC","b":[["34957.34","0.0008"],["34936","0.0341"],["34957.33","0"],["34956.83","0"]],"a":[["34960.85","0.002"]],"u":20009667,"seq":14108029520}}'
2023-11-02 14:54:11,665 DEBUG ++Rcv decoded: fin=1 opcode=1 data=b'{"topic":"orderbook.50.BTCUSDC","ts":1698936846383,"type":"delta","data":{"s":"BTCUSDC","b":[["34957.34","0.0008"],["34936","0.0341"],["34957.33","0"],["34956.83","0"]],"a":[["34960.85","0.002"]],"u":20009667,"seq":14108029520}}'
2023-11-02 14:54:11,666 DEBUG ++Rcv raw: b'\x81~\x00\xae{"topic":"orderbook.50.BTCUSDC","ts":1698936846524,"type":"delta","data":{"s":"BTCUSDC","b":[],"a":[["34960.84","0.007956"],["34981.28","0"]],"u":20009668,"seq":14108029624}}'
2023-11-02 14:54:11,666 DEBUG ++Rcv decoded: fin=1 opcode=1 data=b'{"topic":"orderbook.50.BTCUSDC","ts":1698936846524,"type":"delta","data":{"s":"BTCUSDC","b":[],"a":[["34960.84","0.007956"],["34981.28","0"]],"u":20009668,"seq":14108029624}}'
2023-11-02 14:54:11,666 DEBUG ++Rcv raw: b'\x81~\x00\xae{"topic":"orderbook.50.BTCUSDC","ts":1698936846543,"type":"delta","data":{"s":"BTCUSDC","b":[["34935.63","0.207183"],["34936.95","0"]],"a":[],"u":20009669,"seq":14108029633}}'
2023-11-02 14:54:11,666 DEBUG ++Rcv decoded: fin=1 opcode=1 data=b'{"topic":"orderbook.50.BTCUSDC","ts":1698936846543,"type":"delta","data":{"s":"BTCUSDC","b":[["34935.63","0.207183"],["34936.95","0"]],"a":[],"u":20009669,"seq":14108029633}}'
2023-11-02 14:54:11,666 DEBUG ++Rcv raw: b'\x81~\x00\xae{"topic":"orderbook.50.BTCUSDC","ts":1698936846563,"type":"delta","data":{"s":"BTCUSDC","b":[["34938.17","0.286219"],["34936.96","0"]],"a":[],"u":20009670,"seq":14108029659}}'
2023-11-02 14:54:11,666 DEBUG ++Rcv decoded: fin=1 opcode=1 data=b'{"topic":"orderbook.50.BTCUSDC","ts":1698936846563,"type":"delta","data":{"s":"BTCUSDC","b":[["34938.17","0.286219"],["34936.96","0"]],"a":[],"u":20009670,"seq":14108029659}}'
2023-11-02 14:54:11,667 DEBUG ++Rcv raw: b'\x81~\x00\xae{"topic":"orderbook.50.BTCUSDC","ts":1698936846663,"type":"delta","data":{"s":"BTCUSDC","b":[["34935.14","0.823909"],["34957.34","0"]],"a":[],"u":20009671,"seq":14108029722}}'
2023-11-02 14:54:11,667 DEBUG ++Rcv decoded: fin=1 opcode=1 data=b'{"topic":"orderbook.50.BTCUSDC","ts":1698936846663,"type":"delta","data":{"s":"BTCUSDC","b":[["34935.14","0.823909"],["34957.34","0"]],"a":[],"u":20009671,"seq":14108029722}}'
2023-11-02 14:54:11,667 DEBUG ++Rcv raw: b'\x81~\x00\xd5{"topic":"orderbook.50.BTCUSDC","ts":1698936846683,"type":"delta","data":{"s":"BTCUSDC","b":[["34957.03","0.092751"],["34956.01","0.0008"],["34935.14","0"],["34935.63","0"]],"a":[],"u":20009672,"seq":14108029726}}'
2023-11-02 14:54:11,667 DEBUG ++Rcv decoded: fin=1 opcode=1 data=b'{"topic":"orderbook.50.BTCUSDC","ts":1698936846683,"type":"delta","data":{"s":"BTCUSDC","b":[["34957.03","0.092751"],["34956.01","0.0008"],["34935.14","0"],["34935.63","0"]],"a":[],"u":20009672,"seq":14108029726}}'
2023-11-02 14:54:11,667 DEBUG ++Rcv raw: b'\x81~\x00\xd5{"topic":"orderbook.50.BTCUSDC","ts":1698936846743,"type":"delta","data":{"s":"BTCUSDC","b":[["34957.04","0.0008"],["34935.63","0.207183"],["34957.03","0"],["34956.01","0"]],"a":[],"u":20009673,"seq":14108029755}}'
2023-11-02 14:54:11,667 DEBUG ++Rcv decoded: fin=1 opcode=1 data=b'{"topic":"orderbook.50.BTCUSDC","ts":1698936846743,"type":"delta","data":{"s":"BTCUSDC","b":[["34957.04","0.0008"],["34935.63","0.207183"],["34957.03","0"],["34956.01","0"]],"a":[],"u":20009673,"seq":14108029755}}'
2023-11-02 14:54:11,668 DEBUG ++Rcv raw: b'\x81~\x00\xae{"topic":"orderbook.50.BTCUSDC","ts":1698936846804,"type":"delta","data":{"s":"BTCUSDC","b":[],"a":[["34981.28","0.000562"],["34960.84","0"]],"u":20009674,"seq":14108029769}}'
2023-11-02 14:54:11,668 DEBUG ++Rcv decoded: fin=1 opcode=1 data=b'{"topic":"orderbook.50.BTCUSDC","ts":1698936846804,"type":"delta","data":{"s":"BTCUSDC","b":[],"a":[["34981.28","0.000562"],["34960.84","0"]],"u":20009674,"seq":14108029769}}'
2023-11-02 14:54:11,668 DEBUG ++Rcv raw: b'\x81~\x00\xd6{"topic":"orderbook.50.BTCUSDC","ts":1698936846843,"type":"delta","data":{"s":"BTCUSDC","b":[],"a":[["34960.84","0.007956"],["34974.07","0.000239"],["34981.28","0"],["34980.9","0"]],"u":20009675,"seq":14108029789}}'
2023-11-02 14:54:11,668 DEBUG ++Rcv decoded: fin=1 opcode=1 data=b'{"topic":"orderbook.50.BTCUSDC","ts":1698936846843,"type":"delta","data":{"s":"BTCUSDC","b":[],"a":[["34960.84","0.007956"],["34974.07","0.000239"],["34981.28","0"],["34980.9","0"]],"u":20009675,"seq":14108029789}}'
2023-11-02 14:54:11,668 DEBUG ++Rcv raw: b'\x81~\x00\xc2{"topic":"orderbook.50.BTCUSDC","ts":1698936846863,"type":"delta","data":{"s":"BTCUSDC","b":[["34957.04","0.0038"]],"a":[["34980.9","0.528984"],["34968.48","0"]],"u":20009676,"seq":14108029819}}'
2023-11-02 14:54:11,668 DEBUG ++Rcv decoded: fin=1 opcode=1 data=b'{"topic":"orderbook.50.BTCUSDC","ts":1698936846863,"type":"delta","data":{"s":"BTCUSDC","b":[["34957.04","0.0038"]],"a":[["34980.9","0.528984"],["34968.48","0"]],"u":20009676,"seq":14108029819}}'
2023-11-02 14:54:11,670 DEBUG ++Rcv raw: b'\x81~\x00\xad{"topic":"orderbook.50.BTCUSDC","ts":1698936846883,"type":"delta","data":{"s":"BTCUSDC","b":[],"a":[["34967.48","0.114392"],["34980.9","0"]],"u":20009677,"seq":14108029828}}'
2023-11-02 14:54:11,671 DEBUG ++Rcv decoded: fin=1 opcode=1 data=b'{"topic":"orderbook.50.BTCUSDC","ts":1698936846883,"type":"delta","data":{"s":"BTCUSDC","b":[],"a":[["34967.48","0.114392"],["34980.9","0"]],"u":20009677,"seq":14108029828}}'
2023-11-02 14:54:11,671 DEBUG ++Rcv raw: b'\x81~\x00\x9d{"topic":"orderbook.50.BTCUSDC","ts":1698936846984,"type":"delta","data":{"s":"BTCUSDC","b":[],"a":[["34960.84","0.007756"]],"u":20009678,"seq":14108029885}}'
2023-11-02 14:54:11,671 DEBUG ++Rcv decoded: fin=1 opcode=1 data=b'{"topic":"orderbook.50.BTCUSDC","ts":1698936846984,"type":"delta","data":{"s":"BTCUSDC","b":[],"a":[["34960.84","0.007756"]],"u":20009678,"seq":14108029885}}'
2023-11-02 14:54:11,671 DEBUG ++Rcv raw: b'\x81~\x00\xd7{"topic":"orderbook.50.BTCUSDC","ts":1698936847043,"type":"delta","data":{"s":"BTCUSDC","b":[],"a":[["34974.03","0.000239"],["34975.99","0.029858"],["34980.89","0"],["34979.79","0"]],"u":20009679,"seq":14108029897}}'
2023-11-02 14:54:11,671 DEBUG ++Rcv decoded: fin=1 opcode=1 data=b'{"topic":"orderbook.50.BTCUSDC","ts":1698936847043,"type":"delta","data":{"s":"BTCUSDC","b":[],"a":[["34974.03","0.000239"],["34975.99","0.029858"],["34980.89","0"],["34979.79","0"]],"u":20009679,"seq":14108029897}}'
2023-11-02 14:54:11,671 DEBUG ++Rcv raw: b'\x81~\x00\xd6{"topic":"orderbook.50.BTCUSDC","ts":1698936847084,"type":"delta","data":{"s":"BTCUSDC","b":[["34953.64","0.057218"],["34954.12","0"]],"a":[["34960.72","0.057207"],["34960.88","0"]],"u":20009680,"seq":14108029915}}'
2023-11-02 14:54:11,672 DEBUG ++Rcv decoded: fin=1 opcode=1 data=b'{"topic":"orderbook.50.BTCUSDC","ts":1698936847084,"type":"delta","data":{"s":"BTCUSDC","b":[["34953.64","0.057218"],["34954.12","0"]],"a":[["34960.72","0.057207"],["34960.88","0"]],"u":20009680,"seq":14108029915}}'
2023-11-02 14:54:11,672 DEBUG ++Rcv raw: b'\x81~\x00\xee{"topic":"orderbook.50.BTCUSDC","ts":1698936847104,"type":"delta","data":{"s":"BTCUSDC","b":[["34957.11","0.103148"],["34954.71","0.051548"],["34935.63","0"]],"a":[["34960.71","0.044883"],["34960.87","0"]],"u":20009681,"seq":14108029923}}'
2023-11-02 14:54:11,673 DEBUG ++Rcv decoded: fin=1 opcode=1 data=b'{"topic":"orderbook.50.BTCUSDC","ts":1698936847104,"type":"delta","data":{"s":"BTCUSDC","b":[["34957.11","0.103148"],["34954.71","0.051548"],["34935.63","0"]],"a":[["34960.71","0.044883"],["34960.87","0"]],"u":20009681,"seq":14108029923}}'
2023-11-02 14:54:11,674 DEBUG ++Rcv raw: b'\x81~\x00\xd5{"topic":"orderbook.50.BTCUSDC","ts":1698936847123,"type":"delta","data":{"s":"BTCUSDC","b":[["34935.63","0.207183"],["34957.04","0"]],"a":[["34960.7","0.007756"],["34960.84","0"]],"u":20009682,"seq":14108029934}}'
2023-11-02 14:54:11,674 DEBUG ++Rcv decoded: fin=1 opcode=1 data=b'{"topic":"orderbook.50.BTCUSDC","ts":1698936847123,"type":"delta","data":{"s":"BTCUSDC","b":[["34935.63","0.207183"],["34957.04","0"]],"a":[["34960.7","0.007756"],["34960.84","0"]],"u":20009682,"seq":14108029934}}'
2023-11-02 14:54:11,675 DEBUG ++Rcv raw: b'\x81~\x00\xae{"topic":"orderbook.50.BTCUSDC","ts":1698936847203,"type":"delta","data":{"s":"BTCUSDC","b":[["34935.14","0.823909"],["34935.63","0"]],"a":[],"u":20009683,"seq":14108029964}}'
2023-11-02 14:54:11,676 DEBUG ++Rcv decoded: fin=1 opcode=1 data=b'{"topic":"orderbook.50.BTCUSDC","ts":1698936847203,"type":"delta","data":{"s":"BTCUSDC","b":[["34935.14","0.823909"],["34935.63","0"]],"a":[],"u":20009683,"seq":14108029964}}'
2023-11-02 14:54:11,676 DEBUG ++Rcv raw: b'\x81~\x00\xfc{"topic":"orderbook.50.BTCUSDC","ts":1698936847224,"type":"delta","data":{"s":"BTCUSDC","b":[["34938.18","0.171735"],["34935.14","0"]],"a":[["34967.7","0.1875"],["34971.22","0.074114"],["34960.72","0"],["34977.57","0"]],"u":20009684,"seq":14108029982}}'
2023-11-02 14:54:11,677 DEBUG ++Rcv decoded: fin=1 opcode=1 data=b'{"topic":"orderbook.50.BTCUSDC","ts":1698936847224,"type":"delta","data":{"s":"BTCUSDC","b":[["34938.18","0.171735"],["34935.14","0"]],"a":[["34967.7","0.1875"],["34971.22","0.074114"],["34960.72","0"],["34977.57","0"]],"u":20009684,"seq":14108029982}}'
2023-11-02 14:54:11,677 DEBUG ++Rcv raw: b'\x81~\x00\xd6{"topic":"orderbook.50.BTCUSDC","ts":1698936847244,"type":"delta","data":{"s":"BTCUSDC","b":[],"a":[["34960.35","0.057207"],["34976.37","0.285907"],["34978.9","0"],["34960.71","0"]],"u":20009685,"seq":14108029986}}'
2023-11-02 14:54:11,678 DEBUG ++Rcv decoded: fin=1 opcode=1 data=b'{"topic":"orderbook.50.BTCUSDC","ts":1698936847244,"type":"delta","data":{"s":"BTCUSDC","b":[],"a":[["34960.35","0.057207"],["34976.37","0.285907"],["34978.9","0"],["34960.71","0"]],"u":20009685,"seq":14108029986}}'
2023-11-02 14:54:11,678 DEBUG ++Rcv raw: b'\x81~\x00\xd7{"topic":"orderbook.50.BTCUSDC","ts":1698936847264,"type":"delta","data":{"s":"BTCUSDC","b":[["34935.14","0.823909"],["34935.13","1.373172"],["34953.64","0"],["34938.17","0"]],"a":[],"u":20009686,"seq":14108030001}}'
2023-11-02 14:54:11,679 DEBUG ++Rcv decoded: fin=1 opcode=1 data=b'{"topic":"orderbook.50.BTCUSDC","ts":1698936847264,"type":"delta","data":{"s":"BTCUSDC","b":[["34935.14","0.823909"],["34935.13","1.373172"],["34953.64","0"],["34938.17","0"]],"a":[],"u":20009686,"seq":14108030001}}'
2023-11-02 14:54:11,679 DEBUG ++Rcv raw: b'\x81~\x00\xff{"topic":"orderbook.50.BTCUSDC","ts":1698936847284,"type":"delta","data":{"s":"BTCUSDC","b":[["34953.17","0.057219"],["34937.16","0.286228"],["34938.18","0"],["34935.13","0"]],"a":[["34960.34","0.040183"],["34978.28","0"]],"u":20009687,"seq":14108030021}}'
2023-11-02 14:54:11,679 DEBUG ++Rcv decoded: fin=1 opcode=1 data=b'{"topic":"orderbook.50.BTCUSDC","ts":1698936847284,"type":"delta","data":{"s":"BTCUSDC","b":[["34953.17","0.057219"],["34937.16","0.286228"],["34938.18","0"],["34935.13","0"]],"a":[["34960.34","0.040183"],["34978.28","0"]],"u":20009687,"seq":14108030021}}'
2023-11-02 14:54:11,680 DEBUG ++Rcv raw: b'\x81~\x01I{"topic":"orderbook.50.BTCUSDC","ts":1698936847304,"type":"delta","data":{"s":"BTCUSDC","b":[["34956.01","0.001"],["34935.13","1.373172"],["34956","0"],["34957.11","0"]],"a":[["34960.33","0.007756"],["34978.28","0.001447"],["34978.9","0.002162"],["34960.35","0"],["34974.07","0"],["34960.7","0"]],"u":20009688,"seq":14108030037}}'
2023-11-02 14:54:11,680 DEBUG ++Rcv decoded: fin=1 opcode=1 data=b'{"topic":"orderbook.50.BTCUSDC","ts":1698936847304,"type":"delta","data":{"s":"BTCUSDC","b":[["34956.01","0.001"],["34935.13","1.373172"],["34956","0"],["34957.11","0"]],"a":[["34960.33","0.007756"],["34978.28","0.001447"],["34978.9","0.002162"],["34960.35","0"],["34974.07","0"],["34960.7","0"]],"u":20009688,"seq":14108030037}}'
2023-11-02 14:54:11,680 DEBUG ++Rcv raw: b'\x81~\x00\xad{"topic":"orderbook.50.BTCUSDC","ts":1698936847323,"type":"delta","data":{"s":"BTCUSDC","b":[],"a":[["34979.79","0.02859"],["34960.34","0"]],"u":20009689,"seq":14108030042}}'
2023-11-02 14:54:11,680 DEBUG ++Rcv decoded: fin=1 opcode=1 data=b'{"topic":"orderbook.50.BTCUSDC","ts":1698936847323,"type":"delta","data":{"s":"BTCUSDC","b":[],"a":[["34979.79","0.02859"],["34960.34","0"]],"u":20009689,"seq":14108030042}}'
2023-11-02 14:54:11,680 DEBUG ++Rcv raw: b'\x81~\x00\xe9{"topic":"orderbook.50.BTCUSDC","ts":1698936847344,"type":"delta","data":{"s":"BTCUSDC","b":[["34947.01","0.002717"],["34935.13","0"]],"a":[["34960.33","0.007556"],["34962","0.0324"],["34979.79","0"]],"u":20009690,"seq":14108030071}}'
2023-11-02 14:54:11,681 DEBUG ++Rcv decoded: fin=1 opcode=1 data=b'{"topic":"orderbook.50.BTCUSDC","ts":1698936847344,"type":"delta","data":{"s":"BTCUSDC","b":[["34947.01","0.002717"],["34935.13","0"]],"a":[["34960.33","0.007556"],["34962","0.0324"],["34979.79","0"]],"u":20009690,"seq":14108030071}}'
2023-11-02 14:54:11,681 DEBUG ++Rcv raw: b'\x81~\x00\xae{"topic":"orderbook.50.BTCUSDC","ts":1698936847364,"type":"delta","data":{"s":"BTCUSDC","b":[["34935.13","1.373172"],["34948.02","0"]],"a":[],"u":20009691,"seq":14108030093}}'
2023-11-02 14:54:11,681 DEBUG ++Rcv decoded: fin=1 opcode=1 data=b'{"topic":"orderbook.50.BTCUSDC","ts":1698936847364,"type":"delta","data":{"s":"BTCUSDC","b":[["34935.13","1.373172"],["34948.02","0"]],"a":[],"u":20009691,"seq":14108030093}}'
2023-11-02 14:54:11,681 DEBUG ++Rcv raw: b'\x81~\x00\xad{"topic":"orderbook.50.BTCUSDC","ts":1698936847464,"type":"delta","data":{"s":"BTCUSDC","b":[],"a":[["34979.79","0.02859"],["34974.03","0"]],"u":20009692,"seq":14108030165}}'
2023-11-02 14:54:11,681 DEBUG ++Rcv decoded: fin=1 opcode=1 data=b'{"topic":"orderbook.50.BTCUSDC","ts":1698936847464,"type":"delta","data":{"s":"BTCUSDC","b":[],"a":[["34979.79","0.02859"],["34974.03","0"]],"u":20009692,"seq":14108030165}}'
2023-11-02 14:54:11,681 DEBUG ++Rcv raw: b'\x81~\x00\xfd{"topic":"orderbook.50.BTCUSDC","ts":1698936847643,"type":"delta","data":{"s":"BTCUSDC","b":[["34955.91","0.097389"],["34954.72","0.0012"],["34956.01","0"],["34935.13","0"]],"a":[["34960.84","0.007556"],["34960.33","0"]],"u":20009693,"seq":14108030255}}'
2023-11-02 14:54:11,681 DEBUG ++Rcv decoded: fin=1 opcode=1 data=b'{"topic":"orderbook.50.BTCUSDC","ts":1698936847643,"type":"delta","data":{"s":"BTCUSDC","b":[["34955.91","0.097389"],["34954.72","0.0012"],["34956.01","0"],["34935.13","0"]],"a":[["34960.84","0.007556"],["34960.33","0"]],"u":20009693,"seq":14108030255}}'
2023-11-02 14:54:11,682 DEBUG ++Rcv raw: b'\x81~\x00\x9d{"topic":"orderbook.50.BTCUSDC","ts":1698936847663,"type":"delta","data":{"s":"BTCUSDC","b":[["34954.71","0.054548"]],"a":[],"u":20009694,"seq":14108030259}}'
2023-11-02 14:54:11,682 DEBUG ++Rcv decoded: fin=1 opcode=1 data=b'{"topic":"orderbook.50.BTCUSDC","ts":1698936847663,"type":"delta","data":{"s":"BTCUSDC","b":[["34954.71","0.054548"]],"a":[],"u":20009694,"seq":14108030259}}'
2023-11-02 14:54:11,682 DEBUG ++Rcv raw: b'\x81~\x00\xee{"topic":"orderbook.50.BTCUSDC","ts":1698936847703,"type":"delta","data":{"s":"BTCUSDC","b":[["34955.92","0.055206"],["34935.13","1.373172"],["34954.72","0"],["34955.91","0"]],"a":[["34960.84","0.007356"]],"u":20009695,"seq":14108030291}}'
2023-11-02 14:54:11,682 DEBUG ++Rcv decoded: fin=1 opcode=1 data=b'{"topic":"orderbook.50.BTCUSDC","ts":1698936847703,"type":"delta","data":{"s":"BTCUSDC","b":[["34955.92","0.055206"],["34935.13","1.373172"],["34954.72","0"],["34955.91","0"]],"a":[["34960.84","0.007356"]],"u":20009695,"seq":14108030291}}'
2023-11-02 14:54:11,682 DEBUG ++Rcv raw: b'\x81~\x00\xdb{"topic":"orderbook.50.BTCUSDC","ts":1698936847723,"type":"delta","data":{"s":"BTCUSDC","b":[["34955.92","0.0014"],["34954.71","0.051548"]],"a":[["34980.89","0.317395"],["34960.85","0"]],"u":20009696,"seq":14108030301}}'
2023-11-02 14:54:11,683 DEBUG ++Rcv decoded: fin=1 opcode=1 data=b'{"topic":"orderbook.50.BTCUSDC","ts":1698936847723,"type":"delta","data":{"s":"BTCUSDC","b":[["34955.92","0.0014"],["34954.71","0.051548"]],"a":[["34980.89","0.317395"],["34960.85","0"]],"u":20009696,"seq":14108030301}}'
2023-11-02 14:54:11,684 DEBUG ++Rcv raw: b'\x81~\x00\xd5{"topic":"orderbook.50.BTCUSDC","ts":1698936848064,"type":"delta","data":{"s":"BTCUSDC","b":[["34934.62","0.029858"],["34955.92","0"]],"a":[["34980.9","0.528984"],["34960.84","0"]],"u":20009697,"seq":14108030447}}'
2023-11-02 14:54:11,684 DEBUG ++Rcv decoded: fin=1 opcode=1 data=b'{"topic":"orderbook.50.BTCUSDC","ts":1698936848064,"type":"delta","data":{"s":"BTCUSDC","b":[["34934.62","0.029858"],["34955.92","0"]],"a":[["34980.9","0.528984"],["34960.84","0"]],"u":20009697,"seq":14108030447}}'
2023-11-02 14:54:11,684 DEBUG ++Rcv raw: b'\x81~\x01n{"topic":"orderbook.50.BTCUSDC","ts":1698936848084,"type":"delta","data":{"s":"BTCUSDC","b":[["34957.02","0.102404"],["34954.72","0.0014"],["34934.62","0"],["34952.75","0"]],"a":[["34961.27","0.034331"],["34961.28","0.057206"],["34961.99","0.007356"],["34969","0.1875"],["34962","0"],["34967.7","0"],["34980.89","0"],["34980.9","0"]],"u":20009698,"seq":14108030475}}'
2023-11-02 14:54:11,685 DEBUG ++Rcv decoded: fin=1 opcode=1 data=b'{"topic":"orderbook.50.BTCUSDC","ts":1698936848084,"type":"delta","data":{"s":"BTCUSDC","b":[["34957.02","0.102404"],["34954.72","0.0014"],["34934.62","0"],["34952.75","0"]],"a":[["34961.27","0.034331"],["34961.28","0.057206"],["34961.99","0.007356"],["34969","0.1875"],["34962","0"],["34967.7","0"],["34980.89","0"],["34980.9","0"]],"u":20009698,"seq":14108030475}}'
2023-11-02 14:54:11,685 DEBUG ++Rcv raw: b'\x81~\x01M{"topic":"orderbook.50.BTCUSDC","ts":1698936848104,"type":"delta","data":{"s":"BTCUSDC","b":[["34957.03","0.0014"],["34952.13","0.00057"],["34954.72","0"],["34935.13","0"]],"a":[["34961.26","0.007356"],["34968.99","0.112509"],["34980.89","0.317395"],["34969.6","0"],["34961.28","0"],["34961.99","0"]],"u":20009699,"seq":14108030508}}'
2023-11-02 14:54:11,685 DEBUG ++Rcv decoded: fin=1 opcode=1 data=b'{"topic":"orderbook.50.BTCUSDC","ts":1698936848104,"type":"delta","data":{"s":"BTCUSDC","b":[["34957.03","0.0014"],["34952.13","0.00057"],["34954.72","0"],["34935.13","0"]],"a":[["34961.26","0.007356"],["34968.99","0.112509"],["34980.89","0.317395"],["34969.6","0"],["34961.28","0"],["34961.99","0"]],"u":20009699,"seq":14108030508}}'
2023-11-02 14:54:11,685 DEBUG ++Rcv raw: b'\x81~\x00\xd5{"topic":"orderbook.50.BTCUSDC","ts":1698936848123,"type":"delta","data":{"s":"BTCUSDC","b":[["34935.13","1.373172"],["34957.02","0"]],"a":[["34980.9","0.528984"],["34961.27","0"]],"u":20009700,"seq":14108030528}}'
2023-11-02 14:54:11,685 DEBUG ++Rcv decoded: fin=1 opcode=1 data=b'{"topic":"orderbook.50.BTCUSDC","ts":1698936848123,"type":"delta","data":{"s":"BTCUSDC","b":[["34935.13","1.373172"],["34957.02","0"]],"a":[["34980.9","0.528984"],["34961.27","0"]],"u":20009700,"seq":14108030528}}'
2023-11-02 14:54:11,685 DEBUG ++Rcv raw: b'\x81~\x00\xa9{"topic":"orderbook.50.BTCUSDC","ts":1698936848143,"type":"delta","data":{"s":"BTCUSDC","b":[["34956","0.0324"],["34935.13","0"]],"a":[],"u":20009701,"seq":14108030565}}'
2023-11-02 14:54:11,685 DEBUG ++Rcv decoded: fin=1 opcode=1 data=b'{"topic":"orderbook.50.BTCUSDC","ts":1698936848143,"type":"delta","data":{"s":"BTCUSDC","b":[["34956","0.0324"],["34935.13","0"]],"a":[],"u":20009701,"seq":14108030565}}'
2023-11-02 14:54:11,686 DEBUG ++Rcv raw: b'\x81~\x00\xae{"topic":"orderbook.50.BTCUSDC","ts":1698936848164,"type":"delta","data":{"s":"BTCUSDC","b":[["34935.13","1.373172"],["34953.17","0"]],"a":[],"u":20009702,"seq":14108030583}}'
2023-11-02 14:54:11,686 DEBUG ++Rcv decoded: fin=1 opcode=1 data=b'{"topic":"orderbook.50.BTCUSDC","ts":1698936848164,"type":"delta","data":{"s":"BTCUSDC","b":[["34935.13","1.373172"],["34953.17","0"]],"a":[],"u":20009702,"seq":14108030583}}'
2023-11-02 14:54:11,686 DEBUG ++Rcv raw: b'\x81~\x00\xd5{"topic":"orderbook.50.BTCUSDC","ts":1698936848184,"type":"delta","data":{"s":"BTCUSDC","b":[["34953.72","0.057218"],["34935.13","0"]],"a":[["34960.45","0.057207"],["34980.9","0"]],"u":20009703,"seq":14108030595}}'
2023-11-02 14:54:11,686 DEBUG ++Rcv decoded: fin=1 opcode=1 data=b'{"topic":"orderbook.50.BTCUSDC","ts":1698936848184,"type":"delta","data":{"s":"BTCUSDC","b":[["34953.72","0.057218"],["34935.13","0"]],"a":[["34960.45","0.057207"],["34980.9","0"]],"u":20009703,"seq":14108030595}}'
2023-11-02 14:54:11,686 DEBUG ++Rcv raw: b'\x81~\x00\xc2{"topic":"orderbook.50.BTCUSDC","ts":1698936848204,"type":"delta","data":{"s":"BTCUSDC","b":[["34957.03","0.0044"]],"a":[["34960.44","0.04168"],["34961.26","0"]],"u":20009704,"seq":14108030608}}'
2023-11-02 14:54:11,686 DEBUG ++Rcv decoded: fin=1 opcode=1 data=b'{"topic":"orderbook.50.BTCUSDC","ts":1698936848204,"type":"delta","data":{"s":"BTCUSDC","b":[["34957.03","0.0044"]],"a":[["34960.44","0.04168"],["34961.26","0"]],"u":20009704,"seq":14108030608}}'
2023-11-02 14:54:11,686 DEBUG ++Rcv raw: b'\x81~\x00\xae{"topic":"orderbook.50.BTCUSDC","ts":1698936848224,"type":"delta","data":{"s":"BTCUSDC","b":[["34937.17","0.171737"],["34935.14","0"]],"a":[],"u":20009705,"seq":14108030613}}'
2023-11-02 14:54:11,686 DEBUG ++Rcv decoded: fin=1 opcode=1 data=b'{"topic":"orderbook.50.BTCUSDC","ts":1698936848224,"type":"delta","data":{"s":"BTCUSDC","b":[["34937.17","0.171737"],["34935.14","0"]],"a":[],"u":20009705,"seq":14108030613}}'
2023-11-02 14:54:11,687 DEBUG ++Rcv raw: b'\x81~\x00\xab{"topic":"orderbook.50.BTCUSDC","ts":1698936848243,"type":"delta","data":{"s":"BTCUSDC","b":[["34948.02","0.001627"],["34936","0"]],"a":[],"u":20009706,"seq":14108030638}}'
2023-11-02 14:54:11,687 DEBUG ++Rcv decoded: fin=1 opcode=1 data=b'{"topic":"orderbook.50.BTCUSDC","ts":1698936848243,"type":"delta","data":{"s":"BTCUSDC","b":[["34948.02","0.001627"],["34936","0"]],"a":[],"u":20009706,"seq":14108030638}}'
2023-11-02 14:54:11,687 DEBUG ++Rcv raw: b'\x81~\x00\xa9{"topic":"orderbook.50.BTCUSDC","ts":1698936848264,"type":"delta","data":{"s":"BTCUSDC","b":[["34936","0.0341"],["34947.01","0"]],"a":[],"u":20009707,"seq":14108030647}}'
2023-11-02 14:54:11,687 DEBUG ++Rcv decoded: fin=1 opcode=1 data=b'{"topic":"orderbook.50.BTCUSDC","ts":1698936848264,"type":"delta","data":{"s":"BTCUSDC","b":[["34936","0.0341"],["34947.01","0"]],"a":[],"u":20009707,"seq":14108030647}}'
2023-11-02 14:54:11,688 DEBUG ++Rcv raw: b'\x81~\x00\x9d{"topic":"orderbook.50.BTCUSDC","ts":1698936848283,"type":"delta","data":{"s":"BTCUSDC","b":[],"a":[["34980.89","0.317895"]],"u":20009708,"seq":14108030667}}'
2023-11-02 14:54:11,688 DEBUG ++Rcv decoded: fin=1 opcode=1 data=b'{"topic":"orderbook.50.BTCUSDC","ts":1698936848283,"type":"delta","data":{"s":"BTCUSDC","b":[],"a":[["34980.89","0.317895"]],"u":20009708,"seq":14108030667}}'
2023-11-02 14:54:11,688 DEBUG ++Rcv raw: b'\x81~\x01<{"topic":"orderbook.50.BTCUSDC","ts":1698936848364,"type":"delta","data":{"s":"BTCUSDC","b":[["34938.42","0.286217"],["34935.14","0.823909"],["34935.13","1.373172"],["34937.16","0"],["34953.72","0"],["34947","0"]],"a":[["34960.44","0.007356"],["34980.9","0.528984"],["34960.45","0"]],"u":20009709,"seq":14108030708}}'
2023-11-02 14:54:11,688 DEBUG ++Rcv decoded: fin=1 opcode=1 data=b'{"topic":"orderbook.50.BTCUSDC","ts":1698936848364,"type":"delta","data":{"s":"BTCUSDC","b":[["34938.42","0.286217"],["34935.14","0.823909"],["34935.13","1.373172"],["34937.16","0"],["34953.72","0"],["34947","0"]],"a":[["34960.44","0.007356"],["34980.9","0.528984"],["34960.45","0"]],"u":20009709,"seq":14108030708}}'
2023-11-02 14:54:11,688 DEBUG ++Rcv raw: b'\x81~\x01\x86{"topic":"orderbook.50.BTCUSDC","ts":1698936848384,"type":"delta","data":{"s":"BTCUSDC","b":[["34959.15","0.108154"],["34957.03","0.003"],["34956.42","0.0859"],["34954.68","0.057216"],["34948.29","0.114454"],["34936","0"],["34937.17","0"],["34935.14","0"],["34935.13","0"]],"a":[["34981.28","0.000562"],["34981.45","0.065357"],["34969","0"],["34963.3","0"]],"u":20009710,"seq":14108030737}}'
2023-11-02 14:54:11,688 DEBUG ++Rcv decoded: fin=1 opcode=1 data=b'{"topic":"orderbook.50.BTCUSDC","ts":1698936848384,"type":"delta","data":{"s":"BTCUSDC","b":[["34959.15","0.108154"],["34957.03","0.003"],["34956.42","0.0859"],["34954.68","0.057216"],["34948.29","0.114454"],["34936","0"],["34937.17","0"],["34935.14","0"],["34935.13","0"]],"a":[["34981.28","0.000562"],["34981.45","0.065357"],["34969","0"],["34963.3","0"]],"u":20009710,"seq":14108030737}}'
2023-11-02 14:54:11,790 DEBUG ++Rcv raw: b'\x81~\x01\x7f{"topic":"orderbook.50.BTCUSDC","ts":1698936848404,"type":"delta","data":{"s":"BTCUSDC","b":[["34954.71","0.079428"],["34948.65","0.1875"],["34935.14","0.823909"],["34957.03","0"],["34952.13","0"]],"a":[["34960.44","0.009356"],["34964.79","0.070143"],["34969.88","0.051544"],["34973.71","0.000239"],["34968.99","0"],["34963.17","0"],["34981.45","0"]],"u":20009711,"seq":14108030761}}'
2023-11-02 14:54:11,790 DEBUG ++Rcv decoded: fin=1 opcode=1 data=b'{"topic":"orderbook.50.BTCUSDC","ts":1698936848404,"type":"delta","data":{"s":"BTCUSDC","b":[["34954.71","0.079428"],["34948.65","0.1875"],["34935.14","0.823909"],["34957.03","0"],["34952.13","0"]],"a":[["34960.44","0.009356"],["34964.79","0.070143"],["34969.88","0.051544"],["34973.71","0.000239"],["34968.99","0"],["34963.17","0"],["34981.45","0"]],"u":20009711,"seq":14108030761}}'
2023-11-02 14:54:11,790 DEBUG ++Rcv raw: b'\x81~\x00\xd6{"topic":"orderbook.50.BTCUSDC","ts":1698936848423,"type":"delta","data":{"s":"BTCUSDC","b":[["34948.66","0.112505"],["34949.55","0"]],"a":[["34981.45","0.065357"],["34966.45","0"]],"u":20009712,"seq":14108030767}}'
2023-11-02 14:54:11,790 DEBUG ++Rcv decoded: fin=1 opcode=1 data=b'{"topic":"orderbook.50.BTCUSDC","ts":1698936848423,"type":"delta","data":{"s":"BTCUSDC","b":[["34948.66","0.112505"],["34949.55","0"]],"a":[["34981.45","0.065357"],["34966.45","0"]],"u":20009712,"seq":14108030767}}'
2023-11-02 14:54:11,790 DEBUG ++Rcv raw: b'\x81~\x01\x00{"topic":"orderbook.50.BTCUSDC","ts":1698936848443,"type":"delta","data":{"s":"BTCUSDC","b":[["34956.43","0.026506"],["34952.99","0.051547"],["34948.67","0.003561"],["34951.27","0"],["34954.71","0"],["34935.14","0"]],"a":[],"u":20009713,"seq":14108030783}}'
2023-11-02 14:54:11,790 DEBUG ++Rcv decoded: fin=1 opcode=1 data=b'{"topic":"orderbook.50.BTCUSDC","ts":1698936848443,"type":"delta","data":{"s":"BTCUSDC","b":[["34956.43","0.026506"],["34952.99","0.051547"],["34948.67","0.003561"],["34951.27","0"],["34954.71","0"],["34935.14","0"]],"a":[],"u":20009713,"seq":14108030783}}'
2023-11-02 14:54:11,791 DEBUG ++Rcv raw: b'\x81~\x00\xeb{"topic":"orderbook.50.BTCUSDC","ts":1698936848464,"type":"delta","data":{"s":"BTCUSDC","b":[["34935.14","0.823909"],["34935.13","1.373172"],["34948.02","0"],["34954.68","0"]],"a":[["34960.44","0.002"]],"u":20009714,"seq":14108030798}}'
2023-11-02 14:54:11,791 DEBUG ++Rcv decoded: fin=1 opcode=1 data=b'{"topic":"orderbook.50.BTCUSDC","ts":1698936848464,"type":"delta","data":{"s":"BTCUSDC","b":[["34935.14","0.823909"],["34935.13","1.373172"],["34948.02","0"],["34954.68","0"]],"a":[["34960.44","0.002"]],"u":20009714,"seq":14108030798}}'
2023-11-02 14:54:11,791 DEBUG ++Rcv raw: b'\x81~\x00\xd6{"topic":"orderbook.50.BTCUSDC","ts":1698936848484,"type":"delta","data":{"s":"BTCUSDC","b":[["34954.11","0.057217"],["34939.22","0"]],"a":[["34960.99","0.057206"],["34981.45","0"]],"u":20009715,"seq":14108030810}}'
2023-11-02 14:54:11,791 DEBUG ++Rcv decoded: fin=1 opcode=1 data=b'{"topic":"orderbook.50.BTCUSDC","ts":1698936848484,"type":"delta","data":{"s":"BTCUSDC","b":[["34954.11","0.057217"],["34939.22","0"]],"a":[["34960.99","0.057206"],["34981.45","0"]],"u":20009715,"seq":14108030810}}'
2023-11-02 14:54:11,791 DEBUG ++Rcv raw: b'\x81~\x00\xc6{"topic":"orderbook.50.BTCUSDC","ts":1698936848504,"type":"delta","data":{"s":"BTCUSDC","b":[],"a":[["34960.98","0.030786"],["34964.79","0.051549"],["34981.28","0"]],"u":20009716,"seq":14108030814}}'
2023-11-02 14:54:11,791 DEBUG ++Rcv decoded: fin=1 opcode=1 data=b'{"topic":"orderbook.50.BTCUSDC","ts":1698936848504,"type":"delta","data":{"s":"BTCUSDC","b":[],"a":[["34960.98","0.030786"],["34964.79","0.051549"],["34981.28","0"]],"u":20009716,"seq":14108030814}}'
2023-11-02 14:54:11,792 DEBUG ++Rcv raw: b'\x81~\x00\xad{"topic":"orderbook.50.BTCUSDC","ts":1698936848563,"type":"delta","data":{"s":"BTCUSDC","b":[["34957.04","0.01144"],["34935.13","0"]],"a":[],"u":20009717,"seq":14108030850}}'
2023-11-02 14:54:11,792 DEBUG ++Rcv decoded: fin=1 opcode=1 data=b'{"topic":"orderbook.50.BTCUSDC","ts":1698936848563,"type":"delta","data":{"s":"BTCUSDC","b":[["34957.04","0.01144"],["34935.13","0"]],"a":[],"u":20009717,"seq":14108030850}}'
2023-11-02 14:54:11,792 DEBUG ++Rcv raw: b'\x81~\x00\xc3{"topic":"orderbook.50.BTCUSDC","ts":1698936848703,"type":"delta","data":{"s":"BTCUSDC","b":[["34935.13","1.373172"],["34959.15","0"]],"a":[["34960.44","0.0018"]],"u":20009718,"seq":14108030910}}'
2023-11-02 14:54:11,792 DEBUG ++Rcv decoded: fin=1 opcode=1 data=b'{"topic":"orderbook.50.BTCUSDC","ts":1698936848703,"type":"delta","data":{"s":"BTCUSDC","b":[["34935.13","1.373172"],["34959.15","0"]],"a":[["34960.44","0.0018"]],"u":20009718,"seq":14108030910}}'
2023-11-02 14:54:11,792 DEBUG ++Rcv raw: b'\x81~\x01\x8b{"topic":"orderbook.50.BTCUSDC","ts":1698936848723,"type":"delta","data":{"s":"BTCUSDC","b":[["34957.04","0.012075"],["34954.71","0.08587"],["34952.15","0.00057"],["34951.27","0.051541"],["34956.43","0"],["34952.99","0"],["34935.13","0"]],"a":[["34963.3","0.0859"],["34965.33","0.00057"],["34973.63","0.000239"],["34979.79","0"],["34980.9","0"],["34980.89","0"]],"u":20009719,"seq":14108030932}}'
2023-11-02 14:54:11,792 DEBUG ++Rcv decoded: fin=1 opcode=1 data=b'{"topic":"orderbook.50.BTCUSDC","ts":1698936848723,"type":"delta","data":{"s":"BTCUSDC","b":[["34957.04","0.012075"],["34954.71","0.08587"],["34952.15","0.00057"],["34951.27","0.051541"],["34956.43","0"],["34952.99","0"],["34935.13","0"]],"a":[["34963.3","0.0859"],["34965.33","0.00057"],["34973.63","0.000239"],["34979.79","0"],["34980.9","0"],["34980.89","0"]],"u":20009719,"seq":14108030932}}'
2023-11-02 14:54:11,792 DEBUG ++Rcv raw: b'\x81~\x00\xd4{"topic":"orderbook.50.BTCUSDC","ts":1698936848744,"type":"delta","data":{"s":"BTCUSDC","b":[["34957.05","0.0014"],["34935.14","0"]],"a":[["34963.17","0.051542"],["34964.79","0"]],"u":20009720,"seq":14108030940}}'
2023-11-02 14:54:11,793 DEBUG ++Rcv decoded: fin=1 opcode=1 data=b'{"topic":"orderbook.50.BTCUSDC","ts":1698936848744,"type":"delta","data":{"s":"BTCUSDC","b":[["34957.05","0.0014"],["34935.14","0"]],"a":[["34963.17","0.051542"],["34964.79","0"]],"u":20009720,"seq":14108030940}}'
2023-11-02 14:54:11,793 DEBUG ++Rcv raw: b'\x81~\x00\x9d{"topic":"orderbook.50.BTCUSDC","ts":1698936848764,"type":"delta","data":{"s":"BTCUSDC","b":[["34957.04","0.009075"]],"a":[],"u":20009721,"seq":14108030946}}'
2023-11-02 14:54:11,793 DEBUG ++Rcv decoded: fin=1 opcode=1 data=b'{"topic":"orderbook.50.BTCUSDC","ts":1698936848764,"type":"delta","data":{"s":"BTCUSDC","b":[["34957.04","0.009075"]],"a":[],"u":20009721,"seq":14108030946}}'
2023-11-02 14:54:11,793 DEBUG ++Rcv raw: b'\x81~\x00\xae{"topic":"orderbook.50.BTCUSDC","ts":1698936848804,"type":"delta","data":{"s":"BTCUSDC","b":[["34935.14","0.823909"],["34957.04","0"]],"a":[],"u":20009722,"seq":14108030965}}'
2023-11-02 14:54:11,793 DEBUG ++Rcv decoded: fin=1 opcode=1 data=b'{"topic":"orderbook.50.BTCUSDC","ts":1698936848804,"type":"delta","data":{"s":"BTCUSDC","b":[["34935.14","0.823909"],["34957.04","0"]],"a":[],"u":20009722,"seq":14108030965}}'
2023-11-02 14:54:11,794 DEBUG ++Rcv raw: b'\x81~\x00\xae{"topic":"orderbook.50.BTCUSDC","ts":1698936848823,"type":"delta","data":{"s":"BTCUSDC","b":[["34935.13","1.373172"],["34956.42","0"]],"a":[],"u":20009723,"seq":14108030979}}'
2023-11-02 14:54:11,794 DEBUG ++Rcv decoded: fin=1 opcode=1 data=b'{"topic":"orderbook.50.BTCUSDC","ts":1698936848823,"type":"delta","data":{"s":"BTCUSDC","b":[["34935.13","1.373172"],["34956.42","0"]],"a":[],"u":20009723,"seq":14108030979}}'
2023-11-02 14:54:11,794 DEBUG ++Rcv raw: b'\x81~\x00\xae{"topic":"orderbook.50.BTCUSDC","ts":1698936848884,"type":"delta","data":{"s":"BTCUSDC","b":[["34936.49","0.205817"],["34935.13","0"]],"a":[],"u":20009724,"seq":14108030999}}'
2023-11-02 14:54:11,794 DEBUG ++Rcv decoded: fin=1 opcode=1 data=b'{"topic":"orderbook.50.BTCUSDC","ts":1698936848884,"type":"delta","data":{"s":"BTCUSDC","b":[["34936.49","0.205817"],["34935.13","0"]],"a":[],"u":20009724,"seq":14108030999}}'
2023-11-02 14:54:11,794 DEBUG ++Rcv raw: b'\x81~\x00\xd6{"topic":"orderbook.50.BTCUSDC","ts":1698936848943,"type":"delta","data":{"s":"BTCUSDC","b":[["34957.8","0.104731"],["34957.06","0.009075"],["34936.35","0"],["34935.14","0"]],"a":[],"u":20009725,"seq":14108031033}}'
2023-11-02 14:54:11,794 DEBUG ++Rcv decoded: fin=1 opcode=1 data=b'{"topic":"orderbook.50.BTCUSDC","ts":1698936848943,"type":"delta","data":{"s":"BTCUSDC","b":[["34957.8","0.104731"],["34957.06","0.009075"],["34936.35","0"],["34935.14","0"]],"a":[],"u":20009725,"seq":14108031033}}'
2023-11-02 14:54:11,795 DEBUG ++Rcv raw: b'\x81~\x00\xd3{"topic":"orderbook.50.BTCUSDC","ts":1698936848964,"type":"delta","data":{"s":"BTCUSDC","b":[["34936.35","0.1875"],["34952.15","0"]],"a":[["34979.79","0.02859"],["34965.33","0"]],"u":20009726,"seq":14108031047}}'
2023-11-02 14:54:11,795 DEBUG ++Rcv decoded: fin=1 opcode=1 data=b'{"topic":"orderbook.50.BTCUSDC","ts":1698936848964,"type":"delta","data":{"s":"BTCUSDC","b":[["34936.35","0.1875"],["34952.15","0"]],"a":[["34979.79","0.02859"],["34965.33","0"]],"u":20009726,"seq":14108031047}}'
2023-11-02 14:54:11,795 DEBUG ++Rcv raw: b'\x81~\x00\xd6{"topic":"orderbook.50.BTCUSDC","ts":1698936848983,"type":"delta","data":{"s":"BTCUSDC","b":[["34935.14","0.823909"],["34957.05","0"]],"a":[["34980.89","0.317395"],["34973.71","0"]],"u":20009727,"seq":14108031063}}'
2023-11-02 14:54:11,796 DEBUG ++Rcv decoded: fin=1 opcode=1 data=b'{"topic":"orderbook.50.BTCUSDC","ts":1698936848983,"type":"delta","data":{"s":"BTCUSDC","b":[["34935.14","0.823909"],["34957.05","0"]],"a":[["34980.89","0.317395"],["34973.71","0"]],"u":20009727,"seq":14108031063}}'
2023-11-02 14:54:11,796 DEBUG ++Rcv raw: b'\x81~\x01&{"topic":"orderbook.50.BTCUSDC","ts":1698936849003,"type":"delta","data":{"s":"BTCUSDC","b":[["34959.12","0.099476"],["34957.81","0.0014"],["34954.59","0.057217"],["34939.42","0.286209"],["34938.42","0"],["34954.11","0"],["34935.14","0"],["34957.8","0"]],"a":[],"u":20009728,"seq":14108031087}}'
2023-11-02 14:54:11,796 DEBUG ++Rcv decoded: fin=1 opcode=1 data=b'{"topic":"orderbook.50.BTCUSDC","ts":1698936849003,"type":"delta","data":{"s":"BTCUSDC","b":[["34959.12","0.099476"],["34957.81","0.0014"],["34954.59","0.057217"],["34939.42","0.286209"],["34938.42","0"],["34954.11","0"],["34935.14","0"],["34957.8","0"]],"a":[],"u":20009728,"seq":14108031087}}'
2023-11-02 14:54:11,797 DEBUG ++Rcv raw: b'\x81~\x00\xfa{"topic":"orderbook.50.BTCUSDC","ts":1698936849023,"type":"delta","data":{"s":"BTCUSDC","b":[["34959.13","0.0014"],["34956.42","0.0859"],["34957.81","0"],["34936.35","0"]],"a":[["34980.9","0.528984"],["34960.44","0"]],"u":20009729,"seq":14108031107}}'
2023-11-02 14:54:11,797 DEBUG ++Rcv decoded: fin=1 opcode=1 data=b'{"topic":"orderbook.50.BTCUSDC","ts":1698936849023,"type":"delta","data":{"s":"BTCUSDC","b":[["34959.13","0.0014"],["34956.42","0.0859"],["34957.81","0"],["34936.35","0"]],"a":[["34980.9","0.528984"],["34960.44","0"]],"u":20009729,"seq":14108031107}}'
2023-11-02 14:54:11,797 DEBUG ++Rcv raw: b'\x81~\x00\xf9{"topic":"orderbook.50.BTCUSDC","ts":1698936849043,"type":"delta","data":{"s":"BTCUSDC","b":[["34936.35","0.1875"],["34935.14","0.823909"],["34957.06","0"],["34959.12","0"]],"a":[["34967.68","0.001"],["34980.9","0"]],"u":20009730,"seq":14108031127}}'
2023-11-02 14:54:11,798 DEBUG ++Rcv decoded: fin=1 opcode=1 data=b'{"topic":"orderbook.50.BTCUSDC","ts":1698936849043,"type":"delta","data":{"s":"BTCUSDC","b":[["34936.35","0.1875"],["34935.14","0.823909"],["34957.06","0"],["34959.12","0"]],"a":[["34967.68","0.001"],["34980.9","0"]],"u":20009730,"seq":14108031127}}'
2023-11-02 14:54:11,798 DEBUG ++Rcv raw: b'\x81~\x00\xad{"topic":"orderbook.50.BTCUSDC","ts":1698936849123,"type":"delta","data":{"s":"BTCUSDC","b":[],"a":[["34980.9","0.528984"],["34971.23","0"]],"u":20009731,"seq":14108031193}}'
2023-11-02 14:54:11,798 DEBUG ++Rcv decoded: fin=1 opcode=1 data=b'{"topic":"orderbook.50.BTCUSDC","ts":1698936849123,"type":"delta","data":{"s":"BTCUSDC","b":[],"a":[["34980.9","0.528984"],["34971.23","0"]],"u":20009731,"seq":14108031193}}'
2023-11-02 14:54:11,799 DEBUG ++Rcv raw: b'\x81~\x00\xae{"topic":"orderbook.50.BTCUSDC","ts":1698936849144,"type":"delta","data":{"s":"BTCUSDC","b":[],"a":[["34981.28","0.000562"],["34971.22","0"]],"u":20009732,"seq":14108031196}}'
2023-11-02 14:54:11,799 DEBUG ++Rcv decoded: fin=1 opcode=1 data=b'{"topic":"orderbook.50.BTCUSDC","ts":1698936849144,"type":"delta","data":{"s":"BTCUSDC","b":[],"a":[["34981.28","0.000562"],["34971.22","0"]],"u":20009732,"seq":14108031196}}'
2023-11-02 14:54:11,800 DEBUG ++Rcv raw: b'\x81~\x00\xac{"topic":"orderbook.50.BTCUSDC","ts":1698936849164,"type":"delta","data":{"s":"BTCUSDC","b":[],"a":[["34983.74","0.1875"],["34960.99","0"]],"u":20009733,"seq":14108031209}}'
2023-11-02 14:54:11,800 DEBUG ++Rcv decoded: fin=1 opcode=1 data=b'{"topic":"orderbook.50.BTCUSDC","ts":1698936849164,"type":"delta","data":{"s":"BTCUSDC","b":[],"a":[["34983.74","0.1875"],["34960.99","0"]],"u":20009733,"seq":14108031209}}'
2023-11-02 14:54:11,800 DEBUG ++Rcv raw: b'\x81~\x00\xd4{"topic":"orderbook.50.BTCUSDC","ts":1698936849184,"type":"delta","data":{"s":"BTCUSDC","b":[],"a":[["34960.81","0.057206"],["34981.8","0.0005"],["34983.74","0"],["34960.98","0"]],"u":20009734,"seq":14108031220}}'
2023-11-02 14:54:11,800 DEBUG ++Rcv decoded: fin=1 opcode=1 data=b'{"topic":"orderbook.50.BTCUSDC","ts":1698936849184,"type":"delta","data":{"s":"BTCUSDC","b":[],"a":[["34960.81","0.057206"],["34981.8","0.0005"],["34983.74","0"],["34960.98","0"]],"u":20009734,"seq":14108031220}}'
2023-11-02 14:54:11,801 DEBUG ++Rcv raw: b'\x81~\x00\xd5{"topic":"orderbook.50.BTCUSDC","ts":1698936849204,"type":"delta","data":{"s":"BTCUSDC","b":[["34935.13","1.373172"],["34940.95","0"]],"a":[["34974.47","0.044967"],["34981.8","0"]],"u":20009735,"seq":14108031235}}'
2023-11-02 14:54:11,801 DEBUG ++Rcv decoded: fin=1 opcode=1 data=b'{"topic":"orderbook.50.BTCUSDC","ts":1698936849204,"type":"delta","data":{"s":"BTCUSDC","b":[["34935.13","1.373172"],["34940.95","0"]],"a":[["34974.47","0.044967"],["34981.8","0"]],"u":20009735,"seq":14108031235}}'
2023-11-02 14:54:11,801 DEBUG ++Rcv raw: b'\x81~\x00\xfc{"topic":"orderbook.50.BTCUSDC","ts":1698936849224,"type":"delta","data":{"s":"BTCUSDC","b":[["34940.01","0.171728"],["34939.37","0.089313"],["34935.13","0"],["34940.13","0"]],"a":[["34981.8","0.0005"],["34973.63","0"]],"u":20009736,"seq":14108031243}}'
2023-11-02 14:54:11,802 DEBUG ++Rcv decoded: fin=1 opcode=1 data=b'{"topic":"orderbook.50.BTCUSDC","ts":1698936849224,"type":"delta","data":{"s":"BTCUSDC","b":[["34940.01","0.171728"],["34939.37","0.089313"],["34935.13","0"],["34940.13","0"]],"a":[["34981.8","0.0005"],["34973.63","0"]],"u":20009736,"seq":14108031243}}'
2023-11-02 14:54:11,802 DEBUG ++Rcv raw: b'\x81~\x00\xac{"topic":"orderbook.50.BTCUSDC","ts":1698936849243,"type":"delta","data":{"s":"BTCUSDC","b":[],"a":[["34960.8","0.007356"],["34981.8","0"]],"u":20009737,"seq":14108031255}}'
2023-11-02 14:54:11,803 DEBUG ++Rcv decoded: fin=1 opcode=1 data=b'{"topic":"orderbook.50.BTCUSDC","ts":1698936849243,"type":"delta","data":{"s":"BTCUSDC","b":[],"a":[["34960.8","0.007356"],["34981.8","0"]],"u":20009737,"seq":14108031255}}'
2023-11-02 14:54:11,804 DEBUG ++Rcv raw: b'\x81~\x00\xae{"topic":"orderbook.50.BTCUSDC","ts":1698936849263,"type":"delta","data":{"s":"BTCUSDC","b":[["34959.14","0.009075"],["34948.65","0"]],"a":[],"u":20009738,"seq":14108031260}}'
2023-11-02 14:54:11,805 DEBUG ++Rcv decoded: fin=1 opcode=1 data=b'{"topic":"orderbook.50.BTCUSDC","ts":1698936849263,"type":"delta","data":{"s":"BTCUSDC","b":[["34959.14","0.009075"],["34948.65","0"]],"a":[],"u":20009738,"seq":14108031260}}'
2023-11-02 14:54:11,805 DEBUG ++Rcv raw: b'\x81~\x01-{"topic":"orderbook.50.BTCUSDC","ts":1698936849283,"type":"delta","data":{"s":"BTCUSDC","b":[["34959.13","0.0044"],["34948.66","0.068676"]],"a":[["34960.66","0.057207"],["34966.38","0.114395"],["34975.18","0.285917"],["34976.37","0"],["34960.81","0"],["34967.48","0"]],"u":20009739,"seq":14108031282}}'
2023-11-02 14:54:11,805 DEBUG ++Rcv decoded: fin=1 opcode=1 data=b'{"topic":"orderbook.50.BTCUSDC","ts":1698936849283,"type":"delta","data":{"s":"BTCUSDC","b":[["34959.13","0.0044"],["34948.66","0.068676"]],"a":[["34960.66","0.057207"],["34966.38","0.114395"],["34975.18","0.285917"],["34976.37","0"],["34960.81","0"],["34967.48","0"]],"u":20009739,"seq":14108031282}}'
2023-11-02 14:54:11,805 DEBUG ++Rcv raw: b'\x81~\x00\xd4{"topic":"orderbook.50.BTCUSDC","ts":1698936849303,"type":"delta","data":{"s":"BTCUSDC","b":[["34948.64","0.1875"],["34959.13","0"]],"a":[["34966.37","0.068642"],["34966.73","0"]],"u":20009740,"seq":14108031295}}'
2023-11-02 14:54:11,805 DEBUG ++Rcv decoded: fin=1 opcode=1 data=b'{"topic":"orderbook.50.BTCUSDC","ts":1698936849303,"type":"delta","data":{"s":"BTCUSDC","b":[["34948.64","0.1875"],["34959.13","0"]],"a":[["34966.37","0.068642"],["34966.73","0"]],"u":20009740,"seq":14108031295}}'
2023-11-02 14:54:11,806 DEBUG ++Rcv raw: b'\x81~\x00\x9d{"topic":"orderbook.50.BTCUSDC","ts":1698936849323,"type":"delta","data":{"s":"BTCUSDC","b":[["34948.66","0.103921"]],"a":[],"u":20009741,"seq":14108031296}}'
2023-11-02 14:54:11,806 DEBUG ++Rcv decoded: fin=1 opcode=1 data=b'{"topic":"orderbook.50.BTCUSDC","ts":1698936849323,"type":"delta","data":{"s":"BTCUSDC","b":[["34948.66","0.103921"]],"a":[],"u":20009741,"seq":14108031296}}'
2023-11-02 14:54:11,806 DEBUG ++Rcv raw: b'\x81~\x02\x0c{"topic":"orderbook.50.BTCUSDC","ts":1698936849363,"type":"delta","data":{"s":"BTCUSDC","b":[["34960.29","0.053806"],["34960.28","0.096177"],["34959.15","0.0014"],["34958.14","0.0859"],["34958","0.0324"],["34936.35","0"],["34939.37","0"],["34936.49","0"],["34935.14","0"],["34939.42","0"]],"a":[["34963.16","0.007356"],["34981.8","0.0005"],["34983.74","0.1875"],["34984.65","0.457343"],["34984.83","0.0002"],["34965.02","0"],["34960.8","0"],["34963.17","0"],["34963.3","0"],["34960.66","0"]],"u":20009742,"seq":14108031375}}'
2023-11-02 14:54:11,806 DEBUG ++Rcv decoded: fin=1 opcode=1 data=b'{"topic":"orderbook.50.BTCUSDC","ts":1698936849363,"type":"delta","data":{"s":"BTCUSDC","b":[["34960.29","0.053806"],["34960.28","0.096177"],["34959.15","0.0014"],["34958.14","0.0859"],["34958","0.0324"],["34936.35","0"],["34939.37","0"],["34936.49","0"],["34935.14","0"],["34939.42","0"]],"a":[["34963.16","0.007356"],["34981.8","0.0005"],["34983.74","0.1875"],["34984.65","0.457343"],["34984.83","0.0002"],["34965.02","0"],["34960.8","0"],["34963.17","0"],["34963.3","0"],["34960.66","0"]],"u":20009742,"seq":14108031375}}'
2023-11-02 14:54:11,806 DEBUG ++Rcv raw: b'\x81~\x01m{"topic":"orderbook.50.BTCUSDC","ts":1698936849383,"type":"delta","data":{"s":"BTCUSDC","b":[["34954.71","0.051541"],["34939.42","0.286209"],["34939.37","0.089313"],["34936.49","0.205817"],["34960.29","0"],["34960.28","0"],["34951.27","0"]],"a":[["34963.16","0.007156"],["34966.37","0.1119"],["34968.05","0.00057"],["34984.83","0"]],"u":20009743,"seq":14108031401}}'
2023-11-02 14:54:11,806 DEBUG ++Rcv decoded: fin=1 opcode=1 data=b'{"topic":"orderbook.50.BTCUSDC","ts":1698936849383,"type":"delta","data":{"s":"BTCUSDC","b":[["34954.71","0.051541"],["34939.42","0.286209"],["34939.37","0.089313"],["34936.49","0.205817"],["34960.29","0"],["34960.28","0"],["34951.27","0"]],"a":[["34963.16","0.007156"],["34966.37","0.1119"],["34968.05","0.00057"],["34984.83","0"]],"u":20009743,"seq":14108031401}}'
2023-11-02 14:54:11,806 DEBUG ++Rcv raw: b'\x81~\x01\x1e{"topic":"orderbook.50.BTCUSDC","ts":1698936849403,"type":"delta","data":{"s":"BTCUSDC","b":[["34960.29","0.002"],["34941.45","0.028"],["34936.35","0.1875"],["34948.29","0"],["34959.14","0"],["34939.42","0"]],"a":[["34984.83","0.0002"],["34967.68","0"]],"u":20009744,"seq":14108031434}}'
2023-11-02 14:54:11,806 DEBUG ++Rcv decoded: fin=1 opcode=1 data=b'{"topic":"orderbook.50.BTCUSDC","ts":1698936849403,"type":"delta","data":{"s":"BTCUSDC","b":[["34960.29","0.002"],["34941.45","0.028"],["34936.35","0.1875"],["34948.29","0"],["34959.14","0"],["34939.42","0"]],"a":[["34984.83","0.0002"],["34967.68","0"]],"u":20009744,"seq":14108031434}}'
2023-11-02 14:54:11,806 DEBUG ++Rcv raw: b'\x81~\x01Q{"topic":"orderbook.50.BTCUSDC","ts":1698936849423,"type":"delta","data":{"s":"BTCUSDC","b":[["34955.03","0.057216"],["34949.17","0.114451"],["34940.38","0.286201"],["34936.35","0"],["34940.01","0"],["34954.59","0"]],"a":[["34961.16","0.057206"],["34967.97","0.028603"],["34967.72","0"],["34964.01","0"]],"u":20009745,"seq":14108031473}}'
2023-11-02 14:54:11,806 DEBUG ++Rcv decoded: fin=1 opcode=1 data=b'{"topic":"orderbook.50.BTCUSDC","ts":1698936849423,"type":"delta","data":{"s":"BTCUSDC","b":[["34955.03","0.057216"],["34949.17","0.114451"],["34940.38","0.286201"],["34936.35","0"],["34940.01","0"],["34954.59","0"]],"a":[["34961.16","0.057206"],["34967.97","0.028603"],["34967.72","0"],["34964.01","0"]],"u":20009745,"seq":14108031473}}'
2023-11-02 14:54:11,807 DEBUG ++Rcv raw: b'\x81~\x01\xec{"topic":"orderbook.50.BTCUSDC","ts":1698936849443,"type":"delta","data":{"s":"BTCUSDC","b":[["34956.43","0.070988"],["34952.99","0.051549"],["34949.55","0.003561"],["34948.02","0.364384"],["34954.71","0"],["34958.14","0"],["34946.12","0"],["34936.49","0"]],"a":[["34965.02","0.0859"],["34967.96","0.05154"],["34984.95","0.163728"],["34985","0.001"],["34985.12","0.000491"],["34965.96","0"],["34974.75","0"],["34961.16","0"],["34967.71","0"],["34968.05","0"]],"u":20009746,"seq":14108031504}}'
2023-11-02 14:54:11,807 DEBUG ++Rcv decoded: fin=1 opcode=1 data=b'{"topic":"orderbook.50.BTCUSDC","ts":1698936849443,"type":"delta","data":{"s":"BTCUSDC","b":[["34956.43","0.070988"],["34952.99","0.051549"],["34949.55","0.003561"],["34948.02","0.364384"],["34954.71","0"],["34958.14","0"],["34946.12","0"],["34936.49","0"]],"a":[["34965.02","0.0859"],["34967.96","0.05154"],["34984.95","0.163728"],["34985","0.001"],["34985.12","0.000491"],["34965.96","0"],["34974.75","0"],["34961.16","0"],["34967.71","0"],["34968.05","0"]],"u":20009746,"seq":14108031504}}'
2023-11-02 14:54:11,807 DEBUG ++Rcv raw: b'\x81~\x01\xe1{"topic":"orderbook.50.BTCUSDC","ts":1698936849463,"type":"delta","data":{"s":"BTCUSDC","b":[["34937.39","0.278379"],["34936.35","0.1875"],["34935.14","0.823909"],["34935.13","1.373172"],["34934.62","0.029858"],["34949.17","0"],["34946.13","0"],["34948.67","0"],["34940.38","0"],["34955.03","0"]],"a":[["34964.79","0.070141"],["34966.37","0.068642"],["34968.05","0.00057"],["34976.81","0.075313"],["34975.18","0"],["34985.12","0"],["34966.38","0"]],"u":20009747,"seq":14108031530}}'
2023-11-02 14:54:11,807 DEBUG ++Rcv decoded: fin=1 opcode=1 data=b'{"topic":"orderbook.50.BTCUSDC","ts":1698936849463,"type":"delta","data":{"s":"BTCUSDC","b":[["34937.39","0.278379"],["34936.35","0.1875"],["34935.14","0.823909"],["34935.13","1.373172"],["34934.62","0.029858"],["34949.17","0"],["34946.13","0"],["34948.67","0"],["34940.38","0"],["34955.03","0"]],"a":[["34964.79","0.070141"],["34966.37","0.068642"],["34968.05","0.00057"],["34976.81","0.075313"],["34975.18","0"],["34985.12","0"],["34966.38","0"]],"u":20009747,"seq":14108031530}}'
2023-11-02 14:54:11,807 DEBUG ++Rcv raw: b'\x81~\x00\xd6{"topic":"orderbook.50.BTCUSDC","ts":1698936849483,"type":"delta","data":{"s":"BTCUSDC","b":[],"a":[["34967.6","0.114391"],["34976.36","0.285907"],["34966.37","0"],["34967.73","0"]],"u":20009748,"seq":14108031540}}'
2023-11-02 14:54:11,807 DEBUG ++Rcv decoded: fin=1 opcode=1 data=b'{"topic":"orderbook.50.BTCUSDC","ts":1698936849483,"type":"delta","data":{"s":"BTCUSDC","b":[],"a":[["34967.6","0.114391"],["34976.36","0.285907"],["34966.37","0"],["34967.73","0"]],"u":20009748,"seq":14108031540}}'
2023-11-02 14:54:11,807 DEBUG ++Rcv raw: b'\x81~\x00\xae{"topic":"orderbook.50.BTCUSDC","ts":1698936849503,"type":"delta","data":{"s":"BTCUSDC","b":[],"a":[["34967.59","0.068636"],["34967.96","0"]],"u":20009749,"seq":14108031547}}'
2023-11-02 14:54:11,807 DEBUG ++Rcv decoded: fin=1 opcode=1 data=b'{"topic":"orderbook.50.BTCUSDC","ts":1698936849503,"type":"delta","data":{"s":"BTCUSDC","b":[],"a":[["34967.59","0.068636"],["34967.96","0"]],"u":20009749,"seq":14108031547}}'
2023-11-02 14:54:11,808 DEBUG ++Rcv raw: b'\x81~\x01e{"topic":"orderbook.50.BTCUSDC","ts":1698936849563,"type":"delta","data":{"s":"BTCUSDC","b":[["34955.87","0.057214"],["34950.2","0.114448"],["34947.37","0.050834"],["34941.45","0.314193"],["34950.73","0"],["34934.62","0"],["34945.47","0"]],"a":[["34962.15","0.031716"],["34976.39","0.054459"],["34985","0"],["34974.49","0"]],"u":20009750,"seq":14108031594}}'
2023-11-02 14:54:11,808 DEBUG ++Rcv decoded: fin=1 opcode=1 data=b'{"topic":"orderbook.50.BTCUSDC","ts":1698936849563,"type":"delta","data":{"s":"BTCUSDC","b":[["34955.87","0.057214"],["34950.2","0.114448"],["34947.37","0.050834"],["34941.45","0.314193"],["34950.73","0"],["34934.62","0"],["34945.47","0"]],"a":[["34962.15","0.031716"],["34976.39","0.054459"],["34985","0"],["34974.49","0"]],"u":20009750,"seq":14108031594}}'
2023-11-02 14:54:11,808 DEBUG ++Rcv raw: b'\x81~\x01\xee{"topic":"orderbook.50.BTCUSDC","ts":1698936849583,"type":"delta","data":{"s":"BTCUSDC","b":[["34961.33","0.097609"],["34960.3","0.053806"],["34958.14","0.0859"],["34950.21","0.068674"],["34935.14","0"],["34937.39","0"],["34936.35","0"],["34935.13","0"]],"a":[["34962.15","0.001731"],["34984.95","0.0002"],["34985","0.001"],["34985.12","0.000491"],["34985.37","0.274402"],["34986.02","0.4055"],["34974.47","0"],["34964.8","0"],["34968.05","0"],["34965.02","0"]],"u":20009751,"seq":14108031614}}'
2023-11-02 14:54:11,808 DEBUG ++Rcv decoded: fin=1 opcode=1 data=b'{"topic":"orderbook.50.BTCUSDC","ts":1698936849583,"type":"delta","data":{"s":"BTCUSDC","b":[["34961.33","0.097609"],["34960.3","0.053806"],["34958.14","0.0859"],["34950.21","0.068674"],["34935.14","0"],["34937.39","0"],["34936.35","0"],["34935.13","0"]],"a":[["34962.15","0.001731"],["34984.95","0.0002"],["34985","0.001"],["34985.12","0.000491"],["34985.37","0.274402"],["34986.02","0.4055"],["34974.47","0"],["34964.8","0"],["34968.05","0"],["34965.02","0"]],"u":20009751,"seq":14108031614}}'
2023-11-02 14:54:11,808 DEBUG ++Rcv raw: b'\x81~\x01%{"topic":"orderbook.50.BTCUSDC","ts":1698936849604,"type":"delta","data":{"s":"BTCUSDC","b":[["34937.39","0.278379"],["34936.35","0.1875"],["34959.15","0"],["34960.3","0"]],"a":[["34966.73","0.051547"],["34984.64","0.274413"],["34985.37","0"],["34964.79","0"]],"u":20009752,"seq":14108031627}}'
2023-11-02 14:54:11,808 DEBUG ++Rcv decoded: fin=1 opcode=1 data=b'{"topic":"orderbook.50.BTCUSDC","ts":1698936849604,"type":"delta","data":{"s":"BTCUSDC","b":[["34937.39","0.278379"],["34936.35","0.1875"],["34959.15","0"],["34960.3","0"]],"a":[["34966.73","0.051547"],["34984.64","0.274413"],["34985.37","0"],["34964.79","0"]],"u":20009752,"seq":14108031627}}'
2023-11-02 14:54:11,808 DEBUG ++Rcv raw: b'\x81~\x00\xae{"topic":"orderbook.50.BTCUSDC","ts":1698936849623,"type":"delta","data":{"s":"BTCUSDC","b":[["34959.16","0.009075"],["34936.35","0"]],"a":[],"u":20009753,"seq":14108031631}}'
2023-11-02 14:54:11,808 DEBUG ++Rcv decoded: fin=1 opcode=1 data=b'{"topic":"orderbook.50.BTCUSDC","ts":1698936849623,"type":"delta","data":{"s":"BTCUSDC","b":[["34959.16","0.009075"],["34936.35","0"]],"a":[],"u":20009753,"seq":14108031631}}'
2023-11-02 14:54:11,808 DEBUG ++Rcv raw: b'\x81~\x00\xff{"topic":"orderbook.50.BTCUSDC","ts":1698936849643,"type":"delta","data":{"s":"BTCUSDC","b":[["34940.02","0.038034"],["34937.39","0"]],"a":[["34964.54","0.014471"],["34985.56","0.140478"],["34963.16","0"],["34986.02","0"]],"u":20009754,"seq":14108031637}}'
2023-11-02 14:54:11,808 DEBUG ++Rcv decoded: fin=1 opcode=1 data=b'{"topic":"orderbook.50.BTCUSDC","ts":1698936849643,"type":"delta","data":{"s":"BTCUSDC","b":[["34940.02","0.038034"],["34937.39","0"]],"a":[["34964.54","0.014471"],["34985.56","0.140478"],["34963.16","0"],["34986.02","0"]],"u":20009754,"seq":14108031637}}'
2023-11-02 14:54:11,809 DEBUG ++Rcv raw: b'\x81~\x01\xdc{"topic":"orderbook.50.BTCUSDC","ts":1698936849684,"type":"delta","data":{"s":"BTCUSDC","b":[["34961.33","0.097137"],["34956.41","0.057214"],["34937.39","0.278379"],["34936.35","0.1875"],["34948.02","0"],["34955.87","0"],["34940.94","0"]],"a":[["34962.59","0.048028"],["34962.6","0.057203"],["34986.02","0.4055"],["34987.53","0.1875"],["34988.11","0.245048"],["34967.6","0"],["34984.65","0"],["34964.54","0"],["34976.36","0"],["34962.15","0"]],"u":20009755,"seq":14108031688}}'
2023-11-02 14:54:11,809 DEBUG ++Rcv decoded: fin=1 opcode=1 data=b'{"topic":"orderbook.50.BTCUSDC","ts":1698936849684,"type":"delta","data":{"s":"BTCUSDC","b":[["34961.33","0.097137"],["34956.41","0.057214"],["34937.39","0.278379"],["34936.35","0.1875"],["34948.02","0"],["34955.87","0"],["34940.94","0"]],"a":[["34962.59","0.048028"],["34962.6","0.057203"],["34986.02","0.4055"],["34987.53","0.1875"],["34988.11","0.245048"],["34967.6","0"],["34984.65","0"],["34964.54","0"],["34976.36","0"],["34962.15","0"]],"u":20009755,"seq":14108031688}}'
2023-11-02 14:54:11,809 DEBUG ++Rcv raw: b'\x81~\x01z{"topic":"orderbook.50.BTCUSDC","ts":1698936849704,"type":"delta","data":{"s":"BTCUSDC","b":[["34951.07","0.114445"],["34942.33","0.286185"],["34941.45","0.028"],["34950.2","0"],["34956.41","0"]],"a":[["34967.96","0.05154"],["34968.48","0.114388"],["34977.23","0.4734"],["34986.67","0.457317"],["34984.64","0"],["34967.59","0"],["34988.11","0"]],"u":20009756,"seq":14108031707}}'
2023-11-02 14:54:11,809 DEBUG ++Rcv decoded: fin=1 opcode=1 data=b'{"topic":"orderbook.50.BTCUSDC","ts":1698936849704,"type":"delta","data":{"s":"BTCUSDC","b":[["34951.07","0.114445"],["34942.33","0.286185"],["34941.45","0.028"],["34950.2","0"],["34956.41","0"]],"a":[["34967.96","0.05154"],["34968.48","0.114388"],["34977.23","0.4734"],["34986.67","0.457317"],["34984.64","0"],["34967.59","0"],["34988.11","0"]],"u":20009756,"seq":14108031707}}'
2023-11-02 14:54:11,809 DEBUG ++Rcv raw: b'\x81~\x01i{"topic":"orderbook.50.BTCUSDC","ts":1698936849724,"type":"delta","data":{"s":"BTCUSDC","b":[["34951.27","0.068668"],["34935.14","0.823909"],["34935.13","1.373172"],["34934.62","0.029858"],["34960.29","0"],["34941.47","0"],["34950.21","0"],["34959.16","0"]],"a":[["34962.59","0.047828"],["34988.11","0.245048"],["34985.56","0"]],"u":20009757,"seq":14108031718}}'
2023-11-02 14:54:11,809 DEBUG ++Rcv decoded: fin=1 opcode=1 data=b'{"topic":"orderbook.50.BTCUSDC","ts":1698936849724,"type":"delta","data":{"s":"BTCUSDC","b":[["34951.27","0.068668"],["34935.14","0.823909"],["34935.13","1.373172"],["34934.62","0.029858"],["34960.29","0"],["34941.47","0"],["34950.21","0"],["34959.16","0"]],"a":[["34962.59","0.047828"],["34988.11","0.245048"],["34985.56","0"]],"u":20009757,"seq":14108031718}}'
2023-11-02 14:54:11,809 DEBUG ++Rcv raw: b'\x81~\x00\xd6{"topic":"orderbook.50.BTCUSDC","ts":1698936849744,"type":"delta","data":{"s":"BTCUSDC","b":[["34951.28","0.003144"],["34934.62","0"]],"a":[["34970.31","0.362455"],["34988.11","0"]],"u":20009758,"seq":14108031732}}'
2023-11-02 14:54:11,809 DEBUG ++Rcv decoded: fin=1 opcode=1 data=b'{"topic":"orderbook.50.BTCUSDC","ts":1698936849744,"type":"delta","data":{"s":"BTCUSDC","b":[["34951.28","0.003144"],["34934.62","0"]],"a":[["34970.31","0.362455"],["34988.11","0"]],"u":20009758,"seq":14108031732}}'
2023-11-02 14:54:11,810 DEBUG ++Rcv raw: b'\x81~\x00\xeb{"topic":"orderbook.50.BTCUSDC","ts":1698936849763,"type":"delta","data":{"s":"BTCUSDC","b":[["34934.62","0.029858"],["34949.55","0"]],"a":[["34967.67","0.001"],["34969.88","0.211032"],["34987.53","0"]],"u":20009759,"seq":14108031738}}'
2023-11-02 14:54:11,810 DEBUG ++Rcv decoded: fin=1 opcode=1 data=b'{"topic":"orderbook.50.BTCUSDC","ts":1698936849763,"type":"delta","data":{"s":"BTCUSDC","b":[["34934.62","0.029858"],["34949.55","0"]],"a":[["34967.67","0.001"],["34969.88","0.211032"],["34987.53","0"]],"u":20009759,"seq":14108031738}}'
2023-11-02 14:54:11,810 DEBUG ++Rcv raw: b'\x81~\x00\xeb{"topic":"orderbook.50.BTCUSDC","ts":1698936849783,"type":"delta","data":{"s":"BTCUSDC","b":[["34956.82","0.057213"],["34934.62","0"]],"a":[["34963.18","0.057203"],["34987.53","0.1875"],["34962.6","0"]],"u":20009760,"seq":14108031754}}'
2023-11-02 14:54:11,810 DEBUG ++Rcv decoded: fin=1 opcode=1 data=b'{"topic":"orderbook.50.BTCUSDC","ts":1698936849783,"type":"delta","data":{"s":"BTCUSDC","b":[["34956.82","0.057213"],["34934.62","0"]],"a":[["34963.18","0.057203"],["34987.53","0.1875"],["34962.6","0"]],"u":20009760,"seq":14108031754}}'
2023-11-02 14:54:11,810 DEBUG ++Rcv raw: b'\x81~\x00\xed{"topic":"orderbook.50.BTCUSDC","ts":1698936849803,"type":"delta","data":{"s":"BTCUSDC","b":[["34956.83","0.03433"],["34954.71","0.051544"],["34956.43","0"],["34935.13","0"]],"a":[["34962.59","0.034326"]],"u":20009761,"seq":14108031764}}'
2023-11-02 14:54:11,810 DEBUG ++Rcv decoded: fin=1 opcode=1 data=b'{"topic":"orderbook.50.BTCUSDC","ts":1698936849803,"type":"delta","data":{"s":"BTCUSDC","b":[["34956.83","0.03433"],["34954.71","0.051544"],["34956.43","0"],["34935.13","0"]],"a":[["34962.59","0.034326"]],"u":20009761,"seq":14108031764}}'
2023-11-02 14:54:11,810 DEBUG ++Rcv raw: b'\x81~\x01\x11{"topic":"orderbook.50.BTCUSDC","ts":1698936849824,"type":"delta","data":{"s":"BTCUSDC","b":[["34961.34","0.009075"],["34961.33","0.003"],["34953.73","0.036"],["34936.35","0"],["34935.14","0"]],"a":[["34988.11","0.245048"],["34970.31","0"]],"u":20009762,"seq":14108031777}}'
2023-11-02 14:54:11,811 DEBUG ++Rcv decoded: fin=1 opcode=1 data=b'{"topic":"orderbook.50.BTCUSDC","ts":1698936849824,"type":"delta","data":{"s":"BTCUSDC","b":[["34961.34","0.009075"],["34961.33","0.003"],["34953.73","0.036"],["34936.35","0"],["34935.14","0"]],"a":[["34988.11","0.245048"],["34970.31","0"]],"u":20009762,"seq":14108031777}}'
2023-11-02 14:54:11,811 DEBUG ++Rcv raw: b'\x81~\x00\xe9{"topic":"orderbook.50.BTCUSDC","ts":1698936849844,"type":"delta","data":{"s":"BTCUSDC","b":[],"a":[["34965.02","0.0859"],["34966.87","0.03"],["34969.88","0.051544"],["34987.53","0"],["34988.11","0"]],"u":20009763,"seq":14108031783}}'
2023-11-02 14:54:11,811 DEBUG ++Rcv decoded: fin=1 opcode=1 data=b'{"topic":"orderbook.50.BTCUSDC","ts":1698936849844,"type":"delta","data":{"s":"BTCUSDC","b":[],"a":[["34965.02","0.0859"],["34966.87","0.03"],["34969.88","0.051544"],["34987.53","0"],["34988.11","0"]],"u":20009763,"seq":14108031783}}'
2023-11-02 14:54:11,811 DEBUG ++Rcv raw: b'\x81~\x00\xfd{"topic":"orderbook.50.BTCUSDC","ts":1698936849864,"type":"delta","data":{"s":"BTCUSDC","b":[["34936.35","0.1875"],["34956.82","0"]],"a":[["34965.01","0.051546"],["34972.52","0.000239"],["34966.73","0"],["34986.67","0"]],"u":20009764,"seq":14108031794}}'
2023-11-02 14:54:11,811 DEBUG ++Rcv decoded: fin=1 opcode=1 data=b'{"topic":"orderbook.50.BTCUSDC","ts":1698936849864,"type":"delta","data":{"s":"BTCUSDC","b":[["34936.35","0.1875"],["34956.82","0"]],"a":[["34965.01","0.051546"],["34972.52","0.000239"],["34966.73","0"],["34986.67","0"]],"u":20009764,"seq":14108031794}}'
2023-11-02 14:54:11,811 DEBUG ++Rcv raw: b'\x81~\x01\x18{"topic":"orderbook.50.BTCUSDC","ts":1698936849883,"type":"delta","data":{"s":"BTCUSDC","b":[["34961.33","0.000075"],["34956.43","0.070987"],["34954.01","0.021608"],["34935.14","0.823909"],["34954.71","0"],["34961.34","0"],["34956.83","0"]],"a":[],"u":20009765,"seq":14108031801}}'
2023-11-02 14:54:11,811 DEBUG ++Rcv decoded: fin=1 opcode=1 data=b'{"topic":"orderbook.50.BTCUSDC","ts":1698936849883,"type":"delta","data":{"s":"BTCUSDC","b":[["34961.33","0.000075"],["34956.43","0.070987"],["34954.01","0.021608"],["34935.14","0.823909"],["34954.71","0"],["34961.34","0"],["34956.83","0"]],"a":[],"u":20009765,"seq":14108031801}}'
2023-11-02 14:54:11,811 DEBUG ++Rcv raw: b'\x81~\x00\xd4{"topic":"orderbook.50.BTCUSDC","ts":1698936849903,"type":"delta","data":{"s":"BTCUSDC","b":[["34953.25","0.00057"],["34958.14","0"]],"a":[["34967.48","0.00057"],["34986.02","0"]],"u":20009766,"seq":14108031810}}'
2023-11-02 14:54:11,811 DEBUG ++Rcv decoded: fin=1 opcode=1 data=b'{"topic":"orderbook.50.BTCUSDC","ts":1698936849903,"type":"delta","data":{"s":"BTCUSDC","b":[["34953.25","0.00057"],["34958.14","0"]],"a":[["34967.48","0.00057"],["34986.02","0"]],"u":20009766,"seq":14108031810}}'
2023-11-02 14:54:11,812 DEBUG ++Rcv raw: b'\x81~\x01\x11{"topic":"orderbook.50.BTCUSDC","ts":1698936849923,"type":"delta","data":{"s":"BTCUSDC","b":[["34958","0.030876"],["34948.38","0.042708"],["34961.33","0"]],"a":[["34968.38","0.043665"],["34986.02","0.4055"],["34967.67","0"],["34981.8","0"]],"u":20009767,"seq":14108031818}}'
2023-11-02 14:54:11,812 DEBUG ++Rcv decoded: fin=1 opcode=1 data=b'{"topic":"orderbook.50.BTCUSDC","ts":1698936849923,"type":"delta","data":{"s":"BTCUSDC","b":[["34958","0.030876"],["34948.38","0.042708"],["34961.33","0"]],"a":[["34968.38","0.043665"],["34986.02","0.4055"],["34967.67","0"],["34981.8","0"]],"u":20009767,"seq":14108031818}}'
2023-11-02 14:54:11,812 DEBUG ++Rcv raw: b'\x81~\x00\xae{"topic":"orderbook.50.BTCUSDC","ts":1698936849943,"type":"delta","data":{"s":"BTCUSDC","b":[["34958.01","0.008956"],["34935.14","0"]],"a":[],"u":20009768,"seq":14108031819}}'
2023-11-02 14:54:11,812 DEBUG ++Rcv decoded: fin=1 opcode=1 data=b'{"topic":"orderbook.50.BTCUSDC","ts":1698936849943,"type":"delta","data":{"s":"BTCUSDC","b":[["34958.01","0.008956"],["34935.14","0"]],"a":[],"u":20009768,"seq":14108031819}}'
2023-11-02 14:54:11,812 DEBUG ++Rcv raw: b'\x81~\x00\xd3{"topic":"orderbook.50.BTCUSDC","ts":1698936849963,"type":"delta","data":{"s":"BTCUSDC","b":[],"a":[["34961.68","0.00306"],["34967.25","0.001"],["34985.12","0"],["34986.02","0"]],"u":20009769,"seq":14108031846}}'
2023-11-02 14:54:11,812 DEBUG ++Rcv decoded: fin=1 opcode=1 data=b'{"topic":"orderbook.50.BTCUSDC","ts":1698936849963,"type":"delta","data":{"s":"BTCUSDC","b":[],"a":[["34961.68","0.00306"],["34967.25","0.001"],["34985.12","0"],["34986.02","0"]],"u":20009769,"seq":14108031846}}'
2023-11-02 14:54:11,812 DEBUG ++Rcv raw: b'\x81~\x00\xab{"topic":"orderbook.50.BTCUSDC","ts":1698936850044,"type":"delta","data":{"s":"BTCUSDC","b":[],"a":[["34969.87","0.369058"],["34985","0"]],"u":20009770,"seq":14108031865}}'
2023-11-02 14:54:11,812 DEBUG ++Rcv decoded: fin=1 opcode=1 data=b'{"topic":"orderbook.50.BTCUSDC","ts":1698936850044,"type":"delta","data":{"s":"BTCUSDC","b":[],"a":[["34969.87","0.369058"],["34985","0"]],"u":20009770,"seq":14108031865}}'
2023-11-02 14:54:11,813 DEBUG ++Rcv raw: b'\x81~\x00\xed{"topic":"orderbook.50.BTCUSDC","ts":1698936850064,"type":"delta","data":{"s":"BTCUSDC","b":[["34948.67","0.356113"],["34936.35","0"]],"a":[["34961.68","0.00286"],["34969.86","0.221443"],["34969.88","0"]],"u":20009771,"seq":14108031886}}'
2023-11-02 14:54:11,813 DEBUG ++Rcv decoded: fin=1 opcode=1 data=b'{"topic":"orderbook.50.BTCUSDC","ts":1698936850064,"type":"delta","data":{"s":"BTCUSDC","b":[["34948.67","0.356113"],["34936.35","0"]],"a":[["34961.68","0.00286"],["34969.86","0.221443"],["34969.88","0"]],"u":20009771,"seq":14108031886}}'
2023-11-02 14:54:11,813 DEBUG ++Rcv raw: b'\x81~\x00\xac{"topic":"orderbook.50.BTCUSDC","ts":1698936850084,"type":"delta","data":{"s":"BTCUSDC","b":[["34936.35","0.1875"],["34948.66","0"]],"a":[],"u":20009772,"seq":14108031892}}'
2023-11-02 14:54:11,813 DEBUG ++Rcv decoded: fin=1 opcode=1 data=b'{"topic":"orderbook.50.BTCUSDC","ts":1698936850084,"type":"delta","data":{"s":"BTCUSDC","b":[["34936.35","0.1875"],["34948.66","0"]],"a":[],"u":20009772,"seq":14108031892}}'
2023-11-02 14:54:11,814 DEBUG ++Rcv raw: b'\x81~\x00\xa8{"topic":"orderbook.50.BTCUSDC","ts":1698936850104,"type":"delta","data":{"s":"BTCUSDC","b":[],"a":[["34985","0.001"],["34967.25","0"]],"u":20009773,"seq":14108031903}}'
2023-11-02 14:54:11,814 DEBUG ++Rcv decoded: fin=1 opcode=1 data=b'{"topic":"orderbook.50.BTCUSDC","ts":1698936850104,"type":"delta","data":{"s":"BTCUSDC","b":[],"a":[["34985","0.001"],["34967.25","0"]],"u":20009773,"seq":14108031903}}'
2023-11-02 14:54:11,814 DEBUG ++Rcv raw: b'\x81~\x00\xd7{"topic":"orderbook.50.BTCUSDC","ts":1698936850123,"type":"delta","data":{"s":"BTCUSDC","b":[["34935.14","0.823909"],["34935.13","1.373172"],["34939.37","0"],["34940.02","0"]],"a":[],"u":20009774,"seq":14108031911}}'
2023-11-02 14:54:11,814 DEBUG ++Rcv decoded: fin=1 opcode=1 data=b'{"topic":"orderbook.50.BTCUSDC","ts":1698936850123,"type":"delta","data":{"s":"BTCUSDC","b":[["34935.14","0.823909"],["34935.13","1.373172"],["34939.37","0"],["34940.02","0"]],"a":[],"u":20009774,"seq":14108031911}}'
2023-11-02 14:54:11,814 DEBUG ++Rcv raw: b'\x81~\x00\xad{"topic":"orderbook.50.BTCUSDC","ts":1698936850143,"type":"delta","data":{"s":"BTCUSDC","b":[["34949.2","0.002092"],["34941.45","0"]],"a":[],"u":20009775,"seq":14108031934}}'
2023-11-02 14:54:11,814 DEBUG ++Rcv decoded: fin=1 opcode=1 data=b'{"topic":"orderbook.50.BTCUSDC","ts":1698936850143,"type":"delta","data":{"s":"BTCUSDC","b":[["34949.2","0.002092"],["34941.45","0"]],"a":[],"u":20009775,"seq":14108031934}}'
2023-11-02 14:54:11,815 DEBUG ++Rcv raw: b'\x81~\x00\xd1{"topic":"orderbook.50.BTCUSDC","ts":1698936850164,"type":"delta","data":{"s":"BTCUSDC","b":[["34934.62","0.029858"],["34951.28","0"]],"a":[["34977.06","0.0859"],["34985","0"]],"u":20009776,"seq":14108031939}}'
2023-11-02 14:54:11,815 DEBUG ++Rcv decoded: fin=1 opcode=1 data=b'{"topic":"orderbook.50.BTCUSDC","ts":1698936850164,"type":"delta","data":{"s":"BTCUSDC","b":[["34934.62","0.029858"],["34951.28","0"]],"a":[["34977.06","0.0859"],["34985","0"]],"u":20009776,"seq":14108031939}}'
2023-11-02 14:54:11,816 DEBUG ++Rcv raw: b'\x81~\x00\xae{"topic":"orderbook.50.BTCUSDC","ts":1698936850184,"type":"delta","data":{"s":"BTCUSDC","b":[["34959.76","0.103078"],["34934.62","0"]],"a":[],"u":20009777,"seq":14108031946}}'
2023-11-02 14:54:11,816 DEBUG ++Rcv decoded: fin=1 opcode=1 data=b'{"topic":"orderbook.50.BTCUSDC","ts":1698936850184,"type":"delta","data":{"s":"BTCUSDC","b":[["34959.76","0.103078"],["34934.62","0"]],"a":[],"u":20009777,"seq":14108031946}}'
2023-11-02 14:54:11,817 DEBUG ++Rcv raw: b'\x81~\x01({"topic":"orderbook.50.BTCUSDC","ts":1698936850204,"type":"delta","data":{"s":"BTCUSDC","b":[["34934.62","0.029858"],["34933.63","0.000261"],["34958.01","0"],["34953.25","0"]],"a":[["34972.84","0.058064"],["34983.33","0.152466"],["34967.48","0"],["34984.95","0"]],"u":20009778,"seq":14108031957}}'
2023-11-02 14:54:11,817 DEBUG ++Rcv decoded: fin=1 opcode=1 data=b'{"topic":"orderbook.50.BTCUSDC","ts":1698936850204,"type":"delta","data":{"s":"BTCUSDC","b":[["34934.62","0.029858"],["34933.63","0.000261"],["34958.01","0"],["34953.25","0"]],"a":[["34972.84","0.058064"],["34983.33","0.152466"],["34967.48","0"],["34984.95","0"]],"u":20009778,"seq":14108031957}}'
2023-11-02 14:54:11,817 DEBUG ++Rcv raw: b'\x81~\x00\xd6{"topic":"orderbook.50.BTCUSDC","ts":1698936850223,"type":"delta","data":{"s":"BTCUSDC","b":[["34948.68","0.213667"],["34933.63","0"]],"a":[["34971.89","0.051542"],["34984.83","0"]],"u":20009779,"seq":14108031961}}'
2023-11-02 14:54:11,817 DEBUG ++Rcv decoded: fin=1 opcode=1 data=b'{"topic":"orderbook.50.BTCUSDC","ts":1698936850223,"type":"delta","data":{"s":"BTCUSDC","b":[["34948.68","0.213667"],["34933.63","0"]],"a":[["34971.89","0.051542"],["34984.83","0"]],"u":20009779,"seq":14108031961}}'
2023-11-02 14:54:11,817 DEBUG ++Rcv raw: b'\x81~\x00\x9a{"topic":"orderbook.50.BTCUSDC","ts":1698936850243,"type":"delta","data":{"s":"BTCUSDC","b":[],"a":[["34965","0.038691"]],"u":20009780,"seq":14108031973}}'
2023-11-02 14:54:11,817 DEBUG ++Rcv decoded: fin=1 opcode=1 data=b'{"topic":"orderbook.50.BTCUSDC","ts":1698936850243,"type":"delta","data":{"s":"BTCUSDC","b":[],"a":[["34965","0.038691"]],"u":20009780,"seq":14108031973}}'
2023-11-02 14:54:11,818 DEBUG ++Rcv raw: b'\x81~\x00\xfd{"topic":"orderbook.50.BTCUSDC","ts":1698936850263,"type":"delta","data":{"s":"BTCUSDC","b":[["34957.23","0.057212"],["34943.18","0.286178"],["34942.33","0"],["34934.62","0"]],"a":[["34984.83","0.0002"],["34963.18","0"]],"u":20009781,"seq":14108031986}}'
2023-11-02 14:54:11,818 DEBUG ++Rcv decoded: fin=1 opcode=1 data=b'{"topic":"orderbook.50.BTCUSDC","ts":1698936850263,"type":"delta","data":{"s":"BTCUSDC","b":[["34957.23","0.057212"],["34943.18","0.286178"],["34942.33","0"],["34934.62","0"]],"a":[["34984.83","0.0002"],["34963.18","0"]],"u":20009781,"seq":14108031986}}'
2023-11-02 14:54:11,818 DEBUG ++Rcv raw: b'\x81~\x01\'{"topic":"orderbook.50.BTCUSDC","ts":1698936850283,"type":"delta","data":{"s":"BTCUSDC","b":[["34957.24","0.03433"],["34954.71","0.051544"],["34938.05","0.205662"],["34954.01","0"],["34935.13","0"],["34956.43","0"]],"a":[["34962.78","0.057203"],["34962.59","0"]],"u":20009782,"seq":14108031995}}'
2023-11-02 14:54:11,818 DEBUG ++Rcv decoded: fin=1 opcode=1 data=b'{"topic":"orderbook.50.BTCUSDC","ts":1698936850283,"type":"delta","data":{"s":"BTCUSDC","b":[["34957.24","0.03433"],["34954.71","0.051544"],["34938.05","0.205662"],["34954.01","0"],["34935.13","0"],["34956.43","0"]],"a":[["34962.78","0.057203"],["34962.59","0"]],"u":20009782,"seq":14108031995}}'
2023-11-02 14:54:11,818 DEBUG ++Rcv raw: b'\x81~\x00\xae{"topic":"orderbook.50.BTCUSDC","ts":1698936850303,"type":"delta","data":{"s":"BTCUSDC","b":[],"a":[["34962.77","0.034326"],["34984.83","0"]],"u":20009783,"seq":14108031999}}'
2023-11-02 14:54:11,818 DEBUG ++Rcv decoded: fin=1 opcode=1 data=b'{"topic":"orderbook.50.BTCUSDC","ts":1698936850303,"type":"delta","data":{"s":"BTCUSDC","b":[],"a":[["34962.77","0.034326"],["34984.83","0"]],"u":20009783,"seq":14108031999}}'
2023-11-02 14:54:11,819 DEBUG ++Rcv raw: b'\x81~\x00\xab{"topic":"orderbook.50.BTCUSDC","ts":1698936850343,"type":"delta","data":{"s":"BTCUSDC","b":[["34939.86","0.028"],["34935.14","0"]],"a":[],"u":20009784,"seq":14108032018}}'
2023-11-02 14:54:11,819 DEBUG ++Rcv decoded: fin=1 opcode=1 data=b'{"topic":"orderbook.50.BTCUSDC","ts":1698936850343,"type":"delta","data":{"s":"BTCUSDC","b":[["34939.86","0.028"],["34935.14","0"]],"a":[],"u":20009784,"seq":14108032018}}'
2023-11-02 14:54:11,819 DEBUG ++Rcv raw: b'\x81~\x00\xec{"topic":"orderbook.50.BTCUSDC","ts":1698936850644,"type":"delta","data":{"s":"BTCUSDC","b":[["34959.76","0.018478"],["34935.14","0.823909"],["34948.38","0"]],"a":[["34968.68","0.1875"],["34983.74","0"]],"u":20009785,"seq":14108032182}}'
2023-11-02 14:54:11,819 DEBUG ++Rcv decoded: fin=1 opcode=1 data=b'{"topic":"orderbook.50.BTCUSDC","ts":1698936850644,"type":"delta","data":{"s":"BTCUSDC","b":[["34959.76","0.018478"],["34935.14","0.823909"],["34948.38","0"]],"a":[["34968.68","0.1875"],["34983.74","0"]],"u":20009785,"seq":14108032182}}'
2023-11-02 14:54:11,819 DEBUG ++Rcv raw: b'\x81~\x01*{"topic":"orderbook.50.BTCUSDC","ts":1698936850664,"type":"delta","data":{"s":"BTCUSDC","b":[["34959.76","0.021478"],["34956.43","0.051546"],["34958","0"]],"a":[["34968.18","0.112507"],["34976.35","0.285907"],["34977.23","0.1875"],["34967.96","0"],["34983.33","0"]],"u":20009786,"seq":14108032199}}'
2023-11-02 14:54:11,820 DEBUG ++Rcv decoded: fin=1 opcode=1 data=b'{"topic":"orderbook.50.BTCUSDC","ts":1698936850664,"type":"delta","data":{"s":"BTCUSDC","b":[["34959.76","0.021478"],["34956.43","0.051546"],["34958","0"]],"a":[["34968.18","0.112507"],["34976.35","0.285907"],["34977.23","0.1875"],["34967.96","0"],["34983.33","0"]],"u":20009786,"seq":14108032199}}'
2023-11-02 14:54:11,820 DEBUG ++Rcv raw: b'\x81~\x00\xc5{"topic":"orderbook.50.BTCUSDC","ts":1698936850684,"type":"delta","data":{"s":"BTCUSDC","b":[["34959.76","0.000008"]],"a":[["34983.33","0.152466"],["34976.81","0"]],"u":20009787,"seq":14108032203}}'
2023-11-02 14:54:11,820 DEBUG ++Rcv decoded: fin=1 opcode=1 data=b'{"topic":"orderbook.50.BTCUSDC","ts":1698936850684,"type":"delta","data":{"s":"BTCUSDC","b":[["34959.76","0.000008"]],"a":[["34983.33","0.152466"],["34976.81","0"]],"u":20009787,"seq":14108032203}}'
2023-11-02 14:54:11,820 DEBUG ++Rcv raw: b'\x81~\x00\xd3{"topic":"orderbook.50.BTCUSDC","ts":1698936850723,"type":"delta","data":{"s":"BTCUSDC","b":[["34934.62","0.029858"],["34948.67","0"]],"a":[["34966.08","0.001"],["34983.33","0"]],"u":20009788,"seq":14108032239}}'
2023-11-02 14:54:11,820 DEBUG ++Rcv decoded: fin=1 opcode=1 data=b'{"topic":"orderbook.50.BTCUSDC","ts":1698936850723,"type":"delta","data":{"s":"BTCUSDC","b":[["34934.62","0.029858"],["34948.67","0"]],"a":[["34966.08","0.001"],["34983.33","0"]],"u":20009788,"seq":14108032239}}'
2023-11-02 14:54:11,820 DEBUG ++Rcv raw: b'\x81~\x01\'{"topic":"orderbook.50.BTCUSDC","ts":1698936850743,"type":"delta","data":{"s":"BTCUSDC","b":[["34949.55","0.002302"],["34948.02","0.360282"],["34936.5","1.373091"],["34948.68","0"],["34935.14","0"],["34934.62","0"]],"a":[["34960.11","0.002992"],["34981.28","0"]],"u":20009789,"seq":14108032251}}'
2023-11-02 14:54:11,821 DEBUG ++Rcv decoded: fin=1 opcode=1 data=b'{"topic":"orderbook.50.BTCUSDC","ts":1698936850743,"type":"delta","data":{"s":"BTCUSDC","b":[["34949.55","0.002302"],["34948.02","0.360282"],["34936.5","1.373091"],["34948.68","0"],["34935.14","0"],["34934.62","0"]],"a":[["34960.11","0.002992"],["34981.28","0"]],"u":20009789,"seq":14108032251}}'
2023-11-02 14:54:11,821 DEBUG ++Rcv raw: b'\x81~\x00\xe9{"topic":"orderbook.50.BTCUSDC","ts":1698936850763,"type":"delta","data":{"s":"BTCUSDC","b":[["34952.35","0.00057"],["34934.62","0.029858"],["34949.2","0"],["34948.64","0"]],"a":[["34965","0.039261"]],"u":20009790,"seq":14108032274}}'
2023-11-02 14:54:11,821 DEBUG ++Rcv decoded: fin=1 opcode=1 data=b'{"topic":"orderbook.50.BTCUSDC","ts":1698936850763,"type":"delta","data":{"s":"BTCUSDC","b":[["34952.35","0.00057"],["34934.62","0.029858"],["34949.2","0"],["34948.64","0"]],"a":[["34965","0.039261"]],"u":20009790,"seq":14108032274}}'
2023-11-02 14:54:11,821 DEBUG ++Rcv raw: b'\x81~\x00\xae{"topic":"orderbook.50.BTCUSDC","ts":1698936851123,"type":"delta","data":{"s":"BTCUSDC","b":[],"a":[["34981.28","0.000562"],["34972.84","0"]],"u":20009791,"seq":14108032410}}'
2023-11-02 14:54:11,821 DEBUG ++Rcv decoded: fin=1 opcode=1 data=b'{"topic":"orderbook.50.BTCUSDC","ts":1698936851123,"type":"delta","data":{"s":"BTCUSDC","b":[],"a":[["34981.28","0.000562"],["34972.84","0"]],"u":20009791,"seq":14108032410}}'
2023-11-02 14:54:11,822 DEBUG ++Rcv raw: b'\x81~\x00\xd4{"topic":"orderbook.50.BTCUSDC","ts":1698936851143,"type":"delta","data":{"s":"BTCUSDC","b":[["34949.26","0.1875"],["34947.7","0.041866"],["34936.35","0"],["34934.62","0"]],"a":[],"u":20009792,"seq":14108032421}}'
2023-11-02 14:54:11,822 DEBUG ++Rcv decoded: fin=1 opcode=1 data=b'{"topic":"orderbook.50.BTCUSDC","ts":1698936851143,"type":"delta","data":{"s":"BTCUSDC","b":[["34949.26","0.1875"],["34947.7","0.041866"],["34936.35","0"],["34934.62","0"]],"a":[],"u":20009792,"seq":14108032421}}'
2023-11-02 14:54:11,822 DEBUG ++Rcv raw: b'\x81~\x00\xac{"topic":"orderbook.50.BTCUSDC","ts":1698936851183,"type":"delta","data":{"s":"BTCUSDC","b":[["34936.35","0.1875"],["34951.07","0"]],"a":[],"u":20009793,"seq":14108032431}}'
2023-11-02 14:54:11,822 DEBUG ++Rcv decoded: fin=1 opcode=1 data=b'{"topic":"orderbook.50.BTCUSDC","ts":1698936851183,"type":"delta","data":{"s":"BTCUSDC","b":[["34936.35","0.1875"],["34951.07","0"]],"a":[],"u":20009793,"seq":14108032431}}'
2023-11-02 14:54:11,822 DEBUG ++Rcv raw: b'\x81~\x00\xd7{"topic":"orderbook.50.BTCUSDC","ts":1698936851203,"type":"delta","data":{"s":"BTCUSDC","b":[["34951.98","0.114442"],["34941.17","0.082703"],["34951.27","0"],["34936.35","0"]],"a":[],"u":20009794,"seq":14108032442}}'
2023-11-02 14:54:11,822 DEBUG ++Rcv decoded: fin=1 opcode=1 data=b'{"topic":"orderbook.50.BTCUSDC","ts":1698936851203,"type":"delta","data":{"s":"BTCUSDC","b":[["34951.98","0.114442"],["34941.17","0.082703"],["34951.27","0"],["34936.35","0"]],"a":[],"u":20009794,"seq":14108032442}}'
2023-11-02 14:54:11,823 DEBUG ++Rcv raw: b'\x81~\x00\xad{"topic":"orderbook.50.BTCUSDC","ts":1698936851243,"type":"delta","data":{"s":"BTCUSDC","b":[["34949.27","0.001721"],["34936.5","0"]],"a":[],"u":20009795,"seq":14108032450}}'
2023-11-02 14:54:11,823 DEBUG ++Rcv decoded: fin=1 opcode=1 data=b'{"topic":"orderbook.50.BTCUSDC","ts":1698936851243,"type":"delta","data":{"s":"BTCUSDC","b":[["34949.27","0.001721"],["34936.5","0"]],"a":[],"u":20009795,"seq":14108032450}}'
2023-11-02 14:54:11,823 DEBUG ++Rcv raw: b'\x81~\x00\xd4{"topic":"orderbook.50.BTCUSDC","ts":1698936851263,"type":"delta","data":{"s":"BTCUSDC","b":[["34948.03","0.216177"],["34949.55","0"]],"a":[["34983.74","0.1875"],["34968.48","0"]],"u":20009796,"seq":14108032466}}'
2023-11-02 14:54:11,823 DEBUG ++Rcv decoded: fin=1 opcode=1 data=b'{"topic":"orderbook.50.BTCUSDC","ts":1698936851263,"type":"delta","data":{"s":"BTCUSDC","b":[["34948.03","0.216177"],["34949.55","0"]],"a":[["34983.74","0.1875"],["34968.48","0"]],"u":20009796,"seq":14108032466}}'
2023-11-02 14:54:11,823 DEBUG ++Rcv raw: b'\x81~\x00\xae{"topic":"orderbook.50.BTCUSDC","ts":1698936851283,"type":"delta","data":{"s":"BTCUSDC","b":[],"a":[["34967.64","0.114391"],["34983.74","0"]],"u":20009797,"seq":14108032470}}'
2023-11-02 14:54:11,823 DEBUG ++Rcv decoded: fin=1 opcode=1 data=b'{"topic":"orderbook.50.BTCUSDC","ts":1698936851283,"type":"delta","data":{"s":"BTCUSDC","b":[],"a":[["34967.64","0.114391"],["34983.74","0"]],"u":20009797,"seq":14108032470}}'
2023-11-02 14:54:11,823 DEBUG ++Rcv raw: b'\x81~\x00\xfd{"topic":"orderbook.50.BTCUSDC","ts":1698936851323,"type":"delta","data":{"s":"BTCUSDC","b":[["34959.77","0.098278"],["34937.39","0"]],"a":[["34969.92","0.000239"],["34983.74","0.1875"],["34960.11","0"],["34968.68","0"]],"u":20009798,"seq":14108032486}}'
2023-11-02 14:54:11,823 DEBUG ++Rcv decoded: fin=1 opcode=1 data=b'{"topic":"orderbook.50.BTCUSDC","ts":1698936851323,"type":"delta","data":{"s":"BTCUSDC","b":[["34959.77","0.098278"],["34937.39","0"]],"a":[["34969.92","0.000239"],["34983.74","0.1875"],["34960.11","0"],["34968.68","0"]],"u":20009798,"seq":14108032486}}'
2023-11-02 14:54:11,823 DEBUG ++Rcv raw: b'\x81~\x01\xe9{"topic":"orderbook.50.BTCUSDC","ts":1698936851344,"type":"delta","data":{"s":"BTCUSDC","b":[["34959.78","0.008956"],["34958","0.0324"],["34937.39","0.278379"],["34936.51","0.823863"],["34936.5","1.373091"],["34936.35","0.1875"],["34952.35","0"],["34951.98","0"],["34941.17","0"],["34956.43","0"],["34957.23","0"],["34943.18","0"]],"a":[["34967.63","0.068637"],["34984.83","0.0002"],["34984.95","0.0002"],["34967.64","0"],["34968.18","0"],["34962.78","0"]],"u":20009799,"seq":14108032511}}'
2023-11-02 14:54:11,823 DEBUG ++Rcv decoded: fin=1 opcode=1 data=b'{"topic":"orderbook.50.BTCUSDC","ts":1698936851344,"type":"delta","data":{"s":"BTCUSDC","b":[["34959.78","0.008956"],["34958","0.0324"],["34937.39","0.278379"],["34936.51","0.823863"],["34936.5","1.373091"],["34936.35","0.1875"],["34952.35","0"],["34951.98","0"],["34941.17","0"],["34956.43","0"],["34957.23","0"],["34943.18","0"]],"a":[["34967.63","0.068637"],["34984.83","0.0002"],["34984.95","0.0002"],["34967.64","0"],["34968.18","0"],["34962.78","0"]],"u":20009799,"seq":14108032511}}'
2023-11-02 14:54:11,824 DEBUG ++Rcv raw: b'\x81~\x02\x19{"topic":"orderbook.50.BTCUSDC","ts":1698936851363,"type":"delta","data":{"s":"BTCUSDC","b":[["34958.08","0.057211"],["34956.43","0.070984"],["34954.01","0.021605"],["34952.84","0.114439"],["34944.17","0.28617"],["34936.5","0"],["34954.71","0"],["34959.77","0"],["34936.35","0"],["34957.24","0"]],"a":[["34961.68","0.00006"],["34963.43","0.057202"],["34965","0.038691"],["34967.96","0.051546"],["34985","0.001"],["34985.12","0.000491"],["34962.77","0"],["34976.35","0"],["34967.63","0"],["34968.19","0"]],"u":20009800,"seq":14108032534}}'
2023-11-02 14:54:11,824 DEBUG ++Rcv decoded: fin=1 opcode=1 data=b'{"topic":"orderbook.50.BTCUSDC","ts":1698936851363,"type":"delta","data":{"s":"BTCUSDC","b":[["34958.08","0.057211"],["34956.43","0.070984"],["34954.01","0.021605"],["34952.84","0.114439"],["34944.17","0.28617"],["34936.5","0"],["34954.71","0"],["34959.77","0"],["34936.35","0"],["34957.24","0"]],"a":[["34961.68","0.00006"],["34963.43","0.057202"],["34965","0.038691"],["34967.96","0.051546"],["34985","0.001"],["34985.12","0.000491"],["34962.77","0"],["34976.35","0"],["34967.63","0"],["34968.19","0"]],"u":20009800,"seq":14108032534}}'
2023-11-02 14:54:11,824 DEBUG ++Rcv raw: b'\x81~\x01\xa4{"topic":"orderbook.50.BTCUSDC","ts":1698936851384,"type":"delta","data":{"s":"BTCUSDC","b":[["34959.78","0.011956"],["34958.09","0.053773"],["34956.43","0.051548"],["34954.71","0.051549"],["34954.01","0"],["34936.51","0"]],"a":[["34963.42","0.034321"],["34968.32","0.00057"],["34968.57","0.114388"],["34977.24","0.2859"],["34985","0"],["34966.08","0"],["34985.12","0"],["34984.95","0"]],"u":20009801,"seq":14108032550}}'
2023-11-02 14:54:11,824 DEBUG ++Rcv decoded: fin=1 opcode=1 data=b'{"topic":"orderbook.50.BTCUSDC","ts":1698936851384,"type":"delta","data":{"s":"BTCUSDC","b":[["34959.78","0.011956"],["34958.09","0.053773"],["34956.43","0.051548"],["34954.71","0.051549"],["34954.01","0"],["34936.51","0"]],"a":[["34963.42","0.034321"],["34968.32","0.00057"],["34968.57","0.114388"],["34977.24","0.2859"],["34985","0"],["34966.08","0"],["34985.12","0"],["34984.95","0"]],"u":20009801,"seq":14108032550}}'
2023-11-02 14:54:11,824 DEBUG ++Rcv raw: b'\x81~\x00\xad{"topic":"orderbook.50.BTCUSDC","ts":1698936851424,"type":"delta","data":{"s":"BTCUSDC","b":[["34954.89","0.00057"],["34937.39","0"]],"a":[],"u":20009802,"seq":14108032567}}'
2023-11-02 14:54:11,824 DEBUG ++Rcv decoded: fin=1 opcode=1 data=b'{"topic":"orderbook.50.BTCUSDC","ts":1698936851424,"type":"delta","data":{"s":"BTCUSDC","b":[["34954.89","0.00057"],["34937.39","0"]],"a":[],"u":20009802,"seq":14108032567}}'
2023-11-02 14:54:11,824 DEBUG ++Rcv raw: b'\x81~\x00\xae{"topic":"orderbook.50.BTCUSDC","ts":1698936851444,"type":"delta","data":{"s":"BTCUSDC","b":[["34949.55","0.003167"],["34938.05","0"]],"a":[],"u":20009803,"seq":14108032574}}'
2023-11-02 14:54:11,825 DEBUG ++Rcv decoded: fin=1 opcode=1 data=b'{"topic":"orderbook.50.BTCUSDC","ts":1698936851444,"type":"delta","data":{"s":"BTCUSDC","b":[["34949.55","0.003167"],["34938.05","0"]],"a":[],"u":20009803,"seq":14108032574}}'
2023-11-02 14:54:11,825 DEBUG ++Rcv raw: b'\x81~\x01 {"topic":"orderbook.50.BTCUSDC","ts":1698936851464,"type":"delta","data":{"s":"BTCUSDC","b":[["34938.05","0.205662"],["34937.39","0.278379"],["34949.27","0"],["34958.08","0"]],"a":[["34984.95","0.0002"],["34985","0.001"],["34977.24","0"],["34963.43","0"]],"u":20009804,"seq":14108032597}}'
2023-11-02 14:54:11,825 DEBUG ++Rcv decoded: fin=1 opcode=1 data=b'{"topic":"orderbook.50.BTCUSDC","ts":1698936851464,"type":"delta","data":{"s":"BTCUSDC","b":[["34938.05","0.205662"],["34937.39","0.278379"],["34949.27","0"],["34958.08","0"]],"a":[["34984.95","0.0002"],["34985","0.001"],["34977.24","0"],["34963.43","0"]],"u":20009804,"seq":14108032597}}'
2023-11-02 14:54:11,825 DEBUG ++Rcv raw: b'\x81~\x01%{"topic":"orderbook.50.BTCUSDC","ts":1698936851484,"type":"delta","data":{"s":"BTCUSDC","b":[["34957.43","0.057212"],["34954.01","0.021601"],["34954.71","0"],["34958.09","0"]],"a":[["34962.88","0.057203"],["34976.36","0.285907"],["34963.42","0"],["34985","0"]],"u":20009805,"seq":14108032611}}'
2023-11-02 14:54:11,825 DEBUG ++Rcv decoded: fin=1 opcode=1 data=b'{"topic":"orderbook.50.BTCUSDC","ts":1698936851484,"type":"delta","data":{"s":"BTCUSDC","b":[["34957.43","0.057212"],["34954.01","0.021601"],["34954.71","0"],["34958.09","0"]],"a":[["34962.88","0.057203"],["34976.36","0.285907"],["34963.42","0"],["34985","0"]],"u":20009805,"seq":14108032611}}'
2023-11-02 14:54:11,825 DEBUG ++Rcv raw: b'\x81~\x01\x99{"topic":"orderbook.50.BTCUSDC","ts":1698936851504,"type":"delta","data":{"s":"BTCUSDC","b":[["34959.79","0.053806"],["34958.14","0.0859"],["34958.01","0.053769"],["34954.71","0.051543"],["34939.85","0"],["34954.01","0"],["34938.05","0"],["34937.39","0"]],"a":[["34985","0.001"],["34985.12","0.000491"],["34985.36","0.0005"],["34961.68","0"],["34962.88","0"],["34965.02","0"]],"u":20009806,"seq":14108032663}}'
2023-11-02 14:54:11,825 DEBUG ++Rcv decoded: fin=1 opcode=1 data=b'{"topic":"orderbook.50.BTCUSDC","ts":1698936851504,"type":"delta","data":{"s":"BTCUSDC","b":[["34959.79","0.053806"],["34958.14","0.0859"],["34958.01","0.053769"],["34954.71","0.051543"],["34939.85","0"],["34954.01","0"],["34938.05","0"],["34937.39","0"]],"a":[["34985","0.001"],["34985.12","0.000491"],["34985.36","0.0005"],["34961.68","0"],["34962.88","0"],["34965.02","0"]],"u":20009806,"seq":14108032663}}'
2023-11-02 14:54:11,825 DEBUG ++Rcv raw: b'\x81~\x01:{"topic":"orderbook.50.BTCUSDC","ts":1698936851523,"type":"delta","data":{"s":"BTCUSDC","b":[["34959.8","0.008956"],["34959.78","0.002"],["34952.78","0.1875"],["34956.43","0"],["34959.79","0"]],"a":[["34964.99","0.023218"],["34966.73","0.051545"],["34985.36","0"],["34965.01","0"]],"u":20009807,"seq":14108032683}}'
2023-11-02 14:54:11,826 DEBUG ++Rcv decoded: fin=1 opcode=1 data=b'{"topic":"orderbook.50.BTCUSDC","ts":1698936851523,"type":"delta","data":{"s":"BTCUSDC","b":[["34959.8","0.008956"],["34959.78","0.002"],["34952.78","0.1875"],["34956.43","0"],["34959.79","0"]],"a":[["34964.99","0.023218"],["34966.73","0.051545"],["34985.36","0"],["34965.01","0"]],"u":20009807,"seq":14108032683}}'
2023-11-02 14:54:11,826 DEBUG ++Rcv raw: b'\x81~\x00\xc3{"topic":"orderbook.50.BTCUSDC","ts":1698936851543,"type":"delta","data":{"s":"BTCUSDC","b":[["34952.99","0.106062"]],"a":[["34985.36","0.0005"],["34972.52","0"]],"u":20009808,"seq":14108032702}}'
2023-11-02 14:54:11,826 DEBUG ++Rcv decoded: fin=1 opcode=1 data=b'{"topic":"orderbook.50.BTCUSDC","ts":1698936851543,"type":"delta","data":{"s":"BTCUSDC","b":[["34952.99","0.106062"]],"a":[["34985.36","0.0005"],["34972.52","0"]],"u":20009808,"seq":14108032702}}'
2023-11-02 14:54:11,827 DEBUG ++Rcv raw: b'\x81~\x00\xae{"topic":"orderbook.50.BTCUSDC","ts":1698936851584,"type":"delta","data":{"s":"BTCUSDC","b":[],"a":[["34972.51","0.024746"],["34985.36","0"]],"u":20009809,"seq":14108032752}}'
2023-11-02 14:54:11,827 DEBUG ++Rcv decoded: fin=1 opcode=1 data=b'{"topic":"orderbook.50.BTCUSDC","ts":1698936851584,"type":"delta","data":{"s":"BTCUSDC","b":[],"a":[["34972.51","0.024746"],["34985.36","0"]],"u":20009809,"seq":14108032752}}'
2023-11-02 14:54:11,827 DEBUG ++Rcv raw: b'\x81~\x00\xaa{"topic":"orderbook.50.BTCUSDC","ts":1698936851604,"type":"delta","data":{"s":"BTCUSDC","b":[],"a":[["34969.25","0.03"],["34966.87","0"]],"u":20009810,"seq":14108032767}}'
2023-11-02 14:54:11,827 DEBUG ++Rcv decoded: fin=1 opcode=1 data=b'{"topic":"orderbook.50.BTCUSDC","ts":1698936851604,"type":"delta","data":{"s":"BTCUSDC","b":[],"a":[["34969.25","0.03"],["34966.87","0"]],"u":20009810,"seq":14108032767}}'
2023-11-02 14:54:11,827 DEBUG ++Rcv raw: b'\x81~\x00\xad{"topic":"orderbook.50.BTCUSDC","ts":1698936851624,"type":"delta","data":{"s":"BTCUSDC","b":[],"a":[["34978.6","0.075313"],["34985.12","0"]],"u":20009811,"seq":14108032775}}'
2023-11-02 14:54:11,831 DEBUG ++Rcv decoded: fin=1 opcode=1 data=b'{"topic":"orderbook.50.BTCUSDC","ts":1698936851624,"type":"delta","data":{"s":"BTCUSDC","b":[],"a":[["34978.6","0.075313"],["34985.12","0"]],"u":20009811,"seq":14108032775}}'
2023-11-02 14:54:11,831 DEBUG ++Rcv raw: b'\x81~\x00\xd5{"topic":"orderbook.50.BTCUSDC","ts":1698936851683,"type":"delta","data":{"s":"BTCUSDC","b":[["34961.45","0.10936"],["34952.78","0"]],"a":[["34962.84","0.000003"],["34968.38","0"]],"u":20009812,"seq":14108032819}}'
2023-11-02 14:54:11,831 DEBUG ++Rcv decoded: fin=1 opcode=1 data=b'{"topic":"orderbook.50.BTCUSDC","ts":1698936851683,"type":"delta","data":{"s":"BTCUSDC","b":[["34961.45","0.10936"],["34952.78","0"]],"a":[["34962.84","0.000003"],["34968.38","0"]],"u":20009812,"seq":14108032819}}'
2023-11-02 14:54:11,831 DEBUG ++Rcv raw: b'\x81~\x01\x14{"topic":"orderbook.50.BTCUSDC","ts":1698936851703,"type":"delta","data":{"s":"BTCUSDC","b":[["34961.46","0.008956"],["34952.99","0.051549"],["34939.85","0.1875"],["34961.45","0"],["34959.8","0"]],"a":[["34985.12","0.000491"],["34962.84","0"]],"u":20009813,"seq":14108032830}}'
2023-11-02 14:54:11,831 DEBUG ++Rcv decoded: fin=1 opcode=1 data=b'{"topic":"orderbook.50.BTCUSDC","ts":1698936851703,"type":"delta","data":{"s":"BTCUSDC","b":[["34961.46","0.008956"],["34952.99","0.051549"],["34939.85","0.1875"],["34961.45","0"],["34959.8","0"]],"a":[["34985.12","0.000491"],["34962.84","0"]],"u":20009813,"seq":14108032830}}'
2023-11-02 14:54:11,832 DEBUG ++Rcv raw: b'\x81~\x01\x97{"topic":"orderbook.50.BTCUSDC","ts":1698936851724,"type":"delta","data":{"s":"BTCUSDC","b":[["34961.47","0.053806"],["34960","0.0324"],["34948.02","0"],["34939.85","0"]],"a":[["34985.36","0.0005"],["34986.02","0.4055"],["34986.66","0.274391"],["34986.67","0.457317"],["34986.82","0.131063"],["34967.97","0"],["34969.87","0"],["34973.66","0"],["34964.99","0"],["34965","0"]],"u":20009814,"seq":14108032849}}'
2023-11-02 14:54:11,832 DEBUG ++Rcv decoded: fin=1 opcode=1 data=b'{"topic":"orderbook.50.BTCUSDC","ts":1698936851724,"type":"delta","data":{"s":"BTCUSDC","b":[["34961.47","0.053806"],["34960","0.0324"],["34948.02","0"],["34939.85","0"]],"a":[["34985.36","0.0005"],["34986.02","0.4055"],["34986.66","0.274391"],["34986.67","0.457317"],["34986.82","0.131063"],["34967.97","0"],["34969.87","0"],["34973.66","0"],["34964.99","0"],["34965","0"]],"u":20009814,"seq":14108032849}}'
2023-11-02 14:54:11,832 DEBUG ++Rcv raw: b'\x81~\x02F{"topic":"orderbook.50.BTCUSDC","ts":1698936851743,"type":"delta","data":{"s":"BTCUSDC","b":[["34961.48","0.008956"],["34961.46","0.02598"],["34959.81","0.028604"],["34958.15","0.001894"],["34954.46","0.1875"],["34949.56","0.355602"],["34948.03","0"],["34947.37","0"],["34944.17","0"],["34957.43","0"],["34961.47","0"]],"a":[["34969.49","0.028601"],["34969.86","0.051547"],["34971.88","0.36813"],["34987.53","0.1875"],["34988.11","0.245048"],["34988.12","0.4084"],["34968.32","0"],["34976.36","0"],["34969.46","0"],["34969.89","0"],["34971.89","0"]],"u":20009815,"seq":14108032928}}'
2023-11-02 14:54:11,832 DEBUG ++Rcv decoded: fin=1 opcode=1 data=b'{"topic":"orderbook.50.BTCUSDC","ts":1698936851743,"type":"delta","data":{"s":"BTCUSDC","b":[["34961.48","0.008956"],["34961.46","0.02598"],["34959.81","0.028604"],["34958.15","0.001894"],["34954.46","0.1875"],["34949.56","0.355602"],["34948.03","0"],["34947.37","0"],["34944.17","0"],["34957.43","0"],["34961.47","0"]],"a":[["34969.49","0.028601"],["34969.86","0.051547"],["34971.88","0.36813"],["34987.53","0.1875"],["34988.11","0.245048"],["34988.12","0.4084"],["34968.32","0"],["34976.36","0"],["34969.46","0"],["34969.89","0"],["34971.89","0"]],"u":20009815,"seq":14108032928}}'
2023-11-02 14:54:11,849 DEBUG ++Rcv raw: b'\x81~\x02\xa9{"topic":"orderbook.50.BTCUSDC","ts":1698936851763,"type":"delta","data":{"s":"BTCUSDC","b":[["34960.01","0.037815"],["34959.86","0.0859"],["34958.32","0.0286"],["34958.15","0.053443"],["34956.43","0.05154"],["34954.71","0.106058"],["34949.19","0.074224"],["34948.09","0.114401"],["34949.55","0"],["34939.86","0"],["34958.01","0"],["34952.84","0"],["34940","0"]],"a":[["34971.16","0.0286"],["34971.45","0.00057"],["34971.87","0.22088"],["34976.23","0.080337"],["34978.71","0.045607"],["34978.78","0.0859"],["34981.9","0.114401"],["34988.11","0"],["34987.53","0"],["34976.39","0"],["34968.57","0"],["34969.49","0"],["34986.82","0"],["34988.12","0"]],"u":20009816,"seq":14108033023}}'
2023-11-02 14:54:11,849 DEBUG ++Rcv decoded: fin=1 opcode=1 data=b'{"topic":"orderbook.50.BTCUSDC","ts":1698936851763,"type":"delta","data":{"s":"BTCUSDC","b":[["34960.01","0.037815"],["34959.86","0.0859"],["34958.32","0.0286"],["34958.15","0.053443"],["34956.43","0.05154"],["34954.71","0.106058"],["34949.19","0.074224"],["34948.09","0.114401"],["34949.55","0"],["34939.86","0"],["34958.01","0"],["34952.84","0"],["34940","0"]],"a":[["34971.16","0.0286"],["34971.45","0.00057"],["34971.87","0.22088"],["34976.23","0.080337"],["34978.71","0.045607"],["34978.78","0.0859"],["34981.9","0.114401"],["34988.11","0"],["34987.53","0"],["34976.39","0"],["34968.57","0"],["34969.49","0"],["34986.82","0"],["34988.12","0"]],"u":20009816,"seq":14108033023}}'
2023-11-02 14:54:11,869 DEBUG ++Rcv raw: b'\x81~\x01/{"topic":"orderbook.50.BTCUSDC","ts":1698936851783,"type":"delta","data":{"s":"BTCUSDC","b":[["34960.01","0.065021"],["34958.15","0.001894"],["34945.86","0.286156"],["34949.56","0"]],"a":[["34969.44","0.114385"],["34986.82","0.131063"],["34967.96","0"],["34971.88","0"]],"u":20009817,"seq":14108033064}}'
2023-11-02 14:54:11,869 DEBUG ++Rcv decoded: fin=1 opcode=1 data=b'{"topic":"orderbook.50.BTCUSDC","ts":1698936851783,"type":"delta","data":{"s":"BTCUSDC","b":[["34960.01","0.065021"],["34958.15","0.001894"],["34945.86","0.286156"],["34949.56","0"]],"a":[["34969.44","0.114385"],["34986.82","0.131063"],["34967.96","0"],["34971.88","0"]],"u":20009817,"seq":14108033064}}'
2023-11-02 14:54:11,889 DEBUG ++Rcv raw: b'\x81~\x01\x85{"topic":"orderbook.50.BTCUSDC","ts":1698936851803,"type":"delta","data":{"s":"BTCUSDC","b":[["34940","0.0341"],["34939.86","0.028"],["34939.85","0.1875"],["34942.66","0"],["34954.46","0"],["34944.39","0"]],"a":[["34966.05","0.086165"],["34969.43","0.068635"],["34971.87","0.051545"],["34987.53","0.1875"],["34978.6","0"],["34966.73","0"],["34969.86","0"]],"u":20009818,"seq":14108033111}}'
2023-11-02 14:54:11,889 DEBUG ++Rcv decoded: fin=1 opcode=1 data=b'{"topic":"orderbook.50.BTCUSDC","ts":1698936851803,"type":"delta","data":{"s":"BTCUSDC","b":[["34940","0.0341"],["34939.86","0.028"],["34939.85","0.1875"],["34942.66","0"],["34954.46","0"],["34944.39","0"]],"a":[["34966.05","0.086165"],["34969.43","0.068635"],["34971.87","0.051545"],["34987.53","0.1875"],["34978.6","0"],["34966.73","0"],["34969.86","0"]],"u":20009818,"seq":14108033111}}'
2023-11-02 14:54:11,909 DEBUG ++Rcv raw: b'\x81~\x01-{"topic":"orderbook.50.BTCUSDC","ts":1698936851824,"type":"delta","data":{"s":"BTCUSDC","b":[["34954.71","0.051543"],["34938.05","0.205662"],["34945.86","0"]],"a":[["34966.05","0.051847"],["34988.11","0.245048"],["34988.12","0.4084"],["34969.44","0"],["34986.67","0"]],"u":20009819,"seq":14108033139}}'
2023-11-02 14:54:11,909 DEBUG ++Rcv decoded: fin=1 opcode=1 data=b'{"topic":"orderbook.50.BTCUSDC","ts":1698936851824,"type":"delta","data":{"s":"BTCUSDC","b":[["34954.71","0.051543"],["34938.05","0.205662"],["34945.86","0"]],"a":[["34966.05","0.051847"],["34988.11","0.245048"],["34988.12","0.4084"],["34969.44","0"],["34986.67","0"]],"u":20009819,"seq":14108033139}}'
2023-11-02 14:54:11,929 DEBUG ++Rcv raw: b'\x81~\x01({"topic":"orderbook.50.BTCUSDC","ts":1698936851844,"type":"delta","data":{"s":"BTCUSDC","b":[["34937.39","0.278379"],["34961.46","0"]],"a":[["34970.07","0.051548"],["34988.75","0.457289"],["34990.96","0.002812"],["34986.66","0"],["34986.82","0"],["34969.43","0"]],"u":20009820,"seq":14108033165}}'
2023-11-02 14:54:11,929 DEBUG ++Rcv decoded: fin=1 opcode=1 data=b'{"topic":"orderbook.50.BTCUSDC","ts":1698936851844,"type":"delta","data":{"s":"BTCUSDC","b":[["34937.39","0.278379"],["34961.46","0"]],"a":[["34970.07","0.051548"],["34988.75","0.457289"],["34990.96","0.002812"],["34986.66","0"],["34986.82","0"],["34969.43","0"]],"u":20009820,"seq":14108033165}}'
2023-11-02 14:54:11,949 DEBUG ++Rcv raw: b'\x81~\x01>{"topic":"orderbook.50.BTCUSDC","ts":1698936851863,"type":"delta","data":{"s":"BTCUSDC","b":[["34950.99","0.04509"],["34949.19","0.023176"],["34940.24","0.05724"],["34938.05","0"],["34937.39","0"]],"a":[["34980.51","0.051562"],["34991.01","0.048472"],["34978.71","0"],["34979.79","0"]],"u":20009821,"seq":14108033208}}'
2023-11-02 14:54:11,949 DEBUG ++Rcv decoded: fin=1 opcode=1 data=b'{"topic":"orderbook.50.BTCUSDC","ts":1698936851863,"type":"delta","data":{"s":"BTCUSDC","b":[["34950.99","0.04509"],["34949.19","0.023176"],["34940.24","0.05724"],["34938.05","0"],["34937.39","0"]],"a":[["34980.51","0.051562"],["34991.01","0.048472"],["34978.71","0"],["34979.79","0"]],"u":20009821,"seq":14108033208}}'
2023-11-02 14:54:11,968 DEBUG ++Rcv raw: b'\x81~\x00\xac{"topic":"orderbook.50.BTCUSDC","ts":1698936851883,"type":"delta","data":{"s":"BTCUSDC","b":[],"a":[["34991.03","0.1875"],["34975.99","0"]],"u":20009822,"seq":14108033220}}'
2023-11-02 14:54:11,969 DEBUG ++Rcv decoded: fin=1 opcode=1 data=b'{"topic":"orderbook.50.BTCUSDC","ts":1698936851883,"type":"delta","data":{"s":"BTCUSDC","b":[],"a":[["34991.03","0.1875"],["34975.99","0"]],"u":20009822,"seq":14108033220}}'
2023-11-02 14:54:11,989 DEBUG ++Rcv raw: b'\x81~\x00\xff{"topic":"orderbook.50.BTCUSDC","ts":1698936851903,"type":"delta","data":{"s":"BTCUSDC","b":[["34938.05","0.205662"],["34953.73","0"]],"a":[["34991.24","0.000308"],["34991.45","0.046219"],["34980.51","0"],["34972.51","0"]],"u":20009823,"seq":14108033245}}'
2023-11-02 14:54:11,989 DEBUG ++Rcv decoded: fin=1 opcode=1 data=b'{"topic":"orderbook.50.BTCUSDC","ts":1698936851903,"type":"delta","data":{"s":"BTCUSDC","b":[["34938.05","0.205662"],["34953.73","0"]],"a":[["34991.24","0.000308"],["34991.45","0.046219"],["34980.51","0"],["34972.51","0"]],"u":20009823,"seq":14108033245}}'
2023-11-02 14:54:12,009 DEBUG ++Rcv raw: b'\x81~\x00\xec{"topic":"orderbook.50.BTCUSDC","ts":1698936851924,"type":"delta","data":{"s":"BTCUSDC","b":[["34937.39","0.278379"],["34950.99","0"]],"a":[["34966.56","0.014789"],["34973.05","0.1875"],["34991.45","0"]],"u":20009824,"seq":14108033251}}'
2023-11-02 14:54:12,009 DEBUG ++Rcv decoded: fin=1 opcode=1 data=b'{"topic":"orderbook.50.BTCUSDC","ts":1698936851924,"type":"delta","data":{"s":"BTCUSDC","b":[["34937.39","0.278379"],["34950.99","0"]],"a":[["34966.56","0.014789"],["34973.05","0.1875"],["34991.45","0"]],"u":20009824,"seq":14108033251}}'
2023-11-02 14:54:12,029 DEBUG ++Rcv raw: b'\x81~\x00\xfe{"topic":"orderbook.50.BTCUSDC","ts":1698936851944,"type":"delta","data":{"s":"BTCUSDC","b":[["34943.86","0.092527"],["34937.39","0"]],"a":[["34978.87","0.07078"],["34989.37","0.054843"],["34991.24","0"],["34991.03","0"]],"u":20009825,"seq":14108033278}}'
2023-11-02 14:54:12,029 DEBUG ++Rcv decoded: fin=1 opcode=1 data=b'{"topic":"orderbook.50.BTCUSDC","ts":1698936851944,"type":"delta","data":{"s":"BTCUSDC","b":[["34943.86","0.092527"],["34937.39","0"]],"a":[["34978.87","0.07078"],["34989.37","0.054843"],["34991.24","0"],["34991.03","0"]],"u":20009825,"seq":14108033278}}'
2023-11-02 14:54:12,049 DEBUG ++Rcv raw: b'\x81~\x01\xc6{"topic":"orderbook.50.BTCUSDC","ts":1698936851963,"type":"delta","data":{"s":"BTCUSDC","b":[["34959.2","0.057209"],["34953.79","0.049213"],["34953.76","0.114436"],["34945.03","0.286163"],["34939.86","0"],["34940","0"],["34939.85","0"],["34938.05","0"]],"a":[["34964.97","0.0572"],["34970.47","0.114382"],["34977.72","0.051587"],["34979.49","0.285881"],["34991.01","0"],["34990.96","0"],["34988.75","0"],["34989.37","0"]],"u":20009826,"seq":14108033314}}'
2023-11-02 14:54:12,049 DEBUG ++Rcv decoded: fin=1 opcode=1 data=b'{"topic":"orderbook.50.BTCUSDC","ts":1698936851963,"type":"delta","data":{"s":"BTCUSDC","b":[["34959.2","0.057209"],["34953.79","0.049213"],["34953.76","0.114436"],["34945.03","0.286163"],["34939.86","0"],["34940","0"],["34939.85","0"],["34938.05","0"]],"a":[["34964.97","0.0572"],["34970.47","0.114382"],["34977.72","0.051587"],["34979.49","0.285881"],["34991.01","0"],["34990.96","0"],["34988.75","0"],["34989.37","0"]],"u":20009826,"seq":14108033314}}'
2023-11-02 14:54:12,069 DEBUG ++Rcv raw: b'\x81~\x01\x14{"topic":"orderbook.50.BTCUSDC","ts":1698936851984,"type":"delta","data":{"s":"BTCUSDC","b":[["34962","0.101928"],["34961.48","0.011956"],["34959.81","0"]],"a":[["34964.96","0.034322"],["34981.41","0.029856"],["34973.05","0"],["34966.74","0"]],"u":20009827,"seq":14108033343}}'
2023-11-02 14:54:12,069 DEBUG ++Rcv decoded: fin=1 opcode=1 data=b'{"topic":"orderbook.50.BTCUSDC","ts":1698936851984,"type":"delta","data":{"s":"BTCUSDC","b":[["34962","0.101928"],["34961.48","0.011956"],["34959.81","0"]],"a":[["34964.96","0.034322"],["34981.41","0.029856"],["34973.05","0"],["34966.74","0"]],"u":20009827,"seq":14108033343}}'
2023-11-02 14:54:12,089 DEBUG ++Rcv raw: b'\x81~\x00\xfb{"topic":"orderbook.50.BTCUSDC","ts":1698936852004,"type":"delta","data":{"s":"BTCUSDC","b":[["34939.86","0.028"],["34954.89","0"]],"a":[["34968.45","0.051543"],["34982.24","0.02859"],["34966.05","0"],["34964.97","0"]],"u":20009828,"seq":14108033359}}'
2023-11-02 14:54:12,089 DEBUG ++Rcv decoded: fin=1 opcode=1 data=b'{"topic":"orderbook.50.BTCUSDC","ts":1698936852004,"type":"delta","data":{"s":"BTCUSDC","b":[["34939.86","0.028"],["34954.89","0"]],"a":[["34968.45","0.051543"],["34982.24","0.02859"],["34966.05","0"],["34964.97","0"]],"u":20009828,"seq":14108033359}}'
2023-11-02 14:54:12,109 DEBUG ++Rcv raw: b'\x81~\x00\xeb{"topic":"orderbook.50.BTCUSDC","ts":1698936852023,"type":"delta","data":{"s":"BTCUSDC","b":[["34962.01","0.008956"],["34961.48","0.003"],["34939.86","0"]],"a":[["34965.75","0.103033"],["34964.96","0"]],"u":20009829,"seq":14108033371}}'
2023-11-02 14:54:12,109 DEBUG ++Rcv decoded: fin=1 opcode=1 data=b'{"topic":"orderbook.50.BTCUSDC","ts":1698936852023,"type":"delta","data":{"s":"BTCUSDC","b":[["34962.01","0.008956"],["34961.48","0.003"],["34939.86","0"]],"a":[["34965.75","0.103033"],["34964.96","0"]],"u":20009829,"seq":14108033371}}'
2023-11-02 14:54:12,129 DEBUG ++Rcv raw: b'\x81~\x01"{"topic":"orderbook.50.BTCUSDC","ts":1698936852043,"type":"delta","data":{"s":"BTCUSDC","b":[["34957.11","0.00057"],["34950.01","0.370943"],["34962","0"],["34961.48","0"]],"a":[["34965.74","0.061823"],["34973.56","0.1875"],["34965.75","0"],["34968.45","0"]],"u":20009830,"seq":14108033392}}'
2023-11-02 14:54:12,129 DEBUG ++Rcv decoded: fin=1 opcode=1 data=b'{"topic":"orderbook.50.BTCUSDC","ts":1698936852043,"type":"delta","data":{"s":"BTCUSDC","b":[["34957.11","0.00057"],["34950.01","0.370943"],["34962","0"],["34961.48","0"]],"a":[["34965.74","0.061823"],["34973.56","0.1875"],["34965.75","0"],["34968.45","0"]],"u":20009830,"seq":14108033392}}'
2023-11-02 14:54:12,149 DEBUG ++Rcv raw: b'\x81~\x00\xae{"topic":"orderbook.50.BTCUSDC","ts":1698936852064,"type":"delta","data":{"s":"BTCUSDC","b":[],"a":[["34968.45","0.051545"],["34965.74","0"]],"u":20009831,"seq":14108033396}}'
2023-11-02 14:54:12,149 DEBUG ++Rcv decoded: fin=1 opcode=1 data=b'{"topic":"orderbook.50.BTCUSDC","ts":1698936852064,"type":"delta","data":{"s":"BTCUSDC","b":[],"a":[["34968.45","0.051545"],["34965.74","0"]],"u":20009831,"seq":14108033396}}'
2023-11-02 14:54:12,168 DEBUG ++Rcv raw: b'\x81~\x00\xc0{"topic":"orderbook.50.BTCUSDC","ts":1698936852083,"type":"delta","data":{"s":"BTCUSDC","b":[["34939.86","0.028"],["34949.19","0"]],"a":[["34966.56","0.0376"]],"u":20009832,"seq":14108033422}}'
2023-11-02 14:54:12,169 DEBUG ++Rcv decoded: fin=1 opcode=1 data=b'{"topic":"orderbook.50.BTCUSDC","ts":1698936852083,"type":"delta","data":{"s":"BTCUSDC","b":[["34939.86","0.028"],["34949.19","0"]],"a":[["34966.56","0.0376"]],"u":20009832,"seq":14108033422}}'
2023-11-02 14:54:12,189 DEBUG ++Rcv raw: b'\x81~\x00\xae{"topic":"orderbook.50.BTCUSDC","ts":1698936852103,"type":"delta","data":{"s":"BTCUSDC","b":[],"a":[["34966.55","0.022566"],["34973.56","0"]],"u":20009833,"seq":14108033455}}'
2023-11-02 14:54:12,189 DEBUG ++Rcv decoded: fin=1 opcode=1 data=b'{"topic":"orderbook.50.BTCUSDC","ts":1698936852103,"type":"delta","data":{"s":"BTCUSDC","b":[],"a":[["34966.55","0.022566"],["34973.56","0"]],"u":20009833,"seq":14108033455}}'
2023-11-02 14:54:12,209 DEBUG ++Rcv raw: b'\x81~\x00\xd4{"topic":"orderbook.50.BTCUSDC","ts":1698936852124,"type":"delta","data":{"s":"BTCUSDC","b":[],"a":[["34972.82","0.04395"],["34973.55","0.1875"],["34988.12","0"],["34988.11","0"]],"u":20009834,"seq":14108033470}}'
2023-11-02 14:54:12,209 DEBUG ++Rcv decoded: fin=1 opcode=1 data=b'{"topic":"orderbook.50.BTCUSDC","ts":1698936852124,"type":"delta","data":{"s":"BTCUSDC","b":[],"a":[["34972.82","0.04395"],["34973.55","0.1875"],["34988.12","0"],["34988.11","0"]],"u":20009834,"seq":14108033470}}'
2023-11-02 14:54:12,231 DEBUG ++Rcv raw: b'\x81~\x00\xd6{"topic":"orderbook.50.BTCUSDC","ts":1698936852144,"type":"delta","data":{"s":"BTCUSDC","b":[["34954.72","0.002712"],["34939.86","0"]],"a":[["34969.93","0.042805"],["34969.92","0"]],"u":20009835,"seq":14108033504}}'
2023-11-02 14:54:12,231 DEBUG ++Rcv decoded: fin=1 opcode=1 data=b'{"topic":"orderbook.50.BTCUSDC","ts":1698936852144,"type":"delta","data":{"s":"BTCUSDC","b":[["34954.72","0.002712"],["34939.86","0"]],"a":[["34969.93","0.042805"],["34969.92","0"]],"u":20009835,"seq":14108033504}}'
2023-11-02 14:54:12,250 DEBUG ++Rcv raw: b'\x81~\x00\xd1{"topic":"orderbook.50.BTCUSDC","ts":1698936852164,"type":"delta","data":{"s":"BTCUSDC","b":[["34939.86","0.028"],["34958.15","0"]],"a":[["34964.85","0.0572"],["34987.53","0"]],"u":20009836,"seq":14108033518}}'
2023-11-02 14:54:12,250 DEBUG ++Rcv decoded: fin=1 opcode=1 data=b'{"topic":"orderbook.50.BTCUSDC","ts":1698936852164,"type":"delta","data":{"s":"BTCUSDC","b":[["34939.86","0.028"],["34958.15","0"]],"a":[["34964.85","0.0572"],["34987.53","0"]],"u":20009836,"seq":14108033518}}'
2023-11-02 14:54:12,288 DEBUG ++Rcv raw: b'\x81~\x00\xd7{"topic":"orderbook.50.BTCUSDC","ts":1698936852203,"type":"delta","data":{"s":"BTCUSDC","b":[["34961.49","0.028602"],["34958.46","0.022308"],["34940.24","0"],["34939.86","0"]],"a":[],"u":20009837,"seq":14108033536}}'
2023-11-02 14:54:12,289 DEBUG ++Rcv decoded: fin=1 opcode=1 data=b'{"topic":"orderbook.50.BTCUSDC","ts":1698936852203,"type":"delta","data":{"s":"BTCUSDC","b":[["34961.49","0.028602"],["34958.46","0.022308"],["34940.24","0"],["34939.86","0"]],"a":[],"u":20009837,"seq":14108033536}}'
2023-11-02 14:54:12,309 DEBUG ++Rcv raw: b'\x81~\x00\xac{"topic":"orderbook.50.BTCUSDC","ts":1698936852224,"type":"delta","data":{"s":"BTCUSDC","b":[],"a":[["34987.53","0.1875"],["34981.41","0"]],"u":20009838,"seq":14108033545}}'
2023-11-02 14:54:12,309 DEBUG ++Rcv decoded: fin=1 opcode=1 data=b'{"topic":"orderbook.50.BTCUSDC","ts":1698936852224,"type":"delta","data":{"s":"BTCUSDC","b":[],"a":[["34987.53","0.1875"],["34981.41","0"]],"u":20009838,"seq":14108033545}}'
2023-11-02 14:54:12,328 DEBUG ++Rcv raw: b'\x81~\x00\xab{"topic":"orderbook.50.BTCUSDC","ts":1698936852243,"type":"delta","data":{"s":"BTCUSDC","b":[],"a":[["34980.5","0.0859"],["34987.53","0"]],"u":20009839,"seq":14108033554}}'
2023-11-02 14:54:12,329 DEBUG ++Rcv decoded: fin=1 opcode=1 data=b'{"topic":"orderbook.50.BTCUSDC","ts":1698936852243,"type":"delta","data":{"s":"BTCUSDC","b":[],"a":[["34980.5","0.0859"],["34987.53","0"]],"u":20009839,"seq":14108033554}}'
2023-11-02 14:54:12,389 DEBUG ++Rcv raw: b'\x81~\x00\xd3{"topic":"orderbook.50.BTCUSDC","ts":1698936852303,"type":"delta","data":{"s":"BTCUSDC","b":[["34940.24","0.05724"],["34961.49","0"]],"a":[["34987.53","0.1875"],["34985.36","0"]],"u":20009840,"seq":14108033577}}'
2023-11-02 14:54:12,389 DEBUG ++Rcv decoded: fin=1 opcode=1 data=b'{"topic":"orderbook.50.BTCUSDC","ts":1698936852303,"type":"delta","data":{"s":"BTCUSDC","b":[["34940.24","0.05724"],["34961.49","0"]],"a":[["34987.53","0.1875"],["34985.36","0"]],"u":20009840,"seq":14108033577}}'
2023-11-02 14:54:12,409 DEBUG ++Rcv raw: b'\x81~\x00\xd6{"topic":"orderbook.50.BTCUSDC","ts":1698936852323,"type":"delta","data":{"s":"BTCUSDC","b":[["34950.02","0.222572"],["34940.24","0"]],"a":[["34978.77","0.051549"],["34987.53","0"]],"u":20009841,"seq":14108033583}}'
2023-11-02 14:54:12,410 DEBUG ++Rcv decoded: fin=1 opcode=1 data=b'{"topic":"orderbook.50.BTCUSDC","ts":1698936852323,"type":"delta","data":{"s":"BTCUSDC","b":[["34950.02","0.222572"],["34940.24","0"]],"a":[["34978.77","0.051549"],["34987.53","0"]],"u":20009841,"seq":14108033583}}'
2023-11-02 14:54:12,429 DEBUG ++Rcv raw: b'\x81~\x01\xc8{"topic":"orderbook.50.BTCUSDC","ts":1698936852343,"type":"delta","data":{"s":"BTCUSDC","b":[["34962.06","0.09942"],["34958.72","0.05721"],["34952.55","0.11444"],["34943.41","0.286176"],["34959.2","0"],["34941.44","0"],["34953.76","0"],["34945.03","0"]],"a":[["34965.24","0.057199"],["34965.57","0.099184"],["34971.41","0.114379"],["34980.56","0.285873"],["34964.85","0"],["34970.47","0"],["34986.02","0"],["34979.49","0"]],"u":20009842,"seq":14108033626}}'
2023-11-02 14:54:12,429 DEBUG ++Rcv decoded: fin=1 opcode=1 data=b'{"topic":"orderbook.50.BTCUSDC","ts":1698936852343,"type":"delta","data":{"s":"BTCUSDC","b":[["34962.06","0.09942"],["34958.72","0.05721"],["34952.55","0.11444"],["34943.41","0.286176"],["34959.2","0"],["34941.44","0"],["34953.76","0"],["34945.03","0"]],"a":[["34965.24","0.057199"],["34965.57","0.099184"],["34971.41","0.114379"],["34980.56","0.285873"],["34964.85","0"],["34970.47","0"],["34986.02","0"],["34979.49","0"]],"u":20009842,"seq":14108033626}}'
2023-11-02 14:54:12,449 DEBUG ++Rcv raw: b'\x81~\x01v{"topic":"orderbook.50.BTCUSDC","ts":1698936852364,"type":"delta","data":{"s":"BTCUSDC","b":[["34941.44","0.025298"],["34940.24","0.05724"],["34945.69","0"],["34962.01","0"]],"a":[["34965.23","0.03432"],["34965.56","0.039342"],["34966.59","0.000239"],["34971.4","0.06863"],["34985.12","0"],["34966.55","0"],["34971.87","0"],["34965.57","0"]],"u":20009843,"seq":14108033644}}'
2023-11-02 14:54:12,449 DEBUG ++Rcv decoded: fin=1 opcode=1 data=b'{"topic":"orderbook.50.BTCUSDC","ts":1698936852364,"type":"delta","data":{"s":"BTCUSDC","b":[["34941.44","0.025298"],["34940.24","0.05724"],["34945.69","0"],["34962.01","0"]],"a":[["34965.23","0.03432"],["34965.56","0.039342"],["34966.59","0.000239"],["34971.4","0.06863"],["34985.12","0"],["34966.55","0"],["34971.87","0"],["34965.57","0"]],"u":20009843,"seq":14108033644}}'
2023-11-02 14:54:12,469 DEBUG ++Rcv raw: b'\x81~\x00\xae{"topic":"orderbook.50.BTCUSDC","ts":1698936852384,"type":"delta","data":{"s":"BTCUSDC","b":[],"a":[["34966.55","0.022564"],["34965.56","0"]],"u":20009844,"seq":14108033651}}'
2023-11-02 14:54:12,469 DEBUG ++Rcv decoded: fin=1 opcode=1 data=b'{"topic":"orderbook.50.BTCUSDC","ts":1698936852384,"type":"delta","data":{"s":"BTCUSDC","b":[],"a":[["34966.55","0.022564"],["34965.56","0"]],"u":20009844,"seq":14108033651}}'
2023-11-02 14:54:12,489 DEBUG ++Rcv raw: b'\x81~\x00\xd6{"topic":"orderbook.50.BTCUSDC","ts":1698936852404,"type":"delta","data":{"s":"BTCUSDC","b":[["34962.02","0.028602"],["34940.24","0"]],"a":[["34985.12","0.000491"],["34966.55","0"]],"u":20009845,"seq":14108033655}}'
2023-11-02 14:54:12,489 DEBUG ++Rcv decoded: fin=1 opcode=1 data=b'{"topic":"orderbook.50.BTCUSDC","ts":1698936852404,"type":"delta","data":{"s":"BTCUSDC","b":[["34962.02","0.028602"],["34940.24","0"]],"a":[["34985.12","0.000491"],["34966.55","0"]],"u":20009845,"seq":14108033655}}'
2023-11-02 14:54:12,509 DEBUG ++Rcv raw: b'\x81~\x00\xae{"topic":"orderbook.50.BTCUSDC","ts":1698936852424,"type":"delta","data":{"s":"BTCUSDC","b":[["34954.96","0.014461"],["34941.44","0"]],"a":[],"u":20009846,"seq":14108033673}}'
2023-11-02 14:54:12,509 DEBUG ++Rcv decoded: fin=1 opcode=1 data=b'{"topic":"orderbook.50.BTCUSDC","ts":1698936852424,"type":"delta","data":{"s":"BTCUSDC","b":[["34954.96","0.014461"],["34941.44","0"]],"a":[],"u":20009846,"seq":14108033673}}'
2023-11-02 14:54:12,529 DEBUG ++Rcv raw: b'\x81~\x00\xae{"topic":"orderbook.50.BTCUSDC","ts":1698936852444,"type":"delta","data":{"s":"BTCUSDC","b":[["34954.01","0.002084"],["34941.48","0"]],"a":[],"u":20009847,"seq":14108033690}}'
2023-11-02 14:54:12,529 DEBUG ++Rcv decoded: fin=1 opcode=1 data=b'{"topic":"orderbook.50.BTCUSDC","ts":1698936852444,"type":"delta","data":{"s":"BTCUSDC","b":[["34954.01","0.002084"],["34941.48","0"]],"a":[],"u":20009847,"seq":14108033690}}'
2023-11-02 14:54:12,589 DEBUG ++Rcv raw: b'\x81~\x00\xae{"topic":"orderbook.50.BTCUSDC","ts":1698936852504,"type":"delta","data":{"s":"BTCUSDC","b":[["34941.48","0.082683"],["34954.72","0"]],"a":[],"u":20009848,"seq":14108033716}}'
2023-11-02 14:54:12,589 DEBUG ++Rcv decoded: fin=1 opcode=1 data=b'{"topic":"orderbook.50.BTCUSDC","ts":1698936852504,"type":"delta","data":{"s":"BTCUSDC","b":[["34941.48","0.082683"],["34954.72","0"]],"a":[],"u":20009848,"seq":14108033716}}'
2023-11-02 14:54:12,629 DEBUG ++Rcv raw: b'\x81~\x00\xac{"topic":"orderbook.50.BTCUSDC","ts":1698936852544,"type":"delta","data":{"s":"BTCUSDC","b":[],"a":[["34986.02","0.4055"],["34969.93","0"]],"u":20009849,"seq":14108033732}}'
2023-11-02 14:54:12,629 DEBUG ++Rcv decoded: fin=1 opcode=1 data=b'{"topic":"orderbook.50.BTCUSDC","ts":1698936852544,"type":"delta","data":{"s":"BTCUSDC","b":[],"a":[["34986.02","0.4055"],["34969.93","0"]],"u":20009849,"seq":14108033732}}'
2023-11-02 14:54:12,710 DEBUG ++Rcv raw: b'\x81~\x00\xae{"topic":"orderbook.50.BTCUSDC","ts":1698936852624,"type":"delta","data":{"s":"BTCUSDC","b":[["34941.44","0.025298"],["34962.02","0"]],"a":[],"u":20009850,"seq":14108033750}}'
2023-11-02 14:54:12,710 DEBUG ++Rcv decoded: fin=1 opcode=1 data=b'{"topic":"orderbook.50.BTCUSDC","ts":1698936852624,"type":"delta","data":{"s":"BTCUSDC","b":[["34941.44","0.025298"],["34962.02","0"]],"a":[],"u":20009850,"seq":14108033750}}'
2023-11-02 14:54:12,750 DEBUG ++Rcv raw: b'\x81~\x00\xae{"topic":"orderbook.50.BTCUSDC","ts":1698936852663,"type":"delta","data":{"s":"BTCUSDC","b":[],"a":[["34966.49","0.000239"],["34986.02","0"]],"u":20009851,"seq":14108033752}}'
2023-11-02 14:54:12,750 DEBUG ++Rcv decoded: fin=1 opcode=1 data=b'{"topic":"orderbook.50.BTCUSDC","ts":1698936852663,"type":"delta","data":{"s":"BTCUSDC","b":[],"a":[["34966.49","0.000239"],["34986.02","0"]],"u":20009851,"seq":14108033752}}'
2023-11-02 14:54:12,809 DEBUG ++Rcv raw: b'\x81~\x00\xab{"topic":"orderbook.50.BTCUSDC","ts":1698936852724,"type":"delta","data":{"s":"BTCUSDC","b":[["34941.45","0.028"],["34941.44","0"]],"a":[],"u":20009852,"seq":14108033755}}'
2023-11-02 14:54:12,809 DEBUG ++Rcv decoded: fin=1 opcode=1 data=b'{"topic":"orderbook.50.BTCUSDC","ts":1698936852724,"type":"delta","data":{"s":"BTCUSDC","b":[["34941.45","0.028"],["34941.44","0"]],"a":[],"u":20009852,"seq":14108033755}}'
2023-11-02 14:54:12,849 DEBUG ++Rcv raw: b'\x81~\x00\xae{"topic":"orderbook.50.BTCUSDC","ts":1698936852764,"type":"delta","data":{"s":"BTCUSDC","b":[["34941.52","0.206875"],["34941.45","0"]],"a":[],"u":20009853,"seq":14108033763}}'
2023-11-02 14:54:12,849 DEBUG ++Rcv decoded: fin=1 opcode=1 data=b'{"topic":"orderbook.50.BTCUSDC","ts":1698936852764,"type":"delta","data":{"s":"BTCUSDC","b":[["34941.52","0.206875"],["34941.45","0"]],"a":[],"u":20009853,"seq":14108033763}}'
2023-11-02 14:54:12,929 DEBUG ++Rcv raw: b'\x81~\x00\xae{"topic":"orderbook.50.BTCUSDC","ts":1698936852843,"type":"delta","data":{"s":"BTCUSDC","b":[["34962.07","0.008956"],["34941.48","0"]],"a":[],"u":20009854,"seq":14108033790}}'
2023-11-02 14:54:12,929 DEBUG ++Rcv decoded: fin=1 opcode=1 data=b'{"topic":"orderbook.50.BTCUSDC","ts":1698936852843,"type":"delta","data":{"s":"BTCUSDC","b":[["34962.07","0.008956"],["34941.48","0"]],"a":[],"u":20009854,"seq":14108033790}}'
2023-11-02 14:54:12,948 DEBUG ++Rcv raw: b'\x81~\x00\xc6{"topic":"orderbook.50.BTCUSDC","ts":1698936852863,"type":"delta","data":{"s":"BTCUSDC","b":[["34962.07","0.037558"],["34941.48","0.082683"],["34962.06","0"]],"a":[],"u":20009855,"seq":14108033794}}'
2023-11-02 14:54:12,948 DEBUG ++Rcv decoded: fin=1 opcode=1 data=b'{"topic":"orderbook.50.BTCUSDC","ts":1698936852863,"type":"delta","data":{"s":"BTCUSDC","b":[["34962.07","0.037558"],["34941.48","0.082683"],["34962.06","0"]],"a":[],"u":20009855,"seq":14108033794}}'
2023-11-02 14:54:12,968 DEBUG ++Rcv raw: b'\x81~\x00\xc3{"topic":"orderbook.50.BTCUSDC","ts":1698936852883,"type":"delta","data":{"s":"BTCUSDC","b":[["34962.07","0.040558"],["34957.22","0.036"],["34941.48","0"]],"a":[],"u":20009856,"seq":14108033802}}'
2023-11-02 14:54:12,969 DEBUG ++Rcv decoded: fin=1 opcode=1 data=b'{"topic":"orderbook.50.BTCUSDC","ts":1698936852883,"type":"delta","data":{"s":"BTCUSDC","b":[["34962.07","0.040558"],["34957.22","0.036"],["34941.48","0"]],"a":[],"u":20009856,"seq":14108033802}}'
2023-11-02 14:54:12,989 DEBUG ++Rcv raw: b'\x81~\x00\xd4{"topic":"orderbook.50.BTCUSDC","ts":1698936852903,"type":"delta","data":{"s":"BTCUSDC","b":[["34957.23","0.021605"],["34941.52","0"]],"a":[["34986.02","0.4055"],["34966.59","0"]],"u":20009857,"seq":14108033815}}'
2023-11-02 14:54:12,989 DEBUG ++Rcv decoded: fin=1 opcode=1 data=b'{"topic":"orderbook.50.BTCUSDC","ts":1698936852903,"type":"delta","data":{"s":"BTCUSDC","b":[["34957.23","0.021605"],["34941.52","0"]],"a":[["34986.02","0.4055"],["34966.59","0"]],"u":20009857,"seq":14108033815}}'
2023-11-02 14:54:13,029 DEBUG ++Rcv raw: b'\x81~\x00\xab{"topic":"orderbook.50.BTCUSDC","ts":1698936852943,"type":"delta","data":{"s":"BTCUSDC","b":[["34954.72","0.000946"],["34942","0"]],"a":[],"u":20009858,"seq":14108033821}}'
2023-11-02 14:54:13,029 DEBUG ++Rcv decoded: fin=1 opcode=1 data=b'{"topic":"orderbook.50.BTCUSDC","ts":1698936852943,"type":"delta","data":{"s":"BTCUSDC","b":[["34954.72","0.000946"],["34942","0"]],"a":[],"u":20009858,"seq":14108033821}}'
2023-11-02 14:54:13,049 DEBUG ++Rcv raw: b'\x81~\x00\xc1{"topic":"orderbook.50.BTCUSDC","ts":1698936852963,"type":"delta","data":{"s":"BTCUSDC","b":[["34962.07","0.011956"],["34942","0.0341"],["34954.01","0"]],"a":[],"u":20009859,"seq":14108033825}}'
2023-11-02 14:54:13,049 DEBUG ++Rcv decoded: fin=1 opcode=1 data=b'{"topic":"orderbook.50.BTCUSDC","ts":1698936852963,"type":"delta","data":{"s":"BTCUSDC","b":[["34962.07","0.011956"],["34942","0.0341"],["34954.01","0"]],"a":[],"u":20009859,"seq":14108033825}}'
2023-11-02 14:54:13,089 DEBUG ++Rcv raw: b'\x81~\x00\xfe{"topic":"orderbook.50.BTCUSDC","ts":1698936853003,"type":"delta","data":{"s":"BTCUSDC","b":[],"a":[["34966.35","0.057197"],["34972.52","0.114375"],["34987.53","0.1875"],["34971.41","0"],["34980.56","0"],["34965.24","0"]],"u":20009860,"seq":14108033847}}'
2023-11-02 14:54:13,089 DEBUG ++Rcv decoded: fin=1 opcode=1 data=b'{"topic":"orderbook.50.BTCUSDC","ts":1698936853003,"type":"delta","data":{"s":"BTCUSDC","b":[],"a":[["34966.35","0.057197"],["34972.52","0.114375"],["34987.53","0.1875"],["34971.41","0"],["34980.56","0"],["34965.24","0"]],"u":20009860,"seq":14108033847}}'
2023-11-02 14:54:13,109 DEBUG ++Rcv raw: b'\x81~\x00\xef{"topic":"orderbook.50.BTCUSDC","ts":1698936853023,"type":"delta","data":{"s":"BTCUSDC","b":[],"a":[["34966.34","0.057027"],["34966.56","0.023312"],["34981.67","0.285864"],["34965.23","0"],["34987.53","0"]],"u":20009861,"seq":14108033856}}'
2023-11-02 14:54:13,109 DEBUG ++Rcv decoded: fin=1 opcode=1 data=b'{"topic":"orderbook.50.BTCUSDC","ts":1698936853023,"type":"delta","data":{"s":"BTCUSDC","b":[],"a":[["34966.34","0.057027"],["34966.56","0.023312"],["34981.67","0.285864"],["34965.23","0"],["34987.53","0"]],"u":20009861,"seq":14108033856}}'
2023-11-02 14:54:13,149 DEBUG ++Rcv raw: b'\x81~\x018{"topic":"orderbook.50.BTCUSDC","ts":1698936853063,"type":"delta","data":{"s":"BTCUSDC","b":[["34962.49","0.094053"],["34962.08","0.028602"],["34962.07","0.003"],["34942.2","0"],["34942","0"]],"a":[["34965.99","0.10507"],["34969.95","0.042582"],["34986.02","0"],["34973.55","0"]],"u":20009862,"seq":14108033868}}'
2023-11-02 14:54:13,149 DEBUG ++Rcv decoded: fin=1 opcode=1 data=b'{"topic":"orderbook.50.BTCUSDC","ts":1698936853063,"type":"delta","data":{"s":"BTCUSDC","b":[["34962.49","0.094053"],["34962.08","0.028602"],["34962.07","0.003"],["34942.2","0"],["34942","0"]],"a":[["34965.99","0.10507"],["34969.95","0.042582"],["34986.02","0"],["34973.55","0"]],"u":20009862,"seq":14108033868}}'
2023-11-02 14:54:13,169 DEBUG ++Rcv raw: b'\x81~\x01#{"topic":"orderbook.50.BTCUSDC","ts":1698936853084,"type":"delta","data":{"s":"BTCUSDC","b":[["34962.5","0.008956"],["34962.07","0"]],"a":[["34965.98","0.111497"],["34986.02","0.4055"],["34987.53","0.1875"],["34966.34","0"],["34968.45","0"],["34965.99","0"]],"u":20009863,"seq":14108033877}}'
2023-11-02 14:54:13,169 DEBUG ++Rcv decoded: fin=1 opcode=1 data=b'{"topic":"orderbook.50.BTCUSDC","ts":1698936853084,"type":"delta","data":{"s":"BTCUSDC","b":[["34962.5","0.008956"],["34962.07","0"]],"a":[["34965.98","0.111497"],["34986.02","0.4055"],["34987.53","0.1875"],["34966.34","0"],["34968.45","0"],["34965.99","0"]],"u":20009863,"seq":14108033877}}'
2023-11-02 14:54:13,189 DEBUG ++Rcv raw: b'\x81~\x00\xed{"topic":"orderbook.50.BTCUSDC","ts":1698936853104,"type":"delta","data":{"s":"BTCUSDC","b":[["34942.2","0.043599"],["34962.49","0"]],"a":[["34965.98","0.017756"],["34968.45","0.051549"],["34987.53","0"]],"u":20009864,"seq":14108033884}}'
2023-11-02 14:54:13,189 DEBUG ++Rcv decoded: fin=1 opcode=1 data=b'{"topic":"orderbook.50.BTCUSDC","ts":1698936853104,"type":"delta","data":{"s":"BTCUSDC","b":[["34942.2","0.043599"],["34962.49","0"]],"a":[["34965.98","0.017756"],["34968.45","0.051549"],["34987.53","0"]],"u":20009864,"seq":14108033884}}'
2023-11-02 14:54:13,209 DEBUG ++Rcv raw: b'\x81~\x01${"topic":"orderbook.50.BTCUSDC","ts":1698936853124,"type":"delta","data":{"s":"BTCUSDC","b":[["34961.58","0.0859"],["34943.86","0"]],"a":[["34966.34","0.048449"],["34980.48","0.023472"],["34987.53","0.1875"],["34966.49","0"],["34969.95","0"],["34965.98","0"]],"u":20009865,"seq":14108033904}}'
2023-11-02 14:54:13,209 DEBUG ++Rcv decoded: fin=1 opcode=1 data=b'{"topic":"orderbook.50.BTCUSDC","ts":1698936853124,"type":"delta","data":{"s":"BTCUSDC","b":[["34961.58","0.0859"],["34943.86","0"]],"a":[["34966.34","0.048449"],["34980.48","0.023472"],["34987.53","0.1875"],["34966.49","0"],["34969.95","0"],["34965.98","0"]],"u":20009865,"seq":14108033904}}'
2023-11-02 14:54:13,229 DEBUG ++Rcv raw: b'\x81~\x01J{"topic":"orderbook.50.BTCUSDC","ts":1698936853144,"type":"delta","data":{"s":"BTCUSDC","b":[["34954.97","0.002051"],["34942","0.0341"],["34962.08","0"],["34961.58","0"]],"a":[["34988.11","0.245048"],["34988.12","0.4084"],["34989.37","0.054843"],["34966.35","0"],["34966.34","0"],["34966.56","0"]],"u":20009866,"seq":14108033926}}'
2023-11-02 14:54:13,229 DEBUG ++Rcv decoded: fin=1 opcode=1 data=b'{"topic":"orderbook.50.BTCUSDC","ts":1698936853144,"type":"delta","data":{"s":"BTCUSDC","b":[["34954.97","0.002051"],["34942","0.0341"],["34962.08","0"],["34961.58","0"]],"a":[["34988.11","0.245048"],["34988.12","0.4084"],["34989.37","0.054843"],["34966.35","0"],["34966.34","0"],["34966.56","0"]],"u":20009866,"seq":14108033926}}'
2023-11-02 14:54:13,250 DEBUG ++Rcv raw: b'\x81~\x01\xe4{"topic":"orderbook.50.BTCUSDC","ts":1698936853164,"type":"delta","data":{"s":"BTCUSDC","b":[["34962.52","0.008956"],["34962","0.0324"],["34961.58","0.0859"],["34960.13","0.028599"],["34959.2","0.057209"],["34958.72","0"],["34954.72","0"],["34942","0"],["34958.32","0"],["34962.5","0"]],"a":[["34967.86","0.057195"],["34990.96","0.002812"],["34991","0.1125"],["34991.01","0.048472"],["34969.25","0"],["34971.45","0"],["34968.46","0"],["34971.16","0"]],"u":20009867,"seq":14108033972}}'
2023-11-02 14:54:13,250 DEBUG ++Rcv decoded: fin=1 opcode=1 data=b'{"topic":"orderbook.50.BTCUSDC","ts":1698936853164,"type":"delta","data":{"s":"BTCUSDC","b":[["34962.52","0.008956"],["34962","0.0324"],["34961.58","0.0859"],["34960.13","0.028599"],["34959.2","0.057209"],["34958.72","0"],["34954.72","0"],["34942","0"],["34958.32","0"],["34962.5","0"]],"a":[["34967.86","0.057195"],["34990.96","0.002812"],["34991","0.1125"],["34991.01","0.048472"],["34969.25","0"],["34971.45","0"],["34968.46","0"],["34971.16","0"]],"u":20009867,"seq":14108033972}}'
